root - INFO - 2023-04-12 12:21:53.590657 - Finvant Alcubierre Mk1 OMS Backend turned on.
root - INFO - 2023-04-12 12:21:53.665425 - OMS Backend mainloop started.
root - CRITICAL - CRITICAL ERROR:2023-04-12 12:21:56.017852 - OMSB_ADSINT_2
['Traceback (most recent call last):', '  File "/Users/vishaljha/anaconda3/lib/python3.8/site-packages/urllib3/connectionpool.py", line 379, in _make_request', '    httplib_response = conn.getresponse(buffering=True)', "TypeError: getresponse() got an unexpected keyword argument 'buffering'", '', 'During handling of the above exception, another exception occurred:', '', 'Traceback (most recent call last):', '  File "/Users/vishaljha/Desktop/FINVANT/API/Backend/Scripts/ADS_Interface.py", line 54, in get_user_data', "    return json.loads(self.get('get/user_data'))", '  File "/Users/vishaljha/Desktop/FINVANT/API/Backend/Scripts/ADS_Interface.py", line 42, in get', '    response = requests.get(self.url + route, headers=headers)', '  File "/Users/vishaljha/anaconda3/lib/python3.8/site-packages/requests/api.py", line 73, in get', '    return request("get", url, params=params, **kwargs)', '  File "/Users/vishaljha/anaconda3/lib/python3.8/site-packages/requests/api.py", line 59, in request', '    return session.request(method=method, url=url, **kwargs)', '  File "/Users/vishaljha/anaconda3/lib/python3.8/site-packages/requests/sessions.py", line 587, in request', '    resp = self.send(prep, **send_kwargs)', '  File "/Users/vishaljha/anaconda3/lib/python3.8/site-packages/requests/sessions.py", line 701, in send', '    r = adapter.send(request, **kwargs)', '  File "/Users/vishaljha/anaconda3/lib/python3.8/site-packages/requests/adapters.py", line 489, in send', '    resp = conn.urlopen(', '  File "/Users/vishaljha/anaconda3/lib/python3.8/site-packages/urllib3/connectionpool.py", line 600, in urlopen', '    httplib_response = self._make_request(conn, method, url,', '  File "/Users/vishaljha/anaconda3/lib/python3.8/site-packages/urllib3/connectionpool.py", line 383, in _make_request', '    httplib_response = conn.getresponse()', '  File "/Users/vishaljha/anaconda3/lib/python3.8/http/client.py", line 1332, in getresponse', '    response.begin()', '  File "/Users/vishaljha/anaconda3/lib/python3.8/http/client.py", line 303, in begin', '    version, status, reason = self._read_status()', '  File "/Users/vishaljha/anaconda3/lib/python3.8/http/client.py", line 264, in _read_status', '    line = str(self.fp.readline(_MAXLINE + 1), "iso-8859-1")', '  File "/Users/vishaljha/anaconda3/lib/python3.8/socket.py", line 669, in readinto', '    return self._sock.recv_into(b)', 'KeyboardInterrupt']
root - CRITICAL - CRITICAL ERROR:2023-04-12 12:21:56.019799 - Failed to get user data/spreads/config.
['Traceback (most recent call last):', '  File "/Users/vishaljha/anaconda3/lib/python3.8/site-packages/urllib3/connectionpool.py", line 379, in _make_request', '    httplib_response = conn.getresponse(buffering=True)', "TypeError: getresponse() got an unexpected keyword argument 'buffering'", '', 'During handling of the above exception, another exception occurred:', '', 'Traceback (most recent call last):', '  File "/Users/vishaljha/Desktop/FINVANT/API/Backend/Scripts/ADS_Interface.py", line 54, in get_user_data', "    return json.loads(self.get('get/user_data'))", '  File "/Users/vishaljha/Desktop/FINVANT/API/Backend/Scripts/ADS_Interface.py", line 42, in get', '    response = requests.get(self.url + route, headers=headers)', '  File "/Users/vishaljha/anaconda3/lib/python3.8/site-packages/requests/api.py", line 73, in get', '    return request("get", url, params=params, **kwargs)', '  File "/Users/vishaljha/anaconda3/lib/python3.8/site-packages/requests/api.py", line 59, in request', '    return session.request(method=method, url=url, **kwargs)', '  File "/Users/vishaljha/anaconda3/lib/python3.8/site-packages/requests/sessions.py", line 587, in request', '    resp = self.send(prep, **send_kwargs)', '  File "/Users/vishaljha/anaconda3/lib/python3.8/site-packages/requests/sessions.py", line 701, in send', '    r = adapter.send(request, **kwargs)', '  File "/Users/vishaljha/anaconda3/lib/python3.8/site-packages/requests/adapters.py", line 489, in send', '    resp = conn.urlopen(', '  File "/Users/vishaljha/anaconda3/lib/python3.8/site-packages/urllib3/connectionpool.py", line 600, in urlopen', '    httplib_response = self._make_request(conn, method, url,', '  File "/Users/vishaljha/anaconda3/lib/python3.8/site-packages/urllib3/connectionpool.py", line 383, in _make_request', '    httplib_response = conn.getresponse()', '  File "/Users/vishaljha/anaconda3/lib/python3.8/http/client.py", line 1332, in getresponse', '    response.begin()', '  File "/Users/vishaljha/anaconda3/lib/python3.8/http/client.py", line 303, in begin', '    version, status, reason = self._read_status()', '  File "/Users/vishaljha/anaconda3/lib/python3.8/http/client.py", line 264, in _read_status', '    line = str(self.fp.readline(_MAXLINE + 1), "iso-8859-1")', '  File "/Users/vishaljha/anaconda3/lib/python3.8/socket.py", line 669, in readinto', '    return self._sock.recv_into(b)', 'KeyboardInterrupt', '', 'During handling of the above exception, another exception occurred:', '', 'Traceback (most recent call last):', '  File "Main.py", line 57, in main_loop', '    user_data = self.ads_interface.get_user_data()', '  File "/Users/vishaljha/Desktop/FINVANT/API/Backend/Scripts/ADS_Interface.py", line 56, in get_user_data', "    logCritical('OMSB_ADSINT_2',exit = True)", '  File "/Users/vishaljha/Desktop/FINVANT/API/Backend/Scripts/Logs.py", line 46, in logCritical', '    sys.exit(1)', 'SystemExit: 1']
root - CRITICAL - CRITICAL ERROR:2023-04-12 12:21:56.099142 - Failed to start LTP thread.
['Traceback (most recent call last):', '  File "Main.py", line 68, in main_loop', '    kite_ticker = auto_login_zerodha_ticker(config=config,log_interface=self.log_interface, debug=self.DEBUG)', "UnboundLocalError: local variable 'config' referenced before assignment"]
root - INFO - 2023-04-12 12:22:27.384223 - Finvant Alcubierre Mk1 OMS Backend turned on.
root - INFO - 2023-04-12 12:22:27.469795 - OMS Backend mainloop started.
root - INFO - 2023-04-12 12:22:27.590894 - OMSB: Logging in for backend kite ticker.
root - CRITICAL - CRITICAL ERROR:2023-04-12 12:22:41.858470 - OMSB: Failed auto login to kite ticker.
['Traceback (most recent call last):', '  File "/Users/vishaljha/Desktop/FINVANT/API/Backend/Scripts/AutoLoginKiteTicker.py", line 126, in auto_login_zerodha_ticker', '    data = kite.generate_session(key, api_secret=api_secret)', '  File "/Users/vishaljha/anaconda3/lib/python3.8/site-packages/kiteconnect/connect.py", line 255, in generate_session', '    h = hashlib.sha256(self.api_key.encode("utf-8") + request_token.encode("utf-8") + api_secret.encode("utf-8"))', "AttributeError: 'int' object has no attribute 'encode'"]
root - INFO - 2023-04-12 12:22:42.488114 - Attempting XTS login.
root - CRITICAL - CRITICAL ERROR:2023-04-12 12:22:42.489424 - Failed to start KWS thread.
['Traceback (most recent call last):', '  File "/Users/vishaljha/Desktop/FINVANT/API/Backend/Scripts/GatherLTP.py", line 71, in start', '    self.kws.on_ticks = self.on_ticks', "AttributeError: 'NoneType' object has no attribute 'on_ticks'"]
root - INFO - 2023-04-12 12:22:43.179103 - ODIN login for NB01.
root - INFO - 2023-04-12 12:22:44.269792 - BPWealth login for AHO7706.
root - INFO - 2023-04-12 12:22:45.039601 - ODIN login for S0201.
root - INFO - 2023-04-12 12:22:45.633852 - BPWealth login for AHD083.
root - INFO - 2023-04-12 12:22:45.706664 - ODIN login succesful for S0201.
root - INFO - 2023-04-12 12:22:46.085621 - OMSB: Zerodha login for WG5235.
root - INFO - 2023-04-12 12:22:46.875269 - BPWealth login for ACS1301.
root - INFO - 2023-04-12 12:22:48.367878 - BPWealth login for ACS1207.
root - INFO - 2023-04-12 12:22:49.854605 - BPWealth login for AC66.
root - INFO - 2023-04-12 12:22:54.379955 - OMSB: Zerodha login succesful for WG5235.
root - INFO - 2023-04-12 12:22:54.466139 - OMSB: Zerodha login for WG5235.
root - INFO - 2023-04-12 12:23:01.466803 - OMSB: Zerodha login succesful for WG5235.
root - INFO - 2023-04-12 12:23:13.163292 - Finvant Alcubierre Mk1 OMS Backend turned on.
root - INFO - 2023-04-12 12:23:13.248711 - OMS Backend mainloop started.
root - INFO - 2023-04-12 12:23:13.386518 - OMSB: Logging in for backend kite ticker.
root - CRITICAL - CRITICAL ERROR:2023-04-12 12:23:24.936576 - OMSB: Failed auto login to kite ticker.
['Traceback (most recent call last):', '  File "/Users/vishaljha/Desktop/FINVANT/API/Backend/Scripts/AutoLoginKiteTicker.py", line 126, in auto_login_zerodha_ticker', '    data = kite.generate_session(key, api_secret=api_secret)', '  File "/Users/vishaljha/anaconda3/lib/python3.8/site-packages/kiteconnect/connect.py", line 255, in generate_session', '    h = hashlib.sha256(self.api_key.encode("utf-8") + request_token.encode("utf-8") + api_secret.encode("utf-8"))', "AttributeError: 'int' object has no attribute 'encode'"]
root - INFO - 2023-04-12 12:23:25.344190 - Attempting XTS login.
root - CRITICAL - CRITICAL ERROR:2023-04-12 12:23:25.344667 - Failed to start KWS thread.
['Traceback (most recent call last):', '  File "/Users/vishaljha/Desktop/FINVANT/API/Backend/Scripts/GatherLTP.py", line 71, in start', '    self.kws.on_ticks = self.on_ticks', "AttributeError: 'NoneType' object has no attribute 'on_ticks'"]
root - INFO - 2023-04-12 12:23:25.525446 - BPWealth login for AHO7706.
root - INFO - 2023-04-12 12:23:25.531608 - ODIN login for NB01.
root - INFO - 2023-04-12 12:23:26.216915 - ODIN login for S0201.
root - INFO - 2023-04-12 12:23:26.224276 - BPWealth login for AHD083.
root - INFO - 2023-04-12 12:23:26.909036 - BPWealth login for ACS1301.
root - INFO - 2023-04-12 12:23:27.168103 - ODIN login succesful for S0201.
root - INFO - 2023-04-12 12:23:27.245587 - OMSB: Zerodha login for WG5235.
root - INFO - 2023-04-12 12:23:27.550463 - BPWealth login for ACS1207.
root - INFO - 2023-04-12 12:23:28.182873 - BPWealth login for AC66.
root - CRITICAL - CRITICAL ERROR:2023-04-12 12:23:28.303977 - Failed to generate user dictionary.
['Traceback (most recent call last):', '  File "Main.py", line 76, in main_loop', '    user_dict = UserProfileGenerator().create_user_profiles(user_data=user_data, log_interface=self.log_interface, debug=self.DEBUG)', '  File "/Users/vishaljha/Desktop/FINVANT/API/Backend/Scripts/UserProfileGenerator.py", line 74, in create_user_profiles', '    t.join()', '  File "/Users/vishaljha/anaconda3/lib/python3.8/threading.py", line 1011, in join', '    self._wait_for_tstate_lock()', '  File "/Users/vishaljha/anaconda3/lib/python3.8/threading.py", line 1027, in _wait_for_tstate_lock', '    elif lock.acquire(block, timeout):', 'KeyboardInterrupt']
root - CRITICAL - CRITICAL ERROR:2023-04-12 12:23:28.344843 - OMSB: Failed auto login to kite for user:WG5235.
['Traceback (most recent call last):', '  File "/Users/vishaljha/Desktop/FINVANT/API/Backend/Scripts/AutoLoginZerodha.py", line 36, in automate_login', "    browser = webdriver.Chrome(options = options,executable_path='../Chrome/chromedriver')", '  File "/Users/vishaljha/anaconda3/lib/python3.8/site-packages/selenium/webdriver/chrome/webdriver.py", line 73, in __init__', '    self.service.start()', '  File "/Users/vishaljha/anaconda3/lib/python3.8/site-packages/selenium/webdriver/common/service.py", line 98, in start', '    self.assert_process_still_running()', '  File "/Users/vishaljha/anaconda3/lib/python3.8/site-packages/selenium/webdriver/common/service.py", line 109, in assert_process_still_running', '    raise WebDriverException(', 'selenium.common.exceptions.WebDriverException: Message: Service ../Chrome/chromedriver unexpectedly exited. Status code was: -2', '', '', 'During handling of the above exception, another exception occurred:', '', 'Traceback (most recent call last):', '  File "/Users/vishaljha/anaconda3/lib/python3.8/site-packages/selenium/webdriver/common/service.py", line 72, in start', '    self.process = subprocess.Popen(cmd, env=self.env,', '  File "/Users/vishaljha/anaconda3/lib/python3.8/subprocess.py", line 854, in __init__', '    self._execute_child(args, executable, preexec_fn, close_fds,', '  File "/Users/vishaljha/anaconda3/lib/python3.8/subprocess.py", line 1702, in _execute_child', '    raise child_exception_type(errno_num, err_msg, err_filename)', "FileNotFoundError: [Errno 2] No such file or directory: 'chromedriver'", '', 'During handling of the above exception, another exception occurred:', '', 'Traceback (most recent call last):', '  File "/Users/vishaljha/Desktop/FINVANT/API/Backend/Scripts/AutoLoginZerodha.py", line 117, in auto_login_zerodha', '    key = automate_login(browser_url, user_id, password, totp_pin)', '  File "/Users/vishaljha/Desktop/FINVANT/API/Backend/Scripts/AutoLoginZerodha.py", line 40, in automate_login', '    browser = webdriver.Chrome(options = options)', '  File "/Users/vishaljha/anaconda3/lib/python3.8/site-packages/selenium/webdriver/chrome/webdriver.py", line 73, in __init__', '    self.service.start()', '  File "/Users/vishaljha/anaconda3/lib/python3.8/site-packages/selenium/webdriver/common/service.py", line 81, in start', '    raise WebDriverException(', "selenium.common.exceptions.WebDriverException: Message: 'chromedriver' executable needs to be in PATH. Please see https://sites.google.com/a/chromium.org/chromedriver/home", '']
root - CRITICAL - CRITICAL ERROR:2023-04-12 12:23:28.385292 - Failure in order handler.
['Traceback (most recent call last):', '  File "Main.py", line 82, in main_loop', '    order_handler = OrderHandler(user_profiles=user_dict, spread_list=spread_list, log_interface = self.log_interface, debug=self.DEBUG)', "UnboundLocalError: local variable 'user_dict' referenced before assignment"]
root - INFO - 2023-04-12 12:23:28.422279 - OMSB: Zerodha login for WG5235.
root - INFO - 2023-04-12 12:25:14.546747 - Finvant Alcubierre Mk1 OMS Backend turned on.
root - INFO - 2023-04-12 12:25:14.626191 - OMS Backend mainloop started.
root - INFO - 2023-04-12 12:25:14.751702 - OMSB: Logging in for backend kite ticker.
root - CRITICAL - CRITICAL ERROR:2023-04-12 12:25:27.412031 - OMSB: Failed auto login to kite ticker.
['Traceback (most recent call last):', '  File "/Users/vishaljha/Desktop/FINVANT/API/Backend/Scripts/AutoLoginKiteTicker.py", line 126, in auto_login_zerodha_ticker', '    data = kite.generate_session(key, api_secret=api_secret)', '  File "/Users/vishaljha/anaconda3/lib/python3.8/site-packages/kiteconnect/connect.py", line 255, in generate_session', '    h = hashlib.sha256(self.api_key.encode("utf-8") + request_token.encode("utf-8") + api_secret.encode("utf-8"))', "AttributeError: 'int' object has no attribute 'encode'"]
root - CRITICAL - CRITICAL ERROR:2023-04-12 12:25:27.756151 - Failed to start KWS thread.
['Traceback (most recent call last):', '  File "/Users/vishaljha/Desktop/FINVANT/API/Backend/Scripts/GatherLTP.py", line 71, in start', '    self.kws.on_ticks = self.on_ticks', "AttributeError: 'NoneType' object has no attribute 'on_ticks'"]
root - INFO - 2023-04-12 12:46:39.036837 - Finvant Alcubierre Mk1 OMS Backend turned on.
root - INFO - 2023-04-12 12:46:39.117837 - OMS Backend mainloop started.
root - INFO - 2023-04-12 12:46:39.248735 - OMSB: Logging in for backend kite ticker.
root - CRITICAL - CRITICAL ERROR:2023-04-12 12:46:52.661792 - OMSB: Failed auto login to kite ticker.
['Traceback (most recent call last):', '  File "/Users/vishaljha/Desktop/FINVANT/API/Backend/Scripts/AutoLoginKiteTicker.py", line 126, in auto_login_zerodha_ticker', '    data = kite.generate_session(key, api_secret=api_secret)', '  File "/Users/vishaljha/anaconda3/lib/python3.8/site-packages/kiteconnect/connect.py", line 255, in generate_session', '    h = hashlib.sha256(self.api_key.encode("utf-8") + request_token.encode("utf-8") + api_secret.encode("utf-8"))', "AttributeError: 'int' object has no attribute 'encode'"]
root - CRITICAL - CRITICAL ERROR:2023-04-12 12:46:53.003892 - Failed to start KWS thread.
['Traceback (most recent call last):', '  File "/Users/vishaljha/Desktop/FINVANT/API/Backend/Scripts/GatherLTP.py", line 71, in start', '    self.kws.on_ticks = self.on_ticks', "AttributeError: 'NoneType' object has no attribute 'on_ticks'"]
root - INFO - 2023-04-12 12:48:10.291130 - Finvant Alcubierre Mk1 OMS Backend turned on.
root - INFO - 2023-04-12 12:48:10.386045 - OMS Backend mainloop started.
root - INFO - 2023-04-12 12:48:10.545370 - OMSB: Logging in for backend kite ticker.
root - CRITICAL - CRITICAL ERROR:2023-04-12 12:48:23.104366 - OMSB: Failed auto login to kite ticker.
['Traceback (most recent call last):', '  File "/Users/vishaljha/Desktop/FINVANT/API/Backend/Scripts/AutoLoginKiteTicker.py", line 126, in auto_login_zerodha_ticker', '    data = kite.generate_session(key, api_secret=api_secret)', '  File "/Users/vishaljha/anaconda3/lib/python3.8/site-packages/kiteconnect/connect.py", line 255, in generate_session', '    h = hashlib.sha256(self.api_key.encode("utf-8") + request_token.encode("utf-8") + api_secret.encode("utf-8"))', "AttributeError: 'int' object has no attribute 'encode'"]
root - CRITICAL - CRITICAL ERROR:2023-04-12 12:48:23.419128 - Failed to start KWS thread.
['Traceback (most recent call last):', '  File "/Users/vishaljha/Desktop/FINVANT/API/Backend/Scripts/GatherLTP.py", line 71, in start', '    self.kws.on_ticks = self.on_ticks', "AttributeError: 'NoneType' object has no attribute 'on_ticks'"]
root - INFO - 2023-04-12 12:49:56.045848 - Finvant Alcubierre Mk1 OMS Backend turned on.
root - INFO - 2023-04-12 12:49:56.128339 - OMS Backend mainloop started.
root - INFO - 2023-04-12 12:49:56.244995 - OMSB: Logging in for backend kite ticker.
root - CRITICAL - CRITICAL ERROR:2023-04-12 12:50:08.725400 - OMSB: Failed auto login to kite ticker.
['Traceback (most recent call last):', '  File "/Users/vishaljha/Desktop/FINVANT/API/Backend/Scripts/AutoLoginKiteTicker.py", line 126, in auto_login_zerodha_ticker', '    data = kite.generate_session(key, api_secret=api_secret)', '  File "/Users/vishaljha/anaconda3/lib/python3.8/site-packages/kiteconnect/connect.py", line 255, in generate_session', '    h = hashlib.sha256(self.api_key.encode("utf-8") + request_token.encode("utf-8") + api_secret.encode("utf-8"))', "AttributeError: 'int' object has no attribute 'encode'"]
root - CRITICAL - CRITICAL ERROR:2023-04-12 12:50:09.085481 - Failed to start KWS thread.
['Traceback (most recent call last):', '  File "/Users/vishaljha/Desktop/FINVANT/API/Backend/Scripts/GatherLTP.py", line 71, in start', '    self.kws.on_ticks = self.on_ticks', "AttributeError: 'NoneType' object has no attribute 'on_ticks'"]
