root - INFO - 2023-02-13 11:04:02.976501 - Finvant Alcubierre Mk1 OMS Backend turned on.
root - INFO - 2023-02-13 11:04:03.103753 - OMS Backend mainloop started.
root - INFO - 2023-02-13 11:04:03.286713 - OMSB: Logging in for backend kite ticker.
root - CRITICAL - CRITICAL ERROR:2023-02-13 11:04:07.135518 - OMSB: Failed auto login to kite ticker.
['Traceback (most recent call last):', '  File "/Users/vishaljha/anaconda3/lib/python3.8/site-packages/urllib3/connectionpool.py", line 379, in _make_request', '    httplib_response = conn.getresponse(buffering=True)', "TypeError: getresponse() got an unexpected keyword argument 'buffering'", '', 'During handling of the above exception, another exception occurred:', '', 'Traceback (most recent call last):', '  File "/Users/vishaljha/Desktop/FINVANT/API/Backend/Scripts/AutoLoginKiteTicker.py", line 37, in automate_login', '    browser.get(browser_url)', '  File "/Users/vishaljha/anaconda3/lib/python3.8/site-packages/selenium/webdriver/remote/webdriver.py", line 333, in get', "    self.execute(Command.GET, {'url': url})", '  File "/Users/vishaljha/anaconda3/lib/python3.8/site-packages/selenium/webdriver/remote/webdriver.py", line 319, in execute', '    response = self.command_executor.execute(driver_command, params)', '  File "/Users/vishaljha/anaconda3/lib/python3.8/site-packages/selenium/webdriver/remote/remote_connection.py", line 374, in execute', '    return self._request(command_info[0], url, body=data)', '  File "/Users/vishaljha/anaconda3/lib/python3.8/site-packages/selenium/webdriver/remote/remote_connection.py", line 397, in _request', '    resp = self._conn.request(method, url, body=body, headers=headers)', '  File "/Users/vishaljha/anaconda3/lib/python3.8/site-packages/urllib3/request.py", line 70, in request', '    return self.request_encode_body(method, url, fields=fields,', '  File "/Users/vishaljha/anaconda3/lib/python3.8/site-packages/urllib3/request.py", line 150, in request_encode_body', '    return self.urlopen(method, url, **extra_kw)', '  File "/Users/vishaljha/anaconda3/lib/python3.8/site-packages/urllib3/poolmanager.py", line 326, in urlopen', '    response = conn.urlopen(method, u.request_uri, **kw)', '  File "/Users/vishaljha/anaconda3/lib/python3.8/site-packages/urllib3/connectionpool.py", line 600, in urlopen', '    httplib_response = self._make_request(conn, method, url,', '  File "/Users/vishaljha/anaconda3/lib/python3.8/site-packages/urllib3/connectionpool.py", line 383, in _make_request', '    httplib_response = conn.getresponse()', '  File "/Users/vishaljha/anaconda3/lib/python3.8/http/client.py", line 1332, in getresponse', '    response.begin()', '  File "/Users/vishaljha/anaconda3/lib/python3.8/http/client.py", line 303, in begin', '    version, status, reason = self._read_status()', '  File "/Users/vishaljha/anaconda3/lib/python3.8/http/client.py", line 264, in _read_status', '    line = str(self.fp.readline(_MAXLINE + 1), "iso-8859-1")', '  File "/Users/vishaljha/anaconda3/lib/python3.8/socket.py", line 669, in readinto', '    return self._sock.recv_into(b)', 'KeyboardInterrupt', '', 'During handling of the above exception, another exception occurred:', '', 'Traceback (most recent call last):', '  File "/Users/vishaljha/anaconda3/lib/python3.8/site-packages/selenium/webdriver/common/service.py", line 72, in start', '    self.process = subprocess.Popen(cmd, env=self.env,', '  File "/Users/vishaljha/anaconda3/lib/python3.8/subprocess.py", line 854, in __init__', '    self._execute_child(args, executable, preexec_fn, close_fds,', '  File "/Users/vishaljha/anaconda3/lib/python3.8/subprocess.py", line 1702, in _execute_child', '    raise child_exception_type(errno_num, err_msg, err_filename)', "FileNotFoundError: [Errno 2] No such file or directory: 'chromedriver'", '', 'During handling of the above exception, another exception occurred:', '', 'Traceback (most recent call last):', '  File "/Users/vishaljha/Desktop/FINVANT/API/Backend/Scripts/AutoLoginKiteTicker.py", line 124, in auto_login_zerodha_ticker', '    key = automate_login(browser_url, user_id, password, totp_pin, debug=debug)', '  File "/Users/vishaljha/Desktop/FINVANT/API/Backend/Scripts/AutoLoginKiteTicker.py", line 40, in automate_login', '    browser = webdriver.Chrome(options = options)', '  File "/Users/vishaljha/anaconda3/lib/python3.8/site-packages/selenium/webdriver/chrome/webdriver.py", line 73, in __init__', '    self.service.start()', '  File "/Users/vishaljha/anaconda3/lib/python3.8/site-packages/selenium/webdriver/common/service.py", line 81, in start', '    raise WebDriverException(', "selenium.common.exceptions.WebDriverException: Message: 'chromedriver' executable needs to be in PATH. Please see https://sites.google.com/a/chromium.org/chromedriver/home", '']
root - CRITICAL - CRITICAL ERROR:2023-02-13 11:04:07.254046 - Failed to start LTP thread.
['Traceback (most recent call last):', '  File "/Users/vishaljha/anaconda3/lib/python3.8/site-packages/urllib3/connectionpool.py", line 379, in _make_request', '    httplib_response = conn.getresponse(buffering=True)', "TypeError: getresponse() got an unexpected keyword argument 'buffering'", '', 'During handling of the above exception, another exception occurred:', '', 'Traceback (most recent call last):', '  File "/Users/vishaljha/Desktop/FINVANT/API/Backend/Scripts/AutoLoginKiteTicker.py", line 37, in automate_login', '    browser.get(browser_url)', '  File "/Users/vishaljha/anaconda3/lib/python3.8/site-packages/selenium/webdriver/remote/webdriver.py", line 333, in get', "    self.execute(Command.GET, {'url': url})", '  File "/Users/vishaljha/anaconda3/lib/python3.8/site-packages/selenium/webdriver/remote/webdriver.py", line 319, in execute', '    response = self.command_executor.execute(driver_command, params)', '  File "/Users/vishaljha/anaconda3/lib/python3.8/site-packages/selenium/webdriver/remote/remote_connection.py", line 374, in execute', '    return self._request(command_info[0], url, body=data)', '  File "/Users/vishaljha/anaconda3/lib/python3.8/site-packages/selenium/webdriver/remote/remote_connection.py", line 397, in _request', '    resp = self._conn.request(method, url, body=body, headers=headers)', '  File "/Users/vishaljha/anaconda3/lib/python3.8/site-packages/urllib3/request.py", line 70, in request', '    return self.request_encode_body(method, url, fields=fields,', '  File "/Users/vishaljha/anaconda3/lib/python3.8/site-packages/urllib3/request.py", line 150, in request_encode_body', '    return self.urlopen(method, url, **extra_kw)', '  File "/Users/vishaljha/anaconda3/lib/python3.8/site-packages/urllib3/poolmanager.py", line 326, in urlopen', '    response = conn.urlopen(method, u.request_uri, **kw)', '  File "/Users/vishaljha/anaconda3/lib/python3.8/site-packages/urllib3/connectionpool.py", line 600, in urlopen', '    httplib_response = self._make_request(conn, method, url,', '  File "/Users/vishaljha/anaconda3/lib/python3.8/site-packages/urllib3/connectionpool.py", line 383, in _make_request', '    httplib_response = conn.getresponse()', '  File "/Users/vishaljha/anaconda3/lib/python3.8/http/client.py", line 1332, in getresponse', '    response.begin()', '  File "/Users/vishaljha/anaconda3/lib/python3.8/http/client.py", line 303, in begin', '    version, status, reason = self._read_status()', '  File "/Users/vishaljha/anaconda3/lib/python3.8/http/client.py", line 264, in _read_status', '    line = str(self.fp.readline(_MAXLINE + 1), "iso-8859-1")', '  File "/Users/vishaljha/anaconda3/lib/python3.8/socket.py", line 669, in readinto', '    return self._sock.recv_into(b)', 'KeyboardInterrupt', '', 'During handling of the above exception, another exception occurred:', '', 'Traceback (most recent call last):', '  File "/Users/vishaljha/anaconda3/lib/python3.8/site-packages/selenium/webdriver/common/service.py", line 72, in start', '    self.process = subprocess.Popen(cmd, env=self.env,', '  File "/Users/vishaljha/anaconda3/lib/python3.8/subprocess.py", line 854, in __init__', '    self._execute_child(args, executable, preexec_fn, close_fds,', '  File "/Users/vishaljha/anaconda3/lib/python3.8/subprocess.py", line 1702, in _execute_child', '    raise child_exception_type(errno_num, err_msg, err_filename)', "FileNotFoundError: [Errno 2] No such file or directory: 'chromedriver'", '', 'During handling of the above exception, another exception occurred:', '', 'Traceback (most recent call last):', '  File "/Users/vishaljha/Desktop/FINVANT/API/Backend/Scripts/AutoLoginKiteTicker.py", line 124, in auto_login_zerodha_ticker', '    key = automate_login(browser_url, user_id, password, totp_pin, debug=debug)', '  File "/Users/vishaljha/Desktop/FINVANT/API/Backend/Scripts/AutoLoginKiteTicker.py", line 40, in automate_login', '    browser = webdriver.Chrome(options = options)', '  File "/Users/vishaljha/anaconda3/lib/python3.8/site-packages/selenium/webdriver/chrome/webdriver.py", line 73, in __init__', '    self.service.start()', '  File "/Users/vishaljha/anaconda3/lib/python3.8/site-packages/selenium/webdriver/common/service.py", line 81, in start', '    raise WebDriverException(', "selenium.common.exceptions.WebDriverException: Message: 'chromedriver' executable needs to be in PATH. Please see https://sites.google.com/a/chromium.org/chromedriver/home", '', '', 'During handling of the above exception, another exception occurred:', '', 'Traceback (most recent call last):', '  File "/Users/vishaljha/anaconda3/lib/python3.8/site-packages/urllib3/connectionpool.py", line 379, in _make_request', '    httplib_response = conn.getresponse(buffering=True)', "TypeError: getresponse() got an unexpected keyword argument 'buffering'", '', 'During handling of the above exception, another exception occurred:', '', 'Traceback (most recent call last):', '  File "Main.py", line 63, in main_loop', '    kite_ticker = auto_login_zerodha_ticker(config=config,log_interface=self.log_interface, debug=self.DEBUG)', '  File "/Users/vishaljha/Desktop/FINVANT/API/Backend/Scripts/AutoLoginKiteTicker.py", line 131, in auto_login_zerodha_ticker', '    log_interface.postLog(severity="CRITICAL",message=\'OMSB: Failed auto login to kite ticker.\',publish = 1, tag = \'OMSB_AuLoB_1\')', '  File "/Users/vishaljha/Desktop/FINVANT/API/Backend/Scripts/Log_Server_Interface.py", line 55, in postLog', "    response = requests.post(self.url + 'post/log', headers=headers, json=json_compatible_item_data)", '  File "/Users/vishaljha/anaconda3/lib/python3.8/site-packages/requests/api.py", line 116, in post', "    return request('post', url, data=data, json=json, **kwargs)", '  File "/Users/vishaljha/anaconda3/lib/python3.8/site-packages/requests/api.py", line 60, in request', '    return session.request(method=method, url=url, **kwargs)', '  File "/Users/vishaljha/anaconda3/lib/python3.8/site-packages/requests/sessions.py", line 533, in request', '    resp = self.send(prep, **send_kwargs)', '  File "/Users/vishaljha/anaconda3/lib/python3.8/site-packages/requests/sessions.py", line 646, in send', '    r = adapter.send(request, **kwargs)', '  File "/Users/vishaljha/anaconda3/lib/python3.8/site-packages/requests/adapters.py", line 439, in send', '    resp = conn.urlopen(', '  File "/Users/vishaljha/anaconda3/lib/python3.8/site-packages/urllib3/connectionpool.py", line 600, in urlopen', '    httplib_response = self._make_request(conn, method, url,', '  File "/Users/vishaljha/anaconda3/lib/python3.8/site-packages/urllib3/connectionpool.py", line 383, in _make_request', '    httplib_response = conn.getresponse()', '  File "/Users/vishaljha/anaconda3/lib/python3.8/http/client.py", line 1332, in getresponse', '    response.begin()', '  File "/Users/vishaljha/anaconda3/lib/python3.8/http/client.py", line 303, in begin', '    version, status, reason = self._read_status()', '  File "/Users/vishaljha/anaconda3/lib/python3.8/http/client.py", line 264, in _read_status', '    line = str(self.fp.readline(_MAXLINE + 1), "iso-8859-1")', '  File "/Users/vishaljha/anaconda3/lib/python3.8/socket.py", line 669, in readinto', '    return self._sock.recv_into(b)', 'KeyboardInterrupt']
root - INFO - 2023-02-13 11:04:07.404118 - OMSB: Zerodha login for WG5235.
root - CRITICAL - CRITICAL ERROR:2023-02-13 11:04:07.423055 - Failed to generate user dictionary.
['Traceback (most recent call last):', '  File "Main.py", line 71, in main_loop', '    user_dict = UserProfileGenerator().create_user_profiles(user_data=user_data, log_interface=self.log_interface, debug=self.DEBUG)', '  File "/Users/vishaljha/Desktop/FINVANT/API/Backend/Scripts/UserProfileGenerator.py", line 64, in create_user_profiles', '    t.join()', '  File "/Users/vishaljha/anaconda3/lib/python3.8/threading.py", line 1011, in join', '    self._wait_for_tstate_lock()', '  File "/Users/vishaljha/anaconda3/lib/python3.8/threading.py", line 1027, in _wait_for_tstate_lock', '    elif lock.acquire(block, timeout):', 'KeyboardInterrupt']
root - CRITICAL - CRITICAL ERROR:2023-02-13 11:04:07.583625 - Failed to initialise Log server/ADS.
['Traceback (most recent call last):', '  File "Main.py", line 71, in main_loop', '    user_dict = UserProfileGenerator().create_user_profiles(user_data=user_data, log_interface=self.log_interface, debug=self.DEBUG)', '  File "/Users/vishaljha/Desktop/FINVANT/API/Backend/Scripts/UserProfileGenerator.py", line 64, in create_user_profiles', '    t.join()', '  File "/Users/vishaljha/anaconda3/lib/python3.8/threading.py", line 1011, in join', '    self._wait_for_tstate_lock()', '  File "/Users/vishaljha/anaconda3/lib/python3.8/threading.py", line 1027, in _wait_for_tstate_lock', '    elif lock.acquire(block, timeout):', 'KeyboardInterrupt', '', 'During handling of the above exception, another exception occurred:', '', 'Traceback (most recent call last):', '  File "/Users/vishaljha/anaconda3/lib/python3.8/site-packages/urllib3/connectionpool.py", line 379, in _make_request', '    httplib_response = conn.getresponse(buffering=True)', "TypeError: getresponse() got an unexpected keyword argument 'buffering'", '', 'During handling of the above exception, another exception occurred:', '', 'Traceback (most recent call last):', '  File "Main.py", line 35, in __init__', '    self.start()', '  File "Main.py", line 43, in start', '    self.main_loop()', '  File "Main.py", line 73, in main_loop', '    self.log_interface.postLog(severity="CRITICAL",message=\'Failed to generate user dictionary.\',publish = 1, tag = \'OMSB_MAIN_4\')', '  File "/Users/vishaljha/Desktop/FINVANT/API/Backend/Scripts/Log_Server_Interface.py", line 55, in postLog', "    response = requests.post(self.url + 'post/log', headers=headers, json=json_compatible_item_data)", '  File "/Users/vishaljha/anaconda3/lib/python3.8/site-packages/requests/api.py", line 116, in post', "    return request('post', url, data=data, json=json, **kwargs)", '  File "/Users/vishaljha/anaconda3/lib/python3.8/site-packages/requests/api.py", line 60, in request', '    return session.request(method=method, url=url, **kwargs)', '  File "/Users/vishaljha/anaconda3/lib/python3.8/site-packages/requests/sessions.py", line 533, in request', '    resp = self.send(prep, **send_kwargs)', '  File "/Users/vishaljha/anaconda3/lib/python3.8/site-packages/requests/sessions.py", line 646, in send', '    r = adapter.send(request, **kwargs)', '  File "/Users/vishaljha/anaconda3/lib/python3.8/site-packages/requests/adapters.py", line 439, in send', '    resp = conn.urlopen(', '  File "/Users/vishaljha/anaconda3/lib/python3.8/site-packages/urllib3/connectionpool.py", line 600, in urlopen', '    httplib_response = self._make_request(conn, method, url,', '  File "/Users/vishaljha/anaconda3/lib/python3.8/site-packages/urllib3/connectionpool.py", line 383, in _make_request', '    httplib_response = conn.getresponse()', '  File "/Users/vishaljha/anaconda3/lib/python3.8/http/client.py", line 1332, in getresponse', '    response.begin()', '  File "/Users/vishaljha/anaconda3/lib/python3.8/http/client.py", line 303, in begin', '    version, status, reason = self._read_status()', '  File "/Users/vishaljha/anaconda3/lib/python3.8/http/client.py", line 264, in _read_status', '    line = str(self.fp.readline(_MAXLINE + 1), "iso-8859-1")', '  File "/Users/vishaljha/anaconda3/lib/python3.8/socket.py", line 669, in readinto', '    return self._sock.recv_into(b)', 'KeyboardInterrupt']
