root - INFO - 2023-03-28 23:40:07.618045 - Finvant Alcubierre Mk1 OMS Backend turned on.
root - INFO - 2023-03-28 23:40:07.744867 - OMS Backend mainloop started.
root - INFO - 2023-03-28 23:40:07.924046 - OMSB: Logging in for backend kite ticker.
root - CRITICAL - CRITICAL ERROR:2023-03-28 23:40:08.063725 - OMSB: Failed auto login to kite ticker.
['Traceback (most recent call last):', '  File "/Users/vishaljha/Desktop/FINVANT/API/Backend/Scripts/AutoLoginKiteTicker.py", line 36, in automate_login', "    browser = webdriver.Chrome(options = options,executable_path='../Chrome/chromedriver')", '  File "/Users/vishaljha/anaconda3/lib/python3.8/site-packages/selenium/webdriver/chrome/webdriver.py", line 73, in __init__', '    self.service.start()', '  File "/Users/vishaljha/anaconda3/lib/python3.8/site-packages/selenium/webdriver/common/service.py", line 72, in start', '    self.process = subprocess.Popen(cmd, env=self.env,', '  File "/Users/vishaljha/anaconda3/lib/python3.8/subprocess.py", line 854, in __init__', '    self._execute_child(args, executable, preexec_fn, close_fds,', '  File "/Users/vishaljha/anaconda3/lib/python3.8/subprocess.py", line 1702, in _execute_child', '    raise child_exception_type(errno_num, err_msg, err_filename)', "OSError: [Errno 86] Bad CPU type in executable: '../Chrome/chromedriver'", '', 'During handling of the above exception, another exception occurred:', '', 'Traceback (most recent call last):', '  File "/Users/vishaljha/anaconda3/lib/python3.8/site-packages/selenium/webdriver/common/service.py", line 72, in start', '    self.process = subprocess.Popen(cmd, env=self.env,', '  File "/Users/vishaljha/anaconda3/lib/python3.8/subprocess.py", line 854, in __init__', '    self._execute_child(args, executable, preexec_fn, close_fds,', '  File "/Users/vishaljha/anaconda3/lib/python3.8/subprocess.py", line 1702, in _execute_child', '    raise child_exception_type(errno_num, err_msg, err_filename)', "FileNotFoundError: [Errno 2] No such file or directory: 'chromedriver'", '', 'During handling of the above exception, another exception occurred:', '', 'Traceback (most recent call last):', '  File "/Users/vishaljha/Desktop/FINVANT/API/Backend/Scripts/AutoLoginKiteTicker.py", line 124, in auto_login_zerodha_ticker', '    key = automate_login(browser_url, user_id, password, totp_pin, debug=debug)', '  File "/Users/vishaljha/Desktop/FINVANT/API/Backend/Scripts/AutoLoginKiteTicker.py", line 40, in automate_login', '    browser = webdriver.Chrome(options = options)', '  File "/Users/vishaljha/anaconda3/lib/python3.8/site-packages/selenium/webdriver/chrome/webdriver.py", line 73, in __init__', '    self.service.start()', '  File "/Users/vishaljha/anaconda3/lib/python3.8/site-packages/selenium/webdriver/common/service.py", line 81, in start', '    raise WebDriverException(', "selenium.common.exceptions.WebDriverException: Message: 'chromedriver' executable needs to be in PATH. Please see https://sites.google.com/a/chromium.org/chromedriver/home", '']
root - INFO - 2023-03-28 23:40:08.455449 - OMSB: Zerodha login for WG5235.
root - CRITICAL - CRITICAL ERROR:2023-03-28 23:40:08.456288 - Failed to start KWS thread.
['Traceback (most recent call last):', '  File "/Users/vishaljha/Desktop/FINVANT/API/Backend/Scripts/GatherLTP.py", line 71, in start', '    self.kws.on_ticks = self.on_ticks', "AttributeError: 'NoneType' object has no attribute 'on_ticks'"]
root - CRITICAL - CRITICAL ERROR:2023-03-28 23:40:08.592925 - OMSB: Failed auto login to kite for user:WG5235.
['Traceback (most recent call last):', '  File "/Users/vishaljha/Desktop/FINVANT/API/Backend/Scripts/AutoLoginZerodha.py", line 36, in automate_login', "    browser = webdriver.Chrome(options = options,executable_path='../Chrome/chromedriver')", '  File "/Users/vishaljha/anaconda3/lib/python3.8/site-packages/selenium/webdriver/chrome/webdriver.py", line 73, in __init__', '    self.service.start()', '  File "/Users/vishaljha/anaconda3/lib/python3.8/site-packages/selenium/webdriver/common/service.py", line 72, in start', '    self.process = subprocess.Popen(cmd, env=self.env,', '  File "/Users/vishaljha/anaconda3/lib/python3.8/subprocess.py", line 854, in __init__', '    self._execute_child(args, executable, preexec_fn, close_fds,', '  File "/Users/vishaljha/anaconda3/lib/python3.8/subprocess.py", line 1702, in _execute_child', '    raise child_exception_type(errno_num, err_msg, err_filename)', "OSError: [Errno 86] Bad CPU type in executable: '../Chrome/chromedriver'", '', 'During handling of the above exception, another exception occurred:', '', 'Traceback (most recent call last):', '  File "/Users/vishaljha/anaconda3/lib/python3.8/site-packages/selenium/webdriver/common/service.py", line 72, in start', '    self.process = subprocess.Popen(cmd, env=self.env,', '  File "/Users/vishaljha/anaconda3/lib/python3.8/subprocess.py", line 854, in __init__', '    self._execute_child(args, executable, preexec_fn, close_fds,', '  File "/Users/vishaljha/anaconda3/lib/python3.8/subprocess.py", line 1702, in _execute_child', '    raise child_exception_type(errno_num, err_msg, err_filename)', "FileNotFoundError: [Errno 2] No such file or directory: 'chromedriver'", '', 'During handling of the above exception, another exception occurred:', '', 'Traceback (most recent call last):', '  File "/Users/vishaljha/Desktop/FINVANT/API/Backend/Scripts/AutoLoginZerodha.py", line 117, in auto_login_zerodha', '    key = automate_login(browser_url, user_id, password, totp_pin)', '  File "/Users/vishaljha/Desktop/FINVANT/API/Backend/Scripts/AutoLoginZerodha.py", line 40, in automate_login', '    browser = webdriver.Chrome(options = options)', '  File "/Users/vishaljha/anaconda3/lib/python3.8/site-packages/selenium/webdriver/chrome/webdriver.py", line 73, in __init__', '    self.service.start()', '  File "/Users/vishaljha/anaconda3/lib/python3.8/site-packages/selenium/webdriver/common/service.py", line 81, in start', '    raise WebDriverException(', "selenium.common.exceptions.WebDriverException: Message: 'chromedriver' executable needs to be in PATH. Please see https://sites.google.com/a/chromium.org/chromedriver/home", '']
root - INFO - 2023-03-28 23:40:23.889680 - Finvant Alcubierre Mk1 OMS Backend turned on.
root - INFO - 2023-03-28 23:40:24.016430 - OMS Backend mainloop started.
root - INFO - 2023-03-28 23:40:24.187826 - OMSB: Logging in for backend kite ticker.
root - CRITICAL - CRITICAL ERROR:2023-03-28 23:40:24.324396 - OMSB: Failed auto login to kite ticker.
['Traceback (most recent call last):', '  File "/Users/vishaljha/Desktop/FINVANT/API/Backend/Scripts/AutoLoginKiteTicker.py", line 36, in automate_login', "    browser = webdriver.Chrome(options = options,executable_path='../Chrome/chromedriver')", '  File "/Users/vishaljha/anaconda3/lib/python3.8/site-packages/selenium/webdriver/chrome/webdriver.py", line 73, in __init__', '    self.service.start()', '  File "/Users/vishaljha/anaconda3/lib/python3.8/site-packages/selenium/webdriver/common/service.py", line 72, in start', '    self.process = subprocess.Popen(cmd, env=self.env,', '  File "/Users/vishaljha/anaconda3/lib/python3.8/subprocess.py", line 854, in __init__', '    self._execute_child(args, executable, preexec_fn, close_fds,', '  File "/Users/vishaljha/anaconda3/lib/python3.8/subprocess.py", line 1702, in _execute_child', '    raise child_exception_type(errno_num, err_msg, err_filename)', "OSError: [Errno 86] Bad CPU type in executable: '../Chrome/chromedriver'", '', 'During handling of the above exception, another exception occurred:', '', 'Traceback (most recent call last):', '  File "/Users/vishaljha/anaconda3/lib/python3.8/site-packages/selenium/webdriver/common/service.py", line 72, in start', '    self.process = subprocess.Popen(cmd, env=self.env,', '  File "/Users/vishaljha/anaconda3/lib/python3.8/subprocess.py", line 854, in __init__', '    self._execute_child(args, executable, preexec_fn, close_fds,', '  File "/Users/vishaljha/anaconda3/lib/python3.8/subprocess.py", line 1702, in _execute_child', '    raise child_exception_type(errno_num, err_msg, err_filename)', "FileNotFoundError: [Errno 2] No such file or directory: 'chromedriver'", '', 'During handling of the above exception, another exception occurred:', '', 'Traceback (most recent call last):', '  File "/Users/vishaljha/Desktop/FINVANT/API/Backend/Scripts/AutoLoginKiteTicker.py", line 124, in auto_login_zerodha_ticker', '    key = automate_login(browser_url, user_id, password, totp_pin, debug=debug)', '  File "/Users/vishaljha/Desktop/FINVANT/API/Backend/Scripts/AutoLoginKiteTicker.py", line 40, in automate_login', '    browser = webdriver.Chrome(options = options)', '  File "/Users/vishaljha/anaconda3/lib/python3.8/site-packages/selenium/webdriver/chrome/webdriver.py", line 73, in __init__', '    self.service.start()', '  File "/Users/vishaljha/anaconda3/lib/python3.8/site-packages/selenium/webdriver/common/service.py", line 81, in start', '    raise WebDriverException(', "selenium.common.exceptions.WebDriverException: Message: 'chromedriver' executable needs to be in PATH. Please see https://sites.google.com/a/chromium.org/chromedriver/home", '']
root - CRITICAL - CRITICAL ERROR:2023-03-28 23:40:24.701571 - Failed to start KWS thread.
['Traceback (most recent call last):', '  File "/Users/vishaljha/Desktop/FINVANT/API/Backend/Scripts/GatherLTP.py", line 71, in start', '    self.kws.on_ticks = self.on_ticks', "AttributeError: 'NoneType' object has no attribute 'on_ticks'"]
root - INFO - 2023-03-28 23:40:24.702369 - OMSB: Zerodha login for WG5235.
root - CRITICAL - CRITICAL ERROR:2023-03-28 23:40:24.899255 - OMSB: Failed auto login to kite for user:WG5235.
['Traceback (most recent call last):', '  File "/Users/vishaljha/Desktop/FINVANT/API/Backend/Scripts/AutoLoginZerodha.py", line 36, in automate_login', "    browser = webdriver.Chrome(options = options,executable_path='../Chrome/chromedriver')", '  File "/Users/vishaljha/anaconda3/lib/python3.8/site-packages/selenium/webdriver/chrome/webdriver.py", line 73, in __init__', '    self.service.start()', '  File "/Users/vishaljha/anaconda3/lib/python3.8/site-packages/selenium/webdriver/common/service.py", line 72, in start', '    self.process = subprocess.Popen(cmd, env=self.env,', '  File "/Users/vishaljha/anaconda3/lib/python3.8/subprocess.py", line 854, in __init__', '    self._execute_child(args, executable, preexec_fn, close_fds,', '  File "/Users/vishaljha/anaconda3/lib/python3.8/subprocess.py", line 1702, in _execute_child', '    raise child_exception_type(errno_num, err_msg, err_filename)', "OSError: [Errno 86] Bad CPU type in executable: '../Chrome/chromedriver'", '', 'During handling of the above exception, another exception occurred:', '', 'Traceback (most recent call last):', '  File "/Users/vishaljha/anaconda3/lib/python3.8/site-packages/selenium/webdriver/common/service.py", line 72, in start', '    self.process = subprocess.Popen(cmd, env=self.env,', '  File "/Users/vishaljha/anaconda3/lib/python3.8/subprocess.py", line 854, in __init__', '    self._execute_child(args, executable, preexec_fn, close_fds,', '  File "/Users/vishaljha/anaconda3/lib/python3.8/subprocess.py", line 1702, in _execute_child', '    raise child_exception_type(errno_num, err_msg, err_filename)', "FileNotFoundError: [Errno 2] No such file or directory: 'chromedriver'", '', 'During handling of the above exception, another exception occurred:', '', 'Traceback (most recent call last):', '  File "/Users/vishaljha/Desktop/FINVANT/API/Backend/Scripts/AutoLoginZerodha.py", line 117, in auto_login_zerodha', '    key = automate_login(browser_url, user_id, password, totp_pin)', '  File "/Users/vishaljha/Desktop/FINVANT/API/Backend/Scripts/AutoLoginZerodha.py", line 40, in automate_login', '    browser = webdriver.Chrome(options = options)', '  File "/Users/vishaljha/anaconda3/lib/python3.8/site-packages/selenium/webdriver/chrome/webdriver.py", line 73, in __init__', '    self.service.start()', '  File "/Users/vishaljha/anaconda3/lib/python3.8/site-packages/selenium/webdriver/common/service.py", line 81, in start', '    raise WebDriverException(', "selenium.common.exceptions.WebDriverException: Message: 'chromedriver' executable needs to be in PATH. Please see https://sites.google.com/a/chromium.org/chromedriver/home", '']
root - INFO - 2023-03-28 23:40:57.962649 - Finvant Alcubierre Mk1 OMS Backend turned on.
root - INFO - 2023-03-28 23:40:58.091138 - OMS Backend mainloop started.
root - INFO - 2023-03-28 23:40:58.267131 - OMSB: Logging in for backend kite ticker.
root - CRITICAL - CRITICAL ERROR:2023-03-28 23:41:05.424167 - OMSB: Failed auto login to kite ticker.
['Traceback (most recent call last):', '  File "/Users/vishaljha/Desktop/FINVANT/API/Backend/Scripts/AutoLoginKiteTicker.py", line 36, in automate_login', "    browser = webdriver.Chrome(options = options,executable_path='../Chrome/chromedriver-4')", '  File "/Users/vishaljha/anaconda3/lib/python3.8/site-packages/selenium/webdriver/chrome/webdriver.py", line 73, in __init__', '    self.service.start()', '  File "/Users/vishaljha/anaconda3/lib/python3.8/site-packages/selenium/webdriver/common/service.py", line 98, in start', '    self.assert_process_still_running()', '  File "/Users/vishaljha/anaconda3/lib/python3.8/site-packages/selenium/webdriver/common/service.py", line 109, in assert_process_still_running', '    raise WebDriverException(', 'selenium.common.exceptions.WebDriverException: Message: Service ../Chrome/chromedriver-4 unexpectedly exited. Status code was: -9', '', '', 'During handling of the above exception, another exception occurred:', '', 'Traceback (most recent call last):', '  File "/Users/vishaljha/anaconda3/lib/python3.8/site-packages/selenium/webdriver/common/service.py", line 72, in start', '    self.process = subprocess.Popen(cmd, env=self.env,', '  File "/Users/vishaljha/anaconda3/lib/python3.8/subprocess.py", line 854, in __init__', '    self._execute_child(args, executable, preexec_fn, close_fds,', '  File "/Users/vishaljha/anaconda3/lib/python3.8/subprocess.py", line 1702, in _execute_child', '    raise child_exception_type(errno_num, err_msg, err_filename)', "FileNotFoundError: [Errno 2] No such file or directory: 'chromedriver'", '', 'During handling of the above exception, another exception occurred:', '', 'Traceback (most recent call last):', '  File "/Users/vishaljha/Desktop/FINVANT/API/Backend/Scripts/AutoLoginKiteTicker.py", line 124, in auto_login_zerodha_ticker', '    key = automate_login(browser_url, user_id, password, totp_pin, debug=debug)', '  File "/Users/vishaljha/Desktop/FINVANT/API/Backend/Scripts/AutoLoginKiteTicker.py", line 40, in automate_login', '    browser = webdriver.Chrome(options = options)', '  File "/Users/vishaljha/anaconda3/lib/python3.8/site-packages/selenium/webdriver/chrome/webdriver.py", line 73, in __init__', '    self.service.start()', '  File "/Users/vishaljha/anaconda3/lib/python3.8/site-packages/selenium/webdriver/common/service.py", line 81, in start', '    raise WebDriverException(', "selenium.common.exceptions.WebDriverException: Message: 'chromedriver' executable needs to be in PATH. Please see https://sites.google.com/a/chromium.org/chromedriver/home", '']
root - INFO - 2023-03-28 23:41:05.914233 - OMSB: Zerodha login for WG5235.
root - CRITICAL - CRITICAL ERROR:2023-03-28 23:41:05.914443 - Failed to start KWS thread.
['Traceback (most recent call last):', '  File "/Users/vishaljha/Desktop/FINVANT/API/Backend/Scripts/GatherLTP.py", line 71, in start', '    self.kws.on_ticks = self.on_ticks', "AttributeError: 'NoneType' object has no attribute 'on_ticks'"]
root - CRITICAL - CRITICAL ERROR:2023-03-28 23:41:11.132606 - OMSB: Failed auto login to kite for user:WG5235.
['Traceback (most recent call last):', '  File "/Users/vishaljha/Desktop/FINVANT/API/Backend/Scripts/AutoLoginZerodha.py", line 36, in automate_login', "    browser = webdriver.Chrome(options = options,executable_path='../Chrome/chromedriver-4')", '  File "/Users/vishaljha/anaconda3/lib/python3.8/site-packages/selenium/webdriver/chrome/webdriver.py", line 73, in __init__', '    self.service.start()', '  File "/Users/vishaljha/anaconda3/lib/python3.8/site-packages/selenium/webdriver/common/service.py", line 98, in start', '    self.assert_process_still_running()', '  File "/Users/vishaljha/anaconda3/lib/python3.8/site-packages/selenium/webdriver/common/service.py", line 109, in assert_process_still_running', '    raise WebDriverException(', 'selenium.common.exceptions.WebDriverException: Message: Service ../Chrome/chromedriver-4 unexpectedly exited. Status code was: -9', '', '', 'During handling of the above exception, another exception occurred:', '', 'Traceback (most recent call last):', '  File "/Users/vishaljha/anaconda3/lib/python3.8/site-packages/selenium/webdriver/common/service.py", line 72, in start', '    self.process = subprocess.Popen(cmd, env=self.env,', '  File "/Users/vishaljha/anaconda3/lib/python3.8/subprocess.py", line 854, in __init__', '    self._execute_child(args, executable, preexec_fn, close_fds,', '  File "/Users/vishaljha/anaconda3/lib/python3.8/subprocess.py", line 1702, in _execute_child', '    raise child_exception_type(errno_num, err_msg, err_filename)', "FileNotFoundError: [Errno 2] No such file or directory: 'chromedriver'", '', 'During handling of the above exception, another exception occurred:', '', 'Traceback (most recent call last):', '  File "/Users/vishaljha/Desktop/FINVANT/API/Backend/Scripts/AutoLoginZerodha.py", line 117, in auto_login_zerodha', '    key = automate_login(browser_url, user_id, password, totp_pin)', '  File "/Users/vishaljha/Desktop/FINVANT/API/Backend/Scripts/AutoLoginZerodha.py", line 40, in automate_login', '    browser = webdriver.Chrome(options = options)', '  File "/Users/vishaljha/anaconda3/lib/python3.8/site-packages/selenium/webdriver/chrome/webdriver.py", line 73, in __init__', '    self.service.start()', '  File "/Users/vishaljha/anaconda3/lib/python3.8/site-packages/selenium/webdriver/common/service.py", line 81, in start', '    raise WebDriverException(', "selenium.common.exceptions.WebDriverException: Message: 'chromedriver' executable needs to be in PATH. Please see https://sites.google.com/a/chromium.org/chromedriver/home", '']
root - INFO - 2023-03-28 23:42:00.832756 - Finvant Alcubierre Mk1 OMS Backend turned on.
root - INFO - 2023-03-28 23:42:00.963779 - OMS Backend mainloop started.
root - INFO - 2023-03-28 23:42:01.140103 - OMSB: Logging in for backend kite ticker.
root - CRITICAL - CRITICAL ERROR:2023-03-28 23:42:05.403254 - OMSB: Failed auto login to kite ticker.
['Traceback (most recent call last):', '  File "/Users/vishaljha/Desktop/FINVANT/API/Backend/Scripts/AutoLoginKiteTicker.py", line 36, in automate_login', "    browser = webdriver.Chrome(options = options,executable_path='../Chrome/chromedriver-4')", '  File "/Users/vishaljha/anaconda3/lib/python3.8/site-packages/selenium/webdriver/chrome/webdriver.py", line 76, in __init__', '    RemoteWebDriver.__init__(', '  File "/Users/vishaljha/anaconda3/lib/python3.8/site-packages/selenium/webdriver/remote/webdriver.py", line 157, in __init__', '    self.start_session(capabilities, browser_profile)', '  File "/Users/vishaljha/anaconda3/lib/python3.8/site-packages/selenium/webdriver/remote/webdriver.py", line 252, in start_session', '    response = self.execute(Command.NEW_SESSION, parameters)', '  File "/Users/vishaljha/anaconda3/lib/python3.8/site-packages/selenium/webdriver/remote/webdriver.py", line 321, in execute', '    self.error_handler.check_response(response)', '  File "/Users/vishaljha/anaconda3/lib/python3.8/site-packages/selenium/webdriver/remote/errorhandler.py", line 242, in check_response', '    raise exception_class(message, screen, stacktrace)', 'selenium.common.exceptions.SessionNotCreatedException: Message: session not created: This version of ChromeDriver only supports Chrome version 108', 'Current browser version is 111.0.5563.110 with binary path /Applications/Google Chrome.app/Contents/MacOS/Google Chrome', '', '', 'During handling of the above exception, another exception occurred:', '', 'Traceback (most recent call last):', '  File "/Users/vishaljha/anaconda3/lib/python3.8/site-packages/selenium/webdriver/common/service.py", line 72, in start', '    self.process = subprocess.Popen(cmd, env=self.env,', '  File "/Users/vishaljha/anaconda3/lib/python3.8/subprocess.py", line 854, in __init__', '    self._execute_child(args, executable, preexec_fn, close_fds,', '  File "/Users/vishaljha/anaconda3/lib/python3.8/subprocess.py", line 1702, in _execute_child', '    raise child_exception_type(errno_num, err_msg, err_filename)', "FileNotFoundError: [Errno 2] No such file or directory: 'chromedriver'", '', 'During handling of the above exception, another exception occurred:', '', 'Traceback (most recent call last):', '  File "/Users/vishaljha/Desktop/FINVANT/API/Backend/Scripts/AutoLoginKiteTicker.py", line 124, in auto_login_zerodha_ticker', '    key = automate_login(browser_url, user_id, password, totp_pin, debug=debug)', '  File "/Users/vishaljha/Desktop/FINVANT/API/Backend/Scripts/AutoLoginKiteTicker.py", line 40, in automate_login', '    browser = webdriver.Chrome(options = options)', '  File "/Users/vishaljha/anaconda3/lib/python3.8/site-packages/selenium/webdriver/chrome/webdriver.py", line 73, in __init__', '    self.service.start()', '  File "/Users/vishaljha/anaconda3/lib/python3.8/site-packages/selenium/webdriver/common/service.py", line 81, in start', '    raise WebDriverException(', "selenium.common.exceptions.WebDriverException: Message: 'chromedriver' executable needs to be in PATH. Please see https://sites.google.com/a/chromium.org/chromedriver/home", '']
root - CRITICAL - CRITICAL ERROR:2023-03-28 23:42:05.773262 - Failed to start KWS thread.
['Traceback (most recent call last):', '  File "/Users/vishaljha/Desktop/FINVANT/API/Backend/Scripts/GatherLTP.py", line 71, in start', '    self.kws.on_ticks = self.on_ticks', "AttributeError: 'NoneType' object has no attribute 'on_ticks'"]
root - INFO - 2023-03-28 23:42:05.773557 - OMSB: Zerodha login for WG5235.
root - CRITICAL - CRITICAL ERROR:2023-03-28 23:42:07.178104 - OMSB: Failed auto login to kite for user:WG5235.
['Traceback (most recent call last):', '  File "/Users/vishaljha/Desktop/FINVANT/API/Backend/Scripts/AutoLoginZerodha.py", line 36, in automate_login', "    browser = webdriver.Chrome(options = options,executable_path='../Chrome/chromedriver-4')", '  File "/Users/vishaljha/anaconda3/lib/python3.8/site-packages/selenium/webdriver/chrome/webdriver.py", line 76, in __init__', '    RemoteWebDriver.__init__(', '  File "/Users/vishaljha/anaconda3/lib/python3.8/site-packages/selenium/webdriver/remote/webdriver.py", line 157, in __init__', '    self.start_session(capabilities, browser_profile)', '  File "/Users/vishaljha/anaconda3/lib/python3.8/site-packages/selenium/webdriver/remote/webdriver.py", line 252, in start_session', '    response = self.execute(Command.NEW_SESSION, parameters)', '  File "/Users/vishaljha/anaconda3/lib/python3.8/site-packages/selenium/webdriver/remote/webdriver.py", line 321, in execute', '    self.error_handler.check_response(response)', '  File "/Users/vishaljha/anaconda3/lib/python3.8/site-packages/selenium/webdriver/remote/errorhandler.py", line 242, in check_response', '    raise exception_class(message, screen, stacktrace)', 'selenium.common.exceptions.SessionNotCreatedException: Message: session not created: This version of ChromeDriver only supports Chrome version 108', 'Current browser version is 111.0.5563.110 with binary path /Applications/Google Chrome.app/Contents/MacOS/Google Chrome', '', '', 'During handling of the above exception, another exception occurred:', '', 'Traceback (most recent call last):', '  File "/Users/vishaljha/anaconda3/lib/python3.8/site-packages/selenium/webdriver/common/service.py", line 72, in start', '    self.process = subprocess.Popen(cmd, env=self.env,', '  File "/Users/vishaljha/anaconda3/lib/python3.8/subprocess.py", line 854, in __init__', '    self._execute_child(args, executable, preexec_fn, close_fds,', '  File "/Users/vishaljha/anaconda3/lib/python3.8/subprocess.py", line 1702, in _execute_child', '    raise child_exception_type(errno_num, err_msg, err_filename)', "FileNotFoundError: [Errno 2] No such file or directory: 'chromedriver'", '', 'During handling of the above exception, another exception occurred:', '', 'Traceback (most recent call last):', '  File "/Users/vishaljha/Desktop/FINVANT/API/Backend/Scripts/AutoLoginZerodha.py", line 117, in auto_login_zerodha', '    key = automate_login(browser_url, user_id, password, totp_pin)', '  File "/Users/vishaljha/Desktop/FINVANT/API/Backend/Scripts/AutoLoginZerodha.py", line 40, in automate_login', '    browser = webdriver.Chrome(options = options)', '  File "/Users/vishaljha/anaconda3/lib/python3.8/site-packages/selenium/webdriver/chrome/webdriver.py", line 73, in __init__', '    self.service.start()', '  File "/Users/vishaljha/anaconda3/lib/python3.8/site-packages/selenium/webdriver/common/service.py", line 81, in start', '    raise WebDriverException(', "selenium.common.exceptions.WebDriverException: Message: 'chromedriver' executable needs to be in PATH. Please see https://sites.google.com/a/chromium.org/chromedriver/home", '']
root - INFO - 2023-03-28 23:42:14.844185 - Finvant Alcubierre Mk1 OMS Backend turned on.
root - INFO - 2023-03-28 23:42:14.973260 - OMS Backend mainloop started.
root - INFO - 2023-03-28 23:42:15.145517 - OMSB: Logging in for backend kite ticker.
root - CRITICAL - CRITICAL ERROR:2023-03-28 23:42:16.538927 - OMSB: Failed auto login to kite ticker.
['Traceback (most recent call last):', '  File "/Users/vishaljha/Desktop/FINVANT/API/Backend/Scripts/AutoLoginKiteTicker.py", line 36, in automate_login', "    browser = webdriver.Chrome(options = options,executable_path='../Chrome/chromedriver-4')", '  File "/Users/vishaljha/anaconda3/lib/python3.8/site-packages/selenium/webdriver/chrome/webdriver.py", line 76, in __init__', '    RemoteWebDriver.__init__(', '  File "/Users/vishaljha/anaconda3/lib/python3.8/site-packages/selenium/webdriver/remote/webdriver.py", line 157, in __init__', '    self.start_session(capabilities, browser_profile)', '  File "/Users/vishaljha/anaconda3/lib/python3.8/site-packages/selenium/webdriver/remote/webdriver.py", line 252, in start_session', '    response = self.execute(Command.NEW_SESSION, parameters)', '  File "/Users/vishaljha/anaconda3/lib/python3.8/site-packages/selenium/webdriver/remote/webdriver.py", line 321, in execute', '    self.error_handler.check_response(response)', '  File "/Users/vishaljha/anaconda3/lib/python3.8/site-packages/selenium/webdriver/remote/errorhandler.py", line 242, in check_response', '    raise exception_class(message, screen, stacktrace)', 'selenium.common.exceptions.SessionNotCreatedException: Message: session not created: This version of ChromeDriver only supports Chrome version 108', 'Current browser version is 111.0.5563.110 with binary path /Applications/Google Chrome.app/Contents/MacOS/Google Chrome', '', '', 'During handling of the above exception, another exception occurred:', '', 'Traceback (most recent call last):', '  File "/Users/vishaljha/anaconda3/lib/python3.8/site-packages/selenium/webdriver/common/service.py", line 72, in start', '    self.process = subprocess.Popen(cmd, env=self.env,', '  File "/Users/vishaljha/anaconda3/lib/python3.8/subprocess.py", line 854, in __init__', '    self._execute_child(args, executable, preexec_fn, close_fds,', '  File "/Users/vishaljha/anaconda3/lib/python3.8/subprocess.py", line 1702, in _execute_child', '    raise child_exception_type(errno_num, err_msg, err_filename)', "FileNotFoundError: [Errno 2] No such file or directory: 'chromedriver'", '', 'During handling of the above exception, another exception occurred:', '', 'Traceback (most recent call last):', '  File "/Users/vishaljha/Desktop/FINVANT/API/Backend/Scripts/AutoLoginKiteTicker.py", line 124, in auto_login_zerodha_ticker', '    key = automate_login(browser_url, user_id, password, totp_pin, debug=debug)', '  File "/Users/vishaljha/Desktop/FINVANT/API/Backend/Scripts/AutoLoginKiteTicker.py", line 40, in automate_login', '    browser = webdriver.Chrome(options = options)', '  File "/Users/vishaljha/anaconda3/lib/python3.8/site-packages/selenium/webdriver/chrome/webdriver.py", line 73, in __init__', '    self.service.start()', '  File "/Users/vishaljha/anaconda3/lib/python3.8/site-packages/selenium/webdriver/common/service.py", line 81, in start', '    raise WebDriverException(', "selenium.common.exceptions.WebDriverException: Message: 'chromedriver' executable needs to be in PATH. Please see https://sites.google.com/a/chromium.org/chromedriver/home", '']
root - INFO - 2023-03-28 23:42:16.901023 - OMSB: Zerodha login for WG5235.
root - CRITICAL - CRITICAL ERROR:2023-03-28 23:42:16.901227 - Failed to start KWS thread.
['Traceback (most recent call last):', '  File "/Users/vishaljha/Desktop/FINVANT/API/Backend/Scripts/GatherLTP.py", line 71, in start', '    self.kws.on_ticks = self.on_ticks', "AttributeError: 'NoneType' object has no attribute 'on_ticks'"]
root - CRITICAL - CRITICAL ERROR:2023-03-28 23:42:18.288989 - OMSB: Failed auto login to kite for user:WG5235.
['Traceback (most recent call last):', '  File "/Users/vishaljha/Desktop/FINVANT/API/Backend/Scripts/AutoLoginZerodha.py", line 36, in automate_login', "    browser = webdriver.Chrome(options = options,executable_path='../Chrome/chromedriver-4')", '  File "/Users/vishaljha/anaconda3/lib/python3.8/site-packages/selenium/webdriver/chrome/webdriver.py", line 76, in __init__', '    RemoteWebDriver.__init__(', '  File "/Users/vishaljha/anaconda3/lib/python3.8/site-packages/selenium/webdriver/remote/webdriver.py", line 157, in __init__', '    self.start_session(capabilities, browser_profile)', '  File "/Users/vishaljha/anaconda3/lib/python3.8/site-packages/selenium/webdriver/remote/webdriver.py", line 252, in start_session', '    response = self.execute(Command.NEW_SESSION, parameters)', '  File "/Users/vishaljha/anaconda3/lib/python3.8/site-packages/selenium/webdriver/remote/webdriver.py", line 321, in execute', '    self.error_handler.check_response(response)', '  File "/Users/vishaljha/anaconda3/lib/python3.8/site-packages/selenium/webdriver/remote/errorhandler.py", line 242, in check_response', '    raise exception_class(message, screen, stacktrace)', 'selenium.common.exceptions.SessionNotCreatedException: Message: session not created: This version of ChromeDriver only supports Chrome version 108', 'Current browser version is 111.0.5563.110 with binary path /Applications/Google Chrome.app/Contents/MacOS/Google Chrome', '', '', 'During handling of the above exception, another exception occurred:', '', 'Traceback (most recent call last):', '  File "/Users/vishaljha/anaconda3/lib/python3.8/site-packages/selenium/webdriver/common/service.py", line 72, in start', '    self.process = subprocess.Popen(cmd, env=self.env,', '  File "/Users/vishaljha/anaconda3/lib/python3.8/subprocess.py", line 854, in __init__', '    self._execute_child(args, executable, preexec_fn, close_fds,', '  File "/Users/vishaljha/anaconda3/lib/python3.8/subprocess.py", line 1702, in _execute_child', '    raise child_exception_type(errno_num, err_msg, err_filename)', "FileNotFoundError: [Errno 2] No such file or directory: 'chromedriver'", '', 'During handling of the above exception, another exception occurred:', '', 'Traceback (most recent call last):', '  File "/Users/vishaljha/Desktop/FINVANT/API/Backend/Scripts/AutoLoginZerodha.py", line 117, in auto_login_zerodha', '    key = automate_login(browser_url, user_id, password, totp_pin)', '  File "/Users/vishaljha/Desktop/FINVANT/API/Backend/Scripts/AutoLoginZerodha.py", line 40, in automate_login', '    browser = webdriver.Chrome(options = options)', '  File "/Users/vishaljha/anaconda3/lib/python3.8/site-packages/selenium/webdriver/chrome/webdriver.py", line 73, in __init__', '    self.service.start()', '  File "/Users/vishaljha/anaconda3/lib/python3.8/site-packages/selenium/webdriver/common/service.py", line 81, in start', '    raise WebDriverException(', "selenium.common.exceptions.WebDriverException: Message: 'chromedriver' executable needs to be in PATH. Please see https://sites.google.com/a/chromium.org/chromedriver/home", '']
root - INFO - 2023-03-28 23:43:49.449723 - Finvant Alcubierre Mk1 OMS Backend turned on.
root - INFO - 2023-03-28 23:43:49.577236 - OMS Backend mainloop started.
root - INFO - 2023-03-28 23:43:49.758373 - OMSB: Logging in for backend kite ticker.
root - INFO - 2023-03-28 23:43:57.191752 - OMSB: Login succesful for backend kite ticker.
root - INFO - 2023-03-28 23:43:57.550804 - OMSB: Zerodha login for WG5235.
root - CRITICAL - CRITICAL ERROR:2023-03-28 23:44:09.039551 - OMSB: Failed auto login to kite for user:WG5235.
['Traceback (most recent call last):', '  File "/Users/vishaljha/Desktop/FINVANT/API/Backend/Scripts/AutoLoginZerodha.py", line 119, in auto_login_zerodha', '    data = kite.generate_session(key, api_secret=api_secret)', '  File "/Users/vishaljha/anaconda3/lib/python3.8/site-packages/kiteconnect/connect.py", line 255, in generate_session', '    h = hashlib.sha256(self.api_key.encode("utf-8") + request_token.encode("utf-8") + api_secret.encode("utf-8"))', "AttributeError: 'int' object has no attribute 'encode'"]
root - INFO - 2023-03-28 23:50:04.437626 - Finvant Alcubierre Mk1 OMS Backend turned on.
root - INFO - 2023-03-28 23:50:04.574728 - OMS Backend mainloop started.
root - INFO - 2023-03-28 23:50:04.763075 - OMSB: Logging in for backend kite ticker.
root - INFO - 2023-03-28 23:50:12.379482 - OMSB: Login succesful for backend kite ticker.
root - INFO - 2023-03-28 23:50:12.753505 - OMSB: Zerodha login for WG5235.
root - INFO - 2023-03-28 23:50:20.218674 - OMSB: Zerodha login succesful for WG5235.
root - INFO - 2023-03-29 00:01:01.079636 - Finvant Alcubierre Mk1 OMS Backend turned on.
root - INFO - 2023-03-29 00:01:01.211108 - OMS Backend mainloop started.
root - INFO - 2023-03-29 00:01:01.387065 - OMSB: Logging in for backend kite ticker.
root - INFO - 2023-03-29 00:01:08.320609 - OMSB: Login succesful for backend kite ticker.
root - INFO - 2023-03-29 00:01:08.699334 - OMSB: Zerodha login for WG5235.
root - INFO - 2023-03-29 00:01:15.342263 - OMSB: Zerodha login succesful for WG5235.
root - INFO - 2023-03-29 00:16:28.882395 - Placed Zerodha Kite futures order for:TEST, instrument:NIFTY23MARFUT, qty:50, transaction type:BUY, placed price:16977.7, id:890.
root - INFO - 2023-03-29 00:16:29.020995 - 140.2301788330078
kiteconnect.ticker - ERROR - Connection error: 1006 - connection was closed uncleanly (None)
kiteconnect.ticker - ERROR - Connection closed: 1006 - connection was closed uncleanly (None)
kiteconnect.ticker - ERROR - Connection error: 1006 - connection was closed uncleanly (None)
kiteconnect.ticker - ERROR - Connection closed: 1006 - connection was closed uncleanly (None)
kiteconnect.ticker - ERROR - Connection error: 1006 - connection was closed uncleanly (None)
kiteconnect.ticker - ERROR - Connection closed: 1006 - connection was closed uncleanly (None)
kiteconnect.ticker - ERROR - Connection error: 1006 - connection was closed uncleanly (None)
kiteconnect.ticker - ERROR - Connection closed: 1006 - connection was closed uncleanly (None)
kiteconnect.ticker - ERROR - Connection error: 1006 - connection was closed uncleanly (None)
kiteconnect.ticker - ERROR - Connection closed: 1006 - connection was closed uncleanly (None)
kiteconnect.ticker - ERROR - Connection error: 1006 - connection was closed uncleanly (None)
kiteconnect.ticker - ERROR - Connection closed: 1006 - connection was closed uncleanly (None)
kiteconnect.ticker - ERROR - Connection error: 1006 - connection was closed uncleanly (None)
kiteconnect.ticker - ERROR - Connection closed: 1006 - connection was closed uncleanly (None)
