root - INFO - 2023-01-09 14:31:51.494919 - Finvant Alcubierre Mk1 OMS Backend turned on.
root - INFO - 2023-01-09 14:31:51.615472 - OMS Backend mainloop started.
root - CRITICAL - CRITICAL ERROR:2023-01-09 14:31:57.019814 - Failed to initialise Log server/ADS.
['Traceback (most recent call last):', '  File "/Users/aditya/Documents/Projects/Mothership/Backend/Scripts/AutoLoginKiteTicker.py", line 36, in automate_login', '    browser.get(browser_url)', '  File "/opt/homebrew/lib/python3.9/site-packages/selenium/webdriver/remote/webdriver.py", line 437, in get', "    self.execute(Command.GET, {'url': url})", '  File "/opt/homebrew/lib/python3.9/site-packages/selenium/webdriver/remote/webdriver.py", line 423, in execute', '    response = self.command_executor.execute(driver_command, params)', '  File "/opt/homebrew/lib/python3.9/site-packages/selenium/webdriver/remote/remote_connection.py", line 333, in execute', '    return self._request(command_info[0], url, body=data)', '  File "/opt/homebrew/lib/python3.9/site-packages/selenium/webdriver/remote/remote_connection.py", line 355, in _request', '    resp = self._conn.request(method, url, body=body, headers=headers)', '  File "/opt/homebrew/lib/python3.9/site-packages/urllib3/request.py", line 78, in request', '    return self.request_encode_body(', '  File "/opt/homebrew/lib/python3.9/site-packages/urllib3/request.py", line 170, in request_encode_body', '    return self.urlopen(method, url, **extra_kw)', '  File "/opt/homebrew/lib/python3.9/site-packages/urllib3/poolmanager.py", line 376, in urlopen', '    response = conn.urlopen(method, u.request_uri, **kw)', '  File "/opt/homebrew/lib/python3.9/site-packages/urllib3/connectionpool.py", line 703, in urlopen', '    httplib_response = self._make_request(', '  File "/opt/homebrew/lib/python3.9/site-packages/urllib3/connectionpool.py", line 449, in _make_request', '    six.raise_from(e, None)', '  File "<string>", line 3, in raise_from', '  File "/opt/homebrew/lib/python3.9/site-packages/urllib3/connectionpool.py", line 444, in _make_request', '    httplib_response = conn.getresponse()', '  File "/opt/homebrew/Cellar/python@3.9/3.9.12/Frameworks/Python.framework/Versions/3.9/lib/python3.9/http/client.py", line 1377, in getresponse', '    response.begin()', '  File "/opt/homebrew/Cellar/python@3.9/3.9.12/Frameworks/Python.framework/Versions/3.9/lib/python3.9/http/client.py", line 320, in begin', '    version, status, reason = self._read_status()', '  File "/opt/homebrew/Cellar/python@3.9/3.9.12/Frameworks/Python.framework/Versions/3.9/lib/python3.9/http/client.py", line 281, in _read_status', '    line = str(self.fp.readline(_MAXLINE + 1), "iso-8859-1")', '  File "/opt/homebrew/Cellar/python@3.9/3.9.12/Frameworks/Python.framework/Versions/3.9/lib/python3.9/socket.py", line 704, in readinto', '    return self._sock.recv_into(b)', 'KeyboardInterrupt', '', 'During handling of the above exception, another exception occurred:', '', 'Traceback (most recent call last):', '  File "/opt/homebrew/lib/python3.9/site-packages/selenium/webdriver/common/service.py", line 71, in start', '    self.process = subprocess.Popen(cmd, env=self.env,', '  File "/opt/homebrew/Cellar/python@3.9/3.9.12/Frameworks/Python.framework/Versions/3.9/lib/python3.9/subprocess.py", line 951, in __init__', '    self._execute_child(args, executable, preexec_fn, close_fds,', '  File "/opt/homebrew/Cellar/python@3.9/3.9.12/Frameworks/Python.framework/Versions/3.9/lib/python3.9/subprocess.py", line 1821, in _execute_child', '    raise child_exception_type(errno_num, err_msg, err_filename)', "FileNotFoundError: [Errno 2] No such file or directory: 'chromedriver'", '', 'During handling of the above exception, another exception occurred:', '', 'Traceback (most recent call last):', '  File "/Users/aditya/Documents/Projects/Mothership/Backend/Scripts/Main.py", line 28, in __init__', '    self.start()', '  File "/Users/aditya/Documents/Projects/Mothership/Backend/Scripts/Main.py", line 36, in start', '    self.main_loop()', '  File "/Users/aditya/Documents/Projects/Mothership/Backend/Scripts/Main.py", line 53, in main_loop', '    kite_ticker = auto_login_zerodha_ticker(config=config)', '  File "/Users/aditya/Documents/Projects/Mothership/Backend/Scripts/AutoLoginKiteTicker.py", line 114, in auto_login_zerodha_ticker', '    key = automate_login(browser_url, user_id, password, totp_pin)', '  File "/Users/aditya/Documents/Projects/Mothership/Backend/Scripts/AutoLoginKiteTicker.py", line 39, in automate_login', '    browser = webdriver.Chrome(options = options)', '  File "/opt/homebrew/lib/python3.9/site-packages/selenium/webdriver/chrome/webdriver.py", line 70, in __init__', '    super(WebDriver, self).__init__(DesiredCapabilities.CHROME[\'browserName\'], "goog",', '  File "/opt/homebrew/lib/python3.9/site-packages/selenium/webdriver/chromium/webdriver.py", line 90, in __init__', '    self.service.start()', '  File "/opt/homebrew/lib/python3.9/site-packages/selenium/webdriver/common/service.py", line 81, in start', '    raise WebDriverException(', "selenium.common.exceptions.WebDriverException: Message: 'chromedriver' executable needs to be in PATH. Please see https://chromedriver.chromium.org/home", '']
