root - INFO - 2023-05-08 17:18:20.478263 - Finvant Alcubierre Mk1 OMS Backend turned on.
root - INFO - 2023-05-08 17:18:20.609033 - OMS Backend mainloop started.
root - INFO - 2023-05-08 17:18:21.369421 - User data obtained.
root - INFO - 2023-05-08 17:18:22.111600 - Spreads obtained.
root - INFO - 2023-05-08 17:18:22.241889 - Config file obtained.
root - INFO - 2023-05-08 17:18:22.372855 - OMSB: Logging in for backend kite ticker.
root - INFO - 2023-05-08 17:18:29.495271 - OMSB: Login succesful for backend kite ticker.
root - INFO - 2023-05-08 17:18:29.627226 - Initialising LTP gather thread.
root - INFO - 2023-05-08 17:18:30.074408 - Attempting XTS login.
root - INFO - 2023-05-08 17:18:30.074910 - OMSB: Zerodha login for VR1418.
root - INFO - 2023-05-08 17:18:30.075118 - OMSB: Zerodha login for YU5680.
root - INFO - 2023-05-08 17:18:30.425980 - BPWealth login for ACS1207.
root - INFO - 2023-05-08 17:18:30.432277 - XTS login token: eyJhbGciOiJIUzI1NiIsInR5cCI6IkpXVCJ9.eyJ1c2VySUQiOiJIREwwMDA2XzU5NUU0NzY4RTFEM0ZCNDFCNUUyODIiLCJwdWJsaWNLZXkiOiI1OTVlNDc2OGUxZDNmYjQxYjVlMjgyIiwiaWF0IjoxNjgzNTQ2NTEwLCJleHAiOjE2ODM2MzI5MTB9.UakduLwE-xPGqDIvO5mMYFpWstUufse2yWqqh4blLOU.
root - INFO - 2023-05-08 17:18:30.614028 - ODIN login for NB01.
root - CRITICAL - CRITICAL ERROR:2023-05-08 17:18:31.218912 - ODIN login failed for NB01. Error: 'data'.
['Traceback (most recent call last):', '  File "/Users/vishaljha/Desktop/FINVANT/Alcubierre_Mk1_OMS/Backend/Scripts/AutoLoginOdin.py", line 48, in login', '    access_token = r["data"]["access_token"]', "KeyError: 'data'"]
root - INFO - 2023-05-08 17:18:31.345232 - ODIN login for S0201.
root - INFO - 2023-05-08 17:18:31.380713 - BPWealth login for AC66.
root - INFO - 2023-05-08 17:18:31.979703 - ODIN login succesful for S0201.
root - INFO - 2023-05-08 17:18:32.139936 - OMSB: Zerodha login for WG5235.
root - INFO - 2023-05-08 17:18:37.097120 - OMSB: Zerodha login succesful for VR1418.
root - INFO - 2023-05-08 17:18:37.137931 - OMSB: Zerodha login succesful for YU5680.
root - INFO - 2023-05-08 17:18:37.231251 - OMSB: Zerodha login for OJ8428.
root - INFO - 2023-05-08 17:18:37.294016 - OMSB: Zerodha login for WG5235.
root - INFO - 2023-05-08 17:18:40.087649 - OMSB: Zerodha login succesful for WG5235.
root - INFO - 2023-05-08 17:18:40.224279 - OMSB: Zerodha login for FS3611.
root - CRITICAL - CRITICAL ERROR:2023-05-08 17:18:41.806368 - Failed to generate user dictionary.
['Traceback (most recent call last):', '  File "Main.py", line 99, in main_loop', '    user_dict = UserProfileGenerator().create_user_profiles(user_data=user_data, log_interface=self.log_interface, debug=self.DEBUG)', '  File "/Users/vishaljha/Desktop/FINVANT/Alcubierre_Mk1_OMS/Backend/Scripts/UserProfileGenerator.py", line 73, in create_user_profiles', '    t.join()', '  File "/Users/vishaljha/anaconda3/lib/python3.8/threading.py", line 1011, in join', '    self._wait_for_tstate_lock()', '  File "/Users/vishaljha/anaconda3/lib/python3.8/threading.py", line 1027, in _wait_for_tstate_lock', '    elif lock.acquire(block, timeout):', 'KeyboardInterrupt']
root - CRITICAL - CRITICAL ERROR:2023-05-08 17:18:41.889528 - OMSB: Failed auto login to kite for user:FS3611.
['Traceback (most recent call last):', '  File "/Users/vishaljha/anaconda3/lib/python3.8/site-packages/urllib3/connectionpool.py", line 600, in urlopen', '    httplib_response = self._make_request(conn, method, url,', '  File "/Users/vishaljha/anaconda3/lib/python3.8/site-packages/urllib3/connectionpool.py", line 387, in _make_request', '    six.raise_from(e, None)', '  File "<string>", line 2, in raise_from', '  File "/Users/vishaljha/anaconda3/lib/python3.8/site-packages/urllib3/connectionpool.py", line 383, in _make_request', '    httplib_response = conn.getresponse()', '  File "/Users/vishaljha/anaconda3/lib/python3.8/http/client.py", line 1332, in getresponse', '    response.begin()', '  File "/Users/vishaljha/anaconda3/lib/python3.8/http/client.py", line 303, in begin', '    version, status, reason = self._read_status()', '  File "/Users/vishaljha/anaconda3/lib/python3.8/http/client.py", line 272, in _read_status', '    raise RemoteDisconnected("Remote end closed connection without"', 'http.client.RemoteDisconnected: Remote end closed connection without response', '', 'During handling of the above exception, another exception occurred:', '', 'Traceback (most recent call last):', '  File "/Users/vishaljha/Desktop/FINVANT/Alcubierre_Mk1_OMS/Backend/Scripts/AutoLoginZerodha.py", line 37, in automate_login', '    browser.get(browser_url)', '  File "/Users/vishaljha/anaconda3/lib/python3.8/site-packages/selenium/webdriver/remote/webdriver.py", line 333, in get', "    self.execute(Command.GET, {'url': url})", '  File "/Users/vishaljha/anaconda3/lib/python3.8/site-packages/selenium/webdriver/remote/webdriver.py", line 319, in execute', '    response = self.command_executor.execute(driver_command, params)', '  File "/Users/vishaljha/anaconda3/lib/python3.8/site-packages/selenium/webdriver/remote/remote_connection.py", line 374, in execute', '    return self._request(command_info[0], url, body=data)', '  File "/Users/vishaljha/anaconda3/lib/python3.8/site-packages/selenium/webdriver/remote/remote_connection.py", line 397, in _request', '    resp = self._conn.request(method, url, body=body, headers=headers)', '  File "/Users/vishaljha/anaconda3/lib/python3.8/site-packages/urllib3/request.py", line 70, in request', '    return self.request_encode_body(method, url, fields=fields,', '  File "/Users/vishaljha/anaconda3/lib/python3.8/site-packages/urllib3/request.py", line 150, in request_encode_body', '    return self.urlopen(method, url, **extra_kw)', '  File "/Users/vishaljha/anaconda3/lib/python3.8/site-packages/urllib3/poolmanager.py", line 326, in urlopen', '    response = conn.urlopen(method, u.request_uri, **kw)', '  File "/Users/vishaljha/anaconda3/lib/python3.8/site-packages/urllib3/connectionpool.py", line 640, in urlopen', '    retries = retries.increment(method, url, error=e, _pool=self,', '  File "/Users/vishaljha/anaconda3/lib/python3.8/site-packages/urllib3/util/retry.py", line 368, in increment', '    raise six.reraise(type(error), error, _stacktrace)', '  File "/Users/vishaljha/anaconda3/lib/python3.8/site-packages/urllib3/packages/six.py", line 685, in reraise', '    raise value.with_traceback(tb)', '  File "/Users/vishaljha/anaconda3/lib/python3.8/site-packages/urllib3/connectionpool.py", line 600, in urlopen', '    httplib_response = self._make_request(conn, method, url,', '  File "/Users/vishaljha/anaconda3/lib/python3.8/site-packages/urllib3/connectionpool.py", line 387, in _make_request', '    six.raise_from(e, None)', '  File "<string>", line 2, in raise_from', '  File "/Users/vishaljha/anaconda3/lib/python3.8/site-packages/urllib3/connectionpool.py", line 383, in _make_request', '    httplib_response = conn.getresponse()', '  File "/Users/vishaljha/anaconda3/lib/python3.8/http/client.py", line 1332, in getresponse', '    response.begin()', '  File "/Users/vishaljha/anaconda3/lib/python3.8/http/client.py", line 303, in begin', '    version, status, reason = self._read_status()', '  File "/Users/vishaljha/anaconda3/lib/python3.8/http/client.py", line 272, in _read_status', '    raise RemoteDisconnected("Remote end closed connection without"', "urllib3.exceptions.ProtocolError: ('Connection aborted.', RemoteDisconnected('Remote end closed connection without response'))", '', 'During handling of the above exception, another exception occurred:', '', 'Traceback (most recent call last):', '  File "/Users/vishaljha/anaconda3/lib/python3.8/site-packages/selenium/webdriver/common/service.py", line 72, in start', '    self.process = subprocess.Popen(cmd, env=self.env,', '  File "/Users/vishaljha/anaconda3/lib/python3.8/subprocess.py", line 854, in __init__', '    self._execute_child(args, executable, preexec_fn, close_fds,', '  File "/Users/vishaljha/anaconda3/lib/python3.8/subprocess.py", line 1702, in _execute_child', '    raise child_exception_type(errno_num, err_msg, err_filename)', "FileNotFoundError: [Errno 2] No such file or directory: 'chromedriver'", '', 'During handling of the above exception, another exception occurred:', '', 'Traceback (most recent call last):', '  File "/Users/vishaljha/Desktop/FINVANT/Alcubierre_Mk1_OMS/Backend/Scripts/AutoLoginZerodha.py", line 117, in auto_login_zerodha', '    key = automate_login(browser_url, user_id, password, totp_pin)', '  File "/Users/vishaljha/Desktop/FINVANT/Alcubierre_Mk1_OMS/Backend/Scripts/AutoLoginZerodha.py", line 40, in automate_login', '    browser = webdriver.Chrome(options = options)', '  File "/Users/vishaljha/anaconda3/lib/python3.8/site-packages/selenium/webdriver/chrome/webdriver.py", line 73, in __init__', '    self.service.start()', '  File "/Users/vishaljha/anaconda3/lib/python3.8/site-packages/selenium/webdriver/common/service.py", line 81, in start', '    raise WebDriverException(', "selenium.common.exceptions.WebDriverException: Message: 'chromedriver' executable needs to be in PATH. Please see https://sites.google.com/a/chromium.org/chromedriver/home", '']
root - CRITICAL - CRITICAL ERROR:2023-05-08 17:18:41.959501 - Failure in order handler.
['Traceback (most recent call last):', '  File "Main.py", line 107, in main_loop', '    order_handler = OrderHandler(user_profiles=user_dict, spread_list=spread_list, log_interface = self.log_interface, debug=self.DEBUG)', "UnboundLocalError: local variable 'user_dict' referenced before assignment"]
urllib3.connectionpool - WARNING - Retrying (Retry(total=2, connect=None, read=None, redirect=None, status=None)) after connection broken by 'NewConnectionError('<urllib3.connection.HTTPConnection object at 0x7fbd6c83d940>: Failed to establish a new connection: [Errno 61] Connection refused')': /session/a2493ec53d238242be34c59f9926e855/element/b3cc03de-b356-4c85-94e0-8407a2a4d6cf/value
urllib3.connectionpool - WARNING - Retrying (Retry(total=1, connect=None, read=None, redirect=None, status=None)) after connection broken by 'NewConnectionError('<urllib3.connection.HTTPConnection object at 0x7fbd6c860490>: Failed to establish a new connection: [Errno 61] Connection refused')': /session/a2493ec53d238242be34c59f9926e855/element/b3cc03de-b356-4c85-94e0-8407a2a4d6cf/value
urllib3.connectionpool - WARNING - Retrying (Retry(total=0, connect=None, read=None, redirect=None, status=None)) after connection broken by 'NewConnectionError('<urllib3.connection.HTTPConnection object at 0x7fbd6c859e50>: Failed to establish a new connection: [Errno 61] Connection refused')': /session/a2493ec53d238242be34c59f9926e855/element/b3cc03de-b356-4c85-94e0-8407a2a4d6cf/value
root - CRITICAL - CRITICAL ERROR:2023-05-08 17:20:27.931232 - OMSB_ADSINT_1
['Traceback (most recent call last):', '  File "/Users/vishaljha/anaconda3/lib/python3.8/site-packages/requests/packages/urllib3/connection.py", line 140, in _new_conn', '    conn = connection.create_connection(', '  File "/Users/vishaljha/anaconda3/lib/python3.8/site-packages/requests/packages/urllib3/util/connection.py", line 83, in create_connection', '    raise err', '  File "/Users/vishaljha/anaconda3/lib/python3.8/site-packages/requests/packages/urllib3/util/connection.py", line 73, in create_connection', '    sock.connect(sa)', 'ConnectionRefusedError: [Errno 61] Connection refused', '', 'During handling of the above exception, another exception occurred:', '', 'Traceback (most recent call last):', '  File "/Users/vishaljha/anaconda3/lib/python3.8/site-packages/requests/packages/urllib3/connectionpool.py", line 597, in urlopen', '    httplib_response = self._make_request(conn, method, url,', '  File "/Users/vishaljha/anaconda3/lib/python3.8/site-packages/requests/packages/urllib3/connectionpool.py", line 356, in _make_request', '    conn.request(method, url, **httplib_request_kw)', '  File "/Users/vishaljha/anaconda3/lib/python3.8/http/client.py", line 1240, in request', '    self._send_request(method, url, body, headers, encode_chunked)', '  File "/Users/vishaljha/anaconda3/lib/python3.8/http/client.py", line 1286, in _send_request', '    self.endheaders(body, encode_chunked=encode_chunked)', '  File "/Users/vishaljha/anaconda3/lib/python3.8/http/client.py", line 1235, in endheaders', '    self._send_output(message_body, encode_chunked=encode_chunked)', '  File "/Users/vishaljha/anaconda3/lib/python3.8/http/client.py", line 1006, in _send_output', '    self.send(msg)', '  File "/Users/vishaljha/anaconda3/lib/python3.8/http/client.py", line 946, in send', '    self.connect()', '  File "/Users/vishaljha/anaconda3/lib/python3.8/site-packages/requests/packages/urllib3/connection.py", line 166, in connect', '    conn = self._new_conn()', '  File "/Users/vishaljha/anaconda3/lib/python3.8/site-packages/requests/packages/urllib3/connection.py", line 149, in _new_conn', '    raise NewConnectionError(', 'requests.packages.urllib3.exceptions.NewConnectionError: <requests.packages.urllib3.connection.HTTPConnection object at 0x7f8efc9e6130>: Failed to establish a new connection: [Errno 61] Connection refused', '', 'During handling of the above exception, another exception occurred:', '', 'Traceback (most recent call last):', '  File "/Users/vishaljha/anaconda3/lib/python3.8/site-packages/requests/adapters.py", line 413, in send', '    resp = conn.urlopen(', '  File "/Users/vishaljha/anaconda3/lib/python3.8/site-packages/requests/packages/urllib3/connectionpool.py", line 648, in urlopen', '    retries = retries.increment(method, url, error=e, _pool=self,', '  File "/Users/vishaljha/anaconda3/lib/python3.8/site-packages/requests/packages/urllib3/util/retry.py", line 376, in increment', '    raise MaxRetryError(_pool, url, error or ResponseError(cause))', "requests.packages.urllib3.exceptions.MaxRetryError: HTTPConnectionPool(host='127.0.0.1', port=6000): Max retries exceeded with url: /token (Caused by NewConnectionError('<requests.packages.urllib3.connection.HTTPConnection object at 0x7f8efc9e6130>: Failed to establish a new connection: [Errno 61] Connection refused'))", '', 'During handling of the above exception, another exception occurred:', '', 'Traceback (most recent call last):', '  File "/Users/vishaljha/Desktop/FINVANT/Alcubierre_Mk1_OMS/Backend/Scripts/ADS_Interface.py", line 29, in authentification', "    response = requests.post(self.url + 'token', data=data)", '  File "/Users/vishaljha/anaconda3/lib/python3.8/site-packages/requests/api.py", line 110, in post', "    return request('post', url, data=data, json=json, **kwargs)", '  File "/Users/vishaljha/anaconda3/lib/python3.8/site-packages/requests/api.py", line 56, in request', '    return session.request(method=method, url=url, **kwargs)', '  File "/Users/vishaljha/anaconda3/lib/python3.8/site-packages/requests/sessions.py", line 488, in request', '    resp = self.send(prep, **send_kwargs)', '  File "/Users/vishaljha/anaconda3/lib/python3.8/site-packages/requests/sessions.py", line 609, in send', '    r = adapter.send(request, **kwargs)', '  File "/Users/vishaljha/anaconda3/lib/python3.8/site-packages/requests/adapters.py", line 487, in send', '    raise ConnectionError(e, request=request)', "requests.exceptions.ConnectionError: HTTPConnectionPool(host='127.0.0.1', port=6000): Max retries exceeded with url: /token (Caused by NewConnectionError('<requests.packages.urllib3.connection.HTTPConnection object at 0x7f8efc9e6130>: Failed to establish a new connection: [Errno 61] Connection refused'))"]
root - CRITICAL - CRITICAL ERROR:2023-05-08 17:21:16.816041 - OMSB_ADSINT_1
['Traceback (most recent call last):', '  File "/Users/vishaljha/anaconda3/lib/python3.8/site-packages/requests/packages/urllib3/connection.py", line 140, in _new_conn', '    conn = connection.create_connection(', '  File "/Users/vishaljha/anaconda3/lib/python3.8/site-packages/requests/packages/urllib3/util/connection.py", line 83, in create_connection', '    raise err', '  File "/Users/vishaljha/anaconda3/lib/python3.8/site-packages/requests/packages/urllib3/util/connection.py", line 73, in create_connection', '    sock.connect(sa)', 'ConnectionRefusedError: [Errno 61] Connection refused', '', 'During handling of the above exception, another exception occurred:', '', 'Traceback (most recent call last):', '  File "/Users/vishaljha/anaconda3/lib/python3.8/site-packages/requests/packages/urllib3/connectionpool.py", line 597, in urlopen', '    httplib_response = self._make_request(conn, method, url,', '  File "/Users/vishaljha/anaconda3/lib/python3.8/site-packages/requests/packages/urllib3/connectionpool.py", line 356, in _make_request', '    conn.request(method, url, **httplib_request_kw)', '  File "/Users/vishaljha/anaconda3/lib/python3.8/http/client.py", line 1240, in request', '    self._send_request(method, url, body, headers, encode_chunked)', '  File "/Users/vishaljha/anaconda3/lib/python3.8/http/client.py", line 1286, in _send_request', '    self.endheaders(body, encode_chunked=encode_chunked)', '  File "/Users/vishaljha/anaconda3/lib/python3.8/http/client.py", line 1235, in endheaders', '    self._send_output(message_body, encode_chunked=encode_chunked)', '  File "/Users/vishaljha/anaconda3/lib/python3.8/http/client.py", line 1006, in _send_output', '    self.send(msg)', '  File "/Users/vishaljha/anaconda3/lib/python3.8/http/client.py", line 946, in send', '    self.connect()', '  File "/Users/vishaljha/anaconda3/lib/python3.8/site-packages/requests/packages/urllib3/connection.py", line 166, in connect', '    conn = self._new_conn()', '  File "/Users/vishaljha/anaconda3/lib/python3.8/site-packages/requests/packages/urllib3/connection.py", line 149, in _new_conn', '    raise NewConnectionError(', 'requests.packages.urllib3.exceptions.NewConnectionError: <requests.packages.urllib3.connection.HTTPConnection object at 0x7f79e78d4700>: Failed to establish a new connection: [Errno 61] Connection refused', '', 'During handling of the above exception, another exception occurred:', '', 'Traceback (most recent call last):', '  File "/Users/vishaljha/anaconda3/lib/python3.8/site-packages/requests/adapters.py", line 413, in send', '    resp = conn.urlopen(', '  File "/Users/vishaljha/anaconda3/lib/python3.8/site-packages/requests/packages/urllib3/connectionpool.py", line 648, in urlopen', '    retries = retries.increment(method, url, error=e, _pool=self,', '  File "/Users/vishaljha/anaconda3/lib/python3.8/site-packages/requests/packages/urllib3/util/retry.py", line 376, in increment', '    raise MaxRetryError(_pool, url, error or ResponseError(cause))', "requests.packages.urllib3.exceptions.MaxRetryError: HTTPConnectionPool(host='127.0.0.1', port=6000): Max retries exceeded with url: /token (Caused by NewConnectionError('<requests.packages.urllib3.connection.HTTPConnection object at 0x7f79e78d4700>: Failed to establish a new connection: [Errno 61] Connection refused'))", '', 'During handling of the above exception, another exception occurred:', '', 'Traceback (most recent call last):', '  File "/Users/vishaljha/Desktop/FINVANT/Alcubierre_Mk1_OMS/Backend/Scripts/ADS_Interface.py", line 29, in authentification', "    response = requests.post(self.url + 'token', data=data)", '  File "/Users/vishaljha/anaconda3/lib/python3.8/site-packages/requests/api.py", line 110, in post', "    return request('post', url, data=data, json=json, **kwargs)", '  File "/Users/vishaljha/anaconda3/lib/python3.8/site-packages/requests/api.py", line 56, in request', '    return session.request(method=method, url=url, **kwargs)', '  File "/Users/vishaljha/anaconda3/lib/python3.8/site-packages/requests/sessions.py", line 488, in request', '    resp = self.send(prep, **send_kwargs)', '  File "/Users/vishaljha/anaconda3/lib/python3.8/site-packages/requests/sessions.py", line 609, in send', '    r = adapter.send(request, **kwargs)', '  File "/Users/vishaljha/anaconda3/lib/python3.8/site-packages/requests/adapters.py", line 487, in send', '    raise ConnectionError(e, request=request)', "requests.exceptions.ConnectionError: HTTPConnectionPool(host='127.0.0.1', port=6000): Max retries exceeded with url: /token (Caused by NewConnectionError('<requests.packages.urllib3.connection.HTTPConnection object at 0x7f79e78d4700>: Failed to establish a new connection: [Errno 61] Connection refused'))"]
root - INFO - 2023-05-08 17:21:39.322856 - Finvant Alcubierre Mk1 OMS Backend turned on.
root - INFO - 2023-05-08 17:21:39.450451 - OMS Backend mainloop started.
root - INFO - 2023-05-08 17:21:39.630545 - User data obtained.
root - INFO - 2023-05-08 17:21:39.772344 - Spreads obtained.
root - INFO - 2023-05-08 17:21:39.897116 - Config file obtained.
root - INFO - 2023-05-08 17:21:40.025318 - OMSB: Logging in for backend kite ticker.
root - INFO - 2023-05-08 17:21:48.033947 - OMSB: Login succesful for backend kite ticker.
root - INFO - 2023-05-08 17:21:48.169878 - Initialising LTP gather thread.
root - INFO - 2023-05-08 17:21:48.529941 - OMSB: Zerodha login for WG5235.
root - CRITICAL - CRITICAL ERROR:2023-05-08 17:22:00.070699 - OMSB: Failed auto login to kite for user:WG5235.
['Traceback (most recent call last):', '  File "/Users/vishaljha/Desktop/FINVANT/Alcubierre_Mk1_OMS/Backend/Scripts/AutoLoginZerodha.py", line 119, in auto_login_zerodha', '    data = kite.generate_session(key, api_secret=api_secret)', '  File "/Users/vishaljha/anaconda3/lib/python3.8/site-packages/kiteconnect/connect.py", line 255, in generate_session', '    h = hashlib.sha256(self.api_key.encode("utf-8") + request_token.encode("utf-8") + api_secret.encode("utf-8"))', "AttributeError: 'int' object has no attribute 'encode'"]
root - INFO - 2023-05-08 17:22:00.218670 - Order handler initialised.
root - INFO - 2023-05-08 17:22:00.345371 - Creating order handler sub threads.
root - INFO - 2023-05-08 17:22:00.345615 - Starting order handler sub threads.
root - INFO - 2023-05-08 17:22:00.849399 - Placed Zerodha Kite options order for:fin_user_1, instrument:NIFTY23MAY18300PE, qty:-50, transaction type:SELL, placed price:155.0, id:431.
root - INFO - 2023-05-08 17:22:00.999773 - 652.9238224029541
root - INFO - 2023-05-08 17:22:01.632364 - Placed Zerodha Kite options order for:fin_user_1, instrument:NIFTY23JUN18300PE, qty:50, transaction type:BUY, placed price:268.95, id:966.
root - INFO - 2023-05-08 17:22:01.763993 - 637.4928951263428
root - INFO - 2023-05-08 17:22:02.433590 - Placed Zerodha Kite options order for:fin_user_1, instrument:NIFTY23MAY18200PE, qty:50, transaction type:BUY, placed price:114.95, id:435.
root - INFO - 2023-05-08 17:22:02.566812 - 636.4080905914307
root - INFO - 2023-05-08 17:22:03.200102 - Placed Zerodha Kite options order for:fin_user_1, instrument:NIFTY23JUN18200PE, qty:-50, transaction type:SELL, placed price:230.3, id:658.
root - INFO - 2023-05-08 17:22:03.353976 - 660.0198745727539
root - INFO - 2023-05-08 17:25:33.745629 - Placed Zerodha Kite options order for:fin_user_1, instrument:NIFTY23MAY18500PE, qty:50, transaction type:BUY, placed price:260.05, id:439.
root - INFO - 2023-05-08 17:25:33.875920 - 634.1331005096436
root - INFO - 2023-05-08 17:25:34.527845 - Placed Zerodha Kite options order for:fin_user_1, instrument:NIFTY23MAY18400PE, qty:-50, transaction type:SELL, placed price:200.0, id:339.
root - INFO - 2023-05-08 17:25:34.657550 - 635.5738639831543
root - INFO - 2023-05-08 17:26:27.466657 - Placed Zerodha Kite options order for:fin_user_1, instrument:NIFTY23MAY18500PE, qty:-50, transaction type:SELL, placed price:260.05, id:624.
root - INFO - 2023-05-08 17:26:27.593714 - 632.1227550506592
root - INFO - 2023-05-08 17:26:28.223419 - Placed Zerodha Kite options order for:fin_user_1, instrument:NIFTY23JUN18500PE, qty:50, transaction type:BUY, placed price:353.0, id:888.
root - INFO - 2023-05-08 17:26:28.350895 - 632.6658725738525
root - INFO - 2023-05-08 17:26:28.982943 - Placed Zerodha Kite options order for:fin_user_1, instrument:NIFTY23MAY18400PE, qty:50, transaction type:BUY, placed price:200.0, id:508.
root - INFO - 2023-05-08 17:26:29.113569 - 636.4779472351074
root - INFO - 2023-05-08 17:26:29.744503 - Placed Zerodha Kite options order for:fin_user_1, instrument:NIFTY23JUN18400PE, qty:-50, transaction type:SELL, placed price:310.0, id:425.
root - INFO - 2023-05-08 17:26:29.874042 - 634.8133087158203
