root - INFO - 2023-06-15 00:36:57.788321 - Finvant Alcubierre Mk1 OMS Backend turned on.
root - INFO - 2023-06-15 00:36:57.934271 - OMS Backend mainloop started.
root - INFO - 2023-06-15 00:36:58.084062 - User data obtained.
root - INFO - 2023-06-15 00:36:58.226672 - Spreads obtained.
root - INFO - 2023-06-15 00:36:58.364422 - Config file obtained.
root - INFO - 2023-06-15 00:36:58.496032 - OMSB: Logging in for backend kite ticker.
root - CRITICAL - CRITICAL ERROR:2023-06-15 00:37:01.172045 - OMSB: Failed auto login to kite ticker.
['Traceback (most recent call last):', '  File "/Users/vishaljha/Desktop/FINVANT/Alcubierre_Mk1_OMS/Backend/Scripts/AutoLoginKiteTicker.py", line 36, in automate_login', "    browser = webdriver.Chrome(options = options,executable_path='../Chrome/chromedriver')", '  File "/Users/vishaljha/anaconda3/lib/python3.8/site-packages/selenium/webdriver/chrome/webdriver.py", line 76, in __init__', '    RemoteWebDriver.__init__(', '  File "/Users/vishaljha/anaconda3/lib/python3.8/site-packages/selenium/webdriver/remote/webdriver.py", line 157, in __init__', '    self.start_session(capabilities, browser_profile)', '  File "/Users/vishaljha/anaconda3/lib/python3.8/site-packages/selenium/webdriver/remote/webdriver.py", line 252, in start_session', '    response = self.execute(Command.NEW_SESSION, parameters)', '  File "/Users/vishaljha/anaconda3/lib/python3.8/site-packages/selenium/webdriver/remote/webdriver.py", line 321, in execute', '    self.error_handler.check_response(response)', '  File "/Users/vishaljha/anaconda3/lib/python3.8/site-packages/selenium/webdriver/remote/errorhandler.py", line 242, in check_response', '    raise exception_class(message, screen, stacktrace)', 'selenium.common.exceptions.SessionNotCreatedException: Message: session not created: This version of ChromeDriver only supports Chrome version 111', 'Current browser version is 114.0.5735.106 with binary path /Applications/Google Chrome.app/Contents/MacOS/Google Chrome', '', '', 'During handling of the above exception, another exception occurred:', '', 'Traceback (most recent call last):', '  File "/Users/vishaljha/anaconda3/lib/python3.8/site-packages/selenium/webdriver/common/service.py", line 72, in start', '    self.process = subprocess.Popen(cmd, env=self.env,', '  File "/Users/vishaljha/anaconda3/lib/python3.8/subprocess.py", line 854, in __init__', '    self._execute_child(args, executable, preexec_fn, close_fds,', '  File "/Users/vishaljha/anaconda3/lib/python3.8/subprocess.py", line 1702, in _execute_child', '    raise child_exception_type(errno_num, err_msg, err_filename)', "FileNotFoundError: [Errno 2] No such file or directory: 'chromedriver'", '', 'During handling of the above exception, another exception occurred:', '', 'Traceback (most recent call last):', '  File "/Users/vishaljha/Desktop/FINVANT/Alcubierre_Mk1_OMS/Backend/Scripts/AutoLoginKiteTicker.py", line 123, in auto_login_zerodha_ticker', '    key = automate_login(browser_url, user_id, password, totp_pin, debug=debug)', '  File "/Users/vishaljha/Desktop/FINVANT/Alcubierre_Mk1_OMS/Backend/Scripts/AutoLoginKiteTicker.py", line 40, in automate_login', '    browser = webdriver.Chrome(options = options)', '  File "/Users/vishaljha/anaconda3/lib/python3.8/site-packages/selenium/webdriver/chrome/webdriver.py", line 73, in __init__', '    self.service.start()', '  File "/Users/vishaljha/anaconda3/lib/python3.8/site-packages/selenium/webdriver/common/service.py", line 81, in start', '    raise WebDriverException(', "selenium.common.exceptions.WebDriverException: Message: 'chromedriver' executable needs to be in PATH. Please see https://sites.google.com/a/chromium.org/chromedriver/home", '']
root - INFO - 2023-06-15 00:37:01.310803 - Initialising LTP gather thread.
root - CRITICAL - CRITICAL ERROR:2023-06-15 00:37:01.687358 - Failed to load vital jsons for LTP gathering.
['Traceback (most recent call last):', '  File "/Users/vishaljha/Desktop/FINVANT/Alcubierre_Mk1_OMS/Backend/Scripts/GatherLTP.py", line 38, in __init__', '    instrument_token_json = json.load(f)', '  File "/Users/vishaljha/anaconda3/lib/python3.8/json/__init__.py", line 293, in load', '    return loads(fp.read(),', '  File "/Users/vishaljha/anaconda3/lib/python3.8/json/__init__.py", line 357, in loads', '    return _default_decoder.decode(s)', '  File "/Users/vishaljha/anaconda3/lib/python3.8/json/decoder.py", line 337, in decode', '    obj, end = self.raw_decode(s, idx=_w(s, 0).end())', '  File "/Users/vishaljha/anaconda3/lib/python3.8/json/decoder.py", line 355, in raw_decode', '    raise JSONDecodeError("Expecting value", s, err.value) from None', 'json.decoder.JSONDecodeError: Expecting value: line 3 column 1 (char 27)']
root - CRITICAL - CRITICAL ERROR:2023-06-15 00:37:01.811819 - Failed to initialise LTP gather module.
['Traceback (most recent call last):', '  File "/Users/vishaljha/Desktop/FINVANT/Alcubierre_Mk1_OMS/Backend/Scripts/GatherLTP.py", line 51, in __init__', '    self.instrument_token_list = instrument_token_json["instrument_tokens"]', "UnboundLocalError: local variable 'instrument_token_json' referenced before assignment"]
root - CRITICAL - CRITICAL ERROR:2023-06-15 00:37:01.941806 - Failed to start KWS thread.
['Traceback (most recent call last):', '  File "/Users/vishaljha/Desktop/FINVANT/Alcubierre_Mk1_OMS/Backend/Scripts/GatherLTP.py", line 77, in start', '    self.kws.on_ticks = self.on_ticks', "AttributeError: 'NoneType' object has no attribute 'on_ticks'"]
root - INFO - 2023-06-15 00:37:01.942903 - OMSB: Zerodha login for WG5235.
root - CRITICAL - CRITICAL ERROR:2023-06-15 00:37:03.614082 - OMSB: Failed auto login to kite for user:WG5235.
['Traceback (most recent call last):', '  File "/Users/vishaljha/Desktop/FINVANT/Alcubierre_Mk1_OMS/Backend/Scripts/AutoLoginZerodha.py", line 36, in automate_login', "    browser = webdriver.Chrome(options = options,executable_path='../Chrome/chromedriver')", '  File "/Users/vishaljha/anaconda3/lib/python3.8/site-packages/selenium/webdriver/chrome/webdriver.py", line 76, in __init__', '    RemoteWebDriver.__init__(', '  File "/Users/vishaljha/anaconda3/lib/python3.8/site-packages/selenium/webdriver/remote/webdriver.py", line 157, in __init__', '    self.start_session(capabilities, browser_profile)', '  File "/Users/vishaljha/anaconda3/lib/python3.8/site-packages/selenium/webdriver/remote/webdriver.py", line 252, in start_session', '    response = self.execute(Command.NEW_SESSION, parameters)', '  File "/Users/vishaljha/anaconda3/lib/python3.8/site-packages/selenium/webdriver/remote/webdriver.py", line 321, in execute', '    self.error_handler.check_response(response)', '  File "/Users/vishaljha/anaconda3/lib/python3.8/site-packages/selenium/webdriver/remote/errorhandler.py", line 242, in check_response', '    raise exception_class(message, screen, stacktrace)', 'selenium.common.exceptions.SessionNotCreatedException: Message: session not created: This version of ChromeDriver only supports Chrome version 111', 'Current browser version is 114.0.5735.106 with binary path /Applications/Google Chrome.app/Contents/MacOS/Google Chrome', '', '', 'During handling of the above exception, another exception occurred:', '', 'Traceback (most recent call last):', '  File "/Users/vishaljha/anaconda3/lib/python3.8/site-packages/selenium/webdriver/common/service.py", line 72, in start', '    self.process = subprocess.Popen(cmd, env=self.env,', '  File "/Users/vishaljha/anaconda3/lib/python3.8/subprocess.py", line 854, in __init__', '    self._execute_child(args, executable, preexec_fn, close_fds,', '  File "/Users/vishaljha/anaconda3/lib/python3.8/subprocess.py", line 1702, in _execute_child', '    raise child_exception_type(errno_num, err_msg, err_filename)', "FileNotFoundError: [Errno 2] No such file or directory: 'chromedriver'", '', 'During handling of the above exception, another exception occurred:', '', 'Traceback (most recent call last):', '  File "/Users/vishaljha/Desktop/FINVANT/Alcubierre_Mk1_OMS/Backend/Scripts/AutoLoginZerodha.py", line 117, in auto_login_zerodha', '    key = automate_login(browser_url, user_id, password, totp_pin)', '  File "/Users/vishaljha/Desktop/FINVANT/Alcubierre_Mk1_OMS/Backend/Scripts/AutoLoginZerodha.py", line 40, in automate_login', '    browser = webdriver.Chrome(options = options)', '  File "/Users/vishaljha/anaconda3/lib/python3.8/site-packages/selenium/webdriver/chrome/webdriver.py", line 73, in __init__', '    self.service.start()', '  File "/Users/vishaljha/anaconda3/lib/python3.8/site-packages/selenium/webdriver/common/service.py", line 81, in start', '    raise WebDriverException(', "selenium.common.exceptions.WebDriverException: Message: 'chromedriver' executable needs to be in PATH. Please see https://sites.google.com/a/chromium.org/chromedriver/home", '']
root - INFO - 2023-06-15 00:37:03.747771 - Order handler initialised.
root - INFO - 2023-06-15 00:37:03.884412 - Creating order handler sub threads.
root - INFO - 2023-06-15 00:37:03.884586 - Starting order handler sub threads.
root - INFO - 2023-06-15 00:37:04.087520 - Placed Zerodha Kite futures order for:fin_user_1, instrument:NIFTY23JULFUT, qty:-50, transaction type:SELL, placed price:18719.0, id:882.
root - INFO - 2023-06-15 00:37:04.955092 - 872.3020553588867
root - INFO - 2023-06-15 01:22:30.598444 - Placed Zerodha Kite futures order for:fin_user_1, instrument:NIFTY23JULFUT, qty:50, transaction type:BUY, placed price:18719.0, id:852.
root - INFO - 2023-06-15 01:22:31.660578 - 1064.913034439087
root - INFO - 2023-06-15 01:32:36.013112 - Finvant Alcubierre Mk1 OMS Backend turned on.
root - INFO - 2023-06-15 01:32:36.143824 - OMS Backend mainloop started.
root - INFO - 2023-06-15 01:32:36.324055 - User data obtained.
root - INFO - 2023-06-15 01:32:36.486468 - Spreads obtained.
root - INFO - 2023-06-15 01:32:36.624863 - Config file obtained.
root - INFO - 2023-06-15 01:32:36.760923 - OMSB: Logging in for backend kite ticker.
root - CRITICAL - CRITICAL ERROR:2023-06-15 01:32:39.559812 - OMSB: Failed auto login to kite ticker.
['Traceback (most recent call last):', '  File "/Users/vishaljha/Desktop/FINVANT/Alcubierre_Mk1_OMS/Backend/Scripts/AutoLoginKiteTicker.py", line 36, in automate_login', "    browser = webdriver.Chrome(options = options,executable_path='../Chrome/chromedriver')", '  File "/Users/vishaljha/anaconda3/lib/python3.8/site-packages/selenium/webdriver/chrome/webdriver.py", line 76, in __init__', '    RemoteWebDriver.__init__(', '  File "/Users/vishaljha/anaconda3/lib/python3.8/site-packages/selenium/webdriver/remote/webdriver.py", line 157, in __init__', '    self.start_session(capabilities, browser_profile)', '  File "/Users/vishaljha/anaconda3/lib/python3.8/site-packages/selenium/webdriver/remote/webdriver.py", line 252, in start_session', '    response = self.execute(Command.NEW_SESSION, parameters)', '  File "/Users/vishaljha/anaconda3/lib/python3.8/site-packages/selenium/webdriver/remote/webdriver.py", line 321, in execute', '    self.error_handler.check_response(response)', '  File "/Users/vishaljha/anaconda3/lib/python3.8/site-packages/selenium/webdriver/remote/errorhandler.py", line 242, in check_response', '    raise exception_class(message, screen, stacktrace)', 'selenium.common.exceptions.SessionNotCreatedException: Message: session not created: This version of ChromeDriver only supports Chrome version 111', 'Current browser version is 114.0.5735.106 with binary path /Applications/Google Chrome.app/Contents/MacOS/Google Chrome', '', '', 'During handling of the above exception, another exception occurred:', '', 'Traceback (most recent call last):', '  File "/Users/vishaljha/anaconda3/lib/python3.8/site-packages/selenium/webdriver/common/service.py", line 72, in start', '    self.process = subprocess.Popen(cmd, env=self.env,', '  File "/Users/vishaljha/anaconda3/lib/python3.8/subprocess.py", line 854, in __init__', '    self._execute_child(args, executable, preexec_fn, close_fds,', '  File "/Users/vishaljha/anaconda3/lib/python3.8/subprocess.py", line 1702, in _execute_child', '    raise child_exception_type(errno_num, err_msg, err_filename)', "FileNotFoundError: [Errno 2] No such file or directory: 'chromedriver'", '', 'During handling of the above exception, another exception occurred:', '', 'Traceback (most recent call last):', '  File "/Users/vishaljha/Desktop/FINVANT/Alcubierre_Mk1_OMS/Backend/Scripts/AutoLoginKiteTicker.py", line 123, in auto_login_zerodha_ticker', '    key = automate_login(browser_url, user_id, password, totp_pin, debug=debug)', '  File "/Users/vishaljha/Desktop/FINVANT/Alcubierre_Mk1_OMS/Backend/Scripts/AutoLoginKiteTicker.py", line 40, in automate_login', '    browser = webdriver.Chrome(options = options)', '  File "/Users/vishaljha/anaconda3/lib/python3.8/site-packages/selenium/webdriver/chrome/webdriver.py", line 73, in __init__', '    self.service.start()', '  File "/Users/vishaljha/anaconda3/lib/python3.8/site-packages/selenium/webdriver/common/service.py", line 81, in start', '    raise WebDriverException(', "selenium.common.exceptions.WebDriverException: Message: 'chromedriver' executable needs to be in PATH. Please see https://sites.google.com/a/chromium.org/chromedriver/home", '']
root - INFO - 2023-06-15 01:32:39.696829 - Initialising LTP gather thread.
root - CRITICAL - CRITICAL ERROR:2023-06-15 01:32:40.075967 - Failed to load vital jsons for LTP gathering.
['Traceback (most recent call last):', '  File "/Users/vishaljha/Desktop/FINVANT/Alcubierre_Mk1_OMS/Backend/Scripts/GatherLTP.py", line 38, in __init__', '    instrument_token_json = json.load(f)', '  File "/Users/vishaljha/anaconda3/lib/python3.8/json/__init__.py", line 293, in load', '    return loads(fp.read(),', '  File "/Users/vishaljha/anaconda3/lib/python3.8/json/__init__.py", line 357, in loads', '    return _default_decoder.decode(s)', '  File "/Users/vishaljha/anaconda3/lib/python3.8/json/decoder.py", line 337, in decode', '    obj, end = self.raw_decode(s, idx=_w(s, 0).end())', '  File "/Users/vishaljha/anaconda3/lib/python3.8/json/decoder.py", line 355, in raw_decode', '    raise JSONDecodeError("Expecting value", s, err.value) from None', 'json.decoder.JSONDecodeError: Expecting value: line 3 column 1 (char 27)']
root - CRITICAL - CRITICAL ERROR:2023-06-15 01:32:40.213051 - Failed to initialise LTP gather module.
['Traceback (most recent call last):', '  File "/Users/vishaljha/Desktop/FINVANT/Alcubierre_Mk1_OMS/Backend/Scripts/GatherLTP.py", line 51, in __init__', '    self.instrument_token_list = instrument_token_json["instrument_tokens"]', "UnboundLocalError: local variable 'instrument_token_json' referenced before assignment"]
root - CRITICAL - CRITICAL ERROR:2023-06-15 01:32:40.339824 - Failed to start KWS thread.
['Traceback (most recent call last):', '  File "/Users/vishaljha/Desktop/FINVANT/Alcubierre_Mk1_OMS/Backend/Scripts/GatherLTP.py", line 77, in start', '    self.kws.on_ticks = self.on_ticks', "AttributeError: 'NoneType' object has no attribute 'on_ticks'"]
root - INFO - 2023-06-15 01:32:40.342895 - OMSB: Zerodha login for WG5235.
root - CRITICAL - CRITICAL ERROR:2023-06-15 01:32:41.976633 - OMSB: Failed auto login to kite for user:WG5235.
['Traceback (most recent call last):', '  File "/Users/vishaljha/Desktop/FINVANT/Alcubierre_Mk1_OMS/Backend/Scripts/AutoLoginZerodha.py", line 36, in automate_login', "    browser = webdriver.Chrome(options = options,executable_path='../Chrome/chromedriver')", '  File "/Users/vishaljha/anaconda3/lib/python3.8/site-packages/selenium/webdriver/chrome/webdriver.py", line 76, in __init__', '    RemoteWebDriver.__init__(', '  File "/Users/vishaljha/anaconda3/lib/python3.8/site-packages/selenium/webdriver/remote/webdriver.py", line 157, in __init__', '    self.start_session(capabilities, browser_profile)', '  File "/Users/vishaljha/anaconda3/lib/python3.8/site-packages/selenium/webdriver/remote/webdriver.py", line 252, in start_session', '    response = self.execute(Command.NEW_SESSION, parameters)', '  File "/Users/vishaljha/anaconda3/lib/python3.8/site-packages/selenium/webdriver/remote/webdriver.py", line 321, in execute', '    self.error_handler.check_response(response)', '  File "/Users/vishaljha/anaconda3/lib/python3.8/site-packages/selenium/webdriver/remote/errorhandler.py", line 242, in check_response', '    raise exception_class(message, screen, stacktrace)', 'selenium.common.exceptions.SessionNotCreatedException: Message: session not created: This version of ChromeDriver only supports Chrome version 111', 'Current browser version is 114.0.5735.106 with binary path /Applications/Google Chrome.app/Contents/MacOS/Google Chrome', '', '', 'During handling of the above exception, another exception occurred:', '', 'Traceback (most recent call last):', '  File "/Users/vishaljha/anaconda3/lib/python3.8/site-packages/selenium/webdriver/common/service.py", line 72, in start', '    self.process = subprocess.Popen(cmd, env=self.env,', '  File "/Users/vishaljha/anaconda3/lib/python3.8/subprocess.py", line 854, in __init__', '    self._execute_child(args, executable, preexec_fn, close_fds,', '  File "/Users/vishaljha/anaconda3/lib/python3.8/subprocess.py", line 1702, in _execute_child', '    raise child_exception_type(errno_num, err_msg, err_filename)', "FileNotFoundError: [Errno 2] No such file or directory: 'chromedriver'", '', 'During handling of the above exception, another exception occurred:', '', 'Traceback (most recent call last):', '  File "/Users/vishaljha/Desktop/FINVANT/Alcubierre_Mk1_OMS/Backend/Scripts/AutoLoginZerodha.py", line 117, in auto_login_zerodha', '    key = automate_login(browser_url, user_id, password, totp_pin)', '  File "/Users/vishaljha/Desktop/FINVANT/Alcubierre_Mk1_OMS/Backend/Scripts/AutoLoginZerodha.py", line 40, in automate_login', '    browser = webdriver.Chrome(options = options)', '  File "/Users/vishaljha/anaconda3/lib/python3.8/site-packages/selenium/webdriver/chrome/webdriver.py", line 73, in __init__', '    self.service.start()', '  File "/Users/vishaljha/anaconda3/lib/python3.8/site-packages/selenium/webdriver/common/service.py", line 81, in start', '    raise WebDriverException(', "selenium.common.exceptions.WebDriverException: Message: 'chromedriver' executable needs to be in PATH. Please see https://sites.google.com/a/chromium.org/chromedriver/home", '']
root - INFO - 2023-06-15 01:32:42.113547 - Order handler initialised.
root - INFO - 2023-06-15 01:32:42.273293 - Creating order handler sub threads.
root - INFO - 2023-06-15 01:32:42.273538 - Starting order handler sub threads.
root - INFO - 2023-06-15 01:32:42.964371 - Placed Zerodha Kite options order for:fin_user_1, instrument:NIFTY2361518600PE, qty:-50, transaction type:SELL, placed price:89.05, id:921.
root - INFO - 2023-06-15 01:32:43.832559 - 1371.7849254608154
root - INFO - 2023-06-15 01:32:44.463601 - Placed Zerodha Kite options order for:fin_user_1, instrument:NIFTY2361518600CE, qty:50, transaction type:BUY, placed price:77.0, id:608.
root - INFO - 2023-06-15 01:32:45.359494 - 1397.5131511688232
root - INFO - 2023-06-15 01:33:49.252799 - Finvant Alcubierre Mk1 OMS Backend turned on.
root - INFO - 2023-06-15 01:33:49.396897 - OMS Backend mainloop started.
root - INFO - 2023-06-15 01:33:49.548634 - User data obtained.
root - INFO - 2023-06-15 01:33:49.698270 - Spreads obtained.
root - INFO - 2023-06-15 01:33:49.831125 - Config file obtained.
root - INFO - 2023-06-15 01:33:49.955593 - OMSB: Logging in for backend kite ticker.
root - CRITICAL - CRITICAL ERROR:2023-06-15 01:33:52.172186 - OMSB: Failed auto login to kite ticker.
['Traceback (most recent call last):', '  File "/Users/vishaljha/Desktop/FINVANT/Alcubierre_Mk1_OMS/Backend/Scripts/AutoLoginKiteTicker.py", line 36, in automate_login', "    browser = webdriver.Chrome(options = options,executable_path='../Chrome/chromedriver')", '  File "/Users/vishaljha/anaconda3/lib/python3.8/site-packages/selenium/webdriver/chrome/webdriver.py", line 76, in __init__', '    RemoteWebDriver.__init__(', '  File "/Users/vishaljha/anaconda3/lib/python3.8/site-packages/selenium/webdriver/remote/webdriver.py", line 157, in __init__', '    self.start_session(capabilities, browser_profile)', '  File "/Users/vishaljha/anaconda3/lib/python3.8/site-packages/selenium/webdriver/remote/webdriver.py", line 252, in start_session', '    response = self.execute(Command.NEW_SESSION, parameters)', '  File "/Users/vishaljha/anaconda3/lib/python3.8/site-packages/selenium/webdriver/remote/webdriver.py", line 321, in execute', '    self.error_handler.check_response(response)', '  File "/Users/vishaljha/anaconda3/lib/python3.8/site-packages/selenium/webdriver/remote/errorhandler.py", line 242, in check_response', '    raise exception_class(message, screen, stacktrace)', 'selenium.common.exceptions.SessionNotCreatedException: Message: session not created: This version of ChromeDriver only supports Chrome version 111', 'Current browser version is 114.0.5735.106 with binary path /Applications/Google Chrome.app/Contents/MacOS/Google Chrome', '', '', 'During handling of the above exception, another exception occurred:', '', 'Traceback (most recent call last):', '  File "/Users/vishaljha/anaconda3/lib/python3.8/site-packages/selenium/webdriver/common/service.py", line 72, in start', '    self.process = subprocess.Popen(cmd, env=self.env,', '  File "/Users/vishaljha/anaconda3/lib/python3.8/subprocess.py", line 854, in __init__', '    self._execute_child(args, executable, preexec_fn, close_fds,', '  File "/Users/vishaljha/anaconda3/lib/python3.8/subprocess.py", line 1702, in _execute_child', '    raise child_exception_type(errno_num, err_msg, err_filename)', "FileNotFoundError: [Errno 2] No such file or directory: 'chromedriver'", '', 'During handling of the above exception, another exception occurred:', '', 'Traceback (most recent call last):', '  File "/Users/vishaljha/Desktop/FINVANT/Alcubierre_Mk1_OMS/Backend/Scripts/AutoLoginKiteTicker.py", line 123, in auto_login_zerodha_ticker', '    key = automate_login(browser_url, user_id, password, totp_pin, debug=debug)', '  File "/Users/vishaljha/Desktop/FINVANT/Alcubierre_Mk1_OMS/Backend/Scripts/AutoLoginKiteTicker.py", line 40, in automate_login', '    browser = webdriver.Chrome(options = options)', '  File "/Users/vishaljha/anaconda3/lib/python3.8/site-packages/selenium/webdriver/chrome/webdriver.py", line 73, in __init__', '    self.service.start()', '  File "/Users/vishaljha/anaconda3/lib/python3.8/site-packages/selenium/webdriver/common/service.py", line 81, in start', '    raise WebDriverException(', "selenium.common.exceptions.WebDriverException: Message: 'chromedriver' executable needs to be in PATH. Please see https://sites.google.com/a/chromium.org/chromedriver/home", '']
root - INFO - 2023-06-15 01:33:52.304987 - Initialising LTP gather thread.
root - CRITICAL - CRITICAL ERROR:2023-06-15 01:33:52.677801 - Failed to load vital jsons for LTP gathering.
['Traceback (most recent call last):', '  File "/Users/vishaljha/Desktop/FINVANT/Alcubierre_Mk1_OMS/Backend/Scripts/GatherLTP.py", line 38, in __init__', '    instrument_token_json = json.load(f)', '  File "/Users/vishaljha/anaconda3/lib/python3.8/json/__init__.py", line 293, in load', '    return loads(fp.read(),', '  File "/Users/vishaljha/anaconda3/lib/python3.8/json/__init__.py", line 357, in loads', '    return _default_decoder.decode(s)', '  File "/Users/vishaljha/anaconda3/lib/python3.8/json/decoder.py", line 337, in decode', '    obj, end = self.raw_decode(s, idx=_w(s, 0).end())', '  File "/Users/vishaljha/anaconda3/lib/python3.8/json/decoder.py", line 355, in raw_decode', '    raise JSONDecodeError("Expecting value", s, err.value) from None', 'json.decoder.JSONDecodeError: Expecting value: line 3 column 1 (char 27)']
root - CRITICAL - CRITICAL ERROR:2023-06-15 01:33:52.810267 - Failed to initialise LTP gather module.
['Traceback (most recent call last):', '  File "/Users/vishaljha/Desktop/FINVANT/Alcubierre_Mk1_OMS/Backend/Scripts/GatherLTP.py", line 51, in __init__', '    self.instrument_token_list = instrument_token_json["instrument_tokens"]', "UnboundLocalError: local variable 'instrument_token_json' referenced before assignment"]
root - CRITICAL - CRITICAL ERROR:2023-06-15 01:33:52.940184 - Failed to start KWS thread.
['Traceback (most recent call last):', '  File "/Users/vishaljha/Desktop/FINVANT/Alcubierre_Mk1_OMS/Backend/Scripts/GatherLTP.py", line 77, in start', '    self.kws.on_ticks = self.on_ticks', "AttributeError: 'NoneType' object has no attribute 'on_ticks'"]
root - INFO - 2023-06-15 01:33:52.940925 - OMSB: Zerodha login for WG5235.
root - CRITICAL - CRITICAL ERROR:2023-06-15 01:33:54.584111 - OMSB: Failed auto login to kite for user:WG5235.
['Traceback (most recent call last):', '  File "/Users/vishaljha/Desktop/FINVANT/Alcubierre_Mk1_OMS/Backend/Scripts/AutoLoginZerodha.py", line 36, in automate_login', "    browser = webdriver.Chrome(options = options,executable_path='../Chrome/chromedriver')", '  File "/Users/vishaljha/anaconda3/lib/python3.8/site-packages/selenium/webdriver/chrome/webdriver.py", line 76, in __init__', '    RemoteWebDriver.__init__(', '  File "/Users/vishaljha/anaconda3/lib/python3.8/site-packages/selenium/webdriver/remote/webdriver.py", line 157, in __init__', '    self.start_session(capabilities, browser_profile)', '  File "/Users/vishaljha/anaconda3/lib/python3.8/site-packages/selenium/webdriver/remote/webdriver.py", line 252, in start_session', '    response = self.execute(Command.NEW_SESSION, parameters)', '  File "/Users/vishaljha/anaconda3/lib/python3.8/site-packages/selenium/webdriver/remote/webdriver.py", line 321, in execute', '    self.error_handler.check_response(response)', '  File "/Users/vishaljha/anaconda3/lib/python3.8/site-packages/selenium/webdriver/remote/errorhandler.py", line 242, in check_response', '    raise exception_class(message, screen, stacktrace)', 'selenium.common.exceptions.SessionNotCreatedException: Message: session not created: This version of ChromeDriver only supports Chrome version 111', 'Current browser version is 114.0.5735.106 with binary path /Applications/Google Chrome.app/Contents/MacOS/Google Chrome', '', '', 'During handling of the above exception, another exception occurred:', '', 'Traceback (most recent call last):', '  File "/Users/vishaljha/anaconda3/lib/python3.8/site-packages/selenium/webdriver/common/service.py", line 72, in start', '    self.process = subprocess.Popen(cmd, env=self.env,', '  File "/Users/vishaljha/anaconda3/lib/python3.8/subprocess.py", line 854, in __init__', '    self._execute_child(args, executable, preexec_fn, close_fds,', '  File "/Users/vishaljha/anaconda3/lib/python3.8/subprocess.py", line 1702, in _execute_child', '    raise child_exception_type(errno_num, err_msg, err_filename)', "FileNotFoundError: [Errno 2] No such file or directory: 'chromedriver'", '', 'During handling of the above exception, another exception occurred:', '', 'Traceback (most recent call last):', '  File "/Users/vishaljha/Desktop/FINVANT/Alcubierre_Mk1_OMS/Backend/Scripts/AutoLoginZerodha.py", line 117, in auto_login_zerodha', '    key = automate_login(browser_url, user_id, password, totp_pin)', '  File "/Users/vishaljha/Desktop/FINVANT/Alcubierre_Mk1_OMS/Backend/Scripts/AutoLoginZerodha.py", line 40, in automate_login', '    browser = webdriver.Chrome(options = options)', '  File "/Users/vishaljha/anaconda3/lib/python3.8/site-packages/selenium/webdriver/chrome/webdriver.py", line 73, in __init__', '    self.service.start()', '  File "/Users/vishaljha/anaconda3/lib/python3.8/site-packages/selenium/webdriver/common/service.py", line 81, in start', '    raise WebDriverException(', "selenium.common.exceptions.WebDriverException: Message: 'chromedriver' executable needs to be in PATH. Please see https://sites.google.com/a/chromium.org/chromedriver/home", '']
root - INFO - 2023-06-15 01:33:54.820297 - Order handler initialised.
root - INFO - 2023-06-15 01:33:54.948017 - Creating order handler sub threads.
root - INFO - 2023-06-15 01:33:54.948192 - Starting order handler sub threads.
