root - INFO - 2023-06-04 13:33:08.730747 - Finvant Alcubierre Mk1 OMS Backend turned on.
root - INFO - 2023-06-04 13:33:08.874599 - OMS Backend mainloop started.
root - INFO - 2023-06-04 13:33:09.678559 - User data obtained.
root - INFO - 2023-06-04 13:33:11.051382 - Spreads obtained.
root - INFO - 2023-06-04 13:33:11.192308 - Config file obtained.
root - INFO - 2023-06-04 13:33:11.338494 - OMSB: Logging in for backend kite ticker.
root - CRITICAL - CRITICAL ERROR:2023-06-04 13:33:13.928167 - OMSB: Failed auto login to kite ticker.
['Traceback (most recent call last):', '  File "/Users/vishaljha/Desktop/FINVANT/Alcubierre_Mk1_OMS/Backend/Scripts/AutoLoginKiteTicker.py", line 36, in automate_login', "    browser = webdriver.Chrome(options = options,executable_path='../Chrome/chromedriver')", '  File "/Users/vishaljha/anaconda3/lib/python3.8/site-packages/selenium/webdriver/chrome/webdriver.py", line 76, in __init__', '    RemoteWebDriver.__init__(', '  File "/Users/vishaljha/anaconda3/lib/python3.8/site-packages/selenium/webdriver/remote/webdriver.py", line 157, in __init__', '    self.start_session(capabilities, browser_profile)', '  File "/Users/vishaljha/anaconda3/lib/python3.8/site-packages/selenium/webdriver/remote/webdriver.py", line 252, in start_session', '    response = self.execute(Command.NEW_SESSION, parameters)', '  File "/Users/vishaljha/anaconda3/lib/python3.8/site-packages/selenium/webdriver/remote/webdriver.py", line 321, in execute', '    self.error_handler.check_response(response)', '  File "/Users/vishaljha/anaconda3/lib/python3.8/site-packages/selenium/webdriver/remote/errorhandler.py", line 242, in check_response', '    raise exception_class(message, screen, stacktrace)', 'selenium.common.exceptions.SessionNotCreatedException: Message: session not created: This version of ChromeDriver only supports Chrome version 111', 'Current browser version is 113.0.5672.126 with binary path /Applications/Google Chrome.app/Contents/MacOS/Google Chrome', '', '', 'During handling of the above exception, another exception occurred:', '', 'Traceback (most recent call last):', '  File "/Users/vishaljha/anaconda3/lib/python3.8/site-packages/selenium/webdriver/common/service.py", line 72, in start', '    self.process = subprocess.Popen(cmd, env=self.env,', '  File "/Users/vishaljha/anaconda3/lib/python3.8/subprocess.py", line 854, in __init__', '    self._execute_child(args, executable, preexec_fn, close_fds,', '  File "/Users/vishaljha/anaconda3/lib/python3.8/subprocess.py", line 1702, in _execute_child', '    raise child_exception_type(errno_num, err_msg, err_filename)', "FileNotFoundError: [Errno 2] No such file or directory: 'chromedriver'", '', 'During handling of the above exception, another exception occurred:', '', 'Traceback (most recent call last):', '  File "/Users/vishaljha/Desktop/FINVANT/Alcubierre_Mk1_OMS/Backend/Scripts/AutoLoginKiteTicker.py", line 123, in auto_login_zerodha_ticker', '    key = automate_login(browser_url, user_id, password, totp_pin, debug=debug)', '  File "/Users/vishaljha/Desktop/FINVANT/Alcubierre_Mk1_OMS/Backend/Scripts/AutoLoginKiteTicker.py", line 40, in automate_login', '    browser = webdriver.Chrome(options = options)', '  File "/Users/vishaljha/anaconda3/lib/python3.8/site-packages/selenium/webdriver/chrome/webdriver.py", line 73, in __init__', '    self.service.start()', '  File "/Users/vishaljha/anaconda3/lib/python3.8/site-packages/selenium/webdriver/common/service.py", line 81, in start', '    raise WebDriverException(', "selenium.common.exceptions.WebDriverException: Message: 'chromedriver' executable needs to be in PATH. Please see https://sites.google.com/a/chromium.org/chromedriver/home", '']
root - INFO - 2023-06-04 13:33:14.056182 - Initialising LTP gather thread.
root - INFO - 2023-06-04 13:33:14.614737 - Attempting XTS login.
root - INFO - 2023-06-04 13:33:14.617365 - OMSB: Zerodha login for WG5235.
root - CRITICAL - CRITICAL ERROR:2023-06-04 13:33:14.617823 - Failed to start KWS thread.
['Traceback (most recent call last):', '  File "/Users/vishaljha/Desktop/FINVANT/Alcubierre_Mk1_OMS/Backend/Scripts/GatherLTP.py", line 77, in start', '    self.kws.on_ticks = self.on_ticks', "AttributeError: 'NoneType' object has no attribute 'on_ticks'"]
root - INFO - 2023-06-04 13:33:14.621499 - OMSB: Zerodha login for TL9951.
root - INFO - 2023-06-04 13:33:14.887791 - XTS login token: eyJhbGciOiJIUzI1NiIsInR5cCI6IkpXVCJ9.eyJ1c2VySUQiOiJIREwwMDA2XzU5NUU0NzY4RTFEM0ZCNDFCNUUyODIiLCJwdWJsaWNLZXkiOiI1OTVlNDc2OGUxZDNmYjQxYjVlMjgyIiwiaWF0IjoxNjg1ODY1Nzk0LCJleHAiOjE2ODU5NTIxOTR9.kKLLz6IKv3yjEWc-vhzGscvYy9lsCjT9F0qwch7spLc.
root - INFO - 2023-06-04 13:33:15.021965 - ODIN login for NB01.
root - INFO - 2023-06-04 13:33:15.157230 - BPWealth login for AHO7763.
root - CRITICAL - CRITICAL ERROR:2023-06-04 13:33:16.355105 - OMSB: Failed auto login to kite for user:TL9951.
['Traceback (most recent call last):', '  File "/Users/vishaljha/Desktop/FINVANT/Alcubierre_Mk1_OMS/Backend/Scripts/AutoLoginZerodha.py", line 36, in automate_login', "    browser = webdriver.Chrome(options = options,executable_path='../Chrome/chromedriver')", '  File "/Users/vishaljha/anaconda3/lib/python3.8/site-packages/selenium/webdriver/chrome/webdriver.py", line 76, in __init__', '    RemoteWebDriver.__init__(', '  File "/Users/vishaljha/anaconda3/lib/python3.8/site-packages/selenium/webdriver/remote/webdriver.py", line 157, in __init__', '    self.start_session(capabilities, browser_profile)', '  File "/Users/vishaljha/anaconda3/lib/python3.8/site-packages/selenium/webdriver/remote/webdriver.py", line 252, in start_session', '    response = self.execute(Command.NEW_SESSION, parameters)', '  File "/Users/vishaljha/anaconda3/lib/python3.8/site-packages/selenium/webdriver/remote/webdriver.py", line 321, in execute', '    self.error_handler.check_response(response)', '  File "/Users/vishaljha/anaconda3/lib/python3.8/site-packages/selenium/webdriver/remote/errorhandler.py", line 242, in check_response', '    raise exception_class(message, screen, stacktrace)', 'selenium.common.exceptions.SessionNotCreatedException: Message: session not created: This version of ChromeDriver only supports Chrome version 111', 'Current browser version is 113.0.5672.126 with binary path /Applications/Google Chrome.app/Contents/MacOS/Google Chrome', '', '', 'During handling of the above exception, another exception occurred:', '', 'Traceback (most recent call last):', '  File "/Users/vishaljha/anaconda3/lib/python3.8/site-packages/selenium/webdriver/common/service.py", line 72, in start', '    self.process = subprocess.Popen(cmd, env=self.env,', '  File "/Users/vishaljha/anaconda3/lib/python3.8/subprocess.py", line 854, in __init__', '    self._execute_child(args, executable, preexec_fn, close_fds,', '  File "/Users/vishaljha/anaconda3/lib/python3.8/subprocess.py", line 1702, in _execute_child', '    raise child_exception_type(errno_num, err_msg, err_filename)', "FileNotFoundError: [Errno 2] No such file or directory: 'chromedriver'", '', 'During handling of the above exception, another exception occurred:', '', 'Traceback (most recent call last):', '  File "/Users/vishaljha/Desktop/FINVANT/Alcubierre_Mk1_OMS/Backend/Scripts/AutoLoginZerodha.py", line 117, in auto_login_zerodha', '    key = automate_login(browser_url, user_id, password, totp_pin)', '  File "/Users/vishaljha/Desktop/FINVANT/Alcubierre_Mk1_OMS/Backend/Scripts/AutoLoginZerodha.py", line 40, in automate_login', '    browser = webdriver.Chrome(options = options)', '  File "/Users/vishaljha/anaconda3/lib/python3.8/site-packages/selenium/webdriver/chrome/webdriver.py", line 73, in __init__', '    self.service.start()', '  File "/Users/vishaljha/anaconda3/lib/python3.8/site-packages/selenium/webdriver/common/service.py", line 81, in start', '    raise WebDriverException(', "selenium.common.exceptions.WebDriverException: Message: 'chromedriver' executable needs to be in PATH. Please see https://sites.google.com/a/chromium.org/chromedriver/home", '']
root - CRITICAL - CRITICAL ERROR:2023-06-04 13:33:16.395207 - OMSB: Failed auto login to kite for user:WG5235.
['Traceback (most recent call last):', '  File "/Users/vishaljha/Desktop/FINVANT/Alcubierre_Mk1_OMS/Backend/Scripts/AutoLoginZerodha.py", line 36, in automate_login', "    browser = webdriver.Chrome(options = options,executable_path='../Chrome/chromedriver')", '  File "/Users/vishaljha/anaconda3/lib/python3.8/site-packages/selenium/webdriver/chrome/webdriver.py", line 76, in __init__', '    RemoteWebDriver.__init__(', '  File "/Users/vishaljha/anaconda3/lib/python3.8/site-packages/selenium/webdriver/remote/webdriver.py", line 157, in __init__', '    self.start_session(capabilities, browser_profile)', '  File "/Users/vishaljha/anaconda3/lib/python3.8/site-packages/selenium/webdriver/remote/webdriver.py", line 252, in start_session', '    response = self.execute(Command.NEW_SESSION, parameters)', '  File "/Users/vishaljha/anaconda3/lib/python3.8/site-packages/selenium/webdriver/remote/webdriver.py", line 321, in execute', '    self.error_handler.check_response(response)', '  File "/Users/vishaljha/anaconda3/lib/python3.8/site-packages/selenium/webdriver/remote/errorhandler.py", line 242, in check_response', '    raise exception_class(message, screen, stacktrace)', 'selenium.common.exceptions.SessionNotCreatedException: Message: session not created: This version of ChromeDriver only supports Chrome version 111', 'Current browser version is 113.0.5672.126 with binary path /Applications/Google Chrome.app/Contents/MacOS/Google Chrome', '', '', 'During handling of the above exception, another exception occurred:', '', 'Traceback (most recent call last):', '  File "/Users/vishaljha/anaconda3/lib/python3.8/site-packages/selenium/webdriver/common/service.py", line 72, in start', '    self.process = subprocess.Popen(cmd, env=self.env,', '  File "/Users/vishaljha/anaconda3/lib/python3.8/subprocess.py", line 854, in __init__', '    self._execute_child(args, executable, preexec_fn, close_fds,', '  File "/Users/vishaljha/anaconda3/lib/python3.8/subprocess.py", line 1702, in _execute_child', '    raise child_exception_type(errno_num, err_msg, err_filename)', "FileNotFoundError: [Errno 2] No such file or directory: 'chromedriver'", '', 'During handling of the above exception, another exception occurred:', '', 'Traceback (most recent call last):', '  File "/Users/vishaljha/Desktop/FINVANT/Alcubierre_Mk1_OMS/Backend/Scripts/AutoLoginZerodha.py", line 117, in auto_login_zerodha', '    key = automate_login(browser_url, user_id, password, totp_pin)', '  File "/Users/vishaljha/Desktop/FINVANT/Alcubierre_Mk1_OMS/Backend/Scripts/AutoLoginZerodha.py", line 40, in automate_login', '    browser = webdriver.Chrome(options = options)', '  File "/Users/vishaljha/anaconda3/lib/python3.8/site-packages/selenium/webdriver/chrome/webdriver.py", line 73, in __init__', '    self.service.start()', '  File "/Users/vishaljha/anaconda3/lib/python3.8/site-packages/selenium/webdriver/common/service.py", line 81, in start', '    raise WebDriverException(', "selenium.common.exceptions.WebDriverException: Message: 'chromedriver' executable needs to be in PATH. Please see https://sites.google.com/a/chromium.org/chromedriver/home", '']
root - INFO - 2023-06-04 13:33:16.499415 - OMSB: Zerodha login for RL7826.
root - INFO - 2023-06-04 13:33:16.562437 - OMSB: Zerodha login for FS3611.
root - CRITICAL - CRITICAL ERROR:2023-06-04 13:33:17.373967 - ODIN login failed for NB01. Error: 'data'.
['Traceback (most recent call last):', '  File "/Users/vishaljha/Desktop/FINVANT/Alcubierre_Mk1_OMS/Backend/Scripts/AutoLoginOdin.py", line 48, in login', '    access_token = r["data"]["access_token"]', "KeyError: 'data'"]
root - INFO - 2023-06-04 13:33:17.492424 - ODIN login for AKV2922.
root - INFO - 2023-06-04 13:33:18.033050 - ODIN login succesful for AKV2922.
root - CRITICAL - CRITICAL ERROR:2023-06-04 13:33:18.122438 - OMSB: Failed auto login to kite for user:RL7826.
['Traceback (most recent call last):', '  File "/Users/vishaljha/Desktop/FINVANT/Alcubierre_Mk1_OMS/Backend/Scripts/AutoLoginZerodha.py", line 36, in automate_login', "    browser = webdriver.Chrome(options = options,executable_path='../Chrome/chromedriver')", '  File "/Users/vishaljha/anaconda3/lib/python3.8/site-packages/selenium/webdriver/chrome/webdriver.py", line 76, in __init__', '    RemoteWebDriver.__init__(', '  File "/Users/vishaljha/anaconda3/lib/python3.8/site-packages/selenium/webdriver/remote/webdriver.py", line 157, in __init__', '    self.start_session(capabilities, browser_profile)', '  File "/Users/vishaljha/anaconda3/lib/python3.8/site-packages/selenium/webdriver/remote/webdriver.py", line 252, in start_session', '    response = self.execute(Command.NEW_SESSION, parameters)', '  File "/Users/vishaljha/anaconda3/lib/python3.8/site-packages/selenium/webdriver/remote/webdriver.py", line 321, in execute', '    self.error_handler.check_response(response)', '  File "/Users/vishaljha/anaconda3/lib/python3.8/site-packages/selenium/webdriver/remote/errorhandler.py", line 242, in check_response', '    raise exception_class(message, screen, stacktrace)', 'selenium.common.exceptions.SessionNotCreatedException: Message: session not created: This version of ChromeDriver only supports Chrome version 111', 'Current browser version is 113.0.5672.126 with binary path /Applications/Google Chrome.app/Contents/MacOS/Google Chrome', '', '', 'During handling of the above exception, another exception occurred:', '', 'Traceback (most recent call last):', '  File "/Users/vishaljha/anaconda3/lib/python3.8/site-packages/selenium/webdriver/common/service.py", line 72, in start', '    self.process = subprocess.Popen(cmd, env=self.env,', '  File "/Users/vishaljha/anaconda3/lib/python3.8/subprocess.py", line 854, in __init__', '    self._execute_child(args, executable, preexec_fn, close_fds,', '  File "/Users/vishaljha/anaconda3/lib/python3.8/subprocess.py", line 1702, in _execute_child', '    raise child_exception_type(errno_num, err_msg, err_filename)', "FileNotFoundError: [Errno 2] No such file or directory: 'chromedriver'", '', 'During handling of the above exception, another exception occurred:', '', 'Traceback (most recent call last):', '  File "/Users/vishaljha/Desktop/FINVANT/Alcubierre_Mk1_OMS/Backend/Scripts/AutoLoginZerodha.py", line 117, in auto_login_zerodha', '    key = automate_login(browser_url, user_id, password, totp_pin)', '  File "/Users/vishaljha/Desktop/FINVANT/Alcubierre_Mk1_OMS/Backend/Scripts/AutoLoginZerodha.py", line 40, in automate_login', '    browser = webdriver.Chrome(options = options)', '  File "/Users/vishaljha/anaconda3/lib/python3.8/site-packages/selenium/webdriver/chrome/webdriver.py", line 73, in __init__', '    self.service.start()', '  File "/Users/vishaljha/anaconda3/lib/python3.8/site-packages/selenium/webdriver/common/service.py", line 81, in start', '    raise WebDriverException(', "selenium.common.exceptions.WebDriverException: Message: 'chromedriver' executable needs to be in PATH. Please see https://sites.google.com/a/chromium.org/chromedriver/home", '']
root - CRITICAL - CRITICAL ERROR:2023-06-04 13:33:18.171055 - OMSB: Failed auto login to kite for user:FS3611.
['Traceback (most recent call last):', '  File "/Users/vishaljha/Desktop/FINVANT/Alcubierre_Mk1_OMS/Backend/Scripts/AutoLoginZerodha.py", line 36, in automate_login', "    browser = webdriver.Chrome(options = options,executable_path='../Chrome/chromedriver')", '  File "/Users/vishaljha/anaconda3/lib/python3.8/site-packages/selenium/webdriver/chrome/webdriver.py", line 76, in __init__', '    RemoteWebDriver.__init__(', '  File "/Users/vishaljha/anaconda3/lib/python3.8/site-packages/selenium/webdriver/remote/webdriver.py", line 157, in __init__', '    self.start_session(capabilities, browser_profile)', '  File "/Users/vishaljha/anaconda3/lib/python3.8/site-packages/selenium/webdriver/remote/webdriver.py", line 252, in start_session', '    response = self.execute(Command.NEW_SESSION, parameters)', '  File "/Users/vishaljha/anaconda3/lib/python3.8/site-packages/selenium/webdriver/remote/webdriver.py", line 321, in execute', '    self.error_handler.check_response(response)', '  File "/Users/vishaljha/anaconda3/lib/python3.8/site-packages/selenium/webdriver/remote/errorhandler.py", line 242, in check_response', '    raise exception_class(message, screen, stacktrace)', 'selenium.common.exceptions.SessionNotCreatedException: Message: session not created: This version of ChromeDriver only supports Chrome version 111', 'Current browser version is 113.0.5672.126 with binary path /Applications/Google Chrome.app/Contents/MacOS/Google Chrome', '', '', 'During handling of the above exception, another exception occurred:', '', 'Traceback (most recent call last):', '  File "/Users/vishaljha/anaconda3/lib/python3.8/site-packages/selenium/webdriver/common/service.py", line 72, in start', '    self.process = subprocess.Popen(cmd, env=self.env,', '  File "/Users/vishaljha/anaconda3/lib/python3.8/subprocess.py", line 854, in __init__', '    self._execute_child(args, executable, preexec_fn, close_fds,', '  File "/Users/vishaljha/anaconda3/lib/python3.8/subprocess.py", line 1702, in _execute_child', '    raise child_exception_type(errno_num, err_msg, err_filename)', "FileNotFoundError: [Errno 2] No such file or directory: 'chromedriver'", '', 'During handling of the above exception, another exception occurred:', '', 'Traceback (most recent call last):', '  File "/Users/vishaljha/Desktop/FINVANT/Alcubierre_Mk1_OMS/Backend/Scripts/AutoLoginZerodha.py", line 117, in auto_login_zerodha', '    key = automate_login(browser_url, user_id, password, totp_pin)', '  File "/Users/vishaljha/Desktop/FINVANT/Alcubierre_Mk1_OMS/Backend/Scripts/AutoLoginZerodha.py", line 40, in automate_login', '    browser = webdriver.Chrome(options = options)', '  File "/Users/vishaljha/anaconda3/lib/python3.8/site-packages/selenium/webdriver/chrome/webdriver.py", line 73, in __init__', '    self.service.start()', '  File "/Users/vishaljha/anaconda3/lib/python3.8/site-packages/selenium/webdriver/common/service.py", line 81, in start', '    raise WebDriverException(', "selenium.common.exceptions.WebDriverException: Message: 'chromedriver' executable needs to be in PATH. Please see https://sites.google.com/a/chromium.org/chromedriver/home", '']
root - INFO - 2023-06-04 13:33:18.198513 - ODIN login for S0201.
root - INFO - 2023-06-04 13:33:18.267304 - OMSB: Zerodha login for YU5680.
root - INFO - 2023-06-04 13:33:18.325074 - OMSB: Zerodha login for VR1418.
root - CRITICAL - CRITICAL ERROR:2023-06-04 13:50:38.273338 - ODIN login failed for S0201. Error: 'data'.
['Traceback (most recent call last):', '  File "/Users/vishaljha/Desktop/FINVANT/Alcubierre_Mk1_OMS/Backend/Scripts/AutoLoginOdin.py", line 48, in login', '    access_token = r["data"]["access_token"]', "KeyError: 'data'"]
root - INFO - 2023-06-04 13:50:40.828891 - ODIN login for S0201.
root - CRITICAL - CRITICAL ERROR:2023-06-04 13:50:42.159407 - OMSB: Failed auto login to kite for user:VR1418.
['Traceback (most recent call last):', '  File "/Users/vishaljha/Desktop/FINVANT/Alcubierre_Mk1_OMS/Backend/Scripts/AutoLoginZerodha.py", line 36, in automate_login', "    browser = webdriver.Chrome(options = options,executable_path='../Chrome/chromedriver')", '  File "/Users/vishaljha/anaconda3/lib/python3.8/site-packages/selenium/webdriver/chrome/webdriver.py", line 76, in __init__', '    RemoteWebDriver.__init__(', '  File "/Users/vishaljha/anaconda3/lib/python3.8/site-packages/selenium/webdriver/remote/webdriver.py", line 157, in __init__', '    self.start_session(capabilities, browser_profile)', '  File "/Users/vishaljha/anaconda3/lib/python3.8/site-packages/selenium/webdriver/remote/webdriver.py", line 252, in start_session', '    response = self.execute(Command.NEW_SESSION, parameters)', '  File "/Users/vishaljha/anaconda3/lib/python3.8/site-packages/selenium/webdriver/remote/webdriver.py", line 321, in execute', '    self.error_handler.check_response(response)', '  File "/Users/vishaljha/anaconda3/lib/python3.8/site-packages/selenium/webdriver/remote/errorhandler.py", line 242, in check_response', '    raise exception_class(message, screen, stacktrace)', 'selenium.common.exceptions.SessionNotCreatedException: Message: session not created: This version of ChromeDriver only supports Chrome version 111', 'Current browser version is 113.0.5672.126 with binary path /Applications/Google Chrome.app/Contents/MacOS/Google Chrome', '', '', 'During handling of the above exception, another exception occurred:', '', 'Traceback (most recent call last):', '  File "/Users/vishaljha/anaconda3/lib/python3.8/site-packages/selenium/webdriver/common/service.py", line 72, in start', '    self.process = subprocess.Popen(cmd, env=self.env,', '  File "/Users/vishaljha/anaconda3/lib/python3.8/subprocess.py", line 854, in __init__', '    self._execute_child(args, executable, preexec_fn, close_fds,', '  File "/Users/vishaljha/anaconda3/lib/python3.8/subprocess.py", line 1702, in _execute_child', '    raise child_exception_type(errno_num, err_msg, err_filename)', "FileNotFoundError: [Errno 2] No such file or directory: 'chromedriver'", '', 'During handling of the above exception, another exception occurred:', '', 'Traceback (most recent call last):', '  File "/Users/vishaljha/Desktop/FINVANT/Alcubierre_Mk1_OMS/Backend/Scripts/AutoLoginZerodha.py", line 117, in auto_login_zerodha', '    key = automate_login(browser_url, user_id, password, totp_pin)', '  File "/Users/vishaljha/Desktop/FINVANT/Alcubierre_Mk1_OMS/Backend/Scripts/AutoLoginZerodha.py", line 40, in automate_login', '    browser = webdriver.Chrome(options = options)', '  File "/Users/vishaljha/anaconda3/lib/python3.8/site-packages/selenium/webdriver/chrome/webdriver.py", line 73, in __init__', '    self.service.start()', '  File "/Users/vishaljha/anaconda3/lib/python3.8/site-packages/selenium/webdriver/common/service.py", line 81, in start', '    raise WebDriverException(', "selenium.common.exceptions.WebDriverException: Message: 'chromedriver' executable needs to be in PATH. Please see https://sites.google.com/a/chromium.org/chromedriver/home", '']
root - CRITICAL - CRITICAL ERROR:2023-06-04 13:50:42.161358 - OMSB: Failed auto login to kite for user:YU5680.
['Traceback (most recent call last):', '  File "/Users/vishaljha/Desktop/FINVANT/Alcubierre_Mk1_OMS/Backend/Scripts/AutoLoginZerodha.py", line 36, in automate_login', "    browser = webdriver.Chrome(options = options,executable_path='../Chrome/chromedriver')", '  File "/Users/vishaljha/anaconda3/lib/python3.8/site-packages/selenium/webdriver/chrome/webdriver.py", line 76, in __init__', '    RemoteWebDriver.__init__(', '  File "/Users/vishaljha/anaconda3/lib/python3.8/site-packages/selenium/webdriver/remote/webdriver.py", line 157, in __init__', '    self.start_session(capabilities, browser_profile)', '  File "/Users/vishaljha/anaconda3/lib/python3.8/site-packages/selenium/webdriver/remote/webdriver.py", line 252, in start_session', '    response = self.execute(Command.NEW_SESSION, parameters)', '  File "/Users/vishaljha/anaconda3/lib/python3.8/site-packages/selenium/webdriver/remote/webdriver.py", line 321, in execute', '    self.error_handler.check_response(response)', '  File "/Users/vishaljha/anaconda3/lib/python3.8/site-packages/selenium/webdriver/remote/errorhandler.py", line 242, in check_response', '    raise exception_class(message, screen, stacktrace)', 'selenium.common.exceptions.SessionNotCreatedException: Message: session not created: This version of ChromeDriver only supports Chrome version 111', 'Current browser version is 113.0.5672.126 with binary path /Applications/Google Chrome.app/Contents/MacOS/Google Chrome', '', '', 'During handling of the above exception, another exception occurred:', '', 'Traceback (most recent call last):', '  File "/Users/vishaljha/anaconda3/lib/python3.8/site-packages/selenium/webdriver/common/service.py", line 72, in start', '    self.process = subprocess.Popen(cmd, env=self.env,', '  File "/Users/vishaljha/anaconda3/lib/python3.8/subprocess.py", line 854, in __init__', '    self._execute_child(args, executable, preexec_fn, close_fds,', '  File "/Users/vishaljha/anaconda3/lib/python3.8/subprocess.py", line 1702, in _execute_child', '    raise child_exception_type(errno_num, err_msg, err_filename)', "FileNotFoundError: [Errno 2] No such file or directory: 'chromedriver'", '', 'During handling of the above exception, another exception occurred:', '', 'Traceback (most recent call last):', '  File "/Users/vishaljha/Desktop/FINVANT/Alcubierre_Mk1_OMS/Backend/Scripts/AutoLoginZerodha.py", line 117, in auto_login_zerodha', '    key = automate_login(browser_url, user_id, password, totp_pin)', '  File "/Users/vishaljha/Desktop/FINVANT/Alcubierre_Mk1_OMS/Backend/Scripts/AutoLoginZerodha.py", line 40, in automate_login', '    browser = webdriver.Chrome(options = options)', '  File "/Users/vishaljha/anaconda3/lib/python3.8/site-packages/selenium/webdriver/chrome/webdriver.py", line 73, in __init__', '    self.service.start()', '  File "/Users/vishaljha/anaconda3/lib/python3.8/site-packages/selenium/webdriver/common/service.py", line 81, in start', '    raise WebDriverException(', "selenium.common.exceptions.WebDriverException: Message: 'chromedriver' executable needs to be in PATH. Please see https://sites.google.com/a/chromium.org/chromedriver/home", '']
root - INFO - 2023-06-04 13:50:44.603323 - OMSB: Zerodha login for BQ1244.
root - INFO - 2023-06-04 13:50:44.608408 - OMSB: Zerodha login for WG5235.
root - CRITICAL - CRITICAL ERROR:2023-06-04 13:50:48.508013 - OMSB: Failed auto login to kite for user:WG5235.
['Traceback (most recent call last):', '  File "/Users/vishaljha/Desktop/FINVANT/Alcubierre_Mk1_OMS/Backend/Scripts/AutoLoginZerodha.py", line 36, in automate_login', "    browser = webdriver.Chrome(options = options,executable_path='../Chrome/chromedriver')", '  File "/Users/vishaljha/anaconda3/lib/python3.8/site-packages/selenium/webdriver/chrome/webdriver.py", line 76, in __init__', '    RemoteWebDriver.__init__(', '  File "/Users/vishaljha/anaconda3/lib/python3.8/site-packages/selenium/webdriver/remote/webdriver.py", line 157, in __init__', '    self.start_session(capabilities, browser_profile)', '  File "/Users/vishaljha/anaconda3/lib/python3.8/site-packages/selenium/webdriver/remote/webdriver.py", line 252, in start_session', '    response = self.execute(Command.NEW_SESSION, parameters)', '  File "/Users/vishaljha/anaconda3/lib/python3.8/site-packages/selenium/webdriver/remote/webdriver.py", line 321, in execute', '    self.error_handler.check_response(response)', '  File "/Users/vishaljha/anaconda3/lib/python3.8/site-packages/selenium/webdriver/remote/errorhandler.py", line 242, in check_response', '    raise exception_class(message, screen, stacktrace)', 'selenium.common.exceptions.SessionNotCreatedException: Message: session not created: This version of ChromeDriver only supports Chrome version 111', 'Current browser version is 113.0.5672.126 with binary path /Applications/Google Chrome.app/Contents/MacOS/Google Chrome', '', '', 'During handling of the above exception, another exception occurred:', '', 'Traceback (most recent call last):', '  File "/Users/vishaljha/anaconda3/lib/python3.8/site-packages/selenium/webdriver/common/service.py", line 72, in start', '    self.process = subprocess.Popen(cmd, env=self.env,', '  File "/Users/vishaljha/anaconda3/lib/python3.8/subprocess.py", line 854, in __init__', '    self._execute_child(args, executable, preexec_fn, close_fds,', '  File "/Users/vishaljha/anaconda3/lib/python3.8/subprocess.py", line 1702, in _execute_child', '    raise child_exception_type(errno_num, err_msg, err_filename)', "FileNotFoundError: [Errno 2] No such file or directory: 'chromedriver'", '', 'During handling of the above exception, another exception occurred:', '', 'Traceback (most recent call last):', '  File "/Users/vishaljha/Desktop/FINVANT/Alcubierre_Mk1_OMS/Backend/Scripts/AutoLoginZerodha.py", line 117, in auto_login_zerodha', '    key = automate_login(browser_url, user_id, password, totp_pin)', '  File "/Users/vishaljha/Desktop/FINVANT/Alcubierre_Mk1_OMS/Backend/Scripts/AutoLoginZerodha.py", line 40, in automate_login', '    browser = webdriver.Chrome(options = options)', '  File "/Users/vishaljha/anaconda3/lib/python3.8/site-packages/selenium/webdriver/chrome/webdriver.py", line 73, in __init__', '    self.service.start()', '  File "/Users/vishaljha/anaconda3/lib/python3.8/site-packages/selenium/webdriver/common/service.py", line 81, in start', '    raise WebDriverException(', "selenium.common.exceptions.WebDriverException: Message: 'chromedriver' executable needs to be in PATH. Please see https://sites.google.com/a/chromium.org/chromedriver/home", '']
root - CRITICAL - CRITICAL ERROR:2023-06-04 13:50:48.509574 - OMSB: Failed auto login to kite for user:BQ1244.
['Traceback (most recent call last):', '  File "/Users/vishaljha/Desktop/FINVANT/Alcubierre_Mk1_OMS/Backend/Scripts/AutoLoginZerodha.py", line 36, in automate_login', "    browser = webdriver.Chrome(options = options,executable_path='../Chrome/chromedriver')", '  File "/Users/vishaljha/anaconda3/lib/python3.8/site-packages/selenium/webdriver/chrome/webdriver.py", line 76, in __init__', '    RemoteWebDriver.__init__(', '  File "/Users/vishaljha/anaconda3/lib/python3.8/site-packages/selenium/webdriver/remote/webdriver.py", line 157, in __init__', '    self.start_session(capabilities, browser_profile)', '  File "/Users/vishaljha/anaconda3/lib/python3.8/site-packages/selenium/webdriver/remote/webdriver.py", line 252, in start_session', '    response = self.execute(Command.NEW_SESSION, parameters)', '  File "/Users/vishaljha/anaconda3/lib/python3.8/site-packages/selenium/webdriver/remote/webdriver.py", line 321, in execute', '    self.error_handler.check_response(response)', '  File "/Users/vishaljha/anaconda3/lib/python3.8/site-packages/selenium/webdriver/remote/errorhandler.py", line 242, in check_response', '    raise exception_class(message, screen, stacktrace)', 'selenium.common.exceptions.SessionNotCreatedException: Message: session not created: This version of ChromeDriver only supports Chrome version 111', 'Current browser version is 113.0.5672.126 with binary path /Applications/Google Chrome.app/Contents/MacOS/Google Chrome', '', '', 'During handling of the above exception, another exception occurred:', '', 'Traceback (most recent call last):', '  File "/Users/vishaljha/anaconda3/lib/python3.8/site-packages/selenium/webdriver/common/service.py", line 72, in start', '    self.process = subprocess.Popen(cmd, env=self.env,', '  File "/Users/vishaljha/anaconda3/lib/python3.8/subprocess.py", line 854, in __init__', '    self._execute_child(args, executable, preexec_fn, close_fds,', '  File "/Users/vishaljha/anaconda3/lib/python3.8/subprocess.py", line 1702, in _execute_child', '    raise child_exception_type(errno_num, err_msg, err_filename)', "FileNotFoundError: [Errno 2] No such file or directory: 'chromedriver'", '', 'During handling of the above exception, another exception occurred:', '', 'Traceback (most recent call last):', '  File "/Users/vishaljha/Desktop/FINVANT/Alcubierre_Mk1_OMS/Backend/Scripts/AutoLoginZerodha.py", line 117, in auto_login_zerodha', '    key = automate_login(browser_url, user_id, password, totp_pin)', '  File "/Users/vishaljha/Desktop/FINVANT/Alcubierre_Mk1_OMS/Backend/Scripts/AutoLoginZerodha.py", line 40, in automate_login', '    browser = webdriver.Chrome(options = options)', '  File "/Users/vishaljha/anaconda3/lib/python3.8/site-packages/selenium/webdriver/chrome/webdriver.py", line 73, in __init__', '    self.service.start()', '  File "/Users/vishaljha/anaconda3/lib/python3.8/site-packages/selenium/webdriver/common/service.py", line 81, in start', '    raise WebDriverException(', "selenium.common.exceptions.WebDriverException: Message: 'chromedriver' executable needs to be in PATH. Please see https://sites.google.com/a/chromium.org/chromedriver/home", '']
root - INFO - 2023-06-04 13:50:51.306505 - OMSB: Zerodha login for CJ4922.
root - CRITICAL - CRITICAL ERROR:2023-06-04 13:50:52.695121 - ODIN login failed for S0201. Error: 'data'.
['Traceback (most recent call last):', '  File "/Users/vishaljha/Desktop/FINVANT/Alcubierre_Mk1_OMS/Backend/Scripts/AutoLoginOdin.py", line 48, in login', '    access_token = r["data"]["access_token"]', "KeyError: 'data'"]
root - INFO - 2023-06-04 13:50:54.423829 - BPWealth login for AHO7706.
root - CRITICAL - CRITICAL ERROR:2023-06-04 13:50:54.521021 - OMSB: Failed auto login to kite for user:CJ4922.
['Traceback (most recent call last):', '  File "/Users/vishaljha/Desktop/FINVANT/Alcubierre_Mk1_OMS/Backend/Scripts/AutoLoginZerodha.py", line 36, in automate_login', "    browser = webdriver.Chrome(options = options,executable_path='../Chrome/chromedriver')", '  File "/Users/vishaljha/anaconda3/lib/python3.8/site-packages/selenium/webdriver/chrome/webdriver.py", line 76, in __init__', '    RemoteWebDriver.__init__(', '  File "/Users/vishaljha/anaconda3/lib/python3.8/site-packages/selenium/webdriver/remote/webdriver.py", line 157, in __init__', '    self.start_session(capabilities, browser_profile)', '  File "/Users/vishaljha/anaconda3/lib/python3.8/site-packages/selenium/webdriver/remote/webdriver.py", line 252, in start_session', '    response = self.execute(Command.NEW_SESSION, parameters)', '  File "/Users/vishaljha/anaconda3/lib/python3.8/site-packages/selenium/webdriver/remote/webdriver.py", line 321, in execute', '    self.error_handler.check_response(response)', '  File "/Users/vishaljha/anaconda3/lib/python3.8/site-packages/selenium/webdriver/remote/errorhandler.py", line 242, in check_response', '    raise exception_class(message, screen, stacktrace)', 'selenium.common.exceptions.SessionNotCreatedException: Message: session not created: This version of ChromeDriver only supports Chrome version 111', 'Current browser version is 113.0.5672.126 with binary path /Applications/Google Chrome.app/Contents/MacOS/Google Chrome', '', '', 'During handling of the above exception, another exception occurred:', '', 'Traceback (most recent call last):', '  File "/Users/vishaljha/anaconda3/lib/python3.8/site-packages/selenium/webdriver/common/service.py", line 72, in start', '    self.process = subprocess.Popen(cmd, env=self.env,', '  File "/Users/vishaljha/anaconda3/lib/python3.8/subprocess.py", line 854, in __init__', '    self._execute_child(args, executable, preexec_fn, close_fds,', '  File "/Users/vishaljha/anaconda3/lib/python3.8/subprocess.py", line 1702, in _execute_child', '    raise child_exception_type(errno_num, err_msg, err_filename)', "FileNotFoundError: [Errno 2] No such file or directory: 'chromedriver'", '', 'During handling of the above exception, another exception occurred:', '', 'Traceback (most recent call last):', '  File "/Users/vishaljha/Desktop/FINVANT/Alcubierre_Mk1_OMS/Backend/Scripts/AutoLoginZerodha.py", line 117, in auto_login_zerodha', '    key = automate_login(browser_url, user_id, password, totp_pin)', '  File "/Users/vishaljha/Desktop/FINVANT/Alcubierre_Mk1_OMS/Backend/Scripts/AutoLoginZerodha.py", line 40, in automate_login', '    browser = webdriver.Chrome(options = options)', '  File "/Users/vishaljha/anaconda3/lib/python3.8/site-packages/selenium/webdriver/chrome/webdriver.py", line 73, in __init__', '    self.service.start()', '  File "/Users/vishaljha/anaconda3/lib/python3.8/site-packages/selenium/webdriver/common/service.py", line 81, in start', '    raise WebDriverException(', "selenium.common.exceptions.WebDriverException: Message: 'chromedriver' executable needs to be in PATH. Please see https://sites.google.com/a/chromium.org/chromedriver/home", '']
root - CRITICAL - CRITICAL ERROR:2023-06-05 17:12:19.449452 - Failed to generate user dictionary.
['Traceback (most recent call last):', '  File "Main.py", line 176, in main_loop', '    user_dict = UserProfileGenerator().create_user_profiles(user_data=user_data, log_interface=self.log_interface, debug=self.DEBUG)', '  File "/Users/vishaljha/Desktop/FINVANT/Alcubierre_Mk1_OMS/Backend/Scripts/UserProfileGenerator.py", line 73, in create_user_profiles', '    t.join()', '  File "/Users/vishaljha/anaconda3/lib/python3.8/threading.py", line 1011, in join', '    self._wait_for_tstate_lock()', '  File "/Users/vishaljha/anaconda3/lib/python3.8/threading.py", line 1027, in _wait_for_tstate_lock', '    elif lock.acquire(block, timeout):', 'KeyboardInterrupt']
