root - INFO - 2023-06-15 00:36:57.788321 - Finvant Alcubierre Mk1 OMS Backend turned on.
root - INFO - 2023-06-15 00:36:57.934271 - OMS Backend mainloop started.
root - INFO - 2023-06-15 00:36:58.084062 - User data obtained.
root - INFO - 2023-06-15 00:36:58.226672 - Spreads obtained.
root - INFO - 2023-06-15 00:36:58.364422 - Config file obtained.
root - INFO - 2023-06-15 00:36:58.496032 - OMSB: Logging in for backend kite ticker.
root - CRITICAL - CRITICAL ERROR:2023-06-15 00:37:01.172045 - OMSB: Failed auto login to kite ticker.
['Traceback (most recent call last):', '  File "/Users/vishaljha/Desktop/FINVANT/Alcubierre_Mk1_OMS/Backend/Scripts/AutoLoginKiteTicker.py", line 36, in automate_login', "    browser = webdriver.Chrome(options = options,executable_path='../Chrome/chromedriver')", '  File "/Users/vishaljha/anaconda3/lib/python3.8/site-packages/selenium/webdriver/chrome/webdriver.py", line 76, in __init__', '    RemoteWebDriver.__init__(', '  File "/Users/vishaljha/anaconda3/lib/python3.8/site-packages/selenium/webdriver/remote/webdriver.py", line 157, in __init__', '    self.start_session(capabilities, browser_profile)', '  File "/Users/vishaljha/anaconda3/lib/python3.8/site-packages/selenium/webdriver/remote/webdriver.py", line 252, in start_session', '    response = self.execute(Command.NEW_SESSION, parameters)', '  File "/Users/vishaljha/anaconda3/lib/python3.8/site-packages/selenium/webdriver/remote/webdriver.py", line 321, in execute', '    self.error_handler.check_response(response)', '  File "/Users/vishaljha/anaconda3/lib/python3.8/site-packages/selenium/webdriver/remote/errorhandler.py", line 242, in check_response', '    raise exception_class(message, screen, stacktrace)', 'selenium.common.exceptions.SessionNotCreatedException: Message: session not created: This version of ChromeDriver only supports Chrome version 111', 'Current browser version is 114.0.5735.106 with binary path /Applications/Google Chrome.app/Contents/MacOS/Google Chrome', '', '', 'During handling of the above exception, another exception occurred:', '', 'Traceback (most recent call last):', '  File "/Users/vishaljha/anaconda3/lib/python3.8/site-packages/selenium/webdriver/common/service.py", line 72, in start', '    self.process = subprocess.Popen(cmd, env=self.env,', '  File "/Users/vishaljha/anaconda3/lib/python3.8/subprocess.py", line 854, in __init__', '    self._execute_child(args, executable, preexec_fn, close_fds,', '  File "/Users/vishaljha/anaconda3/lib/python3.8/subprocess.py", line 1702, in _execute_child', '    raise child_exception_type(errno_num, err_msg, err_filename)', "FileNotFoundError: [Errno 2] No such file or directory: 'chromedriver'", '', 'During handling of the above exception, another exception occurred:', '', 'Traceback (most recent call last):', '  File "/Users/vishaljha/Desktop/FINVANT/Alcubierre_Mk1_OMS/Backend/Scripts/AutoLoginKiteTicker.py", line 123, in auto_login_zerodha_ticker', '    key = automate_login(browser_url, user_id, password, totp_pin, debug=debug)', '  File "/Users/vishaljha/Desktop/FINVANT/Alcubierre_Mk1_OMS/Backend/Scripts/AutoLoginKiteTicker.py", line 40, in automate_login', '    browser = webdriver.Chrome(options = options)', '  File "/Users/vishaljha/anaconda3/lib/python3.8/site-packages/selenium/webdriver/chrome/webdriver.py", line 73, in __init__', '    self.service.start()', '  File "/Users/vishaljha/anaconda3/lib/python3.8/site-packages/selenium/webdriver/common/service.py", line 81, in start', '    raise WebDriverException(', "selenium.common.exceptions.WebDriverException: Message: 'chromedriver' executable needs to be in PATH. Please see https://sites.google.com/a/chromium.org/chromedriver/home", '']
root - INFO - 2023-06-15 00:37:01.310803 - Initialising LTP gather thread.
root - CRITICAL - CRITICAL ERROR:2023-06-15 00:37:01.687358 - Failed to load vital jsons for LTP gathering.
['Traceback (most recent call last):', '  File "/Users/vishaljha/Desktop/FINVANT/Alcubierre_Mk1_OMS/Backend/Scripts/GatherLTP.py", line 38, in __init__', '    instrument_token_json = json.load(f)', '  File "/Users/vishaljha/anaconda3/lib/python3.8/json/__init__.py", line 293, in load', '    return loads(fp.read(),', '  File "/Users/vishaljha/anaconda3/lib/python3.8/json/__init__.py", line 357, in loads', '    return _default_decoder.decode(s)', '  File "/Users/vishaljha/anaconda3/lib/python3.8/json/decoder.py", line 337, in decode', '    obj, end = self.raw_decode(s, idx=_w(s, 0).end())', '  File "/Users/vishaljha/anaconda3/lib/python3.8/json/decoder.py", line 355, in raw_decode', '    raise JSONDecodeError("Expecting value", s, err.value) from None', 'json.decoder.JSONDecodeError: Expecting value: line 3 column 1 (char 27)']
root - CRITICAL - CRITICAL ERROR:2023-06-15 00:37:01.811819 - Failed to initialise LTP gather module.
['Traceback (most recent call last):', '  File "/Users/vishaljha/Desktop/FINVANT/Alcubierre_Mk1_OMS/Backend/Scripts/GatherLTP.py", line 51, in __init__', '    self.instrument_token_list = instrument_token_json["instrument_tokens"]', "UnboundLocalError: local variable 'instrument_token_json' referenced before assignment"]
root - CRITICAL - CRITICAL ERROR:2023-06-15 00:37:01.941806 - Failed to start KWS thread.
['Traceback (most recent call last):', '  File "/Users/vishaljha/Desktop/FINVANT/Alcubierre_Mk1_OMS/Backend/Scripts/GatherLTP.py", line 77, in start', '    self.kws.on_ticks = self.on_ticks', "AttributeError: 'NoneType' object has no attribute 'on_ticks'"]
root - INFO - 2023-06-15 00:37:01.942903 - OMSB: Zerodha login for WG5235.
root - CRITICAL - CRITICAL ERROR:2023-06-15 00:37:03.614082 - OMSB: Failed auto login to kite for user:WG5235.
['Traceback (most recent call last):', '  File "/Users/vishaljha/Desktop/FINVANT/Alcubierre_Mk1_OMS/Backend/Scripts/AutoLoginZerodha.py", line 36, in automate_login', "    browser = webdriver.Chrome(options = options,executable_path='../Chrome/chromedriver')", '  File "/Users/vishaljha/anaconda3/lib/python3.8/site-packages/selenium/webdriver/chrome/webdriver.py", line 76, in __init__', '    RemoteWebDriver.__init__(', '  File "/Users/vishaljha/anaconda3/lib/python3.8/site-packages/selenium/webdriver/remote/webdriver.py", line 157, in __init__', '    self.start_session(capabilities, browser_profile)', '  File "/Users/vishaljha/anaconda3/lib/python3.8/site-packages/selenium/webdriver/remote/webdriver.py", line 252, in start_session', '    response = self.execute(Command.NEW_SESSION, parameters)', '  File "/Users/vishaljha/anaconda3/lib/python3.8/site-packages/selenium/webdriver/remote/webdriver.py", line 321, in execute', '    self.error_handler.check_response(response)', '  File "/Users/vishaljha/anaconda3/lib/python3.8/site-packages/selenium/webdriver/remote/errorhandler.py", line 242, in check_response', '    raise exception_class(message, screen, stacktrace)', 'selenium.common.exceptions.SessionNotCreatedException: Message: session not created: This version of ChromeDriver only supports Chrome version 111', 'Current browser version is 114.0.5735.106 with binary path /Applications/Google Chrome.app/Contents/MacOS/Google Chrome', '', '', 'During handling of the above exception, another exception occurred:', '', 'Traceback (most recent call last):', '  File "/Users/vishaljha/anaconda3/lib/python3.8/site-packages/selenium/webdriver/common/service.py", line 72, in start', '    self.process = subprocess.Popen(cmd, env=self.env,', '  File "/Users/vishaljha/anaconda3/lib/python3.8/subprocess.py", line 854, in __init__', '    self._execute_child(args, executable, preexec_fn, close_fds,', '  File "/Users/vishaljha/anaconda3/lib/python3.8/subprocess.py", line 1702, in _execute_child', '    raise child_exception_type(errno_num, err_msg, err_filename)', "FileNotFoundError: [Errno 2] No such file or directory: 'chromedriver'", '', 'During handling of the above exception, another exception occurred:', '', 'Traceback (most recent call last):', '  File "/Users/vishaljha/Desktop/FINVANT/Alcubierre_Mk1_OMS/Backend/Scripts/AutoLoginZerodha.py", line 117, in auto_login_zerodha', '    key = automate_login(browser_url, user_id, password, totp_pin)', '  File "/Users/vishaljha/Desktop/FINVANT/Alcubierre_Mk1_OMS/Backend/Scripts/AutoLoginZerodha.py", line 40, in automate_login', '    browser = webdriver.Chrome(options = options)', '  File "/Users/vishaljha/anaconda3/lib/python3.8/site-packages/selenium/webdriver/chrome/webdriver.py", line 73, in __init__', '    self.service.start()', '  File "/Users/vishaljha/anaconda3/lib/python3.8/site-packages/selenium/webdriver/common/service.py", line 81, in start', '    raise WebDriverException(', "selenium.common.exceptions.WebDriverException: Message: 'chromedriver' executable needs to be in PATH. Please see https://sites.google.com/a/chromium.org/chromedriver/home", '']
root - INFO - 2023-06-15 00:37:03.747771 - Order handler initialised.
root - INFO - 2023-06-15 00:37:03.884412 - Creating order handler sub threads.
root - INFO - 2023-06-15 00:37:03.884586 - Starting order handler sub threads.
root - INFO - 2023-06-15 00:37:04.087520 - Placed Zerodha Kite futures order for:fin_user_1, instrument:NIFTY23JULFUT, qty:-50, transaction type:SELL, placed price:18719.0, id:882.
root - INFO - 2023-06-15 00:37:04.955092 - 872.3020553588867
root - INFO - 2023-06-15 01:22:30.598444 - Placed Zerodha Kite futures order for:fin_user_1, instrument:NIFTY23JULFUT, qty:50, transaction type:BUY, placed price:18719.0, id:852.
root - INFO - 2023-06-15 01:22:31.660578 - 1064.913034439087
root - INFO - 2023-06-15 01:32:36.013112 - Finvant Alcubierre Mk1 OMS Backend turned on.
root - INFO - 2023-06-15 01:32:36.143824 - OMS Backend mainloop started.
root - INFO - 2023-06-15 01:32:36.324055 - User data obtained.
root - INFO - 2023-06-15 01:32:36.486468 - Spreads obtained.
root - INFO - 2023-06-15 01:32:36.624863 - Config file obtained.
root - INFO - 2023-06-15 01:32:36.760923 - OMSB: Logging in for backend kite ticker.
root - CRITICAL - CRITICAL ERROR:2023-06-15 01:32:39.559812 - OMSB: Failed auto login to kite ticker.
['Traceback (most recent call last):', '  File "/Users/vishaljha/Desktop/FINVANT/Alcubierre_Mk1_OMS/Backend/Scripts/AutoLoginKiteTicker.py", line 36, in automate_login', "    browser = webdriver.Chrome(options = options,executable_path='../Chrome/chromedriver')", '  File "/Users/vishaljha/anaconda3/lib/python3.8/site-packages/selenium/webdriver/chrome/webdriver.py", line 76, in __init__', '    RemoteWebDriver.__init__(', '  File "/Users/vishaljha/anaconda3/lib/python3.8/site-packages/selenium/webdriver/remote/webdriver.py", line 157, in __init__', '    self.start_session(capabilities, browser_profile)', '  File "/Users/vishaljha/anaconda3/lib/python3.8/site-packages/selenium/webdriver/remote/webdriver.py", line 252, in start_session', '    response = self.execute(Command.NEW_SESSION, parameters)', '  File "/Users/vishaljha/anaconda3/lib/python3.8/site-packages/selenium/webdriver/remote/webdriver.py", line 321, in execute', '    self.error_handler.check_response(response)', '  File "/Users/vishaljha/anaconda3/lib/python3.8/site-packages/selenium/webdriver/remote/errorhandler.py", line 242, in check_response', '    raise exception_class(message, screen, stacktrace)', 'selenium.common.exceptions.SessionNotCreatedException: Message: session not created: This version of ChromeDriver only supports Chrome version 111', 'Current browser version is 114.0.5735.106 with binary path /Applications/Google Chrome.app/Contents/MacOS/Google Chrome', '', '', 'During handling of the above exception, another exception occurred:', '', 'Traceback (most recent call last):', '  File "/Users/vishaljha/anaconda3/lib/python3.8/site-packages/selenium/webdriver/common/service.py", line 72, in start', '    self.process = subprocess.Popen(cmd, env=self.env,', '  File "/Users/vishaljha/anaconda3/lib/python3.8/subprocess.py", line 854, in __init__', '    self._execute_child(args, executable, preexec_fn, close_fds,', '  File "/Users/vishaljha/anaconda3/lib/python3.8/subprocess.py", line 1702, in _execute_child', '    raise child_exception_type(errno_num, err_msg, err_filename)', "FileNotFoundError: [Errno 2] No such file or directory: 'chromedriver'", '', 'During handling of the above exception, another exception occurred:', '', 'Traceback (most recent call last):', '  File "/Users/vishaljha/Desktop/FINVANT/Alcubierre_Mk1_OMS/Backend/Scripts/AutoLoginKiteTicker.py", line 123, in auto_login_zerodha_ticker', '    key = automate_login(browser_url, user_id, password, totp_pin, debug=debug)', '  File "/Users/vishaljha/Desktop/FINVANT/Alcubierre_Mk1_OMS/Backend/Scripts/AutoLoginKiteTicker.py", line 40, in automate_login', '    browser = webdriver.Chrome(options = options)', '  File "/Users/vishaljha/anaconda3/lib/python3.8/site-packages/selenium/webdriver/chrome/webdriver.py", line 73, in __init__', '    self.service.start()', '  File "/Users/vishaljha/anaconda3/lib/python3.8/site-packages/selenium/webdriver/common/service.py", line 81, in start', '    raise WebDriverException(', "selenium.common.exceptions.WebDriverException: Message: 'chromedriver' executable needs to be in PATH. Please see https://sites.google.com/a/chromium.org/chromedriver/home", '']
root - INFO - 2023-06-15 01:32:39.696829 - Initialising LTP gather thread.
root - CRITICAL - CRITICAL ERROR:2023-06-15 01:32:40.075967 - Failed to load vital jsons for LTP gathering.
['Traceback (most recent call last):', '  File "/Users/vishaljha/Desktop/FINVANT/Alcubierre_Mk1_OMS/Backend/Scripts/GatherLTP.py", line 38, in __init__', '    instrument_token_json = json.load(f)', '  File "/Users/vishaljha/anaconda3/lib/python3.8/json/__init__.py", line 293, in load', '    return loads(fp.read(),', '  File "/Users/vishaljha/anaconda3/lib/python3.8/json/__init__.py", line 357, in loads', '    return _default_decoder.decode(s)', '  File "/Users/vishaljha/anaconda3/lib/python3.8/json/decoder.py", line 337, in decode', '    obj, end = self.raw_decode(s, idx=_w(s, 0).end())', '  File "/Users/vishaljha/anaconda3/lib/python3.8/json/decoder.py", line 355, in raw_decode', '    raise JSONDecodeError("Expecting value", s, err.value) from None', 'json.decoder.JSONDecodeError: Expecting value: line 3 column 1 (char 27)']
root - CRITICAL - CRITICAL ERROR:2023-06-15 01:32:40.213051 - Failed to initialise LTP gather module.
['Traceback (most recent call last):', '  File "/Users/vishaljha/Desktop/FINVANT/Alcubierre_Mk1_OMS/Backend/Scripts/GatherLTP.py", line 51, in __init__', '    self.instrument_token_list = instrument_token_json["instrument_tokens"]', "UnboundLocalError: local variable 'instrument_token_json' referenced before assignment"]
root - CRITICAL - CRITICAL ERROR:2023-06-15 01:32:40.339824 - Failed to start KWS thread.
['Traceback (most recent call last):', '  File "/Users/vishaljha/Desktop/FINVANT/Alcubierre_Mk1_OMS/Backend/Scripts/GatherLTP.py", line 77, in start', '    self.kws.on_ticks = self.on_ticks', "AttributeError: 'NoneType' object has no attribute 'on_ticks'"]
root - INFO - 2023-06-15 01:32:40.342895 - OMSB: Zerodha login for WG5235.
root - CRITICAL - CRITICAL ERROR:2023-06-15 01:32:41.976633 - OMSB: Failed auto login to kite for user:WG5235.
['Traceback (most recent call last):', '  File "/Users/vishaljha/Desktop/FINVANT/Alcubierre_Mk1_OMS/Backend/Scripts/AutoLoginZerodha.py", line 36, in automate_login', "    browser = webdriver.Chrome(options = options,executable_path='../Chrome/chromedriver')", '  File "/Users/vishaljha/anaconda3/lib/python3.8/site-packages/selenium/webdriver/chrome/webdriver.py", line 76, in __init__', '    RemoteWebDriver.__init__(', '  File "/Users/vishaljha/anaconda3/lib/python3.8/site-packages/selenium/webdriver/remote/webdriver.py", line 157, in __init__', '    self.start_session(capabilities, browser_profile)', '  File "/Users/vishaljha/anaconda3/lib/python3.8/site-packages/selenium/webdriver/remote/webdriver.py", line 252, in start_session', '    response = self.execute(Command.NEW_SESSION, parameters)', '  File "/Users/vishaljha/anaconda3/lib/python3.8/site-packages/selenium/webdriver/remote/webdriver.py", line 321, in execute', '    self.error_handler.check_response(response)', '  File "/Users/vishaljha/anaconda3/lib/python3.8/site-packages/selenium/webdriver/remote/errorhandler.py", line 242, in check_response', '    raise exception_class(message, screen, stacktrace)', 'selenium.common.exceptions.SessionNotCreatedException: Message: session not created: This version of ChromeDriver only supports Chrome version 111', 'Current browser version is 114.0.5735.106 with binary path /Applications/Google Chrome.app/Contents/MacOS/Google Chrome', '', '', 'During handling of the above exception, another exception occurred:', '', 'Traceback (most recent call last):', '  File "/Users/vishaljha/anaconda3/lib/python3.8/site-packages/selenium/webdriver/common/service.py", line 72, in start', '    self.process = subprocess.Popen(cmd, env=self.env,', '  File "/Users/vishaljha/anaconda3/lib/python3.8/subprocess.py", line 854, in __init__', '    self._execute_child(args, executable, preexec_fn, close_fds,', '  File "/Users/vishaljha/anaconda3/lib/python3.8/subprocess.py", line 1702, in _execute_child', '    raise child_exception_type(errno_num, err_msg, err_filename)', "FileNotFoundError: [Errno 2] No such file or directory: 'chromedriver'", '', 'During handling of the above exception, another exception occurred:', '', 'Traceback (most recent call last):', '  File "/Users/vishaljha/Desktop/FINVANT/Alcubierre_Mk1_OMS/Backend/Scripts/AutoLoginZerodha.py", line 117, in auto_login_zerodha', '    key = automate_login(browser_url, user_id, password, totp_pin)', '  File "/Users/vishaljha/Desktop/FINVANT/Alcubierre_Mk1_OMS/Backend/Scripts/AutoLoginZerodha.py", line 40, in automate_login', '    browser = webdriver.Chrome(options = options)', '  File "/Users/vishaljha/anaconda3/lib/python3.8/site-packages/selenium/webdriver/chrome/webdriver.py", line 73, in __init__', '    self.service.start()', '  File "/Users/vishaljha/anaconda3/lib/python3.8/site-packages/selenium/webdriver/common/service.py", line 81, in start', '    raise WebDriverException(', "selenium.common.exceptions.WebDriverException: Message: 'chromedriver' executable needs to be in PATH. Please see https://sites.google.com/a/chromium.org/chromedriver/home", '']
root - INFO - 2023-06-15 01:32:42.113547 - Order handler initialised.
root - INFO - 2023-06-15 01:32:42.273293 - Creating order handler sub threads.
root - INFO - 2023-06-15 01:32:42.273538 - Starting order handler sub threads.
root - INFO - 2023-06-15 01:32:42.964371 - Placed Zerodha Kite options order for:fin_user_1, instrument:NIFTY2361518600PE, qty:-50, transaction type:SELL, placed price:89.05, id:921.
root - INFO - 2023-06-15 01:32:43.832559 - 1371.7849254608154
root - INFO - 2023-06-15 01:32:44.463601 - Placed Zerodha Kite options order for:fin_user_1, instrument:NIFTY2361518600CE, qty:50, transaction type:BUY, placed price:77.0, id:608.
root - INFO - 2023-06-15 01:32:45.359494 - 1397.5131511688232
root - INFO - 2023-06-15 01:33:49.252799 - Finvant Alcubierre Mk1 OMS Backend turned on.
root - INFO - 2023-06-15 01:33:49.396897 - OMS Backend mainloop started.
root - INFO - 2023-06-15 01:33:49.548634 - User data obtained.
root - INFO - 2023-06-15 01:33:49.698270 - Spreads obtained.
root - INFO - 2023-06-15 01:33:49.831125 - Config file obtained.
root - INFO - 2023-06-15 01:33:49.955593 - OMSB: Logging in for backend kite ticker.
root - CRITICAL - CRITICAL ERROR:2023-06-15 01:33:52.172186 - OMSB: Failed auto login to kite ticker.
['Traceback (most recent call last):', '  File "/Users/vishaljha/Desktop/FINVANT/Alcubierre_Mk1_OMS/Backend/Scripts/AutoLoginKiteTicker.py", line 36, in automate_login', "    browser = webdriver.Chrome(options = options,executable_path='../Chrome/chromedriver')", '  File "/Users/vishaljha/anaconda3/lib/python3.8/site-packages/selenium/webdriver/chrome/webdriver.py", line 76, in __init__', '    RemoteWebDriver.__init__(', '  File "/Users/vishaljha/anaconda3/lib/python3.8/site-packages/selenium/webdriver/remote/webdriver.py", line 157, in __init__', '    self.start_session(capabilities, browser_profile)', '  File "/Users/vishaljha/anaconda3/lib/python3.8/site-packages/selenium/webdriver/remote/webdriver.py", line 252, in start_session', '    response = self.execute(Command.NEW_SESSION, parameters)', '  File "/Users/vishaljha/anaconda3/lib/python3.8/site-packages/selenium/webdriver/remote/webdriver.py", line 321, in execute', '    self.error_handler.check_response(response)', '  File "/Users/vishaljha/anaconda3/lib/python3.8/site-packages/selenium/webdriver/remote/errorhandler.py", line 242, in check_response', '    raise exception_class(message, screen, stacktrace)', 'selenium.common.exceptions.SessionNotCreatedException: Message: session not created: This version of ChromeDriver only supports Chrome version 111', 'Current browser version is 114.0.5735.106 with binary path /Applications/Google Chrome.app/Contents/MacOS/Google Chrome', '', '', 'During handling of the above exception, another exception occurred:', '', 'Traceback (most recent call last):', '  File "/Users/vishaljha/anaconda3/lib/python3.8/site-packages/selenium/webdriver/common/service.py", line 72, in start', '    self.process = subprocess.Popen(cmd, env=self.env,', '  File "/Users/vishaljha/anaconda3/lib/python3.8/subprocess.py", line 854, in __init__', '    self._execute_child(args, executable, preexec_fn, close_fds,', '  File "/Users/vishaljha/anaconda3/lib/python3.8/subprocess.py", line 1702, in _execute_child', '    raise child_exception_type(errno_num, err_msg, err_filename)', "FileNotFoundError: [Errno 2] No such file or directory: 'chromedriver'", '', 'During handling of the above exception, another exception occurred:', '', 'Traceback (most recent call last):', '  File "/Users/vishaljha/Desktop/FINVANT/Alcubierre_Mk1_OMS/Backend/Scripts/AutoLoginKiteTicker.py", line 123, in auto_login_zerodha_ticker', '    key = automate_login(browser_url, user_id, password, totp_pin, debug=debug)', '  File "/Users/vishaljha/Desktop/FINVANT/Alcubierre_Mk1_OMS/Backend/Scripts/AutoLoginKiteTicker.py", line 40, in automate_login', '    browser = webdriver.Chrome(options = options)', '  File "/Users/vishaljha/anaconda3/lib/python3.8/site-packages/selenium/webdriver/chrome/webdriver.py", line 73, in __init__', '    self.service.start()', '  File "/Users/vishaljha/anaconda3/lib/python3.8/site-packages/selenium/webdriver/common/service.py", line 81, in start', '    raise WebDriverException(', "selenium.common.exceptions.WebDriverException: Message: 'chromedriver' executable needs to be in PATH. Please see https://sites.google.com/a/chromium.org/chromedriver/home", '']
root - INFO - 2023-06-15 01:33:52.304987 - Initialising LTP gather thread.
root - CRITICAL - CRITICAL ERROR:2023-06-15 01:33:52.677801 - Failed to load vital jsons for LTP gathering.
['Traceback (most recent call last):', '  File "/Users/vishaljha/Desktop/FINVANT/Alcubierre_Mk1_OMS/Backend/Scripts/GatherLTP.py", line 38, in __init__', '    instrument_token_json = json.load(f)', '  File "/Users/vishaljha/anaconda3/lib/python3.8/json/__init__.py", line 293, in load', '    return loads(fp.read(),', '  File "/Users/vishaljha/anaconda3/lib/python3.8/json/__init__.py", line 357, in loads', '    return _default_decoder.decode(s)', '  File "/Users/vishaljha/anaconda3/lib/python3.8/json/decoder.py", line 337, in decode', '    obj, end = self.raw_decode(s, idx=_w(s, 0).end())', '  File "/Users/vishaljha/anaconda3/lib/python3.8/json/decoder.py", line 355, in raw_decode', '    raise JSONDecodeError("Expecting value", s, err.value) from None', 'json.decoder.JSONDecodeError: Expecting value: line 3 column 1 (char 27)']
root - CRITICAL - CRITICAL ERROR:2023-06-15 01:33:52.810267 - Failed to initialise LTP gather module.
['Traceback (most recent call last):', '  File "/Users/vishaljha/Desktop/FINVANT/Alcubierre_Mk1_OMS/Backend/Scripts/GatherLTP.py", line 51, in __init__', '    self.instrument_token_list = instrument_token_json["instrument_tokens"]', "UnboundLocalError: local variable 'instrument_token_json' referenced before assignment"]
root - CRITICAL - CRITICAL ERROR:2023-06-15 01:33:52.940184 - Failed to start KWS thread.
['Traceback (most recent call last):', '  File "/Users/vishaljha/Desktop/FINVANT/Alcubierre_Mk1_OMS/Backend/Scripts/GatherLTP.py", line 77, in start', '    self.kws.on_ticks = self.on_ticks', "AttributeError: 'NoneType' object has no attribute 'on_ticks'"]
root - INFO - 2023-06-15 01:33:52.940925 - OMSB: Zerodha login for WG5235.
root - CRITICAL - CRITICAL ERROR:2023-06-15 01:33:54.584111 - OMSB: Failed auto login to kite for user:WG5235.
['Traceback (most recent call last):', '  File "/Users/vishaljha/Desktop/FINVANT/Alcubierre_Mk1_OMS/Backend/Scripts/AutoLoginZerodha.py", line 36, in automate_login', "    browser = webdriver.Chrome(options = options,executable_path='../Chrome/chromedriver')", '  File "/Users/vishaljha/anaconda3/lib/python3.8/site-packages/selenium/webdriver/chrome/webdriver.py", line 76, in __init__', '    RemoteWebDriver.__init__(', '  File "/Users/vishaljha/anaconda3/lib/python3.8/site-packages/selenium/webdriver/remote/webdriver.py", line 157, in __init__', '    self.start_session(capabilities, browser_profile)', '  File "/Users/vishaljha/anaconda3/lib/python3.8/site-packages/selenium/webdriver/remote/webdriver.py", line 252, in start_session', '    response = self.execute(Command.NEW_SESSION, parameters)', '  File "/Users/vishaljha/anaconda3/lib/python3.8/site-packages/selenium/webdriver/remote/webdriver.py", line 321, in execute', '    self.error_handler.check_response(response)', '  File "/Users/vishaljha/anaconda3/lib/python3.8/site-packages/selenium/webdriver/remote/errorhandler.py", line 242, in check_response', '    raise exception_class(message, screen, stacktrace)', 'selenium.common.exceptions.SessionNotCreatedException: Message: session not created: This version of ChromeDriver only supports Chrome version 111', 'Current browser version is 114.0.5735.106 with binary path /Applications/Google Chrome.app/Contents/MacOS/Google Chrome', '', '', 'During handling of the above exception, another exception occurred:', '', 'Traceback (most recent call last):', '  File "/Users/vishaljha/anaconda3/lib/python3.8/site-packages/selenium/webdriver/common/service.py", line 72, in start', '    self.process = subprocess.Popen(cmd, env=self.env,', '  File "/Users/vishaljha/anaconda3/lib/python3.8/subprocess.py", line 854, in __init__', '    self._execute_child(args, executable, preexec_fn, close_fds,', '  File "/Users/vishaljha/anaconda3/lib/python3.8/subprocess.py", line 1702, in _execute_child', '    raise child_exception_type(errno_num, err_msg, err_filename)', "FileNotFoundError: [Errno 2] No such file or directory: 'chromedriver'", '', 'During handling of the above exception, another exception occurred:', '', 'Traceback (most recent call last):', '  File "/Users/vishaljha/Desktop/FINVANT/Alcubierre_Mk1_OMS/Backend/Scripts/AutoLoginZerodha.py", line 117, in auto_login_zerodha', '    key = automate_login(browser_url, user_id, password, totp_pin)', '  File "/Users/vishaljha/Desktop/FINVANT/Alcubierre_Mk1_OMS/Backend/Scripts/AutoLoginZerodha.py", line 40, in automate_login', '    browser = webdriver.Chrome(options = options)', '  File "/Users/vishaljha/anaconda3/lib/python3.8/site-packages/selenium/webdriver/chrome/webdriver.py", line 73, in __init__', '    self.service.start()', '  File "/Users/vishaljha/anaconda3/lib/python3.8/site-packages/selenium/webdriver/common/service.py", line 81, in start', '    raise WebDriverException(', "selenium.common.exceptions.WebDriverException: Message: 'chromedriver' executable needs to be in PATH. Please see https://sites.google.com/a/chromium.org/chromedriver/home", '']
root - INFO - 2023-06-15 01:33:54.820297 - Order handler initialised.
root - INFO - 2023-06-15 01:33:54.948017 - Creating order handler sub threads.
root - INFO - 2023-06-15 01:33:54.948192 - Starting order handler sub threads.
root - INFO - 2023-06-15 12:16:30.360517 - Finvant Alcubierre Mk1 OMS Backend turned on.
root - INFO - 2023-06-15 12:16:30.492148 - OMS Backend mainloop started.
root - INFO - 2023-06-15 12:16:30.696502 - User data obtained.
root - INFO - 2023-06-15 12:16:30.842038 - Spreads obtained.
root - INFO - 2023-06-15 12:16:30.988528 - Config file obtained.
root - INFO - 2023-06-15 12:16:31.117540 - OMSB: Logging in for backend kite ticker.
root - CRITICAL - CRITICAL ERROR:2023-06-15 12:16:33.779688 - OMSB: Failed auto login to kite ticker.
['Traceback (most recent call last):', '  File "/Users/vishaljha/Desktop/FINVANT/Alcubierre_Mk1_OMS/Backend/Scripts/AutoLoginKiteTicker.py", line 36, in automate_login', "    browser = webdriver.Chrome(options = options,executable_path='../Chrome/chromedriver')", '  File "/Users/vishaljha/anaconda3/lib/python3.8/site-packages/selenium/webdriver/chrome/webdriver.py", line 76, in __init__', '    RemoteWebDriver.__init__(', '  File "/Users/vishaljha/anaconda3/lib/python3.8/site-packages/selenium/webdriver/remote/webdriver.py", line 157, in __init__', '    self.start_session(capabilities, browser_profile)', '  File "/Users/vishaljha/anaconda3/lib/python3.8/site-packages/selenium/webdriver/remote/webdriver.py", line 252, in start_session', '    response = self.execute(Command.NEW_SESSION, parameters)', '  File "/Users/vishaljha/anaconda3/lib/python3.8/site-packages/selenium/webdriver/remote/webdriver.py", line 321, in execute', '    self.error_handler.check_response(response)', '  File "/Users/vishaljha/anaconda3/lib/python3.8/site-packages/selenium/webdriver/remote/errorhandler.py", line 242, in check_response', '    raise exception_class(message, screen, stacktrace)', 'selenium.common.exceptions.SessionNotCreatedException: Message: session not created: This version of ChromeDriver only supports Chrome version 111', 'Current browser version is 114.0.5735.106 with binary path /Applications/Google Chrome.app/Contents/MacOS/Google Chrome', '', '', 'During handling of the above exception, another exception occurred:', '', 'Traceback (most recent call last):', '  File "/Users/vishaljha/anaconda3/lib/python3.8/site-packages/selenium/webdriver/common/service.py", line 72, in start', '    self.process = subprocess.Popen(cmd, env=self.env,', '  File "/Users/vishaljha/anaconda3/lib/python3.8/subprocess.py", line 854, in __init__', '    self._execute_child(args, executable, preexec_fn, close_fds,', '  File "/Users/vishaljha/anaconda3/lib/python3.8/subprocess.py", line 1702, in _execute_child', '    raise child_exception_type(errno_num, err_msg, err_filename)', "FileNotFoundError: [Errno 2] No such file or directory: 'chromedriver'", '', 'During handling of the above exception, another exception occurred:', '', 'Traceback (most recent call last):', '  File "/Users/vishaljha/Desktop/FINVANT/Alcubierre_Mk1_OMS/Backend/Scripts/AutoLoginKiteTicker.py", line 123, in auto_login_zerodha_ticker', '    key = automate_login(browser_url, user_id, password, totp_pin, debug=debug)', '  File "/Users/vishaljha/Desktop/FINVANT/Alcubierre_Mk1_OMS/Backend/Scripts/AutoLoginKiteTicker.py", line 40, in automate_login', '    browser = webdriver.Chrome(options = options)', '  File "/Users/vishaljha/anaconda3/lib/python3.8/site-packages/selenium/webdriver/chrome/webdriver.py", line 73, in __init__', '    self.service.start()', '  File "/Users/vishaljha/anaconda3/lib/python3.8/site-packages/selenium/webdriver/common/service.py", line 81, in start', '    raise WebDriverException(', "selenium.common.exceptions.WebDriverException: Message: 'chromedriver' executable needs to be in PATH. Please see https://sites.google.com/a/chromium.org/chromedriver/home", '']
root - INFO - 2023-06-15 12:16:33.911609 - Initialising LTP gather thread.
root - CRITICAL - CRITICAL ERROR:2023-06-15 12:16:34.315489 - Failed to load vital jsons for LTP gathering.
['Traceback (most recent call last):', '  File "/Users/vishaljha/Desktop/FINVANT/Alcubierre_Mk1_OMS/Backend/Scripts/GatherLTP.py", line 38, in __init__', '    instrument_token_json = json.load(f)', '  File "/Users/vishaljha/anaconda3/lib/python3.8/json/__init__.py", line 293, in load', '    return loads(fp.read(),', '  File "/Users/vishaljha/anaconda3/lib/python3.8/json/__init__.py", line 357, in loads', '    return _default_decoder.decode(s)', '  File "/Users/vishaljha/anaconda3/lib/python3.8/json/decoder.py", line 337, in decode', '    obj, end = self.raw_decode(s, idx=_w(s, 0).end())', '  File "/Users/vishaljha/anaconda3/lib/python3.8/json/decoder.py", line 355, in raw_decode', '    raise JSONDecodeError("Expecting value", s, err.value) from None', 'json.decoder.JSONDecodeError: Expecting value: line 1175 column 1 (char 16279)']
root - CRITICAL - CRITICAL ERROR:2023-06-15 12:16:34.446347 - Failed to initialise LTP gather module.
['Traceback (most recent call last):', '  File "/Users/vishaljha/Desktop/FINVANT/Alcubierre_Mk1_OMS/Backend/Scripts/GatherLTP.py", line 51, in __init__', '    self.instrument_token_list = instrument_token_json["instrument_tokens"]', "UnboundLocalError: local variable 'instrument_token_json' referenced before assignment"]
root - CRITICAL - CRITICAL ERROR:2023-06-15 12:16:34.595446 - Failed to start KWS thread.
['Traceback (most recent call last):', '  File "/Users/vishaljha/Desktop/FINVANT/Alcubierre_Mk1_OMS/Backend/Scripts/GatherLTP.py", line 77, in start', '    self.kws.on_ticks = self.on_ticks', "AttributeError: 'NoneType' object has no attribute 'on_ticks'"]
root - CRITICAL - CRITICAL ERROR:2023-06-15 12:16:34.599441 - Failed to generate user dictionary.
['Traceback (most recent call last):', '  File "Main.py", line 176, in main_loop', '    user_dict = UserProfileGenerator().create_user_profiles(user_data=user_data, log_interface=self.log_interface, debug=self.DEBUG)', '  File "/Users/vishaljha/Desktop/FINVANT/Alcubierre_Mk1_OMS/Backend/Scripts/UserProfileGenerator.py", line 67, in create_user_profiles', '    metrics = json.load(f)', '  File "/Users/vishaljha/anaconda3/lib/python3.8/json/__init__.py", line 293, in load', '    return loads(fp.read(),', '  File "/Users/vishaljha/anaconda3/lib/python3.8/json/__init__.py", line 357, in loads', '    return _default_decoder.decode(s)', '  File "/Users/vishaljha/anaconda3/lib/python3.8/json/decoder.py", line 337, in decode', '    obj, end = self.raw_decode(s, idx=_w(s, 0).end())', '  File "/Users/vishaljha/anaconda3/lib/python3.8/json/decoder.py", line 353, in raw_decode', '    obj, end = self.scan_once(s, idx)', 'json.decoder.JSONDecodeError: Expecting property name enclosed in double quotes: line 2 column 1 (char 2)']
root - CRITICAL - CRITICAL ERROR:2023-06-15 12:16:34.810092 - Failure in order handler.
['Traceback (most recent call last):', '  File "Main.py", line 184, in main_loop', '    order_handler = OrderHandler(user_profiles=user_dict, spread_list=spread_list, log_interface = self.log_interface, debug=self.DEBUG)', "UnboundLocalError: local variable 'user_dict' referenced before assignment"]
root - INFO - 2023-06-15 12:17:06.971095 - Finvant Alcubierre Mk1 OMS Backend turned on.
root - INFO - 2023-06-15 12:17:07.104082 - OMS Backend mainloop started.
root - INFO - 2023-06-15 12:17:07.254620 - User data obtained.
root - INFO - 2023-06-15 12:17:07.419023 - Spreads obtained.
root - INFO - 2023-06-15 12:17:07.550831 - Config file obtained.
root - INFO - 2023-06-15 12:17:07.681993 - OMSB: Logging in for backend kite ticker.
root - CRITICAL - CRITICAL ERROR:2023-06-15 12:17:09.842068 - OMSB: Failed auto login to kite ticker.
['Traceback (most recent call last):', '  File "/Users/vishaljha/Desktop/FINVANT/Alcubierre_Mk1_OMS/Backend/Scripts/AutoLoginKiteTicker.py", line 36, in automate_login', "    browser = webdriver.Chrome(options = options,executable_path='../Chrome/chromedriver')", '  File "/Users/vishaljha/anaconda3/lib/python3.8/site-packages/selenium/webdriver/chrome/webdriver.py", line 76, in __init__', '    RemoteWebDriver.__init__(', '  File "/Users/vishaljha/anaconda3/lib/python3.8/site-packages/selenium/webdriver/remote/webdriver.py", line 157, in __init__', '    self.start_session(capabilities, browser_profile)', '  File "/Users/vishaljha/anaconda3/lib/python3.8/site-packages/selenium/webdriver/remote/webdriver.py", line 252, in start_session', '    response = self.execute(Command.NEW_SESSION, parameters)', '  File "/Users/vishaljha/anaconda3/lib/python3.8/site-packages/selenium/webdriver/remote/webdriver.py", line 321, in execute', '    self.error_handler.check_response(response)', '  File "/Users/vishaljha/anaconda3/lib/python3.8/site-packages/selenium/webdriver/remote/errorhandler.py", line 242, in check_response', '    raise exception_class(message, screen, stacktrace)', 'selenium.common.exceptions.SessionNotCreatedException: Message: session not created: This version of ChromeDriver only supports Chrome version 111', 'Current browser version is 114.0.5735.106 with binary path /Applications/Google Chrome.app/Contents/MacOS/Google Chrome', '', '', 'During handling of the above exception, another exception occurred:', '', 'Traceback (most recent call last):', '  File "/Users/vishaljha/anaconda3/lib/python3.8/site-packages/selenium/webdriver/common/service.py", line 72, in start', '    self.process = subprocess.Popen(cmd, env=self.env,', '  File "/Users/vishaljha/anaconda3/lib/python3.8/subprocess.py", line 854, in __init__', '    self._execute_child(args, executable, preexec_fn, close_fds,', '  File "/Users/vishaljha/anaconda3/lib/python3.8/subprocess.py", line 1702, in _execute_child', '    raise child_exception_type(errno_num, err_msg, err_filename)', "FileNotFoundError: [Errno 2] No such file or directory: 'chromedriver'", '', 'During handling of the above exception, another exception occurred:', '', 'Traceback (most recent call last):', '  File "/Users/vishaljha/Desktop/FINVANT/Alcubierre_Mk1_OMS/Backend/Scripts/AutoLoginKiteTicker.py", line 123, in auto_login_zerodha_ticker', '    key = automate_login(browser_url, user_id, password, totp_pin, debug=debug)', '  File "/Users/vishaljha/Desktop/FINVANT/Alcubierre_Mk1_OMS/Backend/Scripts/AutoLoginKiteTicker.py", line 40, in automate_login', '    browser = webdriver.Chrome(options = options)', '  File "/Users/vishaljha/anaconda3/lib/python3.8/site-packages/selenium/webdriver/chrome/webdriver.py", line 73, in __init__', '    self.service.start()', '  File "/Users/vishaljha/anaconda3/lib/python3.8/site-packages/selenium/webdriver/common/service.py", line 81, in start', '    raise WebDriverException(', "selenium.common.exceptions.WebDriverException: Message: 'chromedriver' executable needs to be in PATH. Please see https://sites.google.com/a/chromium.org/chromedriver/home", '']
root - INFO - 2023-06-15 12:17:09.976517 - Initialising LTP gather thread.
root - CRITICAL - CRITICAL ERROR:2023-06-15 12:17:10.373384 - Failed to load vital jsons for LTP gathering.
['Traceback (most recent call last):', '  File "/Users/vishaljha/Desktop/FINVANT/Alcubierre_Mk1_OMS/Backend/Scripts/GatherLTP.py", line 38, in __init__', '    instrument_token_json = json.load(f)', '  File "/Users/vishaljha/anaconda3/lib/python3.8/json/__init__.py", line 293, in load', '    return loads(fp.read(),', '  File "/Users/vishaljha/anaconda3/lib/python3.8/json/__init__.py", line 357, in loads', '    return _default_decoder.decode(s)', '  File "/Users/vishaljha/anaconda3/lib/python3.8/json/decoder.py", line 337, in decode', '    obj, end = self.raw_decode(s, idx=_w(s, 0).end())', '  File "/Users/vishaljha/anaconda3/lib/python3.8/json/decoder.py", line 355, in raw_decode', '    raise JSONDecodeError("Expecting value", s, err.value) from None', 'json.decoder.JSONDecodeError: Expecting value: line 1175 column 1 (char 16279)']
root - CRITICAL - CRITICAL ERROR:2023-06-15 12:17:10.503130 - Failed to initialise LTP gather module.
['Traceback (most recent call last):', '  File "/Users/vishaljha/Desktop/FINVANT/Alcubierre_Mk1_OMS/Backend/Scripts/GatherLTP.py", line 51, in __init__', '    self.instrument_token_list = instrument_token_json["instrument_tokens"]', "UnboundLocalError: local variable 'instrument_token_json' referenced before assignment"]
root - CRITICAL - CRITICAL ERROR:2023-06-15 12:17:10.661552 - Failed to start KWS thread.
['Traceback (most recent call last):', '  File "/Users/vishaljha/Desktop/FINVANT/Alcubierre_Mk1_OMS/Backend/Scripts/GatherLTP.py", line 77, in start', '    self.kws.on_ticks = self.on_ticks', "AttributeError: 'NoneType' object has no attribute 'on_ticks'"]
root - CRITICAL - CRITICAL ERROR:2023-06-15 12:17:10.665634 - Failed to generate user dictionary.
['Traceback (most recent call last):', '  File "Main.py", line 176, in main_loop', '    user_dict = UserProfileGenerator().create_user_profiles(user_data=user_data, log_interface=self.log_interface, debug=self.DEBUG)', '  File "/Users/vishaljha/Desktop/FINVANT/Alcubierre_Mk1_OMS/Backend/Scripts/UserProfileGenerator.py", line 67, in create_user_profiles', '    metrics = json.load(f)', '  File "/Users/vishaljha/anaconda3/lib/python3.8/json/__init__.py", line 293, in load', '    return loads(fp.read(),', '  File "/Users/vishaljha/anaconda3/lib/python3.8/json/__init__.py", line 357, in loads', '    return _default_decoder.decode(s)', '  File "/Users/vishaljha/anaconda3/lib/python3.8/json/decoder.py", line 337, in decode', '    obj, end = self.raw_decode(s, idx=_w(s, 0).end())', '  File "/Users/vishaljha/anaconda3/lib/python3.8/json/decoder.py", line 353, in raw_decode', '    obj, end = self.scan_once(s, idx)', 'json.decoder.JSONDecodeError: Expecting property name enclosed in double quotes: line 2 column 1 (char 2)']
root - CRITICAL - CRITICAL ERROR:2023-06-15 12:17:10.879196 - Failure in order handler.
['Traceback (most recent call last):', '  File "Main.py", line 184, in main_loop', '    order_handler = OrderHandler(user_profiles=user_dict, spread_list=spread_list, log_interface = self.log_interface, debug=self.DEBUG)', "UnboundLocalError: local variable 'user_dict' referenced before assignment"]
root - INFO - 2023-06-15 12:18:58.500447 - Finvant Alcubierre Mk1 OMS Backend turned on.
root - INFO - 2023-06-15 12:18:58.660640 - OMS Backend mainloop started.
root - INFO - 2023-06-15 12:18:58.860443 - User data obtained.
root - INFO - 2023-06-15 12:18:59.015341 - Spreads obtained.
root - INFO - 2023-06-15 12:18:59.163596 - Config file obtained.
root - INFO - 2023-06-15 12:18:59.298483 - OMSB: Logging in for backend kite ticker.
root - INFO - 2023-06-15 12:19:12.664609 - OMSB: Login succesful for backend kite ticker.
root - INFO - 2023-06-15 12:19:12.814065 - Initialising LTP gather thread.
root - CRITICAL - CRITICAL ERROR:2023-06-15 12:19:13.250548 - Failed to load vital jsons for LTP gathering.
['Traceback (most recent call last):', '  File "/Users/vishaljha/Desktop/FINVANT/Alcubierre_Mk1_OMS/Backend/Scripts/GatherLTP.py", line 38, in __init__', '    instrument_token_json = json.load(f)', '  File "/Users/vishaljha/anaconda3/lib/python3.8/json/__init__.py", line 293, in load', '    return loads(fp.read(),', '  File "/Users/vishaljha/anaconda3/lib/python3.8/json/__init__.py", line 357, in loads', '    return _default_decoder.decode(s)', '  File "/Users/vishaljha/anaconda3/lib/python3.8/json/decoder.py", line 337, in decode', '    obj, end = self.raw_decode(s, idx=_w(s, 0).end())', '  File "/Users/vishaljha/anaconda3/lib/python3.8/json/decoder.py", line 355, in raw_decode', '    raise JSONDecodeError("Expecting value", s, err.value) from None', 'json.decoder.JSONDecodeError: Expecting value: line 1175 column 1 (char 16279)']
root - CRITICAL - CRITICAL ERROR:2023-06-15 12:19:13.383209 - Failed to initialise LTP gather module.
['Traceback (most recent call last):', '  File "/Users/vishaljha/Desktop/FINVANT/Alcubierre_Mk1_OMS/Backend/Scripts/GatherLTP.py", line 51, in __init__', '    self.instrument_token_list = instrument_token_json["instrument_tokens"]', "UnboundLocalError: local variable 'instrument_token_json' referenced before assignment"]
root - CRITICAL - CRITICAL ERROR:2023-06-15 12:19:13.517050 - Failed to generate user dictionary.
['Traceback (most recent call last):', '  File "Main.py", line 176, in main_loop', '    user_dict = UserProfileGenerator().create_user_profiles(user_data=user_data, log_interface=self.log_interface, debug=self.DEBUG)', '  File "/Users/vishaljha/Desktop/FINVANT/Alcubierre_Mk1_OMS/Backend/Scripts/UserProfileGenerator.py", line 67, in create_user_profiles', '    metrics = json.load(f)', '  File "/Users/vishaljha/anaconda3/lib/python3.8/json/__init__.py", line 293, in load', '    return loads(fp.read(),', '  File "/Users/vishaljha/anaconda3/lib/python3.8/json/__init__.py", line 357, in loads', '    return _default_decoder.decode(s)', '  File "/Users/vishaljha/anaconda3/lib/python3.8/json/decoder.py", line 337, in decode', '    obj, end = self.raw_decode(s, idx=_w(s, 0).end())', '  File "/Users/vishaljha/anaconda3/lib/python3.8/json/decoder.py", line 353, in raw_decode', '    obj, end = self.scan_once(s, idx)', 'json.decoder.JSONDecodeError: Expecting property name enclosed in double quotes: line 2 column 1 (char 2)']
root - CRITICAL - CRITICAL ERROR:2023-06-15 12:19:13.652710 - Failure in order handler.
['Traceback (most recent call last):', '  File "Main.py", line 184, in main_loop', '    order_handler = OrderHandler(user_profiles=user_dict, spread_list=spread_list, log_interface = self.log_interface, debug=self.DEBUG)', "UnboundLocalError: local variable 'user_dict' referenced before assignment"]
kiteconnect.ticker - ERROR - Connection error: 1006 - connection was closed uncleanly (I dropped the WebSocket TCP connection: 'GatherLTP' object has no attribute 'instrument_token_list')
kiteconnect.ticker - ERROR - Connection closed: 1006 - connection was closed uncleanly (I dropped the WebSocket TCP connection: 'GatherLTP' object has no attribute 'instrument_token_list')
kiteconnect.ticker - ERROR - Connection error: 1006 - connection was closed uncleanly (I dropped the WebSocket TCP connection: 'GatherLTP' object has no attribute 'instrument_token_list')
kiteconnect.ticker - ERROR - Connection closed: 1006 - connection was closed uncleanly (I dropped the WebSocket TCP connection: 'GatherLTP' object has no attribute 'instrument_token_list')
kiteconnect.ticker - ERROR - Connection error: 1006 - connection was closed uncleanly (I dropped the WebSocket TCP connection: 'GatherLTP' object has no attribute 'instrument_token_list')
kiteconnect.ticker - ERROR - Connection closed: 1006 - connection was closed uncleanly (I dropped the WebSocket TCP connection: 'GatherLTP' object has no attribute 'instrument_token_list')
kiteconnect.ticker - ERROR - Connection error: 1006 - connection was closed uncleanly (I dropped the WebSocket TCP connection: 'GatherLTP' object has no attribute 'instrument_token_list')
kiteconnect.ticker - ERROR - Connection closed: 1006 - connection was closed uncleanly (I dropped the WebSocket TCP connection: 'GatherLTP' object has no attribute 'instrument_token_list')
root - INFO - 2023-06-15 12:29:47.099261 - Finvant Alcubierre Mk1 OMS Backend turned on.
root - INFO - 2023-06-15 12:29:47.249561 - OMS Backend mainloop started.
root - INFO - 2023-06-15 12:29:47.458861 - User data obtained.
root - INFO - 2023-06-15 12:29:47.624944 - Spreads obtained.
root - INFO - 2023-06-15 12:29:47.783830 - Config file obtained.
root - INFO - 2023-06-15 12:29:47.947206 - OMSB: Logging in for backend kite ticker.
root - INFO - 2023-06-15 12:29:55.544857 - OMSB: Login succesful for backend kite ticker.
root - INFO - 2023-06-15 12:29:55.714670 - Initialising LTP gather thread.
root - CRITICAL - CRITICAL ERROR:2023-06-15 12:29:56.142758 - Failed to generate user dictionary.
['Traceback (most recent call last):', '  File "Main.py", line 176, in main_loop', '    user_dict = UserProfileGenerator().create_user_profiles(user_data=user_data, log_interface=self.log_interface, debug=self.DEBUG)', '  File "/Users/vishaljha/Desktop/FINVANT/Alcubierre_Mk1_OMS/Backend/Scripts/UserProfileGenerator.py", line 67, in create_user_profiles', '    metrics = json.load(f)', '  File "/Users/vishaljha/anaconda3/lib/python3.8/json/__init__.py", line 293, in load', '    return loads(fp.read(),', '  File "/Users/vishaljha/anaconda3/lib/python3.8/json/__init__.py", line 357, in loads', '    return _default_decoder.decode(s)', '  File "/Users/vishaljha/anaconda3/lib/python3.8/json/decoder.py", line 337, in decode', '    obj, end = self.raw_decode(s, idx=_w(s, 0).end())', '  File "/Users/vishaljha/anaconda3/lib/python3.8/json/decoder.py", line 353, in raw_decode', '    obj, end = self.scan_once(s, idx)', 'json.decoder.JSONDecodeError: Expecting property name enclosed in double quotes: line 2 column 1 (char 2)']
root - CRITICAL - CRITICAL ERROR:2023-06-15 12:29:56.312144 - Failure in order handler.
['Traceback (most recent call last):', '  File "Main.py", line 184, in main_loop', '    order_handler = OrderHandler(user_profiles=user_dict, spread_list=spread_list, log_interface = self.log_interface, debug=self.DEBUG)', "UnboundLocalError: local variable 'user_dict' referenced before assignment"]
kiteconnect.ticker - ERROR - Connection error: 1006 - connection was closed uncleanly (None)
kiteconnect.ticker - ERROR - Connection closed: 1006 - connection was closed uncleanly (None)
kiteconnect.ticker - ERROR - Connection error: 1006 - connection was closed uncleanly (None)
kiteconnect.ticker - ERROR - Connection closed: 1006 - connection was closed uncleanly (None)
kiteconnect.ticker - ERROR - Connection error: 1006 - connection was closed uncleanly (None)
kiteconnect.ticker - ERROR - Connection closed: 1006 - connection was closed uncleanly (None)
kiteconnect.ticker - ERROR - Connection error: 1006 - connection was closed uncleanly (None)
kiteconnect.ticker - ERROR - Connection closed: 1006 - connection was closed uncleanly (None)
root - INFO - 2023-06-15 12:30:58.463506 - Finvant Alcubierre Mk1 OMS Backend turned on.
root - INFO - 2023-06-15 12:30:58.609853 - OMS Backend mainloop started.
root - INFO - 2023-06-15 12:30:58.769072 - User data obtained.
root - INFO - 2023-06-15 12:30:58.938566 - Spreads obtained.
root - INFO - 2023-06-15 12:30:59.094057 - Config file obtained.
root - INFO - 2023-06-15 12:30:59.227402 - OMSB: Logging in for backend kite ticker.
root - INFO - 2023-06-15 12:31:07.077103 - OMSB: Login succesful for backend kite ticker.
root - INFO - 2023-06-15 12:31:07.225717 - Initialising LTP gather thread.
root - INFO - 2023-06-15 12:31:07.635380 - OMSB: Zerodha login for WG5235.
root - INFO - 2023-06-15 12:31:15.410322 - OMSB: Zerodha login succesful for WG5235.
root - INFO - 2023-06-15 12:31:15.555905 - Order handler initialised.
root - INFO - 2023-06-15 12:31:15.715508 - Creating order handler sub threads.
root - INFO - 2023-06-15 12:31:15.715709 - Starting order handler sub threads.
kiteconnect.ticker - ERROR - Connection error: 1006 - connection was closed uncleanly (None)
kiteconnect.ticker - ERROR - Connection closed: 1006 - connection was closed uncleanly (None)
kiteconnect.ticker - ERROR - Connection error: 1006 - connection was closed uncleanly (None)
kiteconnect.ticker - ERROR - Connection closed: 1006 - connection was closed uncleanly (None)
kiteconnect.ticker - ERROR - Connection error: 1006 - connection was closed uncleanly (None)
kiteconnect.ticker - ERROR - Connection closed: 1006 - connection was closed uncleanly (None)
kiteconnect.ticker - ERROR - Connection error: 1006 - connection was closed uncleanly (None)
kiteconnect.ticker - ERROR - Connection closed: 1006 - connection was closed uncleanly (None)
root - INFO - 2023-06-15 12:32:21.334405 - Placed Zerodha Kite options order for:fin_user_1, instrument:NIFTY2361518700PE, qty:-50, transaction type:SELL, placed price:12.8, id:769.
root - INFO - 2023-06-15 12:32:22.468041 - 1639.0399932861328
root - INFO - 2023-06-15 12:32:23.122515 - Placed Zerodha Kite options order for:fin_user_1, instrument:NIFTY2361518700CE, qty:50, transaction type:BUY, placed price:46.75, id:316.
root - INFO - 2023-06-15 12:32:24.020471 - 1403.2502174377441
root - CRITICAL - CRITICAL ERROR:2023-06-15 12:34:33.571464 - Failed to update LTPs.
['Traceback (most recent call last):', '  File "/Users/vishaljha/Desktop/FINVANT/Alcubierre_Mk1_OMS/Backend/Scripts/GatherLTP.py", line 109, in update_ltp', '    DBManager.update_LTP(instrument_token=instrument_token,LTP=last_price)', '  File "/Users/vishaljha/Desktop/FINVANT/Alcubierre_Mk1_OMS/Backend/Scripts/DBManager.py", line 145, in update_LTP', "    cur.execute('UPDATE order_reference SET position_value = {} - position_entry_price WHERE instrument_token = {} and position_type = {} and position_status = {};'.format(LTP,instrument_token,gSF('BUY'),gSF('PLACED')))", '  File "/Users/vishaljha/anaconda3/lib/python3.8/site-packages/pymysql/cursors.py", line 158, in execute', '    result = self._query(query)', '  File "/Users/vishaljha/anaconda3/lib/python3.8/site-packages/pymysql/cursors.py", line 325, in _query', '    conn.query(q)', '  File "/Users/vishaljha/anaconda3/lib/python3.8/site-packages/pymysql/connections.py", line 549, in query', '    self._affected_rows = self._read_query_result(unbuffered=unbuffered)', '  File "/Users/vishaljha/anaconda3/lib/python3.8/site-packages/pymysql/connections.py", line 779, in _read_query_result', '    result.read()', '  File "/Users/vishaljha/anaconda3/lib/python3.8/site-packages/pymysql/connections.py", line 1157, in read', '    first_packet = self.connection._read_packet()', '  File "/Users/vishaljha/anaconda3/lib/python3.8/site-packages/pymysql/connections.py", line 729, in _read_packet', '    packet.raise_for_error()', '  File "/Users/vishaljha/anaconda3/lib/python3.8/site-packages/pymysql/protocol.py", line 221, in raise_for_error', '    err.raise_mysql_exception(self._data)', '  File "/Users/vishaljha/anaconda3/lib/python3.8/site-packages/pymysql/err.py", line 143, in raise_mysql_exception', '    raise errorclass(errno, errval)', "pymysql.err.OperationalError: (1205, 'Lock wait timeout exceeded; try restarting transaction')"]
root - CRITICAL - CRITICAL ERROR:2023-06-15 12:35:24.031296 - Failed to update LTPs.
['Traceback (most recent call last):', '  File "/Users/vishaljha/Desktop/FINVANT/Alcubierre_Mk1_OMS/Backend/Scripts/GatherLTP.py", line 109, in update_ltp', '    DBManager.update_LTP(instrument_token=instrument_token,LTP=last_price)', '  File "/Users/vishaljha/Desktop/FINVANT/Alcubierre_Mk1_OMS/Backend/Scripts/DBManager.py", line 145, in update_LTP', "    cur.execute('UPDATE order_reference SET position_value = {} - position_entry_price WHERE instrument_token = {} and position_type = {} and position_status = {};'.format(LTP,instrument_token,gSF('BUY'),gSF('PLACED')))", '  File "/Users/vishaljha/anaconda3/lib/python3.8/site-packages/pymysql/cursors.py", line 158, in execute', '    result = self._query(query)', '  File "/Users/vishaljha/anaconda3/lib/python3.8/site-packages/pymysql/cursors.py", line 325, in _query', '    conn.query(q)', '  File "/Users/vishaljha/anaconda3/lib/python3.8/site-packages/pymysql/connections.py", line 549, in query', '    self._affected_rows = self._read_query_result(unbuffered=unbuffered)', '  File "/Users/vishaljha/anaconda3/lib/python3.8/site-packages/pymysql/connections.py", line 779, in _read_query_result', '    result.read()', '  File "/Users/vishaljha/anaconda3/lib/python3.8/site-packages/pymysql/connections.py", line 1157, in read', '    first_packet = self.connection._read_packet()', '  File "/Users/vishaljha/anaconda3/lib/python3.8/site-packages/pymysql/connections.py", line 729, in _read_packet', '    packet.raise_for_error()', '  File "/Users/vishaljha/anaconda3/lib/python3.8/site-packages/pymysql/protocol.py", line 221, in raise_for_error', '    err.raise_mysql_exception(self._data)', '  File "/Users/vishaljha/anaconda3/lib/python3.8/site-packages/pymysql/err.py", line 143, in raise_mysql_exception', '    raise errorclass(errno, errval)', "pymysql.err.OperationalError: (1205, 'Lock wait timeout exceeded; try restarting transaction')"]
root - CRITICAL - CRITICAL ERROR:2023-06-15 12:36:14.461443 - Failed to update LTPs.
['Traceback (most recent call last):', '  File "/Users/vishaljha/Desktop/FINVANT/Alcubierre_Mk1_OMS/Backend/Scripts/GatherLTP.py", line 109, in update_ltp', '    DBManager.update_LTP(instrument_token=instrument_token,LTP=last_price)', '  File "/Users/vishaljha/Desktop/FINVANT/Alcubierre_Mk1_OMS/Backend/Scripts/DBManager.py", line 145, in update_LTP', "    cur.execute('UPDATE order_reference SET position_value = {} - position_entry_price WHERE instrument_token = {} and position_type = {} and position_status = {};'.format(LTP,instrument_token,gSF('BUY'),gSF('PLACED')))", '  File "/Users/vishaljha/anaconda3/lib/python3.8/site-packages/pymysql/cursors.py", line 158, in execute', '    result = self._query(query)', '  File "/Users/vishaljha/anaconda3/lib/python3.8/site-packages/pymysql/cursors.py", line 325, in _query', '    conn.query(q)', '  File "/Users/vishaljha/anaconda3/lib/python3.8/site-packages/pymysql/connections.py", line 549, in query', '    self._affected_rows = self._read_query_result(unbuffered=unbuffered)', '  File "/Users/vishaljha/anaconda3/lib/python3.8/site-packages/pymysql/connections.py", line 779, in _read_query_result', '    result.read()', '  File "/Users/vishaljha/anaconda3/lib/python3.8/site-packages/pymysql/connections.py", line 1157, in read', '    first_packet = self.connection._read_packet()', '  File "/Users/vishaljha/anaconda3/lib/python3.8/site-packages/pymysql/connections.py", line 729, in _read_packet', '    packet.raise_for_error()', '  File "/Users/vishaljha/anaconda3/lib/python3.8/site-packages/pymysql/protocol.py", line 221, in raise_for_error', '    err.raise_mysql_exception(self._data)', '  File "/Users/vishaljha/anaconda3/lib/python3.8/site-packages/pymysql/err.py", line 143, in raise_mysql_exception', '    raise errorclass(errno, errval)', "pymysql.err.OperationalError: (1205, 'Lock wait timeout exceeded; try restarting transaction')"]
root - CRITICAL - CRITICAL ERROR:2023-06-15 12:37:04.906664 - Failed to update LTPs.
['Traceback (most recent call last):', '  File "/Users/vishaljha/Desktop/FINVANT/Alcubierre_Mk1_OMS/Backend/Scripts/GatherLTP.py", line 109, in update_ltp', '    DBManager.update_LTP(instrument_token=instrument_token,LTP=last_price)', '  File "/Users/vishaljha/Desktop/FINVANT/Alcubierre_Mk1_OMS/Backend/Scripts/DBManager.py", line 145, in update_LTP', "    cur.execute('UPDATE order_reference SET position_value = {} - position_entry_price WHERE instrument_token = {} and position_type = {} and position_status = {};'.format(LTP,instrument_token,gSF('BUY'),gSF('PLACED')))", '  File "/Users/vishaljha/anaconda3/lib/python3.8/site-packages/pymysql/cursors.py", line 158, in execute', '    result = self._query(query)', '  File "/Users/vishaljha/anaconda3/lib/python3.8/site-packages/pymysql/cursors.py", line 325, in _query', '    conn.query(q)', '  File "/Users/vishaljha/anaconda3/lib/python3.8/site-packages/pymysql/connections.py", line 549, in query', '    self._affected_rows = self._read_query_result(unbuffered=unbuffered)', '  File "/Users/vishaljha/anaconda3/lib/python3.8/site-packages/pymysql/connections.py", line 779, in _read_query_result', '    result.read()', '  File "/Users/vishaljha/anaconda3/lib/python3.8/site-packages/pymysql/connections.py", line 1157, in read', '    first_packet = self.connection._read_packet()', '  File "/Users/vishaljha/anaconda3/lib/python3.8/site-packages/pymysql/connections.py", line 729, in _read_packet', '    packet.raise_for_error()', '  File "/Users/vishaljha/anaconda3/lib/python3.8/site-packages/pymysql/protocol.py", line 221, in raise_for_error', '    err.raise_mysql_exception(self._data)', '  File "/Users/vishaljha/anaconda3/lib/python3.8/site-packages/pymysql/err.py", line 143, in raise_mysql_exception', '    raise errorclass(errno, errval)', "pymysql.err.OperationalError: (1205, 'Lock wait timeout exceeded; try restarting transaction')"]
root - CRITICAL - CRITICAL ERROR:2023-06-15 12:37:56.441580 - Failed to update LTPs.
['Traceback (most recent call last):', '  File "/Users/vishaljha/Desktop/FINVANT/Alcubierre_Mk1_OMS/Backend/Scripts/GatherLTP.py", line 109, in update_ltp', '    DBManager.update_LTP(instrument_token=instrument_token,LTP=last_price)', '  File "/Users/vishaljha/Desktop/FINVANT/Alcubierre_Mk1_OMS/Backend/Scripts/DBManager.py", line 145, in update_LTP', "    cur.execute('UPDATE order_reference SET position_value = {} - position_entry_price WHERE instrument_token = {} and position_type = {} and position_status = {};'.format(LTP,instrument_token,gSF('BUY'),gSF('PLACED')))", '  File "/Users/vishaljha/anaconda3/lib/python3.8/site-packages/pymysql/cursors.py", line 158, in execute', '    result = self._query(query)', '  File "/Users/vishaljha/anaconda3/lib/python3.8/site-packages/pymysql/cursors.py", line 325, in _query', '    conn.query(q)', '  File "/Users/vishaljha/anaconda3/lib/python3.8/site-packages/pymysql/connections.py", line 549, in query', '    self._affected_rows = self._read_query_result(unbuffered=unbuffered)', '  File "/Users/vishaljha/anaconda3/lib/python3.8/site-packages/pymysql/connections.py", line 779, in _read_query_result', '    result.read()', '  File "/Users/vishaljha/anaconda3/lib/python3.8/site-packages/pymysql/connections.py", line 1157, in read', '    first_packet = self.connection._read_packet()', '  File "/Users/vishaljha/anaconda3/lib/python3.8/site-packages/pymysql/connections.py", line 729, in _read_packet', '    packet.raise_for_error()', '  File "/Users/vishaljha/anaconda3/lib/python3.8/site-packages/pymysql/protocol.py", line 221, in raise_for_error', '    err.raise_mysql_exception(self._data)', '  File "/Users/vishaljha/anaconda3/lib/python3.8/site-packages/pymysql/err.py", line 143, in raise_mysql_exception', '    raise errorclass(errno, errval)', "pymysql.err.OperationalError: (1205, 'Lock wait timeout exceeded; try restarting transaction')"]
root - CRITICAL - CRITICAL ERROR:2023-06-15 12:38:47.538620 - Failed to update LTPs.
['Traceback (most recent call last):', '  File "/Users/vishaljha/Desktop/FINVANT/Alcubierre_Mk1_OMS/Backend/Scripts/GatherLTP.py", line 109, in update_ltp', '    DBManager.update_LTP(instrument_token=instrument_token,LTP=last_price)', '  File "/Users/vishaljha/Desktop/FINVANT/Alcubierre_Mk1_OMS/Backend/Scripts/DBManager.py", line 145, in update_LTP', "    cur.execute('UPDATE order_reference SET position_value = {} - position_entry_price WHERE instrument_token = {} and position_type = {} and position_status = {};'.format(LTP,instrument_token,gSF('BUY'),gSF('PLACED')))", '  File "/Users/vishaljha/anaconda3/lib/python3.8/site-packages/pymysql/cursors.py", line 158, in execute', '    result = self._query(query)', '  File "/Users/vishaljha/anaconda3/lib/python3.8/site-packages/pymysql/cursors.py", line 325, in _query', '    conn.query(q)', '  File "/Users/vishaljha/anaconda3/lib/python3.8/site-packages/pymysql/connections.py", line 549, in query', '    self._affected_rows = self._read_query_result(unbuffered=unbuffered)', '  File "/Users/vishaljha/anaconda3/lib/python3.8/site-packages/pymysql/connections.py", line 779, in _read_query_result', '    result.read()', '  File "/Users/vishaljha/anaconda3/lib/python3.8/site-packages/pymysql/connections.py", line 1157, in read', '    first_packet = self.connection._read_packet()', '  File "/Users/vishaljha/anaconda3/lib/python3.8/site-packages/pymysql/connections.py", line 729, in _read_packet', '    packet.raise_for_error()', '  File "/Users/vishaljha/anaconda3/lib/python3.8/site-packages/pymysql/protocol.py", line 221, in raise_for_error', '    err.raise_mysql_exception(self._data)', '  File "/Users/vishaljha/anaconda3/lib/python3.8/site-packages/pymysql/err.py", line 143, in raise_mysql_exception', '    raise errorclass(errno, errval)', "pymysql.err.OperationalError: (1205, 'Lock wait timeout exceeded; try restarting transaction')"]
root - CRITICAL - CRITICAL ERROR:2023-06-15 12:39:38.165320 - Failed to update LTPs.
['Traceback (most recent call last):', '  File "/Users/vishaljha/Desktop/FINVANT/Alcubierre_Mk1_OMS/Backend/Scripts/GatherLTP.py", line 109, in update_ltp', '    DBManager.update_LTP(instrument_token=instrument_token,LTP=last_price)', '  File "/Users/vishaljha/Desktop/FINVANT/Alcubierre_Mk1_OMS/Backend/Scripts/DBManager.py", line 145, in update_LTP', "    cur.execute('UPDATE order_reference SET position_value = {} - position_entry_price WHERE instrument_token = {} and position_type = {} and position_status = {};'.format(LTP,instrument_token,gSF('BUY'),gSF('PLACED')))", '  File "/Users/vishaljha/anaconda3/lib/python3.8/site-packages/pymysql/cursors.py", line 158, in execute', '    result = self._query(query)', '  File "/Users/vishaljha/anaconda3/lib/python3.8/site-packages/pymysql/cursors.py", line 325, in _query', '    conn.query(q)', '  File "/Users/vishaljha/anaconda3/lib/python3.8/site-packages/pymysql/connections.py", line 549, in query', '    self._affected_rows = self._read_query_result(unbuffered=unbuffered)', '  File "/Users/vishaljha/anaconda3/lib/python3.8/site-packages/pymysql/connections.py", line 779, in _read_query_result', '    result.read()', '  File "/Users/vishaljha/anaconda3/lib/python3.8/site-packages/pymysql/connections.py", line 1157, in read', '    first_packet = self.connection._read_packet()', '  File "/Users/vishaljha/anaconda3/lib/python3.8/site-packages/pymysql/connections.py", line 729, in _read_packet', '    packet.raise_for_error()', '  File "/Users/vishaljha/anaconda3/lib/python3.8/site-packages/pymysql/protocol.py", line 221, in raise_for_error', '    err.raise_mysql_exception(self._data)', '  File "/Users/vishaljha/anaconda3/lib/python3.8/site-packages/pymysql/err.py", line 143, in raise_mysql_exception', '    raise errorclass(errno, errval)', "pymysql.err.OperationalError: (1205, 'Lock wait timeout exceeded; try restarting transaction')"]
kiteconnect.ticker - ERROR - Connection error: 1006 - connection was closed uncleanly (None)
kiteconnect.ticker - ERROR - Connection closed: 1006 - connection was closed uncleanly (None)
root - CRITICAL - CRITICAL ERROR:2023-06-15 12:40:31.743404 - Failed to update LTPs.
['Traceback (most recent call last):', '  File "/Users/vishaljha/Desktop/FINVANT/Alcubierre_Mk1_OMS/Backend/Scripts/GatherLTP.py", line 109, in update_ltp', '    DBManager.update_LTP(instrument_token=instrument_token,LTP=last_price)', '  File "/Users/vishaljha/Desktop/FINVANT/Alcubierre_Mk1_OMS/Backend/Scripts/DBManager.py", line 145, in update_LTP', "    cur.execute('UPDATE order_reference SET position_value = {} - position_entry_price WHERE instrument_token = {} and position_type = {} and position_status = {};'.format(LTP,instrument_token,gSF('BUY'),gSF('PLACED')))", '  File "/Users/vishaljha/anaconda3/lib/python3.8/site-packages/pymysql/cursors.py", line 158, in execute', '    result = self._query(query)', '  File "/Users/vishaljha/anaconda3/lib/python3.8/site-packages/pymysql/cursors.py", line 325, in _query', '    conn.query(q)', '  File "/Users/vishaljha/anaconda3/lib/python3.8/site-packages/pymysql/connections.py", line 549, in query', '    self._affected_rows = self._read_query_result(unbuffered=unbuffered)', '  File "/Users/vishaljha/anaconda3/lib/python3.8/site-packages/pymysql/connections.py", line 779, in _read_query_result', '    result.read()', '  File "/Users/vishaljha/anaconda3/lib/python3.8/site-packages/pymysql/connections.py", line 1157, in read', '    first_packet = self.connection._read_packet()', '  File "/Users/vishaljha/anaconda3/lib/python3.8/site-packages/pymysql/connections.py", line 729, in _read_packet', '    packet.raise_for_error()', '  File "/Users/vishaljha/anaconda3/lib/python3.8/site-packages/pymysql/protocol.py", line 221, in raise_for_error', '    err.raise_mysql_exception(self._data)', '  File "/Users/vishaljha/anaconda3/lib/python3.8/site-packages/pymysql/err.py", line 143, in raise_mysql_exception', '    raise errorclass(errno, errval)', "pymysql.err.OperationalError: (1205, 'Lock wait timeout exceeded; try restarting transaction')"]
kiteconnect.ticker - ERROR - Connection error: 1006 - connection was closed uncleanly (None)
kiteconnect.ticker - ERROR - Connection closed: 1006 - connection was closed uncleanly (None)
root - CRITICAL - CRITICAL ERROR:2023-06-15 12:41:25.578223 - Failed to update LTPs.
['Traceback (most recent call last):', '  File "/Users/vishaljha/Desktop/FINVANT/Alcubierre_Mk1_OMS/Backend/Scripts/GatherLTP.py", line 109, in update_ltp', '    DBManager.update_LTP(instrument_token=instrument_token,LTP=last_price)', '  File "/Users/vishaljha/Desktop/FINVANT/Alcubierre_Mk1_OMS/Backend/Scripts/DBManager.py", line 145, in update_LTP', "    cur.execute('UPDATE order_reference SET position_value = {} - position_entry_price WHERE instrument_token = {} and position_type = {} and position_status = {};'.format(LTP,instrument_token,gSF('BUY'),gSF('PLACED')))", '  File "/Users/vishaljha/anaconda3/lib/python3.8/site-packages/pymysql/cursors.py", line 158, in execute', '    result = self._query(query)', '  File "/Users/vishaljha/anaconda3/lib/python3.8/site-packages/pymysql/cursors.py", line 325, in _query', '    conn.query(q)', '  File "/Users/vishaljha/anaconda3/lib/python3.8/site-packages/pymysql/connections.py", line 549, in query', '    self._affected_rows = self._read_query_result(unbuffered=unbuffered)', '  File "/Users/vishaljha/anaconda3/lib/python3.8/site-packages/pymysql/connections.py", line 779, in _read_query_result', '    result.read()', '  File "/Users/vishaljha/anaconda3/lib/python3.8/site-packages/pymysql/connections.py", line 1157, in read', '    first_packet = self.connection._read_packet()', '  File "/Users/vishaljha/anaconda3/lib/python3.8/site-packages/pymysql/connections.py", line 729, in _read_packet', '    packet.raise_for_error()', '  File "/Users/vishaljha/anaconda3/lib/python3.8/site-packages/pymysql/protocol.py", line 221, in raise_for_error', '    err.raise_mysql_exception(self._data)', '  File "/Users/vishaljha/anaconda3/lib/python3.8/site-packages/pymysql/err.py", line 143, in raise_mysql_exception', '    raise errorclass(errno, errval)', "pymysql.err.OperationalError: (1205, 'Lock wait timeout exceeded; try restarting transaction')"]
root - CRITICAL - CRITICAL ERROR:2023-06-15 12:42:16.067057 - Failed to update LTPs.
['Traceback (most recent call last):', '  File "/Users/vishaljha/Desktop/FINVANT/Alcubierre_Mk1_OMS/Backend/Scripts/GatherLTP.py", line 109, in update_ltp', '    DBManager.update_LTP(instrument_token=instrument_token,LTP=last_price)', '  File "/Users/vishaljha/Desktop/FINVANT/Alcubierre_Mk1_OMS/Backend/Scripts/DBManager.py", line 145, in update_LTP', "    cur.execute('UPDATE order_reference SET position_value = {} - position_entry_price WHERE instrument_token = {} and position_type = {} and position_status = {};'.format(LTP,instrument_token,gSF('BUY'),gSF('PLACED')))", '  File "/Users/vishaljha/anaconda3/lib/python3.8/site-packages/pymysql/cursors.py", line 158, in execute', '    result = self._query(query)', '  File "/Users/vishaljha/anaconda3/lib/python3.8/site-packages/pymysql/cursors.py", line 325, in _query', '    conn.query(q)', '  File "/Users/vishaljha/anaconda3/lib/python3.8/site-packages/pymysql/connections.py", line 549, in query', '    self._affected_rows = self._read_query_result(unbuffered=unbuffered)', '  File "/Users/vishaljha/anaconda3/lib/python3.8/site-packages/pymysql/connections.py", line 779, in _read_query_result', '    result.read()', '  File "/Users/vishaljha/anaconda3/lib/python3.8/site-packages/pymysql/connections.py", line 1157, in read', '    first_packet = self.connection._read_packet()', '  File "/Users/vishaljha/anaconda3/lib/python3.8/site-packages/pymysql/connections.py", line 729, in _read_packet', '    packet.raise_for_error()', '  File "/Users/vishaljha/anaconda3/lib/python3.8/site-packages/pymysql/protocol.py", line 221, in raise_for_error', '    err.raise_mysql_exception(self._data)', '  File "/Users/vishaljha/anaconda3/lib/python3.8/site-packages/pymysql/err.py", line 143, in raise_mysql_exception', '    raise errorclass(errno, errval)', "pymysql.err.OperationalError: (1205, 'Lock wait timeout exceeded; try restarting transaction')"]
root - CRITICAL - CRITICAL ERROR:2023-06-15 12:43:06.571105 - Failed to update LTPs.
['Traceback (most recent call last):', '  File "/Users/vishaljha/Desktop/FINVANT/Alcubierre_Mk1_OMS/Backend/Scripts/GatherLTP.py", line 109, in update_ltp', '    DBManager.update_LTP(instrument_token=instrument_token,LTP=last_price)', '  File "/Users/vishaljha/Desktop/FINVANT/Alcubierre_Mk1_OMS/Backend/Scripts/DBManager.py", line 145, in update_LTP', "    cur.execute('UPDATE order_reference SET position_value = {} - position_entry_price WHERE instrument_token = {} and position_type = {} and position_status = {};'.format(LTP,instrument_token,gSF('BUY'),gSF('PLACED')))", '  File "/Users/vishaljha/anaconda3/lib/python3.8/site-packages/pymysql/cursors.py", line 158, in execute', '    result = self._query(query)', '  File "/Users/vishaljha/anaconda3/lib/python3.8/site-packages/pymysql/cursors.py", line 325, in _query', '    conn.query(q)', '  File "/Users/vishaljha/anaconda3/lib/python3.8/site-packages/pymysql/connections.py", line 549, in query', '    self._affected_rows = self._read_query_result(unbuffered=unbuffered)', '  File "/Users/vishaljha/anaconda3/lib/python3.8/site-packages/pymysql/connections.py", line 779, in _read_query_result', '    result.read()', '  File "/Users/vishaljha/anaconda3/lib/python3.8/site-packages/pymysql/connections.py", line 1157, in read', '    first_packet = self.connection._read_packet()', '  File "/Users/vishaljha/anaconda3/lib/python3.8/site-packages/pymysql/connections.py", line 729, in _read_packet', '    packet.raise_for_error()', '  File "/Users/vishaljha/anaconda3/lib/python3.8/site-packages/pymysql/protocol.py", line 221, in raise_for_error', '    err.raise_mysql_exception(self._data)', '  File "/Users/vishaljha/anaconda3/lib/python3.8/site-packages/pymysql/err.py", line 143, in raise_mysql_exception', '    raise errorclass(errno, errval)', "pymysql.err.OperationalError: (1205, 'Lock wait timeout exceeded; try restarting transaction')"]
root - CRITICAL - CRITICAL ERROR:2023-06-15 12:43:57.178078 - Failed to update LTPs.
['Traceback (most recent call last):', '  File "/Users/vishaljha/Desktop/FINVANT/Alcubierre_Mk1_OMS/Backend/Scripts/GatherLTP.py", line 109, in update_ltp', '    DBManager.update_LTP(instrument_token=instrument_token,LTP=last_price)', '  File "/Users/vishaljha/Desktop/FINVANT/Alcubierre_Mk1_OMS/Backend/Scripts/DBManager.py", line 145, in update_LTP', "    cur.execute('UPDATE order_reference SET position_value = {} - position_entry_price WHERE instrument_token = {} and position_type = {} and position_status = {};'.format(LTP,instrument_token,gSF('BUY'),gSF('PLACED')))", '  File "/Users/vishaljha/anaconda3/lib/python3.8/site-packages/pymysql/cursors.py", line 158, in execute', '    result = self._query(query)', '  File "/Users/vishaljha/anaconda3/lib/python3.8/site-packages/pymysql/cursors.py", line 325, in _query', '    conn.query(q)', '  File "/Users/vishaljha/anaconda3/lib/python3.8/site-packages/pymysql/connections.py", line 549, in query', '    self._affected_rows = self._read_query_result(unbuffered=unbuffered)', '  File "/Users/vishaljha/anaconda3/lib/python3.8/site-packages/pymysql/connections.py", line 779, in _read_query_result', '    result.read()', '  File "/Users/vishaljha/anaconda3/lib/python3.8/site-packages/pymysql/connections.py", line 1157, in read', '    first_packet = self.connection._read_packet()', '  File "/Users/vishaljha/anaconda3/lib/python3.8/site-packages/pymysql/connections.py", line 729, in _read_packet', '    packet.raise_for_error()', '  File "/Users/vishaljha/anaconda3/lib/python3.8/site-packages/pymysql/protocol.py", line 221, in raise_for_error', '    err.raise_mysql_exception(self._data)', '  File "/Users/vishaljha/anaconda3/lib/python3.8/site-packages/pymysql/err.py", line 143, in raise_mysql_exception', '    raise errorclass(errno, errval)', "pymysql.err.OperationalError: (1205, 'Lock wait timeout exceeded; try restarting transaction')"]
root - INFO - 2023-06-15 13:39:03.287380 - Finvant Alcubierre Mk1 OMS Backend turned on.
root - INFO - 2023-06-15 13:39:03.443146 - OMS Backend mainloop started.
root - INFO - 2023-06-15 13:39:03.639842 - User data obtained.
root - INFO - 2023-06-15 13:39:03.793358 - Spreads obtained.
root - INFO - 2023-06-15 13:39:03.922274 - Config file obtained.
root - INFO - 2023-06-15 13:39:04.051508 - OMSB: Logging in for backend kite ticker.
root - INFO - 2023-06-15 13:39:12.762320 - OMSB: Login succesful for backend kite ticker.
root - INFO - 2023-06-15 13:39:12.895731 - Initialising LTP gather thread.
root - INFO - 2023-06-15 13:39:13.316296 - OMSB: Zerodha login for WG5235.
root - INFO - 2023-06-15 13:39:20.271553 - OMSB: Zerodha login succesful for WG5235.
root - INFO - 2023-06-15 13:39:20.449333 - Order handler initialised.
root - INFO - 2023-06-15 13:39:20.593231 - Creating order handler sub threads.
root - INFO - 2023-06-15 13:39:20.593474 - Starting order handler sub threads.
kiteconnect.ticker - ERROR - Connection error: 1006 - connection was closed uncleanly (None)
kiteconnect.ticker - ERROR - Connection closed: 1006 - connection was closed uncleanly (None)
kiteconnect.ticker - ERROR - Connection error: 1006 - connection was closed uncleanly (None)
kiteconnect.ticker - ERROR - Connection closed: 1006 - connection was closed uncleanly (None)
root - INFO - 2023-06-15 13:47:44.119177 - Finvant Alcubierre Mk1 OMS Backend turned on.
root - INFO - 2023-06-15 13:47:44.254286 - OMS Backend mainloop started.
root - INFO - 2023-06-15 13:47:44.424839 - User data obtained.
root - INFO - 2023-06-15 13:47:44.585747 - Spreads obtained.
root - INFO - 2023-06-15 13:47:44.983036 - Config file obtained.
root - INFO - 2023-06-15 13:47:45.113401 - OMSB: Logging in for backend kite ticker.
root - INFO - 2023-06-15 13:47:52.665768 - OMSB: Login succesful for backend kite ticker.
root - INFO - 2023-06-15 13:47:52.794736 - Initialising LTP gather thread.
root - INFO - 2023-06-15 13:47:53.228391 - OMSB: Zerodha login for WG5235.
root - INFO - 2023-06-15 13:48:00.167747 - OMSB: Zerodha login succesful for WG5235.
root - INFO - 2023-06-15 13:48:00.311766 - Order handler initialised.
root - INFO - 2023-06-15 13:48:00.448151 - Creating order handler sub threads.
root - INFO - 2023-06-15 13:48:00.448322 - Starting order handler sub threads.
kiteconnect.ticker - ERROR - Connection error: 1006 - connection was closed uncleanly (None)
kiteconnect.ticker - ERROR - Connection closed: 1006 - connection was closed uncleanly (None)
kiteconnect.ticker - ERROR - Connection error: 1006 - connection was closed uncleanly (None)
kiteconnect.ticker - ERROR - Connection closed: 1006 - connection was closed uncleanly (None)
kiteconnect.ticker - ERROR - Connection error: 1006 - connection was closed uncleanly (None)
kiteconnect.ticker - ERROR - Connection closed: 1006 - connection was closed uncleanly (None)
kiteconnect.ticker - ERROR - Connection error: 1006 - connection was closed uncleanly (None)
kiteconnect.ticker - ERROR - Connection closed: 1006 - connection was closed uncleanly (None)
kiteconnect.ticker - ERROR - Connection error: 1006 - connection was closed uncleanly (None)
kiteconnect.ticker - ERROR - Connection closed: 1006 - connection was closed uncleanly (None)
root - CRITICAL - CRITICAL ERROR:2023-06-15 13:48:48.793453 - Failed to refresh lookup table.
['Traceback (most recent call last):', '  File "/Users/vishaljha/Desktop/FINVANT/Alcubierre_Mk1_OMS/Backend/Scripts/GatherLTP.py", line 70, in refresh_lookup_table', '    self.lookup_table = json.load(f)', '  File "/Users/vishaljha/anaconda3/lib/python3.8/json/__init__.py", line 293, in load', '    return loads(fp.read(),', '  File "/Users/vishaljha/anaconda3/lib/python3.8/json/__init__.py", line 357, in loads', '    return _default_decoder.decode(s)', '  File "/Users/vishaljha/anaconda3/lib/python3.8/json/decoder.py", line 337, in decode', '    obj, end = self.raw_decode(s, idx=_w(s, 0).end())', '  File "/Users/vishaljha/anaconda3/lib/python3.8/json/decoder.py", line 355, in raw_decode', '    raise JSONDecodeError("Expecting value", s, err.value) from None', 'json.decoder.JSONDecodeError: Expecting value: line 1 column 1 (char 0)']
kiteconnect.ticker - ERROR - Connection error: 1006 - connection was closed uncleanly (None)
kiteconnect.ticker - ERROR - Connection closed: 1006 - connection was closed uncleanly (None)
kiteconnect.ticker - ERROR - Connection error: 1006 - connection was closed uncleanly (None)
kiteconnect.ticker - ERROR - Connection closed: 1006 - connection was closed uncleanly (None)
root - INFO - 2023-06-15 13:49:20.129642 - Finvant Alcubierre Mk1 OMS Backend turned on.
root - INFO - 2023-06-15 13:49:20.266077 - OMS Backend mainloop started.
root - INFO - 2023-06-15 13:49:20.428423 - User data obtained.
root - INFO - 2023-06-15 13:49:20.588701 - Spreads obtained.
root - INFO - 2023-06-15 13:49:20.729202 - Config file obtained.
root - INFO - 2023-06-15 13:49:20.874365 - OMSB: Logging in for backend kite ticker.
root - INFO - 2023-06-15 13:49:28.191510 - OMSB: Login succesful for backend kite ticker.
root - INFO - 2023-06-15 13:49:28.322002 - Initialising LTP gather thread.
root - INFO - 2023-06-15 13:49:28.720378 - OMSB: Zerodha login for WG5235.
root - INFO - 2023-06-15 13:49:36.623888 - OMSB: Zerodha login succesful for WG5235.
root - INFO - 2023-06-15 13:49:36.785321 - Order handler initialised.
root - INFO - 2023-06-15 13:49:36.927343 - Creating order handler sub threads.
root - INFO - 2023-06-15 13:49:36.927513 - Starting order handler sub threads.
root - INFO - 2023-06-15 13:49:37.609940 - Placed Zerodha Kite options order for:fin_user_1, instrument:NIFTY2361518700CE, qty:50, transaction type:BUY, placed price:51.3, id:179.
kiteconnect.ticker - ERROR - Connection error: 1006 - connection was closed uncleanly (None)
kiteconnect.ticker - ERROR - Connection closed: 1006 - connection was closed uncleanly (None)
root - INFO - 2023-06-15 13:49:38.571817 - 1466.32981300354
root - INFO - 2023-06-15 13:49:39.209866 - Placed Zerodha Kite options order for:fin_user_1, instrument:NIFTY2361518700PE, qty:-50, transaction type:SELL, placed price:10.7, id:311.
root - INFO - 2023-06-15 13:49:40.091984 - 1387.8331184387207
kiteconnect.ticker - ERROR - Connection error: 1006 - connection was closed uncleanly (None)
kiteconnect.ticker - ERROR - Connection closed: 1006 - connection was closed uncleanly (None)
root - INFO - 2023-06-15 13:50:02.118022 - Placed Zerodha Kite options order for:fin_user_1, instrument:NIFTY2361518700CE, qty:-50, transaction type:SELL, placed price:51.45, id:99.
root - INFO - 2023-06-15 13:50:03.068898 - 1455.3320407867432
kiteconnect.ticker - ERROR - Connection error: 1006 - connection was closed uncleanly (None)
kiteconnect.ticker - ERROR - Connection closed: 1006 - connection was closed uncleanly (None)
root - INFO - 2023-06-15 13:50:03.754514 - Placed Zerodha Kite options order for:fin_user_1, instrument:NIFTY2361518700PE, qty:50, transaction type:BUY, placed price:10.35, id:821.
root - INFO - 2023-06-15 13:50:04.629390 - 1376.328945159912
kiteconnect.ticker - ERROR - Connection error: 1006 - connection was closed uncleanly (None)
kiteconnect.ticker - ERROR - Connection closed: 1006 - connection was closed uncleanly (None)
kiteconnect.ticker - ERROR - Connection error: 1006 - connection was closed uncleanly (None)
kiteconnect.ticker - ERROR - Connection closed: 1006 - connection was closed uncleanly (None)
kiteconnect.ticker - ERROR - Connection error: 1006 - connection was closed uncleanly (None)
kiteconnect.ticker - ERROR - Connection closed: 1006 - connection was closed uncleanly (None)
root - INFO - 2023-06-15 17:46:28.700215 - Finvant Alcubierre Mk1 OMS Backend turned on.
root - INFO - 2023-06-15 17:46:28.831687 - OMS Backend mainloop started.
root - INFO - 2023-06-15 17:46:28.987704 - User data obtained.
root - INFO - 2023-06-15 17:46:30.130187 - Spreads obtained.
root - INFO - 2023-06-15 17:46:30.258774 - Config file obtained.
root - INFO - 2023-06-15 17:46:30.397307 - OMSB: Logging in for backend kite ticker.
root - INFO - 2023-06-15 17:46:41.961737 - OMSB: Login succesful for backend kite ticker.
root - INFO - 2023-06-15 17:46:42.117871 - Initialising LTP gather thread.
root - INFO - 2023-06-15 17:46:42.563203 - OMSB: Zerodha login for WG5235.
root - INFO - 2023-06-15 17:46:49.352362 - OMSB: Zerodha login succesful for WG5235.
root - INFO - 2023-06-15 17:46:49.491134 - Order handler initialised.
root - INFO - 2023-06-15 17:46:49.619106 - Creating order handler sub threads.
root - INFO - 2023-06-15 17:46:49.619351 - Starting order handler sub threads.
kiteconnect.ticker - ERROR - Connection error: 1006 - connection was closed uncleanly (None)
kiteconnect.ticker - ERROR - Connection closed: 1006 - connection was closed uncleanly (None)
kiteconnect.ticker - ERROR - Connection error: 1006 - connection was closed uncleanly (None)
kiteconnect.ticker - ERROR - Connection closed: 1006 - connection was closed uncleanly (None)
kiteconnect.ticker - ERROR - Connection error: 1006 - connection was closed uncleanly (None)
kiteconnect.ticker - ERROR - Connection closed: 1006 - connection was closed uncleanly (None)
root - INFO - 2023-06-15 17:47:36.967338 - Finvant Alcubierre Mk1 OMS Backend turned on.
root - INFO - 2023-06-15 17:47:37.095094 - OMS Backend mainloop started.
root - INFO - 2023-06-15 17:47:37.240093 - User data obtained.
root - INFO - 2023-06-15 17:47:37.389353 - Spreads obtained.
root - INFO - 2023-06-15 17:47:37.516584 - Config file obtained.
root - INFO - 2023-06-15 17:47:37.645021 - OMSB: Logging in for backend kite ticker.
root - INFO - 2023-06-15 17:47:45.419506 - OMSB: Login succesful for backend kite ticker.
root - INFO - 2023-06-15 17:47:45.587421 - Initialising LTP gather thread.
root - CRITICAL - CRITICAL ERROR:2023-06-15 17:47:45.733024 - Failed to initialise LTP gather module.
['Traceback (most recent call last):', '  File "/Users/vishaljha/anaconda3/lib/python3.8/site-packages/requests/packages/urllib3/connection.py", line 140, in _new_conn', '    conn = connection.create_connection(', '  File "/Users/vishaljha/anaconda3/lib/python3.8/site-packages/requests/packages/urllib3/util/connection.py", line 83, in create_connection', '    raise err', '  File "/Users/vishaljha/anaconda3/lib/python3.8/site-packages/requests/packages/urllib3/util/connection.py", line 73, in create_connection', '    sock.connect(sa)', 'ConnectionRefusedError: [Errno 61] Connection refused', '', 'During handling of the above exception, another exception occurred:', '', 'Traceback (most recent call last):', '  File "/Users/vishaljha/anaconda3/lib/python3.8/site-packages/requests/packages/urllib3/connectionpool.py", line 597, in urlopen', '    httplib_response = self._make_request(conn, method, url,', '  File "/Users/vishaljha/anaconda3/lib/python3.8/site-packages/requests/packages/urllib3/connectionpool.py", line 356, in _make_request', '    conn.request(method, url, **httplib_request_kw)', '  File "/Users/vishaljha/anaconda3/lib/python3.8/http/client.py", line 1240, in request', '    self._send_request(method, url, body, headers, encode_chunked)', '  File "/Users/vishaljha/anaconda3/lib/python3.8/http/client.py", line 1286, in _send_request', '    self.endheaders(body, encode_chunked=encode_chunked)', '  File "/Users/vishaljha/anaconda3/lib/python3.8/http/client.py", line 1235, in endheaders', '    self._send_output(message_body, encode_chunked=encode_chunked)', '  File "/Users/vishaljha/anaconda3/lib/python3.8/http/client.py", line 1006, in _send_output', '    self.send(msg)', '  File "/Users/vishaljha/anaconda3/lib/python3.8/http/client.py", line 946, in send', '    self.connect()', '  File "/Users/vishaljha/anaconda3/lib/python3.8/site-packages/requests/packages/urllib3/connection.py", line 166, in connect', '    conn = self._new_conn()', '  File "/Users/vishaljha/anaconda3/lib/python3.8/site-packages/requests/packages/urllib3/connection.py", line 149, in _new_conn', '    raise NewConnectionError(', 'requests.packages.urllib3.exceptions.NewConnectionError: <requests.packages.urllib3.connection.HTTPConnection object at 0x7fd5741261f0>: Failed to establish a new connection: [Errno 61] Connection refused', '', 'During handling of the above exception, another exception occurred:', '', 'Traceback (most recent call last):', '  File "/Users/vishaljha/anaconda3/lib/python3.8/site-packages/requests/adapters.py", line 413, in send', '    resp = conn.urlopen(', '  File "/Users/vishaljha/anaconda3/lib/python3.8/site-packages/requests/packages/urllib3/connectionpool.py", line 648, in urlopen', '    retries = retries.increment(method, url, error=e, _pool=self,', '  File "/Users/vishaljha/anaconda3/lib/python3.8/site-packages/requests/packages/urllib3/util/retry.py", line 376, in increment', '    raise MaxRetryError(_pool, url, error or ResponseError(cause))', "requests.packages.urllib3.exceptions.MaxRetryError: HTTPConnectionPool(host='127.0.0.1', port=9093): Max retries exceeded with url: /token (Caused by NewConnectionError('<requests.packages.urllib3.connection.HTTPConnection object at 0x7fd5741261f0>: Failed to establish a new connection: [Errno 61] Connection refused'))", '', 'During handling of the above exception, another exception occurred:', '', 'Traceback (most recent call last):', '  File "/Users/vishaljha/Desktop/FINVANT/Alcubierre_Mk1_OMS/Backend/Scripts/GatherLTP.py", line 32, in __init__', '    self.OMS_interface = OMS_API_Interface.OMS_Interface(Config().OMS_SERVER_ADDRESS)', '  File "/Users/vishaljha/Desktop/FINVANT/Alcubierre_Mk1_OMS/Backend/Scripts/OMS_API_Interface.py", line 12, in __init__', '    self.token = self.authentification()', '  File "/Users/vishaljha/Desktop/FINVANT/Alcubierre_Mk1_OMS/Backend/Scripts/OMS_API_Interface.py", line 23, in authentification', "    response = requests.post(self.url + 'token', data=data)", '  File "/Users/vishaljha/anaconda3/lib/python3.8/site-packages/requests/api.py", line 110, in post', "    return request('post', url, data=data, json=json, **kwargs)", '  File "/Users/vishaljha/anaconda3/lib/python3.8/site-packages/requests/api.py", line 56, in request', '    return session.request(method=method, url=url, **kwargs)', '  File "/Users/vishaljha/anaconda3/lib/python3.8/site-packages/requests/sessions.py", line 488, in request', '    resp = self.send(prep, **send_kwargs)', '  File "/Users/vishaljha/anaconda3/lib/python3.8/site-packages/requests/sessions.py", line 609, in send', '    r = adapter.send(request, **kwargs)', '  File "/Users/vishaljha/anaconda3/lib/python3.8/site-packages/requests/adapters.py", line 487, in send', '    raise ConnectionError(e, request=request)', "requests.exceptions.ConnectionError: HTTPConnectionPool(host='127.0.0.1', port=9093): Max retries exceeded with url: /token (Caused by NewConnectionError('<requests.packages.urllib3.connection.HTTPConnection object at 0x7fd5741261f0>: Failed to establish a new connection: [Errno 61] Connection refused'))"]
root - INFO - 2023-06-15 17:47:45.888892 - OMSB: Zerodha login for WG5235.
kiteconnect.ticker - ERROR - Connection error: 1006 - connection was closed uncleanly (I dropped the WebSocket TCP connection: 'GatherLTP' object has no attribute 'instrument_token_list')
kiteconnect.ticker - ERROR - Connection closed: 1006 - connection was closed uncleanly (I dropped the WebSocket TCP connection: 'GatherLTP' object has no attribute 'instrument_token_list')
kiteconnect.ticker - ERROR - Connection error: 1006 - connection was closed uncleanly (I dropped the WebSocket TCP connection: 'GatherLTP' object has no attribute 'instrument_token_list')
kiteconnect.ticker - ERROR - Connection closed: 1006 - connection was closed uncleanly (I dropped the WebSocket TCP connection: 'GatherLTP' object has no attribute 'instrument_token_list')
root - INFO - 2023-06-15 17:47:52.753076 - OMSB: Zerodha login succesful for WG5235.
root - INFO - 2023-06-15 17:47:52.884398 - Order handler initialised.
root - INFO - 2023-06-15 17:47:53.030108 - Creating order handler sub threads.
root - INFO - 2023-06-15 17:47:53.030429 - Starting order handler sub threads.
kiteconnect.ticker - ERROR - Connection error: 1006 - connection was closed uncleanly (I dropped the WebSocket TCP connection: 'GatherLTP' object has no attribute 'instrument_token_list')
kiteconnect.ticker - ERROR - Connection closed: 1006 - connection was closed uncleanly (I dropped the WebSocket TCP connection: 'GatherLTP' object has no attribute 'instrument_token_list')
root - INFO - 2023-06-15 17:49:05.064254 - Finvant Alcubierre Mk1 OMS Backend turned on.
root - INFO - 2023-06-15 17:49:05.193278 - OMS Backend mainloop started.
root - INFO - 2023-06-15 17:49:05.346381 - User data obtained.
root - INFO - 2023-06-15 17:49:05.496502 - Spreads obtained.
root - INFO - 2023-06-15 17:49:05.633913 - Config file obtained.
root - INFO - 2023-06-15 17:49:05.767643 - OMSB: Logging in for backend kite ticker.
root - INFO - 2023-06-15 17:49:14.137206 - OMSB: Login succesful for backend kite ticker.
root - INFO - 2023-06-15 17:49:14.269140 - Initialising LTP gather thread.
root - INFO - 2023-06-15 17:49:14.671833 - OMSB: Zerodha login for WG5235.
root - INFO - 2023-06-15 17:49:22.453504 - OMSB: Zerodha login succesful for WG5235.
root - INFO - 2023-06-15 17:49:23.589964 - Order handler initialised.
root - INFO - 2023-06-15 17:49:23.722027 - Creating order handler sub threads.
root - INFO - 2023-06-15 17:49:23.722178 - Starting order handler sub threads.
root - INFO - 2023-06-15 17:49:41.967278 - Placed Zerodha Kite futures order for:fin_user_1, instrument:NIFTY23JULFUT, qty:-50, transaction type:SELL, placed price:18825.0, id:561.
root - INFO - 2023-06-15 17:49:43.085461 - 1119.6379661560059
kiteconnect.ticker - ERROR - Connection error: 1006 - connection was closed uncleanly (None)
kiteconnect.ticker - ERROR - Connection closed: 1006 - connection was closed uncleanly (None)
kiteconnect.ticker - ERROR - Connection error: 1006 - connection was closed uncleanly (None)
kiteconnect.ticker - ERROR - Connection closed: 1006 - connection was closed uncleanly (None)
root - INFO - 2023-06-15 17:50:09.885505 - Placed Zerodha Kite futures order for:fin_user_1, instrument:NIFTY23JULFUT, qty:50, transaction type:BUY, placed price:18825.0, id:634.
root - INFO - 2023-06-15 17:50:11.275261 - 1393.6920166015625
kiteconnect.ticker - ERROR - Connection error: 1006 - connection was closed uncleanly (None)
kiteconnect.ticker - ERROR - Connection closed: 1006 - connection was closed uncleanly (None)
kiteconnect.ticker - ERROR - Connection error: 1006 - connection was closed uncleanly (None)
kiteconnect.ticker - ERROR - Connection closed: 1006 - connection was closed uncleanly (None)
kiteconnect.ticker - ERROR - Connection error: 1006 - connection was closed uncleanly (None)
kiteconnect.ticker - ERROR - Connection closed: 1006 - connection was closed uncleanly (None)
kiteconnect.ticker - ERROR - Connection error: 1006 - connection was closed uncleanly (None)
kiteconnect.ticker - ERROR - Connection closed: 1006 - connection was closed uncleanly (None)
kiteconnect.ticker - ERROR - Connection error: 1006 - connection was closed uncleanly (None)
kiteconnect.ticker - ERROR - Connection closed: 1006 - connection was closed uncleanly (None)
kiteconnect.ticker - ERROR - Connection error: 1006 - connection was closed uncleanly (None)
kiteconnect.ticker - ERROR - Connection closed: 1006 - connection was closed uncleanly (None)
kiteconnect.ticker - ERROR - Connection error: 1006 - connection was closed uncleanly (None)
kiteconnect.ticker - ERROR - Connection closed: 1006 - connection was closed uncleanly (None)
kiteconnect.ticker - ERROR - Connection error: 1006 - connection was closed uncleanly (None)
kiteconnect.ticker - ERROR - Connection closed: 1006 - connection was closed uncleanly (None)
kiteconnect.ticker - ERROR - Connection error: 1006 - connection was closed uncleanly (None)
kiteconnect.ticker - ERROR - Connection closed: 1006 - connection was closed uncleanly (None)
kiteconnect.ticker - ERROR - Connection error: 1006 - connection was closed uncleanly (None)
kiteconnect.ticker - ERROR - Connection closed: 1006 - connection was closed uncleanly (None)
kiteconnect.ticker - ERROR - Connection error: 1006 - connection was closed uncleanly (None)
kiteconnect.ticker - ERROR - Connection closed: 1006 - connection was closed uncleanly (None)
kiteconnect.ticker - ERROR - Connection error: 1006 - connection was closed uncleanly (None)
kiteconnect.ticker - ERROR - Connection closed: 1006 - connection was closed uncleanly (None)
kiteconnect.ticker - ERROR - Connection error: 1006 - connection was closed uncleanly (None)
kiteconnect.ticker - ERROR - Connection closed: 1006 - connection was closed uncleanly (None)
kiteconnect.ticker - ERROR - Connection error: 1006 - connection was closed uncleanly (None)
kiteconnect.ticker - ERROR - Connection closed: 1006 - connection was closed uncleanly (None)
kiteconnect.ticker - ERROR - Connection error: 1006 - connection was closed uncleanly (None)
kiteconnect.ticker - ERROR - Connection closed: 1006 - connection was closed uncleanly (None)
kiteconnect.ticker - ERROR - Connection error: 1006 - connection was closed uncleanly (None)
kiteconnect.ticker - ERROR - Connection closed: 1006 - connection was closed uncleanly (None)
kiteconnect.ticker - ERROR - Connection error: 1006 - connection was closed uncleanly (None)
kiteconnect.ticker - ERROR - Connection closed: 1006 - connection was closed uncleanly (None)
kiteconnect.ticker - ERROR - Connection error: 1006 - connection was closed uncleanly (None)
kiteconnect.ticker - ERROR - Connection closed: 1006 - connection was closed uncleanly (None)
kiteconnect.ticker - ERROR - Connection error: 1006 - connection was closed uncleanly (None)
kiteconnect.ticker - ERROR - Connection closed: 1006 - connection was closed uncleanly (None)
kiteconnect.ticker - ERROR - Connection error: 1006 - connection was closed uncleanly (None)
kiteconnect.ticker - ERROR - Connection closed: 1006 - connection was closed uncleanly (None)
kiteconnect.ticker - ERROR - Connection error: 1006 - connection was closed uncleanly (None)
kiteconnect.ticker - ERROR - Connection closed: 1006 - connection was closed uncleanly (None)
kiteconnect.ticker - ERROR - Connection error: 1006 - connection was closed uncleanly (None)
kiteconnect.ticker - ERROR - Connection closed: 1006 - connection was closed uncleanly (None)
kiteconnect.ticker - ERROR - Connection error: 1006 - connection was closed uncleanly (None)
kiteconnect.ticker - ERROR - Connection closed: 1006 - connection was closed uncleanly (None)
kiteconnect.ticker - ERROR - Connection error: 1006 - connection was closed uncleanly (None)
kiteconnect.ticker - ERROR - Connection closed: 1006 - connection was closed uncleanly (None)
kiteconnect.ticker - ERROR - Connection error: 1006 - connection was closed uncleanly (None)
kiteconnect.ticker - ERROR - Connection closed: 1006 - connection was closed uncleanly (None)
kiteconnect.ticker - ERROR - Connection error: 1006 - connection was closed uncleanly (None)
kiteconnect.ticker - ERROR - Connection closed: 1006 - connection was closed uncleanly (None)
kiteconnect.ticker - ERROR - Connection error: 1006 - connection was closed uncleanly (None)
kiteconnect.ticker - ERROR - Connection closed: 1006 - connection was closed uncleanly (None)
kiteconnect.ticker - ERROR - Connection error: 1006 - connection was closed uncleanly (None)
kiteconnect.ticker - ERROR - Connection closed: 1006 - connection was closed uncleanly (None)
kiteconnect.ticker - ERROR - Connection error: 1006 - connection was closed uncleanly (None)
kiteconnect.ticker - ERROR - Connection closed: 1006 - connection was closed uncleanly (None)
kiteconnect.ticker - ERROR - Connection error: 1006 - connection was closed uncleanly (None)
kiteconnect.ticker - ERROR - Connection closed: 1006 - connection was closed uncleanly (None)
kiteconnect.ticker - ERROR - Connection error: 1006 - connection was closed uncleanly (None)
kiteconnect.ticker - ERROR - Connection closed: 1006 - connection was closed uncleanly (None)
