root - INFO - 2023-01-19 12:31:38.637978 - Finvant Alcubierre Mk1 OMS Backend turned on.
root - INFO - 2023-01-19 12:31:38.760815 - OMS Backend mainloop started.
root - INFO - 2023-01-19 12:31:38.938782 - OMSB: Logging in for backend kite ticker.
root - INFO - 2023-01-19 12:31:48.663308 - OMSB: Login succesful for backend kite ticker.
root - CRITICAL - CRITICAL ERROR:2023-01-19 12:31:48.789919 - Failed to initialise LTP gather module.
['Traceback (most recent call last):', '  File "/Users/vishaljha/Desktop/FINVANT/API/Backend/Scripts/GatherLTP.py", line 18, in __init__', "    with open('../../OMS_Server/Data/lookup_table.json') as f:", "FileNotFoundError: [Errno 2] No such file or directory: '../../OMS_Server/Data/lookup_table.json'"]
root - INFO - 2023-01-19 12:31:48.914779 - OMSB: Zerodha login for WG5235.
root - INFO - 2023-01-19 12:31:48.914887 - OMSB: Zerodha login for WG5235.
root - INFO - 2023-01-19 12:31:48.915384 - OMSB: Zerodha login for WG5235.
root - INFO - 2023-01-19 12:31:48.915802 - OMSB: Zerodha login for WG5235.
kiteconnect.ticker - ERROR - Connection error: 1006 - connection was closed uncleanly (I dropped the WebSocket TCP connection: 'GatherLTP' object has no attribute 'instrument_token_list')
kiteconnect.ticker - ERROR - Connection closed: 1006 - connection was closed uncleanly (I dropped the WebSocket TCP connection: 'GatherLTP' object has no attribute 'instrument_token_list')
kiteconnect.ticker - ERROR - Connection error: 1006 - connection was closed uncleanly (I dropped the WebSocket TCP connection: 'GatherLTP' object has no attribute 'instrument_token_list')
kiteconnect.ticker - ERROR - Connection closed: 1006 - connection was closed uncleanly (I dropped the WebSocket TCP connection: 'GatherLTP' object has no attribute 'instrument_token_list')
root - INFO - 2023-01-19 12:31:56.684939 - OMSB: Zerodha login succesful for WG5235.
root - INFO - 2023-01-19 12:31:56.819222 - OMSB: Zerodha login for WG5235.
root - INFO - 2023-01-19 12:31:57.232137 - OMSB: Zerodha login succesful for WG5235.
root - INFO - 2023-01-19 12:31:57.354668 - OMSB: Zerodha login for WG5235.
root - CRITICAL - CRITICAL ERROR:2023-01-19 12:31:57.444542 - OMSB: Failed auto login to kite for user:WG5235.
['Traceback (most recent call last):', '  File "/Users/vishaljha/Desktop/FINVANT/API/Backend/Scripts/AutoLoginZerodha.py", line 119, in auto_login_zerodha', '    data = kite.generate_session(key, api_secret=api_secret)', '  File "/Users/vishaljha/anaconda3/lib/python3.8/site-packages/kiteconnect/connect.py", line 258, in generate_session', '    resp = self._post("api.token", params={', '  File "/Users/vishaljha/anaconda3/lib/python3.8/site-packages/kiteconnect/connect.py", line 841, in _post', '    return self._request(route, "POST", url_args=url_args, params=params, is_json=is_json, query_params=query_params)', '  File "/Users/vishaljha/anaconda3/lib/python3.8/site-packages/kiteconnect/connect.py", line 913, in _request', '    raise exp(data["message"], code=r.status_code)', 'kiteconnect.exceptions.InputException: `request_token` should be minimum 10 characters in length.']
root - INFO - 2023-01-19 12:31:57.549831 - OMSB: Zerodha login succesful for WG5235.
root - INFO - 2023-01-19 12:31:57.568331 - OMSB: Zerodha login for WG5235.
root - INFO - 2023-01-19 12:31:57.692095 - OMSB: Zerodha login for WG5235.
kiteconnect.ticker - ERROR - Connection error: 1006 - connection was closed uncleanly (I dropped the WebSocket TCP connection: 'GatherLTP' object has no attribute 'instrument_token_list')
kiteconnect.ticker - ERROR - Connection closed: 1006 - connection was closed uncleanly (I dropped the WebSocket TCP connection: 'GatherLTP' object has no attribute 'instrument_token_list')
root - INFO - 2023-01-19 12:32:04.511527 - OMSB: Zerodha login succesful for WG5235.
root - INFO - 2023-01-19 12:32:04.646613 - OMSB: Zerodha login for WG5235.
root - INFO - 2023-01-19 12:32:04.815046 - OMSB: Zerodha login succesful for WG5235.
root - INFO - 2023-01-19 12:32:04.945423 - OMSB: Zerodha login for WG5235.
root - CRITICAL - CRITICAL ERROR:2023-01-19 12:32:05.250455 - OMSB: Failed auto login to kite for user:WG5235.
['Traceback (most recent call last):', '  File "/Users/vishaljha/Desktop/FINVANT/API/Backend/Scripts/AutoLoginZerodha.py", line 119, in auto_login_zerodha', '    data = kite.generate_session(key, api_secret=api_secret)', '  File "/Users/vishaljha/anaconda3/lib/python3.8/site-packages/kiteconnect/connect.py", line 258, in generate_session', '    resp = self._post("api.token", params={', '  File "/Users/vishaljha/anaconda3/lib/python3.8/site-packages/kiteconnect/connect.py", line 841, in _post', '    return self._request(route, "POST", url_args=url_args, params=params, is_json=is_json, query_params=query_params)', '  File "/Users/vishaljha/anaconda3/lib/python3.8/site-packages/kiteconnect/connect.py", line 913, in _request', '    raise exp(data["message"], code=r.status_code)', 'kiteconnect.exceptions.InputException: `request_token` should be minimum 10 characters in length.']
root - INFO - 2023-01-19 12:32:05.375595 - OMSB: Zerodha login for WG5235.
root - INFO - 2023-01-19 12:32:05.403632 - OMSB: Zerodha login succesful for WG5235.
root - INFO - 2023-01-19 12:32:05.596223 - OMSB: Zerodha login for WG5235.
root - CRITICAL - CRITICAL ERROR:2023-01-19 12:32:08.708815 - Failed to generate user dictionary.
['Traceback (most recent call last):', '  File "Main.py", line 66, in main_loop', '    user_dict = UserProfileGenerator().create_user_profiles(user_data=user_data, log_interface=self.log_interface)', '  File "/Users/vishaljha/Desktop/FINVANT/API/Backend/Scripts/UserProfileGenerator.py", line 56, in create_user_profiles', '    t.join()', '  File "/Users/vishaljha/anaconda3/lib/python3.8/threading.py", line 1011, in join', '    self._wait_for_tstate_lock()', '  File "/Users/vishaljha/anaconda3/lib/python3.8/threading.py", line 1027, in _wait_for_tstate_lock', '    elif lock.acquire(block, timeout):', 'KeyboardInterrupt']
root - CRITICAL - CRITICAL ERROR:2023-01-19 12:32:08.790188 - OMSB: Failed auto login to kite for user:WG5235.
['Traceback (most recent call last):', '  File "/Users/vishaljha/anaconda3/lib/python3.8/site-packages/urllib3/connectionpool.py", line 600, in urlopen', '    httplib_response = self._make_request(conn, method, url,', '  File "/Users/vishaljha/anaconda3/lib/python3.8/site-packages/urllib3/connectionpool.py", line 387, in _make_request', '    six.raise_from(e, None)', '  File "<string>", line 2, in raise_from', '  File "/Users/vishaljha/anaconda3/lib/python3.8/site-packages/urllib3/connectionpool.py", line 383, in _make_request', '    httplib_response = conn.getresponse()', '  File "/Users/vishaljha/anaconda3/lib/python3.8/http/client.py", line 1332, in getresponse', '    response.begin()', '  File "/Users/vishaljha/anaconda3/lib/python3.8/http/client.py", line 303, in begin', '    version, status, reason = self._read_status()', '  File "/Users/vishaljha/anaconda3/lib/python3.8/http/client.py", line 272, in _read_status', '    raise RemoteDisconnected("Remote end closed connection without"', 'http.client.RemoteDisconnected: Remote end closed connection without response', '', 'During handling of the above exception, another exception occurred:', '', 'Traceback (most recent call last):', '  File "/Users/vishaljha/Desktop/FINVANT/API/Backend/Scripts/AutoLoginZerodha.py", line 37, in automate_login', '    browser.get(browser_url)', '  File "/Users/vishaljha/anaconda3/lib/python3.8/site-packages/selenium/webdriver/remote/webdriver.py", line 333, in get', "    self.execute(Command.GET, {'url': url})", '  File "/Users/vishaljha/anaconda3/lib/python3.8/site-packages/selenium/webdriver/remote/webdriver.py", line 319, in execute', '    response = self.command_executor.execute(driver_command, params)', '  File "/Users/vishaljha/anaconda3/lib/python3.8/site-packages/selenium/webdriver/remote/remote_connection.py", line 374, in execute', '    return self._request(command_info[0], url, body=data)', '  File "/Users/vishaljha/anaconda3/lib/python3.8/site-packages/selenium/webdriver/remote/remote_connection.py", line 397, in _request', '    resp = self._conn.request(method, url, body=body, headers=headers)', '  File "/Users/vishaljha/anaconda3/lib/python3.8/site-packages/urllib3/request.py", line 70, in request', '    return self.request_encode_body(method, url, fields=fields,', '  File "/Users/vishaljha/anaconda3/lib/python3.8/site-packages/urllib3/request.py", line 150, in request_encode_body', '    return self.urlopen(method, url, **extra_kw)', '  File "/Users/vishaljha/anaconda3/lib/python3.8/site-packages/urllib3/poolmanager.py", line 326, in urlopen', '    response = conn.urlopen(method, u.request_uri, **kw)', '  File "/Users/vishaljha/anaconda3/lib/python3.8/site-packages/urllib3/connectionpool.py", line 640, in urlopen', '    retries = retries.increment(method, url, error=e, _pool=self,', '  File "/Users/vishaljha/anaconda3/lib/python3.8/site-packages/urllib3/util/retry.py", line 368, in increment', '    raise six.reraise(type(error), error, _stacktrace)', '  File "/Users/vishaljha/anaconda3/lib/python3.8/site-packages/urllib3/packages/six.py", line 685, in reraise', '    raise value.with_traceback(tb)', '  File "/Users/vishaljha/anaconda3/lib/python3.8/site-packages/urllib3/connectionpool.py", line 600, in urlopen', '    httplib_response = self._make_request(conn, method, url,', '  File "/Users/vishaljha/anaconda3/lib/python3.8/site-packages/urllib3/connectionpool.py", line 387, in _make_request', '    six.raise_from(e, None)', '  File "<string>", line 2, in raise_from', '  File "/Users/vishaljha/anaconda3/lib/python3.8/site-packages/urllib3/connectionpool.py", line 383, in _make_request', '    httplib_response = conn.getresponse()', '  File "/Users/vishaljha/anaconda3/lib/python3.8/http/client.py", line 1332, in getresponse', '    response.begin()', '  File "/Users/vishaljha/anaconda3/lib/python3.8/http/client.py", line 303, in begin', '    version, status, reason = self._read_status()', '  File "/Users/vishaljha/anaconda3/lib/python3.8/http/client.py", line 272, in _read_status', '    raise RemoteDisconnected("Remote end closed connection without"', "urllib3.exceptions.ProtocolError: ('Connection aborted.', RemoteDisconnected('Remote end closed connection without response'))", '', 'During handling of the above exception, another exception occurred:', '', 'Traceback (most recent call last):', '  File "/Users/vishaljha/anaconda3/lib/python3.8/site-packages/selenium/webdriver/common/service.py", line 72, in start', '    self.process = subprocess.Popen(cmd, env=self.env,', '  File "/Users/vishaljha/anaconda3/lib/python3.8/subprocess.py", line 854, in __init__', '    self._execute_child(args, executable, preexec_fn, close_fds,', '  File "/Users/vishaljha/anaconda3/lib/python3.8/subprocess.py", line 1702, in _execute_child', '    raise child_exception_type(errno_num, err_msg, err_filename)', "FileNotFoundError: [Errno 2] No such file or directory: 'chromedriver'", '', 'During handling of the above exception, another exception occurred:', '', 'Traceback (most recent call last):', '  File "/Users/vishaljha/Desktop/FINVANT/API/Backend/Scripts/AutoLoginZerodha.py", line 117, in auto_login_zerodha', '    key = automate_login(browser_url, user_id, password, totp_pin)', '  File "/Users/vishaljha/Desktop/FINVANT/API/Backend/Scripts/AutoLoginZerodha.py", line 40, in automate_login', '    browser = webdriver.Chrome(options = options)', '  File "/Users/vishaljha/anaconda3/lib/python3.8/site-packages/selenium/webdriver/chrome/webdriver.py", line 73, in __init__', '    self.service.start()', '  File "/Users/vishaljha/anaconda3/lib/python3.8/site-packages/selenium/webdriver/common/service.py", line 81, in start', '    raise WebDriverException(', "selenium.common.exceptions.WebDriverException: Message: 'chromedriver' executable needs to be in PATH. Please see https://sites.google.com/a/chromium.org/chromedriver/home", '']
root - CRITICAL - CRITICAL ERROR:2023-01-19 12:32:08.794630 - OMSB: Failed auto login to kite for user:WG5235.
['Traceback (most recent call last):', '  File "/Users/vishaljha/anaconda3/lib/python3.8/site-packages/urllib3/connectionpool.py", line 600, in urlopen', '    httplib_response = self._make_request(conn, method, url,', '  File "/Users/vishaljha/anaconda3/lib/python3.8/site-packages/urllib3/connectionpool.py", line 387, in _make_request', '    six.raise_from(e, None)', '  File "<string>", line 2, in raise_from', '  File "/Users/vishaljha/anaconda3/lib/python3.8/site-packages/urllib3/connectionpool.py", line 383, in _make_request', '    httplib_response = conn.getresponse()', '  File "/Users/vishaljha/anaconda3/lib/python3.8/http/client.py", line 1332, in getresponse', '    response.begin()', '  File "/Users/vishaljha/anaconda3/lib/python3.8/http/client.py", line 303, in begin', '    version, status, reason = self._read_status()', '  File "/Users/vishaljha/anaconda3/lib/python3.8/http/client.py", line 272, in _read_status', '    raise RemoteDisconnected("Remote end closed connection without"', 'http.client.RemoteDisconnected: Remote end closed connection without response', '', 'During handling of the above exception, another exception occurred:', '', 'Traceback (most recent call last):', '  File "/Users/vishaljha/Desktop/FINVANT/API/Backend/Scripts/AutoLoginZerodha.py", line 37, in automate_login', '    browser.get(browser_url)', '  File "/Users/vishaljha/anaconda3/lib/python3.8/site-packages/selenium/webdriver/remote/webdriver.py", line 333, in get', "    self.execute(Command.GET, {'url': url})", '  File "/Users/vishaljha/anaconda3/lib/python3.8/site-packages/selenium/webdriver/remote/webdriver.py", line 319, in execute', '    response = self.command_executor.execute(driver_command, params)', '  File "/Users/vishaljha/anaconda3/lib/python3.8/site-packages/selenium/webdriver/remote/remote_connection.py", line 374, in execute', '    return self._request(command_info[0], url, body=data)', '  File "/Users/vishaljha/anaconda3/lib/python3.8/site-packages/selenium/webdriver/remote/remote_connection.py", line 397, in _request', '    resp = self._conn.request(method, url, body=body, headers=headers)', '  File "/Users/vishaljha/anaconda3/lib/python3.8/site-packages/urllib3/request.py", line 70, in request', '    return self.request_encode_body(method, url, fields=fields,', '  File "/Users/vishaljha/anaconda3/lib/python3.8/site-packages/urllib3/request.py", line 150, in request_encode_body', '    return self.urlopen(method, url, **extra_kw)', '  File "/Users/vishaljha/anaconda3/lib/python3.8/site-packages/urllib3/poolmanager.py", line 326, in urlopen', '    response = conn.urlopen(method, u.request_uri, **kw)', '  File "/Users/vishaljha/anaconda3/lib/python3.8/site-packages/urllib3/connectionpool.py", line 640, in urlopen', '    retries = retries.increment(method, url, error=e, _pool=self,', '  File "/Users/vishaljha/anaconda3/lib/python3.8/site-packages/urllib3/util/retry.py", line 368, in increment', '    raise six.reraise(type(error), error, _stacktrace)', '  File "/Users/vishaljha/anaconda3/lib/python3.8/site-packages/urllib3/packages/six.py", line 685, in reraise', '    raise value.with_traceback(tb)', '  File "/Users/vishaljha/anaconda3/lib/python3.8/site-packages/urllib3/connectionpool.py", line 600, in urlopen', '    httplib_response = self._make_request(conn, method, url,', '  File "/Users/vishaljha/anaconda3/lib/python3.8/site-packages/urllib3/connectionpool.py", line 387, in _make_request', '    six.raise_from(e, None)', '  File "<string>", line 2, in raise_from', '  File "/Users/vishaljha/anaconda3/lib/python3.8/site-packages/urllib3/connectionpool.py", line 383, in _make_request', '    httplib_response = conn.getresponse()', '  File "/Users/vishaljha/anaconda3/lib/python3.8/http/client.py", line 1332, in getresponse', '    response.begin()', '  File "/Users/vishaljha/anaconda3/lib/python3.8/http/client.py", line 303, in begin', '    version, status, reason = self._read_status()', '  File "/Users/vishaljha/anaconda3/lib/python3.8/http/client.py", line 272, in _read_status', '    raise RemoteDisconnected("Remote end closed connection without"', "urllib3.exceptions.ProtocolError: ('Connection aborted.', RemoteDisconnected('Remote end closed connection without response'))", '', 'During handling of the above exception, another exception occurred:', '', 'Traceback (most recent call last):', '  File "/Users/vishaljha/anaconda3/lib/python3.8/site-packages/selenium/webdriver/common/service.py", line 72, in start', '    self.process = subprocess.Popen(cmd, env=self.env,', '  File "/Users/vishaljha/anaconda3/lib/python3.8/subprocess.py", line 854, in __init__', '    self._execute_child(args, executable, preexec_fn, close_fds,', '  File "/Users/vishaljha/anaconda3/lib/python3.8/subprocess.py", line 1702, in _execute_child', '    raise child_exception_type(errno_num, err_msg, err_filename)', "FileNotFoundError: [Errno 2] No such file or directory: 'chromedriver'", '', 'During handling of the above exception, another exception occurred:', '', 'Traceback (most recent call last):', '  File "/Users/vishaljha/Desktop/FINVANT/API/Backend/Scripts/AutoLoginZerodha.py", line 117, in auto_login_zerodha', '    key = automate_login(browser_url, user_id, password, totp_pin)', '  File "/Users/vishaljha/Desktop/FINVANT/API/Backend/Scripts/AutoLoginZerodha.py", line 40, in automate_login', '    browser = webdriver.Chrome(options = options)', '  File "/Users/vishaljha/anaconda3/lib/python3.8/site-packages/selenium/webdriver/chrome/webdriver.py", line 73, in __init__', '    self.service.start()', '  File "/Users/vishaljha/anaconda3/lib/python3.8/site-packages/selenium/webdriver/common/service.py", line 81, in start', '    raise WebDriverException(', "selenium.common.exceptions.WebDriverException: Message: 'chromedriver' executable needs to be in PATH. Please see https://sites.google.com/a/chromium.org/chromedriver/home", '']
root - CRITICAL - CRITICAL ERROR:2023-01-19 12:32:08.806425 - OMSB: Failed auto login to kite for user:WG5235.
['Traceback (most recent call last):', '  File "/Users/vishaljha/anaconda3/lib/python3.8/site-packages/urllib3/connectionpool.py", line 600, in urlopen', '    httplib_response = self._make_request(conn, method, url,', '  File "/Users/vishaljha/anaconda3/lib/python3.8/site-packages/urllib3/connectionpool.py", line 387, in _make_request', '    six.raise_from(e, None)', '  File "<string>", line 2, in raise_from', '  File "/Users/vishaljha/anaconda3/lib/python3.8/site-packages/urllib3/connectionpool.py", line 383, in _make_request', '    httplib_response = conn.getresponse()', '  File "/Users/vishaljha/anaconda3/lib/python3.8/http/client.py", line 1332, in getresponse', '    response.begin()', '  File "/Users/vishaljha/anaconda3/lib/python3.8/http/client.py", line 303, in begin', '    version, status, reason = self._read_status()', '  File "/Users/vishaljha/anaconda3/lib/python3.8/http/client.py", line 272, in _read_status', '    raise RemoteDisconnected("Remote end closed connection without"', 'http.client.RemoteDisconnected: Remote end closed connection without response', '', 'During handling of the above exception, another exception occurred:', '', 'Traceback (most recent call last):', '  File "/Users/vishaljha/Desktop/FINVANT/API/Backend/Scripts/AutoLoginZerodha.py", line 37, in automate_login', '    browser.get(browser_url)', '  File "/Users/vishaljha/anaconda3/lib/python3.8/site-packages/selenium/webdriver/remote/webdriver.py", line 333, in get', "    self.execute(Command.GET, {'url': url})", '  File "/Users/vishaljha/anaconda3/lib/python3.8/site-packages/selenium/webdriver/remote/webdriver.py", line 319, in execute', '    response = self.command_executor.execute(driver_command, params)', '  File "/Users/vishaljha/anaconda3/lib/python3.8/site-packages/selenium/webdriver/remote/remote_connection.py", line 374, in execute', '    return self._request(command_info[0], url, body=data)', '  File "/Users/vishaljha/anaconda3/lib/python3.8/site-packages/selenium/webdriver/remote/remote_connection.py", line 397, in _request', '    resp = self._conn.request(method, url, body=body, headers=headers)', '  File "/Users/vishaljha/anaconda3/lib/python3.8/site-packages/urllib3/request.py", line 70, in request', '    return self.request_encode_body(method, url, fields=fields,', '  File "/Users/vishaljha/anaconda3/lib/python3.8/site-packages/urllib3/request.py", line 150, in request_encode_body', '    return self.urlopen(method, url, **extra_kw)', '  File "/Users/vishaljha/anaconda3/lib/python3.8/site-packages/urllib3/poolmanager.py", line 326, in urlopen', '    response = conn.urlopen(method, u.request_uri, **kw)', '  File "/Users/vishaljha/anaconda3/lib/python3.8/site-packages/urllib3/connectionpool.py", line 640, in urlopen', '    retries = retries.increment(method, url, error=e, _pool=self,', '  File "/Users/vishaljha/anaconda3/lib/python3.8/site-packages/urllib3/util/retry.py", line 368, in increment', '    raise six.reraise(type(error), error, _stacktrace)', '  File "/Users/vishaljha/anaconda3/lib/python3.8/site-packages/urllib3/packages/six.py", line 685, in reraise', '    raise value.with_traceback(tb)', '  File "/Users/vishaljha/anaconda3/lib/python3.8/site-packages/urllib3/connectionpool.py", line 600, in urlopen', '    httplib_response = self._make_request(conn, method, url,', '  File "/Users/vishaljha/anaconda3/lib/python3.8/site-packages/urllib3/connectionpool.py", line 387, in _make_request', '    six.raise_from(e, None)', '  File "<string>", line 2, in raise_from', '  File "/Users/vishaljha/anaconda3/lib/python3.8/site-packages/urllib3/connectionpool.py", line 383, in _make_request', '    httplib_response = conn.getresponse()', '  File "/Users/vishaljha/anaconda3/lib/python3.8/http/client.py", line 1332, in getresponse', '    response.begin()', '  File "/Users/vishaljha/anaconda3/lib/python3.8/http/client.py", line 303, in begin', '    version, status, reason = self._read_status()', '  File "/Users/vishaljha/anaconda3/lib/python3.8/http/client.py", line 272, in _read_status', '    raise RemoteDisconnected("Remote end closed connection without"', "urllib3.exceptions.ProtocolError: ('Connection aborted.', RemoteDisconnected('Remote end closed connection without response'))", '', 'During handling of the above exception, another exception occurred:', '', 'Traceback (most recent call last):', '  File "/Users/vishaljha/anaconda3/lib/python3.8/site-packages/selenium/webdriver/common/service.py", line 72, in start', '    self.process = subprocess.Popen(cmd, env=self.env,', '  File "/Users/vishaljha/anaconda3/lib/python3.8/subprocess.py", line 854, in __init__', '    self._execute_child(args, executable, preexec_fn, close_fds,', '  File "/Users/vishaljha/anaconda3/lib/python3.8/subprocess.py", line 1702, in _execute_child', '    raise child_exception_type(errno_num, err_msg, err_filename)', "FileNotFoundError: [Errno 2] No such file or directory: 'chromedriver'", '', 'During handling of the above exception, another exception occurred:', '', 'Traceback (most recent call last):', '  File "/Users/vishaljha/Desktop/FINVANT/API/Backend/Scripts/AutoLoginZerodha.py", line 117, in auto_login_zerodha', '    key = automate_login(browser_url, user_id, password, totp_pin)', '  File "/Users/vishaljha/Desktop/FINVANT/API/Backend/Scripts/AutoLoginZerodha.py", line 40, in automate_login', '    browser = webdriver.Chrome(options = options)', '  File "/Users/vishaljha/anaconda3/lib/python3.8/site-packages/selenium/webdriver/chrome/webdriver.py", line 73, in __init__', '    self.service.start()', '  File "/Users/vishaljha/anaconda3/lib/python3.8/site-packages/selenium/webdriver/common/service.py", line 81, in start', '    raise WebDriverException(', "selenium.common.exceptions.WebDriverException: Message: 'chromedriver' executable needs to be in PATH. Please see https://sites.google.com/a/chromium.org/chromedriver/home", '']
root - CRITICAL - CRITICAL ERROR:2023-01-19 12:32:08.815641 - Failed to initialise Log server/ADS.
['Traceback (most recent call last):', '  File "Main.py", line 66, in main_loop', '    user_dict = UserProfileGenerator().create_user_profiles(user_data=user_data, log_interface=self.log_interface)', '  File "/Users/vishaljha/Desktop/FINVANT/API/Backend/Scripts/UserProfileGenerator.py", line 56, in create_user_profiles', '    t.join()', '  File "/Users/vishaljha/anaconda3/lib/python3.8/threading.py", line 1011, in join', '    self._wait_for_tstate_lock()', '  File "/Users/vishaljha/anaconda3/lib/python3.8/threading.py", line 1027, in _wait_for_tstate_lock', '    elif lock.acquire(block, timeout):', 'KeyboardInterrupt', '', 'During handling of the above exception, another exception occurred:', '', 'Traceback (most recent call last):', '  File "Main.py", line 30, in __init__', '    self.start()', '  File "Main.py", line 38, in start', '    self.main_loop()', '  File "Main.py", line 68, in main_loop', '    self.log_interface.postLog(severity="CRITICAL",message=\'Failed to generate user dictionary.\',publish = 1, tag = \'OMSB_MAIN_4\')', '  File "/Users/vishaljha/Desktop/FINVANT/API/Backend/Scripts/Log_Server_Interface.py", line 55, in postLog', "    response = requests.post(self.url + 'post/log', headers=headers, json=json_compatible_item_data)", '  File "/Users/vishaljha/anaconda3/lib/python3.8/site-packages/requests/api.py", line 116, in post', "    return request('post', url, data=data, json=json, **kwargs)", '  File "/Users/vishaljha/anaconda3/lib/python3.8/site-packages/requests/api.py", line 60, in request', '    return session.request(method=method, url=url, **kwargs)', '  File "/Users/vishaljha/anaconda3/lib/python3.8/site-packages/requests/sessions.py", line 533, in request', '    resp = self.send(prep, **send_kwargs)', '  File "/Users/vishaljha/anaconda3/lib/python3.8/site-packages/requests/sessions.py", line 646, in send', '    r = adapter.send(request, **kwargs)', '  File "/Users/vishaljha/anaconda3/lib/python3.8/site-packages/requests/adapters.py", line 439, in send', '    resp = conn.urlopen(', '  File "/Users/vishaljha/anaconda3/lib/python3.8/site-packages/urllib3/connectionpool.py", line 600, in urlopen', '    httplib_response = self._make_request(conn, method, url,', '  File "/Users/vishaljha/anaconda3/lib/python3.8/site-packages/urllib3/connectionpool.py", line 355, in _make_request', '    conn.request(method, url, **httplib_request_kw)', '  File "/Users/vishaljha/anaconda3/lib/python3.8/http/client.py", line 1240, in request', '    self._send_request(method, url, body, headers, encode_chunked)', '  File "/Users/vishaljha/anaconda3/lib/python3.8/http/client.py", line 1286, in _send_request', '    self.endheaders(body, encode_chunked=encode_chunked)', '  File "/Users/vishaljha/anaconda3/lib/python3.8/http/client.py", line 1235, in endheaders', '    self._send_output(message_body, encode_chunked=encode_chunked)', '  File "/Users/vishaljha/anaconda3/lib/python3.8/http/client.py", line 1006, in _send_output', '    self.send(msg)', '  File "/Users/vishaljha/anaconda3/lib/python3.8/http/client.py", line 946, in send', '    self.connect()', '  File "/Users/vishaljha/anaconda3/lib/python3.8/site-packages/urllib3/connection.py", line 183, in connect', '    conn = self._new_conn()', '  File "/Users/vishaljha/anaconda3/lib/python3.8/site-packages/urllib3/connection.py", line 159, in _new_conn', '    conn = connection.create_connection(', '  File "/Users/vishaljha/anaconda3/lib/python3.8/site-packages/urllib3/util/connection.py", line 70, in create_connection', '    sock.connect(sa)', 'KeyboardInterrupt']
root - INFO - 2023-01-19 12:32:08.921057 - OMSB: Zerodha login for WG5235.
root - INFO - 2023-01-19 12:32:15.587091 - Finvant Alcubierre Mk1 OMS Backend turned on.
root - INFO - 2023-01-19 12:32:15.730419 - OMS Backend mainloop started.
root - INFO - 2023-01-19 12:32:15.918532 - OMSB: Logging in for backend kite ticker.
root - INFO - 2023-01-19 12:32:23.826099 - OMSB: Login succesful for backend kite ticker.
root - CRITICAL - CRITICAL ERROR:2023-01-19 12:32:23.956847 - Failed to initialise LTP gather module.
['Traceback (most recent call last):', '  File "/Users/vishaljha/Desktop/FINVANT/API/Backend/Scripts/GatherLTP.py", line 18, in __init__', "    with open('../../OMS_Server/Data/lookup_table.json') as f:", "FileNotFoundError: [Errno 2] No such file or directory: '../../OMS_Server/Data/lookup_table.json'"]
root - INFO - 2023-01-19 12:32:24.101080 - OMSB: Zerodha login for WG5235.
root - INFO - 2023-01-19 12:32:24.101352 - OMSB: Zerodha login for WG5235.
root - INFO - 2023-01-19 12:32:24.101941 - OMSB: Zerodha login for WG5235.
root - INFO - 2023-01-19 12:32:24.102296 - OMSB: Zerodha login for WG5235.
kiteconnect.ticker - ERROR - Connection error: 1006 - connection was closed uncleanly (I dropped the WebSocket TCP connection: 'GatherLTP' object has no attribute 'instrument_token_list')
kiteconnect.ticker - ERROR - Connection closed: 1006 - connection was closed uncleanly (I dropped the WebSocket TCP connection: 'GatherLTP' object has no attribute 'instrument_token_list')
kiteconnect.ticker - ERROR - Connection error: 1006 - connection was closed uncleanly (I dropped the WebSocket TCP connection: 'GatherLTP' object has no attribute 'instrument_token_list')
kiteconnect.ticker - ERROR - Connection closed: 1006 - connection was closed uncleanly (I dropped the WebSocket TCP connection: 'GatherLTP' object has no attribute 'instrument_token_list')
root - INFO - 2023-01-19 12:32:31.376208 - OMSB: Zerodha login succesful for WG5235.
root - INFO - 2023-01-19 12:32:31.498508 - OMSB: Zerodha login for WG5235.
root - INFO - 2023-01-19 12:32:34.528021 - OMSB: Zerodha login succesful for WG5235.
root - INFO - 2023-01-19 12:32:34.663506 - OMSB: Zerodha login for WG5235.
kiteconnect.ticker - ERROR - Connection error: 1006 - connection was closed uncleanly (I dropped the WebSocket TCP connection: 'GatherLTP' object has no attribute 'instrument_token_list')
kiteconnect.ticker - ERROR - Connection closed: 1006 - connection was closed uncleanly (I dropped the WebSocket TCP connection: 'GatherLTP' object has no attribute 'instrument_token_list')
root - INFO - 2023-01-19 12:32:35.261931 - OMSB: Zerodha login succesful for WG5235.
root - INFO - 2023-01-19 12:32:35.396174 - OMSB: Zerodha login for WG5235.
root - INFO - 2023-01-19 12:32:35.561165 - OMSB: Zerodha login succesful for WG5235.
root - INFO - 2023-01-19 12:32:35.702453 - OMSB: Zerodha login for WG5235.
root - INFO - 2023-01-19 12:32:38.949090 - OMSB: Zerodha login succesful for WG5235.
root - INFO - 2023-01-19 12:32:39.089138 - OMSB: Zerodha login for WG5235.
root - INFO - 2023-01-19 12:32:42.745338 - OMSB: Zerodha login succesful for WG5235.
root - CRITICAL - CRITICAL ERROR:2023-01-19 12:32:42.765943 - OMSB: Failed auto login to kite for user:WG5235.
['Traceback (most recent call last):', '  File "/Users/vishaljha/Desktop/FINVANT/API/Backend/Scripts/AutoLoginZerodha.py", line 119, in auto_login_zerodha', '    data = kite.generate_session(key, api_secret=api_secret)', '  File "/Users/vishaljha/anaconda3/lib/python3.8/site-packages/kiteconnect/connect.py", line 258, in generate_session', '    resp = self._post("api.token", params={', '  File "/Users/vishaljha/anaconda3/lib/python3.8/site-packages/kiteconnect/connect.py", line 841, in _post', '    return self._request(route, "POST", url_args=url_args, params=params, is_json=is_json, query_params=query_params)', '  File "/Users/vishaljha/anaconda3/lib/python3.8/site-packages/kiteconnect/connect.py", line 913, in _request', '    raise exp(data["message"], code=r.status_code)', 'kiteconnect.exceptions.InputException: `request_token` should be minimum 10 characters in length.']
root - INFO - 2023-01-19 12:32:42.868655 - OMSB: Zerodha login for WG5235.
root - INFO - 2023-01-19 12:32:42.929503 - OMSB: Zerodha login for WG5235.
root - INFO - 2023-01-19 12:32:43.881592 - OMSB: Zerodha login succesful for WG5235.
root - INFO - 2023-01-19 12:32:44.007954 - OMSB: Zerodha login for WG5235.
root - CRITICAL - CRITICAL ERROR:2023-01-19 12:32:45.749350 - Failed to generate user dictionary.
['Traceback (most recent call last):', '  File "Main.py", line 66, in main_loop', '    user_dict = UserProfileGenerator().create_user_profiles(user_data=user_data, log_interface=self.log_interface)', '  File "/Users/vishaljha/Desktop/FINVANT/API/Backend/Scripts/UserProfileGenerator.py", line 56, in create_user_profiles', '    t.join()', '  File "/Users/vishaljha/anaconda3/lib/python3.8/threading.py", line 1011, in join', '    self._wait_for_tstate_lock()', '  File "/Users/vishaljha/anaconda3/lib/python3.8/threading.py", line 1027, in _wait_for_tstate_lock', '    elif lock.acquire(block, timeout):', 'KeyboardInterrupt']
root - CRITICAL - CRITICAL ERROR:2023-01-19 12:32:45.773878 - OMSB: Failed auto login to kite for user:WG5235.
['Traceback (most recent call last):', '  File "/Users/vishaljha/anaconda3/lib/python3.8/site-packages/urllib3/connectionpool.py", line 600, in urlopen', '    httplib_response = self._make_request(conn, method, url,', '  File "/Users/vishaljha/anaconda3/lib/python3.8/site-packages/urllib3/connectionpool.py", line 387, in _make_request', '    six.raise_from(e, None)', '  File "<string>", line 2, in raise_from', '  File "/Users/vishaljha/anaconda3/lib/python3.8/site-packages/urllib3/connectionpool.py", line 383, in _make_request', '    httplib_response = conn.getresponse()', '  File "/Users/vishaljha/anaconda3/lib/python3.8/http/client.py", line 1332, in getresponse', '    response.begin()', '  File "/Users/vishaljha/anaconda3/lib/python3.8/http/client.py", line 303, in begin', '    version, status, reason = self._read_status()', '  File "/Users/vishaljha/anaconda3/lib/python3.8/http/client.py", line 272, in _read_status', '    raise RemoteDisconnected("Remote end closed connection without"', 'http.client.RemoteDisconnected: Remote end closed connection without response', '', 'During handling of the above exception, another exception occurred:', '', 'Traceback (most recent call last):', '  File "/Users/vishaljha/Desktop/FINVANT/API/Backend/Scripts/AutoLoginZerodha.py", line 37, in automate_login', '    browser.get(browser_url)', '  File "/Users/vishaljha/anaconda3/lib/python3.8/site-packages/selenium/webdriver/remote/webdriver.py", line 333, in get', "    self.execute(Command.GET, {'url': url})", '  File "/Users/vishaljha/anaconda3/lib/python3.8/site-packages/selenium/webdriver/remote/webdriver.py", line 319, in execute', '    response = self.command_executor.execute(driver_command, params)', '  File "/Users/vishaljha/anaconda3/lib/python3.8/site-packages/selenium/webdriver/remote/remote_connection.py", line 374, in execute', '    return self._request(command_info[0], url, body=data)', '  File "/Users/vishaljha/anaconda3/lib/python3.8/site-packages/selenium/webdriver/remote/remote_connection.py", line 397, in _request', '    resp = self._conn.request(method, url, body=body, headers=headers)', '  File "/Users/vishaljha/anaconda3/lib/python3.8/site-packages/urllib3/request.py", line 70, in request', '    return self.request_encode_body(method, url, fields=fields,', '  File "/Users/vishaljha/anaconda3/lib/python3.8/site-packages/urllib3/request.py", line 150, in request_encode_body', '    return self.urlopen(method, url, **extra_kw)', '  File "/Users/vishaljha/anaconda3/lib/python3.8/site-packages/urllib3/poolmanager.py", line 326, in urlopen', '    response = conn.urlopen(method, u.request_uri, **kw)', '  File "/Users/vishaljha/anaconda3/lib/python3.8/site-packages/urllib3/connectionpool.py", line 640, in urlopen', '    retries = retries.increment(method, url, error=e, _pool=self,', '  File "/Users/vishaljha/anaconda3/lib/python3.8/site-packages/urllib3/util/retry.py", line 368, in increment', '    raise six.reraise(type(error), error, _stacktrace)', '  File "/Users/vishaljha/anaconda3/lib/python3.8/site-packages/urllib3/packages/six.py", line 685, in reraise', '    raise value.with_traceback(tb)', '  File "/Users/vishaljha/anaconda3/lib/python3.8/site-packages/urllib3/connectionpool.py", line 600, in urlopen', '    httplib_response = self._make_request(conn, method, url,', '  File "/Users/vishaljha/anaconda3/lib/python3.8/site-packages/urllib3/connectionpool.py", line 387, in _make_request', '    six.raise_from(e, None)', '  File "<string>", line 2, in raise_from', '  File "/Users/vishaljha/anaconda3/lib/python3.8/site-packages/urllib3/connectionpool.py", line 383, in _make_request', '    httplib_response = conn.getresponse()', '  File "/Users/vishaljha/anaconda3/lib/python3.8/http/client.py", line 1332, in getresponse', '    response.begin()', '  File "/Users/vishaljha/anaconda3/lib/python3.8/http/client.py", line 303, in begin', '    version, status, reason = self._read_status()', '  File "/Users/vishaljha/anaconda3/lib/python3.8/http/client.py", line 272, in _read_status', '    raise RemoteDisconnected("Remote end closed connection without"', "urllib3.exceptions.ProtocolError: ('Connection aborted.', RemoteDisconnected('Remote end closed connection without response'))", '', 'During handling of the above exception, another exception occurred:', '', 'Traceback (most recent call last):', '  File "/Users/vishaljha/anaconda3/lib/python3.8/site-packages/selenium/webdriver/common/service.py", line 72, in start', '    self.process = subprocess.Popen(cmd, env=self.env,', '  File "/Users/vishaljha/anaconda3/lib/python3.8/subprocess.py", line 854, in __init__', '    self._execute_child(args, executable, preexec_fn, close_fds,', '  File "/Users/vishaljha/anaconda3/lib/python3.8/subprocess.py", line 1702, in _execute_child', '    raise child_exception_type(errno_num, err_msg, err_filename)', "FileNotFoundError: [Errno 2] No such file or directory: 'chromedriver'", '', 'During handling of the above exception, another exception occurred:', '', 'Traceback (most recent call last):', '  File "/Users/vishaljha/Desktop/FINVANT/API/Backend/Scripts/AutoLoginZerodha.py", line 117, in auto_login_zerodha', '    key = automate_login(browser_url, user_id, password, totp_pin)', '  File "/Users/vishaljha/Desktop/FINVANT/API/Backend/Scripts/AutoLoginZerodha.py", line 40, in automate_login', '    browser = webdriver.Chrome(options = options)', '  File "/Users/vishaljha/anaconda3/lib/python3.8/site-packages/selenium/webdriver/chrome/webdriver.py", line 73, in __init__', '    self.service.start()', '  File "/Users/vishaljha/anaconda3/lib/python3.8/site-packages/selenium/webdriver/common/service.py", line 81, in start', '    raise WebDriverException(', "selenium.common.exceptions.WebDriverException: Message: 'chromedriver' executable needs to be in PATH. Please see https://sites.google.com/a/chromium.org/chromedriver/home", '']
root - CRITICAL - CRITICAL ERROR:2023-01-19 12:32:45.791951 - OMSB: Failed auto login to kite for user:WG5235.
['Traceback (most recent call last):', '  File "/Users/vishaljha/anaconda3/lib/python3.8/site-packages/urllib3/connectionpool.py", line 600, in urlopen', '    httplib_response = self._make_request(conn, method, url,', '  File "/Users/vishaljha/anaconda3/lib/python3.8/site-packages/urllib3/connectionpool.py", line 387, in _make_request', '    six.raise_from(e, None)', '  File "<string>", line 2, in raise_from', '  File "/Users/vishaljha/anaconda3/lib/python3.8/site-packages/urllib3/connectionpool.py", line 383, in _make_request', '    httplib_response = conn.getresponse()', '  File "/Users/vishaljha/anaconda3/lib/python3.8/http/client.py", line 1332, in getresponse', '    response.begin()', '  File "/Users/vishaljha/anaconda3/lib/python3.8/http/client.py", line 303, in begin', '    version, status, reason = self._read_status()', '  File "/Users/vishaljha/anaconda3/lib/python3.8/http/client.py", line 272, in _read_status', '    raise RemoteDisconnected("Remote end closed connection without"', 'http.client.RemoteDisconnected: Remote end closed connection without response', '', 'During handling of the above exception, another exception occurred:', '', 'Traceback (most recent call last):', '  File "/Users/vishaljha/Desktop/FINVANT/API/Backend/Scripts/AutoLoginZerodha.py", line 37, in automate_login', '    browser.get(browser_url)', '  File "/Users/vishaljha/anaconda3/lib/python3.8/site-packages/selenium/webdriver/remote/webdriver.py", line 333, in get', "    self.execute(Command.GET, {'url': url})", '  File "/Users/vishaljha/anaconda3/lib/python3.8/site-packages/selenium/webdriver/remote/webdriver.py", line 319, in execute', '    response = self.command_executor.execute(driver_command, params)', '  File "/Users/vishaljha/anaconda3/lib/python3.8/site-packages/selenium/webdriver/remote/remote_connection.py", line 374, in execute', '    return self._request(command_info[0], url, body=data)', '  File "/Users/vishaljha/anaconda3/lib/python3.8/site-packages/selenium/webdriver/remote/remote_connection.py", line 397, in _request', '    resp = self._conn.request(method, url, body=body, headers=headers)', '  File "/Users/vishaljha/anaconda3/lib/python3.8/site-packages/urllib3/request.py", line 70, in request', '    return self.request_encode_body(method, url, fields=fields,', '  File "/Users/vishaljha/anaconda3/lib/python3.8/site-packages/urllib3/request.py", line 150, in request_encode_body', '    return self.urlopen(method, url, **extra_kw)', '  File "/Users/vishaljha/anaconda3/lib/python3.8/site-packages/urllib3/poolmanager.py", line 326, in urlopen', '    response = conn.urlopen(method, u.request_uri, **kw)', '  File "/Users/vishaljha/anaconda3/lib/python3.8/site-packages/urllib3/connectionpool.py", line 640, in urlopen', '    retries = retries.increment(method, url, error=e, _pool=self,', '  File "/Users/vishaljha/anaconda3/lib/python3.8/site-packages/urllib3/util/retry.py", line 368, in increment', '    raise six.reraise(type(error), error, _stacktrace)', '  File "/Users/vishaljha/anaconda3/lib/python3.8/site-packages/urllib3/packages/six.py", line 685, in reraise', '    raise value.with_traceback(tb)', '  File "/Users/vishaljha/anaconda3/lib/python3.8/site-packages/urllib3/connectionpool.py", line 600, in urlopen', '    httplib_response = self._make_request(conn, method, url,', '  File "/Users/vishaljha/anaconda3/lib/python3.8/site-packages/urllib3/connectionpool.py", line 387, in _make_request', '    six.raise_from(e, None)', '  File "<string>", line 2, in raise_from', '  File "/Users/vishaljha/anaconda3/lib/python3.8/site-packages/urllib3/connectionpool.py", line 383, in _make_request', '    httplib_response = conn.getresponse()', '  File "/Users/vishaljha/anaconda3/lib/python3.8/http/client.py", line 1332, in getresponse', '    response.begin()', '  File "/Users/vishaljha/anaconda3/lib/python3.8/http/client.py", line 303, in begin', '    version, status, reason = self._read_status()', '  File "/Users/vishaljha/anaconda3/lib/python3.8/http/client.py", line 272, in _read_status', '    raise RemoteDisconnected("Remote end closed connection without"', "urllib3.exceptions.ProtocolError: ('Connection aborted.', RemoteDisconnected('Remote end closed connection without response'))", '', 'During handling of the above exception, another exception occurred:', '', 'Traceback (most recent call last):', '  File "/Users/vishaljha/anaconda3/lib/python3.8/site-packages/selenium/webdriver/common/service.py", line 72, in start', '    self.process = subprocess.Popen(cmd, env=self.env,', '  File "/Users/vishaljha/anaconda3/lib/python3.8/subprocess.py", line 854, in __init__', '    self._execute_child(args, executable, preexec_fn, close_fds,', '  File "/Users/vishaljha/anaconda3/lib/python3.8/subprocess.py", line 1702, in _execute_child', '    raise child_exception_type(errno_num, err_msg, err_filename)', "FileNotFoundError: [Errno 2] No such file or directory: 'chromedriver'", '', 'During handling of the above exception, another exception occurred:', '', 'Traceback (most recent call last):', '  File "/Users/vishaljha/Desktop/FINVANT/API/Backend/Scripts/AutoLoginZerodha.py", line 117, in auto_login_zerodha', '    key = automate_login(browser_url, user_id, password, totp_pin)', '  File "/Users/vishaljha/Desktop/FINVANT/API/Backend/Scripts/AutoLoginZerodha.py", line 40, in automate_login', '    browser = webdriver.Chrome(options = options)', '  File "/Users/vishaljha/anaconda3/lib/python3.8/site-packages/selenium/webdriver/chrome/webdriver.py", line 73, in __init__', '    self.service.start()', '  File "/Users/vishaljha/anaconda3/lib/python3.8/site-packages/selenium/webdriver/common/service.py", line 81, in start', '    raise WebDriverException(', "selenium.common.exceptions.WebDriverException: Message: 'chromedriver' executable needs to be in PATH. Please see https://sites.google.com/a/chromium.org/chromedriver/home", '']
root - CRITICAL - CRITICAL ERROR:2023-01-19 12:32:45.871239 - Failed to initialise Log server/ADS.
['Traceback (most recent call last):', '  File "Main.py", line 66, in main_loop', '    user_dict = UserProfileGenerator().create_user_profiles(user_data=user_data, log_interface=self.log_interface)', '  File "/Users/vishaljha/Desktop/FINVANT/API/Backend/Scripts/UserProfileGenerator.py", line 56, in create_user_profiles', '    t.join()', '  File "/Users/vishaljha/anaconda3/lib/python3.8/threading.py", line 1011, in join', '    self._wait_for_tstate_lock()', '  File "/Users/vishaljha/anaconda3/lib/python3.8/threading.py", line 1027, in _wait_for_tstate_lock', '    elif lock.acquire(block, timeout):', 'KeyboardInterrupt', '', 'During handling of the above exception, another exception occurred:', '', 'Traceback (most recent call last):', '  File "/Users/vishaljha/anaconda3/lib/python3.8/site-packages/urllib3/connectionpool.py", line 379, in _make_request', '    httplib_response = conn.getresponse(buffering=True)', "TypeError: getresponse() got an unexpected keyword argument 'buffering'", '', 'During handling of the above exception, another exception occurred:', '', 'Traceback (most recent call last):', '  File "Main.py", line 30, in __init__', '    self.start()', '  File "Main.py", line 38, in start', '    self.main_loop()', '  File "Main.py", line 68, in main_loop', '    self.log_interface.postLog(severity="CRITICAL",message=\'Failed to generate user dictionary.\',publish = 1, tag = \'OMSB_MAIN_4\')', '  File "/Users/vishaljha/Desktop/FINVANT/API/Backend/Scripts/Log_Server_Interface.py", line 55, in postLog', "    response = requests.post(self.url + 'post/log', headers=headers, json=json_compatible_item_data)", '  File "/Users/vishaljha/anaconda3/lib/python3.8/site-packages/requests/api.py", line 116, in post', "    return request('post', url, data=data, json=json, **kwargs)", '  File "/Users/vishaljha/anaconda3/lib/python3.8/site-packages/requests/api.py", line 60, in request', '    return session.request(method=method, url=url, **kwargs)', '  File "/Users/vishaljha/anaconda3/lib/python3.8/site-packages/requests/sessions.py", line 533, in request', '    resp = self.send(prep, **send_kwargs)', '  File "/Users/vishaljha/anaconda3/lib/python3.8/site-packages/requests/sessions.py", line 646, in send', '    r = adapter.send(request, **kwargs)', '  File "/Users/vishaljha/anaconda3/lib/python3.8/site-packages/requests/adapters.py", line 439, in send', '    resp = conn.urlopen(', '  File "/Users/vishaljha/anaconda3/lib/python3.8/site-packages/urllib3/connectionpool.py", line 600, in urlopen', '    httplib_response = self._make_request(conn, method, url,', '  File "/Users/vishaljha/anaconda3/lib/python3.8/site-packages/urllib3/connectionpool.py", line 383, in _make_request', '    httplib_response = conn.getresponse()', '  File "/Users/vishaljha/anaconda3/lib/python3.8/http/client.py", line 1332, in getresponse', '    response.begin()', '  File "/Users/vishaljha/anaconda3/lib/python3.8/http/client.py", line 303, in begin', '    version, status, reason = self._read_status()', '  File "/Users/vishaljha/anaconda3/lib/python3.8/http/client.py", line 264, in _read_status', '    line = str(self.fp.readline(_MAXLINE + 1), "iso-8859-1")', '  File "/Users/vishaljha/anaconda3/lib/python3.8/socket.py", line 669, in readinto', '    return self._sock.recv_into(b)', 'KeyboardInterrupt']
root - INFO - 2023-01-19 12:32:45.963526 - OMSB: Zerodha login for WG5235.
root - INFO - 2023-01-19 12:32:46.031528 - OMSB: Zerodha login for WG5235.
urllib3.connectionpool - WARNING - Retrying (Retry(total=2, connect=None, read=None, redirect=None, status=None)) after connection broken by 'NewConnectionError('<urllib3.connection.HTTPConnection object at 0x7fe54ed5ea00>: Failed to establish a new connection: [Errno 61] Connection refused')': /session/59fce7681496b381e8d288e39126098c/element
urllib3.connectionpool - WARNING - Retrying (Retry(total=1, connect=None, read=None, redirect=None, status=None)) after connection broken by 'NewConnectionError('<urllib3.connection.HTTPConnection object at 0x7fe54f105940>: Failed to establish a new connection: [Errno 61] Connection refused')': /session/59fce7681496b381e8d288e39126098c/element
urllib3.connectionpool - WARNING - Retrying (Retry(total=0, connect=None, read=None, redirect=None, status=None)) after connection broken by 'NewConnectionError('<urllib3.connection.HTTPConnection object at 0x7fe54f105ac0>: Failed to establish a new connection: [Errno 61] Connection refused')': /session/59fce7681496b381e8d288e39126098c/element
root - INFO - 2023-01-19 12:32:54.156326 - Finvant Alcubierre Mk1 OMS Backend turned on.
root - INFO - 2023-01-19 12:32:54.282472 - OMS Backend mainloop started.
root - INFO - 2023-01-19 12:32:54.477807 - OMSB: Logging in for backend kite ticker.
root - INFO - 2023-01-19 12:33:01.439815 - OMSB: Login succesful for backend kite ticker.
root - INFO - 2023-01-19 12:33:01.599819 - OMSB: Zerodha login for WG5235.
root - INFO - 2023-01-19 12:33:01.600187 - OMSB: Zerodha login for WG5235.
root - INFO - 2023-01-19 12:33:01.601430 - OMSB: Zerodha login for WG5235.
root - INFO - 2023-01-19 12:33:01.602117 - OMSB: Zerodha login for WG5235.
root - CRITICAL - CRITICAL ERROR:2023-01-19 12:33:09.410412 - OMSB: Failed auto login to kite for user:WG5235.
['Traceback (most recent call last):', '  File "/Users/vishaljha/Desktop/FINVANT/API/Backend/Scripts/AutoLoginZerodha.py", line 119, in auto_login_zerodha', '    data = kite.generate_session(key, api_secret=api_secret)', '  File "/Users/vishaljha/anaconda3/lib/python3.8/site-packages/kiteconnect/connect.py", line 258, in generate_session', '    resp = self._post("api.token", params={', '  File "/Users/vishaljha/anaconda3/lib/python3.8/site-packages/kiteconnect/connect.py", line 841, in _post', '    return self._request(route, "POST", url_args=url_args, params=params, is_json=is_json, query_params=query_params)', '  File "/Users/vishaljha/anaconda3/lib/python3.8/site-packages/kiteconnect/connect.py", line 913, in _request', '    raise exp(data["message"], code=r.status_code)', 'kiteconnect.exceptions.InputException: `request_token` should be minimum 10 characters in length.']
root - INFO - 2023-01-19 12:33:09.417054 - OMSB: Zerodha login succesful for WG5235.
root - INFO - 2023-01-19 12:33:09.549839 - OMSB: Zerodha login for WG5235.
root - CRITICAL - CRITICAL ERROR:2023-01-19 12:33:09.598618 - OMSB: Failed auto login to kite for user:WG5235.
['Traceback (most recent call last):', '  File "/Users/vishaljha/Desktop/FINVANT/API/Backend/Scripts/AutoLoginZerodha.py", line 119, in auto_login_zerodha', '    data = kite.generate_session(key, api_secret=api_secret)', '  File "/Users/vishaljha/anaconda3/lib/python3.8/site-packages/kiteconnect/connect.py", line 258, in generate_session', '    resp = self._post("api.token", params={', '  File "/Users/vishaljha/anaconda3/lib/python3.8/site-packages/kiteconnect/connect.py", line 841, in _post', '    return self._request(route, "POST", url_args=url_args, params=params, is_json=is_json, query_params=query_params)', '  File "/Users/vishaljha/anaconda3/lib/python3.8/site-packages/kiteconnect/connect.py", line 913, in _request', '    raise exp(data["message"], code=r.status_code)', 'kiteconnect.exceptions.InputException: `request_token` should be minimum 10 characters in length.']
root - INFO - 2023-01-19 12:33:09.610812 - OMSB: Zerodha login for WG5235.
root - INFO - 2023-01-19 12:33:09.718855 - OMSB: Zerodha login succesful for WG5235.
root - INFO - 2023-01-19 12:33:09.741605 - OMSB: Zerodha login for WG5235.
root - INFO - 2023-01-19 12:33:09.868864 - OMSB: Zerodha login for WG5235.
root - CRITICAL - CRITICAL ERROR:2023-01-19 12:33:17.762542 - OMSB: Failed auto login to kite for user:WG5235.
['Traceback (most recent call last):', '  File "/Users/vishaljha/Desktop/FINVANT/API/Backend/Scripts/AutoLoginZerodha.py", line 119, in auto_login_zerodha', '    data = kite.generate_session(key, api_secret=api_secret)', '  File "/Users/vishaljha/anaconda3/lib/python3.8/site-packages/kiteconnect/connect.py", line 258, in generate_session', '    resp = self._post("api.token", params={', '  File "/Users/vishaljha/anaconda3/lib/python3.8/site-packages/kiteconnect/connect.py", line 841, in _post', '    return self._request(route, "POST", url_args=url_args, params=params, is_json=is_json, query_params=query_params)', '  File "/Users/vishaljha/anaconda3/lib/python3.8/site-packages/kiteconnect/connect.py", line 913, in _request', '    raise exp(data["message"], code=r.status_code)', 'kiteconnect.exceptions.InputException: `request_token` should be minimum 10 characters in length.']
root - CRITICAL - CRITICAL ERROR:2023-01-19 12:33:17.808112 - OMSB: Failed auto login to kite for user:WG5235.
['Traceback (most recent call last):', '  File "/Users/vishaljha/Desktop/FINVANT/API/Backend/Scripts/AutoLoginZerodha.py", line 119, in auto_login_zerodha', '    data = kite.generate_session(key, api_secret=api_secret)', '  File "/Users/vishaljha/anaconda3/lib/python3.8/site-packages/kiteconnect/connect.py", line 258, in generate_session', '    resp = self._post("api.token", params={', '  File "/Users/vishaljha/anaconda3/lib/python3.8/site-packages/kiteconnect/connect.py", line 841, in _post', '    return self._request(route, "POST", url_args=url_args, params=params, is_json=is_json, query_params=query_params)', '  File "/Users/vishaljha/anaconda3/lib/python3.8/site-packages/kiteconnect/connect.py", line 913, in _request', '    raise exp(data["message"], code=r.status_code)', 'kiteconnect.exceptions.InputException: `request_token` should be minimum 10 characters in length.']
root - INFO - 2023-01-19 12:33:17.829195 - OMSB: Zerodha login succesful for WG5235.
root - INFO - 2023-01-19 12:33:17.896950 - OMSB: Zerodha login for WG5235.
root - INFO - 2023-01-19 12:33:17.956664 - OMSB: Zerodha login for WG5235.
root - INFO - 2023-01-19 12:33:18.013642 - OMSB: Zerodha login for WG5235.
root - INFO - 2023-01-19 12:33:18.351725 - OMSB: Zerodha login succesful for WG5235.
root - INFO - 2023-01-19 12:33:18.498704 - OMSB: Zerodha login for WG5235.
root - INFO - 2023-01-19 12:33:25.580718 - OMSB: Zerodha login succesful for WG5235.
root - INFO - 2023-01-19 12:33:25.714710 - OMSB: Zerodha login for WG5235.
root - CRITICAL - CRITICAL ERROR:2023-01-19 12:33:25.811760 - OMSB: Failed auto login to kite for user:WG5235.
['Traceback (most recent call last):', '  File "/Users/vishaljha/Desktop/FINVANT/API/Backend/Scripts/AutoLoginZerodha.py", line 119, in auto_login_zerodha', '    data = kite.generate_session(key, api_secret=api_secret)', '  File "/Users/vishaljha/anaconda3/lib/python3.8/site-packages/kiteconnect/connect.py", line 258, in generate_session', '    resp = self._post("api.token", params={', '  File "/Users/vishaljha/anaconda3/lib/python3.8/site-packages/kiteconnect/connect.py", line 841, in _post', '    return self._request(route, "POST", url_args=url_args, params=params, is_json=is_json, query_params=query_params)', '  File "/Users/vishaljha/anaconda3/lib/python3.8/site-packages/kiteconnect/connect.py", line 913, in _request', '    raise exp(data["message"], code=r.status_code)', 'kiteconnect.exceptions.InputException: `request_token` should be minimum 10 characters in length.']
root - INFO - 2023-01-19 12:33:25.905625 - OMSB: Zerodha login succesful for WG5235.
root - INFO - 2023-01-19 12:33:25.949487 - OMSB: Zerodha login for WG5235.
root - INFO - 2023-01-19 12:33:26.040576 - OMSB: Zerodha login for WG5235.
root - INFO - 2023-01-19 12:33:26.156492 - OMSB: Zerodha login succesful for WG5235.
root - INFO - 2023-01-19 12:33:26.297040 - OMSB: Zerodha login for WG5235.
root - INFO - 2023-01-19 12:33:32.991648 - OMSB: Zerodha login succesful for WG5235.
root - INFO - 2023-01-19 12:33:33.132787 - OMSB: Zerodha login for WG5235.
root - INFO - 2023-01-19 12:33:33.431457 - OMSB: Zerodha login succesful for WG5235.
root - INFO - 2023-01-19 12:33:33.553846 - OMSB: Zerodha login for WG5235.
root - INFO - 2023-01-19 12:33:33.857856 - OMSB: Zerodha login succesful for WG5235.
root - INFO - 2023-01-19 12:33:34.000780 - OMSB: Zerodha login for WG5235.
root - INFO - 2023-01-19 12:33:34.162228 - OMSB: Zerodha login succesful for WG5235.
root - INFO - 2023-01-19 12:33:34.303632 - OMSB: Zerodha login for WG5235.
root - INFO - 2023-01-19 12:33:40.086080 - OMSB: Zerodha login succesful for WG5235.
root - INFO - 2023-01-19 12:33:40.798563 - OMSB: Zerodha login succesful for WG5235.
root - INFO - 2023-01-19 12:33:42.109358 - OMSB: Zerodha login succesful for WG5235.
root - INFO - 2023-01-19 12:33:42.395506 - OMSB: Zerodha login succesful for WG5235.
kiteconnect.ticker - ERROR - Connection error: 1006 - connection was closed uncleanly (None)
kiteconnect.ticker - ERROR - Connection closed: 1006 - connection was closed uncleanly (None)
kiteconnect.ticker - ERROR - Connection error: 1006 - connection was closed uncleanly (None)
kiteconnect.ticker - ERROR - Connection closed: 1006 - connection was closed uncleanly (None)
kiteconnect.ticker - ERROR - Connection error: 1006 - connection was closed uncleanly (None)
kiteconnect.ticker - ERROR - Connection closed: 1006 - connection was closed uncleanly (None)
kiteconnect.ticker - ERROR - Connection error: 1006 - connection was closed uncleanly (None)
kiteconnect.ticker - ERROR - Connection closed: 1006 - connection was closed uncleanly (None)
kiteconnect.ticker - ERROR - Connection error: 1006 - connection was closed uncleanly (None)
kiteconnect.ticker - ERROR - Connection closed: 1006 - connection was closed uncleanly (None)
root - INFO - 2023-01-19 12:34:46.173344 - Placed Zerodha Kite futures order for:LXfgnNeV, instrument:NIFTY23JANFUT, qty:1, transaction type:BUY, placed price:17269, id:7.
root - INFO - 2023-01-19 12:34:46.174302 - Placed Zerodha Kite futures order for:ecCsimDH, instrument:NIFTY23JANFUT, qty:1, transaction type:BUY, placed price:17555, id:1.
root - INFO - 2023-01-19 12:34:46.176774 - Placed Zerodha Kite futures order for:WprNkyOw, instrument:NIFTY23JANFUT, qty:1, transaction type:BUY, placed price:17771, id:12.
root - INFO - 2023-01-19 12:34:46.177819 - Placed Zerodha Kite futures order for:uRSwdIpo, instrument:NIFTY23JANFUT, qty:1, transaction type:BUY, placed price:17099, id:16.
root - INFO - 2023-01-19 12:34:46.179583 - Placed Zerodha Kite futures order for:DHYVmDuL, instrument:NIFTY23JANFUT, qty:1, transaction type:BUY, placed price:17822, id:6.
root - INFO - 2023-01-19 12:34:46.180091 - Placed Zerodha Kite futures order for:KsCsvenc, instrument:NIFTY23JANFUT, qty:1, transaction type:BUY, placed price:17932, id:15.
root - INFO - 2023-01-19 12:34:46.188690 - Placed Zerodha Kite futures order for:cJPEsAqA, instrument:NIFTY23JANFUT, qty:1, transaction type:BUY, placed price:17438, id:16.
root - INFO - 2023-01-19 12:34:46.191779 - Placed Zerodha Kite futures order for:TTQaNDXf, instrument:NIFTY23JANFUT, qty:1, transaction type:BUY, placed price:17068, id:5.
root - INFO - 2023-01-19 12:34:46.206571 - Placed Zerodha Kite futures order for:PVYWqipD, instrument:NIFTY23JANFUT, qty:1, transaction type:BUY, placed price:17843, id:7.
root - INFO - 2023-01-19 12:34:46.671033 - 494.2760467529297
root - INFO - 2023-01-19 12:34:46.697528 - 518.1529521942139
root - INFO - 2023-01-19 12:34:46.761783 - 587.4476432800293
root - INFO - 2023-01-19 12:34:46.823592 - 631.8249702453613
root - INFO - 2023-01-19 12:34:46.881625 - 700.3719806671143
root - INFO - 2023-01-19 12:34:46.930770 - 752.7072429656982
root - INFO - 2023-01-19 12:34:47.024399 - 835.5729579925537
root - INFO - 2023-01-19 12:34:47.082465 - 908.3971977233887
root - INFO - 2023-01-19 12:34:47.119596 - 912.9440784454346
kiteconnect.ticker - ERROR - Connection error: 1006 - connection was closed uncleanly (None)
kiteconnect.ticker - ERROR - Connection closed: 1006 - connection was closed uncleanly (None)
kiteconnect.ticker - ERROR - Connection error: 1006 - connection was closed uncleanly (None)
kiteconnect.ticker - ERROR - Connection closed: 1006 - connection was closed uncleanly (None)
kiteconnect.ticker - ERROR - Connection error: 1006 - connection was closed uncleanly (None)
kiteconnect.ticker - ERROR - Connection closed: 1006 - connection was closed uncleanly (None)
kiteconnect.ticker - ERROR - Connection error: 1006 - connection was closed uncleanly (None)
kiteconnect.ticker - ERROR - Connection closed: 1006 - connection was closed uncleanly (None)
kiteconnect.ticker - ERROR - Connection error: 1006 - connection was closed uncleanly (None)
kiteconnect.ticker - ERROR - Connection closed: 1006 - connection was closed uncleanly (None)
kiteconnect.ticker - ERROR - Connection error: 1006 - connection was closed uncleanly (None)
kiteconnect.ticker - ERROR - Connection closed: 1006 - connection was closed uncleanly (None)
kiteconnect.ticker - ERROR - Connection error: 1006 - connection was closed uncleanly (None)
kiteconnect.ticker - ERROR - Connection closed: 1006 - connection was closed uncleanly (None)
kiteconnect.ticker - ERROR - Connection error: 1006 - connection was closed uncleanly (None)
kiteconnect.ticker - ERROR - Connection closed: 1006 - connection was closed uncleanly (None)
kiteconnect.ticker - ERROR - Connection error: 1006 - connection was closed uncleanly (None)
kiteconnect.ticker - ERROR - Connection closed: 1006 - connection was closed uncleanly (None)
kiteconnect.ticker - ERROR - Connection error: 1006 - connection was closed uncleanly (None)
kiteconnect.ticker - ERROR - Connection closed: 1006 - connection was closed uncleanly (None)
kiteconnect.ticker - ERROR - Connection error: 1006 - connection was closed uncleanly (None)
kiteconnect.ticker - ERROR - Connection closed: 1006 - connection was closed uncleanly (None)
root - CRITICAL - CRITICAL ERROR:2023-01-19 12:36:44.860326 - Failed to initialise Log server/ADS.
['Traceback (most recent call last):', '  File "Main.py", line 30, in __init__', '    self.start()', '  File "Main.py", line 38, in start', '    self.main_loop()', '  File "Main.py", line 78, in main_loop', '    sleep(1)', 'KeyboardInterrupt']
root - INFO - 2023-01-19 12:37:35.126006 - Finvant Alcubierre Mk1 OMS Backend turned on.
root - INFO - 2023-01-19 12:37:35.262471 - OMS Backend mainloop started.
root - INFO - 2023-01-19 12:37:35.437235 - OMSB: Logging in for backend kite ticker.
root - INFO - 2023-01-19 12:37:43.460808 - OMSB: Login succesful for backend kite ticker.
root - INFO - 2023-01-19 12:37:43.595325 - OMSB: Zerodha login for WG5235.
root - INFO - 2023-01-19 12:37:51.369828 - OMSB: Zerodha login succesful for WG5235.
root - INFO - 2023-01-19 12:37:59.697154 - Placed Zerodha Kite futures order for:FINVANT, instrument:NIFTY23JANFUT, qty:1, transaction type:BUY, placed price:17380, id:5.
root - INFO - 2023-01-19 12:38:00.227386 - 530.2190780639648
root - CRITICAL - CRITICAL ERROR:2023-01-19 12:39:34.513720 - Failed to initialise Log server/ADS.
['Traceback (most recent call last):', '  File "Main.py", line 30, in __init__', '    self.start()', '  File "Main.py", line 38, in start', '    self.main_loop()', '  File "Main.py", line 78, in main_loop', '    sleep(1)', 'KeyboardInterrupt']
root - INFO - 2023-01-19 12:39:46.237081 - Finvant Alcubierre Mk1 OMS Backend turned on.
root - INFO - 2023-01-19 12:39:46.368297 - OMS Backend mainloop started.
root - INFO - 2023-01-19 12:39:46.549212 - OMSB: Logging in for backend kite ticker.
root - INFO - 2023-01-19 12:39:53.826015 - OMSB: Login succesful for backend kite ticker.
root - INFO - 2023-01-19 12:39:53.958233 - OMSB: Zerodha login for WG5235.
root - INFO - 2023-01-19 12:40:01.685360 - OMSB: Zerodha login succesful for WG5235.
root - INFO - 2023-01-19 12:40:09.141301 - Placed Zerodha Kite futures order for:FINVANT, instrument:NIFTY23JANFUT, qty:1, transaction type:BUY, placed price:17957, id:13.
root - INFO - 2023-01-19 12:40:09.558778 - 417.4768924713135
root - CRITICAL - CRITICAL ERROR:2023-01-19 12:42:16.127623 - Failed to initialise Log server/ADS.
['Traceback (most recent call last):', '  File "Main.py", line 30, in __init__', '    self.start()', '  File "Main.py", line 38, in start', '    self.main_loop()', '  File "Main.py", line 78, in main_loop', '    sleep(1)', 'KeyboardInterrupt']
root - INFO - 2023-01-19 12:42:30.354708 - Finvant Alcubierre Mk1 OMS Backend turned on.
root - INFO - 2023-01-19 12:42:30.481818 - OMS Backend mainloop started.
root - INFO - 2023-01-19 12:42:30.657727 - OMSB: Logging in for backend kite ticker.
root - INFO - 2023-01-19 12:42:37.613369 - OMSB: Login succesful for backend kite ticker.
root - INFO - 2023-01-19 12:42:37.748237 - OMSB: Zerodha login for WG5235.
root - INFO - 2023-01-19 12:42:44.625789 - OMSB: Zerodha login succesful for WG5235.
root - CRITICAL - CRITICAL ERROR:2023-01-19 12:43:08.354478 - Failed to refresh lookup table.
['Traceback (most recent call last):', '  File "/Users/vishaljha/Desktop/FINVANT/API/Backend/Scripts/GatherLTP.py", line 45, in refresh_lookup_table', '    self.lookup_table = json.load(f)', '  File "/Users/vishaljha/anaconda3/lib/python3.8/json/__init__.py", line 293, in load', '    return loads(fp.read(),', '  File "/Users/vishaljha/anaconda3/lib/python3.8/json/__init__.py", line 357, in loads', '    return _default_decoder.decode(s)', '  File "/Users/vishaljha/anaconda3/lib/python3.8/json/decoder.py", line 337, in decode', '    obj, end = self.raw_decode(s, idx=_w(s, 0).end())', '  File "/Users/vishaljha/anaconda3/lib/python3.8/json/decoder.py", line 355, in raw_decode', '    raise JSONDecodeError("Expecting value", s, err.value) from None', 'json.decoder.JSONDecodeError: Expecting value: line 1 column 1 (char 0)']
root - INFO - 2023-01-19 12:43:08.556540 - Placed Zerodha Kite futures order for:FINVANT, instrument:NIFTY23JANFUT, qty:1, transaction type:BUY, placed price:17679, id:10.
root - INFO - 2023-01-19 12:43:08.969756 - 413.1741523742676
root - CRITICAL - CRITICAL ERROR:2023-01-19 12:44:03.737706 - Failed to initialise Log server/ADS.
['Traceback (most recent call last):', '  File "Main.py", line 30, in __init__', '    self.start()', '  File "Main.py", line 38, in start', '    self.main_loop()', '  File "Main.py", line 78, in main_loop', '    sleep(1)', 'KeyboardInterrupt']
root - INFO - 2023-01-19 12:46:54.331140 - Finvant Alcubierre Mk1 OMS Backend turned on.
root - INFO - 2023-01-19 12:46:54.466402 - OMS Backend mainloop started.
root - INFO - 2023-01-19 12:46:54.645495 - OMSB: Logging in for backend kite ticker.
root - INFO - 2023-01-19 12:47:02.743262 - OMSB: Login succesful for backend kite ticker.
root - INFO - 2023-01-19 12:47:02.875633 - OMSB: Zerodha login for WG5235.
root - INFO - 2023-01-19 12:47:10.063896 - OMSB: Zerodha login succesful for WG5235.
root - INFO - 2023-01-19 12:47:15.697408 - Placed Zerodha Kite futures order for:FINVANT, instrument:NIFTY23JANFUT, qty:1, transaction type:BUY, placed price:17158, id:15.
root - INFO - 2023-01-19 12:47:16.118985 - 421.5691089630127
root - INFO - 2023-01-19 12:50:35.183348 - Placed Zerodha Kite futures order for:FINVANT, instrument:NIFTY23JANFUT, qty:1, transaction type:BUY, placed price:17560, id:18.
root - INFO - 2023-01-19 12:50:35.509047 - TARGET HIT FOR USER:FINVANT STRATEGY:NOVA INSTRUMENT:NIFTY.
root - INFO - 2023-01-19 12:50:35.619007 - 435.6343746185303
root - INFO - 2023-01-19 12:50:35.759483 - Placed Zerodha Kite futures order for:FINVANT, instrument:NIFTY23JANFUT, qty:1, transaction type:BUY, placed price:17432, id:10.
root - INFO - 2023-01-19 12:50:36.167408 - 407.9320430755615
root - INFO - 2023-01-19 12:51:17.057662 - Placed Zerodha Kite futures order for:FINVANT, instrument:NIFTY23JANFUT, qty:1, transaction type:BUY, placed price:17700, id:12.
root - INFO - 2023-01-19 12:51:17.485345 - 427.66523361206055
root - INFO - 2023-01-19 12:51:17.610449 - TARGET HIT FOR USER:FINVANT STRATEGY:NOVA INSTRUMENT:NIFTY.
root - INFO - 2023-01-19 12:51:17.764841 - Placed Zerodha Kite futures order for:FINVANT, instrument:NIFTY23JANFUT, qty:1, transaction type:BUY, placed price:17365, id:2.
root - INFO - 2023-01-19 12:51:18.177373 - 412.49704360961914
root - CRITICAL - CRITICAL ERROR:2023-01-19 12:52:53.848470 - Failed to initialise Log server/ADS.
['Traceback (most recent call last):', '  File "Main.py", line 30, in __init__', '    self.start()', '  File "Main.py", line 38, in start', '    self.main_loop()', '  File "Main.py", line 78, in main_loop', '    sleep(1)', 'KeyboardInterrupt']
root - INFO - 2023-01-19 12:53:23.836658 - Finvant Alcubierre Mk1 OMS Backend turned on.
root - INFO - 2023-01-19 12:53:23.964015 - OMS Backend mainloop started.
root - INFO - 2023-01-19 12:53:24.149206 - OMSB: Logging in for backend kite ticker.
root - INFO - 2023-01-19 12:53:31.465225 - OMSB: Login succesful for backend kite ticker.
root - INFO - 2023-01-19 12:53:31.599440 - OMSB: Zerodha login for WG5235.
root - INFO - 2023-01-19 12:53:39.770526 - OMSB: Zerodha login succesful for WG5235.
root - INFO - 2023-01-19 12:53:47.661636 - Placed Zerodha Kite futures order for:FINVANT, instrument:NIFTY23JANFUT, qty:50, transaction type:BUY, placed price:18132.0, id:459.
root - INFO - 2023-01-19 12:53:48.078253 - 417.4230098724365
root - CRITICAL - CRITICAL ERROR:2023-01-19 12:54:59.355780 - Failed to refresh lookup table.
['Traceback (most recent call last):', '  File "/Users/vishaljha/Desktop/FINVANT/API/Backend/Scripts/GatherLTP.py", line 45, in refresh_lookup_table', '    self.lookup_table = json.load(f)', '  File "/Users/vishaljha/anaconda3/lib/python3.8/json/__init__.py", line 293, in load', '    return loads(fp.read(),', '  File "/Users/vishaljha/anaconda3/lib/python3.8/json/__init__.py", line 357, in loads', '    return _default_decoder.decode(s)', '  File "/Users/vishaljha/anaconda3/lib/python3.8/json/decoder.py", line 337, in decode', '    obj, end = self.raw_decode(s, idx=_w(s, 0).end())', '  File "/Users/vishaljha/anaconda3/lib/python3.8/json/decoder.py", line 355, in raw_decode', '    raise JSONDecodeError("Expecting value", s, err.value) from None', 'json.decoder.JSONDecodeError: Expecting value: line 1 column 1 (char 0)']
root - INFO - 2023-01-19 12:54:59.494810 - Placed Zerodha Kite futures order for:FINVANT, instrument:NIFTY23JANFUT, qty:50, transaction type:BUY, placed price:18133.0, id:401.
root - INFO - 2023-01-19 12:54:59.914912 - 420.89295387268066
kiteconnect.ticker - ERROR - Connection error: 1006 - connection was closed uncleanly (None)
kiteconnect.ticker - ERROR - Connection closed: 1006 - connection was closed uncleanly (None)
kiteconnect.ticker - ERROR - Connection error: 1006 - connection was closed uncleanly (None)
kiteconnect.ticker - ERROR - Connection closed: 1006 - connection was closed uncleanly (None)
kiteconnect.ticker - ERROR - Connection error: 1006 - connection was closed uncleanly (None)
kiteconnect.ticker - ERROR - Connection closed: 1006 - connection was closed uncleanly (None)
kiteconnect.ticker - ERROR - Connection error: 1006 - connection was closed uncleanly (None)
kiteconnect.ticker - ERROR - Connection closed: 1006 - connection was closed uncleanly (None)
kiteconnect.ticker - ERROR - Connection error: 1006 - connection was closed uncleanly (None)
kiteconnect.ticker - ERROR - Connection closed: 1006 - connection was closed uncleanly (None)
kiteconnect.ticker - ERROR - Connection error: 1006 - connection was closed uncleanly (None)
kiteconnect.ticker - ERROR - Connection closed: 1006 - connection was closed uncleanly (None)
root - INFO - 2023-01-19 14:23:22.806632 - STOPLOSS HIT FOR USER:FINVANT STRATEGY:NOVA INSTRUMENT:NIFTY.
root - INFO - 2023-01-19 14:23:22.953910 - Placed Zerodha Kite futures order for:FINVANT, instrument:NIFTY23JANFUT, qty:50, transaction type:BUY, placed price:18114.0, id:46.
root - INFO - 2023-01-19 14:23:23.364534 - 411.4649295806885
kiteconnect.ticker - ERROR - Connection error: 1006 - connection was closed uncleanly (None)
kiteconnect.ticker - ERROR - Connection closed: 1006 - connection was closed uncleanly (None)
kiteconnect.ticker - ERROR - Connection error: 1006 - connection was closed uncleanly (None)
kiteconnect.ticker - ERROR - Connection closed: 1006 - connection was closed uncleanly (None)
kiteconnect.ticker - ERROR - Connection error: 1006 - connection was closed uncleanly (None)
kiteconnect.ticker - ERROR - Connection closed: 1006 - connection was closed uncleanly (None)
kiteconnect.ticker - ERROR - Connection error: 1006 - connection was closed uncleanly (None)
kiteconnect.ticker - ERROR - Connection closed: 1006 - connection was closed uncleanly (None)
kiteconnect.ticker - ERROR - Connection error: 1006 - connection was closed uncleanly (None)
kiteconnect.ticker - ERROR - Connection closed: 1006 - connection was closed uncleanly (None)
kiteconnect.ticker - ERROR - Connection error: 1006 - connection was closed uncleanly (None)
kiteconnect.ticker - ERROR - Connection closed: 1006 - connection was closed uncleanly (None)
kiteconnect.ticker - ERROR - Connection error: 1006 - connection was closed uncleanly (None)
kiteconnect.ticker - ERROR - Connection closed: 1006 - connection was closed uncleanly (None)
kiteconnect.ticker - ERROR - Connection error: 1006 - connection was closed uncleanly (None)
kiteconnect.ticker - ERROR - Connection closed: 1006 - connection was closed uncleanly (None)
kiteconnect.ticker - ERROR - Connection error: 1006 - connection was closed uncleanly (None)
kiteconnect.ticker - ERROR - Connection closed: 1006 - connection was closed uncleanly (None)
kiteconnect.ticker - ERROR - Connection error: 1006 - connection was closed uncleanly (None)
kiteconnect.ticker - ERROR - Connection closed: 1006 - connection was closed uncleanly (None)
kiteconnect.ticker - ERROR - Connection error: 1006 - connection was closed uncleanly (None)
kiteconnect.ticker - ERROR - Connection closed: 1006 - connection was closed uncleanly (None)
kiteconnect.ticker - ERROR - Connection error: 1006 - connection was closed uncleanly (WebSocket opening handshake timeout (peer did not finish the opening handshake in time))
kiteconnect.ticker - ERROR - Connection closed: 1006 - connection was closed uncleanly (WebSocket opening handshake timeout (peer did not finish the opening handshake in time))
root - CRITICAL - CRITICAL ERROR:2023-01-19 22:08:30.325487 - Failed to initialise Log server/ADS.
['Traceback (most recent call last):', '  File "Main.py", line 30, in __init__', '    self.start()', '  File "Main.py", line 38, in start', '    self.main_loop()', '  File "Main.py", line 78, in main_loop', '    sleep(1)', 'KeyboardInterrupt']
