root - INFO - 2023-01-12 11:55:23.760069 - Finvant Alcubierre Mk1 OMS Backend turned on.
root - INFO - 2023-01-12 11:55:23.861394 - OMS Backend mainloop started.
root - INFO - 2023-01-12 11:55:25.882233 - OMSB: Logging in for backend kite ticker.
root - CRITICAL - CRITICAL ERROR:2023-01-12 11:55:40.008274 - OMSB: Failed auto login to kite ticker.
['Traceback (most recent call last):', '  File "/Users/aditya/Documents/Projects/Mothership/Backend/Scripts/AutoLoginKiteTicker.py", line 116, in auto_login_zerodha_ticker', '    key = automate_login(browser_url, user_id, password, totp_pin)', '  File "/Users/aditya/Documents/Projects/Mothership/Backend/Scripts/AutoLoginKiteTicker.py", line 82, in automate_login', '    time.sleep(1)', 'KeyboardInterrupt']
root - INFO - 2023-01-12 11:55:40.156294 - OMSB: Zerodha login for WG5235.
root - CRITICAL - CRITICAL ERROR:2023-01-12 11:55:40.156995 - Failed to start KWS thread.
['Traceback (most recent call last):', '  File "/Users/aditya/Documents/Projects/Mothership/Backend/Scripts/GatherLTP.py", line 51, in start', '    self.kws.on_ticks = self.on_ticks', "AttributeError: 'NoneType' object has no attribute 'on_ticks'"]
root - CRITICAL - CRITICAL ERROR:2023-01-12 11:55:40.167899 - Failed to generate user dictionary.
['Traceback (most recent call last):', '  File "/Users/aditya/Documents/Projects/Mothership/Backend/Scripts/Main.py", line 64, in main_loop', '    user_dict = UserProfileGenerator().create_user_profiles(user_data=user_data, log_interface=self.log_interface)', '  File "/Users/aditya/Documents/Projects/Mothership/Backend/Scripts/UserProfileGenerator.py", line 15, in create_user_profiles', '    brokerage_interface = auto_login_zerodha(login_details, log_interface=log_interface)', '  File "/Users/aditya/Documents/Projects/Mothership/Backend/Scripts/AutoLoginZerodha.py", line 111, in auto_login_zerodha', "    log_interface.postLog(severity='INFO',message='OMSB: Zerodha login for {}.'.format(user_id),publish=0)", '  File "/Users/aditya/Documents/Projects/Mothership/Backend/Scripts/Log_Server_Interface.py", line 55, in postLog', "    response = requests.post(self.url + 'post/log', headers=headers, json=json_compatible_item_data)", '  File "/opt/homebrew/lib/python3.9/site-packages/requests/api.py", line 117, in post', "    return request('post', url, data=data, json=json, **kwargs)", '  File "/opt/homebrew/lib/python3.9/site-packages/requests/api.py", line 61, in request', '    return session.request(method=method, url=url, **kwargs)', '  File "/opt/homebrew/lib/python3.9/site-packages/requests/sessions.py", line 529, in request', '    resp = self.send(prep, **send_kwargs)', '  File "/opt/homebrew/lib/python3.9/site-packages/requests/sessions.py", line 645, in send', '    r = adapter.send(request, **kwargs)', '  File "/opt/homebrew/lib/python3.9/site-packages/requests/adapters.py", line 440, in send', '    resp = conn.urlopen(', '  File "/opt/homebrew/lib/python3.9/site-packages/urllib3/connectionpool.py", line 703, in urlopen', '    httplib_response = self._make_request(', '  File "/opt/homebrew/lib/python3.9/site-packages/urllib3/connectionpool.py", line 398, in _make_request', '    conn.request(method, url, **httplib_request_kw)', '  File "/opt/homebrew/lib/python3.9/site-packages/urllib3/connection.py", line 239, in request', '    super(HTTPConnection, self).request(method, url, body=body, headers=headers)', '  File "/opt/homebrew/Cellar/python@3.9/3.9.12/Frameworks/Python.framework/Versions/3.9/lib/python3.9/http/client.py", line 1285, in request', '    self._send_request(method, url, body, headers, encode_chunked)', '  File "/opt/homebrew/Cellar/python@3.9/3.9.12/Frameworks/Python.framework/Versions/3.9/lib/python3.9/http/client.py", line 1331, in _send_request', '    self.endheaders(body, encode_chunked=encode_chunked)', '  File "/opt/homebrew/Cellar/python@3.9/3.9.12/Frameworks/Python.framework/Versions/3.9/lib/python3.9/http/client.py", line 1280, in endheaders', '    self._send_output(message_body, encode_chunked=encode_chunked)', '  File "/opt/homebrew/Cellar/python@3.9/3.9.12/Frameworks/Python.framework/Versions/3.9/lib/python3.9/http/client.py", line 1040, in _send_output', '    self.send(msg)', '  File "/opt/homebrew/Cellar/python@3.9/3.9.12/Frameworks/Python.framework/Versions/3.9/lib/python3.9/http/client.py", line 980, in send', '    self.connect()', '  File "/opt/homebrew/lib/python3.9/site-packages/urllib3/connection.py", line 205, in connect', '    conn = self._new_conn()', '  File "/opt/homebrew/lib/python3.9/site-packages/urllib3/connection.py", line 174, in _new_conn', '    conn = connection.create_connection(', '  File "/opt/homebrew/lib/python3.9/site-packages/urllib3/util/connection.py", line 85, in create_connection', '    sock.connect(sa)', 'KeyboardInterrupt']
root - CRITICAL - CRITICAL ERROR:2023-01-12 11:55:40.322923 - Failed to initialise Log server/ADS.
['Traceback (most recent call last):', '  File "/Users/aditya/Documents/Projects/Mothership/Backend/Scripts/Main.py", line 28, in __init__', '    self.start()', '  File "/Users/aditya/Documents/Projects/Mothership/Backend/Scripts/Main.py", line 36, in start', '    self.main_loop()', '  File "/Users/aditya/Documents/Projects/Mothership/Backend/Scripts/Main.py", line 66, in main_loop', '    self.log_interface.postLog(severity="CRITICAL",message=\'Failed to generate user dictionary.\',publish = 1, tag = \'OMSB_MAIN_4\')', '  File "/Users/aditya/Documents/Projects/Mothership/Backend/Scripts/Log_Server_Interface.py", line 55, in postLog', "    response = requests.post(self.url + 'post/log', headers=headers, json=json_compatible_item_data)", '  File "/opt/homebrew/lib/python3.9/site-packages/requests/api.py", line 117, in post', "    return request('post', url, data=data, json=json, **kwargs)", '  File "/opt/homebrew/lib/python3.9/site-packages/requests/api.py", line 61, in request', '    return session.request(method=method, url=url, **kwargs)', '  File "/opt/homebrew/lib/python3.9/site-packages/requests/sessions.py", line 529, in request', '    resp = self.send(prep, **send_kwargs)', '  File "/opt/homebrew/lib/python3.9/site-packages/requests/sessions.py", line 645, in send', '    r = adapter.send(request, **kwargs)', '  File "/opt/homebrew/lib/python3.9/site-packages/requests/adapters.py", line 440, in send', '    resp = conn.urlopen(', '  File "/opt/homebrew/lib/python3.9/site-packages/urllib3/connectionpool.py", line 703, in urlopen', '    httplib_response = self._make_request(', '  File "/opt/homebrew/lib/python3.9/site-packages/urllib3/connectionpool.py", line 449, in _make_request', '    six.raise_from(e, None)', '  File "<string>", line 3, in raise_from', '  File "/opt/homebrew/lib/python3.9/site-packages/urllib3/connectionpool.py", line 444, in _make_request', '    httplib_response = conn.getresponse()', '  File "/opt/homebrew/Cellar/python@3.9/3.9.12/Frameworks/Python.framework/Versions/3.9/lib/python3.9/http/client.py", line 1377, in getresponse', '    response.begin()', '  File "/opt/homebrew/Cellar/python@3.9/3.9.12/Frameworks/Python.framework/Versions/3.9/lib/python3.9/http/client.py", line 320, in begin', '    version, status, reason = self._read_status()', '  File "/opt/homebrew/Cellar/python@3.9/3.9.12/Frameworks/Python.framework/Versions/3.9/lib/python3.9/http/client.py", line 281, in _read_status', '    line = str(self.fp.readline(_MAXLINE + 1), "iso-8859-1")', '  File "/opt/homebrew/Cellar/python@3.9/3.9.12/Frameworks/Python.framework/Versions/3.9/lib/python3.9/socket.py", line 704, in readinto', '    return self._sock.recv_into(b)', 'KeyboardInterrupt']
root - INFO - 2023-01-12 11:55:57.693477 - Finvant Alcubierre Mk1 OMS Backend turned on.
root - INFO - 2023-01-12 11:55:57.796708 - OMS Backend mainloop started.
root - INFO - 2023-01-12 11:55:59.817798 - OMSB: Logging in for backend kite ticker.
root - INFO - 2023-01-12 11:56:13.450185 - OMSB: Login succesful for backend kite ticker.
root - INFO - 2023-01-12 11:56:13.832600 - OMSB: Zerodha login for WG5235.
root - INFO - 2023-01-12 11:56:26.437019 - OMSB: Zerodha login succesful for WG5235.
root - INFO - 2023-01-12 11:56:26.547836 - Placed Zerodha Kite futures order for:FINVANT, instrument:NIFTY23JANFUT, qty:1, transaction type:BUY, placed price:17125, id:10.
root - INFO - 2023-01-12 11:56:33.000385 - Placed Zerodha Kite futures order for:FINVANT, instrument:NIFTY23JANFUT, qty:1, transaction type:BUY, placed price:17760, id:11.
root - CRITICAL - CRITICAL ERROR:2023-01-12 12:02:53.095059 - Failed to initialise Log server/ADS.
['Traceback (most recent call last):', '  File "/Users/aditya/Documents/Projects/Mothership/Backend/Scripts/Main.py", line 28, in __init__', '    self.start()', '  File "/Users/aditya/Documents/Projects/Mothership/Backend/Scripts/Main.py", line 36, in start', '    self.main_loop()', '  File "/Users/aditya/Documents/Projects/Mothership/Backend/Scripts/Main.py", line 76, in main_loop', '    sleep(1)', 'KeyboardInterrupt']
root - INFO - 2023-01-12 12:02:56.538710 - Finvant Alcubierre Mk1 OMS Backend turned on.
root - INFO - 2023-01-12 12:02:56.653289 - OMS Backend mainloop started.
root - INFO - 2023-01-12 12:02:58.694797 - OMSB: Logging in for backend kite ticker.
root - INFO - 2023-01-12 12:03:13.176744 - OMSB: Login succesful for backend kite ticker.
root - INFO - 2023-01-12 12:03:13.284734 - OMSB: Zerodha login for WG5235.
root - INFO - 2023-01-12 12:03:27.623635 - OMSB: Zerodha login succesful for WG5235.
root - CRITICAL - CRITICAL ERROR:2023-01-12 12:03:27.880855 - Failed to place Zerodha Kite futures order. User: FINVANT. Tradingsymbol:NIFTY23JANFUT.
['Traceback (most recent call last):', '  File "/Users/aditya/Documents/Projects/Mothership/Backend/Scripts/OrderPlacement.py", line 51, in placeOrder', '    for order in orders:', "UnboundLocalError: local variable 'orders' referenced before assignment"]
root - CRITICAL - CRITICAL ERROR:2023-01-12 12:03:34.095735 - Failed to place Zerodha Kite futures order. User: FINVANT. Tradingsymbol:NIFTY23JANFUT.
['Traceback (most recent call last):', '  File "/Users/aditya/Documents/Projects/Mothership/Backend/Scripts/OrderPlacement.py", line 51, in placeOrder', '    for order in orders:', "UnboundLocalError: local variable 'orders' referenced before assignment"]
root - CRITICAL - CRITICAL ERROR:2023-01-12 12:04:48.624005 - Failed to place Zerodha Kite futures order. User: FINVANT. Tradingsymbol:NIFTY23JANFUT.
['Traceback (most recent call last):', '  File "/Users/aditya/Documents/Projects/Mothership/Backend/Scripts/OrderPlacement.py", line 51, in placeOrder', "    if order['status'] == 'COMPLETE':", "UnboundLocalError: local variable 'orders' referenced before assignment"]
root - CRITICAL - CRITICAL ERROR:2023-01-12 12:04:55.116555 - Failed to place Zerodha Kite futures order. User: FINVANT. Tradingsymbol:NIFTY23JANFUT.
['Traceback (most recent call last):', '  File "/Users/aditya/Documents/Projects/Mothership/Backend/Scripts/OrderPlacement.py", line 51, in placeOrder', "    if order['status'] == 'COMPLETE':", "UnboundLocalError: local variable 'orders' referenced before assignment"]
root - CRITICAL - CRITICAL ERROR:2023-01-12 12:05:03.224776 - Failed to initialise Log server/ADS.
['Traceback (most recent call last):', '  File "/Users/aditya/Documents/Projects/Mothership/Backend/Scripts/Main.py", line 28, in __init__', '    self.start()', '  File "/Users/aditya/Documents/Projects/Mothership/Backend/Scripts/Main.py", line 36, in start', '    self.main_loop()', '  File "/Users/aditya/Documents/Projects/Mothership/Backend/Scripts/Main.py", line 76, in main_loop', '    sleep(1)', 'KeyboardInterrupt']
root - INFO - 2023-01-12 12:05:07.175817 - Finvant Alcubierre Mk1 OMS Backend turned on.
root - INFO - 2023-01-12 12:05:07.277930 - OMS Backend mainloop started.
root - INFO - 2023-01-12 12:05:09.276404 - OMSB: Logging in for backend kite ticker.
root - INFO - 2023-01-12 12:05:23.404835 - OMSB: Login succesful for backend kite ticker.
root - INFO - 2023-01-12 12:05:23.514159 - OMSB: Zerodha login for WG5235.
root - INFO - 2023-01-12 12:05:36.517550 - OMSB: Zerodha login succesful for WG5235.
root - INFO - 2023-01-12 12:05:49.904816 - Placed Zerodha Kite futures order for:FINVANT, instrument:NIFTY23JANFUT, qty:1, transaction type:BUY, placed price:17863.55, id:230112601215161.
root - INFO - 2023-01-12 12:05:57.270400 - Placed Zerodha Kite futures order for:FINVANT, instrument:NIFTY23JANFUT, qty:1, transaction type:BUY, placed price:17863.95, id:230112601215689.
root - INFO - 2023-01-12 12:07:16.276733 - Placed Zerodha Kite futures order for:FINVANT, instrument:NIFTY23JANFUT, qty:-1, transaction type:SELL, placed price:17867.5, id:230112601219980.
root - INFO - 2023-01-12 12:07:23.210811 - Placed Zerodha Kite futures order for:FINVANT, instrument:NIFTY23JANFUT, qty:-1, transaction type:SELL, placed price:17867.45, id:230112601220343.
root - INFO - 2023-01-12 13:34:28.370521 - Finvant Alcubierre Mk1 OMS Backend turned on.
root - INFO - 2023-01-12 13:34:28.523359 - OMS Backend mainloop started.
root - INFO - 2023-01-12 13:34:30.625499 - OMSB: Logging in for backend kite ticker.
root - INFO - 2023-01-12 13:34:42.374508 - OMSB: Login succesful for backend kite ticker.
root - INFO - 2023-01-12 13:34:42.509938 - OMSB: Zerodha login for WG5235.
root - INFO - 2023-01-12 13:34:51.612115 - OMSB: Zerodha login succesful for WG5235.
root - CRITICAL - CRITICAL ERROR:2023-01-12 13:34:51.750668 - Failed to clear pending orders.
['Traceback (most recent call last):', '  File "/Users/vishaljha/Desktop/FINVANT/API/Backend/Scripts/OrderHandler.py", line 36, in thread_function', '    self.place_pending_orders(username, spread_list= self.spread_list)', '  File "/Users/vishaljha/Desktop/FINVANT/API/Backend/Scripts/OrderHandler.py", line 46, in place_pending_orders', '    pending_orders = DBManager.get_pending_orders(username)', '  File "/Users/vishaljha/Desktop/FINVANT/API/Backend/Scripts/DBManager.py", line 61, in get_pending_orders', '    db_connection = get_new_dbconnection()', '  File "/Users/vishaljha/Desktop/FINVANT/API/Backend/Scripts/DBManager.py", line 11, in get_new_dbconnection', "    con = sqlite3.connect('../../OMS_Server/Data/OrderData.db')", 'sqlite3.OperationalError: unable to open database file']
root - CRITICAL - CRITICAL ERROR:2023-01-12 13:34:51.882686 - Failed to clear pending orders.
['Traceback (most recent call last):', '  File "/Users/vishaljha/Desktop/FINVANT/API/Backend/Scripts/OrderHandler.py", line 36, in thread_function', '    self.place_pending_orders(username, spread_list= self.spread_list)', '  File "/Users/vishaljha/Desktop/FINVANT/API/Backend/Scripts/OrderHandler.py", line 46, in place_pending_orders', '    pending_orders = DBManager.get_pending_orders(username)', '  File "/Users/vishaljha/Desktop/FINVANT/API/Backend/Scripts/DBManager.py", line 61, in get_pending_orders', '    db_connection = get_new_dbconnection()', '  File "/Users/vishaljha/Desktop/FINVANT/API/Backend/Scripts/DBManager.py", line 11, in get_new_dbconnection', "    con = sqlite3.connect('../../OMS_Server/Data/OrderData.db')", 'sqlite3.OperationalError: unable to open database file']
root - CRITICAL - CRITICAL ERROR:2023-01-12 13:34:52.040715 - Failed to clear pending orders.
['Traceback (most recent call last):', '  File "/Users/vishaljha/Desktop/FINVANT/API/Backend/Scripts/OrderHandler.py", line 36, in thread_function', '    self.place_pending_orders(username, spread_list= self.spread_list)', '  File "/Users/vishaljha/Desktop/FINVANT/API/Backend/Scripts/OrderHandler.py", line 46, in place_pending_orders', '    pending_orders = DBManager.get_pending_orders(username)', '  File "/Users/vishaljha/Desktop/FINVANT/API/Backend/Scripts/DBManager.py", line 61, in get_pending_orders', '    db_connection = get_new_dbconnection()', '  File "/Users/vishaljha/Desktop/FINVANT/API/Backend/Scripts/DBManager.py", line 11, in get_new_dbconnection', "    con = sqlite3.connect('../../OMS_Server/Data/OrderData.db')", 'sqlite3.OperationalError: unable to open database file']
root - CRITICAL - CRITICAL ERROR:2023-01-12 13:34:52.173035 - Failed to clear pending orders.
['Traceback (most recent call last):', '  File "/Users/vishaljha/Desktop/FINVANT/API/Backend/Scripts/OrderHandler.py", line 36, in thread_function', '    self.place_pending_orders(username, spread_list= self.spread_list)', '  File "/Users/vishaljha/Desktop/FINVANT/API/Backend/Scripts/OrderHandler.py", line 46, in place_pending_orders', '    pending_orders = DBManager.get_pending_orders(username)', '  File "/Users/vishaljha/Desktop/FINVANT/API/Backend/Scripts/DBManager.py", line 61, in get_pending_orders', '    db_connection = get_new_dbconnection()', '  File "/Users/vishaljha/Desktop/FINVANT/API/Backend/Scripts/DBManager.py", line 11, in get_new_dbconnection', "    con = sqlite3.connect('../../OMS_Server/Data/OrderData.db')", 'sqlite3.OperationalError: unable to open database file']
root - CRITICAL - CRITICAL ERROR:2023-01-12 13:34:52.319202 - Failed to clear pending orders.
['Traceback (most recent call last):', '  File "/Users/vishaljha/Desktop/FINVANT/API/Backend/Scripts/OrderHandler.py", line 36, in thread_function', '    self.place_pending_orders(username, spread_list= self.spread_list)', '  File "/Users/vishaljha/Desktop/FINVANT/API/Backend/Scripts/OrderHandler.py", line 46, in place_pending_orders', '    pending_orders = DBManager.get_pending_orders(username)', '  File "/Users/vishaljha/Desktop/FINVANT/API/Backend/Scripts/DBManager.py", line 61, in get_pending_orders', '    db_connection = get_new_dbconnection()', '  File "/Users/vishaljha/Desktop/FINVANT/API/Backend/Scripts/DBManager.py", line 11, in get_new_dbconnection', "    con = sqlite3.connect('../../OMS_Server/Data/OrderData.db')", 'sqlite3.OperationalError: unable to open database file']
root - CRITICAL - CRITICAL ERROR:2023-01-12 13:34:52.477980 - Failed to clear pending orders.
['Traceback (most recent call last):', '  File "/Users/vishaljha/Desktop/FINVANT/API/Backend/Scripts/OrderHandler.py", line 36, in thread_function', '    self.place_pending_orders(username, spread_list= self.spread_list)', '  File "/Users/vishaljha/Desktop/FINVANT/API/Backend/Scripts/OrderHandler.py", line 46, in place_pending_orders', '    pending_orders = DBManager.get_pending_orders(username)', '  File "/Users/vishaljha/Desktop/FINVANT/API/Backend/Scripts/DBManager.py", line 61, in get_pending_orders', '    db_connection = get_new_dbconnection()', '  File "/Users/vishaljha/Desktop/FINVANT/API/Backend/Scripts/DBManager.py", line 11, in get_new_dbconnection', "    con = sqlite3.connect('../../OMS_Server/Data/OrderData.db')", 'sqlite3.OperationalError: unable to open database file']
root - CRITICAL - CRITICAL ERROR:2023-01-12 13:34:52.648454 - Failed to clear pending orders.
['Traceback (most recent call last):', '  File "/Users/vishaljha/Desktop/FINVANT/API/Backend/Scripts/OrderHandler.py", line 36, in thread_function', '    self.place_pending_orders(username, spread_list= self.spread_list)', '  File "/Users/vishaljha/Desktop/FINVANT/API/Backend/Scripts/OrderHandler.py", line 46, in place_pending_orders', '    pending_orders = DBManager.get_pending_orders(username)', '  File "/Users/vishaljha/Desktop/FINVANT/API/Backend/Scripts/DBManager.py", line 61, in get_pending_orders', '    db_connection = get_new_dbconnection()', '  File "/Users/vishaljha/Desktop/FINVANT/API/Backend/Scripts/DBManager.py", line 11, in get_new_dbconnection', "    con = sqlite3.connect('../../OMS_Server/Data/OrderData.db')", 'sqlite3.OperationalError: unable to open database file']
root - CRITICAL - CRITICAL ERROR:2023-01-12 13:34:52.813635 - Failed to clear pending orders.
['Traceback (most recent call last):', '  File "/Users/vishaljha/Desktop/FINVANT/API/Backend/Scripts/OrderHandler.py", line 36, in thread_function', '    self.place_pending_orders(username, spread_list= self.spread_list)', '  File "/Users/vishaljha/Desktop/FINVANT/API/Backend/Scripts/OrderHandler.py", line 46, in place_pending_orders', '    pending_orders = DBManager.get_pending_orders(username)', '  File "/Users/vishaljha/Desktop/FINVANT/API/Backend/Scripts/DBManager.py", line 61, in get_pending_orders', '    db_connection = get_new_dbconnection()', '  File "/Users/vishaljha/Desktop/FINVANT/API/Backend/Scripts/DBManager.py", line 11, in get_new_dbconnection', "    con = sqlite3.connect('../../OMS_Server/Data/OrderData.db')", 'sqlite3.OperationalError: unable to open database file']
root - CRITICAL - CRITICAL ERROR:2023-01-12 13:34:52.963017 - Failed to clear pending orders.
['Traceback (most recent call last):', '  File "/Users/vishaljha/Desktop/FINVANT/API/Backend/Scripts/OrderHandler.py", line 36, in thread_function', '    self.place_pending_orders(username, spread_list= self.spread_list)', '  File "/Users/vishaljha/Desktop/FINVANT/API/Backend/Scripts/OrderHandler.py", line 46, in place_pending_orders', '    pending_orders = DBManager.get_pending_orders(username)', '  File "/Users/vishaljha/Desktop/FINVANT/API/Backend/Scripts/DBManager.py", line 61, in get_pending_orders', '    db_connection = get_new_dbconnection()', '  File "/Users/vishaljha/Desktop/FINVANT/API/Backend/Scripts/DBManager.py", line 11, in get_new_dbconnection', "    con = sqlite3.connect('../../OMS_Server/Data/OrderData.db')", 'sqlite3.OperationalError: unable to open database file']
root - CRITICAL - CRITICAL ERROR:2023-01-12 13:34:53.095644 - Failed to clear pending orders.
['Traceback (most recent call last):', '  File "/Users/vishaljha/Desktop/FINVANT/API/Backend/Scripts/OrderHandler.py", line 36, in thread_function', '    self.place_pending_orders(username, spread_list= self.spread_list)', '  File "/Users/vishaljha/Desktop/FINVANT/API/Backend/Scripts/OrderHandler.py", line 46, in place_pending_orders', '    pending_orders = DBManager.get_pending_orders(username)', '  File "/Users/vishaljha/Desktop/FINVANT/API/Backend/Scripts/DBManager.py", line 61, in get_pending_orders', '    db_connection = get_new_dbconnection()', '  File "/Users/vishaljha/Desktop/FINVANT/API/Backend/Scripts/DBManager.py", line 11, in get_new_dbconnection', "    con = sqlite3.connect('../../OMS_Server/Data/OrderData.db')", 'sqlite3.OperationalError: unable to open database file']
root - CRITICAL - CRITICAL ERROR:2023-01-12 13:34:53.231008 - Failed to clear pending orders.
['Traceback (most recent call last):', '  File "/Users/vishaljha/Desktop/FINVANT/API/Backend/Scripts/OrderHandler.py", line 36, in thread_function', '    self.place_pending_orders(username, spread_list= self.spread_list)', '  File "/Users/vishaljha/Desktop/FINVANT/API/Backend/Scripts/OrderHandler.py", line 46, in place_pending_orders', '    pending_orders = DBManager.get_pending_orders(username)', '  File "/Users/vishaljha/Desktop/FINVANT/API/Backend/Scripts/DBManager.py", line 61, in get_pending_orders', '    db_connection = get_new_dbconnection()', '  File "/Users/vishaljha/Desktop/FINVANT/API/Backend/Scripts/DBManager.py", line 11, in get_new_dbconnection', "    con = sqlite3.connect('../../OMS_Server/Data/OrderData.db')", 'sqlite3.OperationalError: unable to open database file']
root - CRITICAL - CRITICAL ERROR:2023-01-12 13:34:53.377042 - Failed to clear pending orders.
['Traceback (most recent call last):', '  File "/Users/vishaljha/Desktop/FINVANT/API/Backend/Scripts/OrderHandler.py", line 36, in thread_function', '    self.place_pending_orders(username, spread_list= self.spread_list)', '  File "/Users/vishaljha/Desktop/FINVANT/API/Backend/Scripts/OrderHandler.py", line 46, in place_pending_orders', '    pending_orders = DBManager.get_pending_orders(username)', '  File "/Users/vishaljha/Desktop/FINVANT/API/Backend/Scripts/DBManager.py", line 61, in get_pending_orders', '    db_connection = get_new_dbconnection()', '  File "/Users/vishaljha/Desktop/FINVANT/API/Backend/Scripts/DBManager.py", line 11, in get_new_dbconnection', "    con = sqlite3.connect('../../OMS_Server/Data/OrderData.db')", 'sqlite3.OperationalError: unable to open database file']
root - CRITICAL - CRITICAL ERROR:2023-01-12 13:34:53.528876 - Failed to clear pending orders.
['Traceback (most recent call last):', '  File "/Users/vishaljha/Desktop/FINVANT/API/Backend/Scripts/OrderHandler.py", line 36, in thread_function', '    self.place_pending_orders(username, spread_list= self.spread_list)', '  File "/Users/vishaljha/Desktop/FINVANT/API/Backend/Scripts/OrderHandler.py", line 46, in place_pending_orders', '    pending_orders = DBManager.get_pending_orders(username)', '  File "/Users/vishaljha/Desktop/FINVANT/API/Backend/Scripts/DBManager.py", line 61, in get_pending_orders', '    db_connection = get_new_dbconnection()', '  File "/Users/vishaljha/Desktop/FINVANT/API/Backend/Scripts/DBManager.py", line 11, in get_new_dbconnection', "    con = sqlite3.connect('../../OMS_Server/Data/OrderData.db')", 'sqlite3.OperationalError: unable to open database file']
root - CRITICAL - CRITICAL ERROR:2023-01-12 13:34:53.701902 - Failed to clear pending orders.
['Traceback (most recent call last):', '  File "/Users/vishaljha/Desktop/FINVANT/API/Backend/Scripts/OrderHandler.py", line 36, in thread_function', '    self.place_pending_orders(username, spread_list= self.spread_list)', '  File "/Users/vishaljha/Desktop/FINVANT/API/Backend/Scripts/OrderHandler.py", line 46, in place_pending_orders', '    pending_orders = DBManager.get_pending_orders(username)', '  File "/Users/vishaljha/Desktop/FINVANT/API/Backend/Scripts/DBManager.py", line 61, in get_pending_orders', '    db_connection = get_new_dbconnection()', '  File "/Users/vishaljha/Desktop/FINVANT/API/Backend/Scripts/DBManager.py", line 11, in get_new_dbconnection', "    con = sqlite3.connect('../../OMS_Server/Data/OrderData.db')", 'sqlite3.OperationalError: unable to open database file']
root - CRITICAL - CRITICAL ERROR:2023-01-12 13:34:53.869948 - Failed to clear pending orders.
['Traceback (most recent call last):', '  File "/Users/vishaljha/Desktop/FINVANT/API/Backend/Scripts/OrderHandler.py", line 36, in thread_function', '    self.place_pending_orders(username, spread_list= self.spread_list)', '  File "/Users/vishaljha/Desktop/FINVANT/API/Backend/Scripts/OrderHandler.py", line 46, in place_pending_orders', '    pending_orders = DBManager.get_pending_orders(username)', '  File "/Users/vishaljha/Desktop/FINVANT/API/Backend/Scripts/DBManager.py", line 61, in get_pending_orders', '    db_connection = get_new_dbconnection()', '  File "/Users/vishaljha/Desktop/FINVANT/API/Backend/Scripts/DBManager.py", line 11, in get_new_dbconnection', "    con = sqlite3.connect('../../OMS_Server/Data/OrderData.db')", 'sqlite3.OperationalError: unable to open database file']
root - CRITICAL - CRITICAL ERROR:2023-01-12 13:34:54.057916 - Failed to clear pending orders.
['Traceback (most recent call last):', '  File "/Users/vishaljha/Desktop/FINVANT/API/Backend/Scripts/OrderHandler.py", line 36, in thread_function', '    self.place_pending_orders(username, spread_list= self.spread_list)', '  File "/Users/vishaljha/Desktop/FINVANT/API/Backend/Scripts/OrderHandler.py", line 46, in place_pending_orders', '    pending_orders = DBManager.get_pending_orders(username)', '  File "/Users/vishaljha/Desktop/FINVANT/API/Backend/Scripts/DBManager.py", line 61, in get_pending_orders', '    db_connection = get_new_dbconnection()', '  File "/Users/vishaljha/Desktop/FINVANT/API/Backend/Scripts/DBManager.py", line 11, in get_new_dbconnection', "    con = sqlite3.connect('../../OMS_Server/Data/OrderData.db')", 'sqlite3.OperationalError: unable to open database file']
root - CRITICAL - CRITICAL ERROR:2023-01-12 13:34:54.231675 - Failed to clear pending orders.
['Traceback (most recent call last):', '  File "/Users/vishaljha/Desktop/FINVANT/API/Backend/Scripts/OrderHandler.py", line 36, in thread_function', '    self.place_pending_orders(username, spread_list= self.spread_list)', '  File "/Users/vishaljha/Desktop/FINVANT/API/Backend/Scripts/OrderHandler.py", line 46, in place_pending_orders', '    pending_orders = DBManager.get_pending_orders(username)', '  File "/Users/vishaljha/Desktop/FINVANT/API/Backend/Scripts/DBManager.py", line 61, in get_pending_orders', '    db_connection = get_new_dbconnection()', '  File "/Users/vishaljha/Desktop/FINVANT/API/Backend/Scripts/DBManager.py", line 11, in get_new_dbconnection', "    con = sqlite3.connect('../../OMS_Server/Data/OrderData.db')", 'sqlite3.OperationalError: unable to open database file']
root - CRITICAL - CRITICAL ERROR:2023-01-12 13:34:54.416686 - Failed to clear pending orders.
['Traceback (most recent call last):', '  File "/Users/vishaljha/Desktop/FINVANT/API/Backend/Scripts/OrderHandler.py", line 36, in thread_function', '    self.place_pending_orders(username, spread_list= self.spread_list)', '  File "/Users/vishaljha/Desktop/FINVANT/API/Backend/Scripts/OrderHandler.py", line 46, in place_pending_orders', '    pending_orders = DBManager.get_pending_orders(username)', '  File "/Users/vishaljha/Desktop/FINVANT/API/Backend/Scripts/DBManager.py", line 61, in get_pending_orders', '    db_connection = get_new_dbconnection()', '  File "/Users/vishaljha/Desktop/FINVANT/API/Backend/Scripts/DBManager.py", line 11, in get_new_dbconnection', "    con = sqlite3.connect('../../OMS_Server/Data/OrderData.db')", 'sqlite3.OperationalError: unable to open database file']
root - CRITICAL - CRITICAL ERROR:2023-01-12 13:34:54.578654 - Failed to clear pending orders.
['Traceback (most recent call last):', '  File "/Users/vishaljha/Desktop/FINVANT/API/Backend/Scripts/OrderHandler.py", line 36, in thread_function', '    self.place_pending_orders(username, spread_list= self.spread_list)', '  File "/Users/vishaljha/Desktop/FINVANT/API/Backend/Scripts/OrderHandler.py", line 46, in place_pending_orders', '    pending_orders = DBManager.get_pending_orders(username)', '  File "/Users/vishaljha/Desktop/FINVANT/API/Backend/Scripts/DBManager.py", line 61, in get_pending_orders', '    db_connection = get_new_dbconnection()', '  File "/Users/vishaljha/Desktop/FINVANT/API/Backend/Scripts/DBManager.py", line 11, in get_new_dbconnection', "    con = sqlite3.connect('../../OMS_Server/Data/OrderData.db')", 'sqlite3.OperationalError: unable to open database file']
root - CRITICAL - CRITICAL ERROR:2023-01-12 13:34:54.732933 - Failed to clear pending orders.
['Traceback (most recent call last):', '  File "/Users/vishaljha/Desktop/FINVANT/API/Backend/Scripts/OrderHandler.py", line 36, in thread_function', '    self.place_pending_orders(username, spread_list= self.spread_list)', '  File "/Users/vishaljha/Desktop/FINVANT/API/Backend/Scripts/OrderHandler.py", line 46, in place_pending_orders', '    pending_orders = DBManager.get_pending_orders(username)', '  File "/Users/vishaljha/Desktop/FINVANT/API/Backend/Scripts/DBManager.py", line 61, in get_pending_orders', '    db_connection = get_new_dbconnection()', '  File "/Users/vishaljha/Desktop/FINVANT/API/Backend/Scripts/DBManager.py", line 11, in get_new_dbconnection', "    con = sqlite3.connect('../../OMS_Server/Data/OrderData.db')", 'sqlite3.OperationalError: unable to open database file']
root - CRITICAL - CRITICAL ERROR:2023-01-12 13:34:54.866515 - Failed to clear pending orders.
['Traceback (most recent call last):', '  File "/Users/vishaljha/Desktop/FINVANT/API/Backend/Scripts/OrderHandler.py", line 36, in thread_function', '    self.place_pending_orders(username, spread_list= self.spread_list)', '  File "/Users/vishaljha/Desktop/FINVANT/API/Backend/Scripts/OrderHandler.py", line 46, in place_pending_orders', '    pending_orders = DBManager.get_pending_orders(username)', '  File "/Users/vishaljha/Desktop/FINVANT/API/Backend/Scripts/DBManager.py", line 61, in get_pending_orders', '    db_connection = get_new_dbconnection()', '  File "/Users/vishaljha/Desktop/FINVANT/API/Backend/Scripts/DBManager.py", line 11, in get_new_dbconnection', "    con = sqlite3.connect('../../OMS_Server/Data/OrderData.db')", 'sqlite3.OperationalError: unable to open database file']
root - CRITICAL - CRITICAL ERROR:2023-01-12 13:34:55.037365 - Failed to clear pending orders.
['Traceback (most recent call last):', '  File "/Users/vishaljha/Desktop/FINVANT/API/Backend/Scripts/OrderHandler.py", line 36, in thread_function', '    self.place_pending_orders(username, spread_list= self.spread_list)', '  File "/Users/vishaljha/Desktop/FINVANT/API/Backend/Scripts/OrderHandler.py", line 46, in place_pending_orders', '    pending_orders = DBManager.get_pending_orders(username)', '  File "/Users/vishaljha/Desktop/FINVANT/API/Backend/Scripts/DBManager.py", line 61, in get_pending_orders', '    db_connection = get_new_dbconnection()', '  File "/Users/vishaljha/Desktop/FINVANT/API/Backend/Scripts/DBManager.py", line 11, in get_new_dbconnection', "    con = sqlite3.connect('../../OMS_Server/Data/OrderData.db')", 'sqlite3.OperationalError: unable to open database file']
root - CRITICAL - CRITICAL ERROR:2023-01-12 13:34:55.168357 - Failed to clear pending orders.
['Traceback (most recent call last):', '  File "/Users/vishaljha/Desktop/FINVANT/API/Backend/Scripts/OrderHandler.py", line 36, in thread_function', '    self.place_pending_orders(username, spread_list= self.spread_list)', '  File "/Users/vishaljha/Desktop/FINVANT/API/Backend/Scripts/OrderHandler.py", line 46, in place_pending_orders', '    pending_orders = DBManager.get_pending_orders(username)', '  File "/Users/vishaljha/Desktop/FINVANT/API/Backend/Scripts/DBManager.py", line 61, in get_pending_orders', '    db_connection = get_new_dbconnection()', '  File "/Users/vishaljha/Desktop/FINVANT/API/Backend/Scripts/DBManager.py", line 11, in get_new_dbconnection', "    con = sqlite3.connect('../../OMS_Server/Data/OrderData.db')", 'sqlite3.OperationalError: unable to open database file']
root - CRITICAL - CRITICAL ERROR:2023-01-12 13:34:55.304887 - Failed to clear pending orders.
['Traceback (most recent call last):', '  File "/Users/vishaljha/Desktop/FINVANT/API/Backend/Scripts/OrderHandler.py", line 36, in thread_function', '    self.place_pending_orders(username, spread_list= self.spread_list)', '  File "/Users/vishaljha/Desktop/FINVANT/API/Backend/Scripts/OrderHandler.py", line 46, in place_pending_orders', '    pending_orders = DBManager.get_pending_orders(username)', '  File "/Users/vishaljha/Desktop/FINVANT/API/Backend/Scripts/DBManager.py", line 61, in get_pending_orders', '    db_connection = get_new_dbconnection()', '  File "/Users/vishaljha/Desktop/FINVANT/API/Backend/Scripts/DBManager.py", line 11, in get_new_dbconnection', "    con = sqlite3.connect('../../OMS_Server/Data/OrderData.db')", 'sqlite3.OperationalError: unable to open database file']
root - CRITICAL - CRITICAL ERROR:2023-01-12 13:34:55.455230 - Failed to clear pending orders.
['Traceback (most recent call last):', '  File "/Users/vishaljha/Desktop/FINVANT/API/Backend/Scripts/OrderHandler.py", line 36, in thread_function', '    self.place_pending_orders(username, spread_list= self.spread_list)', '  File "/Users/vishaljha/Desktop/FINVANT/API/Backend/Scripts/OrderHandler.py", line 46, in place_pending_orders', '    pending_orders = DBManager.get_pending_orders(username)', '  File "/Users/vishaljha/Desktop/FINVANT/API/Backend/Scripts/DBManager.py", line 61, in get_pending_orders', '    db_connection = get_new_dbconnection()', '  File "/Users/vishaljha/Desktop/FINVANT/API/Backend/Scripts/DBManager.py", line 11, in get_new_dbconnection', "    con = sqlite3.connect('../../OMS_Server/Data/OrderData.db')", 'sqlite3.OperationalError: unable to open database file']
root - CRITICAL - CRITICAL ERROR:2023-01-12 13:34:55.611266 - Failed to clear pending orders.
['Traceback (most recent call last):', '  File "/Users/vishaljha/Desktop/FINVANT/API/Backend/Scripts/OrderHandler.py", line 36, in thread_function', '    self.place_pending_orders(username, spread_list= self.spread_list)', '  File "/Users/vishaljha/Desktop/FINVANT/API/Backend/Scripts/OrderHandler.py", line 46, in place_pending_orders', '    pending_orders = DBManager.get_pending_orders(username)', '  File "/Users/vishaljha/Desktop/FINVANT/API/Backend/Scripts/DBManager.py", line 61, in get_pending_orders', '    db_connection = get_new_dbconnection()', '  File "/Users/vishaljha/Desktop/FINVANT/API/Backend/Scripts/DBManager.py", line 11, in get_new_dbconnection', "    con = sqlite3.connect('../../OMS_Server/Data/OrderData.db')", 'sqlite3.OperationalError: unable to open database file']
root - CRITICAL - CRITICAL ERROR:2023-01-12 13:34:55.750633 - Failed to clear pending orders.
['Traceback (most recent call last):', '  File "/Users/vishaljha/Desktop/FINVANT/API/Backend/Scripts/OrderHandler.py", line 36, in thread_function', '    self.place_pending_orders(username, spread_list= self.spread_list)', '  File "/Users/vishaljha/Desktop/FINVANT/API/Backend/Scripts/OrderHandler.py", line 46, in place_pending_orders', '    pending_orders = DBManager.get_pending_orders(username)', '  File "/Users/vishaljha/Desktop/FINVANT/API/Backend/Scripts/DBManager.py", line 61, in get_pending_orders', '    db_connection = get_new_dbconnection()', '  File "/Users/vishaljha/Desktop/FINVANT/API/Backend/Scripts/DBManager.py", line 11, in get_new_dbconnection', "    con = sqlite3.connect('../../OMS_Server/Data/OrderData.db')", 'sqlite3.OperationalError: unable to open database file']
root - CRITICAL - CRITICAL ERROR:2023-01-12 13:34:55.928811 - Failed to clear pending orders.
['Traceback (most recent call last):', '  File "/Users/vishaljha/Desktop/FINVANT/API/Backend/Scripts/OrderHandler.py", line 36, in thread_function', '    self.place_pending_orders(username, spread_list= self.spread_list)', '  File "/Users/vishaljha/Desktop/FINVANT/API/Backend/Scripts/OrderHandler.py", line 46, in place_pending_orders', '    pending_orders = DBManager.get_pending_orders(username)', '  File "/Users/vishaljha/Desktop/FINVANT/API/Backend/Scripts/DBManager.py", line 61, in get_pending_orders', '    db_connection = get_new_dbconnection()', '  File "/Users/vishaljha/Desktop/FINVANT/API/Backend/Scripts/DBManager.py", line 11, in get_new_dbconnection', "    con = sqlite3.connect('../../OMS_Server/Data/OrderData.db')", 'sqlite3.OperationalError: unable to open database file']
root - CRITICAL - CRITICAL ERROR:2023-01-12 13:34:56.064609 - Failed to clear pending orders.
['Traceback (most recent call last):', '  File "/Users/vishaljha/Desktop/FINVANT/API/Backend/Scripts/OrderHandler.py", line 36, in thread_function', '    self.place_pending_orders(username, spread_list= self.spread_list)', '  File "/Users/vishaljha/Desktop/FINVANT/API/Backend/Scripts/OrderHandler.py", line 46, in place_pending_orders', '    pending_orders = DBManager.get_pending_orders(username)', '  File "/Users/vishaljha/Desktop/FINVANT/API/Backend/Scripts/DBManager.py", line 61, in get_pending_orders', '    db_connection = get_new_dbconnection()', '  File "/Users/vishaljha/Desktop/FINVANT/API/Backend/Scripts/DBManager.py", line 11, in get_new_dbconnection', "    con = sqlite3.connect('../../OMS_Server/Data/OrderData.db')", 'sqlite3.OperationalError: unable to open database file']
root - CRITICAL - CRITICAL ERROR:2023-01-12 13:34:56.215748 - Failed to clear pending orders.
['Traceback (most recent call last):', '  File "/Users/vishaljha/Desktop/FINVANT/API/Backend/Scripts/OrderHandler.py", line 36, in thread_function', '    self.place_pending_orders(username, spread_list= self.spread_list)', '  File "/Users/vishaljha/Desktop/FINVANT/API/Backend/Scripts/OrderHandler.py", line 46, in place_pending_orders', '    pending_orders = DBManager.get_pending_orders(username)', '  File "/Users/vishaljha/Desktop/FINVANT/API/Backend/Scripts/DBManager.py", line 61, in get_pending_orders', '    db_connection = get_new_dbconnection()', '  File "/Users/vishaljha/Desktop/FINVANT/API/Backend/Scripts/DBManager.py", line 11, in get_new_dbconnection', "    con = sqlite3.connect('../../OMS_Server/Data/OrderData.db')", 'sqlite3.OperationalError: unable to open database file']
root - CRITICAL - CRITICAL ERROR:2023-01-12 13:34:56.379076 - Failed to clear pending orders.
['Traceback (most recent call last):', '  File "/Users/vishaljha/Desktop/FINVANT/API/Backend/Scripts/OrderHandler.py", line 36, in thread_function', '    self.place_pending_orders(username, spread_list= self.spread_list)', '  File "/Users/vishaljha/Desktop/FINVANT/API/Backend/Scripts/OrderHandler.py", line 46, in place_pending_orders', '    pending_orders = DBManager.get_pending_orders(username)', '  File "/Users/vishaljha/Desktop/FINVANT/API/Backend/Scripts/DBManager.py", line 61, in get_pending_orders', '    db_connection = get_new_dbconnection()', '  File "/Users/vishaljha/Desktop/FINVANT/API/Backend/Scripts/DBManager.py", line 11, in get_new_dbconnection', "    con = sqlite3.connect('../../OMS_Server/Data/OrderData.db')", 'sqlite3.OperationalError: unable to open database file']
root - CRITICAL - CRITICAL ERROR:2023-01-12 13:34:56.543505 - Failed to clear pending orders.
['Traceback (most recent call last):', '  File "/Users/vishaljha/Desktop/FINVANT/API/Backend/Scripts/OrderHandler.py", line 36, in thread_function', '    self.place_pending_orders(username, spread_list= self.spread_list)', '  File "/Users/vishaljha/Desktop/FINVANT/API/Backend/Scripts/OrderHandler.py", line 46, in place_pending_orders', '    pending_orders = DBManager.get_pending_orders(username)', '  File "/Users/vishaljha/Desktop/FINVANT/API/Backend/Scripts/DBManager.py", line 61, in get_pending_orders', '    db_connection = get_new_dbconnection()', '  File "/Users/vishaljha/Desktop/FINVANT/API/Backend/Scripts/DBManager.py", line 11, in get_new_dbconnection', "    con = sqlite3.connect('../../OMS_Server/Data/OrderData.db')", 'sqlite3.OperationalError: unable to open database file']
root - CRITICAL - CRITICAL ERROR:2023-01-12 13:34:56.686366 - Failed to clear pending orders.
['Traceback (most recent call last):', '  File "/Users/vishaljha/Desktop/FINVANT/API/Backend/Scripts/OrderHandler.py", line 36, in thread_function', '    self.place_pending_orders(username, spread_list= self.spread_list)', '  File "/Users/vishaljha/Desktop/FINVANT/API/Backend/Scripts/OrderHandler.py", line 46, in place_pending_orders', '    pending_orders = DBManager.get_pending_orders(username)', '  File "/Users/vishaljha/Desktop/FINVANT/API/Backend/Scripts/DBManager.py", line 61, in get_pending_orders', '    db_connection = get_new_dbconnection()', '  File "/Users/vishaljha/Desktop/FINVANT/API/Backend/Scripts/DBManager.py", line 11, in get_new_dbconnection', "    con = sqlite3.connect('../../OMS_Server/Data/OrderData.db')", 'sqlite3.OperationalError: unable to open database file']
root - CRITICAL - CRITICAL ERROR:2023-01-12 13:34:56.917632 - Failed to clear pending orders.
['Traceback (most recent call last):', '  File "/Users/vishaljha/Desktop/FINVANT/API/Backend/Scripts/OrderHandler.py", line 36, in thread_function', '    self.place_pending_orders(username, spread_list= self.spread_list)', '  File "/Users/vishaljha/Desktop/FINVANT/API/Backend/Scripts/OrderHandler.py", line 46, in place_pending_orders', '    pending_orders = DBManager.get_pending_orders(username)', '  File "/Users/vishaljha/Desktop/FINVANT/API/Backend/Scripts/DBManager.py", line 61, in get_pending_orders', '    db_connection = get_new_dbconnection()', '  File "/Users/vishaljha/Desktop/FINVANT/API/Backend/Scripts/DBManager.py", line 11, in get_new_dbconnection', "    con = sqlite3.connect('../../OMS_Server/Data/OrderData.db')", 'sqlite3.OperationalError: unable to open database file']
root - CRITICAL - CRITICAL ERROR:2023-01-12 13:34:57.077815 - Failed to clear pending orders.
['Traceback (most recent call last):', '  File "/Users/vishaljha/Desktop/FINVANT/API/Backend/Scripts/OrderHandler.py", line 36, in thread_function', '    self.place_pending_orders(username, spread_list= self.spread_list)', '  File "/Users/vishaljha/Desktop/FINVANT/API/Backend/Scripts/OrderHandler.py", line 46, in place_pending_orders', '    pending_orders = DBManager.get_pending_orders(username)', '  File "/Users/vishaljha/Desktop/FINVANT/API/Backend/Scripts/DBManager.py", line 61, in get_pending_orders', '    db_connection = get_new_dbconnection()', '  File "/Users/vishaljha/Desktop/FINVANT/API/Backend/Scripts/DBManager.py", line 11, in get_new_dbconnection', "    con = sqlite3.connect('../../OMS_Server/Data/OrderData.db')", 'sqlite3.OperationalError: unable to open database file']
root - CRITICAL - CRITICAL ERROR:2023-01-12 13:34:57.227552 - Failed to clear pending orders.
['Traceback (most recent call last):', '  File "/Users/vishaljha/Desktop/FINVANT/API/Backend/Scripts/OrderHandler.py", line 36, in thread_function', '    self.place_pending_orders(username, spread_list= self.spread_list)', '  File "/Users/vishaljha/Desktop/FINVANT/API/Backend/Scripts/OrderHandler.py", line 46, in place_pending_orders', '    pending_orders = DBManager.get_pending_orders(username)', '  File "/Users/vishaljha/Desktop/FINVANT/API/Backend/Scripts/DBManager.py", line 61, in get_pending_orders', '    db_connection = get_new_dbconnection()', '  File "/Users/vishaljha/Desktop/FINVANT/API/Backend/Scripts/DBManager.py", line 11, in get_new_dbconnection', "    con = sqlite3.connect('../../OMS_Server/Data/OrderData.db')", 'sqlite3.OperationalError: unable to open database file']
root - CRITICAL - CRITICAL ERROR:2023-01-12 13:34:57.403829 - Failed to clear pending orders.
['Traceback (most recent call last):', '  File "/Users/vishaljha/Desktop/FINVANT/API/Backend/Scripts/OrderHandler.py", line 36, in thread_function', '    self.place_pending_orders(username, spread_list= self.spread_list)', '  File "/Users/vishaljha/Desktop/FINVANT/API/Backend/Scripts/OrderHandler.py", line 46, in place_pending_orders', '    pending_orders = DBManager.get_pending_orders(username)', '  File "/Users/vishaljha/Desktop/FINVANT/API/Backend/Scripts/DBManager.py", line 61, in get_pending_orders', '    db_connection = get_new_dbconnection()', '  File "/Users/vishaljha/Desktop/FINVANT/API/Backend/Scripts/DBManager.py", line 11, in get_new_dbconnection', "    con = sqlite3.connect('../../OMS_Server/Data/OrderData.db')", 'sqlite3.OperationalError: unable to open database file']
root - CRITICAL - CRITICAL ERROR:2023-01-12 13:34:57.605189 - Failed to clear pending orders.
['Traceback (most recent call last):', '  File "/Users/vishaljha/Desktop/FINVANT/API/Backend/Scripts/OrderHandler.py", line 36, in thread_function', '    self.place_pending_orders(username, spread_list= self.spread_list)', '  File "/Users/vishaljha/Desktop/FINVANT/API/Backend/Scripts/OrderHandler.py", line 46, in place_pending_orders', '    pending_orders = DBManager.get_pending_orders(username)', '  File "/Users/vishaljha/Desktop/FINVANT/API/Backend/Scripts/DBManager.py", line 61, in get_pending_orders', '    db_connection = get_new_dbconnection()', '  File "/Users/vishaljha/Desktop/FINVANT/API/Backend/Scripts/DBManager.py", line 11, in get_new_dbconnection', "    con = sqlite3.connect('../../OMS_Server/Data/OrderData.db')", 'sqlite3.OperationalError: unable to open database file']
root - CRITICAL - CRITICAL ERROR:2023-01-12 13:34:57.758902 - Failed to clear pending orders.
['Traceback (most recent call last):', '  File "/Users/vishaljha/Desktop/FINVANT/API/Backend/Scripts/OrderHandler.py", line 36, in thread_function', '    self.place_pending_orders(username, spread_list= self.spread_list)', '  File "/Users/vishaljha/Desktop/FINVANT/API/Backend/Scripts/OrderHandler.py", line 46, in place_pending_orders', '    pending_orders = DBManager.get_pending_orders(username)', '  File "/Users/vishaljha/Desktop/FINVANT/API/Backend/Scripts/DBManager.py", line 61, in get_pending_orders', '    db_connection = get_new_dbconnection()', '  File "/Users/vishaljha/Desktop/FINVANT/API/Backend/Scripts/DBManager.py", line 11, in get_new_dbconnection', "    con = sqlite3.connect('../../OMS_Server/Data/OrderData.db')", 'sqlite3.OperationalError: unable to open database file']
root - CRITICAL - CRITICAL ERROR:2023-01-12 13:34:57.911061 - Failed to clear pending orders.
['Traceback (most recent call last):', '  File "/Users/vishaljha/Desktop/FINVANT/API/Backend/Scripts/OrderHandler.py", line 36, in thread_function', '    self.place_pending_orders(username, spread_list= self.spread_list)', '  File "/Users/vishaljha/Desktop/FINVANT/API/Backend/Scripts/OrderHandler.py", line 46, in place_pending_orders', '    pending_orders = DBManager.get_pending_orders(username)', '  File "/Users/vishaljha/Desktop/FINVANT/API/Backend/Scripts/DBManager.py", line 61, in get_pending_orders', '    db_connection = get_new_dbconnection()', '  File "/Users/vishaljha/Desktop/FINVANT/API/Backend/Scripts/DBManager.py", line 11, in get_new_dbconnection', "    con = sqlite3.connect('../../OMS_Server/Data/OrderData.db')", 'sqlite3.OperationalError: unable to open database file']
root - CRITICAL - CRITICAL ERROR:2023-01-12 13:34:58.062468 - Failed to clear pending orders.
['Traceback (most recent call last):', '  File "/Users/vishaljha/Desktop/FINVANT/API/Backend/Scripts/OrderHandler.py", line 36, in thread_function', '    self.place_pending_orders(username, spread_list= self.spread_list)', '  File "/Users/vishaljha/Desktop/FINVANT/API/Backend/Scripts/OrderHandler.py", line 46, in place_pending_orders', '    pending_orders = DBManager.get_pending_orders(username)', '  File "/Users/vishaljha/Desktop/FINVANT/API/Backend/Scripts/DBManager.py", line 61, in get_pending_orders', '    db_connection = get_new_dbconnection()', '  File "/Users/vishaljha/Desktop/FINVANT/API/Backend/Scripts/DBManager.py", line 11, in get_new_dbconnection', "    con = sqlite3.connect('../../OMS_Server/Data/OrderData.db')", 'sqlite3.OperationalError: unable to open database file']
root - CRITICAL - CRITICAL ERROR:2023-01-12 13:34:58.223556 - Failed to clear pending orders.
['Traceback (most recent call last):', '  File "/Users/vishaljha/Desktop/FINVANT/API/Backend/Scripts/OrderHandler.py", line 36, in thread_function', '    self.place_pending_orders(username, spread_list= self.spread_list)', '  File "/Users/vishaljha/Desktop/FINVANT/API/Backend/Scripts/OrderHandler.py", line 46, in place_pending_orders', '    pending_orders = DBManager.get_pending_orders(username)', '  File "/Users/vishaljha/Desktop/FINVANT/API/Backend/Scripts/DBManager.py", line 61, in get_pending_orders', '    db_connection = get_new_dbconnection()', '  File "/Users/vishaljha/Desktop/FINVANT/API/Backend/Scripts/DBManager.py", line 11, in get_new_dbconnection', "    con = sqlite3.connect('../../OMS_Server/Data/OrderData.db')", 'sqlite3.OperationalError: unable to open database file']
root - CRITICAL - CRITICAL ERROR:2023-01-12 13:34:58.397837 - Failed to clear pending orders.
['Traceback (most recent call last):', '  File "/Users/vishaljha/Desktop/FINVANT/API/Backend/Scripts/OrderHandler.py", line 36, in thread_function', '    self.place_pending_orders(username, spread_list= self.spread_list)', '  File "/Users/vishaljha/Desktop/FINVANT/API/Backend/Scripts/OrderHandler.py", line 46, in place_pending_orders', '    pending_orders = DBManager.get_pending_orders(username)', '  File "/Users/vishaljha/Desktop/FINVANT/API/Backend/Scripts/DBManager.py", line 61, in get_pending_orders', '    db_connection = get_new_dbconnection()', '  File "/Users/vishaljha/Desktop/FINVANT/API/Backend/Scripts/DBManager.py", line 11, in get_new_dbconnection', "    con = sqlite3.connect('../../OMS_Server/Data/OrderData.db')", 'sqlite3.OperationalError: unable to open database file']
root - CRITICAL - CRITICAL ERROR:2023-01-12 13:34:58.553214 - Failed to clear pending orders.
['Traceback (most recent call last):', '  File "/Users/vishaljha/Desktop/FINVANT/API/Backend/Scripts/OrderHandler.py", line 36, in thread_function', '    self.place_pending_orders(username, spread_list= self.spread_list)', '  File "/Users/vishaljha/Desktop/FINVANT/API/Backend/Scripts/OrderHandler.py", line 46, in place_pending_orders', '    pending_orders = DBManager.get_pending_orders(username)', '  File "/Users/vishaljha/Desktop/FINVANT/API/Backend/Scripts/DBManager.py", line 61, in get_pending_orders', '    db_connection = get_new_dbconnection()', '  File "/Users/vishaljha/Desktop/FINVANT/API/Backend/Scripts/DBManager.py", line 11, in get_new_dbconnection', "    con = sqlite3.connect('../../OMS_Server/Data/OrderData.db')", 'sqlite3.OperationalError: unable to open database file']
root - CRITICAL - CRITICAL ERROR:2023-01-12 13:34:58.707388 - Failed to clear pending orders.
['Traceback (most recent call last):', '  File "/Users/vishaljha/Desktop/FINVANT/API/Backend/Scripts/OrderHandler.py", line 36, in thread_function', '    self.place_pending_orders(username, spread_list= self.spread_list)', '  File "/Users/vishaljha/Desktop/FINVANT/API/Backend/Scripts/OrderHandler.py", line 46, in place_pending_orders', '    pending_orders = DBManager.get_pending_orders(username)', '  File "/Users/vishaljha/Desktop/FINVANT/API/Backend/Scripts/DBManager.py", line 61, in get_pending_orders', '    db_connection = get_new_dbconnection()', '  File "/Users/vishaljha/Desktop/FINVANT/API/Backend/Scripts/DBManager.py", line 11, in get_new_dbconnection', "    con = sqlite3.connect('../../OMS_Server/Data/OrderData.db')", 'sqlite3.OperationalError: unable to open database file']
root - CRITICAL - CRITICAL ERROR:2023-01-12 13:34:58.878024 - Failed to clear pending orders.
['Traceback (most recent call last):', '  File "/Users/vishaljha/Desktop/FINVANT/API/Backend/Scripts/OrderHandler.py", line 36, in thread_function', '    self.place_pending_orders(username, spread_list= self.spread_list)', '  File "/Users/vishaljha/Desktop/FINVANT/API/Backend/Scripts/OrderHandler.py", line 46, in place_pending_orders', '    pending_orders = DBManager.get_pending_orders(username)', '  File "/Users/vishaljha/Desktop/FINVANT/API/Backend/Scripts/DBManager.py", line 61, in get_pending_orders', '    db_connection = get_new_dbconnection()', '  File "/Users/vishaljha/Desktop/FINVANT/API/Backend/Scripts/DBManager.py", line 11, in get_new_dbconnection', "    con = sqlite3.connect('../../OMS_Server/Data/OrderData.db')", 'sqlite3.OperationalError: unable to open database file']
root - CRITICAL - CRITICAL ERROR:2023-01-12 13:34:59.053561 - Failed to clear pending orders.
['Traceback (most recent call last):', '  File "/Users/vishaljha/Desktop/FINVANT/API/Backend/Scripts/OrderHandler.py", line 36, in thread_function', '    self.place_pending_orders(username, spread_list= self.spread_list)', '  File "/Users/vishaljha/Desktop/FINVANT/API/Backend/Scripts/OrderHandler.py", line 46, in place_pending_orders', '    pending_orders = DBManager.get_pending_orders(username)', '  File "/Users/vishaljha/Desktop/FINVANT/API/Backend/Scripts/DBManager.py", line 61, in get_pending_orders', '    db_connection = get_new_dbconnection()', '  File "/Users/vishaljha/Desktop/FINVANT/API/Backend/Scripts/DBManager.py", line 11, in get_new_dbconnection', "    con = sqlite3.connect('../../OMS_Server/Data/OrderData.db')", 'sqlite3.OperationalError: unable to open database file']
root - CRITICAL - CRITICAL ERROR:2023-01-12 13:34:59.240436 - Failed to clear pending orders.
['Traceback (most recent call last):', '  File "/Users/vishaljha/Desktop/FINVANT/API/Backend/Scripts/OrderHandler.py", line 36, in thread_function', '    self.place_pending_orders(username, spread_list= self.spread_list)', '  File "/Users/vishaljha/Desktop/FINVANT/API/Backend/Scripts/OrderHandler.py", line 46, in place_pending_orders', '    pending_orders = DBManager.get_pending_orders(username)', '  File "/Users/vishaljha/Desktop/FINVANT/API/Backend/Scripts/DBManager.py", line 61, in get_pending_orders', '    db_connection = get_new_dbconnection()', '  File "/Users/vishaljha/Desktop/FINVANT/API/Backend/Scripts/DBManager.py", line 11, in get_new_dbconnection', "    con = sqlite3.connect('../../OMS_Server/Data/OrderData.db')", 'sqlite3.OperationalError: unable to open database file']
root - CRITICAL - CRITICAL ERROR:2023-01-12 13:34:59.391429 - Failed to clear pending orders.
['Traceback (most recent call last):', '  File "/Users/vishaljha/Desktop/FINVANT/API/Backend/Scripts/OrderHandler.py", line 36, in thread_function', '    self.place_pending_orders(username, spread_list= self.spread_list)', '  File "/Users/vishaljha/Desktop/FINVANT/API/Backend/Scripts/OrderHandler.py", line 46, in place_pending_orders', '    pending_orders = DBManager.get_pending_orders(username)', '  File "/Users/vishaljha/Desktop/FINVANT/API/Backend/Scripts/DBManager.py", line 61, in get_pending_orders', '    db_connection = get_new_dbconnection()', '  File "/Users/vishaljha/Desktop/FINVANT/API/Backend/Scripts/DBManager.py", line 11, in get_new_dbconnection', "    con = sqlite3.connect('../../OMS_Server/Data/OrderData.db')", 'sqlite3.OperationalError: unable to open database file']
root - CRITICAL - CRITICAL ERROR:2023-01-12 13:34:59.467939 - Failed to initialise Log server/ADS.
['Traceback (most recent call last):', '  File "Main.py", line 28, in __init__', '    self.start()', '  File "Main.py", line 36, in start', '    self.main_loop()', '  File "Main.py", line 76, in main_loop', '    sleep(1)', 'KeyboardInterrupt']
root - CRITICAL - CRITICAL ERROR:2023-01-12 13:34:59.596069 - Failed to clear pending orders.
['Traceback (most recent call last):', '  File "/Users/vishaljha/Desktop/FINVANT/API/Backend/Scripts/OrderHandler.py", line 36, in thread_function', '    self.place_pending_orders(username, spread_list= self.spread_list)', '  File "/Users/vishaljha/Desktop/FINVANT/API/Backend/Scripts/OrderHandler.py", line 46, in place_pending_orders', '    pending_orders = DBManager.get_pending_orders(username)', '  File "/Users/vishaljha/Desktop/FINVANT/API/Backend/Scripts/DBManager.py", line 61, in get_pending_orders', '    db_connection = get_new_dbconnection()', '  File "/Users/vishaljha/Desktop/FINVANT/API/Backend/Scripts/DBManager.py", line 11, in get_new_dbconnection', "    con = sqlite3.connect('../../OMS_Server/Data/OrderData.db')", 'sqlite3.OperationalError: unable to open database file']
root - CRITICAL - CRITICAL ERROR:2023-01-12 13:34:59.815562 - Failed to clear pending orders.
['Traceback (most recent call last):', '  File "/Users/vishaljha/Desktop/FINVANT/API/Backend/Scripts/OrderHandler.py", line 36, in thread_function', '    self.place_pending_orders(username, spread_list= self.spread_list)', '  File "/Users/vishaljha/Desktop/FINVANT/API/Backend/Scripts/OrderHandler.py", line 46, in place_pending_orders', '    pending_orders = DBManager.get_pending_orders(username)', '  File "/Users/vishaljha/Desktop/FINVANT/API/Backend/Scripts/DBManager.py", line 61, in get_pending_orders', '    db_connection = get_new_dbconnection()', '  File "/Users/vishaljha/Desktop/FINVANT/API/Backend/Scripts/DBManager.py", line 11, in get_new_dbconnection', "    con = sqlite3.connect('../../OMS_Server/Data/OrderData.db')", 'sqlite3.OperationalError: unable to open database file']
root - CRITICAL - CRITICAL ERROR:2023-01-12 13:34:59.964911 - Failed to clear pending orders.
['Traceback (most recent call last):', '  File "/Users/vishaljha/Desktop/FINVANT/API/Backend/Scripts/OrderHandler.py", line 36, in thread_function', '    self.place_pending_orders(username, spread_list= self.spread_list)', '  File "/Users/vishaljha/Desktop/FINVANT/API/Backend/Scripts/OrderHandler.py", line 46, in place_pending_orders', '    pending_orders = DBManager.get_pending_orders(username)', '  File "/Users/vishaljha/Desktop/FINVANT/API/Backend/Scripts/DBManager.py", line 61, in get_pending_orders', '    db_connection = get_new_dbconnection()', '  File "/Users/vishaljha/Desktop/FINVANT/API/Backend/Scripts/DBManager.py", line 11, in get_new_dbconnection', "    con = sqlite3.connect('../../OMS_Server/Data/OrderData.db')", 'sqlite3.OperationalError: unable to open database file']
root - CRITICAL - CRITICAL ERROR:2023-01-12 13:35:00.095054 - Failed to clear pending orders.
['Traceback (most recent call last):', '  File "/Users/vishaljha/Desktop/FINVANT/API/Backend/Scripts/OrderHandler.py", line 36, in thread_function', '    self.place_pending_orders(username, spread_list= self.spread_list)', '  File "/Users/vishaljha/Desktop/FINVANT/API/Backend/Scripts/OrderHandler.py", line 46, in place_pending_orders', '    pending_orders = DBManager.get_pending_orders(username)', '  File "/Users/vishaljha/Desktop/FINVANT/API/Backend/Scripts/DBManager.py", line 61, in get_pending_orders', '    db_connection = get_new_dbconnection()', '  File "/Users/vishaljha/Desktop/FINVANT/API/Backend/Scripts/DBManager.py", line 11, in get_new_dbconnection', "    con = sqlite3.connect('../../OMS_Server/Data/OrderData.db')", 'sqlite3.OperationalError: unable to open database file']
root - CRITICAL - CRITICAL ERROR:2023-01-12 13:35:00.231307 - Failed to clear pending orders.
['Traceback (most recent call last):', '  File "/Users/vishaljha/Desktop/FINVANT/API/Backend/Scripts/OrderHandler.py", line 36, in thread_function', '    self.place_pending_orders(username, spread_list= self.spread_list)', '  File "/Users/vishaljha/Desktop/FINVANT/API/Backend/Scripts/OrderHandler.py", line 46, in place_pending_orders', '    pending_orders = DBManager.get_pending_orders(username)', '  File "/Users/vishaljha/Desktop/FINVANT/API/Backend/Scripts/DBManager.py", line 61, in get_pending_orders', '    db_connection = get_new_dbconnection()', '  File "/Users/vishaljha/Desktop/FINVANT/API/Backend/Scripts/DBManager.py", line 11, in get_new_dbconnection', "    con = sqlite3.connect('../../OMS_Server/Data/OrderData.db')", 'sqlite3.OperationalError: unable to open database file']
root - CRITICAL - CRITICAL ERROR:2023-01-12 13:35:00.369788 - Failed to clear pending orders.
['Traceback (most recent call last):', '  File "/Users/vishaljha/Desktop/FINVANT/API/Backend/Scripts/OrderHandler.py", line 36, in thread_function', '    self.place_pending_orders(username, spread_list= self.spread_list)', '  File "/Users/vishaljha/Desktop/FINVANT/API/Backend/Scripts/OrderHandler.py", line 46, in place_pending_orders', '    pending_orders = DBManager.get_pending_orders(username)', '  File "/Users/vishaljha/Desktop/FINVANT/API/Backend/Scripts/DBManager.py", line 61, in get_pending_orders', '    db_connection = get_new_dbconnection()', '  File "/Users/vishaljha/Desktop/FINVANT/API/Backend/Scripts/DBManager.py", line 11, in get_new_dbconnection', "    con = sqlite3.connect('../../OMS_Server/Data/OrderData.db')", 'sqlite3.OperationalError: unable to open database file']
root - CRITICAL - CRITICAL ERROR:2023-01-12 13:35:00.502028 - Failed to clear pending orders.
['Traceback (most recent call last):', '  File "/Users/vishaljha/Desktop/FINVANT/API/Backend/Scripts/OrderHandler.py", line 36, in thread_function', '    self.place_pending_orders(username, spread_list= self.spread_list)', '  File "/Users/vishaljha/Desktop/FINVANT/API/Backend/Scripts/OrderHandler.py", line 46, in place_pending_orders', '    pending_orders = DBManager.get_pending_orders(username)', '  File "/Users/vishaljha/Desktop/FINVANT/API/Backend/Scripts/DBManager.py", line 61, in get_pending_orders', '    db_connection = get_new_dbconnection()', '  File "/Users/vishaljha/Desktop/FINVANT/API/Backend/Scripts/DBManager.py", line 11, in get_new_dbconnection', "    con = sqlite3.connect('../../OMS_Server/Data/OrderData.db')", 'sqlite3.OperationalError: unable to open database file']
root - CRITICAL - CRITICAL ERROR:2023-01-12 13:35:00.644366 - Failed to clear pending orders.
['Traceback (most recent call last):', '  File "/Users/vishaljha/Desktop/FINVANT/API/Backend/Scripts/OrderHandler.py", line 36, in thread_function', '    self.place_pending_orders(username, spread_list= self.spread_list)', '  File "/Users/vishaljha/Desktop/FINVANT/API/Backend/Scripts/OrderHandler.py", line 46, in place_pending_orders', '    pending_orders = DBManager.get_pending_orders(username)', '  File "/Users/vishaljha/Desktop/FINVANT/API/Backend/Scripts/DBManager.py", line 61, in get_pending_orders', '    db_connection = get_new_dbconnection()', '  File "/Users/vishaljha/Desktop/FINVANT/API/Backend/Scripts/DBManager.py", line 11, in get_new_dbconnection', "    con = sqlite3.connect('../../OMS_Server/Data/OrderData.db')", 'sqlite3.OperationalError: unable to open database file']
root - CRITICAL - CRITICAL ERROR:2023-01-12 13:35:00.782216 - Failed to clear pending orders.
['Traceback (most recent call last):', '  File "/Users/vishaljha/Desktop/FINVANT/API/Backend/Scripts/OrderHandler.py", line 36, in thread_function', '    self.place_pending_orders(username, spread_list= self.spread_list)', '  File "/Users/vishaljha/Desktop/FINVANT/API/Backend/Scripts/OrderHandler.py", line 46, in place_pending_orders', '    pending_orders = DBManager.get_pending_orders(username)', '  File "/Users/vishaljha/Desktop/FINVANT/API/Backend/Scripts/DBManager.py", line 61, in get_pending_orders', '    db_connection = get_new_dbconnection()', '  File "/Users/vishaljha/Desktop/FINVANT/API/Backend/Scripts/DBManager.py", line 11, in get_new_dbconnection', "    con = sqlite3.connect('../../OMS_Server/Data/OrderData.db')", 'sqlite3.OperationalError: unable to open database file']
root - CRITICAL - CRITICAL ERROR:2023-01-12 13:35:00.916192 - Failed to clear pending orders.
['Traceback (most recent call last):', '  File "/Users/vishaljha/Desktop/FINVANT/API/Backend/Scripts/OrderHandler.py", line 36, in thread_function', '    self.place_pending_orders(username, spread_list= self.spread_list)', '  File "/Users/vishaljha/Desktop/FINVANT/API/Backend/Scripts/OrderHandler.py", line 46, in place_pending_orders', '    pending_orders = DBManager.get_pending_orders(username)', '  File "/Users/vishaljha/Desktop/FINVANT/API/Backend/Scripts/DBManager.py", line 61, in get_pending_orders', '    db_connection = get_new_dbconnection()', '  File "/Users/vishaljha/Desktop/FINVANT/API/Backend/Scripts/DBManager.py", line 11, in get_new_dbconnection', "    con = sqlite3.connect('../../OMS_Server/Data/OrderData.db')", 'sqlite3.OperationalError: unable to open database file']
root - CRITICAL - CRITICAL ERROR:2023-01-12 13:35:01.051204 - Failed to clear pending orders.
['Traceback (most recent call last):', '  File "/Users/vishaljha/Desktop/FINVANT/API/Backend/Scripts/OrderHandler.py", line 36, in thread_function', '    self.place_pending_orders(username, spread_list= self.spread_list)', '  File "/Users/vishaljha/Desktop/FINVANT/API/Backend/Scripts/OrderHandler.py", line 46, in place_pending_orders', '    pending_orders = DBManager.get_pending_orders(username)', '  File "/Users/vishaljha/Desktop/FINVANT/API/Backend/Scripts/DBManager.py", line 61, in get_pending_orders', '    db_connection = get_new_dbconnection()', '  File "/Users/vishaljha/Desktop/FINVANT/API/Backend/Scripts/DBManager.py", line 11, in get_new_dbconnection', "    con = sqlite3.connect('../../OMS_Server/Data/OrderData.db')", 'sqlite3.OperationalError: unable to open database file']
root - INFO - 2023-01-12 13:36:26.413882 - Finvant Alcubierre Mk1 OMS Backend turned on.
root - INFO - 2023-01-12 13:36:26.568490 - OMS Backend mainloop started.
root - INFO - 2023-01-12 13:36:28.626289 - OMSB: Logging in for backend kite ticker.
root - INFO - 2023-01-12 13:36:38.657569 - OMSB: Login succesful for backend kite ticker.
root - INFO - 2023-01-12 13:36:38.794400 - OMSB: Zerodha login for WG5235.
root - INFO - 2023-01-12 13:36:47.001631 - OMSB: Zerodha login succesful for WG5235.
root - CRITICAL - CRITICAL ERROR:2023-01-12 13:41:38.569527 - Failed to initialise Log server/ADS.
['Traceback (most recent call last):', '  File "Main.py", line 28, in __init__', '    self.start()', '  File "Main.py", line 36, in start', '    self.main_loop()', '  File "Main.py", line 76, in main_loop', '    sleep(1)', 'KeyboardInterrupt']
root - INFO - 2023-01-12 13:43:12.434961 - Finvant Alcubierre Mk1 OMS Backend turned on.
root - INFO - 2023-01-12 13:43:12.595580 - OMS Backend mainloop started.
root - INFO - 2023-01-12 13:43:14.638078 - OMSB: Logging in for backend kite ticker.
root - INFO - 2023-01-12 13:43:24.579596 - OMSB: Login succesful for backend kite ticker.
root - INFO - 2023-01-12 13:43:24.856644 - OMSB: Zerodha login for WG5235.
root - INFO - 2023-01-12 13:43:35.119636 - OMSB: Zerodha login succesful for WG5235.
root - INFO - 2023-01-12 13:44:33.426483 - Placed Zerodha Kite futures order for:FINVANT, instrument:NIFTY23JANFUT, qty:1, transaction type:BUY, placed price:17081, id:15.
root - INFO - 2023-01-12 13:45:10.290899 - Placed Zerodha Kite futures order for:FINVANT, instrument:NIFTY23JANFUT, qty:-1, transaction type:SELL, placed price:17905, id:16.
root - INFO - 2023-01-12 13:45:32.936605 - Placed Zerodha Kite futures order for:FINVANT, instrument:NIFTY23JANFUT, qty:-1, transaction type:SELL, placed price:17195, id:7.
root - INFO - 2023-01-12 13:48:17.068963 - Placed Zerodha Kite futures order for:FINVANT, instrument:NIFTY23JANFUT, qty:-1, transaction type:SELL, placed price:17132, id:18.
root - CRITICAL - CRITICAL ERROR:2023-01-12 13:49:51.159169 - Failed to initialise Log server/ADS.
['Traceback (most recent call last):', '  File "Main.py", line 28, in __init__', '    self.start()', '  File "Main.py", line 36, in start', '    self.main_loop()', '  File "Main.py", line 76, in main_loop', '    sleep(1)', 'KeyboardInterrupt']
root - INFO - 2023-01-12 13:50:46.795664 - Finvant Alcubierre Mk1 OMS Backend turned on.
root - INFO - 2023-01-12 13:50:46.927389 - OMS Backend mainloop started.
root - INFO - 2023-01-12 13:50:48.946184 - OMSB: Logging in for backend kite ticker.
root - INFO - 2023-01-12 13:50:58.947959 - OMSB: Login succesful for backend kite ticker.
root - INFO - 2023-01-12 13:50:59.093092 - OMSB: Zerodha login for WG5235.
root - INFO - 2023-01-12 13:51:08.260512 - OMSB: Zerodha login succesful for WG5235.
root - INFO - 2023-01-12 14:02:21.423749 - Placed Zerodha Kite futures order for:FINVANT, instrument:NIFTY23JANFUT, qty:-1, transaction type:SELL, placed price:17287, id:19.
root - INFO - 2023-01-12 14:03:10.351819 - Placed Zerodha Kite futures order for:FINVANT, instrument:NIFTY23JANFUT, qty:-1, transaction type:SELL, placed price:17469, id:9.
root - INFO - 2023-01-12 14:13:17.098083 - Placed Zerodha Kite options order for:FINVANT, instrument:NIFTY23JAN17700PE, qty:1, transaction type:BUY, placed price:17841, id:16.
root - INFO - 2023-01-12 14:13:17.252959 - Placed Zerodha Kite options order for:FINVANT, instrument:NIFTY23JAN18100PE, qty:1, transaction type:BUY, placed price:17155, id:6.
root - INFO - 2023-01-12 14:13:17.386284 - Placed Zerodha Kite options order for:FINVANT, instrument:NIFTY23JAN17800PE, qty:-1, transaction type:SELL, placed price:17508, id:13.
root - INFO - 2023-01-12 14:13:17.521688 - Placed Zerodha Kite options order for:FINVANT, instrument:NIFTY23JAN18000PE, qty:-1, transaction type:SELL, placed price:17901, id:6.
root - INFO - 2023-01-12 14:13:48.333279 - Placed Zerodha Kite options order for:FINVANT, instrument:NIFTY23JAN17700PE, qty:-1, transaction type:SELL, placed price:17570, id:5.
root - INFO - 2023-01-12 14:13:48.464582 - Placed Zerodha Kite options order for:FINVANT, instrument:NIFTY23JAN18100PE, qty:-1, transaction type:SELL, placed price:17906, id:13.
root - INFO - 2023-01-12 14:13:48.601107 - Placed Zerodha Kite options order for:FINVANT, instrument:NIFTY23JAN17800PE, qty:1, transaction type:BUY, placed price:17292, id:2.
root - INFO - 2023-01-12 14:13:48.760159 - Placed Zerodha Kite options order for:FINVANT, instrument:NIFTY23JAN18000PE, qty:1, transaction type:BUY, placed price:17692, id:2.
root - CRITICAL - CRITICAL ERROR:2023-01-12 14:14:01.161467 - Failed to initialise Log server/ADS.
['Traceback (most recent call last):', '  File "Main.py", line 28, in __init__', '    self.start()', '  File "Main.py", line 36, in start', '    self.main_loop()', '  File "Main.py", line 76, in main_loop', '    sleep(1)', 'KeyboardInterrupt']
root - INFO - 2023-01-12 15:24:43.104230 - Finvant Alcubierre Mk1 OMS Backend turned on.
root - INFO - 2023-01-12 15:24:43.505716 - OMS Backend mainloop started.
root - INFO - 2023-01-12 15:24:45.489283 - OMSB: Logging in for backend kite ticker.
root - INFO - 2023-01-12 15:24:55.636473 - OMSB: Login succesful for backend kite ticker.
root - INFO - 2023-01-12 15:24:55.771628 - OMSB: Zerodha login for WG5235.
root - INFO - 2023-01-12 15:25:04.328326 - OMSB: Zerodha login succesful for WG5235.
root - INFO - 2023-01-12 15:25:32.075656 - Placed Zerodha Kite futures order for:FINVANT, instrument:NIFTY23JANFUT, qty:-1, transaction type:SELL, placed price:17758, id:3.
root - INFO - 2023-01-12 15:25:55.580051 - Placed Zerodha Kite futures order for:FINVANT, instrument:NIFTY23JANFUT, qty:-1, transaction type:SELL, placed price:17906, id:7.
root - CRITICAL - CRITICAL ERROR:2023-01-12 15:26:22.770286 - Failed to initialise Log server/ADS.
['Traceback (most recent call last):', '  File "Main.py", line 28, in __init__', '    self.start()', '  File "Main.py", line 36, in start', '    self.main_loop()', '  File "Main.py", line 76, in main_loop', '    sleep(1)', 'KeyboardInterrupt']
root - INFO - 2023-01-12 15:27:15.998856 - Finvant Alcubierre Mk1 OMS Backend turned on.
root - INFO - 2023-01-12 15:27:16.137493 - OMS Backend mainloop started.
root - INFO - 2023-01-12 15:27:18.404514 - OMSB: Logging in for backend kite ticker.
root - INFO - 2023-01-12 15:27:30.685428 - OMSB: Login succesful for backend kite ticker.
root - INFO - 2023-01-12 15:27:30.837075 - OMSB: Zerodha login for WG5235.
root - INFO - 2023-01-12 15:27:42.616105 - OMSB: Zerodha login succesful for WG5235.
root - INFO - 2023-01-12 15:27:42.759328 - Placed Zerodha Kite futures order for:FINVANT, instrument:NIFTY23JANFUT, qty:-1, transaction type:SELL, placed price:17956, id:11.
root - CRITICAL - CRITICAL ERROR:2023-01-12 15:27:54.089154 - Failed to initialise Log server/ADS.
['Traceback (most recent call last):', '  File "Main.py", line 28, in __init__', '    self.start()', '  File "Main.py", line 36, in start', '    self.main_loop()', '  File "Main.py", line 76, in main_loop', '    sleep(1)', 'KeyboardInterrupt']
root - INFO - 2023-01-12 15:35:01.258299 - Finvant Alcubierre Mk1 OMS Backend turned on.
root - CRITICAL - CRITICAL ERROR:2023-01-12 15:35:39.019562 - Failed to initialise Log server/ADS.
['Traceback (most recent call last):', '  File "Main.py", line 28, in __init__', '    self.start()', '  File "Main.py", line 38, in start', '    sleep(100)', 'KeyboardInterrupt']
root - INFO - 2023-01-12 15:36:03.659029 - Finvant Alcubierre Mk1 OMS Backend turned on.
root - INFO - 2023-01-12 15:36:03.790529 - OMS Backend mainloop started.
root - INFO - 2023-01-12 15:36:05.799358 - OMSB: Logging in for backend kite ticker.
root - INFO - 2023-01-12 15:36:18.366408 - OMSB: Login succesful for backend kite ticker.
root - INFO - 2023-01-12 15:36:18.522238 - OMSB: Zerodha login for WG5235.
root - INFO - 2023-01-12 15:36:30.430393 - OMSB: Zerodha login succesful for WG5235.
root - INFO - 2023-01-12 15:36:30.572642 - Placed Zerodha Kite futures order for:FINVANT, instrument:NIFTY23JANFUT, qty:-1, transaction type:SELL, placed price:17134, id:11.
root - INFO - 2023-01-12 15:36:48.386555 - Placed Zerodha Kite futures order for:FINVANT, instrument:NIFTY23JANFUT, qty:-1, transaction type:SELL, placed price:17817, id:6.
root - INFO - 2023-01-12 15:37:26.983003 - Placed Zerodha Kite futures order for:FINVANT, instrument:NIFTY23JANFUT, qty:1, transaction type:BUY, placed price:17802, id:11.
kiteconnect.ticker - ERROR - Connection error: 1006 - connection was closed uncleanly (None)
kiteconnect.ticker - ERROR - Connection closed: 1006 - connection was closed uncleanly (None)
root - CRITICAL - CRITICAL ERROR:2023-01-12 16:56:18.082274 - Failed to initialise Log server/ADS.
['Traceback (most recent call last):', '  File "Main.py", line 28, in __init__', '    self.start()', '  File "Main.py", line 38, in start', '    sleep(100)', 'KeyboardInterrupt']
