root - INFO - 2023-06-08 12:49:42.615518 - OMS Server turned on.
uvicorn.error - INFO - Started server process [271046]
uvicorn.error - INFO - Waiting for application startup.
tortoise - INFO - Tortoise-ORM started, {'default': <tortoise.backends.sqlite.client.SqliteClient object at 0x7f977eec9f00>}, {'models': {'OptionSpread': <class 'models.OptionSpread'>, 'User': <class 'models.User'>, 'User_Finvant': <class 'models.User_Finvant'>}}
tortoise - INFO - Tortoise-ORM generating schema
uvicorn.error - INFO - Application startup complete.
uvicorn.error - INFO - Uvicorn running on http://0.0.0.0:9093 (Press CTRL+C to quit)
uvicorn.error - WARNING - Invalid HTTP request received.
Traceback (most recent call last):
  File "/usr/lib/python3/dist-packages/uvicorn/protocols/http/h11_impl.py", line 136, in handle_events
    event = self.conn.next_event()
  File "/home/ubuntu/.local/lib/python3.10/site-packages/h11/_connection.py", line 487, in next_event
    exc._reraise_as_remote_protocol_error()
  File "/home/ubuntu/.local/lib/python3.10/site-packages/h11/_util.py", line 77, in _reraise_as_remote_protocol_error
    raise self
  File "/home/ubuntu/.local/lib/python3.10/site-packages/h11/_connection.py", line 469, in next_event
    event = self._extract_next_receive_event()
  File "/home/ubuntu/.local/lib/python3.10/site-packages/h11/_connection.py", line 411, in _extract_next_receive_event
    event = self._reader(self._receive_buffer)
  File "/home/ubuntu/.local/lib/python3.10/site-packages/h11/_readers.py", line 79, in maybe_read_from_IDLE_client
    raise LocalProtocolError("illegal request line")
h11._util.RemoteProtocolError: illegal request line
uvicorn.error - WARNING - Invalid HTTP request received.
Traceback (most recent call last):
  File "/home/ubuntu/.local/lib/python3.10/site-packages/starlette/middleware/exceptions.py", line 68, in __call__
    await self.app(scope, receive, sender)
  File "/home/ubuntu/.local/lib/python3.10/site-packages/fastapi/middleware/asyncexitstack.py", line 21, in __call__
    raise e
  File "/home/ubuntu/.local/lib/python3.10/site-packages/fastapi/middleware/asyncexitstack.py", line 18, in __call__
    await self.app(scope, receive, send)
  File "/home/ubuntu/.local/lib/python3.10/site-packages/starlette/routing.py", line 747, in __call__
    await self.default(scope, receive, send)
  File "/home/ubuntu/.local/lib/python3.10/site-packages/starlette/routing.py", line 635, in not_found
    raise HTTPException(status_code=404)
starlette.exceptions.HTTPException

During handling of the above exception, another exception occurred:

Traceback (most recent call last):
  File "/usr/lib/python3/dist-packages/uvicorn/protocols/http/h11_impl.py", line 136, in handle_events
    event = self.conn.next_event()
  File "/home/ubuntu/.local/lib/python3.10/site-packages/h11/_connection.py", line 487, in next_event
    exc._reraise_as_remote_protocol_error()
  File "/home/ubuntu/.local/lib/python3.10/site-packages/h11/_util.py", line 77, in _reraise_as_remote_protocol_error
    raise self
  File "/home/ubuntu/.local/lib/python3.10/site-packages/h11/_connection.py", line 469, in next_event
    event = self._extract_next_receive_event()
  File "/home/ubuntu/.local/lib/python3.10/site-packages/h11/_connection.py", line 411, in _extract_next_receive_event
    event = self._reader(self._receive_buffer)
  File "/home/ubuntu/.local/lib/python3.10/site-packages/h11/_readers.py", line 83, in maybe_read_from_IDLE_client
    matches = validate(
  File "/home/ubuntu/.local/lib/python3.10/site-packages/h11/_util.py", line 91, in validate
    raise LocalProtocolError(msg)
h11._util.RemoteProtocolError: illegal request line: bytearray(b'SM')
uvicorn.error - WARNING - Invalid HTTP request received.
Traceback (most recent call last):
  File "/usr/lib/python3/dist-packages/uvicorn/protocols/http/h11_impl.py", line 136, in handle_events
    event = self.conn.next_event()
  File "/home/ubuntu/.local/lib/python3.10/site-packages/h11/_connection.py", line 487, in next_event
    exc._reraise_as_remote_protocol_error()
  File "/home/ubuntu/.local/lib/python3.10/site-packages/h11/_util.py", line 77, in _reraise_as_remote_protocol_error
    raise self
  File "/home/ubuntu/.local/lib/python3.10/site-packages/h11/_connection.py", line 469, in next_event
    event = self._extract_next_receive_event()
  File "/home/ubuntu/.local/lib/python3.10/site-packages/h11/_connection.py", line 411, in _extract_next_receive_event
    event = self._reader(self._receive_buffer)
  File "/home/ubuntu/.local/lib/python3.10/site-packages/h11/_readers.py", line 79, in maybe_read_from_IDLE_client
    raise LocalProtocolError("illegal request line")
h11._util.RemoteProtocolError: illegal request line
uvicorn.error - WARNING - Invalid HTTP request received.
Traceback (most recent call last):
  File "/home/ubuntu/.local/lib/python3.10/site-packages/starlette/middleware/exceptions.py", line 68, in __call__
    await self.app(scope, receive, sender)
  File "/home/ubuntu/.local/lib/python3.10/site-packages/fastapi/middleware/asyncexitstack.py", line 21, in __call__
    raise e
  File "/home/ubuntu/.local/lib/python3.10/site-packages/fastapi/middleware/asyncexitstack.py", line 18, in __call__
    await self.app(scope, receive, send)
  File "/home/ubuntu/.local/lib/python3.10/site-packages/starlette/routing.py", line 747, in __call__
    await self.default(scope, receive, send)
  File "/home/ubuntu/.local/lib/python3.10/site-packages/starlette/routing.py", line 635, in not_found
    raise HTTPException(status_code=404)
starlette.exceptions.HTTPException

During handling of the above exception, another exception occurred:

Traceback (most recent call last):
  File "/usr/lib/python3/dist-packages/uvicorn/protocols/http/h11_impl.py", line 136, in handle_events
    event = self.conn.next_event()
  File "/home/ubuntu/.local/lib/python3.10/site-packages/h11/_connection.py", line 487, in next_event
    exc._reraise_as_remote_protocol_error()
  File "/home/ubuntu/.local/lib/python3.10/site-packages/h11/_util.py", line 77, in _reraise_as_remote_protocol_error
    raise self
  File "/home/ubuntu/.local/lib/python3.10/site-packages/h11/_connection.py", line 469, in next_event
    event = self._extract_next_receive_event()
  File "/home/ubuntu/.local/lib/python3.10/site-packages/h11/_connection.py", line 411, in _extract_next_receive_event
    event = self._reader(self._receive_buffer)
  File "/home/ubuntu/.local/lib/python3.10/site-packages/h11/_readers.py", line 83, in maybe_read_from_IDLE_client
    matches = validate(
  File "/home/ubuntu/.local/lib/python3.10/site-packages/h11/_util.py", line 91, in validate
    raise LocalProtocolError(msg)
h11._util.RemoteProtocolError: illegal request line: bytearray(b'SM')
uvicorn.error - WARNING - Invalid HTTP request received.
Traceback (most recent call last):
  File "/usr/lib/python3/dist-packages/uvicorn/protocols/http/h11_impl.py", line 136, in handle_events
    event = self.conn.next_event()
  File "/home/ubuntu/.local/lib/python3.10/site-packages/h11/_connection.py", line 487, in next_event
    exc._reraise_as_remote_protocol_error()
  File "/home/ubuntu/.local/lib/python3.10/site-packages/h11/_util.py", line 77, in _reraise_as_remote_protocol_error
    raise self
  File "/home/ubuntu/.local/lib/python3.10/site-packages/h11/_connection.py", line 469, in next_event
    event = self._extract_next_receive_event()
  File "/home/ubuntu/.local/lib/python3.10/site-packages/h11/_connection.py", line 411, in _extract_next_receive_event
    event = self._reader(self._receive_buffer)
  File "/home/ubuntu/.local/lib/python3.10/site-packages/h11/_readers.py", line 79, in maybe_read_from_IDLE_client
    raise LocalProtocolError("illegal request line")
h11._util.RemoteProtocolError: illegal request line
uvicorn.error - WARNING - Invalid HTTP request received.
Traceback (most recent call last):
  File "/home/ubuntu/.local/lib/python3.10/site-packages/starlette/middleware/exceptions.py", line 68, in __call__
    await self.app(scope, receive, sender)
  File "/home/ubuntu/.local/lib/python3.10/site-packages/fastapi/middleware/asyncexitstack.py", line 21, in __call__
    raise e
  File "/home/ubuntu/.local/lib/python3.10/site-packages/fastapi/middleware/asyncexitstack.py", line 18, in __call__
    await self.app(scope, receive, send)
  File "/home/ubuntu/.local/lib/python3.10/site-packages/starlette/routing.py", line 747, in __call__
    await self.default(scope, receive, send)
  File "/home/ubuntu/.local/lib/python3.10/site-packages/starlette/routing.py", line 635, in not_found
    raise HTTPException(status_code=404)
starlette.exceptions.HTTPException

During handling of the above exception, another exception occurred:

Traceback (most recent call last):
  File "/usr/lib/python3/dist-packages/uvicorn/protocols/http/h11_impl.py", line 136, in handle_events
    event = self.conn.next_event()
  File "/home/ubuntu/.local/lib/python3.10/site-packages/h11/_connection.py", line 487, in next_event
    exc._reraise_as_remote_protocol_error()
  File "/home/ubuntu/.local/lib/python3.10/site-packages/h11/_util.py", line 77, in _reraise_as_remote_protocol_error
    raise self
  File "/home/ubuntu/.local/lib/python3.10/site-packages/h11/_connection.py", line 469, in next_event
    event = self._extract_next_receive_event()
  File "/home/ubuntu/.local/lib/python3.10/site-packages/h11/_connection.py", line 411, in _extract_next_receive_event
    event = self._reader(self._receive_buffer)
  File "/home/ubuntu/.local/lib/python3.10/site-packages/h11/_readers.py", line 83, in maybe_read_from_IDLE_client
    matches = validate(
  File "/home/ubuntu/.local/lib/python3.10/site-packages/h11/_util.py", line 91, in validate
    raise LocalProtocolError(msg)
h11._util.RemoteProtocolError: illegal request line: bytearray(b'SM')
uvicorn.error - WARNING - Invalid HTTP request received.
Traceback (most recent call last):
  File "/usr/lib/python3/dist-packages/uvicorn/protocols/http/h11_impl.py", line 136, in handle_events
    event = self.conn.next_event()
  File "/home/ubuntu/.local/lib/python3.10/site-packages/h11/_connection.py", line 487, in next_event
    exc._reraise_as_remote_protocol_error()
  File "/home/ubuntu/.local/lib/python3.10/site-packages/h11/_util.py", line 77, in _reraise_as_remote_protocol_error
    raise self
  File "/home/ubuntu/.local/lib/python3.10/site-packages/h11/_connection.py", line 469, in next_event
    event = self._extract_next_receive_event()
  File "/home/ubuntu/.local/lib/python3.10/site-packages/h11/_connection.py", line 411, in _extract_next_receive_event
    event = self._reader(self._receive_buffer)
  File "/home/ubuntu/.local/lib/python3.10/site-packages/h11/_readers.py", line 79, in maybe_read_from_IDLE_client
    raise LocalProtocolError("illegal request line")
h11._util.RemoteProtocolError: illegal request line
uvicorn.error - WARNING - Invalid HTTP request received.
Traceback (most recent call last):
  File "/usr/lib/python3/dist-packages/uvicorn/protocols/http/h11_impl.py", line 136, in handle_events
    event = self.conn.next_event()
  File "/home/ubuntu/.local/lib/python3.10/site-packages/h11/_connection.py", line 487, in next_event
    exc._reraise_as_remote_protocol_error()
  File "/home/ubuntu/.local/lib/python3.10/site-packages/h11/_util.py", line 77, in _reraise_as_remote_protocol_error
    raise self
  File "/home/ubuntu/.local/lib/python3.10/site-packages/h11/_connection.py", line 469, in next_event
    event = self._extract_next_receive_event()
  File "/home/ubuntu/.local/lib/python3.10/site-packages/h11/_connection.py", line 411, in _extract_next_receive_event
    event = self._reader(self._receive_buffer)
  File "/home/ubuntu/.local/lib/python3.10/site-packages/h11/_readers.py", line 79, in maybe_read_from_IDLE_client
    raise LocalProtocolError("illegal request line")
h11._util.RemoteProtocolError: illegal request line
uvicorn.error - WARNING - Invalid HTTP request received.
Traceback (most recent call last):
  File "/usr/lib/python3/dist-packages/uvicorn/protocols/http/h11_impl.py", line 136, in handle_events
    event = self.conn.next_event()
  File "/home/ubuntu/.local/lib/python3.10/site-packages/h11/_connection.py", line 487, in next_event
    exc._reraise_as_remote_protocol_error()
  File "/home/ubuntu/.local/lib/python3.10/site-packages/h11/_util.py", line 77, in _reraise_as_remote_protocol_error
    raise self
  File "/home/ubuntu/.local/lib/python3.10/site-packages/h11/_connection.py", line 469, in next_event
    event = self._extract_next_receive_event()
  File "/home/ubuntu/.local/lib/python3.10/site-packages/h11/_connection.py", line 411, in _extract_next_receive_event
    event = self._reader(self._receive_buffer)
  File "/home/ubuntu/.local/lib/python3.10/site-packages/h11/_readers.py", line 79, in maybe_read_from_IDLE_client
    raise LocalProtocolError("illegal request line")
h11._util.RemoteProtocolError: illegal request line
uvicorn.error - WARNING - Invalid HTTP request received.
Traceback (most recent call last):
  File "/home/ubuntu/.local/lib/python3.10/site-packages/starlette/middleware/exceptions.py", line 68, in __call__
    await self.app(scope, receive, sender)
  File "/home/ubuntu/.local/lib/python3.10/site-packages/fastapi/middleware/asyncexitstack.py", line 21, in __call__
    raise e
  File "/home/ubuntu/.local/lib/python3.10/site-packages/fastapi/middleware/asyncexitstack.py", line 18, in __call__
    await self.app(scope, receive, send)
  File "/home/ubuntu/.local/lib/python3.10/site-packages/starlette/routing.py", line 747, in __call__
    await self.default(scope, receive, send)
  File "/home/ubuntu/.local/lib/python3.10/site-packages/starlette/routing.py", line 635, in not_found
    raise HTTPException(status_code=404)
starlette.exceptions.HTTPException

During handling of the above exception, another exception occurred:

Traceback (most recent call last):
  File "/usr/lib/python3/dist-packages/uvicorn/protocols/http/h11_impl.py", line 136, in handle_events
    event = self.conn.next_event()
  File "/home/ubuntu/.local/lib/python3.10/site-packages/h11/_connection.py", line 487, in next_event
    exc._reraise_as_remote_protocol_error()
  File "/home/ubuntu/.local/lib/python3.10/site-packages/h11/_util.py", line 77, in _reraise_as_remote_protocol_error
    raise self
  File "/home/ubuntu/.local/lib/python3.10/site-packages/h11/_connection.py", line 469, in next_event
    event = self._extract_next_receive_event()
  File "/home/ubuntu/.local/lib/python3.10/site-packages/h11/_connection.py", line 411, in _extract_next_receive_event
    event = self._reader(self._receive_buffer)
  File "/home/ubuntu/.local/lib/python3.10/site-packages/h11/_readers.py", line 83, in maybe_read_from_IDLE_client
    matches = validate(
  File "/home/ubuntu/.local/lib/python3.10/site-packages/h11/_util.py", line 91, in validate
    raise LocalProtocolError(msg)
h11._util.RemoteProtocolError: illegal request line: bytearray(b'SM')
uvicorn.error - INFO - Shutting down
uvicorn.error - INFO - Waiting for application shutdown.
tortoise - INFO - Tortoise-ORM shutdown
uvicorn.error - INFO - Application shutdown complete.
uvicorn.error - INFO - Finished server process [271046]
