root - INFO - 2023-04-24 08:51:30.849620 - OMS Server turned on.
uvicorn.error - INFO - Started server process [45822]
uvicorn.error - INFO - Waiting for application startup.
tortoise - INFO - Tortoise-ORM started, {'default': <tortoise.backends.sqlite.client.SqliteClient object at 0x7f3fb7dd7f70>}, {'models': {'OptionSpread': <class 'models.OptionSpread'>, 'User': <class 'models.User'>, 'User_Finvant': <class 'models.User_Finvant'>}}
tortoise - INFO - Tortoise-ORM generating schema
uvicorn.error - INFO - Application startup complete.
uvicorn.error - INFO - Uvicorn running on http://0.0.0.0:9093 (Press CTRL+C to quit)
uvicorn.error - INFO - Shutting down
uvicorn.error - INFO - Waiting for application shutdown.
tortoise - INFO - Tortoise-ORM shutdown
tortoise - INFO - Tortoise-ORM shutdown
uvicorn.error - INFO - Application shutdown complete.
uvicorn.error - INFO - Finished server process [45822]
root - INFO - 2023-04-24 08:54:13.400119 - OMS Server turned on.
uvicorn.error - INFO - Started server process [53701]
uvicorn.error - INFO - Waiting for application startup.
tortoise - INFO - Tortoise-ORM started, {'default': <tortoise.backends.sqlite.client.SqliteClient object at 0x7f50fd458f40>}, {'models': {'OptionSpread': <class 'models.OptionSpread'>, 'User': <class 'models.User'>, 'User_Finvant': <class 'models.User_Finvant'>}}
tortoise - INFO - Tortoise-ORM generating schema
uvicorn.error - INFO - Application startup complete.
uvicorn.error - INFO - Uvicorn running on http://0.0.0.0:9093 (Press CTRL+C to quit)
root - INFO - 2023-04-24 09:30:17.929591 - Order placement successful for users: []
uvicorn.error - ERROR - Exception in ASGI application
Traceback (most recent call last):
  File "/home/ubuntu/.local/lib/python3.8/site-packages/uvicorn/protocols/http/h11_impl.py", line 373, in run_asgi
    result = await app(self.scope, self.receive, self.send)
  File "/home/ubuntu/.local/lib/python3.8/site-packages/uvicorn/middleware/proxy_headers.py", line 75, in __call__
    return await self.app(scope, receive, send)
  File "/home/ubuntu/.local/lib/python3.8/site-packages/fastapi/applications.py", line 208, in __call__
    await super().__call__(scope, receive, send)
  File "/home/ubuntu/.local/lib/python3.8/site-packages/starlette/applications.py", line 112, in __call__
    await self.middleware_stack(scope, receive, send)
  File "/home/ubuntu/.local/lib/python3.8/site-packages/starlette/middleware/errors.py", line 181, in __call__
    raise exc
  File "/home/ubuntu/.local/lib/python3.8/site-packages/starlette/middleware/errors.py", line 159, in __call__
    await self.app(scope, receive, _send)
  File "/home/ubuntu/.local/lib/python3.8/site-packages/starlette/middleware/cors.py", line 84, in __call__
    await self.app(scope, receive, send)
  File "/home/ubuntu/.local/lib/python3.8/site-packages/starlette/exceptions.py", line 82, in __call__
    raise exc
  File "/home/ubuntu/.local/lib/python3.8/site-packages/starlette/exceptions.py", line 71, in __call__
    await self.app(scope, receive, sender)
  File "/home/ubuntu/.local/lib/python3.8/site-packages/starlette/routing.py", line 656, in __call__
    await route.handle(scope, receive, send)
  File "/home/ubuntu/.local/lib/python3.8/site-packages/starlette/routing.py", line 259, in handle
    await self.app(scope, receive, send)
  File "/home/ubuntu/.local/lib/python3.8/site-packages/starlette/routing.py", line 61, in app
    response = await func(request)
  File "/home/ubuntu/.local/lib/python3.8/site-packages/fastapi/routing.py", line 226, in app
    raw_response = await run_endpoint_function(
  File "/home/ubuntu/.local/lib/python3.8/site-packages/fastapi/routing.py", line 159, in run_endpoint_function
    return await dependant.call(**values)
  File "/home/ubuntu/C/RUN/./main.py", line 1086, in create_order
    return user_result
UnboundLocalError: local variable 'user_result' referenced before assignment
root - INFO - 2023-04-24 09:30:19.638276 - Order placement successful for users: []
uvicorn.error - ERROR - Exception in ASGI application
Traceback (most recent call last):
  File "/home/ubuntu/.local/lib/python3.8/site-packages/uvicorn/protocols/http/h11_impl.py", line 373, in run_asgi
    result = await app(self.scope, self.receive, self.send)
  File "/home/ubuntu/.local/lib/python3.8/site-packages/uvicorn/middleware/proxy_headers.py", line 75, in __call__
    return await self.app(scope, receive, send)
  File "/home/ubuntu/.local/lib/python3.8/site-packages/fastapi/applications.py", line 208, in __call__
    await super().__call__(scope, receive, send)
  File "/home/ubuntu/.local/lib/python3.8/site-packages/starlette/applications.py", line 112, in __call__
    await self.middleware_stack(scope, receive, send)
  File "/home/ubuntu/.local/lib/python3.8/site-packages/starlette/middleware/errors.py", line 181, in __call__
    raise exc
  File "/home/ubuntu/.local/lib/python3.8/site-packages/starlette/middleware/errors.py", line 159, in __call__
    await self.app(scope, receive, _send)
  File "/home/ubuntu/.local/lib/python3.8/site-packages/starlette/middleware/cors.py", line 84, in __call__
    await self.app(scope, receive, send)
  File "/home/ubuntu/.local/lib/python3.8/site-packages/starlette/exceptions.py", line 82, in __call__
    raise exc
  File "/home/ubuntu/.local/lib/python3.8/site-packages/starlette/exceptions.py", line 71, in __call__
    await self.app(scope, receive, sender)
  File "/home/ubuntu/.local/lib/python3.8/site-packages/starlette/routing.py", line 656, in __call__
    await route.handle(scope, receive, send)
  File "/home/ubuntu/.local/lib/python3.8/site-packages/starlette/routing.py", line 259, in handle
    await self.app(scope, receive, send)
  File "/home/ubuntu/.local/lib/python3.8/site-packages/starlette/routing.py", line 61, in app
    response = await func(request)
  File "/home/ubuntu/.local/lib/python3.8/site-packages/fastapi/routing.py", line 226, in app
    raw_response = await run_endpoint_function(
  File "/home/ubuntu/.local/lib/python3.8/site-packages/fastapi/routing.py", line 159, in run_endpoint_function
    return await dependant.call(**values)
  File "/home/ubuntu/C/RUN/./main.py", line 1086, in create_order
    return user_result
UnboundLocalError: local variable 'user_result' referenced before assignment
root - INFO - 2023-04-24 09:35:16.114678 - Order placement successful for users: []
root - INFO - 2023-04-24 09:40:16.090939 - Order placement successful for users: []
root - INFO - 2023-04-24 09:45:16.068359 - Order placement successful for users: []
uvicorn.error - ERROR - Exception in ASGI application
Traceback (most recent call last):
  File "/home/ubuntu/.local/lib/python3.8/site-packages/uvicorn/protocols/http/h11_impl.py", line 373, in run_asgi
    result = await app(self.scope, self.receive, self.send)
  File "/home/ubuntu/.local/lib/python3.8/site-packages/uvicorn/middleware/proxy_headers.py", line 75, in __call__
    return await self.app(scope, receive, send)
  File "/home/ubuntu/.local/lib/python3.8/site-packages/fastapi/applications.py", line 208, in __call__
    await super().__call__(scope, receive, send)
  File "/home/ubuntu/.local/lib/python3.8/site-packages/starlette/applications.py", line 112, in __call__
    await self.middleware_stack(scope, receive, send)
  File "/home/ubuntu/.local/lib/python3.8/site-packages/starlette/middleware/errors.py", line 181, in __call__
    raise exc
  File "/home/ubuntu/.local/lib/python3.8/site-packages/starlette/middleware/errors.py", line 159, in __call__
    await self.app(scope, receive, _send)
  File "/home/ubuntu/.local/lib/python3.8/site-packages/starlette/middleware/cors.py", line 84, in __call__
    await self.app(scope, receive, send)
  File "/home/ubuntu/.local/lib/python3.8/site-packages/starlette/exceptions.py", line 82, in __call__
    raise exc
  File "/home/ubuntu/.local/lib/python3.8/site-packages/starlette/exceptions.py", line 71, in __call__
    await self.app(scope, receive, sender)
  File "/home/ubuntu/.local/lib/python3.8/site-packages/starlette/routing.py", line 656, in __call__
    await route.handle(scope, receive, send)
  File "/home/ubuntu/.local/lib/python3.8/site-packages/starlette/routing.py", line 259, in handle
    await self.app(scope, receive, send)
  File "/home/ubuntu/.local/lib/python3.8/site-packages/starlette/routing.py", line 61, in app
    response = await func(request)
  File "/home/ubuntu/.local/lib/python3.8/site-packages/fastapi/routing.py", line 226, in app
    raw_response = await run_endpoint_function(
  File "/home/ubuntu/.local/lib/python3.8/site-packages/fastapi/routing.py", line 159, in run_endpoint_function
    return await dependant.call(**values)
  File "/home/ubuntu/C/RUN/./main.py", line 1086, in create_order
    return user_result
UnboundLocalError: local variable 'user_result' referenced before assignment
root - INFO - 2023-04-24 09:45:17.818276 - Order placement successful for users: []
uvicorn.error - ERROR - Exception in ASGI application
Traceback (most recent call last):
  File "/home/ubuntu/.local/lib/python3.8/site-packages/uvicorn/protocols/http/h11_impl.py", line 373, in run_asgi
    result = await app(self.scope, self.receive, self.send)
  File "/home/ubuntu/.local/lib/python3.8/site-packages/uvicorn/middleware/proxy_headers.py", line 75, in __call__
    return await self.app(scope, receive, send)
  File "/home/ubuntu/.local/lib/python3.8/site-packages/fastapi/applications.py", line 208, in __call__
    await super().__call__(scope, receive, send)
  File "/home/ubuntu/.local/lib/python3.8/site-packages/starlette/applications.py", line 112, in __call__
    await self.middleware_stack(scope, receive, send)
  File "/home/ubuntu/.local/lib/python3.8/site-packages/starlette/middleware/errors.py", line 181, in __call__
    raise exc
  File "/home/ubuntu/.local/lib/python3.8/site-packages/starlette/middleware/errors.py", line 159, in __call__
    await self.app(scope, receive, _send)
  File "/home/ubuntu/.local/lib/python3.8/site-packages/starlette/middleware/cors.py", line 84, in __call__
    await self.app(scope, receive, send)
  File "/home/ubuntu/.local/lib/python3.8/site-packages/starlette/exceptions.py", line 82, in __call__
    raise exc
  File "/home/ubuntu/.local/lib/python3.8/site-packages/starlette/exceptions.py", line 71, in __call__
    await self.app(scope, receive, sender)
  File "/home/ubuntu/.local/lib/python3.8/site-packages/starlette/routing.py", line 656, in __call__
    await route.handle(scope, receive, send)
  File "/home/ubuntu/.local/lib/python3.8/site-packages/starlette/routing.py", line 259, in handle
    await self.app(scope, receive, send)
  File "/home/ubuntu/.local/lib/python3.8/site-packages/starlette/routing.py", line 61, in app
    response = await func(request)
  File "/home/ubuntu/.local/lib/python3.8/site-packages/fastapi/routing.py", line 226, in app
    raw_response = await run_endpoint_function(
  File "/home/ubuntu/.local/lib/python3.8/site-packages/fastapi/routing.py", line 159, in run_endpoint_function
    return await dependant.call(**values)
  File "/home/ubuntu/C/RUN/./main.py", line 1086, in create_order
    return user_result
UnboundLocalError: local variable 'user_result' referenced before assignment
root - INFO - 2023-04-24 09:50:16.146148 - Order placed for FINVANT_LIVE ALTAIR NIFTY_SYNTHETIC_INTRADAY_SHORT BUY 1 2 0.5
root - INFO - 2023-04-24 09:50:16.214536 - Order placed for AIRAN ALTAIR_FUTURES NIFTY OPEN SHORT -3 0.5 2
root - INFO - 2023-04-24 09:50:16.276590 - Order placed for BPWealth_AHO7706 ALTAIR_FUTURES NIFTY OPEN SHORT -2 0.5 2
root - INFO - 2023-04-24 09:50:16.345997 - Order placement successful for users: [{'user_name': 'FINVANT_LIVE', 'strategy': 'ALTAIR', 'instrument_nomenclature': 'NIFTY_SYNTHETIC_INTRADAY_SHORT', 'position': 'BUY', 'target': 0.5, 'stoploss': 2, 'quantity': 1}, {'user_name': 'AIRAN', 'strategy': 'ALTAIR_FUTURES', 'instrument_nomenclature': 'NIFTY', 'position': 'OPEN SHORT', 'target': 2, 'stoploss': 0.5, 'quantity': 3}, {'user_name': 'BPWealth_AHO7706', 'strategy': 'ALTAIR_FUTURES', 'instrument_nomenclature': 'NIFTY', 'position': 'OPEN SHORT', 'target': 2, 'stoploss': 0.5, 'quantity': 2}]
root - INFO - 2023-04-24 09:55:16.071183 - Order placed for FINVANT_LIVE ALTAIR BANKNIFTY_SYNTHETIC_INTRADAY_SHORT BUY 1 2 0.5
root - INFO - 2023-04-24 09:55:16.134108 - Order placed for AIRAN ALTAIR_FUTURES BANKNIFTY OPEN SHORT -3 0.5 2
root - INFO - 2023-04-24 09:55:16.197667 - Order placed for BPWealth_AHO7706 ALTAIR_FUTURES BANKNIFTY OPEN SHORT -1 0.5 2
root - INFO - 2023-04-24 09:55:16.266139 - Order placement successful for users: [{'user_name': 'FINVANT_LIVE', 'strategy': 'ALTAIR', 'instrument_nomenclature': 'BANKNIFTY_SYNTHETIC_INTRADAY_SHORT', 'position': 'BUY', 'target': 0.5, 'stoploss': 2, 'quantity': 1}, {'user_name': 'AIRAN', 'strategy': 'ALTAIR_FUTURES', 'instrument_nomenclature': 'BANKNIFTY', 'position': 'OPEN SHORT', 'target': 2, 'stoploss': 0.5, 'quantity': 3}, {'user_name': 'BPWealth_AHO7706', 'strategy': 'ALTAIR_FUTURES', 'instrument_nomenclature': 'BANKNIFTY', 'position': 'OPEN SHORT', 'target': 2, 'stoploss': 0.5, 'quantity': 1}]
root - INFO - 2023-04-24 10:00:16.070787 - Order placement successful for users: []
uvicorn.error - ERROR - Exception in ASGI application
Traceback (most recent call last):
  File "/home/ubuntu/.local/lib/python3.8/site-packages/uvicorn/protocols/http/h11_impl.py", line 373, in run_asgi
    result = await app(self.scope, self.receive, self.send)
  File "/home/ubuntu/.local/lib/python3.8/site-packages/uvicorn/middleware/proxy_headers.py", line 75, in __call__
    return await self.app(scope, receive, send)
  File "/home/ubuntu/.local/lib/python3.8/site-packages/fastapi/applications.py", line 208, in __call__
    await super().__call__(scope, receive, send)
  File "/home/ubuntu/.local/lib/python3.8/site-packages/starlette/applications.py", line 112, in __call__
    await self.middleware_stack(scope, receive, send)
  File "/home/ubuntu/.local/lib/python3.8/site-packages/starlette/middleware/errors.py", line 181, in __call__
    raise exc
  File "/home/ubuntu/.local/lib/python3.8/site-packages/starlette/middleware/errors.py", line 159, in __call__
    await self.app(scope, receive, _send)
  File "/home/ubuntu/.local/lib/python3.8/site-packages/starlette/middleware/cors.py", line 84, in __call__
    await self.app(scope, receive, send)
  File "/home/ubuntu/.local/lib/python3.8/site-packages/starlette/exceptions.py", line 82, in __call__
    raise exc
  File "/home/ubuntu/.local/lib/python3.8/site-packages/starlette/exceptions.py", line 71, in __call__
    await self.app(scope, receive, sender)
  File "/home/ubuntu/.local/lib/python3.8/site-packages/starlette/routing.py", line 656, in __call__
    await route.handle(scope, receive, send)
  File "/home/ubuntu/.local/lib/python3.8/site-packages/starlette/routing.py", line 259, in handle
    await self.app(scope, receive, send)
  File "/home/ubuntu/.local/lib/python3.8/site-packages/starlette/routing.py", line 61, in app
    response = await func(request)
  File "/home/ubuntu/.local/lib/python3.8/site-packages/fastapi/routing.py", line 226, in app
    raw_response = await run_endpoint_function(
  File "/home/ubuntu/.local/lib/python3.8/site-packages/fastapi/routing.py", line 159, in run_endpoint_function
    return await dependant.call(**values)
  File "/home/ubuntu/C/RUN/./main.py", line 1086, in create_order
    return user_result
UnboundLocalError: local variable 'user_result' referenced before assignment
root - INFO - 2023-04-24 10:00:17.819513 - Order placement successful for users: []
uvicorn.error - ERROR - Exception in ASGI application
Traceback (most recent call last):
  File "/home/ubuntu/.local/lib/python3.8/site-packages/uvicorn/protocols/http/h11_impl.py", line 373, in run_asgi
    result = await app(self.scope, self.receive, self.send)
  File "/home/ubuntu/.local/lib/python3.8/site-packages/uvicorn/middleware/proxy_headers.py", line 75, in __call__
    return await self.app(scope, receive, send)
  File "/home/ubuntu/.local/lib/python3.8/site-packages/fastapi/applications.py", line 208, in __call__
    await super().__call__(scope, receive, send)
  File "/home/ubuntu/.local/lib/python3.8/site-packages/starlette/applications.py", line 112, in __call__
    await self.middleware_stack(scope, receive, send)
  File "/home/ubuntu/.local/lib/python3.8/site-packages/starlette/middleware/errors.py", line 181, in __call__
    raise exc
  File "/home/ubuntu/.local/lib/python3.8/site-packages/starlette/middleware/errors.py", line 159, in __call__
    await self.app(scope, receive, _send)
  File "/home/ubuntu/.local/lib/python3.8/site-packages/starlette/middleware/cors.py", line 84, in __call__
    await self.app(scope, receive, send)
  File "/home/ubuntu/.local/lib/python3.8/site-packages/starlette/exceptions.py", line 82, in __call__
    raise exc
  File "/home/ubuntu/.local/lib/python3.8/site-packages/starlette/exceptions.py", line 71, in __call__
    await self.app(scope, receive, sender)
  File "/home/ubuntu/.local/lib/python3.8/site-packages/starlette/routing.py", line 656, in __call__
    await route.handle(scope, receive, send)
  File "/home/ubuntu/.local/lib/python3.8/site-packages/starlette/routing.py", line 259, in handle
    await self.app(scope, receive, send)
  File "/home/ubuntu/.local/lib/python3.8/site-packages/starlette/routing.py", line 61, in app
    response = await func(request)
  File "/home/ubuntu/.local/lib/python3.8/site-packages/fastapi/routing.py", line 226, in app
    raw_response = await run_endpoint_function(
  File "/home/ubuntu/.local/lib/python3.8/site-packages/fastapi/routing.py", line 159, in run_endpoint_function
    return await dependant.call(**values)
  File "/home/ubuntu/C/RUN/./main.py", line 1086, in create_order
    return user_result
UnboundLocalError: local variable 'user_result' referenced before assignment
root - INFO - 2023-04-24 10:10:16.087592 - Order placement successful for users: []
uvicorn.error - INFO - Shutting down
uvicorn.error - INFO - Waiting for application shutdown.
tortoise - INFO - Tortoise-ORM shutdown
tortoise - INFO - Tortoise-ORM shutdown
uvicorn.error - INFO - Application shutdown complete.
uvicorn.error - INFO - Finished server process [53701]
root - INFO - 2023-04-24 10:14:03.757779 - OMS Server turned on.
uvicorn.error - INFO - Started server process [55480]
uvicorn.error - INFO - Waiting for application startup.
tortoise - INFO - Tortoise-ORM started, {'default': <tortoise.backends.sqlite.client.SqliteClient object at 0x7fed8438bf40>}, {'models': {'OptionSpread': <class 'models.OptionSpread'>, 'User': <class 'models.User'>, 'User_Finvant': <class 'models.User_Finvant'>}}
tortoise - INFO - Tortoise-ORM generating schema
uvicorn.error - INFO - Application startup complete.
uvicorn.error - INFO - Uvicorn running on http://0.0.0.0:9093 (Press CTRL+C to quit)
root - INFO - 2023-04-24 10:15:16.053270 - Order placement successful for users: []
root - INFO - 2023-04-24 10:20:16.061990 - Order placement successful for users: []
root - INFO - 2023-04-24 10:25:16.058383 - Order placement successful for users: []
uvicorn.error - ERROR - Exception in ASGI application
Traceback (most recent call last):
  File "/home/ubuntu/.local/lib/python3.8/site-packages/uvicorn/protocols/http/h11_impl.py", line 373, in run_asgi
    result = await app(self.scope, self.receive, self.send)
  File "/home/ubuntu/.local/lib/python3.8/site-packages/uvicorn/middleware/proxy_headers.py", line 75, in __call__
    return await self.app(scope, receive, send)
  File "/home/ubuntu/.local/lib/python3.8/site-packages/fastapi/applications.py", line 208, in __call__
    await super().__call__(scope, receive, send)
  File "/home/ubuntu/.local/lib/python3.8/site-packages/starlette/applications.py", line 112, in __call__
    await self.middleware_stack(scope, receive, send)
  File "/home/ubuntu/.local/lib/python3.8/site-packages/starlette/middleware/errors.py", line 181, in __call__
    raise exc
  File "/home/ubuntu/.local/lib/python3.8/site-packages/starlette/middleware/errors.py", line 159, in __call__
    await self.app(scope, receive, _send)
  File "/home/ubuntu/.local/lib/python3.8/site-packages/starlette/middleware/cors.py", line 84, in __call__
    await self.app(scope, receive, send)
  File "/home/ubuntu/.local/lib/python3.8/site-packages/starlette/exceptions.py", line 82, in __call__
    raise exc
  File "/home/ubuntu/.local/lib/python3.8/site-packages/starlette/exceptions.py", line 71, in __call__
    await self.app(scope, receive, sender)
  File "/home/ubuntu/.local/lib/python3.8/site-packages/starlette/routing.py", line 656, in __call__
    await route.handle(scope, receive, send)
  File "/home/ubuntu/.local/lib/python3.8/site-packages/starlette/routing.py", line 259, in handle
    await self.app(scope, receive, send)
  File "/home/ubuntu/.local/lib/python3.8/site-packages/starlette/routing.py", line 61, in app
    response = await func(request)
  File "/home/ubuntu/.local/lib/python3.8/site-packages/fastapi/routing.py", line 226, in app
    raw_response = await run_endpoint_function(
  File "/home/ubuntu/.local/lib/python3.8/site-packages/fastapi/routing.py", line 159, in run_endpoint_function
    return await dependant.call(**values)
  File "/home/ubuntu/C/RUN/./main.py", line 1086, in create_order
    return user_result
UnboundLocalError: local variable 'user_result' referenced before assignment
root - INFO - 2023-04-24 10:25:17.439158 - Order placement successful for users: []
uvicorn.error - ERROR - Exception in ASGI application
Traceback (most recent call last):
  File "/home/ubuntu/.local/lib/python3.8/site-packages/uvicorn/protocols/http/h11_impl.py", line 373, in run_asgi
    result = await app(self.scope, self.receive, self.send)
  File "/home/ubuntu/.local/lib/python3.8/site-packages/uvicorn/middleware/proxy_headers.py", line 75, in __call__
    return await self.app(scope, receive, send)
  File "/home/ubuntu/.local/lib/python3.8/site-packages/fastapi/applications.py", line 208, in __call__
    await super().__call__(scope, receive, send)
  File "/home/ubuntu/.local/lib/python3.8/site-packages/starlette/applications.py", line 112, in __call__
    await self.middleware_stack(scope, receive, send)
  File "/home/ubuntu/.local/lib/python3.8/site-packages/starlette/middleware/errors.py", line 181, in __call__
    raise exc
  File "/home/ubuntu/.local/lib/python3.8/site-packages/starlette/middleware/errors.py", line 159, in __call__
    await self.app(scope, receive, _send)
  File "/home/ubuntu/.local/lib/python3.8/site-packages/starlette/middleware/cors.py", line 84, in __call__
    await self.app(scope, receive, send)
  File "/home/ubuntu/.local/lib/python3.8/site-packages/starlette/exceptions.py", line 82, in __call__
    raise exc
  File "/home/ubuntu/.local/lib/python3.8/site-packages/starlette/exceptions.py", line 71, in __call__
    await self.app(scope, receive, sender)
  File "/home/ubuntu/.local/lib/python3.8/site-packages/starlette/routing.py", line 656, in __call__
    await route.handle(scope, receive, send)
  File "/home/ubuntu/.local/lib/python3.8/site-packages/starlette/routing.py", line 259, in handle
    await self.app(scope, receive, send)
  File "/home/ubuntu/.local/lib/python3.8/site-packages/starlette/routing.py", line 61, in app
    response = await func(request)
  File "/home/ubuntu/.local/lib/python3.8/site-packages/fastapi/routing.py", line 226, in app
    raw_response = await run_endpoint_function(
  File "/home/ubuntu/.local/lib/python3.8/site-packages/fastapi/routing.py", line 159, in run_endpoint_function
    return await dependant.call(**values)
  File "/home/ubuntu/C/RUN/./main.py", line 1086, in create_order
    return user_result
UnboundLocalError: local variable 'user_result' referenced before assignment
root - INFO - 2023-04-24 10:30:16.062154 - Order placement successful for users: []
root - INFO - 2023-04-24 10:35:16.059485 - Order placement successful for users: []
root - INFO - 2023-04-24 10:40:16.026671 - Order placement successful for users: []
root - INFO - 2023-04-24 10:45:16.235049 - Order placement successful for users: []
uvicorn.error - ERROR - Exception in ASGI application
Traceback (most recent call last):
  File "/home/ubuntu/.local/lib/python3.8/site-packages/uvicorn/protocols/http/h11_impl.py", line 373, in run_asgi
    result = await app(self.scope, self.receive, self.send)
  File "/home/ubuntu/.local/lib/python3.8/site-packages/uvicorn/middleware/proxy_headers.py", line 75, in __call__
    return await self.app(scope, receive, send)
  File "/home/ubuntu/.local/lib/python3.8/site-packages/fastapi/applications.py", line 208, in __call__
    await super().__call__(scope, receive, send)
  File "/home/ubuntu/.local/lib/python3.8/site-packages/starlette/applications.py", line 112, in __call__
    await self.middleware_stack(scope, receive, send)
  File "/home/ubuntu/.local/lib/python3.8/site-packages/starlette/middleware/errors.py", line 181, in __call__
    raise exc
  File "/home/ubuntu/.local/lib/python3.8/site-packages/starlette/middleware/errors.py", line 159, in __call__
    await self.app(scope, receive, _send)
  File "/home/ubuntu/.local/lib/python3.8/site-packages/starlette/middleware/cors.py", line 84, in __call__
    await self.app(scope, receive, send)
  File "/home/ubuntu/.local/lib/python3.8/site-packages/starlette/exceptions.py", line 82, in __call__
    raise exc
  File "/home/ubuntu/.local/lib/python3.8/site-packages/starlette/exceptions.py", line 71, in __call__
    await self.app(scope, receive, sender)
  File "/home/ubuntu/.local/lib/python3.8/site-packages/starlette/routing.py", line 656, in __call__
    await route.handle(scope, receive, send)
  File "/home/ubuntu/.local/lib/python3.8/site-packages/starlette/routing.py", line 259, in handle
    await self.app(scope, receive, send)
  File "/home/ubuntu/.local/lib/python3.8/site-packages/starlette/routing.py", line 61, in app
    response = await func(request)
  File "/home/ubuntu/.local/lib/python3.8/site-packages/fastapi/routing.py", line 226, in app
    raw_response = await run_endpoint_function(
  File "/home/ubuntu/.local/lib/python3.8/site-packages/fastapi/routing.py", line 159, in run_endpoint_function
    return await dependant.call(**values)
  File "/home/ubuntu/C/RUN/./main.py", line 1086, in create_order
    return user_result
UnboundLocalError: local variable 'user_result' referenced before assignment
root - INFO - 2023-04-24 10:45:17.990412 - Order placement successful for users: []
uvicorn.error - ERROR - Exception in ASGI application
Traceback (most recent call last):
  File "/home/ubuntu/.local/lib/python3.8/site-packages/uvicorn/protocols/http/h11_impl.py", line 373, in run_asgi
    result = await app(self.scope, self.receive, self.send)
  File "/home/ubuntu/.local/lib/python3.8/site-packages/uvicorn/middleware/proxy_headers.py", line 75, in __call__
    return await self.app(scope, receive, send)
  File "/home/ubuntu/.local/lib/python3.8/site-packages/fastapi/applications.py", line 208, in __call__
    await super().__call__(scope, receive, send)
  File "/home/ubuntu/.local/lib/python3.8/site-packages/starlette/applications.py", line 112, in __call__
    await self.middleware_stack(scope, receive, send)
  File "/home/ubuntu/.local/lib/python3.8/site-packages/starlette/middleware/errors.py", line 181, in __call__
    raise exc
  File "/home/ubuntu/.local/lib/python3.8/site-packages/starlette/middleware/errors.py", line 159, in __call__
    await self.app(scope, receive, _send)
  File "/home/ubuntu/.local/lib/python3.8/site-packages/starlette/middleware/cors.py", line 84, in __call__
    await self.app(scope, receive, send)
  File "/home/ubuntu/.local/lib/python3.8/site-packages/starlette/exceptions.py", line 82, in __call__
    raise exc
  File "/home/ubuntu/.local/lib/python3.8/site-packages/starlette/exceptions.py", line 71, in __call__
    await self.app(scope, receive, sender)
  File "/home/ubuntu/.local/lib/python3.8/site-packages/starlette/routing.py", line 656, in __call__
    await route.handle(scope, receive, send)
  File "/home/ubuntu/.local/lib/python3.8/site-packages/starlette/routing.py", line 259, in handle
    await self.app(scope, receive, send)
  File "/home/ubuntu/.local/lib/python3.8/site-packages/starlette/routing.py", line 61, in app
    response = await func(request)
  File "/home/ubuntu/.local/lib/python3.8/site-packages/fastapi/routing.py", line 226, in app
    raw_response = await run_endpoint_function(
  File "/home/ubuntu/.local/lib/python3.8/site-packages/fastapi/routing.py", line 159, in run_endpoint_function
    return await dependant.call(**values)
  File "/home/ubuntu/C/RUN/./main.py", line 1086, in create_order
    return user_result
UnboundLocalError: local variable 'user_result' referenced before assignment
root - INFO - 2023-04-24 10:50:16.092157 - Order placement successful for users: []
uvicorn.error - ERROR - Exception in ASGI application
Traceback (most recent call last):
  File "/home/ubuntu/.local/lib/python3.8/site-packages/uvicorn/protocols/http/h11_impl.py", line 373, in run_asgi
    result = await app(self.scope, self.receive, self.send)
  File "/home/ubuntu/.local/lib/python3.8/site-packages/uvicorn/middleware/proxy_headers.py", line 75, in __call__
    return await self.app(scope, receive, send)
  File "/home/ubuntu/.local/lib/python3.8/site-packages/fastapi/applications.py", line 208, in __call__
    await super().__call__(scope, receive, send)
  File "/home/ubuntu/.local/lib/python3.8/site-packages/starlette/applications.py", line 112, in __call__
    await self.middleware_stack(scope, receive, send)
  File "/home/ubuntu/.local/lib/python3.8/site-packages/starlette/middleware/errors.py", line 181, in __call__
    raise exc
  File "/home/ubuntu/.local/lib/python3.8/site-packages/starlette/middleware/errors.py", line 159, in __call__
    await self.app(scope, receive, _send)
  File "/home/ubuntu/.local/lib/python3.8/site-packages/starlette/middleware/cors.py", line 84, in __call__
    await self.app(scope, receive, send)
  File "/home/ubuntu/.local/lib/python3.8/site-packages/starlette/exceptions.py", line 82, in __call__
    raise exc
  File "/home/ubuntu/.local/lib/python3.8/site-packages/starlette/exceptions.py", line 71, in __call__
    await self.app(scope, receive, sender)
  File "/home/ubuntu/.local/lib/python3.8/site-packages/starlette/routing.py", line 656, in __call__
    await route.handle(scope, receive, send)
  File "/home/ubuntu/.local/lib/python3.8/site-packages/starlette/routing.py", line 259, in handle
    await self.app(scope, receive, send)
  File "/home/ubuntu/.local/lib/python3.8/site-packages/starlette/routing.py", line 61, in app
    response = await func(request)
  File "/home/ubuntu/.local/lib/python3.8/site-packages/fastapi/routing.py", line 226, in app
    raw_response = await run_endpoint_function(
  File "/home/ubuntu/.local/lib/python3.8/site-packages/fastapi/routing.py", line 159, in run_endpoint_function
    return await dependant.call(**values)
  File "/home/ubuntu/C/RUN/./main.py", line 1086, in create_order
    return user_result
UnboundLocalError: local variable 'user_result' referenced before assignment
root - INFO - 2023-04-24 10:50:17.579962 - Order placement successful for users: []
uvicorn.error - ERROR - Exception in ASGI application
Traceback (most recent call last):
  File "/home/ubuntu/.local/lib/python3.8/site-packages/uvicorn/protocols/http/h11_impl.py", line 373, in run_asgi
    result = await app(self.scope, self.receive, self.send)
  File "/home/ubuntu/.local/lib/python3.8/site-packages/uvicorn/middleware/proxy_headers.py", line 75, in __call__
    return await self.app(scope, receive, send)
  File "/home/ubuntu/.local/lib/python3.8/site-packages/fastapi/applications.py", line 208, in __call__
    await super().__call__(scope, receive, send)
  File "/home/ubuntu/.local/lib/python3.8/site-packages/starlette/applications.py", line 112, in __call__
    await self.middleware_stack(scope, receive, send)
  File "/home/ubuntu/.local/lib/python3.8/site-packages/starlette/middleware/errors.py", line 181, in __call__
    raise exc
  File "/home/ubuntu/.local/lib/python3.8/site-packages/starlette/middleware/errors.py", line 159, in __call__
    await self.app(scope, receive, _send)
  File "/home/ubuntu/.local/lib/python3.8/site-packages/starlette/middleware/cors.py", line 84, in __call__
    await self.app(scope, receive, send)
  File "/home/ubuntu/.local/lib/python3.8/site-packages/starlette/exceptions.py", line 82, in __call__
    raise exc
  File "/home/ubuntu/.local/lib/python3.8/site-packages/starlette/exceptions.py", line 71, in __call__
    await self.app(scope, receive, sender)
  File "/home/ubuntu/.local/lib/python3.8/site-packages/starlette/routing.py", line 656, in __call__
    await route.handle(scope, receive, send)
  File "/home/ubuntu/.local/lib/python3.8/site-packages/starlette/routing.py", line 259, in handle
    await self.app(scope, receive, send)
  File "/home/ubuntu/.local/lib/python3.8/site-packages/starlette/routing.py", line 61, in app
    response = await func(request)
  File "/home/ubuntu/.local/lib/python3.8/site-packages/fastapi/routing.py", line 226, in app
    raw_response = await run_endpoint_function(
  File "/home/ubuntu/.local/lib/python3.8/site-packages/fastapi/routing.py", line 159, in run_endpoint_function
    return await dependant.call(**values)
  File "/home/ubuntu/C/RUN/./main.py", line 1086, in create_order
    return user_result
UnboundLocalError: local variable 'user_result' referenced before assignment
root - INFO - 2023-04-24 10:55:15.959490 - Order placement successful for users: []
uvicorn.error - ERROR - Exception in ASGI application
Traceback (most recent call last):
  File "/home/ubuntu/.local/lib/python3.8/site-packages/uvicorn/protocols/http/h11_impl.py", line 373, in run_asgi
    result = await app(self.scope, self.receive, self.send)
  File "/home/ubuntu/.local/lib/python3.8/site-packages/uvicorn/middleware/proxy_headers.py", line 75, in __call__
    return await self.app(scope, receive, send)
  File "/home/ubuntu/.local/lib/python3.8/site-packages/fastapi/applications.py", line 208, in __call__
    await super().__call__(scope, receive, send)
  File "/home/ubuntu/.local/lib/python3.8/site-packages/starlette/applications.py", line 112, in __call__
    await self.middleware_stack(scope, receive, send)
  File "/home/ubuntu/.local/lib/python3.8/site-packages/starlette/middleware/errors.py", line 181, in __call__
    raise exc
  File "/home/ubuntu/.local/lib/python3.8/site-packages/starlette/middleware/errors.py", line 159, in __call__
    await self.app(scope, receive, _send)
  File "/home/ubuntu/.local/lib/python3.8/site-packages/starlette/middleware/cors.py", line 84, in __call__
    await self.app(scope, receive, send)
  File "/home/ubuntu/.local/lib/python3.8/site-packages/starlette/exceptions.py", line 82, in __call__
    raise exc
  File "/home/ubuntu/.local/lib/python3.8/site-packages/starlette/exceptions.py", line 71, in __call__
    await self.app(scope, receive, sender)
  File "/home/ubuntu/.local/lib/python3.8/site-packages/starlette/routing.py", line 656, in __call__
    await route.handle(scope, receive, send)
  File "/home/ubuntu/.local/lib/python3.8/site-packages/starlette/routing.py", line 259, in handle
    await self.app(scope, receive, send)
  File "/home/ubuntu/.local/lib/python3.8/site-packages/starlette/routing.py", line 61, in app
    response = await func(request)
  File "/home/ubuntu/.local/lib/python3.8/site-packages/fastapi/routing.py", line 226, in app
    raw_response = await run_endpoint_function(
  File "/home/ubuntu/.local/lib/python3.8/site-packages/fastapi/routing.py", line 159, in run_endpoint_function
    return await dependant.call(**values)
  File "/home/ubuntu/C/RUN/./main.py", line 1086, in create_order
    return user_result
UnboundLocalError: local variable 'user_result' referenced before assignment
root - INFO - 2023-04-24 10:55:17.580363 - Order placement successful for users: []
uvicorn.error - ERROR - Exception in ASGI application
Traceback (most recent call last):
  File "/home/ubuntu/.local/lib/python3.8/site-packages/uvicorn/protocols/http/h11_impl.py", line 373, in run_asgi
    result = await app(self.scope, self.receive, self.send)
  File "/home/ubuntu/.local/lib/python3.8/site-packages/uvicorn/middleware/proxy_headers.py", line 75, in __call__
    return await self.app(scope, receive, send)
  File "/home/ubuntu/.local/lib/python3.8/site-packages/fastapi/applications.py", line 208, in __call__
    await super().__call__(scope, receive, send)
  File "/home/ubuntu/.local/lib/python3.8/site-packages/starlette/applications.py", line 112, in __call__
    await self.middleware_stack(scope, receive, send)
  File "/home/ubuntu/.local/lib/python3.8/site-packages/starlette/middleware/errors.py", line 181, in __call__
    raise exc
  File "/home/ubuntu/.local/lib/python3.8/site-packages/starlette/middleware/errors.py", line 159, in __call__
    await self.app(scope, receive, _send)
  File "/home/ubuntu/.local/lib/python3.8/site-packages/starlette/middleware/cors.py", line 84, in __call__
    await self.app(scope, receive, send)
  File "/home/ubuntu/.local/lib/python3.8/site-packages/starlette/exceptions.py", line 82, in __call__
    raise exc
  File "/home/ubuntu/.local/lib/python3.8/site-packages/starlette/exceptions.py", line 71, in __call__
    await self.app(scope, receive, sender)
  File "/home/ubuntu/.local/lib/python3.8/site-packages/starlette/routing.py", line 656, in __call__
    await route.handle(scope, receive, send)
  File "/home/ubuntu/.local/lib/python3.8/site-packages/starlette/routing.py", line 259, in handle
    await self.app(scope, receive, send)
  File "/home/ubuntu/.local/lib/python3.8/site-packages/starlette/routing.py", line 61, in app
    response = await func(request)
  File "/home/ubuntu/.local/lib/python3.8/site-packages/fastapi/routing.py", line 226, in app
    raw_response = await run_endpoint_function(
  File "/home/ubuntu/.local/lib/python3.8/site-packages/fastapi/routing.py", line 159, in run_endpoint_function
    return await dependant.call(**values)
  File "/home/ubuntu/C/RUN/./main.py", line 1086, in create_order
    return user_result
UnboundLocalError: local variable 'user_result' referenced before assignment
root - INFO - 2023-04-24 11:00:15.985312 - Order placement successful for users: []
root - INFO - 2023-04-24 11:05:15.967516 - Order placement successful for users: []
root - INFO - 2023-04-24 11:10:16.048808 - Order placement successful for users: []
root - INFO - 2023-04-24 11:15:16.077288 - Order placement successful for users: []
root - INFO - 2023-04-24 11:20:16.051217 - Order placement successful for users: []
root - INFO - 2023-04-24 11:25:16.067295 - Order placement successful for users: []
uvicorn.error - ERROR - Exception in ASGI application
Traceback (most recent call last):
  File "/home/ubuntu/.local/lib/python3.8/site-packages/uvicorn/protocols/http/h11_impl.py", line 373, in run_asgi
    result = await app(self.scope, self.receive, self.send)
  File "/home/ubuntu/.local/lib/python3.8/site-packages/uvicorn/middleware/proxy_headers.py", line 75, in __call__
    return await self.app(scope, receive, send)
  File "/home/ubuntu/.local/lib/python3.8/site-packages/fastapi/applications.py", line 208, in __call__
    await super().__call__(scope, receive, send)
  File "/home/ubuntu/.local/lib/python3.8/site-packages/starlette/applications.py", line 112, in __call__
    await self.middleware_stack(scope, receive, send)
  File "/home/ubuntu/.local/lib/python3.8/site-packages/starlette/middleware/errors.py", line 181, in __call__
    raise exc
  File "/home/ubuntu/.local/lib/python3.8/site-packages/starlette/middleware/errors.py", line 159, in __call__
    await self.app(scope, receive, _send)
  File "/home/ubuntu/.local/lib/python3.8/site-packages/starlette/middleware/cors.py", line 84, in __call__
    await self.app(scope, receive, send)
  File "/home/ubuntu/.local/lib/python3.8/site-packages/starlette/exceptions.py", line 82, in __call__
    raise exc
  File "/home/ubuntu/.local/lib/python3.8/site-packages/starlette/exceptions.py", line 71, in __call__
    await self.app(scope, receive, sender)
  File "/home/ubuntu/.local/lib/python3.8/site-packages/starlette/routing.py", line 656, in __call__
    await route.handle(scope, receive, send)
  File "/home/ubuntu/.local/lib/python3.8/site-packages/starlette/routing.py", line 259, in handle
    await self.app(scope, receive, send)
  File "/home/ubuntu/.local/lib/python3.8/site-packages/starlette/routing.py", line 61, in app
    response = await func(request)
  File "/home/ubuntu/.local/lib/python3.8/site-packages/fastapi/routing.py", line 226, in app
    raw_response = await run_endpoint_function(
  File "/home/ubuntu/.local/lib/python3.8/site-packages/fastapi/routing.py", line 159, in run_endpoint_function
    return await dependant.call(**values)
  File "/home/ubuntu/C/RUN/./main.py", line 1086, in create_order
    return user_result
UnboundLocalError: local variable 'user_result' referenced before assignment
root - INFO - 2023-04-24 11:25:17.858561 - Order placement successful for users: []
uvicorn.error - ERROR - Exception in ASGI application
Traceback (most recent call last):
  File "/home/ubuntu/.local/lib/python3.8/site-packages/uvicorn/protocols/http/h11_impl.py", line 373, in run_asgi
    result = await app(self.scope, self.receive, self.send)
  File "/home/ubuntu/.local/lib/python3.8/site-packages/uvicorn/middleware/proxy_headers.py", line 75, in __call__
    return await self.app(scope, receive, send)
  File "/home/ubuntu/.local/lib/python3.8/site-packages/fastapi/applications.py", line 208, in __call__
    await super().__call__(scope, receive, send)
  File "/home/ubuntu/.local/lib/python3.8/site-packages/starlette/applications.py", line 112, in __call__
    await self.middleware_stack(scope, receive, send)
  File "/home/ubuntu/.local/lib/python3.8/site-packages/starlette/middleware/errors.py", line 181, in __call__
    raise exc
  File "/home/ubuntu/.local/lib/python3.8/site-packages/starlette/middleware/errors.py", line 159, in __call__
    await self.app(scope, receive, _send)
  File "/home/ubuntu/.local/lib/python3.8/site-packages/starlette/middleware/cors.py", line 84, in __call__
    await self.app(scope, receive, send)
  File "/home/ubuntu/.local/lib/python3.8/site-packages/starlette/exceptions.py", line 82, in __call__
    raise exc
  File "/home/ubuntu/.local/lib/python3.8/site-packages/starlette/exceptions.py", line 71, in __call__
    await self.app(scope, receive, sender)
  File "/home/ubuntu/.local/lib/python3.8/site-packages/starlette/routing.py", line 656, in __call__
    await route.handle(scope, receive, send)
  File "/home/ubuntu/.local/lib/python3.8/site-packages/starlette/routing.py", line 259, in handle
    await self.app(scope, receive, send)
  File "/home/ubuntu/.local/lib/python3.8/site-packages/starlette/routing.py", line 61, in app
    response = await func(request)
  File "/home/ubuntu/.local/lib/python3.8/site-packages/fastapi/routing.py", line 226, in app
    raw_response = await run_endpoint_function(
  File "/home/ubuntu/.local/lib/python3.8/site-packages/fastapi/routing.py", line 159, in run_endpoint_function
    return await dependant.call(**values)
  File "/home/ubuntu/C/RUN/./main.py", line 1086, in create_order
    return user_result
UnboundLocalError: local variable 'user_result' referenced before assignment
root - INFO - 2023-04-24 11:30:16.028718 - Order placement successful for users: []
root - INFO - 2023-04-24 11:50:16.834286 - Order placement successful for users: []
uvicorn.error - ERROR - Exception in ASGI application
Traceback (most recent call last):
  File "/home/ubuntu/.local/lib/python3.8/site-packages/uvicorn/protocols/http/h11_impl.py", line 373, in run_asgi
    result = await app(self.scope, self.receive, self.send)
  File "/home/ubuntu/.local/lib/python3.8/site-packages/uvicorn/middleware/proxy_headers.py", line 75, in __call__
    return await self.app(scope, receive, send)
  File "/home/ubuntu/.local/lib/python3.8/site-packages/fastapi/applications.py", line 208, in __call__
    await super().__call__(scope, receive, send)
  File "/home/ubuntu/.local/lib/python3.8/site-packages/starlette/applications.py", line 112, in __call__
    await self.middleware_stack(scope, receive, send)
  File "/home/ubuntu/.local/lib/python3.8/site-packages/starlette/middleware/errors.py", line 181, in __call__
    raise exc
  File "/home/ubuntu/.local/lib/python3.8/site-packages/starlette/middleware/errors.py", line 159, in __call__
    await self.app(scope, receive, _send)
  File "/home/ubuntu/.local/lib/python3.8/site-packages/starlette/middleware/cors.py", line 84, in __call__
    await self.app(scope, receive, send)
  File "/home/ubuntu/.local/lib/python3.8/site-packages/starlette/exceptions.py", line 82, in __call__
    raise exc
  File "/home/ubuntu/.local/lib/python3.8/site-packages/starlette/exceptions.py", line 71, in __call__
    await self.app(scope, receive, sender)
  File "/home/ubuntu/.local/lib/python3.8/site-packages/starlette/routing.py", line 656, in __call__
    await route.handle(scope, receive, send)
  File "/home/ubuntu/.local/lib/python3.8/site-packages/starlette/routing.py", line 259, in handle
    await self.app(scope, receive, send)
  File "/home/ubuntu/.local/lib/python3.8/site-packages/starlette/routing.py", line 61, in app
    response = await func(request)
  File "/home/ubuntu/.local/lib/python3.8/site-packages/fastapi/routing.py", line 226, in app
    raw_response = await run_endpoint_function(
  File "/home/ubuntu/.local/lib/python3.8/site-packages/fastapi/routing.py", line 159, in run_endpoint_function
    return await dependant.call(**values)
  File "/home/ubuntu/C/RUN/./main.py", line 1086, in create_order
    return user_result
UnboundLocalError: local variable 'user_result' referenced before assignment
root - INFO - 2023-04-24 11:50:18.595969 - Order placement successful for users: []
uvicorn.error - ERROR - Exception in ASGI application
Traceback (most recent call last):
  File "/home/ubuntu/.local/lib/python3.8/site-packages/uvicorn/protocols/http/h11_impl.py", line 373, in run_asgi
    result = await app(self.scope, self.receive, self.send)
  File "/home/ubuntu/.local/lib/python3.8/site-packages/uvicorn/middleware/proxy_headers.py", line 75, in __call__
    return await self.app(scope, receive, send)
  File "/home/ubuntu/.local/lib/python3.8/site-packages/fastapi/applications.py", line 208, in __call__
    await super().__call__(scope, receive, send)
  File "/home/ubuntu/.local/lib/python3.8/site-packages/starlette/applications.py", line 112, in __call__
    await self.middleware_stack(scope, receive, send)
  File "/home/ubuntu/.local/lib/python3.8/site-packages/starlette/middleware/errors.py", line 181, in __call__
    raise exc
  File "/home/ubuntu/.local/lib/python3.8/site-packages/starlette/middleware/errors.py", line 159, in __call__
    await self.app(scope, receive, _send)
  File "/home/ubuntu/.local/lib/python3.8/site-packages/starlette/middleware/cors.py", line 84, in __call__
    await self.app(scope, receive, send)
  File "/home/ubuntu/.local/lib/python3.8/site-packages/starlette/exceptions.py", line 82, in __call__
    raise exc
  File "/home/ubuntu/.local/lib/python3.8/site-packages/starlette/exceptions.py", line 71, in __call__
    await self.app(scope, receive, sender)
  File "/home/ubuntu/.local/lib/python3.8/site-packages/starlette/routing.py", line 656, in __call__
    await route.handle(scope, receive, send)
  File "/home/ubuntu/.local/lib/python3.8/site-packages/starlette/routing.py", line 259, in handle
    await self.app(scope, receive, send)
  File "/home/ubuntu/.local/lib/python3.8/site-packages/starlette/routing.py", line 61, in app
    response = await func(request)
  File "/home/ubuntu/.local/lib/python3.8/site-packages/fastapi/routing.py", line 226, in app
    raw_response = await run_endpoint_function(
  File "/home/ubuntu/.local/lib/python3.8/site-packages/fastapi/routing.py", line 159, in run_endpoint_function
    return await dependant.call(**values)
  File "/home/ubuntu/C/RUN/./main.py", line 1086, in create_order
    return user_result
UnboundLocalError: local variable 'user_result' referenced before assignment
root - INFO - 2023-04-24 11:55:15.961330 - Order placed for FINVANT_LIVE QUASAR_5M NIFTY_SYNTHETIC_INTRADAY_SHORT BUY 2 0 0.5
root - INFO - 2023-04-24 11:55:16.030900 - Order placement successful for users: [{'user_name': 'FINVANT_LIVE', 'strategy': 'QUASAR_5M', 'instrument_nomenclature': 'NIFTY_SYNTHETIC_INTRADAY_SHORT', 'position': 'BUY', 'target': 0.5, 'stoploss': 0, 'quantity': 2}]
root - INFO - 2023-04-24 12:00:15.950404 - Order placement successful for users: []
root - INFO - 2023-04-24 12:05:15.946926 - Order placement successful for users: []
root - INFO - 2023-04-24 12:10:15.900840 - Order placement successful for users: []
root - INFO - 2023-04-24 12:15:15.877935 - Order placement successful for users: []
uvicorn.error - ERROR - Exception in ASGI application
Traceback (most recent call last):
  File "/home/ubuntu/.local/lib/python3.8/site-packages/uvicorn/protocols/http/h11_impl.py", line 373, in run_asgi
    result = await app(self.scope, self.receive, self.send)
  File "/home/ubuntu/.local/lib/python3.8/site-packages/uvicorn/middleware/proxy_headers.py", line 75, in __call__
    return await self.app(scope, receive, send)
  File "/home/ubuntu/.local/lib/python3.8/site-packages/fastapi/applications.py", line 208, in __call__
    await super().__call__(scope, receive, send)
  File "/home/ubuntu/.local/lib/python3.8/site-packages/starlette/applications.py", line 112, in __call__
    await self.middleware_stack(scope, receive, send)
  File "/home/ubuntu/.local/lib/python3.8/site-packages/starlette/middleware/errors.py", line 181, in __call__
    raise exc
  File "/home/ubuntu/.local/lib/python3.8/site-packages/starlette/middleware/errors.py", line 159, in __call__
    await self.app(scope, receive, _send)
  File "/home/ubuntu/.local/lib/python3.8/site-packages/starlette/middleware/cors.py", line 84, in __call__
    await self.app(scope, receive, send)
  File "/home/ubuntu/.local/lib/python3.8/site-packages/starlette/exceptions.py", line 82, in __call__
    raise exc
  File "/home/ubuntu/.local/lib/python3.8/site-packages/starlette/exceptions.py", line 71, in __call__
    await self.app(scope, receive, sender)
  File "/home/ubuntu/.local/lib/python3.8/site-packages/starlette/routing.py", line 656, in __call__
    await route.handle(scope, receive, send)
  File "/home/ubuntu/.local/lib/python3.8/site-packages/starlette/routing.py", line 259, in handle
    await self.app(scope, receive, send)
  File "/home/ubuntu/.local/lib/python3.8/site-packages/starlette/routing.py", line 61, in app
    response = await func(request)
  File "/home/ubuntu/.local/lib/python3.8/site-packages/fastapi/routing.py", line 226, in app
    raw_response = await run_endpoint_function(
  File "/home/ubuntu/.local/lib/python3.8/site-packages/fastapi/routing.py", line 159, in run_endpoint_function
    return await dependant.call(**values)
  File "/home/ubuntu/C/RUN/./main.py", line 1086, in create_order
    return user_result
UnboundLocalError: local variable 'user_result' referenced before assignment
root - INFO - 2023-04-24 12:15:17.218945 - Order placement successful for users: []
uvicorn.error - ERROR - Exception in ASGI application
Traceback (most recent call last):
  File "/home/ubuntu/.local/lib/python3.8/site-packages/uvicorn/protocols/http/h11_impl.py", line 373, in run_asgi
    result = await app(self.scope, self.receive, self.send)
  File "/home/ubuntu/.local/lib/python3.8/site-packages/uvicorn/middleware/proxy_headers.py", line 75, in __call__
    return await self.app(scope, receive, send)
  File "/home/ubuntu/.local/lib/python3.8/site-packages/fastapi/applications.py", line 208, in __call__
    await super().__call__(scope, receive, send)
  File "/home/ubuntu/.local/lib/python3.8/site-packages/starlette/applications.py", line 112, in __call__
    await self.middleware_stack(scope, receive, send)
  File "/home/ubuntu/.local/lib/python3.8/site-packages/starlette/middleware/errors.py", line 181, in __call__
    raise exc
  File "/home/ubuntu/.local/lib/python3.8/site-packages/starlette/middleware/errors.py", line 159, in __call__
    await self.app(scope, receive, _send)
  File "/home/ubuntu/.local/lib/python3.8/site-packages/starlette/middleware/cors.py", line 84, in __call__
    await self.app(scope, receive, send)
  File "/home/ubuntu/.local/lib/python3.8/site-packages/starlette/exceptions.py", line 82, in __call__
    raise exc
  File "/home/ubuntu/.local/lib/python3.8/site-packages/starlette/exceptions.py", line 71, in __call__
    await self.app(scope, receive, sender)
  File "/home/ubuntu/.local/lib/python3.8/site-packages/starlette/routing.py", line 656, in __call__
    await route.handle(scope, receive, send)
  File "/home/ubuntu/.local/lib/python3.8/site-packages/starlette/routing.py", line 259, in handle
    await self.app(scope, receive, send)
  File "/home/ubuntu/.local/lib/python3.8/site-packages/starlette/routing.py", line 61, in app
    response = await func(request)
  File "/home/ubuntu/.local/lib/python3.8/site-packages/fastapi/routing.py", line 226, in app
    raw_response = await run_endpoint_function(
  File "/home/ubuntu/.local/lib/python3.8/site-packages/fastapi/routing.py", line 159, in run_endpoint_function
    return await dependant.call(**values)
  File "/home/ubuntu/C/RUN/./main.py", line 1086, in create_order
    return user_result
UnboundLocalError: local variable 'user_result' referenced before assignment
root - INFO - 2023-04-24 12:20:15.930395 - Order placement successful for users: []
root - INFO - 2023-04-24 12:25:15.905780 - Order placement successful for users: []
root - INFO - 2023-04-24 12:30:15.936389 - Order placement successful for users: []
uvicorn.error - ERROR - Exception in ASGI application
Traceback (most recent call last):
  File "/home/ubuntu/.local/lib/python3.8/site-packages/uvicorn/protocols/http/h11_impl.py", line 373, in run_asgi
    result = await app(self.scope, self.receive, self.send)
  File "/home/ubuntu/.local/lib/python3.8/site-packages/uvicorn/middleware/proxy_headers.py", line 75, in __call__
    return await self.app(scope, receive, send)
  File "/home/ubuntu/.local/lib/python3.8/site-packages/fastapi/applications.py", line 208, in __call__
    await super().__call__(scope, receive, send)
  File "/home/ubuntu/.local/lib/python3.8/site-packages/starlette/applications.py", line 112, in __call__
    await self.middleware_stack(scope, receive, send)
  File "/home/ubuntu/.local/lib/python3.8/site-packages/starlette/middleware/errors.py", line 181, in __call__
    raise exc
  File "/home/ubuntu/.local/lib/python3.8/site-packages/starlette/middleware/errors.py", line 159, in __call__
    await self.app(scope, receive, _send)
  File "/home/ubuntu/.local/lib/python3.8/site-packages/starlette/middleware/cors.py", line 84, in __call__
    await self.app(scope, receive, send)
  File "/home/ubuntu/.local/lib/python3.8/site-packages/starlette/exceptions.py", line 82, in __call__
    raise exc
  File "/home/ubuntu/.local/lib/python3.8/site-packages/starlette/exceptions.py", line 71, in __call__
    await self.app(scope, receive, sender)
  File "/home/ubuntu/.local/lib/python3.8/site-packages/starlette/routing.py", line 656, in __call__
    await route.handle(scope, receive, send)
  File "/home/ubuntu/.local/lib/python3.8/site-packages/starlette/routing.py", line 259, in handle
    await self.app(scope, receive, send)
  File "/home/ubuntu/.local/lib/python3.8/site-packages/starlette/routing.py", line 61, in app
    response = await func(request)
  File "/home/ubuntu/.local/lib/python3.8/site-packages/fastapi/routing.py", line 226, in app
    raw_response = await run_endpoint_function(
  File "/home/ubuntu/.local/lib/python3.8/site-packages/fastapi/routing.py", line 159, in run_endpoint_function
    return await dependant.call(**values)
  File "/home/ubuntu/C/RUN/./main.py", line 1086, in create_order
    return user_result
UnboundLocalError: local variable 'user_result' referenced before assignment
root - INFO - 2023-04-24 12:30:17.348704 - Order placement successful for users: []
uvicorn.error - ERROR - Exception in ASGI application
Traceback (most recent call last):
  File "/home/ubuntu/.local/lib/python3.8/site-packages/uvicorn/protocols/http/h11_impl.py", line 373, in run_asgi
    result = await app(self.scope, self.receive, self.send)
  File "/home/ubuntu/.local/lib/python3.8/site-packages/uvicorn/middleware/proxy_headers.py", line 75, in __call__
    return await self.app(scope, receive, send)
  File "/home/ubuntu/.local/lib/python3.8/site-packages/fastapi/applications.py", line 208, in __call__
    await super().__call__(scope, receive, send)
  File "/home/ubuntu/.local/lib/python3.8/site-packages/starlette/applications.py", line 112, in __call__
    await self.middleware_stack(scope, receive, send)
  File "/home/ubuntu/.local/lib/python3.8/site-packages/starlette/middleware/errors.py", line 181, in __call__
    raise exc
  File "/home/ubuntu/.local/lib/python3.8/site-packages/starlette/middleware/errors.py", line 159, in __call__
    await self.app(scope, receive, _send)
  File "/home/ubuntu/.local/lib/python3.8/site-packages/starlette/middleware/cors.py", line 84, in __call__
    await self.app(scope, receive, send)
  File "/home/ubuntu/.local/lib/python3.8/site-packages/starlette/exceptions.py", line 82, in __call__
    raise exc
  File "/home/ubuntu/.local/lib/python3.8/site-packages/starlette/exceptions.py", line 71, in __call__
    await self.app(scope, receive, sender)
  File "/home/ubuntu/.local/lib/python3.8/site-packages/starlette/routing.py", line 656, in __call__
    await route.handle(scope, receive, send)
  File "/home/ubuntu/.local/lib/python3.8/site-packages/starlette/routing.py", line 259, in handle
    await self.app(scope, receive, send)
  File "/home/ubuntu/.local/lib/python3.8/site-packages/starlette/routing.py", line 61, in app
    response = await func(request)
  File "/home/ubuntu/.local/lib/python3.8/site-packages/fastapi/routing.py", line 226, in app
    raw_response = await run_endpoint_function(
  File "/home/ubuntu/.local/lib/python3.8/site-packages/fastapi/routing.py", line 159, in run_endpoint_function
    return await dependant.call(**values)
  File "/home/ubuntu/C/RUN/./main.py", line 1086, in create_order
    return user_result
UnboundLocalError: local variable 'user_result' referenced before assignment
root - INFO - 2023-04-24 12:35:15.894242 - Order placement successful for users: []
root - INFO - 2023-04-24 12:40:15.908461 - Order placement successful for users: []
root - INFO - 2023-04-24 12:45:15.960684 - Order placement successful for users: []
root - INFO - 2023-04-24 12:50:15.874720 - Order placement successful for users: []
root - INFO - 2023-04-24 12:55:15.855920 - Order placement successful for users: []
root - INFO - 2023-04-24 13:00:15.902526 - Order placement successful for users: []
uvicorn.error - ERROR - Exception in ASGI application
Traceback (most recent call last):
  File "/home/ubuntu/.local/lib/python3.8/site-packages/uvicorn/protocols/http/h11_impl.py", line 373, in run_asgi
    result = await app(self.scope, self.receive, self.send)
  File "/home/ubuntu/.local/lib/python3.8/site-packages/uvicorn/middleware/proxy_headers.py", line 75, in __call__
    return await self.app(scope, receive, send)
  File "/home/ubuntu/.local/lib/python3.8/site-packages/fastapi/applications.py", line 208, in __call__
    await super().__call__(scope, receive, send)
  File "/home/ubuntu/.local/lib/python3.8/site-packages/starlette/applications.py", line 112, in __call__
    await self.middleware_stack(scope, receive, send)
  File "/home/ubuntu/.local/lib/python3.8/site-packages/starlette/middleware/errors.py", line 181, in __call__
    raise exc
  File "/home/ubuntu/.local/lib/python3.8/site-packages/starlette/middleware/errors.py", line 159, in __call__
    await self.app(scope, receive, _send)
  File "/home/ubuntu/.local/lib/python3.8/site-packages/starlette/middleware/cors.py", line 84, in __call__
    await self.app(scope, receive, send)
  File "/home/ubuntu/.local/lib/python3.8/site-packages/starlette/exceptions.py", line 82, in __call__
    raise exc
  File "/home/ubuntu/.local/lib/python3.8/site-packages/starlette/exceptions.py", line 71, in __call__
    await self.app(scope, receive, sender)
  File "/home/ubuntu/.local/lib/python3.8/site-packages/starlette/routing.py", line 656, in __call__
    await route.handle(scope, receive, send)
  File "/home/ubuntu/.local/lib/python3.8/site-packages/starlette/routing.py", line 259, in handle
    await self.app(scope, receive, send)
  File "/home/ubuntu/.local/lib/python3.8/site-packages/starlette/routing.py", line 61, in app
    response = await func(request)
  File "/home/ubuntu/.local/lib/python3.8/site-packages/fastapi/routing.py", line 226, in app
    raw_response = await run_endpoint_function(
  File "/home/ubuntu/.local/lib/python3.8/site-packages/fastapi/routing.py", line 159, in run_endpoint_function
    return await dependant.call(**values)
  File "/home/ubuntu/C/RUN/./main.py", line 1086, in create_order
    return user_result
UnboundLocalError: local variable 'user_result' referenced before assignment
root - INFO - 2023-04-24 13:00:17.496313 - Order placement successful for users: []
uvicorn.error - ERROR - Exception in ASGI application
Traceback (most recent call last):
  File "/home/ubuntu/.local/lib/python3.8/site-packages/uvicorn/protocols/http/h11_impl.py", line 373, in run_asgi
    result = await app(self.scope, self.receive, self.send)
  File "/home/ubuntu/.local/lib/python3.8/site-packages/uvicorn/middleware/proxy_headers.py", line 75, in __call__
    return await self.app(scope, receive, send)
  File "/home/ubuntu/.local/lib/python3.8/site-packages/fastapi/applications.py", line 208, in __call__
    await super().__call__(scope, receive, send)
  File "/home/ubuntu/.local/lib/python3.8/site-packages/starlette/applications.py", line 112, in __call__
    await self.middleware_stack(scope, receive, send)
  File "/home/ubuntu/.local/lib/python3.8/site-packages/starlette/middleware/errors.py", line 181, in __call__
    raise exc
  File "/home/ubuntu/.local/lib/python3.8/site-packages/starlette/middleware/errors.py", line 159, in __call__
    await self.app(scope, receive, _send)
  File "/home/ubuntu/.local/lib/python3.8/site-packages/starlette/middleware/cors.py", line 84, in __call__
    await self.app(scope, receive, send)
  File "/home/ubuntu/.local/lib/python3.8/site-packages/starlette/exceptions.py", line 82, in __call__
    raise exc
  File "/home/ubuntu/.local/lib/python3.8/site-packages/starlette/exceptions.py", line 71, in __call__
    await self.app(scope, receive, sender)
  File "/home/ubuntu/.local/lib/python3.8/site-packages/starlette/routing.py", line 656, in __call__
    await route.handle(scope, receive, send)
  File "/home/ubuntu/.local/lib/python3.8/site-packages/starlette/routing.py", line 259, in handle
    await self.app(scope, receive, send)
  File "/home/ubuntu/.local/lib/python3.8/site-packages/starlette/routing.py", line 61, in app
    response = await func(request)
  File "/home/ubuntu/.local/lib/python3.8/site-packages/fastapi/routing.py", line 226, in app
    raw_response = await run_endpoint_function(
  File "/home/ubuntu/.local/lib/python3.8/site-packages/fastapi/routing.py", line 159, in run_endpoint_function
    return await dependant.call(**values)
  File "/home/ubuntu/C/RUN/./main.py", line 1086, in create_order
    return user_result
UnboundLocalError: local variable 'user_result' referenced before assignment
root - INFO - 2023-04-24 13:05:15.869591 - Order placement successful for users: []
uvicorn.error - ERROR - Exception in ASGI application
Traceback (most recent call last):
  File "/home/ubuntu/.local/lib/python3.8/site-packages/uvicorn/protocols/http/h11_impl.py", line 373, in run_asgi
    result = await app(self.scope, self.receive, self.send)
  File "/home/ubuntu/.local/lib/python3.8/site-packages/uvicorn/middleware/proxy_headers.py", line 75, in __call__
    return await self.app(scope, receive, send)
  File "/home/ubuntu/.local/lib/python3.8/site-packages/fastapi/applications.py", line 208, in __call__
    await super().__call__(scope, receive, send)
  File "/home/ubuntu/.local/lib/python3.8/site-packages/starlette/applications.py", line 112, in __call__
    await self.middleware_stack(scope, receive, send)
  File "/home/ubuntu/.local/lib/python3.8/site-packages/starlette/middleware/errors.py", line 181, in __call__
    raise exc
  File "/home/ubuntu/.local/lib/python3.8/site-packages/starlette/middleware/errors.py", line 159, in __call__
    await self.app(scope, receive, _send)
  File "/home/ubuntu/.local/lib/python3.8/site-packages/starlette/middleware/cors.py", line 84, in __call__
    await self.app(scope, receive, send)
  File "/home/ubuntu/.local/lib/python3.8/site-packages/starlette/exceptions.py", line 82, in __call__
    raise exc
  File "/home/ubuntu/.local/lib/python3.8/site-packages/starlette/exceptions.py", line 71, in __call__
    await self.app(scope, receive, sender)
  File "/home/ubuntu/.local/lib/python3.8/site-packages/starlette/routing.py", line 656, in __call__
    await route.handle(scope, receive, send)
  File "/home/ubuntu/.local/lib/python3.8/site-packages/starlette/routing.py", line 259, in handle
    await self.app(scope, receive, send)
  File "/home/ubuntu/.local/lib/python3.8/site-packages/starlette/routing.py", line 61, in app
    response = await func(request)
  File "/home/ubuntu/.local/lib/python3.8/site-packages/fastapi/routing.py", line 226, in app
    raw_response = await run_endpoint_function(
  File "/home/ubuntu/.local/lib/python3.8/site-packages/fastapi/routing.py", line 159, in run_endpoint_function
    return await dependant.call(**values)
  File "/home/ubuntu/C/RUN/./main.py", line 1086, in create_order
    return user_result
UnboundLocalError: local variable 'user_result' referenced before assignment
root - INFO - 2023-04-24 13:05:17.377538 - Order placement successful for users: []
uvicorn.error - ERROR - Exception in ASGI application
Traceback (most recent call last):
  File "/home/ubuntu/.local/lib/python3.8/site-packages/uvicorn/protocols/http/h11_impl.py", line 373, in run_asgi
    result = await app(self.scope, self.receive, self.send)
  File "/home/ubuntu/.local/lib/python3.8/site-packages/uvicorn/middleware/proxy_headers.py", line 75, in __call__
    return await self.app(scope, receive, send)
  File "/home/ubuntu/.local/lib/python3.8/site-packages/fastapi/applications.py", line 208, in __call__
    await super().__call__(scope, receive, send)
  File "/home/ubuntu/.local/lib/python3.8/site-packages/starlette/applications.py", line 112, in __call__
    await self.middleware_stack(scope, receive, send)
  File "/home/ubuntu/.local/lib/python3.8/site-packages/starlette/middleware/errors.py", line 181, in __call__
    raise exc
  File "/home/ubuntu/.local/lib/python3.8/site-packages/starlette/middleware/errors.py", line 159, in __call__
    await self.app(scope, receive, _send)
  File "/home/ubuntu/.local/lib/python3.8/site-packages/starlette/middleware/cors.py", line 84, in __call__
    await self.app(scope, receive, send)
  File "/home/ubuntu/.local/lib/python3.8/site-packages/starlette/exceptions.py", line 82, in __call__
    raise exc
  File "/home/ubuntu/.local/lib/python3.8/site-packages/starlette/exceptions.py", line 71, in __call__
    await self.app(scope, receive, sender)
  File "/home/ubuntu/.local/lib/python3.8/site-packages/starlette/routing.py", line 656, in __call__
    await route.handle(scope, receive, send)
  File "/home/ubuntu/.local/lib/python3.8/site-packages/starlette/routing.py", line 259, in handle
    await self.app(scope, receive, send)
  File "/home/ubuntu/.local/lib/python3.8/site-packages/starlette/routing.py", line 61, in app
    response = await func(request)
  File "/home/ubuntu/.local/lib/python3.8/site-packages/fastapi/routing.py", line 226, in app
    raw_response = await run_endpoint_function(
  File "/home/ubuntu/.local/lib/python3.8/site-packages/fastapi/routing.py", line 159, in run_endpoint_function
    return await dependant.call(**values)
  File "/home/ubuntu/C/RUN/./main.py", line 1086, in create_order
    return user_result
UnboundLocalError: local variable 'user_result' referenced before assignment
root - INFO - 2023-04-24 13:15:15.934194 - Order placement successful for users: []
uvicorn.error - ERROR - Exception in ASGI application
Traceback (most recent call last):
  File "/home/ubuntu/.local/lib/python3.8/site-packages/uvicorn/protocols/http/h11_impl.py", line 373, in run_asgi
    result = await app(self.scope, self.receive, self.send)
  File "/home/ubuntu/.local/lib/python3.8/site-packages/uvicorn/middleware/proxy_headers.py", line 75, in __call__
    return await self.app(scope, receive, send)
  File "/home/ubuntu/.local/lib/python3.8/site-packages/fastapi/applications.py", line 208, in __call__
    await super().__call__(scope, receive, send)
  File "/home/ubuntu/.local/lib/python3.8/site-packages/starlette/applications.py", line 112, in __call__
    await self.middleware_stack(scope, receive, send)
  File "/home/ubuntu/.local/lib/python3.8/site-packages/starlette/middleware/errors.py", line 181, in __call__
    raise exc
  File "/home/ubuntu/.local/lib/python3.8/site-packages/starlette/middleware/errors.py", line 159, in __call__
    await self.app(scope, receive, _send)
  File "/home/ubuntu/.local/lib/python3.8/site-packages/starlette/middleware/cors.py", line 84, in __call__
    await self.app(scope, receive, send)
  File "/home/ubuntu/.local/lib/python3.8/site-packages/starlette/exceptions.py", line 82, in __call__
    raise exc
  File "/home/ubuntu/.local/lib/python3.8/site-packages/starlette/exceptions.py", line 71, in __call__
    await self.app(scope, receive, sender)
  File "/home/ubuntu/.local/lib/python3.8/site-packages/starlette/routing.py", line 656, in __call__
    await route.handle(scope, receive, send)
  File "/home/ubuntu/.local/lib/python3.8/site-packages/starlette/routing.py", line 259, in handle
    await self.app(scope, receive, send)
  File "/home/ubuntu/.local/lib/python3.8/site-packages/starlette/routing.py", line 61, in app
    response = await func(request)
  File "/home/ubuntu/.local/lib/python3.8/site-packages/fastapi/routing.py", line 226, in app
    raw_response = await run_endpoint_function(
  File "/home/ubuntu/.local/lib/python3.8/site-packages/fastapi/routing.py", line 159, in run_endpoint_function
    return await dependant.call(**values)
  File "/home/ubuntu/C/RUN/./main.py", line 1086, in create_order
    return user_result
UnboundLocalError: local variable 'user_result' referenced before assignment
root - INFO - 2023-04-24 13:15:17.399422 - Order placement successful for users: []
uvicorn.error - ERROR - Exception in ASGI application
Traceback (most recent call last):
  File "/home/ubuntu/.local/lib/python3.8/site-packages/uvicorn/protocols/http/h11_impl.py", line 373, in run_asgi
    result = await app(self.scope, self.receive, self.send)
  File "/home/ubuntu/.local/lib/python3.8/site-packages/uvicorn/middleware/proxy_headers.py", line 75, in __call__
    return await self.app(scope, receive, send)
  File "/home/ubuntu/.local/lib/python3.8/site-packages/fastapi/applications.py", line 208, in __call__
    await super().__call__(scope, receive, send)
  File "/home/ubuntu/.local/lib/python3.8/site-packages/starlette/applications.py", line 112, in __call__
    await self.middleware_stack(scope, receive, send)
  File "/home/ubuntu/.local/lib/python3.8/site-packages/starlette/middleware/errors.py", line 181, in __call__
    raise exc
  File "/home/ubuntu/.local/lib/python3.8/site-packages/starlette/middleware/errors.py", line 159, in __call__
    await self.app(scope, receive, _send)
  File "/home/ubuntu/.local/lib/python3.8/site-packages/starlette/middleware/cors.py", line 84, in __call__
    await self.app(scope, receive, send)
  File "/home/ubuntu/.local/lib/python3.8/site-packages/starlette/exceptions.py", line 82, in __call__
    raise exc
  File "/home/ubuntu/.local/lib/python3.8/site-packages/starlette/exceptions.py", line 71, in __call__
    await self.app(scope, receive, sender)
  File "/home/ubuntu/.local/lib/python3.8/site-packages/starlette/routing.py", line 656, in __call__
    await route.handle(scope, receive, send)
  File "/home/ubuntu/.local/lib/python3.8/site-packages/starlette/routing.py", line 259, in handle
    await self.app(scope, receive, send)
  File "/home/ubuntu/.local/lib/python3.8/site-packages/starlette/routing.py", line 61, in app
    response = await func(request)
  File "/home/ubuntu/.local/lib/python3.8/site-packages/fastapi/routing.py", line 226, in app
    raw_response = await run_endpoint_function(
  File "/home/ubuntu/.local/lib/python3.8/site-packages/fastapi/routing.py", line 159, in run_endpoint_function
    return await dependant.call(**values)
  File "/home/ubuntu/C/RUN/./main.py", line 1086, in create_order
    return user_result
UnboundLocalError: local variable 'user_result' referenced before assignment
root - INFO - 2023-04-24 13:25:15.873074 - Order placement successful for users: []
uvicorn.error - ERROR - Exception in ASGI application
Traceback (most recent call last):
  File "/home/ubuntu/.local/lib/python3.8/site-packages/uvicorn/protocols/http/h11_impl.py", line 373, in run_asgi
    result = await app(self.scope, self.receive, self.send)
  File "/home/ubuntu/.local/lib/python3.8/site-packages/uvicorn/middleware/proxy_headers.py", line 75, in __call__
    return await self.app(scope, receive, send)
  File "/home/ubuntu/.local/lib/python3.8/site-packages/fastapi/applications.py", line 208, in __call__
    await super().__call__(scope, receive, send)
  File "/home/ubuntu/.local/lib/python3.8/site-packages/starlette/applications.py", line 112, in __call__
    await self.middleware_stack(scope, receive, send)
  File "/home/ubuntu/.local/lib/python3.8/site-packages/starlette/middleware/errors.py", line 181, in __call__
    raise exc
  File "/home/ubuntu/.local/lib/python3.8/site-packages/starlette/middleware/errors.py", line 159, in __call__
    await self.app(scope, receive, _send)
  File "/home/ubuntu/.local/lib/python3.8/site-packages/starlette/middleware/cors.py", line 84, in __call__
    await self.app(scope, receive, send)
  File "/home/ubuntu/.local/lib/python3.8/site-packages/starlette/exceptions.py", line 82, in __call__
    raise exc
  File "/home/ubuntu/.local/lib/python3.8/site-packages/starlette/exceptions.py", line 71, in __call__
    await self.app(scope, receive, sender)
  File "/home/ubuntu/.local/lib/python3.8/site-packages/starlette/routing.py", line 656, in __call__
    await route.handle(scope, receive, send)
  File "/home/ubuntu/.local/lib/python3.8/site-packages/starlette/routing.py", line 259, in handle
    await self.app(scope, receive, send)
  File "/home/ubuntu/.local/lib/python3.8/site-packages/starlette/routing.py", line 61, in app
    response = await func(request)
  File "/home/ubuntu/.local/lib/python3.8/site-packages/fastapi/routing.py", line 226, in app
    raw_response = await run_endpoint_function(
  File "/home/ubuntu/.local/lib/python3.8/site-packages/fastapi/routing.py", line 159, in run_endpoint_function
    return await dependant.call(**values)
  File "/home/ubuntu/C/RUN/./main.py", line 1086, in create_order
    return user_result
UnboundLocalError: local variable 'user_result' referenced before assignment
root - INFO - 2023-04-24 13:25:17.404078 - Order placement successful for users: []
uvicorn.error - ERROR - Exception in ASGI application
Traceback (most recent call last):
  File "/home/ubuntu/.local/lib/python3.8/site-packages/uvicorn/protocols/http/h11_impl.py", line 373, in run_asgi
    result = await app(self.scope, self.receive, self.send)
  File "/home/ubuntu/.local/lib/python3.8/site-packages/uvicorn/middleware/proxy_headers.py", line 75, in __call__
    return await self.app(scope, receive, send)
  File "/home/ubuntu/.local/lib/python3.8/site-packages/fastapi/applications.py", line 208, in __call__
    await super().__call__(scope, receive, send)
  File "/home/ubuntu/.local/lib/python3.8/site-packages/starlette/applications.py", line 112, in __call__
    await self.middleware_stack(scope, receive, send)
  File "/home/ubuntu/.local/lib/python3.8/site-packages/starlette/middleware/errors.py", line 181, in __call__
    raise exc
  File "/home/ubuntu/.local/lib/python3.8/site-packages/starlette/middleware/errors.py", line 159, in __call__
    await self.app(scope, receive, _send)
  File "/home/ubuntu/.local/lib/python3.8/site-packages/starlette/middleware/cors.py", line 84, in __call__
    await self.app(scope, receive, send)
  File "/home/ubuntu/.local/lib/python3.8/site-packages/starlette/exceptions.py", line 82, in __call__
    raise exc
  File "/home/ubuntu/.local/lib/python3.8/site-packages/starlette/exceptions.py", line 71, in __call__
    await self.app(scope, receive, sender)
  File "/home/ubuntu/.local/lib/python3.8/site-packages/starlette/routing.py", line 656, in __call__
    await route.handle(scope, receive, send)
  File "/home/ubuntu/.local/lib/python3.8/site-packages/starlette/routing.py", line 259, in handle
    await self.app(scope, receive, send)
  File "/home/ubuntu/.local/lib/python3.8/site-packages/starlette/routing.py", line 61, in app
    response = await func(request)
  File "/home/ubuntu/.local/lib/python3.8/site-packages/fastapi/routing.py", line 226, in app
    raw_response = await run_endpoint_function(
  File "/home/ubuntu/.local/lib/python3.8/site-packages/fastapi/routing.py", line 159, in run_endpoint_function
    return await dependant.call(**values)
  File "/home/ubuntu/C/RUN/./main.py", line 1086, in create_order
    return user_result
UnboundLocalError: local variable 'user_result' referenced before assignment
root - INFO - 2023-04-24 13:30:15.878096 - Order placement successful for users: []
uvicorn.error - ERROR - Exception in ASGI application
Traceback (most recent call last):
  File "/home/ubuntu/.local/lib/python3.8/site-packages/uvicorn/protocols/http/h11_impl.py", line 373, in run_asgi
    result = await app(self.scope, self.receive, self.send)
  File "/home/ubuntu/.local/lib/python3.8/site-packages/uvicorn/middleware/proxy_headers.py", line 75, in __call__
    return await self.app(scope, receive, send)
  File "/home/ubuntu/.local/lib/python3.8/site-packages/fastapi/applications.py", line 208, in __call__
    await super().__call__(scope, receive, send)
  File "/home/ubuntu/.local/lib/python3.8/site-packages/starlette/applications.py", line 112, in __call__
    await self.middleware_stack(scope, receive, send)
  File "/home/ubuntu/.local/lib/python3.8/site-packages/starlette/middleware/errors.py", line 181, in __call__
    raise exc
  File "/home/ubuntu/.local/lib/python3.8/site-packages/starlette/middleware/errors.py", line 159, in __call__
    await self.app(scope, receive, _send)
  File "/home/ubuntu/.local/lib/python3.8/site-packages/starlette/middleware/cors.py", line 84, in __call__
    await self.app(scope, receive, send)
  File "/home/ubuntu/.local/lib/python3.8/site-packages/starlette/exceptions.py", line 82, in __call__
    raise exc
  File "/home/ubuntu/.local/lib/python3.8/site-packages/starlette/exceptions.py", line 71, in __call__
    await self.app(scope, receive, sender)
  File "/home/ubuntu/.local/lib/python3.8/site-packages/starlette/routing.py", line 656, in __call__
    await route.handle(scope, receive, send)
  File "/home/ubuntu/.local/lib/python3.8/site-packages/starlette/routing.py", line 259, in handle
    await self.app(scope, receive, send)
  File "/home/ubuntu/.local/lib/python3.8/site-packages/starlette/routing.py", line 61, in app
    response = await func(request)
  File "/home/ubuntu/.local/lib/python3.8/site-packages/fastapi/routing.py", line 226, in app
    raw_response = await run_endpoint_function(
  File "/home/ubuntu/.local/lib/python3.8/site-packages/fastapi/routing.py", line 159, in run_endpoint_function
    return await dependant.call(**values)
  File "/home/ubuntu/C/RUN/./main.py", line 1086, in create_order
    return user_result
UnboundLocalError: local variable 'user_result' referenced before assignment
root - INFO - 2023-04-24 13:30:17.487427 - Order placement successful for users: []
uvicorn.error - ERROR - Exception in ASGI application
Traceback (most recent call last):
  File "/home/ubuntu/.local/lib/python3.8/site-packages/uvicorn/protocols/http/h11_impl.py", line 373, in run_asgi
    result = await app(self.scope, self.receive, self.send)
  File "/home/ubuntu/.local/lib/python3.8/site-packages/uvicorn/middleware/proxy_headers.py", line 75, in __call__
    return await self.app(scope, receive, send)
  File "/home/ubuntu/.local/lib/python3.8/site-packages/fastapi/applications.py", line 208, in __call__
    await super().__call__(scope, receive, send)
  File "/home/ubuntu/.local/lib/python3.8/site-packages/starlette/applications.py", line 112, in __call__
    await self.middleware_stack(scope, receive, send)
  File "/home/ubuntu/.local/lib/python3.8/site-packages/starlette/middleware/errors.py", line 181, in __call__
    raise exc
  File "/home/ubuntu/.local/lib/python3.8/site-packages/starlette/middleware/errors.py", line 159, in __call__
    await self.app(scope, receive, _send)
  File "/home/ubuntu/.local/lib/python3.8/site-packages/starlette/middleware/cors.py", line 84, in __call__
    await self.app(scope, receive, send)
  File "/home/ubuntu/.local/lib/python3.8/site-packages/starlette/exceptions.py", line 82, in __call__
    raise exc
  File "/home/ubuntu/.local/lib/python3.8/site-packages/starlette/exceptions.py", line 71, in __call__
    await self.app(scope, receive, sender)
  File "/home/ubuntu/.local/lib/python3.8/site-packages/starlette/routing.py", line 656, in __call__
    await route.handle(scope, receive, send)
  File "/home/ubuntu/.local/lib/python3.8/site-packages/starlette/routing.py", line 259, in handle
    await self.app(scope, receive, send)
  File "/home/ubuntu/.local/lib/python3.8/site-packages/starlette/routing.py", line 61, in app
    response = await func(request)
  File "/home/ubuntu/.local/lib/python3.8/site-packages/fastapi/routing.py", line 226, in app
    raw_response = await run_endpoint_function(
  File "/home/ubuntu/.local/lib/python3.8/site-packages/fastapi/routing.py", line 159, in run_endpoint_function
    return await dependant.call(**values)
  File "/home/ubuntu/C/RUN/./main.py", line 1086, in create_order
    return user_result
UnboundLocalError: local variable 'user_result' referenced before assignment
root - INFO - 2023-04-24 13:35:15.991656 - Order placed for MASTER_TRUST OPHIUCUS NIFTY|L|0|PE|WEEK|0 OPEN SHORT -10 0 0
root - INFO - 2023-04-24 13:35:16.060281 - Order placed for ODIN OPHIUCUS NIFTY|L|0|PE|WEEK|0 OPEN SHORT -1 0 0
root - INFO - 2023-04-24 13:35:16.129695 - Order placed for BPWealth_AHD083 OPHIUCUS NIFTY|L|0|PE|WEEK|0 OPEN SHORT -1 0 0
root - INFO - 2023-04-24 13:35:16.198050 - Order placed for BPWealth_ACS1301 OPHIUCUS NIFTY|L|0|PE|WEEK|0 OPEN SHORT -1 0 0
root - INFO - 2023-04-24 13:35:16.264949 - Order placed for BPWealth_ACS1207 OPHIUCUS NIFTY|L|0|PE|WEEK|0 OPEN SHORT -1 0 0
root - INFO - 2023-04-24 13:35:16.332196 - Order placed for BPWealth_AC66 OPHIUCUS NIFTY|L|0|PE|WEEK|0 OPEN SHORT -2 0 0
root - INFO - 2023-04-24 13:35:16.402977 - Order placed for FINVANT_LIVE OPHIUCUS_HEDGED OPHIUCUS_HEDGED_NIFTY_LONG BUY 1 0 0
root - INFO - 2023-04-24 13:35:16.472566 - Order placement successful for users: [{'user_name': 'MASTER_TRUST', 'strategy': 'OPHIUCUS', 'instrument_nomenclature': 'NIFTY|L|0|PE|WEEK|0', 'position': 'OPEN SHORT', 'target': 0, 'stoploss': 0, 'quantity': 10}, {'user_name': 'ODIN', 'strategy': 'OPHIUCUS', 'instrument_nomenclature': 'NIFTY|L|0|PE|WEEK|0', 'position': 'OPEN SHORT', 'target': 0, 'stoploss': 0, 'quantity': 1}, {'user_name': 'BPWealth_AHD083', 'strategy': 'OPHIUCUS', 'instrument_nomenclature': 'NIFTY|L|0|PE|WEEK|0', 'position': 'OPEN SHORT', 'target': 0, 'stoploss': 0, 'quantity': 1}, {'user_name': 'BPWealth_ACS1301', 'strategy': 'OPHIUCUS', 'instrument_nomenclature': 'NIFTY|L|0|PE|WEEK|0', 'position': 'OPEN SHORT', 'target': 0, 'stoploss': 0, 'quantity': 1}, {'user_name': 'BPWealth_ACS1207', 'strategy': 'OPHIUCUS', 'instrument_nomenclature': 'NIFTY|L|0|PE|WEEK|0', 'position': 'OPEN SHORT', 'target': 0, 'stoploss': 0, 'quantity': 1}, {'user_name': 'BPWealth_AC66', 'strategy': 'OPHIUCUS', 'instrument_nomenclature': 'NIFTY|L|0|PE|WEEK|0', 'position': 'OPEN SHORT', 'target': 0, 'stoploss': 0, 'quantity': 2}, {'user_name': 'FINVANT_LIVE', 'strategy': 'OPHIUCUS_HEDGED', 'instrument_nomenclature': 'OPHIUCUS_HEDGED_NIFTY_LONG', 'position': 'BUY', 'target': 0, 'stoploss': 0, 'quantity': 1}]
root - INFO - 2023-04-24 13:40:15.915632 - Order placement successful for users: []
root - INFO - 2023-04-24 13:45:15.920152 - Order placement successful for users: []
root - INFO - 2023-04-24 13:50:15.948464 - Order placement successful for users: []
root - INFO - 2023-04-24 13:55:16.862014 - Order placement successful for users: []
uvicorn.error - ERROR - Exception in ASGI application
Traceback (most recent call last):
  File "/home/ubuntu/.local/lib/python3.8/site-packages/uvicorn/protocols/http/h11_impl.py", line 373, in run_asgi
    result = await app(self.scope, self.receive, self.send)
  File "/home/ubuntu/.local/lib/python3.8/site-packages/uvicorn/middleware/proxy_headers.py", line 75, in __call__
    return await self.app(scope, receive, send)
  File "/home/ubuntu/.local/lib/python3.8/site-packages/fastapi/applications.py", line 208, in __call__
    await super().__call__(scope, receive, send)
  File "/home/ubuntu/.local/lib/python3.8/site-packages/starlette/applications.py", line 112, in __call__
    await self.middleware_stack(scope, receive, send)
  File "/home/ubuntu/.local/lib/python3.8/site-packages/starlette/middleware/errors.py", line 181, in __call__
    raise exc
  File "/home/ubuntu/.local/lib/python3.8/site-packages/starlette/middleware/errors.py", line 159, in __call__
    await self.app(scope, receive, _send)
  File "/home/ubuntu/.local/lib/python3.8/site-packages/starlette/middleware/cors.py", line 84, in __call__
    await self.app(scope, receive, send)
  File "/home/ubuntu/.local/lib/python3.8/site-packages/starlette/exceptions.py", line 82, in __call__
    raise exc
  File "/home/ubuntu/.local/lib/python3.8/site-packages/starlette/exceptions.py", line 71, in __call__
    await self.app(scope, receive, sender)
  File "/home/ubuntu/.local/lib/python3.8/site-packages/starlette/routing.py", line 656, in __call__
    await route.handle(scope, receive, send)
  File "/home/ubuntu/.local/lib/python3.8/site-packages/starlette/routing.py", line 259, in handle
    await self.app(scope, receive, send)
  File "/home/ubuntu/.local/lib/python3.8/site-packages/starlette/routing.py", line 61, in app
    response = await func(request)
  File "/home/ubuntu/.local/lib/python3.8/site-packages/fastapi/routing.py", line 226, in app
    raw_response = await run_endpoint_function(
  File "/home/ubuntu/.local/lib/python3.8/site-packages/fastapi/routing.py", line 159, in run_endpoint_function
    return await dependant.call(**values)
  File "/home/ubuntu/C/RUN/./main.py", line 1086, in create_order
    return user_result
UnboundLocalError: local variable 'user_result' referenced before assignment
root - INFO - 2023-04-24 13:55:18.295829 - Order placement successful for users: []
uvicorn.error - ERROR - Exception in ASGI application
Traceback (most recent call last):
  File "/home/ubuntu/.local/lib/python3.8/site-packages/uvicorn/protocols/http/h11_impl.py", line 373, in run_asgi
    result = await app(self.scope, self.receive, self.send)
  File "/home/ubuntu/.local/lib/python3.8/site-packages/uvicorn/middleware/proxy_headers.py", line 75, in __call__
    return await self.app(scope, receive, send)
  File "/home/ubuntu/.local/lib/python3.8/site-packages/fastapi/applications.py", line 208, in __call__
    await super().__call__(scope, receive, send)
  File "/home/ubuntu/.local/lib/python3.8/site-packages/starlette/applications.py", line 112, in __call__
    await self.middleware_stack(scope, receive, send)
  File "/home/ubuntu/.local/lib/python3.8/site-packages/starlette/middleware/errors.py", line 181, in __call__
    raise exc
  File "/home/ubuntu/.local/lib/python3.8/site-packages/starlette/middleware/errors.py", line 159, in __call__
    await self.app(scope, receive, _send)
  File "/home/ubuntu/.local/lib/python3.8/site-packages/starlette/middleware/cors.py", line 84, in __call__
    await self.app(scope, receive, send)
  File "/home/ubuntu/.local/lib/python3.8/site-packages/starlette/exceptions.py", line 82, in __call__
    raise exc
  File "/home/ubuntu/.local/lib/python3.8/site-packages/starlette/exceptions.py", line 71, in __call__
    await self.app(scope, receive, sender)
  File "/home/ubuntu/.local/lib/python3.8/site-packages/starlette/routing.py", line 656, in __call__
    await route.handle(scope, receive, send)
  File "/home/ubuntu/.local/lib/python3.8/site-packages/starlette/routing.py", line 259, in handle
    await self.app(scope, receive, send)
  File "/home/ubuntu/.local/lib/python3.8/site-packages/starlette/routing.py", line 61, in app
    response = await func(request)
  File "/home/ubuntu/.local/lib/python3.8/site-packages/fastapi/routing.py", line 226, in app
    raw_response = await run_endpoint_function(
  File "/home/ubuntu/.local/lib/python3.8/site-packages/fastapi/routing.py", line 159, in run_endpoint_function
    return await dependant.call(**values)
  File "/home/ubuntu/C/RUN/./main.py", line 1086, in create_order
    return user_result
UnboundLocalError: local variable 'user_result' referenced before assignment
root - INFO - 2023-04-24 14:00:16.029520 - Order placement successful for users: []
uvicorn.error - ERROR - Exception in ASGI application
Traceback (most recent call last):
  File "/home/ubuntu/.local/lib/python3.8/site-packages/uvicorn/protocols/http/h11_impl.py", line 373, in run_asgi
    result = await app(self.scope, self.receive, self.send)
  File "/home/ubuntu/.local/lib/python3.8/site-packages/uvicorn/middleware/proxy_headers.py", line 75, in __call__
    return await self.app(scope, receive, send)
  File "/home/ubuntu/.local/lib/python3.8/site-packages/fastapi/applications.py", line 208, in __call__
    await super().__call__(scope, receive, send)
  File "/home/ubuntu/.local/lib/python3.8/site-packages/starlette/applications.py", line 112, in __call__
    await self.middleware_stack(scope, receive, send)
  File "/home/ubuntu/.local/lib/python3.8/site-packages/starlette/middleware/errors.py", line 181, in __call__
    raise exc
  File "/home/ubuntu/.local/lib/python3.8/site-packages/starlette/middleware/errors.py", line 159, in __call__
    await self.app(scope, receive, _send)
  File "/home/ubuntu/.local/lib/python3.8/site-packages/starlette/middleware/cors.py", line 84, in __call__
    await self.app(scope, receive, send)
  File "/home/ubuntu/.local/lib/python3.8/site-packages/starlette/exceptions.py", line 82, in __call__
    raise exc
  File "/home/ubuntu/.local/lib/python3.8/site-packages/starlette/exceptions.py", line 71, in __call__
    await self.app(scope, receive, sender)
  File "/home/ubuntu/.local/lib/python3.8/site-packages/starlette/routing.py", line 656, in __call__
    await route.handle(scope, receive, send)
  File "/home/ubuntu/.local/lib/python3.8/site-packages/starlette/routing.py", line 259, in handle
    await self.app(scope, receive, send)
  File "/home/ubuntu/.local/lib/python3.8/site-packages/starlette/routing.py", line 61, in app
    response = await func(request)
  File "/home/ubuntu/.local/lib/python3.8/site-packages/fastapi/routing.py", line 226, in app
    raw_response = await run_endpoint_function(
  File "/home/ubuntu/.local/lib/python3.8/site-packages/fastapi/routing.py", line 159, in run_endpoint_function
    return await dependant.call(**values)
  File "/home/ubuntu/C/RUN/./main.py", line 1086, in create_order
    return user_result
UnboundLocalError: local variable 'user_result' referenced before assignment
root - INFO - 2023-04-24 14:00:17.731215 - Order placement successful for users: []
uvicorn.error - ERROR - Exception in ASGI application
Traceback (most recent call last):
  File "/home/ubuntu/.local/lib/python3.8/site-packages/uvicorn/protocols/http/h11_impl.py", line 373, in run_asgi
    result = await app(self.scope, self.receive, self.send)
  File "/home/ubuntu/.local/lib/python3.8/site-packages/uvicorn/middleware/proxy_headers.py", line 75, in __call__
    return await self.app(scope, receive, send)
  File "/home/ubuntu/.local/lib/python3.8/site-packages/fastapi/applications.py", line 208, in __call__
    await super().__call__(scope, receive, send)
  File "/home/ubuntu/.local/lib/python3.8/site-packages/starlette/applications.py", line 112, in __call__
    await self.middleware_stack(scope, receive, send)
  File "/home/ubuntu/.local/lib/python3.8/site-packages/starlette/middleware/errors.py", line 181, in __call__
    raise exc
  File "/home/ubuntu/.local/lib/python3.8/site-packages/starlette/middleware/errors.py", line 159, in __call__
    await self.app(scope, receive, _send)
  File "/home/ubuntu/.local/lib/python3.8/site-packages/starlette/middleware/cors.py", line 84, in __call__
    await self.app(scope, receive, send)
  File "/home/ubuntu/.local/lib/python3.8/site-packages/starlette/exceptions.py", line 82, in __call__
    raise exc
  File "/home/ubuntu/.local/lib/python3.8/site-packages/starlette/exceptions.py", line 71, in __call__
    await self.app(scope, receive, sender)
  File "/home/ubuntu/.local/lib/python3.8/site-packages/starlette/routing.py", line 656, in __call__
    await route.handle(scope, receive, send)
  File "/home/ubuntu/.local/lib/python3.8/site-packages/starlette/routing.py", line 259, in handle
    await self.app(scope, receive, send)
  File "/home/ubuntu/.local/lib/python3.8/site-packages/starlette/routing.py", line 61, in app
    response = await func(request)
  File "/home/ubuntu/.local/lib/python3.8/site-packages/fastapi/routing.py", line 226, in app
    raw_response = await run_endpoint_function(
  File "/home/ubuntu/.local/lib/python3.8/site-packages/fastapi/routing.py", line 159, in run_endpoint_function
    return await dependant.call(**values)
  File "/home/ubuntu/C/RUN/./main.py", line 1086, in create_order
    return user_result
UnboundLocalError: local variable 'user_result' referenced before assignment
root - INFO - 2023-04-24 14:05:16.362283 - Order placement successful for users: []
root - INFO - 2023-04-24 14:05:16.766711 - Order placement successful for users: []
root - INFO - 2023-04-24 14:10:16.395851 - Order placement successful for users: []
uvicorn.error - ERROR - Exception in ASGI application
Traceback (most recent call last):
  File "/home/ubuntu/.local/lib/python3.8/site-packages/uvicorn/protocols/http/h11_impl.py", line 373, in run_asgi
    result = await app(self.scope, self.receive, self.send)
  File "/home/ubuntu/.local/lib/python3.8/site-packages/uvicorn/middleware/proxy_headers.py", line 75, in __call__
    return await self.app(scope, receive, send)
  File "/home/ubuntu/.local/lib/python3.8/site-packages/fastapi/applications.py", line 208, in __call__
    await super().__call__(scope, receive, send)
  File "/home/ubuntu/.local/lib/python3.8/site-packages/starlette/applications.py", line 112, in __call__
    await self.middleware_stack(scope, receive, send)
  File "/home/ubuntu/.local/lib/python3.8/site-packages/starlette/middleware/errors.py", line 181, in __call__
    raise exc
  File "/home/ubuntu/.local/lib/python3.8/site-packages/starlette/middleware/errors.py", line 159, in __call__
    await self.app(scope, receive, _send)
  File "/home/ubuntu/.local/lib/python3.8/site-packages/starlette/middleware/cors.py", line 84, in __call__
    await self.app(scope, receive, send)
  File "/home/ubuntu/.local/lib/python3.8/site-packages/starlette/exceptions.py", line 82, in __call__
    raise exc
  File "/home/ubuntu/.local/lib/python3.8/site-packages/starlette/exceptions.py", line 71, in __call__
    await self.app(scope, receive, sender)
  File "/home/ubuntu/.local/lib/python3.8/site-packages/starlette/routing.py", line 656, in __call__
    await route.handle(scope, receive, send)
  File "/home/ubuntu/.local/lib/python3.8/site-packages/starlette/routing.py", line 259, in handle
    await self.app(scope, receive, send)
  File "/home/ubuntu/.local/lib/python3.8/site-packages/starlette/routing.py", line 61, in app
    response = await func(request)
  File "/home/ubuntu/.local/lib/python3.8/site-packages/fastapi/routing.py", line 226, in app
    raw_response = await run_endpoint_function(
  File "/home/ubuntu/.local/lib/python3.8/site-packages/fastapi/routing.py", line 159, in run_endpoint_function
    return await dependant.call(**values)
  File "/home/ubuntu/C/RUN/./main.py", line 1086, in create_order
    return user_result
UnboundLocalError: local variable 'user_result' referenced before assignment
root - INFO - 2023-04-24 14:10:16.801570 - Order placement successful for users: []
uvicorn.error - ERROR - Exception in ASGI application
Traceback (most recent call last):
  File "/home/ubuntu/.local/lib/python3.8/site-packages/uvicorn/protocols/http/h11_impl.py", line 373, in run_asgi
    result = await app(self.scope, self.receive, self.send)
  File "/home/ubuntu/.local/lib/python3.8/site-packages/uvicorn/middleware/proxy_headers.py", line 75, in __call__
    return await self.app(scope, receive, send)
  File "/home/ubuntu/.local/lib/python3.8/site-packages/fastapi/applications.py", line 208, in __call__
    await super().__call__(scope, receive, send)
  File "/home/ubuntu/.local/lib/python3.8/site-packages/starlette/applications.py", line 112, in __call__
    await self.middleware_stack(scope, receive, send)
  File "/home/ubuntu/.local/lib/python3.8/site-packages/starlette/middleware/errors.py", line 181, in __call__
    raise exc
  File "/home/ubuntu/.local/lib/python3.8/site-packages/starlette/middleware/errors.py", line 159, in __call__
    await self.app(scope, receive, _send)
  File "/home/ubuntu/.local/lib/python3.8/site-packages/starlette/middleware/cors.py", line 84, in __call__
    await self.app(scope, receive, send)
  File "/home/ubuntu/.local/lib/python3.8/site-packages/starlette/exceptions.py", line 82, in __call__
    raise exc
  File "/home/ubuntu/.local/lib/python3.8/site-packages/starlette/exceptions.py", line 71, in __call__
    await self.app(scope, receive, sender)
  File "/home/ubuntu/.local/lib/python3.8/site-packages/starlette/routing.py", line 656, in __call__
    await route.handle(scope, receive, send)
  File "/home/ubuntu/.local/lib/python3.8/site-packages/starlette/routing.py", line 259, in handle
    await self.app(scope, receive, send)
  File "/home/ubuntu/.local/lib/python3.8/site-packages/starlette/routing.py", line 61, in app
    response = await func(request)
  File "/home/ubuntu/.local/lib/python3.8/site-packages/fastapi/routing.py", line 226, in app
    raw_response = await run_endpoint_function(
  File "/home/ubuntu/.local/lib/python3.8/site-packages/fastapi/routing.py", line 159, in run_endpoint_function
    return await dependant.call(**values)
  File "/home/ubuntu/C/RUN/./main.py", line 1086, in create_order
    return user_result
UnboundLocalError: local variable 'user_result' referenced before assignment
root - INFO - 2023-04-24 14:10:18.782083 - Order placement successful for users: []
uvicorn.error - ERROR - Exception in ASGI application
Traceback (most recent call last):
  File "/home/ubuntu/.local/lib/python3.8/site-packages/uvicorn/protocols/http/h11_impl.py", line 373, in run_asgi
    result = await app(self.scope, self.receive, self.send)
  File "/home/ubuntu/.local/lib/python3.8/site-packages/uvicorn/middleware/proxy_headers.py", line 75, in __call__
    return await self.app(scope, receive, send)
  File "/home/ubuntu/.local/lib/python3.8/site-packages/fastapi/applications.py", line 208, in __call__
    await super().__call__(scope, receive, send)
  File "/home/ubuntu/.local/lib/python3.8/site-packages/starlette/applications.py", line 112, in __call__
    await self.middleware_stack(scope, receive, send)
  File "/home/ubuntu/.local/lib/python3.8/site-packages/starlette/middleware/errors.py", line 181, in __call__
    raise exc
  File "/home/ubuntu/.local/lib/python3.8/site-packages/starlette/middleware/errors.py", line 159, in __call__
    await self.app(scope, receive, _send)
  File "/home/ubuntu/.local/lib/python3.8/site-packages/starlette/middleware/cors.py", line 84, in __call__
    await self.app(scope, receive, send)
  File "/home/ubuntu/.local/lib/python3.8/site-packages/starlette/exceptions.py", line 82, in __call__
    raise exc
  File "/home/ubuntu/.local/lib/python3.8/site-packages/starlette/exceptions.py", line 71, in __call__
    await self.app(scope, receive, sender)
  File "/home/ubuntu/.local/lib/python3.8/site-packages/starlette/routing.py", line 656, in __call__
    await route.handle(scope, receive, send)
  File "/home/ubuntu/.local/lib/python3.8/site-packages/starlette/routing.py", line 259, in handle
    await self.app(scope, receive, send)
  File "/home/ubuntu/.local/lib/python3.8/site-packages/starlette/routing.py", line 61, in app
    response = await func(request)
  File "/home/ubuntu/.local/lib/python3.8/site-packages/fastapi/routing.py", line 226, in app
    raw_response = await run_endpoint_function(
  File "/home/ubuntu/.local/lib/python3.8/site-packages/fastapi/routing.py", line 159, in run_endpoint_function
    return await dependant.call(**values)
  File "/home/ubuntu/C/RUN/./main.py", line 1086, in create_order
    return user_result
UnboundLocalError: local variable 'user_result' referenced before assignment
root - INFO - 2023-04-24 14:10:19.579661 - Order placement successful for users: []
uvicorn.error - ERROR - Exception in ASGI application
Traceback (most recent call last):
  File "/home/ubuntu/.local/lib/python3.8/site-packages/uvicorn/protocols/http/h11_impl.py", line 373, in run_asgi
    result = await app(self.scope, self.receive, self.send)
  File "/home/ubuntu/.local/lib/python3.8/site-packages/uvicorn/middleware/proxy_headers.py", line 75, in __call__
    return await self.app(scope, receive, send)
  File "/home/ubuntu/.local/lib/python3.8/site-packages/fastapi/applications.py", line 208, in __call__
    await super().__call__(scope, receive, send)
  File "/home/ubuntu/.local/lib/python3.8/site-packages/starlette/applications.py", line 112, in __call__
    await self.middleware_stack(scope, receive, send)
  File "/home/ubuntu/.local/lib/python3.8/site-packages/starlette/middleware/errors.py", line 181, in __call__
    raise exc
  File "/home/ubuntu/.local/lib/python3.8/site-packages/starlette/middleware/errors.py", line 159, in __call__
    await self.app(scope, receive, _send)
  File "/home/ubuntu/.local/lib/python3.8/site-packages/starlette/middleware/cors.py", line 84, in __call__
    await self.app(scope, receive, send)
  File "/home/ubuntu/.local/lib/python3.8/site-packages/starlette/exceptions.py", line 82, in __call__
    raise exc
  File "/home/ubuntu/.local/lib/python3.8/site-packages/starlette/exceptions.py", line 71, in __call__
    await self.app(scope, receive, sender)
  File "/home/ubuntu/.local/lib/python3.8/site-packages/starlette/routing.py", line 656, in __call__
    await route.handle(scope, receive, send)
  File "/home/ubuntu/.local/lib/python3.8/site-packages/starlette/routing.py", line 259, in handle
    await self.app(scope, receive, send)
  File "/home/ubuntu/.local/lib/python3.8/site-packages/starlette/routing.py", line 61, in app
    response = await func(request)
  File "/home/ubuntu/.local/lib/python3.8/site-packages/fastapi/routing.py", line 226, in app
    raw_response = await run_endpoint_function(
  File "/home/ubuntu/.local/lib/python3.8/site-packages/fastapi/routing.py", line 159, in run_endpoint_function
    return await dependant.call(**values)
  File "/home/ubuntu/C/RUN/./main.py", line 1086, in create_order
    return user_result
UnboundLocalError: local variable 'user_result' referenced before assignment
root - INFO - 2023-04-24 14:15:16.066230 - Order placement successful for users: []
root - INFO - 2023-04-24 14:15:16.811573 - Order placement successful for users: []
uvicorn.error - ERROR - Exception in ASGI application
Traceback (most recent call last):
  File "/home/ubuntu/.local/lib/python3.8/site-packages/uvicorn/protocols/http/h11_impl.py", line 373, in run_asgi
    result = await app(self.scope, self.receive, self.send)
  File "/home/ubuntu/.local/lib/python3.8/site-packages/uvicorn/middleware/proxy_headers.py", line 75, in __call__
    return await self.app(scope, receive, send)
  File "/home/ubuntu/.local/lib/python3.8/site-packages/fastapi/applications.py", line 208, in __call__
    await super().__call__(scope, receive, send)
  File "/home/ubuntu/.local/lib/python3.8/site-packages/starlette/applications.py", line 112, in __call__
    await self.middleware_stack(scope, receive, send)
  File "/home/ubuntu/.local/lib/python3.8/site-packages/starlette/middleware/errors.py", line 181, in __call__
    raise exc
  File "/home/ubuntu/.local/lib/python3.8/site-packages/starlette/middleware/errors.py", line 159, in __call__
    await self.app(scope, receive, _send)
  File "/home/ubuntu/.local/lib/python3.8/site-packages/starlette/middleware/cors.py", line 84, in __call__
    await self.app(scope, receive, send)
  File "/home/ubuntu/.local/lib/python3.8/site-packages/starlette/exceptions.py", line 82, in __call__
    raise exc
  File "/home/ubuntu/.local/lib/python3.8/site-packages/starlette/exceptions.py", line 71, in __call__
    await self.app(scope, receive, sender)
  File "/home/ubuntu/.local/lib/python3.8/site-packages/starlette/routing.py", line 656, in __call__
    await route.handle(scope, receive, send)
  File "/home/ubuntu/.local/lib/python3.8/site-packages/starlette/routing.py", line 259, in handle
    await self.app(scope, receive, send)
  File "/home/ubuntu/.local/lib/python3.8/site-packages/starlette/routing.py", line 61, in app
    response = await func(request)
  File "/home/ubuntu/.local/lib/python3.8/site-packages/fastapi/routing.py", line 226, in app
    raw_response = await run_endpoint_function(
  File "/home/ubuntu/.local/lib/python3.8/site-packages/fastapi/routing.py", line 159, in run_endpoint_function
    return await dependant.call(**values)
  File "/home/ubuntu/C/RUN/./main.py", line 1086, in create_order
    return user_result
UnboundLocalError: local variable 'user_result' referenced before assignment
root - INFO - 2023-04-24 14:15:18.514220 - Order placement successful for users: []
uvicorn.error - ERROR - Exception in ASGI application
Traceback (most recent call last):
  File "/home/ubuntu/.local/lib/python3.8/site-packages/uvicorn/protocols/http/h11_impl.py", line 373, in run_asgi
    result = await app(self.scope, self.receive, self.send)
  File "/home/ubuntu/.local/lib/python3.8/site-packages/uvicorn/middleware/proxy_headers.py", line 75, in __call__
    return await self.app(scope, receive, send)
  File "/home/ubuntu/.local/lib/python3.8/site-packages/fastapi/applications.py", line 208, in __call__
    await super().__call__(scope, receive, send)
  File "/home/ubuntu/.local/lib/python3.8/site-packages/starlette/applications.py", line 112, in __call__
    await self.middleware_stack(scope, receive, send)
  File "/home/ubuntu/.local/lib/python3.8/site-packages/starlette/middleware/errors.py", line 181, in __call__
    raise exc
  File "/home/ubuntu/.local/lib/python3.8/site-packages/starlette/middleware/errors.py", line 159, in __call__
    await self.app(scope, receive, _send)
  File "/home/ubuntu/.local/lib/python3.8/site-packages/starlette/middleware/cors.py", line 84, in __call__
    await self.app(scope, receive, send)
  File "/home/ubuntu/.local/lib/python3.8/site-packages/starlette/exceptions.py", line 82, in __call__
    raise exc
  File "/home/ubuntu/.local/lib/python3.8/site-packages/starlette/exceptions.py", line 71, in __call__
    await self.app(scope, receive, sender)
  File "/home/ubuntu/.local/lib/python3.8/site-packages/starlette/routing.py", line 656, in __call__
    await route.handle(scope, receive, send)
  File "/home/ubuntu/.local/lib/python3.8/site-packages/starlette/routing.py", line 259, in handle
    await self.app(scope, receive, send)
  File "/home/ubuntu/.local/lib/python3.8/site-packages/starlette/routing.py", line 61, in app
    response = await func(request)
  File "/home/ubuntu/.local/lib/python3.8/site-packages/fastapi/routing.py", line 226, in app
    raw_response = await run_endpoint_function(
  File "/home/ubuntu/.local/lib/python3.8/site-packages/fastapi/routing.py", line 159, in run_endpoint_function
    return await dependant.call(**values)
  File "/home/ubuntu/C/RUN/./main.py", line 1086, in create_order
    return user_result
UnboundLocalError: local variable 'user_result' referenced before assignment
root - INFO - 2023-04-24 14:20:16.430799 - Order placement successful for users: []
root - INFO - 2023-04-24 14:20:16.828555 - Order placement successful for users: []
root - INFO - 2023-04-24 14:25:16.343772 - Order placement successful for users: []
root - INFO - 2023-04-24 14:25:16.741601 - Order placement successful for users: []
uvicorn.error - ERROR - Exception in ASGI application
Traceback (most recent call last):
  File "/home/ubuntu/.local/lib/python3.8/site-packages/uvicorn/protocols/http/h11_impl.py", line 373, in run_asgi
    result = await app(self.scope, self.receive, self.send)
  File "/home/ubuntu/.local/lib/python3.8/site-packages/uvicorn/middleware/proxy_headers.py", line 75, in __call__
    return await self.app(scope, receive, send)
  File "/home/ubuntu/.local/lib/python3.8/site-packages/fastapi/applications.py", line 208, in __call__
    await super().__call__(scope, receive, send)
  File "/home/ubuntu/.local/lib/python3.8/site-packages/starlette/applications.py", line 112, in __call__
    await self.middleware_stack(scope, receive, send)
  File "/home/ubuntu/.local/lib/python3.8/site-packages/starlette/middleware/errors.py", line 181, in __call__
    raise exc
  File "/home/ubuntu/.local/lib/python3.8/site-packages/starlette/middleware/errors.py", line 159, in __call__
    await self.app(scope, receive, _send)
  File "/home/ubuntu/.local/lib/python3.8/site-packages/starlette/middleware/cors.py", line 84, in __call__
    await self.app(scope, receive, send)
  File "/home/ubuntu/.local/lib/python3.8/site-packages/starlette/exceptions.py", line 82, in __call__
    raise exc
  File "/home/ubuntu/.local/lib/python3.8/site-packages/starlette/exceptions.py", line 71, in __call__
    await self.app(scope, receive, sender)
  File "/home/ubuntu/.local/lib/python3.8/site-packages/starlette/routing.py", line 656, in __call__
    await route.handle(scope, receive, send)
  File "/home/ubuntu/.local/lib/python3.8/site-packages/starlette/routing.py", line 259, in handle
    await self.app(scope, receive, send)
  File "/home/ubuntu/.local/lib/python3.8/site-packages/starlette/routing.py", line 61, in app
    response = await func(request)
  File "/home/ubuntu/.local/lib/python3.8/site-packages/fastapi/routing.py", line 226, in app
    raw_response = await run_endpoint_function(
  File "/home/ubuntu/.local/lib/python3.8/site-packages/fastapi/routing.py", line 159, in run_endpoint_function
    return await dependant.call(**values)
  File "/home/ubuntu/C/RUN/./main.py", line 1086, in create_order
    return user_result
UnboundLocalError: local variable 'user_result' referenced before assignment
root - INFO - 2023-04-24 14:25:18.276347 - Order placement successful for users: []
uvicorn.error - ERROR - Exception in ASGI application
Traceback (most recent call last):
  File "/home/ubuntu/.local/lib/python3.8/site-packages/uvicorn/protocols/http/h11_impl.py", line 373, in run_asgi
    result = await app(self.scope, self.receive, self.send)
  File "/home/ubuntu/.local/lib/python3.8/site-packages/uvicorn/middleware/proxy_headers.py", line 75, in __call__
    return await self.app(scope, receive, send)
  File "/home/ubuntu/.local/lib/python3.8/site-packages/fastapi/applications.py", line 208, in __call__
    await super().__call__(scope, receive, send)
  File "/home/ubuntu/.local/lib/python3.8/site-packages/starlette/applications.py", line 112, in __call__
    await self.middleware_stack(scope, receive, send)
  File "/home/ubuntu/.local/lib/python3.8/site-packages/starlette/middleware/errors.py", line 181, in __call__
    raise exc
  File "/home/ubuntu/.local/lib/python3.8/site-packages/starlette/middleware/errors.py", line 159, in __call__
    await self.app(scope, receive, _send)
  File "/home/ubuntu/.local/lib/python3.8/site-packages/starlette/middleware/cors.py", line 84, in __call__
    await self.app(scope, receive, send)
  File "/home/ubuntu/.local/lib/python3.8/site-packages/starlette/exceptions.py", line 82, in __call__
    raise exc
  File "/home/ubuntu/.local/lib/python3.8/site-packages/starlette/exceptions.py", line 71, in __call__
    await self.app(scope, receive, sender)
  File "/home/ubuntu/.local/lib/python3.8/site-packages/starlette/routing.py", line 656, in __call__
    await route.handle(scope, receive, send)
  File "/home/ubuntu/.local/lib/python3.8/site-packages/starlette/routing.py", line 259, in handle
    await self.app(scope, receive, send)
  File "/home/ubuntu/.local/lib/python3.8/site-packages/starlette/routing.py", line 61, in app
    response = await func(request)
  File "/home/ubuntu/.local/lib/python3.8/site-packages/fastapi/routing.py", line 226, in app
    raw_response = await run_endpoint_function(
  File "/home/ubuntu/.local/lib/python3.8/site-packages/fastapi/routing.py", line 159, in run_endpoint_function
    return await dependant.call(**values)
  File "/home/ubuntu/C/RUN/./main.py", line 1086, in create_order
    return user_result
UnboundLocalError: local variable 'user_result' referenced before assignment
root - INFO - 2023-04-24 14:30:15.998882 - Order placement successful for users: []
uvicorn.error - ERROR - Exception in ASGI application
Traceback (most recent call last):
  File "/home/ubuntu/.local/lib/python3.8/site-packages/uvicorn/protocols/http/h11_impl.py", line 373, in run_asgi
    result = await app(self.scope, self.receive, self.send)
  File "/home/ubuntu/.local/lib/python3.8/site-packages/uvicorn/middleware/proxy_headers.py", line 75, in __call__
    return await self.app(scope, receive, send)
  File "/home/ubuntu/.local/lib/python3.8/site-packages/fastapi/applications.py", line 208, in __call__
    await super().__call__(scope, receive, send)
  File "/home/ubuntu/.local/lib/python3.8/site-packages/starlette/applications.py", line 112, in __call__
    await self.middleware_stack(scope, receive, send)
  File "/home/ubuntu/.local/lib/python3.8/site-packages/starlette/middleware/errors.py", line 181, in __call__
    raise exc
  File "/home/ubuntu/.local/lib/python3.8/site-packages/starlette/middleware/errors.py", line 159, in __call__
    await self.app(scope, receive, _send)
  File "/home/ubuntu/.local/lib/python3.8/site-packages/starlette/middleware/cors.py", line 84, in __call__
    await self.app(scope, receive, send)
  File "/home/ubuntu/.local/lib/python3.8/site-packages/starlette/exceptions.py", line 82, in __call__
    raise exc
  File "/home/ubuntu/.local/lib/python3.8/site-packages/starlette/exceptions.py", line 71, in __call__
    await self.app(scope, receive, sender)
  File "/home/ubuntu/.local/lib/python3.8/site-packages/starlette/routing.py", line 656, in __call__
    await route.handle(scope, receive, send)
  File "/home/ubuntu/.local/lib/python3.8/site-packages/starlette/routing.py", line 259, in handle
    await self.app(scope, receive, send)
  File "/home/ubuntu/.local/lib/python3.8/site-packages/starlette/routing.py", line 61, in app
    response = await func(request)
  File "/home/ubuntu/.local/lib/python3.8/site-packages/fastapi/routing.py", line 226, in app
    raw_response = await run_endpoint_function(
  File "/home/ubuntu/.local/lib/python3.8/site-packages/fastapi/routing.py", line 159, in run_endpoint_function
    return await dependant.call(**values)
  File "/home/ubuntu/C/RUN/./main.py", line 1086, in create_order
    return user_result
UnboundLocalError: local variable 'user_result' referenced before assignment
root - INFO - 2023-04-24 14:30:16.742485 - Order placement successful for users: []
uvicorn.error - ERROR - Exception in ASGI application
Traceback (most recent call last):
  File "/home/ubuntu/.local/lib/python3.8/site-packages/uvicorn/protocols/http/h11_impl.py", line 373, in run_asgi
    result = await app(self.scope, self.receive, self.send)
  File "/home/ubuntu/.local/lib/python3.8/site-packages/uvicorn/middleware/proxy_headers.py", line 75, in __call__
    return await self.app(scope, receive, send)
  File "/home/ubuntu/.local/lib/python3.8/site-packages/fastapi/applications.py", line 208, in __call__
    await super().__call__(scope, receive, send)
  File "/home/ubuntu/.local/lib/python3.8/site-packages/starlette/applications.py", line 112, in __call__
    await self.middleware_stack(scope, receive, send)
  File "/home/ubuntu/.local/lib/python3.8/site-packages/starlette/middleware/errors.py", line 181, in __call__
    raise exc
  File "/home/ubuntu/.local/lib/python3.8/site-packages/starlette/middleware/errors.py", line 159, in __call__
    await self.app(scope, receive, _send)
  File "/home/ubuntu/.local/lib/python3.8/site-packages/starlette/middleware/cors.py", line 84, in __call__
    await self.app(scope, receive, send)
  File "/home/ubuntu/.local/lib/python3.8/site-packages/starlette/exceptions.py", line 82, in __call__
    raise exc
  File "/home/ubuntu/.local/lib/python3.8/site-packages/starlette/exceptions.py", line 71, in __call__
    await self.app(scope, receive, sender)
  File "/home/ubuntu/.local/lib/python3.8/site-packages/starlette/routing.py", line 656, in __call__
    await route.handle(scope, receive, send)
  File "/home/ubuntu/.local/lib/python3.8/site-packages/starlette/routing.py", line 259, in handle
    await self.app(scope, receive, send)
  File "/home/ubuntu/.local/lib/python3.8/site-packages/starlette/routing.py", line 61, in app
    response = await func(request)
  File "/home/ubuntu/.local/lib/python3.8/site-packages/fastapi/routing.py", line 226, in app
    raw_response = await run_endpoint_function(
  File "/home/ubuntu/.local/lib/python3.8/site-packages/fastapi/routing.py", line 159, in run_endpoint_function
    return await dependant.call(**values)
  File "/home/ubuntu/C/RUN/./main.py", line 1086, in create_order
    return user_result
UnboundLocalError: local variable 'user_result' referenced before assignment
root - INFO - 2023-04-24 14:30:18.514695 - Order placement successful for users: []
uvicorn.error - ERROR - Exception in ASGI application
Traceback (most recent call last):
  File "/home/ubuntu/.local/lib/python3.8/site-packages/uvicorn/protocols/http/h11_impl.py", line 373, in run_asgi
    result = await app(self.scope, self.receive, self.send)
  File "/home/ubuntu/.local/lib/python3.8/site-packages/uvicorn/middleware/proxy_headers.py", line 75, in __call__
    return await self.app(scope, receive, send)
  File "/home/ubuntu/.local/lib/python3.8/site-packages/fastapi/applications.py", line 208, in __call__
    await super().__call__(scope, receive, send)
  File "/home/ubuntu/.local/lib/python3.8/site-packages/starlette/applications.py", line 112, in __call__
    await self.middleware_stack(scope, receive, send)
  File "/home/ubuntu/.local/lib/python3.8/site-packages/starlette/middleware/errors.py", line 181, in __call__
    raise exc
  File "/home/ubuntu/.local/lib/python3.8/site-packages/starlette/middleware/errors.py", line 159, in __call__
    await self.app(scope, receive, _send)
  File "/home/ubuntu/.local/lib/python3.8/site-packages/starlette/middleware/cors.py", line 84, in __call__
    await self.app(scope, receive, send)
  File "/home/ubuntu/.local/lib/python3.8/site-packages/starlette/exceptions.py", line 82, in __call__
    raise exc
  File "/home/ubuntu/.local/lib/python3.8/site-packages/starlette/exceptions.py", line 71, in __call__
    await self.app(scope, receive, sender)
  File "/home/ubuntu/.local/lib/python3.8/site-packages/starlette/routing.py", line 656, in __call__
    await route.handle(scope, receive, send)
  File "/home/ubuntu/.local/lib/python3.8/site-packages/starlette/routing.py", line 259, in handle
    await self.app(scope, receive, send)
  File "/home/ubuntu/.local/lib/python3.8/site-packages/starlette/routing.py", line 61, in app
    response = await func(request)
  File "/home/ubuntu/.local/lib/python3.8/site-packages/fastapi/routing.py", line 226, in app
    raw_response = await run_endpoint_function(
  File "/home/ubuntu/.local/lib/python3.8/site-packages/fastapi/routing.py", line 159, in run_endpoint_function
    return await dependant.call(**values)
  File "/home/ubuntu/C/RUN/./main.py", line 1086, in create_order
    return user_result
UnboundLocalError: local variable 'user_result' referenced before assignment
root - INFO - 2023-04-24 14:30:19.323239 - Order placement successful for users: []
uvicorn.error - ERROR - Exception in ASGI application
Traceback (most recent call last):
  File "/home/ubuntu/.local/lib/python3.8/site-packages/uvicorn/protocols/http/h11_impl.py", line 373, in run_asgi
    result = await app(self.scope, self.receive, self.send)
  File "/home/ubuntu/.local/lib/python3.8/site-packages/uvicorn/middleware/proxy_headers.py", line 75, in __call__
    return await self.app(scope, receive, send)
  File "/home/ubuntu/.local/lib/python3.8/site-packages/fastapi/applications.py", line 208, in __call__
    await super().__call__(scope, receive, send)
  File "/home/ubuntu/.local/lib/python3.8/site-packages/starlette/applications.py", line 112, in __call__
    await self.middleware_stack(scope, receive, send)
  File "/home/ubuntu/.local/lib/python3.8/site-packages/starlette/middleware/errors.py", line 181, in __call__
    raise exc
  File "/home/ubuntu/.local/lib/python3.8/site-packages/starlette/middleware/errors.py", line 159, in __call__
    await self.app(scope, receive, _send)
  File "/home/ubuntu/.local/lib/python3.8/site-packages/starlette/middleware/cors.py", line 84, in __call__
    await self.app(scope, receive, send)
  File "/home/ubuntu/.local/lib/python3.8/site-packages/starlette/exceptions.py", line 82, in __call__
    raise exc
  File "/home/ubuntu/.local/lib/python3.8/site-packages/starlette/exceptions.py", line 71, in __call__
    await self.app(scope, receive, sender)
  File "/home/ubuntu/.local/lib/python3.8/site-packages/starlette/routing.py", line 656, in __call__
    await route.handle(scope, receive, send)
  File "/home/ubuntu/.local/lib/python3.8/site-packages/starlette/routing.py", line 259, in handle
    await self.app(scope, receive, send)
  File "/home/ubuntu/.local/lib/python3.8/site-packages/starlette/routing.py", line 61, in app
    response = await func(request)
  File "/home/ubuntu/.local/lib/python3.8/site-packages/fastapi/routing.py", line 226, in app
    raw_response = await run_endpoint_function(
  File "/home/ubuntu/.local/lib/python3.8/site-packages/fastapi/routing.py", line 159, in run_endpoint_function
    return await dependant.call(**values)
  File "/home/ubuntu/C/RUN/./main.py", line 1086, in create_order
    return user_result
UnboundLocalError: local variable 'user_result' referenced before assignment
root - INFO - 2023-04-24 14:35:16.330828 - Order placement successful for users: []
root - INFO - 2023-04-24 14:35:16.728294 - Order placement successful for users: []
root - INFO - 2023-04-24 14:40:16.332309 - Order placement successful for users: []
root - INFO - 2023-04-24 14:40:16.731798 - Order placement successful for users: []
root - INFO - 2023-04-24 14:45:16.471851 - Order placement successful for users: []
root - INFO - 2023-04-24 14:45:16.870658 - Order placement successful for users: []
root - INFO - 2023-04-24 14:50:16.367954 - Order placement successful for users: []
root - INFO - 2023-04-24 14:50:16.769060 - Order placement successful for users: []
root - INFO - 2023-04-24 14:55:16.012112 - Order placement successful for users: []
root - INFO - 2023-04-24 15:20:16.368090 - Order placed for MASTER_TRUST OPHIUCUS NIFTY|L|0|PE|WEEK|0 CLOSE SHORT -10 0 0
root - INFO - 2023-04-24 15:20:16.439747 - Order placed for ODIN OPHIUCUS NIFTY|L|0|PE|WEEK|0 CLOSE SHORT -1 0 0
root - INFO - 2023-04-24 15:20:16.560741 - Order placed for BPWealth_AHD083 OPHIUCUS NIFTY|L|0|PE|WEEK|0 CLOSE SHORT -1 0 0
root - INFO - 2023-04-24 15:20:16.628595 - Order placed for BPWealth_ACS1301 OPHIUCUS NIFTY|L|0|PE|WEEK|0 CLOSE SHORT -1 0 0
root - INFO - 2023-04-24 15:20:16.695548 - Order placed for BPWealth_ACS1207 OPHIUCUS NIFTY|L|0|PE|WEEK|0 CLOSE SHORT -1 0 0
root - INFO - 2023-04-24 15:20:16.762804 - Order placed for BPWealth_AC66 OPHIUCUS NIFTY|L|0|PE|WEEK|0 CLOSE SHORT -2 0 0
root - INFO - 2023-04-24 15:20:16.834656 - Order placed for FINVANT_LIVE OPHIUCUS_HEDGED OPHIUCUS_HEDGED_NIFTY_LONG SELL 1 0 0
root - INFO - 2023-04-24 15:20:16.902558 - Order placement successful for users: [{'user_name': 'MASTER_TRUST', 'strategy': 'OPHIUCUS', 'instrument_nomenclature': 'NIFTY|L|0|PE|WEEK|0', 'position': 'CLOSE SHORT', 'target': 0, 'stoploss': 0}, {'user_name': 'ODIN', 'strategy': 'OPHIUCUS', 'instrument_nomenclature': 'NIFTY|L|0|PE|WEEK|0', 'position': 'CLOSE SHORT', 'target': 0, 'stoploss': 0}, {'user_name': 'BPWealth_AHD083', 'strategy': 'OPHIUCUS', 'instrument_nomenclature': 'NIFTY|L|0|PE|WEEK|0', 'position': 'CLOSE SHORT', 'target': 0, 'stoploss': 0}, {'user_name': 'BPWealth_ACS1301', 'strategy': 'OPHIUCUS', 'instrument_nomenclature': 'NIFTY|L|0|PE|WEEK|0', 'position': 'CLOSE SHORT', 'target': 0, 'stoploss': 0}, {'user_name': 'BPWealth_ACS1207', 'strategy': 'OPHIUCUS', 'instrument_nomenclature': 'NIFTY|L|0|PE|WEEK|0', 'position': 'CLOSE SHORT', 'target': 0, 'stoploss': 0}, {'user_name': 'BPWealth_AC66', 'strategy': 'OPHIUCUS', 'instrument_nomenclature': 'NIFTY|L|0|PE|WEEK|0', 'position': 'CLOSE SHORT', 'target': 0, 'stoploss': 0}, {'user_name': 'FINVANT_LIVE', 'strategy': 'OPHIUCUS_HEDGED', 'instrument_nomenclature': 'OPHIUCUS_HEDGED_NIFTY_LONG', 'position': 'SELL', 'target': 0, 'stoploss': 0}]
root - INFO - 2023-04-24 15:20:17.675562 - Order placed for MASTER_TRUST OPHIUCUS NIFTY|L|0|PE|WEEK|0 CLOSE SHORT -10 0 0
root - INFO - 2023-04-24 15:20:17.977715 - Order placed for ODIN OPHIUCUS NIFTY|L|0|PE|WEEK|0 CLOSE SHORT -1 0 0
root - INFO - 2023-04-24 15:20:18.158262 - Order placed for BPWealth_AHD083 OPHIUCUS NIFTY|L|0|PE|WEEK|0 CLOSE SHORT -1 0 0
root - INFO - 2023-04-24 15:20:18.224014 - Order placed for BPWealth_ACS1301 OPHIUCUS NIFTY|L|0|PE|WEEK|0 CLOSE SHORT -1 0 0
uvicorn.error - ERROR - Exception in ASGI application
Traceback (most recent call last):
  File "/home/ubuntu/.local/lib/python3.8/site-packages/uvicorn/protocols/http/h11_impl.py", line 373, in run_asgi
    result = await app(self.scope, self.receive, self.send)
  File "/home/ubuntu/.local/lib/python3.8/site-packages/uvicorn/middleware/proxy_headers.py", line 75, in __call__
    return await self.app(scope, receive, send)
  File "/home/ubuntu/.local/lib/python3.8/site-packages/fastapi/applications.py", line 208, in __call__
    await super().__call__(scope, receive, send)
  File "/home/ubuntu/.local/lib/python3.8/site-packages/starlette/applications.py", line 112, in __call__
    await self.middleware_stack(scope, receive, send)
  File "/home/ubuntu/.local/lib/python3.8/site-packages/starlette/middleware/errors.py", line 181, in __call__
    raise exc
  File "/home/ubuntu/.local/lib/python3.8/site-packages/starlette/middleware/errors.py", line 159, in __call__
    await self.app(scope, receive, _send)
  File "/home/ubuntu/.local/lib/python3.8/site-packages/starlette/middleware/cors.py", line 84, in __call__
    await self.app(scope, receive, send)
  File "/home/ubuntu/.local/lib/python3.8/site-packages/starlette/exceptions.py", line 82, in __call__
    raise exc
  File "/home/ubuntu/.local/lib/python3.8/site-packages/starlette/exceptions.py", line 71, in __call__
    await self.app(scope, receive, sender)
  File "/home/ubuntu/.local/lib/python3.8/site-packages/starlette/routing.py", line 656, in __call__
    await route.handle(scope, receive, send)
  File "/home/ubuntu/.local/lib/python3.8/site-packages/starlette/routing.py", line 259, in handle
    await self.app(scope, receive, send)
  File "/home/ubuntu/.local/lib/python3.8/site-packages/starlette/routing.py", line 61, in app
    response = await func(request)
  File "/home/ubuntu/.local/lib/python3.8/site-packages/fastapi/routing.py", line 226, in app
    raw_response = await run_endpoint_function(
  File "/home/ubuntu/.local/lib/python3.8/site-packages/fastapi/routing.py", line 159, in run_endpoint_function
    return await dependant.call(**values)
  File "/home/ubuntu/C/RUN/./main.py", line 1060, in create_order
    row = list(cur.execute(query).fetchall()[0])
IndexError: list index out of range
root - INFO - 2023-04-24 15:20:19.742368 - Order placement successful for users: []
root - INFO - 2023-04-24 15:25:16.409923 - Order placement successful for users: []
root - INFO - 2023-04-24 15:25:16.812798 - Order placement successful for users: []
root - INFO - 2023-04-24 18:10:00.691674 - Order placed for MASTER_TRUST OPHIUCUS NIFTY|L|0|CE|WEEK|0 OPEN SHORT -10 0 0
root - INFO - 2023-04-24 18:10:00.804333 - Order placed for ODIN OPHIUCUS NIFTY|L|0|CE|WEEK|0 OPEN SHORT -1 0 0
root - INFO - 2023-04-24 18:10:00.886117 - Order placed for BPWealth_AHD083 OPHIUCUS NIFTY|L|0|CE|WEEK|0 OPEN SHORT -1 0 0
root - INFO - 2023-04-24 18:10:01.026992 - Order placed for BPWealth_ACS1301 OPHIUCUS NIFTY|L|0|CE|WEEK|0 OPEN SHORT -1 0 0
root - INFO - 2023-04-24 18:10:01.166892 - Order placed for BPWealth_ACS1207 OPHIUCUS NIFTY|L|0|CE|WEEK|0 OPEN SHORT -1 0 0
root - INFO - 2023-04-24 18:10:01.295135 - Order placed for BPWealth_AC66 OPHIUCUS NIFTY|L|0|CE|WEEK|0 OPEN SHORT -2 0 0
root - INFO - 2023-04-24 18:10:01.399186 - Order placement successful for users: [{'user_name': 'MASTER_TRUST', 'strategy': 'OPHIUCUS', 'instrument_nomenclature': 'NIFTY|L|0|CE|WEEK|0', 'position': 'OPEN SHORT', 'target': 0, 'stoploss': 0, 'quantity': 10}, {'user_name': 'ODIN', 'strategy': 'OPHIUCUS', 'instrument_nomenclature': 'NIFTY|L|0|CE|WEEK|0', 'position': 'OPEN SHORT', 'target': 0, 'stoploss': 0, 'quantity': 1}, {'user_name': 'BPWealth_AHD083', 'strategy': 'OPHIUCUS', 'instrument_nomenclature': 'NIFTY|L|0|CE|WEEK|0', 'position': 'OPEN SHORT', 'target': 0, 'stoploss': 0, 'quantity': 1}, {'user_name': 'BPWealth_ACS1301', 'strategy': 'OPHIUCUS', 'instrument_nomenclature': 'NIFTY|L|0|CE|WEEK|0', 'position': 'OPEN SHORT', 'target': 0, 'stoploss': 0, 'quantity': 1}, {'user_name': 'BPWealth_ACS1207', 'strategy': 'OPHIUCUS', 'instrument_nomenclature': 'NIFTY|L|0|CE|WEEK|0', 'position': 'OPEN SHORT', 'target': 0, 'stoploss': 0, 'quantity': 1}, {'user_name': 'BPWealth_AC66', 'strategy': 'OPHIUCUS', 'instrument_nomenclature': 'NIFTY|L|0|CE|WEEK|0', 'position': 'OPEN SHORT', 'target': 0, 'stoploss': 0, 'quantity': 2}]
root - INFO - 2023-04-24 18:10:01.954197 - Order placed for MASTER_TRUST OPHIUCUS NIFTY|L|0|CE|WEEK|0 OPEN SHORT -10 0 0
root - INFO - 2023-04-24 18:10:02.100459 - Order placed for ODIN OPHIUCUS NIFTY|L|0|CE|WEEK|0 OPEN SHORT -1 0 0
root - INFO - 2023-04-24 18:10:02.352626 - Order placed for BPWealth_AHD083 OPHIUCUS NIFTY|L|0|CE|WEEK|0 OPEN SHORT -1 0 0
root - INFO - 2023-04-24 18:10:02.510748 - Order placed for BPWealth_ACS1301 OPHIUCUS NIFTY|L|0|CE|WEEK|0 OPEN SHORT -1 0 0
root - INFO - 2023-04-24 18:10:02.621137 - Order placed for BPWealth_ACS1207 OPHIUCUS NIFTY|L|0|CE|WEEK|0 OPEN SHORT -1 0 0
root - INFO - 2023-04-24 18:10:02.717308 - Order placement successful for users: [{'user_name': 'MASTER_TRUST', 'strategy': 'OPHIUCUS', 'instrument_nomenclature': 'NIFTY|L|0|CE|WEEK|0', 'position': 'OPEN SHORT', 'target': 0, 'stoploss': 0, 'quantity': 10}, {'user_name': 'ODIN', 'strategy': 'OPHIUCUS', 'instrument_nomenclature': 'NIFTY|L|0|CE|WEEK|0', 'position': 'OPEN SHORT', 'target': 0, 'stoploss': 0, 'quantity': 1}, {'user_name': 'BPWealth_AHD083', 'strategy': 'OPHIUCUS', 'instrument_nomenclature': 'NIFTY|L|0|CE|WEEK|0', 'position': 'OPEN SHORT', 'target': 0, 'stoploss': 0, 'quantity': 1}, {'user_name': 'BPWealth_ACS1301', 'strategy': 'OPHIUCUS', 'instrument_nomenclature': 'NIFTY|L|0|CE|WEEK|0', 'position': 'OPEN SHORT', 'target': 0, 'stoploss': 0, 'quantity': 1}, {'user_name': 'BPWealth_ACS1207', 'strategy': 'OPHIUCUS', 'instrument_nomenclature': 'NIFTY|L|0|CE|WEEK|0', 'position': 'OPEN SHORT', 'target': 0, 'stoploss': 0, 'quantity': 1}]
root - INFO - 2023-04-24 18:10:03.402832 - Order placed for ODIN OPHIUCUS NIFTY|L|0|CE|WEEK|0 OPEN SHORT -1 0 0
root - INFO - 2023-04-24 18:10:03.535976 - Order placed for BPWealth_AHD083 OPHIUCUS NIFTY|L|0|CE|WEEK|0 OPEN SHORT -1 0 0
root - INFO - 2023-04-24 18:10:03.692243 - Order placement successful for users: [{'user_name': 'MASTER_TRUST', 'strategy': 'OPHIUCUS', 'instrument_nomenclature': 'NIFTY|L|0|CE|WEEK|0', 'position': 'OPEN SHORT', 'target': 0, 'stoploss': 0, 'quantity': 10}, {'user_name': 'ODIN', 'strategy': 'OPHIUCUS', 'instrument_nomenclature': 'NIFTY|L|0|CE|WEEK|0', 'position': 'OPEN SHORT', 'target': 0, 'stoploss': 0, 'quantity': 1}, {'user_name': 'BPWealth_AHD083', 'strategy': 'OPHIUCUS', 'instrument_nomenclature': 'NIFTY|L|0|CE|WEEK|0', 'position': 'OPEN SHORT', 'target': 0, 'stoploss': 0, 'quantity': 1}]
root - INFO - 2023-04-24 18:11:58.896600 - Order placed for ODIN OPHIUCUS NIFTY|L|0|CE|WEEK|0 CLOSE SHORT -1 0 0
root - INFO - 2023-04-24 18:11:59.034111 - Order placed for BPWealth_AHD083 OPHIUCUS NIFTY|L|0|CE|WEEK|0 CLOSE SHORT -1 0 0
root - INFO - 2023-04-24 18:11:59.179688 - Order placed for BPWealth_ACS1301 OPHIUCUS NIFTY|L|0|CE|WEEK|0 CLOSE SHORT -1 0 0
root - INFO - 2023-04-24 18:11:59.351838 - Order placed for BPWealth_ACS1207 OPHIUCUS NIFTY|L|0|CE|WEEK|0 CLOSE SHORT -1 0 0
root - INFO - 2023-04-24 18:11:59.512705 - Order placed for BPWealth_AC66 OPHIUCUS NIFTY|L|0|CE|WEEK|0 CLOSE SHORT -2 0 0
root - INFO - 2023-04-24 18:11:59.638814 - Order placement successful for users: [{'user_name': 'ODIN', 'strategy': 'OPHIUCUS', 'instrument_nomenclature': 'NIFTY|L|0|CE|WEEK|0', 'position': 'CLOSE SHORT', 'target': 0, 'stoploss': 0}, {'user_name': 'BPWealth_AHD083', 'strategy': 'OPHIUCUS', 'instrument_nomenclature': 'NIFTY|L|0|CE|WEEK|0', 'position': 'CLOSE SHORT', 'target': 0, 'stoploss': 0}, {'user_name': 'BPWealth_ACS1301', 'strategy': 'OPHIUCUS', 'instrument_nomenclature': 'NIFTY|L|0|CE|WEEK|0', 'position': 'CLOSE SHORT', 'target': 0, 'stoploss': 0}, {'user_name': 'BPWealth_ACS1207', 'strategy': 'OPHIUCUS', 'instrument_nomenclature': 'NIFTY|L|0|CE|WEEK|0', 'position': 'CLOSE SHORT', 'target': 0, 'stoploss': 0}, {'user_name': 'BPWealth_AC66', 'strategy': 'OPHIUCUS', 'instrument_nomenclature': 'NIFTY|L|0|CE|WEEK|0', 'position': 'CLOSE SHORT', 'target': 0, 'stoploss': 0}]
root - INFO - 2023-04-24 18:12:01.171934 - Order placement successful for users: []
root - INFO - 2023-04-24 18:12:01.665342 - Order placement successful for users: []
root - INFO - 2023-04-24 18:15:11.285447 - Order placed for MASTER_TRUST OPHIUCUS NIFTY|L|0|CE|WEEK|0 CLOSE SHORT -10 0 0
root - INFO - 2023-04-24 18:15:11.353381 - Order placement successful for users: [{'user_name': 'MASTER_TRUST', 'strategy': 'OPHIUCUS', 'instrument_nomenclature': 'NIFTY|L|0|CE|WEEK|0', 'position': 'CLOSE SHORT', 'target': 0, 'stoploss': 0}]
root - INFO - 2023-04-24 18:19:22.655711 - Order placed for BPWealth_AC66 OPHIUCUS NIFTY|L|0|CE|WEEK|0 OPEN SHORT -2 0 0
root - INFO - 2023-04-24 18:19:22.754501 - Order placement successful for users: [{'user_name': 'BPWealth_AC66', 'strategy': 'OPHIUCUS', 'instrument_nomenclature': 'NIFTY|L|0|CE|WEEK|0', 'position': 'OPEN SHORT', 'target': 0, 'stoploss': 0, 'quantity': 2}]
uvicorn.error - INFO - Shutting down
uvicorn.error - INFO - Waiting for application shutdown.
tortoise - INFO - Tortoise-ORM shutdown
tortoise - INFO - Tortoise-ORM shutdown
uvicorn.error - INFO - Application shutdown complete.
uvicorn.error - INFO - Finished server process [55480]
root - INFO - 2023-04-24 18:22:40.358447 - OMS Server turned on.
uvicorn.error - INFO - Started server process [60915]
uvicorn.error - INFO - Waiting for application startup.
tortoise - INFO - Tortoise-ORM started, {'default': <tortoise.backends.sqlite.client.SqliteClient object at 0x7f1ca8bd1f40>}, {'models': {'OptionSpread': <class 'models.OptionSpread'>, 'User': <class 'models.User'>, 'User_Finvant': <class 'models.User_Finvant'>}}
tortoise - INFO - Tortoise-ORM generating schema
uvicorn.error - INFO - Application startup complete.
uvicorn.error - INFO - Uvicorn running on http://0.0.0.0:9093 (Press CTRL+C to quit)
root - INFO - 2023-04-24 18:23:06.590067 - Order placed for MASTER_TRUST OPHIUCUS NIFTY|L|0|CE|WEEK|0 OPEN SHORT -10 0 0
root - INFO - 2023-04-24 18:23:06.656307 - Order placed for ODIN OPHIUCUS NIFTY|L|0|CE|WEEK|0 OPEN SHORT -1 0 0
root - INFO - 2023-04-24 18:23:06.721963 - Order placed for BPWealth_AHD083 OPHIUCUS NIFTY|L|0|CE|WEEK|0 OPEN SHORT -1 0 0
root - INFO - 2023-04-24 18:23:06.787401 - Order placed for BPWealth_ACS1301 OPHIUCUS NIFTY|L|0|CE|WEEK|0 OPEN SHORT -1 0 0
root - INFO - 2023-04-24 18:23:06.853429 - Order placed for BPWealth_ACS1207 OPHIUCUS NIFTY|L|0|CE|WEEK|0 OPEN SHORT -1 0 0
root - INFO - 2023-04-24 18:23:06.944073 - Order placed for BPWealth_AC66 OPHIUCUS NIFTY|L|0|CE|WEEK|0 OPEN SHORT -2 0 0
root - INFO - 2023-04-24 18:23:07.026479 - Order placement successful for users: [{'user_name': 'MASTER_TRUST', 'strategy': 'OPHIUCUS', 'instrument_nomenclature': 'NIFTY|L|0|CE|WEEK|0', 'position': 'OPEN SHORT', 'target': 0, 'stoploss': 0, 'quantity': 10}, {'user_name': 'ODIN', 'strategy': 'OPHIUCUS', 'instrument_nomenclature': 'NIFTY|L|0|CE|WEEK|0', 'position': 'OPEN SHORT', 'target': 0, 'stoploss': 0, 'quantity': 1}, {'user_name': 'BPWealth_AHD083', 'strategy': 'OPHIUCUS', 'instrument_nomenclature': 'NIFTY|L|0|CE|WEEK|0', 'position': 'OPEN SHORT', 'target': 0, 'stoploss': 0, 'quantity': 1}, {'user_name': 'BPWealth_ACS1301', 'strategy': 'OPHIUCUS', 'instrument_nomenclature': 'NIFTY|L|0|CE|WEEK|0', 'position': 'OPEN SHORT', 'target': 0, 'stoploss': 0, 'quantity': 1}, {'user_name': 'BPWealth_ACS1207', 'strategy': 'OPHIUCUS', 'instrument_nomenclature': 'NIFTY|L|0|CE|WEEK|0', 'position': 'OPEN SHORT', 'target': 0, 'stoploss': 0, 'quantity': 1}, {'user_name': 'BPWealth_AC66', 'strategy': 'OPHIUCUS', 'instrument_nomenclature': 'NIFTY|L|0|CE|WEEK|0', 'position': 'OPEN SHORT', 'target': 0, 'stoploss': 0, 'quantity': 2}]
root - INFO - 2023-04-24 18:23:07.427438 - Order placed for MASTER_TRUST OPHIUCUS NIFTY|L|0|CE|WEEK|0 OPEN SHORT -10 0 0
root - INFO - 2023-04-24 18:23:07.509951 - Order placed for ODIN OPHIUCUS NIFTY|L|0|CE|WEEK|0 OPEN SHORT -1 0 0
root - INFO - 2023-04-24 18:23:07.596969 - Order placed for BPWealth_AHD083 OPHIUCUS NIFTY|L|0|CE|WEEK|0 OPEN SHORT -1 0 0
root - INFO - 2023-04-24 18:23:07.662858 - Order placed for BPWealth_ACS1301 OPHIUCUS NIFTY|L|0|CE|WEEK|0 OPEN SHORT -1 0 0
root - INFO - 2023-04-24 18:23:07.748609 - Order placed for BPWealth_ACS1207 OPHIUCUS NIFTY|L|0|CE|WEEK|0 OPEN SHORT -1 0 0
root - INFO - 2023-04-24 18:23:07.814171 - Order placement successful for users: [{'user_name': 'MASTER_TRUST', 'strategy': 'OPHIUCUS', 'instrument_nomenclature': 'NIFTY|L|0|CE|WEEK|0', 'position': 'OPEN SHORT', 'target': 0, 'stoploss': 0, 'quantity': 10}, {'user_name': 'ODIN', 'strategy': 'OPHIUCUS', 'instrument_nomenclature': 'NIFTY|L|0|CE|WEEK|0', 'position': 'OPEN SHORT', 'target': 0, 'stoploss': 0, 'quantity': 1}, {'user_name': 'BPWealth_AHD083', 'strategy': 'OPHIUCUS', 'instrument_nomenclature': 'NIFTY|L|0|CE|WEEK|0', 'position': 'OPEN SHORT', 'target': 0, 'stoploss': 0, 'quantity': 1}, {'user_name': 'BPWealth_ACS1301', 'strategy': 'OPHIUCUS', 'instrument_nomenclature': 'NIFTY|L|0|CE|WEEK|0', 'position': 'OPEN SHORT', 'target': 0, 'stoploss': 0, 'quantity': 1}, {'user_name': 'BPWealth_ACS1207', 'strategy': 'OPHIUCUS', 'instrument_nomenclature': 'NIFTY|L|0|CE|WEEK|0', 'position': 'OPEN SHORT', 'target': 0, 'stoploss': 0, 'quantity': 1}]
root - INFO - 2023-04-24 18:23:08.213717 - Order placed for MASTER_TRUST OPHIUCUS NIFTY|L|0|CE|WEEK|0 OPEN SHORT -10 0 0
root - INFO - 2023-04-24 18:23:08.296481 - Order placed for ODIN OPHIUCUS NIFTY|L|0|CE|WEEK|0 OPEN SHORT -1 0 0
root - INFO - 2023-04-24 18:23:08.379042 - Order placed for BPWealth_AHD083 OPHIUCUS NIFTY|L|0|CE|WEEK|0 OPEN SHORT -1 0 0
root - INFO - 2023-04-24 18:23:08.444875 - Order placement successful for users: [{'user_name': 'MASTER_TRUST', 'strategy': 'OPHIUCUS', 'instrument_nomenclature': 'NIFTY|L|0|CE|WEEK|0', 'position': 'OPEN SHORT', 'target': 0, 'stoploss': 0, 'quantity': 10}, {'user_name': 'ODIN', 'strategy': 'OPHIUCUS', 'instrument_nomenclature': 'NIFTY|L|0|CE|WEEK|0', 'position': 'OPEN SHORT', 'target': 0, 'stoploss': 0, 'quantity': 1}, {'user_name': 'BPWealth_AHD083', 'strategy': 'OPHIUCUS', 'instrument_nomenclature': 'NIFTY|L|0|CE|WEEK|0', 'position': 'OPEN SHORT', 'target': 0, 'stoploss': 0, 'quantity': 1}]
root - INFO - 2023-04-24 18:24:35.794001 - Order placed for MASTER_TRUST OPHIUCUS NIFTY|L|0|CE|WEEK|0 OPEN SHORT -10 0 0
root - INFO - 2023-04-24 18:24:35.876572 - Order placed for ODIN OPHIUCUS NIFTY|L|0|CE|WEEK|0 OPEN SHORT -1 0 0
root - INFO - 2023-04-24 18:24:35.949744 - Order placed for BPWealth_AHD083 OPHIUCUS NIFTY|L|0|CE|WEEK|0 OPEN SHORT -1 0 0
root - INFO - 2023-04-24 18:24:36.024129 - Order placed for BPWealth_ACS1301 OPHIUCUS NIFTY|L|0|CE|WEEK|0 OPEN SHORT -1 0 0
root - INFO - 2023-04-24 18:24:36.089820 - Order placed for BPWealth_ACS1207 OPHIUCUS NIFTY|L|0|CE|WEEK|0 OPEN SHORT -1 0 0
root - INFO - 2023-04-24 18:24:36.172191 - Order placed for BPWealth_AC66 OPHIUCUS NIFTY|L|0|CE|WEEK|0 OPEN SHORT -2 0 0
root - INFO - 2023-04-24 18:24:36.237280 - Order placement successful for users: [{'user_name': 'MASTER_TRUST', 'strategy': 'OPHIUCUS', 'instrument_nomenclature': 'NIFTY|L|0|CE|WEEK|0', 'position': 'OPEN SHORT', 'target': 0, 'stoploss': 0, 'quantity': 10}, {'user_name': 'ODIN', 'strategy': 'OPHIUCUS', 'instrument_nomenclature': 'NIFTY|L|0|CE|WEEK|0', 'position': 'OPEN SHORT', 'target': 0, 'stoploss': 0, 'quantity': 1}, {'user_name': 'BPWealth_AHD083', 'strategy': 'OPHIUCUS', 'instrument_nomenclature': 'NIFTY|L|0|CE|WEEK|0', 'position': 'OPEN SHORT', 'target': 0, 'stoploss': 0, 'quantity': 1}, {'user_name': 'BPWealth_ACS1301', 'strategy': 'OPHIUCUS', 'instrument_nomenclature': 'NIFTY|L|0|CE|WEEK|0', 'position': 'OPEN SHORT', 'target': 0, 'stoploss': 0, 'quantity': 1}, {'user_name': 'BPWealth_ACS1207', 'strategy': 'OPHIUCUS', 'instrument_nomenclature': 'NIFTY|L|0|CE|WEEK|0', 'position': 'OPEN SHORT', 'target': 0, 'stoploss': 0, 'quantity': 1}, {'user_name': 'BPWealth_AC66', 'strategy': 'OPHIUCUS', 'instrument_nomenclature': 'NIFTY|L|0|CE|WEEK|0', 'position': 'OPEN SHORT', 'target': 0, 'stoploss': 0, 'quantity': 2}]
root - INFO - 2023-04-24 18:24:45.779779 - Order placement successful for users: []
root - INFO - 2023-04-24 18:24:55.806023 - Order placement successful for users: []
uvicorn.error - INFO - Shutting down
uvicorn.error - INFO - Waiting for application shutdown.
tortoise - INFO - Tortoise-ORM shutdown
tortoise - INFO - Tortoise-ORM shutdown
uvicorn.error - INFO - Application shutdown complete.
uvicorn.error - INFO - Finished server process [60915]
root - INFO - 2023-04-24 22:52:42.684031 - OMS Server turned on.
uvicorn.error - INFO - Started server process [62423]
uvicorn.error - INFO - Waiting for application startup.
tortoise - INFO - Tortoise-ORM started, {'default': <tortoise.backends.sqlite.client.SqliteClient object at 0x7fac283a1f40>}, {'models': {'OptionSpread': <class 'models.OptionSpread'>, 'User': <class 'models.User'>, 'User_Finvant': <class 'models.User_Finvant'>}}
tortoise - INFO - Tortoise-ORM generating schema
uvicorn.error - INFO - Application startup complete.
uvicorn.error - INFO - Uvicorn running on http://0.0.0.0:9093 (Press CTRL+C to quit)
root - INFO - 2023-04-24 22:53:11.616566 - Order placed for MASTER_TRUST OPHIUCUS NIFTY|L|0|CE|WEEK|0 OPEN SHORT -10 0 0
root - INFO - 2023-04-24 22:53:11.682494 - Order placed for ODIN OPHIUCUS NIFTY|L|0|CE|WEEK|0 OPEN SHORT -1 0 0
root - INFO - 2023-04-24 22:53:11.748435 - Order placed for BPWealth_AHD083 OPHIUCUS NIFTY|L|0|CE|WEEK|0 OPEN SHORT -1 0 0
root - INFO - 2023-04-24 22:53:11.814062 - Order placed for BPWealth_ACS1301 OPHIUCUS NIFTY|L|0|CE|WEEK|0 OPEN SHORT -1 0 0
root - INFO - 2023-04-24 22:53:11.879886 - Order placed for BPWealth_ACS1207 OPHIUCUS NIFTY|L|0|CE|WEEK|0 OPEN SHORT -1 0 0
root - INFO - 2023-04-24 22:53:11.945883 - Order placed for BPWealth_AC66 OPHIUCUS NIFTY|L|0|CE|WEEK|0 OPEN SHORT -2 0 0
root - INFO - 2023-04-24 22:53:12.011422 - Order placement successful for users: [{'user_name': 'MASTER_TRUST', 'strategy': 'OPHIUCUS', 'instrument_nomenclature': 'NIFTY|L|0|CE|WEEK|0', 'position': 'OPEN SHORT', 'target': 0, 'stoploss': 0, 'quantity': 10}, {'user_name': 'ODIN', 'strategy': 'OPHIUCUS', 'instrument_nomenclature': 'NIFTY|L|0|CE|WEEK|0', 'position': 'OPEN SHORT', 'target': 0, 'stoploss': 0, 'quantity': 1}, {'user_name': 'BPWealth_AHD083', 'strategy': 'OPHIUCUS', 'instrument_nomenclature': 'NIFTY|L|0|CE|WEEK|0', 'position': 'OPEN SHORT', 'target': 0, 'stoploss': 0, 'quantity': 1}, {'user_name': 'BPWealth_ACS1301', 'strategy': 'OPHIUCUS', 'instrument_nomenclature': 'NIFTY|L|0|CE|WEEK|0', 'position': 'OPEN SHORT', 'target': 0, 'stoploss': 0, 'quantity': 1}, {'user_name': 'BPWealth_ACS1207', 'strategy': 'OPHIUCUS', 'instrument_nomenclature': 'NIFTY|L|0|CE|WEEK|0', 'position': 'OPEN SHORT', 'target': 0, 'stoploss': 0, 'quantity': 1}, {'user_name': 'BPWealth_AC66', 'strategy': 'OPHIUCUS', 'instrument_nomenclature': 'NIFTY|L|0|CE|WEEK|0', 'position': 'OPEN SHORT', 'target': 0, 'stoploss': 0, 'quantity': 2}]
root - INFO - 2023-04-24 22:53:20.737807 - Order placement successful for users: []
root - INFO - 2023-04-24 22:53:30.743403 - Order placement successful for users: []
uvicorn.error - INFO - Shutting down
uvicorn.error - INFO - Waiting for application shutdown.
tortoise - INFO - Tortoise-ORM shutdown
tortoise - INFO - Tortoise-ORM shutdown
uvicorn.error - INFO - Application shutdown complete.
uvicorn.error - INFO - Finished server process [62423]
root - INFO - 2023-04-24 22:54:14.603174 - OMS Server turned on.
uvicorn.error - INFO - Started server process [62665]
uvicorn.error - INFO - Waiting for application startup.
tortoise - INFO - Tortoise-ORM started, {'default': <tortoise.backends.sqlite.client.SqliteClient object at 0x7f999a52bf40>}, {'models': {'OptionSpread': <class 'models.OptionSpread'>, 'User': <class 'models.User'>, 'User_Finvant': <class 'models.User_Finvant'>}}
tortoise - INFO - Tortoise-ORM generating schema
uvicorn.error - INFO - Application startup complete.
uvicorn.error - INFO - Uvicorn running on http://0.0.0.0:9093 (Press CTRL+C to quit)
uvicorn.error - INFO - Shutting down
uvicorn.error - INFO - Waiting for application shutdown.
tortoise - INFO - Tortoise-ORM shutdown
tortoise - INFO - Tortoise-ORM shutdown
uvicorn.error - INFO - Application shutdown complete.
uvicorn.error - INFO - Finished server process [62665]
root - INFO - 2023-04-24 22:54:30.209863 - OMS Server turned on.
uvicorn.error - INFO - Started server process [62669]
uvicorn.error - INFO - Waiting for application startup.
tortoise - INFO - Tortoise-ORM started, {'default': <tortoise.backends.sqlite.client.SqliteClient object at 0x7f6d13291f40>}, {'models': {'OptionSpread': <class 'models.OptionSpread'>, 'User': <class 'models.User'>, 'User_Finvant': <class 'models.User_Finvant'>}}
tortoise - INFO - Tortoise-ORM generating schema
uvicorn.error - INFO - Application startup complete.
uvicorn.error - INFO - Uvicorn running on http://0.0.0.0:9093 (Press CTRL+C to quit)
root - INFO - 2023-04-24 22:54:35.934324 - Order placed for MASTER_TRUST OPHIUCUS NIFTY|L|0|CE|WEEK|0 OPEN SHORT -10 0 0
root - INFO - 2023-04-24 22:54:36.000203 - Order placed for ODIN OPHIUCUS NIFTY|L|0|CE|WEEK|0 OPEN SHORT -1 0 0
root - INFO - 2023-04-24 22:54:36.066458 - Order placed for BPWealth_AHD083 OPHIUCUS NIFTY|L|0|CE|WEEK|0 OPEN SHORT -1 0 0
root - INFO - 2023-04-24 22:54:36.131969 - Order placed for BPWealth_ACS1301 OPHIUCUS NIFTY|L|0|CE|WEEK|0 OPEN SHORT -1 0 0
root - INFO - 2023-04-24 22:54:36.197310 - Order placed for BPWealth_ACS1207 OPHIUCUS NIFTY|L|0|CE|WEEK|0 OPEN SHORT -1 0 0
root - INFO - 2023-04-24 22:54:36.262793 - Order placed for BPWealth_AC66 OPHIUCUS NIFTY|L|0|CE|WEEK|0 OPEN SHORT -2 0 0
root - INFO - 2023-04-24 22:54:36.328043 - Order placement successful for users: [{'user_name': 'MASTER_TRUST', 'strategy': 'OPHIUCUS', 'instrument_nomenclature': 'NIFTY|L|0|CE|WEEK|0', 'position': 'OPEN SHORT', 'target': 0, 'stoploss': 0, 'quantity': 10}, {'user_name': 'ODIN', 'strategy': 'OPHIUCUS', 'instrument_nomenclature': 'NIFTY|L|0|CE|WEEK|0', 'position': 'OPEN SHORT', 'target': 0, 'stoploss': 0, 'quantity': 1}, {'user_name': 'BPWealth_AHD083', 'strategy': 'OPHIUCUS', 'instrument_nomenclature': 'NIFTY|L|0|CE|WEEK|0', 'position': 'OPEN SHORT', 'target': 0, 'stoploss': 0, 'quantity': 1}, {'user_name': 'BPWealth_ACS1301', 'strategy': 'OPHIUCUS', 'instrument_nomenclature': 'NIFTY|L|0|CE|WEEK|0', 'position': 'OPEN SHORT', 'target': 0, 'stoploss': 0, 'quantity': 1}, {'user_name': 'BPWealth_ACS1207', 'strategy': 'OPHIUCUS', 'instrument_nomenclature': 'NIFTY|L|0|CE|WEEK|0', 'position': 'OPEN SHORT', 'target': 0, 'stoploss': 0, 'quantity': 1}, {'user_name': 'BPWealth_AC66', 'strategy': 'OPHIUCUS', 'instrument_nomenclature': 'NIFTY|L|0|CE|WEEK|0', 'position': 'OPEN SHORT', 'target': 0, 'stoploss': 0, 'quantity': 2}]
root - INFO - 2023-04-24 22:54:36.729811 - Order placed for MASTER_TRUST OPHIUCUS NIFTY|L|0|CE|WEEK|0 OPEN SHORT -10 0 0
root - INFO - 2023-04-24 22:54:36.795302 - Order placed for ODIN OPHIUCUS NIFTY|L|0|CE|WEEK|0 OPEN SHORT -1 0 0
root - INFO - 2023-04-24 22:54:36.861125 - Order placed for BPWealth_AHD083 OPHIUCUS NIFTY|L|0|CE|WEEK|0 OPEN SHORT -1 0 0
root - INFO - 2023-04-24 22:54:36.926790 - Order placed for BPWealth_ACS1301 OPHIUCUS NIFTY|L|0|CE|WEEK|0 OPEN SHORT -1 0 0
root - INFO - 2023-04-24 22:54:36.992724 - Order placed for BPWealth_ACS1207 OPHIUCUS NIFTY|L|0|CE|WEEK|0 OPEN SHORT -1 0 0
root - INFO - 2023-04-24 22:54:37.058456 - Order placement successful for users: [{'user_name': 'MASTER_TRUST', 'strategy': 'OPHIUCUS', 'instrument_nomenclature': 'NIFTY|L|0|CE|WEEK|0', 'position': 'OPEN SHORT', 'target': 0, 'stoploss': 0, 'quantity': 10}, {'user_name': 'ODIN', 'strategy': 'OPHIUCUS', 'instrument_nomenclature': 'NIFTY|L|0|CE|WEEK|0', 'position': 'OPEN SHORT', 'target': 0, 'stoploss': 0, 'quantity': 1}, {'user_name': 'BPWealth_AHD083', 'strategy': 'OPHIUCUS', 'instrument_nomenclature': 'NIFTY|L|0|CE|WEEK|0', 'position': 'OPEN SHORT', 'target': 0, 'stoploss': 0, 'quantity': 1}, {'user_name': 'BPWealth_ACS1301', 'strategy': 'OPHIUCUS', 'instrument_nomenclature': 'NIFTY|L|0|CE|WEEK|0', 'position': 'OPEN SHORT', 'target': 0, 'stoploss': 0, 'quantity': 1}, {'user_name': 'BPWealth_ACS1207', 'strategy': 'OPHIUCUS', 'instrument_nomenclature': 'NIFTY|L|0|CE|WEEK|0', 'position': 'OPEN SHORT', 'target': 0, 'stoploss': 0, 'quantity': 1}]
root - INFO - 2023-04-24 22:54:37.464415 - Order placed for MASTER_TRUST OPHIUCUS NIFTY|L|0|CE|WEEK|0 OPEN SHORT -10 0 0
root - INFO - 2023-04-24 22:54:37.530471 - Order placed for ODIN OPHIUCUS NIFTY|L|0|CE|WEEK|0 OPEN SHORT -1 0 0
root - INFO - 2023-04-24 22:54:37.603006 - Order placement successful for users: [{'user_name': 'MASTER_TRUST', 'strategy': 'OPHIUCUS', 'instrument_nomenclature': 'NIFTY|L|0|CE|WEEK|0', 'position': 'OPEN SHORT', 'target': 0, 'stoploss': 0, 'quantity': 10}, {'user_name': 'ODIN', 'strategy': 'OPHIUCUS', 'instrument_nomenclature': 'NIFTY|L|0|CE|WEEK|0', 'position': 'OPEN SHORT', 'target': 0, 'stoploss': 0, 'quantity': 1}]
uvicorn.error - INFO - Shutting down
uvicorn.error - INFO - Waiting for application shutdown.
tortoise - INFO - Tortoise-ORM shutdown
tortoise - INFO - Tortoise-ORM shutdown
uvicorn.error - INFO - Application shutdown complete.
uvicorn.error - INFO - Finished server process [62669]
