root - INFO - 2023-03-21 09:10:24.448301 - OMS Server turned on.
uvicorn.error - INFO - Started server process [70838]
uvicorn.error - INFO - Waiting for application startup.
tortoise - INFO - Tortoise-ORM started, {'default': <tortoise.backends.sqlite.client.SqliteClient object at 0x12a28d6a0>}, {'models': {'OptionSpread': <class 'models.OptionSpread'>, 'User': <class 'models.User'>, 'User_Finvant': <class 'models.User_Finvant'>}}
tortoise - INFO - Tortoise-ORM generating schema
uvicorn.error - INFO - Application startup complete.
uvicorn.error - INFO - Uvicorn running on http://0.0.0.0:8000 (Press CTRL+C to quit)
root - INFO - 2023-03-21 09:35:17.885875 - Order placed for FINVANT_LIVE ALTAIR BANKNIFTY_SYNTHETIC_INTRADAY_SHORT BUY 1 2 0.5
root - INFO - 2023-03-21 09:35:17.983824 - Order placed for AIRAN ALTAIR_FUTURES BANKNIFTY OPEN SHORT -3 0.5 2
root - INFO - 2023-03-21 09:35:18.080035 - Order placed for BPWealth_AHO7706 ALTAIR_FUTURES BANKNIFTY OPEN SHORT -1 0.5 2
root - INFO - 2023-03-21 09:35:18.179013 - Order placement successful for users: [{'user_name': 'FINVANT_LIVE', 'strategy': 'ALTAIR', 'instrument_nomenclature': 'BANKNIFTY_SYNTHETIC_INTRADAY_SHORT', 'position': 'BUY', 'target': 0.5, 'stoploss': 2, 'quantity': 1}, {'user_name': 'AIRAN', 'strategy': 'ALTAIR_FUTURES', 'instrument_nomenclature': 'BANKNIFTY', 'position': 'OPEN SHORT', 'target': 2, 'stoploss': 0.5, 'quantity': 3}, {'user_name': 'BPWealth_AHO7706', 'strategy': 'ALTAIR_FUTURES', 'instrument_nomenclature': 'BANKNIFTY', 'position': 'OPEN SHORT', 'target': 2, 'stoploss': 0.5, 'quantity': 1}]
root - INFO - 2023-03-21 09:40:15.907207 - Order placement successful for users: []
root - INFO - 2023-03-21 09:50:15.897240 - Order placed for FINVANT_LIVE ALTAIR NIFTY_SYNTHETIC_INTRADAY_SHORT BUY 1 2 0.5
root - INFO - 2023-03-21 09:50:16.000019 - Order placed for AIRAN ALTAIR_FUTURES NIFTY OPEN SHORT -3 0.5 2
root - INFO - 2023-03-21 09:50:16.107501 - Order placed for BPWealth_AHO7706 ALTAIR_FUTURES NIFTY OPEN SHORT -2 0.5 2
root - INFO - 2023-03-21 09:50:16.204004 - Order placement successful for users: [{'user_name': 'FINVANT_LIVE', 'strategy': 'ALTAIR', 'instrument_nomenclature': 'NIFTY_SYNTHETIC_INTRADAY_SHORT', 'position': 'BUY', 'target': 0.5, 'stoploss': 2, 'quantity': 1}, {'user_name': 'AIRAN', 'strategy': 'ALTAIR_FUTURES', 'instrument_nomenclature': 'NIFTY', 'position': 'OPEN SHORT', 'target': 2, 'stoploss': 0.5, 'quantity': 3}, {'user_name': 'BPWealth_AHO7706', 'strategy': 'ALTAIR_FUTURES', 'instrument_nomenclature': 'NIFTY', 'position': 'OPEN SHORT', 'target': 2, 'stoploss': 0.5, 'quantity': 2}]
root - INFO - 2023-03-21 09:55:15.874426 - Order placement successful for users: []
root - INFO - 2023-03-21 10:00:15.860278 - Order placement successful for users: []
root - INFO - 2023-03-21 10:05:15.886821 - Order placement successful for users: []
root - INFO - 2023-03-21 10:10:15.964880 - Order placement successful for users: []
root - INFO - 2023-03-21 10:15:15.914863 - Order placement successful for users: []
root - INFO - 2023-03-21 10:20:15.914129 - Order placement successful for users: []
root - INFO - 2023-03-21 10:25:15.879511 - Order placement successful for users: []
root - INFO - 2023-03-21 10:30:15.940972 - Order placement successful for users: []
root - INFO - 2023-03-21 10:40:15.865033 - Order placement successful for users: []
root - INFO - 2023-03-21 10:45:15.864268 - Order placement successful for users: []
root - INFO - 2023-03-21 10:50:15.903711 - Order placement successful for users: []
root - INFO - 2023-03-21 11:15:15.908980 - Order placement successful for users: []
root - INFO - 2023-03-21 11:20:15.984514 - Order placement successful for users: []
root - INFO - 2023-03-21 11:25:15.916489 - Order placement successful for users: []
root - INFO - 2023-03-21 11:35:15.932706 - Order placement successful for users: []
root - INFO - 2023-03-21 11:40:17.078721 - Order placed for FINVANT_LIVE QUASAR_5M BANKNIFTY_SYNTHETIC_INTRADAY_SHORT BUY 1 0 0.5
root - INFO - 2023-03-21 11:40:17.192064 - Order placement successful for users: [{'user_name': 'FINVANT_LIVE', 'strategy': 'QUASAR_5M', 'instrument_nomenclature': 'BANKNIFTY_SYNTHETIC_INTRADAY_SHORT', 'position': 'BUY', 'target': 0.5, 'stoploss': 0, 'quantity': 1}]
root - INFO - 2023-03-21 11:45:15.897966 - Order placement successful for users: []
root - INFO - 2023-03-21 11:50:15.923866 - Order placement successful for users: []
root - INFO - 2023-03-21 11:55:16.077024 - Order placed for FINVANT_LIVE QUASAR_5M NIFTY_SYNTHETIC_INTRADAY_SHORT BUY 2 0 0.5
root - INFO - 2023-03-21 11:55:16.180815 - Order placement successful for users: [{'user_name': 'FINVANT_LIVE', 'strategy': 'QUASAR_5M', 'instrument_nomenclature': 'NIFTY_SYNTHETIC_INTRADAY_SHORT', 'position': 'BUY', 'target': 0.5, 'stoploss': 0, 'quantity': 2}]
root - INFO - 2023-03-21 12:00:16.004571 - Order placement successful for users: []
root - INFO - 2023-03-21 12:05:15.949673 - Order placement successful for users: []
root - INFO - 2023-03-21 12:10:16.295930 - Order placement successful for users: []
root - INFO - 2023-03-21 12:15:15.994637 - Order placement successful for users: []
root - INFO - 2023-03-21 12:20:15.912572 - Order placement successful for users: []
root - INFO - 2023-03-21 12:25:15.934047 - Order placement successful for users: []
root - INFO - 2023-03-21 12:30:15.888575 - Order placement successful for users: []
root - INFO - 2023-03-21 12:35:15.877896 - Order placement successful for users: []
root - INFO - 2023-03-21 12:45:15.870972 - Order placement successful for users: []
root - INFO - 2023-03-21 12:50:15.891386 - Order placement successful for users: []
root - INFO - 2023-03-21 13:00:15.971135 - Order placed for MASTER_TRUST OPHIUCUS NIFTY|L|0|PE|WEEK|0 OPEN SHORT -10 0 0
root - INFO - 2023-03-21 13:00:16.076221 - Order placed for ODIN OPHIUCUS NIFTY|L|0|PE|WEEK|0 OPEN SHORT -1 0 0
root - INFO - 2023-03-21 13:00:16.204425 - Order placed for FINVANT_LIVE OPHIUCUS NIFTY|L|0|PE|WEEK|0 OPEN SHORT -1 0 0
root - INFO - 2023-03-21 13:00:16.303986 - Order placed for BPWealth_AHD083 OPHIUCUS NIFTY|L|0|PE|WEEK|0 OPEN SHORT -1 0 0
root - INFO - 2023-03-21 13:00:16.403141 - Order placed for BPWealth_ACS1301 OPHIUCUS NIFTY|L|0|PE|WEEK|0 OPEN SHORT -1 0 0
root - INFO - 2023-03-21 13:00:16.500598 - Order placed for BPWealth_ACS1207 OPHIUCUS NIFTY|L|0|PE|WEEK|0 OPEN SHORT -1 0 0
root - INFO - 2023-03-21 13:00:16.609749 - Order placed for BPWealth_AC66 OPHIUCUS NIFTY|L|0|PE|WEEK|0 OPEN SHORT -1 0 0
root - INFO - 2023-03-21 13:00:16.713417 - Order placement successful for users: [{'user_name': 'MASTER_TRUST', 'strategy': 'OPHIUCUS', 'instrument_nomenclature': 'NIFTY|L|0|PE|WEEK|0', 'position': 'OPEN SHORT', 'target': 0, 'stoploss': 0, 'quantity': 10}, {'user_name': 'ODIN', 'strategy': 'OPHIUCUS', 'instrument_nomenclature': 'NIFTY|L|0|PE|WEEK|0', 'position': 'OPEN SHORT', 'target': 0, 'stoploss': 0, 'quantity': 1}, {'user_name': 'FINVANT_LIVE', 'strategy': 'OPHIUCUS', 'instrument_nomenclature': 'NIFTY|L|0|PE|WEEK|0', 'position': 'OPEN SHORT', 'target': 0, 'stoploss': 0, 'quantity': 1}, {'user_name': 'BPWealth_AHD083', 'strategy': 'OPHIUCUS', 'instrument_nomenclature': 'NIFTY|L|0|PE|WEEK|0', 'position': 'OPEN SHORT', 'target': 0, 'stoploss': 0, 'quantity': 1}, {'user_name': 'BPWealth_ACS1301', 'strategy': 'OPHIUCUS', 'instrument_nomenclature': 'NIFTY|L|0|PE|WEEK|0', 'position': 'OPEN SHORT', 'target': 0, 'stoploss': 0, 'quantity': 1}, {'user_name': 'BPWealth_ACS1207', 'strategy': 'OPHIUCUS', 'instrument_nomenclature': 'NIFTY|L|0|PE|WEEK|0', 'position': 'OPEN SHORT', 'target': 0, 'stoploss': 0, 'quantity': 1}, {'user_name': 'BPWealth_AC66', 'strategy': 'OPHIUCUS', 'instrument_nomenclature': 'NIFTY|L|0|PE|WEEK|0', 'position': 'OPEN SHORT', 'target': 0, 'stoploss': 0, 'quantity': 1}]
root - INFO - 2023-03-21 13:05:15.901109 - Order placement successful for users: []
uvicorn.error - ERROR - Exception in ASGI application
Traceback (most recent call last):
  File "/opt/homebrew/lib/python3.9/site-packages/uvicorn/protocols/http/h11_impl.py", line 366, in run_asgi
    result = await app(self.scope, self.receive, self.send)
  File "/opt/homebrew/lib/python3.9/site-packages/uvicorn/middleware/proxy_headers.py", line 75, in __call__
    return await self.app(scope, receive, send)
  File "/opt/homebrew/lib/python3.9/site-packages/fastapi/applications.py", line 269, in __call__
    await super().__call__(scope, receive, send)
  File "/opt/homebrew/lib/python3.9/site-packages/starlette/applications.py", line 124, in __call__
    await self.middleware_stack(scope, receive, send)
  File "/opt/homebrew/lib/python3.9/site-packages/starlette/middleware/errors.py", line 184, in __call__
    raise exc
  File "/opt/homebrew/lib/python3.9/site-packages/starlette/middleware/errors.py", line 162, in __call__
    await self.app(scope, receive, _send)
  File "/opt/homebrew/lib/python3.9/site-packages/starlette/middleware/cors.py", line 84, in __call__
    await self.app(scope, receive, send)
  File "/opt/homebrew/lib/python3.9/site-packages/starlette/exceptions.py", line 93, in __call__
    raise exc
  File "/opt/homebrew/lib/python3.9/site-packages/starlette/exceptions.py", line 82, in __call__
    await self.app(scope, receive, sender)
  File "/opt/homebrew/lib/python3.9/site-packages/fastapi/middleware/asyncexitstack.py", line 21, in __call__
    raise e
  File "/opt/homebrew/lib/python3.9/site-packages/fastapi/middleware/asyncexitstack.py", line 18, in __call__
    await self.app(scope, receive, send)
  File "/opt/homebrew/lib/python3.9/site-packages/starlette/routing.py", line 670, in __call__
    await route.handle(scope, receive, send)
  File "/opt/homebrew/lib/python3.9/site-packages/starlette/routing.py", line 266, in handle
    await self.app(scope, receive, send)
  File "/opt/homebrew/lib/python3.9/site-packages/starlette/routing.py", line 65, in app
    response = await func(request)
  File "/opt/homebrew/lib/python3.9/site-packages/fastapi/routing.py", line 227, in app
    raw_response = await run_endpoint_function(
  File "/opt/homebrew/lib/python3.9/site-packages/fastapi/routing.py", line 160, in run_endpoint_function
    return await dependant.call(**values)
  File "/Users/aditya/Downloads/API 2/C/RUN/./main.py", line 1038, in create_order
    return user_result
UnboundLocalError: local variable 'user_result' referenced before assignment
root - INFO - 2023-03-21 13:05:17.116372 - Order placement successful for users: []
uvicorn.error - ERROR - Exception in ASGI application
Traceback (most recent call last):
  File "/opt/homebrew/lib/python3.9/site-packages/uvicorn/protocols/http/h11_impl.py", line 366, in run_asgi
    result = await app(self.scope, self.receive, self.send)
  File "/opt/homebrew/lib/python3.9/site-packages/uvicorn/middleware/proxy_headers.py", line 75, in __call__
    return await self.app(scope, receive, send)
  File "/opt/homebrew/lib/python3.9/site-packages/fastapi/applications.py", line 269, in __call__
    await super().__call__(scope, receive, send)
  File "/opt/homebrew/lib/python3.9/site-packages/starlette/applications.py", line 124, in __call__
    await self.middleware_stack(scope, receive, send)
  File "/opt/homebrew/lib/python3.9/site-packages/starlette/middleware/errors.py", line 184, in __call__
    raise exc
  File "/opt/homebrew/lib/python3.9/site-packages/starlette/middleware/errors.py", line 162, in __call__
    await self.app(scope, receive, _send)
  File "/opt/homebrew/lib/python3.9/site-packages/starlette/middleware/cors.py", line 84, in __call__
    await self.app(scope, receive, send)
  File "/opt/homebrew/lib/python3.9/site-packages/starlette/exceptions.py", line 93, in __call__
    raise exc
  File "/opt/homebrew/lib/python3.9/site-packages/starlette/exceptions.py", line 82, in __call__
    await self.app(scope, receive, sender)
  File "/opt/homebrew/lib/python3.9/site-packages/fastapi/middleware/asyncexitstack.py", line 21, in __call__
    raise e
  File "/opt/homebrew/lib/python3.9/site-packages/fastapi/middleware/asyncexitstack.py", line 18, in __call__
    await self.app(scope, receive, send)
  File "/opt/homebrew/lib/python3.9/site-packages/starlette/routing.py", line 670, in __call__
    await route.handle(scope, receive, send)
  File "/opt/homebrew/lib/python3.9/site-packages/starlette/routing.py", line 266, in handle
    await self.app(scope, receive, send)
  File "/opt/homebrew/lib/python3.9/site-packages/starlette/routing.py", line 65, in app
    response = await func(request)
  File "/opt/homebrew/lib/python3.9/site-packages/fastapi/routing.py", line 227, in app
    raw_response = await run_endpoint_function(
  File "/opt/homebrew/lib/python3.9/site-packages/fastapi/routing.py", line 160, in run_endpoint_function
    return await dependant.call(**values)
  File "/Users/aditya/Downloads/API 2/C/RUN/./main.py", line 1038, in create_order
    return user_result
UnboundLocalError: local variable 'user_result' referenced before assignment
root - INFO - 2023-03-21 13:10:15.914050 - Order placement successful for users: []
uvicorn.error - ERROR - Exception in ASGI application
Traceback (most recent call last):
  File "/opt/homebrew/lib/python3.9/site-packages/uvicorn/protocols/http/h11_impl.py", line 366, in run_asgi
    result = await app(self.scope, self.receive, self.send)
  File "/opt/homebrew/lib/python3.9/site-packages/uvicorn/middleware/proxy_headers.py", line 75, in __call__
    return await self.app(scope, receive, send)
  File "/opt/homebrew/lib/python3.9/site-packages/fastapi/applications.py", line 269, in __call__
    await super().__call__(scope, receive, send)
  File "/opt/homebrew/lib/python3.9/site-packages/starlette/applications.py", line 124, in __call__
    await self.middleware_stack(scope, receive, send)
  File "/opt/homebrew/lib/python3.9/site-packages/starlette/middleware/errors.py", line 184, in __call__
    raise exc
  File "/opt/homebrew/lib/python3.9/site-packages/starlette/middleware/errors.py", line 162, in __call__
    await self.app(scope, receive, _send)
  File "/opt/homebrew/lib/python3.9/site-packages/starlette/middleware/cors.py", line 84, in __call__
    await self.app(scope, receive, send)
  File "/opt/homebrew/lib/python3.9/site-packages/starlette/exceptions.py", line 93, in __call__
    raise exc
  File "/opt/homebrew/lib/python3.9/site-packages/starlette/exceptions.py", line 82, in __call__
    await self.app(scope, receive, sender)
  File "/opt/homebrew/lib/python3.9/site-packages/fastapi/middleware/asyncexitstack.py", line 21, in __call__
    raise e
  File "/opt/homebrew/lib/python3.9/site-packages/fastapi/middleware/asyncexitstack.py", line 18, in __call__
    await self.app(scope, receive, send)
  File "/opt/homebrew/lib/python3.9/site-packages/starlette/routing.py", line 670, in __call__
    await route.handle(scope, receive, send)
  File "/opt/homebrew/lib/python3.9/site-packages/starlette/routing.py", line 266, in handle
    await self.app(scope, receive, send)
  File "/opt/homebrew/lib/python3.9/site-packages/starlette/routing.py", line 65, in app
    response = await func(request)
  File "/opt/homebrew/lib/python3.9/site-packages/fastapi/routing.py", line 227, in app
    raw_response = await run_endpoint_function(
  File "/opt/homebrew/lib/python3.9/site-packages/fastapi/routing.py", line 160, in run_endpoint_function
    return await dependant.call(**values)
  File "/Users/aditya/Downloads/API 2/C/RUN/./main.py", line 1038, in create_order
    return user_result
UnboundLocalError: local variable 'user_result' referenced before assignment
root - INFO - 2023-03-21 13:10:17.335929 - Order placement successful for users: []
uvicorn.error - ERROR - Exception in ASGI application
Traceback (most recent call last):
  File "/opt/homebrew/lib/python3.9/site-packages/uvicorn/protocols/http/h11_impl.py", line 366, in run_asgi
    result = await app(self.scope, self.receive, self.send)
  File "/opt/homebrew/lib/python3.9/site-packages/uvicorn/middleware/proxy_headers.py", line 75, in __call__
    return await self.app(scope, receive, send)
  File "/opt/homebrew/lib/python3.9/site-packages/fastapi/applications.py", line 269, in __call__
    await super().__call__(scope, receive, send)
  File "/opt/homebrew/lib/python3.9/site-packages/starlette/applications.py", line 124, in __call__
    await self.middleware_stack(scope, receive, send)
  File "/opt/homebrew/lib/python3.9/site-packages/starlette/middleware/errors.py", line 184, in __call__
    raise exc
  File "/opt/homebrew/lib/python3.9/site-packages/starlette/middleware/errors.py", line 162, in __call__
    await self.app(scope, receive, _send)
  File "/opt/homebrew/lib/python3.9/site-packages/starlette/middleware/cors.py", line 84, in __call__
    await self.app(scope, receive, send)
  File "/opt/homebrew/lib/python3.9/site-packages/starlette/exceptions.py", line 93, in __call__
    raise exc
  File "/opt/homebrew/lib/python3.9/site-packages/starlette/exceptions.py", line 82, in __call__
    await self.app(scope, receive, sender)
  File "/opt/homebrew/lib/python3.9/site-packages/fastapi/middleware/asyncexitstack.py", line 21, in __call__
    raise e
  File "/opt/homebrew/lib/python3.9/site-packages/fastapi/middleware/asyncexitstack.py", line 18, in __call__
    await self.app(scope, receive, send)
  File "/opt/homebrew/lib/python3.9/site-packages/starlette/routing.py", line 670, in __call__
    await route.handle(scope, receive, send)
  File "/opt/homebrew/lib/python3.9/site-packages/starlette/routing.py", line 266, in handle
    await self.app(scope, receive, send)
  File "/opt/homebrew/lib/python3.9/site-packages/starlette/routing.py", line 65, in app
    response = await func(request)
  File "/opt/homebrew/lib/python3.9/site-packages/fastapi/routing.py", line 227, in app
    raw_response = await run_endpoint_function(
  File "/opt/homebrew/lib/python3.9/site-packages/fastapi/routing.py", line 160, in run_endpoint_function
    return await dependant.call(**values)
  File "/Users/aditya/Downloads/API 2/C/RUN/./main.py", line 1038, in create_order
    return user_result
UnboundLocalError: local variable 'user_result' referenced before assignment
root - INFO - 2023-03-21 13:15:15.888882 - Order placement successful for users: []
uvicorn.error - ERROR - Exception in ASGI application
Traceback (most recent call last):
  File "/opt/homebrew/lib/python3.9/site-packages/uvicorn/protocols/http/h11_impl.py", line 366, in run_asgi
    result = await app(self.scope, self.receive, self.send)
  File "/opt/homebrew/lib/python3.9/site-packages/uvicorn/middleware/proxy_headers.py", line 75, in __call__
    return await self.app(scope, receive, send)
  File "/opt/homebrew/lib/python3.9/site-packages/fastapi/applications.py", line 269, in __call__
    await super().__call__(scope, receive, send)
  File "/opt/homebrew/lib/python3.9/site-packages/starlette/applications.py", line 124, in __call__
    await self.middleware_stack(scope, receive, send)
  File "/opt/homebrew/lib/python3.9/site-packages/starlette/middleware/errors.py", line 184, in __call__
    raise exc
  File "/opt/homebrew/lib/python3.9/site-packages/starlette/middleware/errors.py", line 162, in __call__
    await self.app(scope, receive, _send)
  File "/opt/homebrew/lib/python3.9/site-packages/starlette/middleware/cors.py", line 84, in __call__
    await self.app(scope, receive, send)
  File "/opt/homebrew/lib/python3.9/site-packages/starlette/exceptions.py", line 93, in __call__
    raise exc
  File "/opt/homebrew/lib/python3.9/site-packages/starlette/exceptions.py", line 82, in __call__
    await self.app(scope, receive, sender)
  File "/opt/homebrew/lib/python3.9/site-packages/fastapi/middleware/asyncexitstack.py", line 21, in __call__
    raise e
  File "/opt/homebrew/lib/python3.9/site-packages/fastapi/middleware/asyncexitstack.py", line 18, in __call__
    await self.app(scope, receive, send)
  File "/opt/homebrew/lib/python3.9/site-packages/starlette/routing.py", line 670, in __call__
    await route.handle(scope, receive, send)
  File "/opt/homebrew/lib/python3.9/site-packages/starlette/routing.py", line 266, in handle
    await self.app(scope, receive, send)
  File "/opt/homebrew/lib/python3.9/site-packages/starlette/routing.py", line 65, in app
    response = await func(request)
  File "/opt/homebrew/lib/python3.9/site-packages/fastapi/routing.py", line 227, in app
    raw_response = await run_endpoint_function(
  File "/opt/homebrew/lib/python3.9/site-packages/fastapi/routing.py", line 160, in run_endpoint_function
    return await dependant.call(**values)
  File "/Users/aditya/Downloads/API 2/C/RUN/./main.py", line 1038, in create_order
    return user_result
UnboundLocalError: local variable 'user_result' referenced before assignment
root - INFO - 2023-03-21 13:15:17.132767 - Order placement successful for users: []
uvicorn.error - ERROR - Exception in ASGI application
Traceback (most recent call last):
  File "/opt/homebrew/lib/python3.9/site-packages/uvicorn/protocols/http/h11_impl.py", line 366, in run_asgi
    result = await app(self.scope, self.receive, self.send)
  File "/opt/homebrew/lib/python3.9/site-packages/uvicorn/middleware/proxy_headers.py", line 75, in __call__
    return await self.app(scope, receive, send)
  File "/opt/homebrew/lib/python3.9/site-packages/fastapi/applications.py", line 269, in __call__
    await super().__call__(scope, receive, send)
  File "/opt/homebrew/lib/python3.9/site-packages/starlette/applications.py", line 124, in __call__
    await self.middleware_stack(scope, receive, send)
  File "/opt/homebrew/lib/python3.9/site-packages/starlette/middleware/errors.py", line 184, in __call__
    raise exc
  File "/opt/homebrew/lib/python3.9/site-packages/starlette/middleware/errors.py", line 162, in __call__
    await self.app(scope, receive, _send)
  File "/opt/homebrew/lib/python3.9/site-packages/starlette/middleware/cors.py", line 84, in __call__
    await self.app(scope, receive, send)
  File "/opt/homebrew/lib/python3.9/site-packages/starlette/exceptions.py", line 93, in __call__
    raise exc
  File "/opt/homebrew/lib/python3.9/site-packages/starlette/exceptions.py", line 82, in __call__
    await self.app(scope, receive, sender)
  File "/opt/homebrew/lib/python3.9/site-packages/fastapi/middleware/asyncexitstack.py", line 21, in __call__
    raise e
  File "/opt/homebrew/lib/python3.9/site-packages/fastapi/middleware/asyncexitstack.py", line 18, in __call__
    await self.app(scope, receive, send)
  File "/opt/homebrew/lib/python3.9/site-packages/starlette/routing.py", line 670, in __call__
    await route.handle(scope, receive, send)
  File "/opt/homebrew/lib/python3.9/site-packages/starlette/routing.py", line 266, in handle
    await self.app(scope, receive, send)
  File "/opt/homebrew/lib/python3.9/site-packages/starlette/routing.py", line 65, in app
    response = await func(request)
  File "/opt/homebrew/lib/python3.9/site-packages/fastapi/routing.py", line 227, in app
    raw_response = await run_endpoint_function(
  File "/opt/homebrew/lib/python3.9/site-packages/fastapi/routing.py", line 160, in run_endpoint_function
    return await dependant.call(**values)
  File "/Users/aditya/Downloads/API 2/C/RUN/./main.py", line 1038, in create_order
    return user_result
UnboundLocalError: local variable 'user_result' referenced before assignment
root - INFO - 2023-03-21 13:20:15.916758 - Order placement successful for users: []
uvicorn.error - ERROR - Exception in ASGI application
Traceback (most recent call last):
  File "/opt/homebrew/lib/python3.9/site-packages/uvicorn/protocols/http/h11_impl.py", line 366, in run_asgi
    result = await app(self.scope, self.receive, self.send)
  File "/opt/homebrew/lib/python3.9/site-packages/uvicorn/middleware/proxy_headers.py", line 75, in __call__
    return await self.app(scope, receive, send)
  File "/opt/homebrew/lib/python3.9/site-packages/fastapi/applications.py", line 269, in __call__
    await super().__call__(scope, receive, send)
  File "/opt/homebrew/lib/python3.9/site-packages/starlette/applications.py", line 124, in __call__
    await self.middleware_stack(scope, receive, send)
  File "/opt/homebrew/lib/python3.9/site-packages/starlette/middleware/errors.py", line 184, in __call__
    raise exc
  File "/opt/homebrew/lib/python3.9/site-packages/starlette/middleware/errors.py", line 162, in __call__
    await self.app(scope, receive, _send)
  File "/opt/homebrew/lib/python3.9/site-packages/starlette/middleware/cors.py", line 84, in __call__
    await self.app(scope, receive, send)
  File "/opt/homebrew/lib/python3.9/site-packages/starlette/exceptions.py", line 93, in __call__
    raise exc
  File "/opt/homebrew/lib/python3.9/site-packages/starlette/exceptions.py", line 82, in __call__
    await self.app(scope, receive, sender)
  File "/opt/homebrew/lib/python3.9/site-packages/fastapi/middleware/asyncexitstack.py", line 21, in __call__
    raise e
  File "/opt/homebrew/lib/python3.9/site-packages/fastapi/middleware/asyncexitstack.py", line 18, in __call__
    await self.app(scope, receive, send)
  File "/opt/homebrew/lib/python3.9/site-packages/starlette/routing.py", line 670, in __call__
    await route.handle(scope, receive, send)
  File "/opt/homebrew/lib/python3.9/site-packages/starlette/routing.py", line 266, in handle
    await self.app(scope, receive, send)
  File "/opt/homebrew/lib/python3.9/site-packages/starlette/routing.py", line 65, in app
    response = await func(request)
  File "/opt/homebrew/lib/python3.9/site-packages/fastapi/routing.py", line 227, in app
    raw_response = await run_endpoint_function(
  File "/opt/homebrew/lib/python3.9/site-packages/fastapi/routing.py", line 160, in run_endpoint_function
    return await dependant.call(**values)
  File "/Users/aditya/Downloads/API 2/C/RUN/./main.py", line 1038, in create_order
    return user_result
UnboundLocalError: local variable 'user_result' referenced before assignment
root - INFO - 2023-03-21 13:20:17.396351 - Order placement successful for users: []
uvicorn.error - ERROR - Exception in ASGI application
Traceback (most recent call last):
  File "/opt/homebrew/lib/python3.9/site-packages/uvicorn/protocols/http/h11_impl.py", line 366, in run_asgi
    result = await app(self.scope, self.receive, self.send)
  File "/opt/homebrew/lib/python3.9/site-packages/uvicorn/middleware/proxy_headers.py", line 75, in __call__
    return await self.app(scope, receive, send)
  File "/opt/homebrew/lib/python3.9/site-packages/fastapi/applications.py", line 269, in __call__
    await super().__call__(scope, receive, send)
  File "/opt/homebrew/lib/python3.9/site-packages/starlette/applications.py", line 124, in __call__
    await self.middleware_stack(scope, receive, send)
  File "/opt/homebrew/lib/python3.9/site-packages/starlette/middleware/errors.py", line 184, in __call__
    raise exc
  File "/opt/homebrew/lib/python3.9/site-packages/starlette/middleware/errors.py", line 162, in __call__
    await self.app(scope, receive, _send)
  File "/opt/homebrew/lib/python3.9/site-packages/starlette/middleware/cors.py", line 84, in __call__
    await self.app(scope, receive, send)
  File "/opt/homebrew/lib/python3.9/site-packages/starlette/exceptions.py", line 93, in __call__
    raise exc
  File "/opt/homebrew/lib/python3.9/site-packages/starlette/exceptions.py", line 82, in __call__
    await self.app(scope, receive, sender)
  File "/opt/homebrew/lib/python3.9/site-packages/fastapi/middleware/asyncexitstack.py", line 21, in __call__
    raise e
  File "/opt/homebrew/lib/python3.9/site-packages/fastapi/middleware/asyncexitstack.py", line 18, in __call__
    await self.app(scope, receive, send)
  File "/opt/homebrew/lib/python3.9/site-packages/starlette/routing.py", line 670, in __call__
    await route.handle(scope, receive, send)
  File "/opt/homebrew/lib/python3.9/site-packages/starlette/routing.py", line 266, in handle
    await self.app(scope, receive, send)
  File "/opt/homebrew/lib/python3.9/site-packages/starlette/routing.py", line 65, in app
    response = await func(request)
  File "/opt/homebrew/lib/python3.9/site-packages/fastapi/routing.py", line 227, in app
    raw_response = await run_endpoint_function(
  File "/opt/homebrew/lib/python3.9/site-packages/fastapi/routing.py", line 160, in run_endpoint_function
    return await dependant.call(**values)
  File "/Users/aditya/Downloads/API 2/C/RUN/./main.py", line 1038, in create_order
    return user_result
UnboundLocalError: local variable 'user_result' referenced before assignment
root - INFO - 2023-03-21 13:25:15.855177 - Order placement successful for users: []
uvicorn.error - ERROR - Exception in ASGI application
Traceback (most recent call last):
  File "/opt/homebrew/lib/python3.9/site-packages/uvicorn/protocols/http/h11_impl.py", line 366, in run_asgi
    result = await app(self.scope, self.receive, self.send)
  File "/opt/homebrew/lib/python3.9/site-packages/uvicorn/middleware/proxy_headers.py", line 75, in __call__
    return await self.app(scope, receive, send)
  File "/opt/homebrew/lib/python3.9/site-packages/fastapi/applications.py", line 269, in __call__
    await super().__call__(scope, receive, send)
  File "/opt/homebrew/lib/python3.9/site-packages/starlette/applications.py", line 124, in __call__
    await self.middleware_stack(scope, receive, send)
  File "/opt/homebrew/lib/python3.9/site-packages/starlette/middleware/errors.py", line 184, in __call__
    raise exc
  File "/opt/homebrew/lib/python3.9/site-packages/starlette/middleware/errors.py", line 162, in __call__
    await self.app(scope, receive, _send)
  File "/opt/homebrew/lib/python3.9/site-packages/starlette/middleware/cors.py", line 84, in __call__
    await self.app(scope, receive, send)
  File "/opt/homebrew/lib/python3.9/site-packages/starlette/exceptions.py", line 93, in __call__
    raise exc
  File "/opt/homebrew/lib/python3.9/site-packages/starlette/exceptions.py", line 82, in __call__
    await self.app(scope, receive, sender)
  File "/opt/homebrew/lib/python3.9/site-packages/fastapi/middleware/asyncexitstack.py", line 21, in __call__
    raise e
  File "/opt/homebrew/lib/python3.9/site-packages/fastapi/middleware/asyncexitstack.py", line 18, in __call__
    await self.app(scope, receive, send)
  File "/opt/homebrew/lib/python3.9/site-packages/starlette/routing.py", line 670, in __call__
    await route.handle(scope, receive, send)
  File "/opt/homebrew/lib/python3.9/site-packages/starlette/routing.py", line 266, in handle
    await self.app(scope, receive, send)
  File "/opt/homebrew/lib/python3.9/site-packages/starlette/routing.py", line 65, in app
    response = await func(request)
  File "/opt/homebrew/lib/python3.9/site-packages/fastapi/routing.py", line 227, in app
    raw_response = await run_endpoint_function(
  File "/opt/homebrew/lib/python3.9/site-packages/fastapi/routing.py", line 160, in run_endpoint_function
    return await dependant.call(**values)
  File "/Users/aditya/Downloads/API 2/C/RUN/./main.py", line 1038, in create_order
    return user_result
UnboundLocalError: local variable 'user_result' referenced before assignment
root - INFO - 2023-03-21 13:25:17.106498 - Order placement successful for users: []
uvicorn.error - ERROR - Exception in ASGI application
Traceback (most recent call last):
  File "/opt/homebrew/lib/python3.9/site-packages/uvicorn/protocols/http/h11_impl.py", line 366, in run_asgi
    result = await app(self.scope, self.receive, self.send)
  File "/opt/homebrew/lib/python3.9/site-packages/uvicorn/middleware/proxy_headers.py", line 75, in __call__
    return await self.app(scope, receive, send)
  File "/opt/homebrew/lib/python3.9/site-packages/fastapi/applications.py", line 269, in __call__
    await super().__call__(scope, receive, send)
  File "/opt/homebrew/lib/python3.9/site-packages/starlette/applications.py", line 124, in __call__
    await self.middleware_stack(scope, receive, send)
  File "/opt/homebrew/lib/python3.9/site-packages/starlette/middleware/errors.py", line 184, in __call__
    raise exc
  File "/opt/homebrew/lib/python3.9/site-packages/starlette/middleware/errors.py", line 162, in __call__
    await self.app(scope, receive, _send)
  File "/opt/homebrew/lib/python3.9/site-packages/starlette/middleware/cors.py", line 84, in __call__
    await self.app(scope, receive, send)
  File "/opt/homebrew/lib/python3.9/site-packages/starlette/exceptions.py", line 93, in __call__
    raise exc
  File "/opt/homebrew/lib/python3.9/site-packages/starlette/exceptions.py", line 82, in __call__
    await self.app(scope, receive, sender)
  File "/opt/homebrew/lib/python3.9/site-packages/fastapi/middleware/asyncexitstack.py", line 21, in __call__
    raise e
  File "/opt/homebrew/lib/python3.9/site-packages/fastapi/middleware/asyncexitstack.py", line 18, in __call__
    await self.app(scope, receive, send)
  File "/opt/homebrew/lib/python3.9/site-packages/starlette/routing.py", line 670, in __call__
    await route.handle(scope, receive, send)
  File "/opt/homebrew/lib/python3.9/site-packages/starlette/routing.py", line 266, in handle
    await self.app(scope, receive, send)
  File "/opt/homebrew/lib/python3.9/site-packages/starlette/routing.py", line 65, in app
    response = await func(request)
  File "/opt/homebrew/lib/python3.9/site-packages/fastapi/routing.py", line 227, in app
    raw_response = await run_endpoint_function(
  File "/opt/homebrew/lib/python3.9/site-packages/fastapi/routing.py", line 160, in run_endpoint_function
    return await dependant.call(**values)
  File "/Users/aditya/Downloads/API 2/C/RUN/./main.py", line 1038, in create_order
    return user_result
UnboundLocalError: local variable 'user_result' referenced before assignment
root - INFO - 2023-03-21 13:30:15.909504 - Order placement successful for users: []
root - INFO - 2023-03-21 13:35:15.906492 - Order placement successful for users: []
root - INFO - 2023-03-21 13:40:15.942144 - Order placed for FINVANT_LIVE ALTAIR NIFTY_SYNTHETIC_INTRADAY_SHORT BUY 1 2 0.5
root - INFO - 2023-03-21 13:40:16.043973 - Order placed for AIRAN ALTAIR_FUTURES NIFTY OPEN SHORT -3 0.5 2
root - INFO - 2023-03-21 13:40:16.150566 - Order placed for BPWealth_AHO7706 ALTAIR_FUTURES NIFTY OPEN SHORT -2 0.5 2
root - INFO - 2023-03-21 13:40:16.259318 - Order placement successful for users: [{'user_name': 'FINVANT_LIVE', 'strategy': 'ALTAIR', 'instrument_nomenclature': 'NIFTY_SYNTHETIC_INTRADAY_SHORT', 'position': 'BUY', 'target': 0.5, 'stoploss': 2, 'quantity': 1}, {'user_name': 'AIRAN', 'strategy': 'ALTAIR_FUTURES', 'instrument_nomenclature': 'NIFTY', 'position': 'OPEN SHORT', 'target': 2, 'stoploss': 0.5, 'quantity': 3}, {'user_name': 'BPWealth_AHO7706', 'strategy': 'ALTAIR_FUTURES', 'instrument_nomenclature': 'NIFTY', 'position': 'OPEN SHORT', 'target': 2, 'stoploss': 0.5, 'quantity': 2}]
root - INFO - 2023-03-21 13:50:16.922013 - Order placement successful for users: []
root - INFO - 2023-03-21 13:55:15.910640 - Order placement successful for users: []
uvicorn.error - ERROR - Exception in ASGI application
Traceback (most recent call last):
  File "/opt/homebrew/lib/python3.9/site-packages/uvicorn/protocols/http/h11_impl.py", line 366, in run_asgi
    result = await app(self.scope, self.receive, self.send)
  File "/opt/homebrew/lib/python3.9/site-packages/uvicorn/middleware/proxy_headers.py", line 75, in __call__
    return await self.app(scope, receive, send)
  File "/opt/homebrew/lib/python3.9/site-packages/fastapi/applications.py", line 269, in __call__
    await super().__call__(scope, receive, send)
  File "/opt/homebrew/lib/python3.9/site-packages/starlette/applications.py", line 124, in __call__
    await self.middleware_stack(scope, receive, send)
  File "/opt/homebrew/lib/python3.9/site-packages/starlette/middleware/errors.py", line 184, in __call__
    raise exc
  File "/opt/homebrew/lib/python3.9/site-packages/starlette/middleware/errors.py", line 162, in __call__
    await self.app(scope, receive, _send)
  File "/opt/homebrew/lib/python3.9/site-packages/starlette/middleware/cors.py", line 84, in __call__
    await self.app(scope, receive, send)
  File "/opt/homebrew/lib/python3.9/site-packages/starlette/exceptions.py", line 93, in __call__
    raise exc
  File "/opt/homebrew/lib/python3.9/site-packages/starlette/exceptions.py", line 82, in __call__
    await self.app(scope, receive, sender)
  File "/opt/homebrew/lib/python3.9/site-packages/fastapi/middleware/asyncexitstack.py", line 21, in __call__
    raise e
  File "/opt/homebrew/lib/python3.9/site-packages/fastapi/middleware/asyncexitstack.py", line 18, in __call__
    await self.app(scope, receive, send)
  File "/opt/homebrew/lib/python3.9/site-packages/starlette/routing.py", line 670, in __call__
    await route.handle(scope, receive, send)
  File "/opt/homebrew/lib/python3.9/site-packages/starlette/routing.py", line 266, in handle
    await self.app(scope, receive, send)
  File "/opt/homebrew/lib/python3.9/site-packages/starlette/routing.py", line 65, in app
    response = await func(request)
  File "/opt/homebrew/lib/python3.9/site-packages/fastapi/routing.py", line 227, in app
    raw_response = await run_endpoint_function(
  File "/opt/homebrew/lib/python3.9/site-packages/fastapi/routing.py", line 160, in run_endpoint_function
    return await dependant.call(**values)
  File "/Users/aditya/Downloads/API 2/C/RUN/./main.py", line 1038, in create_order
    return user_result
UnboundLocalError: local variable 'user_result' referenced before assignment
root - INFO - 2023-03-21 13:55:17.191505 - Order placement successful for users: []
uvicorn.error - ERROR - Exception in ASGI application
Traceback (most recent call last):
  File "/opt/homebrew/lib/python3.9/site-packages/uvicorn/protocols/http/h11_impl.py", line 366, in run_asgi
    result = await app(self.scope, self.receive, self.send)
  File "/opt/homebrew/lib/python3.9/site-packages/uvicorn/middleware/proxy_headers.py", line 75, in __call__
    return await self.app(scope, receive, send)
  File "/opt/homebrew/lib/python3.9/site-packages/fastapi/applications.py", line 269, in __call__
    await super().__call__(scope, receive, send)
  File "/opt/homebrew/lib/python3.9/site-packages/starlette/applications.py", line 124, in __call__
    await self.middleware_stack(scope, receive, send)
  File "/opt/homebrew/lib/python3.9/site-packages/starlette/middleware/errors.py", line 184, in __call__
    raise exc
  File "/opt/homebrew/lib/python3.9/site-packages/starlette/middleware/errors.py", line 162, in __call__
    await self.app(scope, receive, _send)
  File "/opt/homebrew/lib/python3.9/site-packages/starlette/middleware/cors.py", line 84, in __call__
    await self.app(scope, receive, send)
  File "/opt/homebrew/lib/python3.9/site-packages/starlette/exceptions.py", line 93, in __call__
    raise exc
  File "/opt/homebrew/lib/python3.9/site-packages/starlette/exceptions.py", line 82, in __call__
    await self.app(scope, receive, sender)
  File "/opt/homebrew/lib/python3.9/site-packages/fastapi/middleware/asyncexitstack.py", line 21, in __call__
    raise e
  File "/opt/homebrew/lib/python3.9/site-packages/fastapi/middleware/asyncexitstack.py", line 18, in __call__
    await self.app(scope, receive, send)
  File "/opt/homebrew/lib/python3.9/site-packages/starlette/routing.py", line 670, in __call__
    await route.handle(scope, receive, send)
  File "/opt/homebrew/lib/python3.9/site-packages/starlette/routing.py", line 266, in handle
    await self.app(scope, receive, send)
  File "/opt/homebrew/lib/python3.9/site-packages/starlette/routing.py", line 65, in app
    response = await func(request)
  File "/opt/homebrew/lib/python3.9/site-packages/fastapi/routing.py", line 227, in app
    raw_response = await run_endpoint_function(
  File "/opt/homebrew/lib/python3.9/site-packages/fastapi/routing.py", line 160, in run_endpoint_function
    return await dependant.call(**values)
  File "/Users/aditya/Downloads/API 2/C/RUN/./main.py", line 1038, in create_order
    return user_result
UnboundLocalError: local variable 'user_result' referenced before assignment
root - INFO - 2023-03-21 14:00:15.925525 - Order placement successful for users: []
uvicorn.error - ERROR - Exception in ASGI application
Traceback (most recent call last):
  File "/opt/homebrew/lib/python3.9/site-packages/uvicorn/protocols/http/h11_impl.py", line 366, in run_asgi
    result = await app(self.scope, self.receive, self.send)
  File "/opt/homebrew/lib/python3.9/site-packages/uvicorn/middleware/proxy_headers.py", line 75, in __call__
    return await self.app(scope, receive, send)
  File "/opt/homebrew/lib/python3.9/site-packages/fastapi/applications.py", line 269, in __call__
    await super().__call__(scope, receive, send)
  File "/opt/homebrew/lib/python3.9/site-packages/starlette/applications.py", line 124, in __call__
    await self.middleware_stack(scope, receive, send)
  File "/opt/homebrew/lib/python3.9/site-packages/starlette/middleware/errors.py", line 184, in __call__
    raise exc
  File "/opt/homebrew/lib/python3.9/site-packages/starlette/middleware/errors.py", line 162, in __call__
    await self.app(scope, receive, _send)
  File "/opt/homebrew/lib/python3.9/site-packages/starlette/middleware/cors.py", line 84, in __call__
    await self.app(scope, receive, send)
  File "/opt/homebrew/lib/python3.9/site-packages/starlette/exceptions.py", line 93, in __call__
    raise exc
  File "/opt/homebrew/lib/python3.9/site-packages/starlette/exceptions.py", line 82, in __call__
    await self.app(scope, receive, sender)
  File "/opt/homebrew/lib/python3.9/site-packages/fastapi/middleware/asyncexitstack.py", line 21, in __call__
    raise e
  File "/opt/homebrew/lib/python3.9/site-packages/fastapi/middleware/asyncexitstack.py", line 18, in __call__
    await self.app(scope, receive, send)
  File "/opt/homebrew/lib/python3.9/site-packages/starlette/routing.py", line 670, in __call__
    await route.handle(scope, receive, send)
  File "/opt/homebrew/lib/python3.9/site-packages/starlette/routing.py", line 266, in handle
    await self.app(scope, receive, send)
  File "/opt/homebrew/lib/python3.9/site-packages/starlette/routing.py", line 65, in app
    response = await func(request)
  File "/opt/homebrew/lib/python3.9/site-packages/fastapi/routing.py", line 227, in app
    raw_response = await run_endpoint_function(
  File "/opt/homebrew/lib/python3.9/site-packages/fastapi/routing.py", line 160, in run_endpoint_function
    return await dependant.call(**values)
  File "/Users/aditya/Downloads/API 2/C/RUN/./main.py", line 1038, in create_order
    return user_result
UnboundLocalError: local variable 'user_result' referenced before assignment
root - INFO - 2023-03-21 14:00:17.218726 - Order placement successful for users: []
uvicorn.error - ERROR - Exception in ASGI application
Traceback (most recent call last):
  File "/opt/homebrew/lib/python3.9/site-packages/uvicorn/protocols/http/h11_impl.py", line 366, in run_asgi
    result = await app(self.scope, self.receive, self.send)
  File "/opt/homebrew/lib/python3.9/site-packages/uvicorn/middleware/proxy_headers.py", line 75, in __call__
    return await self.app(scope, receive, send)
  File "/opt/homebrew/lib/python3.9/site-packages/fastapi/applications.py", line 269, in __call__
    await super().__call__(scope, receive, send)
  File "/opt/homebrew/lib/python3.9/site-packages/starlette/applications.py", line 124, in __call__
    await self.middleware_stack(scope, receive, send)
  File "/opt/homebrew/lib/python3.9/site-packages/starlette/middleware/errors.py", line 184, in __call__
    raise exc
  File "/opt/homebrew/lib/python3.9/site-packages/starlette/middleware/errors.py", line 162, in __call__
    await self.app(scope, receive, _send)
  File "/opt/homebrew/lib/python3.9/site-packages/starlette/middleware/cors.py", line 84, in __call__
    await self.app(scope, receive, send)
  File "/opt/homebrew/lib/python3.9/site-packages/starlette/exceptions.py", line 93, in __call__
    raise exc
  File "/opt/homebrew/lib/python3.9/site-packages/starlette/exceptions.py", line 82, in __call__
    await self.app(scope, receive, sender)
  File "/opt/homebrew/lib/python3.9/site-packages/fastapi/middleware/asyncexitstack.py", line 21, in __call__
    raise e
  File "/opt/homebrew/lib/python3.9/site-packages/fastapi/middleware/asyncexitstack.py", line 18, in __call__
    await self.app(scope, receive, send)
  File "/opt/homebrew/lib/python3.9/site-packages/starlette/routing.py", line 670, in __call__
    await route.handle(scope, receive, send)
  File "/opt/homebrew/lib/python3.9/site-packages/starlette/routing.py", line 266, in handle
    await self.app(scope, receive, send)
  File "/opt/homebrew/lib/python3.9/site-packages/starlette/routing.py", line 65, in app
    response = await func(request)
  File "/opt/homebrew/lib/python3.9/site-packages/fastapi/routing.py", line 227, in app
    raw_response = await run_endpoint_function(
  File "/opt/homebrew/lib/python3.9/site-packages/fastapi/routing.py", line 160, in run_endpoint_function
    return await dependant.call(**values)
  File "/Users/aditya/Downloads/API 2/C/RUN/./main.py", line 1038, in create_order
    return user_result
UnboundLocalError: local variable 'user_result' referenced before assignment
root - INFO - 2023-03-21 14:05:15.892693 - Order placement successful for users: []
uvicorn.error - ERROR - Exception in ASGI application
Traceback (most recent call last):
  File "/opt/homebrew/lib/python3.9/site-packages/uvicorn/protocols/http/h11_impl.py", line 366, in run_asgi
    result = await app(self.scope, self.receive, self.send)
  File "/opt/homebrew/lib/python3.9/site-packages/uvicorn/middleware/proxy_headers.py", line 75, in __call__
    return await self.app(scope, receive, send)
  File "/opt/homebrew/lib/python3.9/site-packages/fastapi/applications.py", line 269, in __call__
    await super().__call__(scope, receive, send)
  File "/opt/homebrew/lib/python3.9/site-packages/starlette/applications.py", line 124, in __call__
    await self.middleware_stack(scope, receive, send)
  File "/opt/homebrew/lib/python3.9/site-packages/starlette/middleware/errors.py", line 184, in __call__
    raise exc
  File "/opt/homebrew/lib/python3.9/site-packages/starlette/middleware/errors.py", line 162, in __call__
    await self.app(scope, receive, _send)
  File "/opt/homebrew/lib/python3.9/site-packages/starlette/middleware/cors.py", line 84, in __call__
    await self.app(scope, receive, send)
  File "/opt/homebrew/lib/python3.9/site-packages/starlette/exceptions.py", line 93, in __call__
    raise exc
  File "/opt/homebrew/lib/python3.9/site-packages/starlette/exceptions.py", line 82, in __call__
    await self.app(scope, receive, sender)
  File "/opt/homebrew/lib/python3.9/site-packages/fastapi/middleware/asyncexitstack.py", line 21, in __call__
    raise e
  File "/opt/homebrew/lib/python3.9/site-packages/fastapi/middleware/asyncexitstack.py", line 18, in __call__
    await self.app(scope, receive, send)
  File "/opt/homebrew/lib/python3.9/site-packages/starlette/routing.py", line 670, in __call__
    await route.handle(scope, receive, send)
  File "/opt/homebrew/lib/python3.9/site-packages/starlette/routing.py", line 266, in handle
    await self.app(scope, receive, send)
  File "/opt/homebrew/lib/python3.9/site-packages/starlette/routing.py", line 65, in app
    response = await func(request)
  File "/opt/homebrew/lib/python3.9/site-packages/fastapi/routing.py", line 227, in app
    raw_response = await run_endpoint_function(
  File "/opt/homebrew/lib/python3.9/site-packages/fastapi/routing.py", line 160, in run_endpoint_function
    return await dependant.call(**values)
  File "/Users/aditya/Downloads/API 2/C/RUN/./main.py", line 1038, in create_order
    return user_result
UnboundLocalError: local variable 'user_result' referenced before assignment
root - INFO - 2023-03-21 14:05:17.150822 - Order placement successful for users: []
uvicorn.error - ERROR - Exception in ASGI application
Traceback (most recent call last):
  File "/opt/homebrew/lib/python3.9/site-packages/uvicorn/protocols/http/h11_impl.py", line 366, in run_asgi
    result = await app(self.scope, self.receive, self.send)
  File "/opt/homebrew/lib/python3.9/site-packages/uvicorn/middleware/proxy_headers.py", line 75, in __call__
    return await self.app(scope, receive, send)
  File "/opt/homebrew/lib/python3.9/site-packages/fastapi/applications.py", line 269, in __call__
    await super().__call__(scope, receive, send)
  File "/opt/homebrew/lib/python3.9/site-packages/starlette/applications.py", line 124, in __call__
    await self.middleware_stack(scope, receive, send)
  File "/opt/homebrew/lib/python3.9/site-packages/starlette/middleware/errors.py", line 184, in __call__
    raise exc
  File "/opt/homebrew/lib/python3.9/site-packages/starlette/middleware/errors.py", line 162, in __call__
    await self.app(scope, receive, _send)
  File "/opt/homebrew/lib/python3.9/site-packages/starlette/middleware/cors.py", line 84, in __call__
    await self.app(scope, receive, send)
  File "/opt/homebrew/lib/python3.9/site-packages/starlette/exceptions.py", line 93, in __call__
    raise exc
  File "/opt/homebrew/lib/python3.9/site-packages/starlette/exceptions.py", line 82, in __call__
    await self.app(scope, receive, sender)
  File "/opt/homebrew/lib/python3.9/site-packages/fastapi/middleware/asyncexitstack.py", line 21, in __call__
    raise e
  File "/opt/homebrew/lib/python3.9/site-packages/fastapi/middleware/asyncexitstack.py", line 18, in __call__
    await self.app(scope, receive, send)
  File "/opt/homebrew/lib/python3.9/site-packages/starlette/routing.py", line 670, in __call__
    await route.handle(scope, receive, send)
  File "/opt/homebrew/lib/python3.9/site-packages/starlette/routing.py", line 266, in handle
    await self.app(scope, receive, send)
  File "/opt/homebrew/lib/python3.9/site-packages/starlette/routing.py", line 65, in app
    response = await func(request)
  File "/opt/homebrew/lib/python3.9/site-packages/fastapi/routing.py", line 227, in app
    raw_response = await run_endpoint_function(
  File "/opt/homebrew/lib/python3.9/site-packages/fastapi/routing.py", line 160, in run_endpoint_function
    return await dependant.call(**values)
  File "/Users/aditya/Downloads/API 2/C/RUN/./main.py", line 1038, in create_order
    return user_result
UnboundLocalError: local variable 'user_result' referenced before assignment
root - INFO - 2023-03-21 14:10:15.887679 - Order placement successful for users: []
uvicorn.error - ERROR - Exception in ASGI application
Traceback (most recent call last):
  File "/opt/homebrew/lib/python3.9/site-packages/uvicorn/protocols/http/h11_impl.py", line 366, in run_asgi
    result = await app(self.scope, self.receive, self.send)
  File "/opt/homebrew/lib/python3.9/site-packages/uvicorn/middleware/proxy_headers.py", line 75, in __call__
    return await self.app(scope, receive, send)
  File "/opt/homebrew/lib/python3.9/site-packages/fastapi/applications.py", line 269, in __call__
    await super().__call__(scope, receive, send)
  File "/opt/homebrew/lib/python3.9/site-packages/starlette/applications.py", line 124, in __call__
    await self.middleware_stack(scope, receive, send)
  File "/opt/homebrew/lib/python3.9/site-packages/starlette/middleware/errors.py", line 184, in __call__
    raise exc
  File "/opt/homebrew/lib/python3.9/site-packages/starlette/middleware/errors.py", line 162, in __call__
    await self.app(scope, receive, _send)
  File "/opt/homebrew/lib/python3.9/site-packages/starlette/middleware/cors.py", line 84, in __call__
    await self.app(scope, receive, send)
  File "/opt/homebrew/lib/python3.9/site-packages/starlette/exceptions.py", line 93, in __call__
    raise exc
  File "/opt/homebrew/lib/python3.9/site-packages/starlette/exceptions.py", line 82, in __call__
    await self.app(scope, receive, sender)
  File "/opt/homebrew/lib/python3.9/site-packages/fastapi/middleware/asyncexitstack.py", line 21, in __call__
    raise e
  File "/opt/homebrew/lib/python3.9/site-packages/fastapi/middleware/asyncexitstack.py", line 18, in __call__
    await self.app(scope, receive, send)
  File "/opt/homebrew/lib/python3.9/site-packages/starlette/routing.py", line 670, in __call__
    await route.handle(scope, receive, send)
  File "/opt/homebrew/lib/python3.9/site-packages/starlette/routing.py", line 266, in handle
    await self.app(scope, receive, send)
  File "/opt/homebrew/lib/python3.9/site-packages/starlette/routing.py", line 65, in app
    response = await func(request)
  File "/opt/homebrew/lib/python3.9/site-packages/fastapi/routing.py", line 227, in app
    raw_response = await run_endpoint_function(
  File "/opt/homebrew/lib/python3.9/site-packages/fastapi/routing.py", line 160, in run_endpoint_function
    return await dependant.call(**values)
  File "/Users/aditya/Downloads/API 2/C/RUN/./main.py", line 1038, in create_order
    return user_result
UnboundLocalError: local variable 'user_result' referenced before assignment
root - INFO - 2023-03-21 14:10:17.103585 - Order placement successful for users: []
uvicorn.error - ERROR - Exception in ASGI application
Traceback (most recent call last):
  File "/opt/homebrew/lib/python3.9/site-packages/uvicorn/protocols/http/h11_impl.py", line 366, in run_asgi
    result = await app(self.scope, self.receive, self.send)
  File "/opt/homebrew/lib/python3.9/site-packages/uvicorn/middleware/proxy_headers.py", line 75, in __call__
    return await self.app(scope, receive, send)
  File "/opt/homebrew/lib/python3.9/site-packages/fastapi/applications.py", line 269, in __call__
    await super().__call__(scope, receive, send)
  File "/opt/homebrew/lib/python3.9/site-packages/starlette/applications.py", line 124, in __call__
    await self.middleware_stack(scope, receive, send)
  File "/opt/homebrew/lib/python3.9/site-packages/starlette/middleware/errors.py", line 184, in __call__
    raise exc
  File "/opt/homebrew/lib/python3.9/site-packages/starlette/middleware/errors.py", line 162, in __call__
    await self.app(scope, receive, _send)
  File "/opt/homebrew/lib/python3.9/site-packages/starlette/middleware/cors.py", line 84, in __call__
    await self.app(scope, receive, send)
  File "/opt/homebrew/lib/python3.9/site-packages/starlette/exceptions.py", line 93, in __call__
    raise exc
  File "/opt/homebrew/lib/python3.9/site-packages/starlette/exceptions.py", line 82, in __call__
    await self.app(scope, receive, sender)
  File "/opt/homebrew/lib/python3.9/site-packages/fastapi/middleware/asyncexitstack.py", line 21, in __call__
    raise e
  File "/opt/homebrew/lib/python3.9/site-packages/fastapi/middleware/asyncexitstack.py", line 18, in __call__
    await self.app(scope, receive, send)
  File "/opt/homebrew/lib/python3.9/site-packages/starlette/routing.py", line 670, in __call__
    await route.handle(scope, receive, send)
  File "/opt/homebrew/lib/python3.9/site-packages/starlette/routing.py", line 266, in handle
    await self.app(scope, receive, send)
  File "/opt/homebrew/lib/python3.9/site-packages/starlette/routing.py", line 65, in app
    response = await func(request)
  File "/opt/homebrew/lib/python3.9/site-packages/fastapi/routing.py", line 227, in app
    raw_response = await run_endpoint_function(
  File "/opt/homebrew/lib/python3.9/site-packages/fastapi/routing.py", line 160, in run_endpoint_function
    return await dependant.call(**values)
  File "/Users/aditya/Downloads/API 2/C/RUN/./main.py", line 1038, in create_order
    return user_result
UnboundLocalError: local variable 'user_result' referenced before assignment
root - INFO - 2023-03-21 14:15:16.054528 - Order placement successful for users: []
uvicorn.error - ERROR - Exception in ASGI application
Traceback (most recent call last):
  File "/opt/homebrew/lib/python3.9/site-packages/uvicorn/protocols/http/h11_impl.py", line 366, in run_asgi
    result = await app(self.scope, self.receive, self.send)
  File "/opt/homebrew/lib/python3.9/site-packages/uvicorn/middleware/proxy_headers.py", line 75, in __call__
    return await self.app(scope, receive, send)
  File "/opt/homebrew/lib/python3.9/site-packages/fastapi/applications.py", line 269, in __call__
    await super().__call__(scope, receive, send)
  File "/opt/homebrew/lib/python3.9/site-packages/starlette/applications.py", line 124, in __call__
    await self.middleware_stack(scope, receive, send)
  File "/opt/homebrew/lib/python3.9/site-packages/starlette/middleware/errors.py", line 184, in __call__
    raise exc
  File "/opt/homebrew/lib/python3.9/site-packages/starlette/middleware/errors.py", line 162, in __call__
    await self.app(scope, receive, _send)
  File "/opt/homebrew/lib/python3.9/site-packages/starlette/middleware/cors.py", line 84, in __call__
    await self.app(scope, receive, send)
  File "/opt/homebrew/lib/python3.9/site-packages/starlette/exceptions.py", line 93, in __call__
    raise exc
  File "/opt/homebrew/lib/python3.9/site-packages/starlette/exceptions.py", line 82, in __call__
    await self.app(scope, receive, sender)
  File "/opt/homebrew/lib/python3.9/site-packages/fastapi/middleware/asyncexitstack.py", line 21, in __call__
    raise e
  File "/opt/homebrew/lib/python3.9/site-packages/fastapi/middleware/asyncexitstack.py", line 18, in __call__
    await self.app(scope, receive, send)
  File "/opt/homebrew/lib/python3.9/site-packages/starlette/routing.py", line 670, in __call__
    await route.handle(scope, receive, send)
  File "/opt/homebrew/lib/python3.9/site-packages/starlette/routing.py", line 266, in handle
    await self.app(scope, receive, send)
  File "/opt/homebrew/lib/python3.9/site-packages/starlette/routing.py", line 65, in app
    response = await func(request)
  File "/opt/homebrew/lib/python3.9/site-packages/fastapi/routing.py", line 227, in app
    raw_response = await run_endpoint_function(
  File "/opt/homebrew/lib/python3.9/site-packages/fastapi/routing.py", line 160, in run_endpoint_function
    return await dependant.call(**values)
  File "/Users/aditya/Downloads/API 2/C/RUN/./main.py", line 1038, in create_order
    return user_result
UnboundLocalError: local variable 'user_result' referenced before assignment
root - INFO - 2023-03-21 14:15:17.396549 - Order placement successful for users: []
uvicorn.error - ERROR - Exception in ASGI application
Traceback (most recent call last):
  File "/opt/homebrew/lib/python3.9/site-packages/uvicorn/protocols/http/h11_impl.py", line 366, in run_asgi
    result = await app(self.scope, self.receive, self.send)
  File "/opt/homebrew/lib/python3.9/site-packages/uvicorn/middleware/proxy_headers.py", line 75, in __call__
    return await self.app(scope, receive, send)
  File "/opt/homebrew/lib/python3.9/site-packages/fastapi/applications.py", line 269, in __call__
    await super().__call__(scope, receive, send)
  File "/opt/homebrew/lib/python3.9/site-packages/starlette/applications.py", line 124, in __call__
    await self.middleware_stack(scope, receive, send)
  File "/opt/homebrew/lib/python3.9/site-packages/starlette/middleware/errors.py", line 184, in __call__
    raise exc
  File "/opt/homebrew/lib/python3.9/site-packages/starlette/middleware/errors.py", line 162, in __call__
    await self.app(scope, receive, _send)
  File "/opt/homebrew/lib/python3.9/site-packages/starlette/middleware/cors.py", line 84, in __call__
    await self.app(scope, receive, send)
  File "/opt/homebrew/lib/python3.9/site-packages/starlette/exceptions.py", line 93, in __call__
    raise exc
  File "/opt/homebrew/lib/python3.9/site-packages/starlette/exceptions.py", line 82, in __call__
    await self.app(scope, receive, sender)
  File "/opt/homebrew/lib/python3.9/site-packages/fastapi/middleware/asyncexitstack.py", line 21, in __call__
    raise e
  File "/opt/homebrew/lib/python3.9/site-packages/fastapi/middleware/asyncexitstack.py", line 18, in __call__
    await self.app(scope, receive, send)
  File "/opt/homebrew/lib/python3.9/site-packages/starlette/routing.py", line 670, in __call__
    await route.handle(scope, receive, send)
  File "/opt/homebrew/lib/python3.9/site-packages/starlette/routing.py", line 266, in handle
    await self.app(scope, receive, send)
  File "/opt/homebrew/lib/python3.9/site-packages/starlette/routing.py", line 65, in app
    response = await func(request)
  File "/opt/homebrew/lib/python3.9/site-packages/fastapi/routing.py", line 227, in app
    raw_response = await run_endpoint_function(
  File "/opt/homebrew/lib/python3.9/site-packages/fastapi/routing.py", line 160, in run_endpoint_function
    return await dependant.call(**values)
  File "/Users/aditya/Downloads/API 2/C/RUN/./main.py", line 1038, in create_order
    return user_result
UnboundLocalError: local variable 'user_result' referenced before assignment
root - INFO - 2023-03-21 14:20:15.895778 - Order placement successful for users: []
uvicorn.error - ERROR - Exception in ASGI application
Traceback (most recent call last):
  File "/opt/homebrew/lib/python3.9/site-packages/uvicorn/protocols/http/h11_impl.py", line 366, in run_asgi
    result = await app(self.scope, self.receive, self.send)
  File "/opt/homebrew/lib/python3.9/site-packages/uvicorn/middleware/proxy_headers.py", line 75, in __call__
    return await self.app(scope, receive, send)
  File "/opt/homebrew/lib/python3.9/site-packages/fastapi/applications.py", line 269, in __call__
    await super().__call__(scope, receive, send)
  File "/opt/homebrew/lib/python3.9/site-packages/starlette/applications.py", line 124, in __call__
    await self.middleware_stack(scope, receive, send)
  File "/opt/homebrew/lib/python3.9/site-packages/starlette/middleware/errors.py", line 184, in __call__
    raise exc
  File "/opt/homebrew/lib/python3.9/site-packages/starlette/middleware/errors.py", line 162, in __call__
    await self.app(scope, receive, _send)
  File "/opt/homebrew/lib/python3.9/site-packages/starlette/middleware/cors.py", line 84, in __call__
    await self.app(scope, receive, send)
  File "/opt/homebrew/lib/python3.9/site-packages/starlette/exceptions.py", line 93, in __call__
    raise exc
  File "/opt/homebrew/lib/python3.9/site-packages/starlette/exceptions.py", line 82, in __call__
    await self.app(scope, receive, sender)
  File "/opt/homebrew/lib/python3.9/site-packages/fastapi/middleware/asyncexitstack.py", line 21, in __call__
    raise e
  File "/opt/homebrew/lib/python3.9/site-packages/fastapi/middleware/asyncexitstack.py", line 18, in __call__
    await self.app(scope, receive, send)
  File "/opt/homebrew/lib/python3.9/site-packages/starlette/routing.py", line 670, in __call__
    await route.handle(scope, receive, send)
  File "/opt/homebrew/lib/python3.9/site-packages/starlette/routing.py", line 266, in handle
    await self.app(scope, receive, send)
  File "/opt/homebrew/lib/python3.9/site-packages/starlette/routing.py", line 65, in app
    response = await func(request)
  File "/opt/homebrew/lib/python3.9/site-packages/fastapi/routing.py", line 227, in app
    raw_response = await run_endpoint_function(
  File "/opt/homebrew/lib/python3.9/site-packages/fastapi/routing.py", line 160, in run_endpoint_function
    return await dependant.call(**values)
  File "/Users/aditya/Downloads/API 2/C/RUN/./main.py", line 1038, in create_order
    return user_result
UnboundLocalError: local variable 'user_result' referenced before assignment
root - INFO - 2023-03-21 14:20:17.233681 - Order placement successful for users: []
uvicorn.error - ERROR - Exception in ASGI application
Traceback (most recent call last):
  File "/opt/homebrew/lib/python3.9/site-packages/uvicorn/protocols/http/h11_impl.py", line 366, in run_asgi
    result = await app(self.scope, self.receive, self.send)
  File "/opt/homebrew/lib/python3.9/site-packages/uvicorn/middleware/proxy_headers.py", line 75, in __call__
    return await self.app(scope, receive, send)
  File "/opt/homebrew/lib/python3.9/site-packages/fastapi/applications.py", line 269, in __call__
    await super().__call__(scope, receive, send)
  File "/opt/homebrew/lib/python3.9/site-packages/starlette/applications.py", line 124, in __call__
    await self.middleware_stack(scope, receive, send)
  File "/opt/homebrew/lib/python3.9/site-packages/starlette/middleware/errors.py", line 184, in __call__
    raise exc
  File "/opt/homebrew/lib/python3.9/site-packages/starlette/middleware/errors.py", line 162, in __call__
    await self.app(scope, receive, _send)
  File "/opt/homebrew/lib/python3.9/site-packages/starlette/middleware/cors.py", line 84, in __call__
    await self.app(scope, receive, send)
  File "/opt/homebrew/lib/python3.9/site-packages/starlette/exceptions.py", line 93, in __call__
    raise exc
  File "/opt/homebrew/lib/python3.9/site-packages/starlette/exceptions.py", line 82, in __call__
    await self.app(scope, receive, sender)
  File "/opt/homebrew/lib/python3.9/site-packages/fastapi/middleware/asyncexitstack.py", line 21, in __call__
    raise e
  File "/opt/homebrew/lib/python3.9/site-packages/fastapi/middleware/asyncexitstack.py", line 18, in __call__
    await self.app(scope, receive, send)
  File "/opt/homebrew/lib/python3.9/site-packages/starlette/routing.py", line 670, in __call__
    await route.handle(scope, receive, send)
  File "/opt/homebrew/lib/python3.9/site-packages/starlette/routing.py", line 266, in handle
    await self.app(scope, receive, send)
  File "/opt/homebrew/lib/python3.9/site-packages/starlette/routing.py", line 65, in app
    response = await func(request)
  File "/opt/homebrew/lib/python3.9/site-packages/fastapi/routing.py", line 227, in app
    raw_response = await run_endpoint_function(
  File "/opt/homebrew/lib/python3.9/site-packages/fastapi/routing.py", line 160, in run_endpoint_function
    return await dependant.call(**values)
  File "/Users/aditya/Downloads/API 2/C/RUN/./main.py", line 1038, in create_order
    return user_result
UnboundLocalError: local variable 'user_result' referenced before assignment
root - INFO - 2023-03-21 14:25:15.917723 - Order placement successful for users: []
uvicorn.error - ERROR - Exception in ASGI application
Traceback (most recent call last):
  File "/opt/homebrew/lib/python3.9/site-packages/uvicorn/protocols/http/h11_impl.py", line 366, in run_asgi
    result = await app(self.scope, self.receive, self.send)
  File "/opt/homebrew/lib/python3.9/site-packages/uvicorn/middleware/proxy_headers.py", line 75, in __call__
    return await self.app(scope, receive, send)
  File "/opt/homebrew/lib/python3.9/site-packages/fastapi/applications.py", line 269, in __call__
    await super().__call__(scope, receive, send)
  File "/opt/homebrew/lib/python3.9/site-packages/starlette/applications.py", line 124, in __call__
    await self.middleware_stack(scope, receive, send)
  File "/opt/homebrew/lib/python3.9/site-packages/starlette/middleware/errors.py", line 184, in __call__
    raise exc
  File "/opt/homebrew/lib/python3.9/site-packages/starlette/middleware/errors.py", line 162, in __call__
    await self.app(scope, receive, _send)
  File "/opt/homebrew/lib/python3.9/site-packages/starlette/middleware/cors.py", line 84, in __call__
    await self.app(scope, receive, send)
  File "/opt/homebrew/lib/python3.9/site-packages/starlette/exceptions.py", line 93, in __call__
    raise exc
  File "/opt/homebrew/lib/python3.9/site-packages/starlette/exceptions.py", line 82, in __call__
    await self.app(scope, receive, sender)
  File "/opt/homebrew/lib/python3.9/site-packages/fastapi/middleware/asyncexitstack.py", line 21, in __call__
    raise e
  File "/opt/homebrew/lib/python3.9/site-packages/fastapi/middleware/asyncexitstack.py", line 18, in __call__
    await self.app(scope, receive, send)
  File "/opt/homebrew/lib/python3.9/site-packages/starlette/routing.py", line 670, in __call__
    await route.handle(scope, receive, send)
  File "/opt/homebrew/lib/python3.9/site-packages/starlette/routing.py", line 266, in handle
    await self.app(scope, receive, send)
  File "/opt/homebrew/lib/python3.9/site-packages/starlette/routing.py", line 65, in app
    response = await func(request)
  File "/opt/homebrew/lib/python3.9/site-packages/fastapi/routing.py", line 227, in app
    raw_response = await run_endpoint_function(
  File "/opt/homebrew/lib/python3.9/site-packages/fastapi/routing.py", line 160, in run_endpoint_function
    return await dependant.call(**values)
  File "/Users/aditya/Downloads/API 2/C/RUN/./main.py", line 1038, in create_order
    return user_result
UnboundLocalError: local variable 'user_result' referenced before assignment
root - INFO - 2023-03-21 14:25:17.184778 - Order placement successful for users: []
uvicorn.error - ERROR - Exception in ASGI application
Traceback (most recent call last):
  File "/opt/homebrew/lib/python3.9/site-packages/uvicorn/protocols/http/h11_impl.py", line 366, in run_asgi
    result = await app(self.scope, self.receive, self.send)
  File "/opt/homebrew/lib/python3.9/site-packages/uvicorn/middleware/proxy_headers.py", line 75, in __call__
    return await self.app(scope, receive, send)
  File "/opt/homebrew/lib/python3.9/site-packages/fastapi/applications.py", line 269, in __call__
    await super().__call__(scope, receive, send)
  File "/opt/homebrew/lib/python3.9/site-packages/starlette/applications.py", line 124, in __call__
    await self.middleware_stack(scope, receive, send)
  File "/opt/homebrew/lib/python3.9/site-packages/starlette/middleware/errors.py", line 184, in __call__
    raise exc
  File "/opt/homebrew/lib/python3.9/site-packages/starlette/middleware/errors.py", line 162, in __call__
    await self.app(scope, receive, _send)
  File "/opt/homebrew/lib/python3.9/site-packages/starlette/middleware/cors.py", line 84, in __call__
    await self.app(scope, receive, send)
  File "/opt/homebrew/lib/python3.9/site-packages/starlette/exceptions.py", line 93, in __call__
    raise exc
  File "/opt/homebrew/lib/python3.9/site-packages/starlette/exceptions.py", line 82, in __call__
    await self.app(scope, receive, sender)
  File "/opt/homebrew/lib/python3.9/site-packages/fastapi/middleware/asyncexitstack.py", line 21, in __call__
    raise e
  File "/opt/homebrew/lib/python3.9/site-packages/fastapi/middleware/asyncexitstack.py", line 18, in __call__
    await self.app(scope, receive, send)
  File "/opt/homebrew/lib/python3.9/site-packages/starlette/routing.py", line 670, in __call__
    await route.handle(scope, receive, send)
  File "/opt/homebrew/lib/python3.9/site-packages/starlette/routing.py", line 266, in handle
    await self.app(scope, receive, send)
  File "/opt/homebrew/lib/python3.9/site-packages/starlette/routing.py", line 65, in app
    response = await func(request)
  File "/opt/homebrew/lib/python3.9/site-packages/fastapi/routing.py", line 227, in app
    raw_response = await run_endpoint_function(
  File "/opt/homebrew/lib/python3.9/site-packages/fastapi/routing.py", line 160, in run_endpoint_function
    return await dependant.call(**values)
  File "/Users/aditya/Downloads/API 2/C/RUN/./main.py", line 1038, in create_order
    return user_result
UnboundLocalError: local variable 'user_result' referenced before assignment
root - INFO - 2023-03-21 14:30:15.931341 - Order placement successful for users: []
uvicorn.error - ERROR - Exception in ASGI application
Traceback (most recent call last):
  File "/opt/homebrew/lib/python3.9/site-packages/uvicorn/protocols/http/h11_impl.py", line 366, in run_asgi
    result = await app(self.scope, self.receive, self.send)
  File "/opt/homebrew/lib/python3.9/site-packages/uvicorn/middleware/proxy_headers.py", line 75, in __call__
    return await self.app(scope, receive, send)
  File "/opt/homebrew/lib/python3.9/site-packages/fastapi/applications.py", line 269, in __call__
    await super().__call__(scope, receive, send)
  File "/opt/homebrew/lib/python3.9/site-packages/starlette/applications.py", line 124, in __call__
    await self.middleware_stack(scope, receive, send)
  File "/opt/homebrew/lib/python3.9/site-packages/starlette/middleware/errors.py", line 184, in __call__
    raise exc
  File "/opt/homebrew/lib/python3.9/site-packages/starlette/middleware/errors.py", line 162, in __call__
    await self.app(scope, receive, _send)
  File "/opt/homebrew/lib/python3.9/site-packages/starlette/middleware/cors.py", line 84, in __call__
    await self.app(scope, receive, send)
  File "/opt/homebrew/lib/python3.9/site-packages/starlette/exceptions.py", line 93, in __call__
    raise exc
  File "/opt/homebrew/lib/python3.9/site-packages/starlette/exceptions.py", line 82, in __call__
    await self.app(scope, receive, sender)
  File "/opt/homebrew/lib/python3.9/site-packages/fastapi/middleware/asyncexitstack.py", line 21, in __call__
    raise e
  File "/opt/homebrew/lib/python3.9/site-packages/fastapi/middleware/asyncexitstack.py", line 18, in __call__
    await self.app(scope, receive, send)
  File "/opt/homebrew/lib/python3.9/site-packages/starlette/routing.py", line 670, in __call__
    await route.handle(scope, receive, send)
  File "/opt/homebrew/lib/python3.9/site-packages/starlette/routing.py", line 266, in handle
    await self.app(scope, receive, send)
  File "/opt/homebrew/lib/python3.9/site-packages/starlette/routing.py", line 65, in app
    response = await func(request)
  File "/opt/homebrew/lib/python3.9/site-packages/fastapi/routing.py", line 227, in app
    raw_response = await run_endpoint_function(
  File "/opt/homebrew/lib/python3.9/site-packages/fastapi/routing.py", line 160, in run_endpoint_function
    return await dependant.call(**values)
  File "/Users/aditya/Downloads/API 2/C/RUN/./main.py", line 1038, in create_order
    return user_result
UnboundLocalError: local variable 'user_result' referenced before assignment
root - INFO - 2023-03-21 14:30:17.314549 - Order placement successful for users: []
uvicorn.error - ERROR - Exception in ASGI application
Traceback (most recent call last):
  File "/opt/homebrew/lib/python3.9/site-packages/uvicorn/protocols/http/h11_impl.py", line 366, in run_asgi
    result = await app(self.scope, self.receive, self.send)
  File "/opt/homebrew/lib/python3.9/site-packages/uvicorn/middleware/proxy_headers.py", line 75, in __call__
    return await self.app(scope, receive, send)
  File "/opt/homebrew/lib/python3.9/site-packages/fastapi/applications.py", line 269, in __call__
    await super().__call__(scope, receive, send)
  File "/opt/homebrew/lib/python3.9/site-packages/starlette/applications.py", line 124, in __call__
    await self.middleware_stack(scope, receive, send)
  File "/opt/homebrew/lib/python3.9/site-packages/starlette/middleware/errors.py", line 184, in __call__
    raise exc
  File "/opt/homebrew/lib/python3.9/site-packages/starlette/middleware/errors.py", line 162, in __call__
    await self.app(scope, receive, _send)
  File "/opt/homebrew/lib/python3.9/site-packages/starlette/middleware/cors.py", line 84, in __call__
    await self.app(scope, receive, send)
  File "/opt/homebrew/lib/python3.9/site-packages/starlette/exceptions.py", line 93, in __call__
    raise exc
  File "/opt/homebrew/lib/python3.9/site-packages/starlette/exceptions.py", line 82, in __call__
    await self.app(scope, receive, sender)
  File "/opt/homebrew/lib/python3.9/site-packages/fastapi/middleware/asyncexitstack.py", line 21, in __call__
    raise e
  File "/opt/homebrew/lib/python3.9/site-packages/fastapi/middleware/asyncexitstack.py", line 18, in __call__
    await self.app(scope, receive, send)
  File "/opt/homebrew/lib/python3.9/site-packages/starlette/routing.py", line 670, in __call__
    await route.handle(scope, receive, send)
  File "/opt/homebrew/lib/python3.9/site-packages/starlette/routing.py", line 266, in handle
    await self.app(scope, receive, send)
  File "/opt/homebrew/lib/python3.9/site-packages/starlette/routing.py", line 65, in app
    response = await func(request)
  File "/opt/homebrew/lib/python3.9/site-packages/fastapi/routing.py", line 227, in app
    raw_response = await run_endpoint_function(
  File "/opt/homebrew/lib/python3.9/site-packages/fastapi/routing.py", line 160, in run_endpoint_function
    return await dependant.call(**values)
  File "/Users/aditya/Downloads/API 2/C/RUN/./main.py", line 1038, in create_order
    return user_result
UnboundLocalError: local variable 'user_result' referenced before assignment
root - INFO - 2023-03-21 14:35:15.899285 - Order placement successful for users: []
uvicorn.error - ERROR - Exception in ASGI application
Traceback (most recent call last):
  File "/opt/homebrew/lib/python3.9/site-packages/uvicorn/protocols/http/h11_impl.py", line 366, in run_asgi
    result = await app(self.scope, self.receive, self.send)
  File "/opt/homebrew/lib/python3.9/site-packages/uvicorn/middleware/proxy_headers.py", line 75, in __call__
    return await self.app(scope, receive, send)
  File "/opt/homebrew/lib/python3.9/site-packages/fastapi/applications.py", line 269, in __call__
    await super().__call__(scope, receive, send)
  File "/opt/homebrew/lib/python3.9/site-packages/starlette/applications.py", line 124, in __call__
    await self.middleware_stack(scope, receive, send)
  File "/opt/homebrew/lib/python3.9/site-packages/starlette/middleware/errors.py", line 184, in __call__
    raise exc
  File "/opt/homebrew/lib/python3.9/site-packages/starlette/middleware/errors.py", line 162, in __call__
    await self.app(scope, receive, _send)
  File "/opt/homebrew/lib/python3.9/site-packages/starlette/middleware/cors.py", line 84, in __call__
    await self.app(scope, receive, send)
  File "/opt/homebrew/lib/python3.9/site-packages/starlette/exceptions.py", line 93, in __call__
    raise exc
  File "/opt/homebrew/lib/python3.9/site-packages/starlette/exceptions.py", line 82, in __call__
    await self.app(scope, receive, sender)
  File "/opt/homebrew/lib/python3.9/site-packages/fastapi/middleware/asyncexitstack.py", line 21, in __call__
    raise e
  File "/opt/homebrew/lib/python3.9/site-packages/fastapi/middleware/asyncexitstack.py", line 18, in __call__
    await self.app(scope, receive, send)
  File "/opt/homebrew/lib/python3.9/site-packages/starlette/routing.py", line 670, in __call__
    await route.handle(scope, receive, send)
  File "/opt/homebrew/lib/python3.9/site-packages/starlette/routing.py", line 266, in handle
    await self.app(scope, receive, send)
  File "/opt/homebrew/lib/python3.9/site-packages/starlette/routing.py", line 65, in app
    response = await func(request)
  File "/opt/homebrew/lib/python3.9/site-packages/fastapi/routing.py", line 227, in app
    raw_response = await run_endpoint_function(
  File "/opt/homebrew/lib/python3.9/site-packages/fastapi/routing.py", line 160, in run_endpoint_function
    return await dependant.call(**values)
  File "/Users/aditya/Downloads/API 2/C/RUN/./main.py", line 1038, in create_order
    return user_result
UnboundLocalError: local variable 'user_result' referenced before assignment
root - INFO - 2023-03-21 14:35:17.197139 - Order placement successful for users: []
uvicorn.error - ERROR - Exception in ASGI application
Traceback (most recent call last):
  File "/opt/homebrew/lib/python3.9/site-packages/uvicorn/protocols/http/h11_impl.py", line 366, in run_asgi
    result = await app(self.scope, self.receive, self.send)
  File "/opt/homebrew/lib/python3.9/site-packages/uvicorn/middleware/proxy_headers.py", line 75, in __call__
    return await self.app(scope, receive, send)
  File "/opt/homebrew/lib/python3.9/site-packages/fastapi/applications.py", line 269, in __call__
    await super().__call__(scope, receive, send)
  File "/opt/homebrew/lib/python3.9/site-packages/starlette/applications.py", line 124, in __call__
    await self.middleware_stack(scope, receive, send)
  File "/opt/homebrew/lib/python3.9/site-packages/starlette/middleware/errors.py", line 184, in __call__
    raise exc
  File "/opt/homebrew/lib/python3.9/site-packages/starlette/middleware/errors.py", line 162, in __call__
    await self.app(scope, receive, _send)
  File "/opt/homebrew/lib/python3.9/site-packages/starlette/middleware/cors.py", line 84, in __call__
    await self.app(scope, receive, send)
  File "/opt/homebrew/lib/python3.9/site-packages/starlette/exceptions.py", line 93, in __call__
    raise exc
  File "/opt/homebrew/lib/python3.9/site-packages/starlette/exceptions.py", line 82, in __call__
    await self.app(scope, receive, sender)
  File "/opt/homebrew/lib/python3.9/site-packages/fastapi/middleware/asyncexitstack.py", line 21, in __call__
    raise e
  File "/opt/homebrew/lib/python3.9/site-packages/fastapi/middleware/asyncexitstack.py", line 18, in __call__
    await self.app(scope, receive, send)
  File "/opt/homebrew/lib/python3.9/site-packages/starlette/routing.py", line 670, in __call__
    await route.handle(scope, receive, send)
  File "/opt/homebrew/lib/python3.9/site-packages/starlette/routing.py", line 266, in handle
    await self.app(scope, receive, send)
  File "/opt/homebrew/lib/python3.9/site-packages/starlette/routing.py", line 65, in app
    response = await func(request)
  File "/opt/homebrew/lib/python3.9/site-packages/fastapi/routing.py", line 227, in app
    raw_response = await run_endpoint_function(
  File "/opt/homebrew/lib/python3.9/site-packages/fastapi/routing.py", line 160, in run_endpoint_function
    return await dependant.call(**values)
  File "/Users/aditya/Downloads/API 2/C/RUN/./main.py", line 1038, in create_order
    return user_result
UnboundLocalError: local variable 'user_result' referenced before assignment
root - INFO - 2023-03-21 15:20:16.092769 - Order placed for MASTER_TRUST OPHIUCUS NIFTY|L|0|PE|WEEK|0 CLOSE SHORT -10 0 0
root - INFO - 2023-03-21 15:20:16.210459 - Order placed for ODIN OPHIUCUS NIFTY|L|0|PE|WEEK|0 CLOSE SHORT -1 0 0
root - INFO - 2023-03-21 15:20:16.312889 - Order placed for FINVANT_LIVE OPHIUCUS NIFTY|L|0|PE|WEEK|0 CLOSE SHORT -1 0 0
root - INFO - 2023-03-21 15:20:16.414641 - Order placed for BPWealth_AHD083 OPHIUCUS NIFTY|L|0|PE|WEEK|0 CLOSE SHORT -1 0 0
root - INFO - 2023-03-21 15:20:16.512713 - Order placed for BPWealth_ACS1301 OPHIUCUS NIFTY|L|0|PE|WEEK|0 CLOSE SHORT -1 0 0
root - INFO - 2023-03-21 15:20:16.615175 - Order placed for BPWealth_ACS1207 OPHIUCUS NIFTY|L|0|PE|WEEK|0 CLOSE SHORT -1 0 0
root - INFO - 2023-03-21 15:20:16.722588 - Order placed for BPWealth_AC66 OPHIUCUS NIFTY|L|0|PE|WEEK|0 CLOSE SHORT -1 0 0
root - INFO - 2023-03-21 15:20:16.833627 - Order placement successful for users: [{'user_name': 'MASTER_TRUST', 'strategy': 'OPHIUCUS', 'instrument_nomenclature': 'NIFTY|L|0|PE|WEEK|0', 'position': 'CLOSE SHORT', 'target': 0, 'stoploss': 0}, {'user_name': 'ODIN', 'strategy': 'OPHIUCUS', 'instrument_nomenclature': 'NIFTY|L|0|PE|WEEK|0', 'position': 'CLOSE SHORT', 'target': 0, 'stoploss': 0}, {'user_name': 'FINVANT_LIVE', 'strategy': 'OPHIUCUS', 'instrument_nomenclature': 'NIFTY|L|0|PE|WEEK|0', 'position': 'CLOSE SHORT', 'target': 0, 'stoploss': 0}, {'user_name': 'BPWealth_AHD083', 'strategy': 'OPHIUCUS', 'instrument_nomenclature': 'NIFTY|L|0|PE|WEEK|0', 'position': 'CLOSE SHORT', 'target': 0, 'stoploss': 0}, {'user_name': 'BPWealth_ACS1301', 'strategy': 'OPHIUCUS', 'instrument_nomenclature': 'NIFTY|L|0|PE|WEEK|0', 'position': 'CLOSE SHORT', 'target': 0, 'stoploss': 0}, {'user_name': 'BPWealth_ACS1207', 'strategy': 'OPHIUCUS', 'instrument_nomenclature': 'NIFTY|L|0|PE|WEEK|0', 'position': 'CLOSE SHORT', 'target': 0, 'stoploss': 0}, {'user_name': 'BPWealth_AC66', 'strategy': 'OPHIUCUS', 'instrument_nomenclature': 'NIFTY|L|0|PE|WEEK|0', 'position': 'CLOSE SHORT', 'target': 0, 'stoploss': 0}]
root - INFO - 2023-03-21 15:25:15.946241 - Order placed for FINVANT_LIVE ALTAIR NIFTY_SYNTHETIC_INTRADAY_SHORT SELL 1 0 0
root - INFO - 2023-03-21 15:25:16.044763 - Order placed for AIRAN ALTAIR_FUTURES NIFTY CLOSE SHORT -3 0 0
root - INFO - 2023-03-21 15:25:16.171660 - Order placed for BPWealth_AHO7706 ALTAIR_FUTURES NIFTY CLOSE SHORT -2 0 0
root - INFO - 2023-03-21 15:25:16.274545 - Order placement successful for users: [{'user_name': 'FINVANT_LIVE', 'strategy': 'ALTAIR', 'instrument_nomenclature': 'NIFTY_SYNTHETIC_INTRADAY_SHORT', 'position': 'SELL', 'target': 0, 'stoploss': 0}, {'user_name': 'AIRAN', 'strategy': 'ALTAIR_FUTURES', 'instrument_nomenclature': 'NIFTY', 'position': 'CLOSE SHORT', 'target': 0, 'stoploss': 0}, {'user_name': 'BPWealth_AHO7706', 'strategy': 'ALTAIR_FUTURES', 'instrument_nomenclature': 'NIFTY', 'position': 'CLOSE SHORT', 'target': 0, 'stoploss': 0}]
root - INFO - 2023-03-22 08:04:08.714729 - Order placement successful for users: []
uvicorn.error - ERROR - Exception in ASGI application
Traceback (most recent call last):
  File "/opt/homebrew/lib/python3.9/site-packages/uvicorn/protocols/http/h11_impl.py", line 366, in run_asgi
    result = await app(self.scope, self.receive, self.send)
  File "/opt/homebrew/lib/python3.9/site-packages/uvicorn/middleware/proxy_headers.py", line 75, in __call__
    return await self.app(scope, receive, send)
  File "/opt/homebrew/lib/python3.9/site-packages/fastapi/applications.py", line 269, in __call__
    await super().__call__(scope, receive, send)
  File "/opt/homebrew/lib/python3.9/site-packages/starlette/applications.py", line 124, in __call__
    await self.middleware_stack(scope, receive, send)
  File "/opt/homebrew/lib/python3.9/site-packages/starlette/middleware/errors.py", line 184, in __call__
    raise exc
  File "/opt/homebrew/lib/python3.9/site-packages/starlette/middleware/errors.py", line 162, in __call__
    await self.app(scope, receive, _send)
  File "/opt/homebrew/lib/python3.9/site-packages/starlette/middleware/cors.py", line 84, in __call__
    await self.app(scope, receive, send)
  File "/opt/homebrew/lib/python3.9/site-packages/starlette/exceptions.py", line 93, in __call__
    raise exc
  File "/opt/homebrew/lib/python3.9/site-packages/starlette/exceptions.py", line 82, in __call__
    await self.app(scope, receive, sender)
  File "/opt/homebrew/lib/python3.9/site-packages/fastapi/middleware/asyncexitstack.py", line 21, in __call__
    raise e
  File "/opt/homebrew/lib/python3.9/site-packages/fastapi/middleware/asyncexitstack.py", line 18, in __call__
    await self.app(scope, receive, send)
  File "/opt/homebrew/lib/python3.9/site-packages/starlette/routing.py", line 670, in __call__
    await route.handle(scope, receive, send)
  File "/opt/homebrew/lib/python3.9/site-packages/starlette/routing.py", line 266, in handle
    await self.app(scope, receive, send)
  File "/opt/homebrew/lib/python3.9/site-packages/starlette/routing.py", line 65, in app
    response = await func(request)
  File "/opt/homebrew/lib/python3.9/site-packages/fastapi/routing.py", line 227, in app
    raw_response = await run_endpoint_function(
  File "/opt/homebrew/lib/python3.9/site-packages/fastapi/routing.py", line 160, in run_endpoint_function
    return await dependant.call(**values)
  File "/Users/aditya/Downloads/API 2/C/RUN/./main.py", line 1038, in create_order
    return user_result
UnboundLocalError: local variable 'user_result' referenced before assignment
root - INFO - 2023-03-22 08:04:09.918088 - Order placement successful for users: []
uvicorn.error - ERROR - Exception in ASGI application
Traceback (most recent call last):
  File "/opt/homebrew/lib/python3.9/site-packages/uvicorn/protocols/http/h11_impl.py", line 366, in run_asgi
    result = await app(self.scope, self.receive, self.send)
  File "/opt/homebrew/lib/python3.9/site-packages/uvicorn/middleware/proxy_headers.py", line 75, in __call__
    return await self.app(scope, receive, send)
  File "/opt/homebrew/lib/python3.9/site-packages/fastapi/applications.py", line 269, in __call__
    await super().__call__(scope, receive, send)
  File "/opt/homebrew/lib/python3.9/site-packages/starlette/applications.py", line 124, in __call__
    await self.middleware_stack(scope, receive, send)
  File "/opt/homebrew/lib/python3.9/site-packages/starlette/middleware/errors.py", line 184, in __call__
    raise exc
  File "/opt/homebrew/lib/python3.9/site-packages/starlette/middleware/errors.py", line 162, in __call__
    await self.app(scope, receive, _send)
  File "/opt/homebrew/lib/python3.9/site-packages/starlette/middleware/cors.py", line 84, in __call__
    await self.app(scope, receive, send)
  File "/opt/homebrew/lib/python3.9/site-packages/starlette/exceptions.py", line 93, in __call__
    raise exc
  File "/opt/homebrew/lib/python3.9/site-packages/starlette/exceptions.py", line 82, in __call__
    await self.app(scope, receive, sender)
  File "/opt/homebrew/lib/python3.9/site-packages/fastapi/middleware/asyncexitstack.py", line 21, in __call__
    raise e
  File "/opt/homebrew/lib/python3.9/site-packages/fastapi/middleware/asyncexitstack.py", line 18, in __call__
    await self.app(scope, receive, send)
  File "/opt/homebrew/lib/python3.9/site-packages/starlette/routing.py", line 670, in __call__
    await route.handle(scope, receive, send)
  File "/opt/homebrew/lib/python3.9/site-packages/starlette/routing.py", line 266, in handle
    await self.app(scope, receive, send)
  File "/opt/homebrew/lib/python3.9/site-packages/starlette/routing.py", line 65, in app
    response = await func(request)
  File "/opt/homebrew/lib/python3.9/site-packages/fastapi/routing.py", line 227, in app
    raw_response = await run_endpoint_function(
  File "/opt/homebrew/lib/python3.9/site-packages/fastapi/routing.py", line 160, in run_endpoint_function
    return await dependant.call(**values)
  File "/Users/aditya/Downloads/API 2/C/RUN/./main.py", line 1038, in create_order
    return user_result
UnboundLocalError: local variable 'user_result' referenced before assignment
root - INFO - 2023-03-22 08:05:21.194902 - Order placed for AIRAN ALTAIR_FUTURES NIFTY OPEN SHORT -3 0 0
root - INFO - 2023-03-22 08:05:21.295776 - Order placed for BPWealth_AHO7706 ALTAIR_FUTURES NIFTY OPEN SHORT -2 0 0
root - INFO - 2023-03-22 08:05:21.393444 - Order placement successful for users: [{'user_name': 'AIRAN', 'strategy': 'ALTAIR_FUTURES', 'instrument_nomenclature': 'NIFTY', 'position': 'OPEN SHORT', 'target': 0, 'stoploss': 0, 'quantity': 3}, {'user_name': 'BPWealth_AHO7706', 'strategy': 'ALTAIR_FUTURES', 'instrument_nomenclature': 'NIFTY', 'position': 'OPEN SHORT', 'target': 0, 'stoploss': 0, 'quantity': 2}]
root - INFO - 2023-03-22 08:05:58.690211 - Order placed for AIRAN ALTAIR_FUTURES NIFTY CLOSE SHORT -3 0 0
root - INFO - 2023-03-22 08:05:58.786820 - Order placed for BPWealth_AHO7706 ALTAIR_FUTURES NIFTY CLOSE SHORT -2 0 0
root - INFO - 2023-03-22 08:05:58.892277 - Order placement successful for users: [{'user_name': 'AIRAN', 'strategy': 'ALTAIR_FUTURES', 'instrument_nomenclature': 'NIFTY', 'position': 'CLOSE SHORT', 'target': 0, 'stoploss': 0}, {'user_name': 'BPWealth_AHO7706', 'strategy': 'ALTAIR_FUTURES', 'instrument_nomenclature': 'NIFTY', 'position': 'CLOSE SHORT', 'target': 0, 'stoploss': 0}]
root - INFO - 2023-03-22 08:08:17.147870 - Order placed for AIRAN ALTAIR_FUTURES NIFTY OPEN SHORT -3 0 0
root - INFO - 2023-03-22 08:08:17.253361 - Order placed for BPWealth_AHO7706 ALTAIR_FUTURES NIFTY OPEN SHORT -2 0 0
root - INFO - 2023-03-22 08:08:17.365701 - Order placement successful for users: [{'user_name': 'AIRAN', 'strategy': 'ALTAIR_FUTURES', 'instrument_nomenclature': 'NIFTY', 'position': 'OPEN SHORT', 'target': 0, 'stoploss': 0, 'quantity': 3}, {'user_name': 'BPWealth_AHO7706', 'strategy': 'ALTAIR_FUTURES', 'instrument_nomenclature': 'NIFTY', 'position': 'OPEN SHORT', 'target': 0, 'stoploss': 0, 'quantity': 2}]
uvicorn.error - INFO - Shutting down
uvicorn.error - INFO - Waiting for application shutdown.
tortoise - INFO - Tortoise-ORM shutdown
uvicorn.error - INFO - Application shutdown complete.
uvicorn.error - INFO - Finished server process [70838]
