root - INFO - 2023-04-22 12:06:48.883648 - OMS Server turned on.
uvicorn.error - INFO - Started server process [31369]
uvicorn.error - INFO - Waiting for application startup.
tortoise - INFO - Tortoise-ORM started, {'default': <tortoise.backends.sqlite.client.SqliteClient object at 0x7fb87b517f70>}, {'models': {'OptionSpread': <class 'models.OptionSpread'>, 'User': <class 'models.User'>, 'User_Finvant': <class 'models.User_Finvant'>}}
tortoise - INFO - Tortoise-ORM generating schema
uvicorn.error - INFO - Application startup complete.
uvicorn.error - INFO - Uvicorn running on http://0.0.0.0:9093 (Press CTRL+C to quit)
uvicorn.error - WARNING - Invalid HTTP request received.
Traceback (most recent call last):
  File "/home/ubuntu/.local/lib/python3.8/site-packages/uvicorn/protocols/http/h11_impl.py", line 136, in handle_events
    event = self.conn.next_event()
  File "/home/ubuntu/.local/lib/python3.8/site-packages/h11/_connection.py", line 443, in next_event
    exc._reraise_as_remote_protocol_error()
  File "/home/ubuntu/.local/lib/python3.8/site-packages/h11/_util.py", line 76, in _reraise_as_remote_protocol_error
    raise self
  File "/home/ubuntu/.local/lib/python3.8/site-packages/h11/_connection.py", line 425, in next_event
    event = self._extract_next_receive_event()
  File "/home/ubuntu/.local/lib/python3.8/site-packages/h11/_connection.py", line 367, in _extract_next_receive_event
    event = self._reader(self._receive_buffer)
  File "/home/ubuntu/.local/lib/python3.8/site-packages/h11/_readers.py", line 68, in maybe_read_from_IDLE_client
    raise LocalProtocolError("illegal request line")
h11._util.RemoteProtocolError: illegal request line
uvicorn.error - WARNING - Invalid HTTP request received.
Traceback (most recent call last):
  File "/home/ubuntu/.local/lib/python3.8/site-packages/uvicorn/protocols/http/h11_impl.py", line 136, in handle_events
    event = self.conn.next_event()
  File "/home/ubuntu/.local/lib/python3.8/site-packages/h11/_connection.py", line 443, in next_event
    exc._reraise_as_remote_protocol_error()
  File "/home/ubuntu/.local/lib/python3.8/site-packages/h11/_util.py", line 76, in _reraise_as_remote_protocol_error
    raise self
  File "/home/ubuntu/.local/lib/python3.8/site-packages/h11/_connection.py", line 425, in next_event
    event = self._extract_next_receive_event()
  File "/home/ubuntu/.local/lib/python3.8/site-packages/h11/_connection.py", line 367, in _extract_next_receive_event
    event = self._reader(self._receive_buffer)
  File "/home/ubuntu/.local/lib/python3.8/site-packages/h11/_readers.py", line 68, in maybe_read_from_IDLE_client
    raise LocalProtocolError("illegal request line")
h11._util.RemoteProtocolError: illegal request line
uvicorn.error - WARNING - Invalid HTTP request received.
Traceback (most recent call last):
  File "/home/ubuntu/.local/lib/python3.8/site-packages/starlette/exceptions.py", line 71, in __call__
    await self.app(scope, receive, sender)
  File "/home/ubuntu/.local/lib/python3.8/site-packages/starlette/routing.py", line 685, in __call__
    await self.default(scope, receive, send)
  File "/home/ubuntu/.local/lib/python3.8/site-packages/starlette/routing.py", line 579, in not_found
    raise HTTPException(status_code=404)
starlette.exceptions.HTTPException

During handling of the above exception, another exception occurred:

Traceback (most recent call last):
  File "/home/ubuntu/.local/lib/python3.8/site-packages/uvicorn/protocols/http/h11_impl.py", line 136, in handle_events
    event = self.conn.next_event()
  File "/home/ubuntu/.local/lib/python3.8/site-packages/h11/_connection.py", line 443, in next_event
    exc._reraise_as_remote_protocol_error()
  File "/home/ubuntu/.local/lib/python3.8/site-packages/h11/_util.py", line 76, in _reraise_as_remote_protocol_error
    raise self
  File "/home/ubuntu/.local/lib/python3.8/site-packages/h11/_connection.py", line 425, in next_event
    event = self._extract_next_receive_event()
  File "/home/ubuntu/.local/lib/python3.8/site-packages/h11/_connection.py", line 367, in _extract_next_receive_event
    event = self._reader(self._receive_buffer)
  File "/home/ubuntu/.local/lib/python3.8/site-packages/h11/_readers.py", line 72, in maybe_read_from_IDLE_client
    matches = validate(
  File "/home/ubuntu/.local/lib/python3.8/site-packages/h11/_util.py", line 88, in validate
    raise LocalProtocolError(msg)
h11._util.RemoteProtocolError: illegal request line: bytearray(b'SM')
uvicorn.error - INFO - Shutting down
uvicorn.error - INFO - Waiting for application shutdown.
tortoise - INFO - Tortoise-ORM shutdown
tortoise - INFO - Tortoise-ORM shutdown
uvicorn.error - INFO - Application shutdown complete.
uvicorn.error - INFO - Finished server process [31369]
