root - INFO - 2023-03-20 08:25:11.722035 - OMS Server turned on.
uvicorn.error - INFO - Started server process [4739]
uvicorn.error - INFO - Waiting for application startup.
tortoise - INFO - Tortoise-ORM started, {'default': <tortoise.backends.sqlite.client.SqliteClient object at 0x1143496a0>}, {'models': {'OptionSpread': <class 'models.OptionSpread'>, 'User': <class 'models.User'>, 'User_Finvant': <class 'models.User_Finvant'>}}
tortoise - INFO - Tortoise-ORM generating schema
uvicorn.error - INFO - Application startup complete.
uvicorn.error - INFO - Uvicorn running on http://0.0.0.0:8000 (Press CTRL+C to quit)
root - INFO - 2023-03-20 08:25:54.740346 - Order placed for AIRAN LUNA_FUTURES NIFTY OPEN SHORT -3 0 0
root - INFO - 2023-03-20 08:25:54.848572 - Order placed for BPWealth_AHO7706 LUNA_FUTURES NIFTY OPEN SHORT -2 0 0
root - INFO - 2023-03-20 08:25:54.948589 - Order placement successful for users: [{'user_name': 'AIRAN', 'strategy': 'LUNA_FUTURES', 'instrument_nomenclature': 'NIFTY', 'position': 'OPEN SHORT', 'target': 0, 'stoploss': 0, 'quantity': 3}, {'user_name': 'BPWealth_AHO7706', 'strategy': 'LUNA_FUTURES', 'instrument_nomenclature': 'NIFTY', 'position': 'OPEN SHORT', 'target': 0, 'stoploss': 0, 'quantity': 2}]
root - INFO - 2023-03-20 08:26:46.452750 - Order placed for AIRAN LUNA_FUTURES NIFTY CLOSE SHORT -3 0 0
root - INFO - 2023-03-20 08:26:46.550736 - Order placed for BPWealth_AHO7706 LUNA_FUTURES NIFTY CLOSE SHORT -2 0 0
root - INFO - 2023-03-20 08:26:46.646923 - Order placement successful for users: [{'user_name': 'AIRAN', 'strategy': 'LUNA_FUTURES', 'instrument_nomenclature': 'NIFTY', 'position': 'CLOSE SHORT', 'target': 0, 'stoploss': 0}, {'user_name': 'BPWealth_AHO7706', 'strategy': 'LUNA_FUTURES', 'instrument_nomenclature': 'NIFTY', 'position': 'CLOSE SHORT', 'target': 0, 'stoploss': 0}]
uvicorn.error - INFO - Shutting down
uvicorn.error - INFO - Waiting for application shutdown.
tortoise - INFO - Tortoise-ORM shutdown
uvicorn.error - INFO - Application shutdown complete.
uvicorn.error - INFO - Finished server process [4739]
root - INFO - 2023-03-20 08:29:14.113047 - OMS Server turned on.
uvicorn.error - INFO - Started server process [4977]
uvicorn.error - INFO - Waiting for application startup.
tortoise - INFO - Tortoise-ORM started, {'default': <tortoise.backends.sqlite.client.SqliteClient object at 0x1092cd6a0>}, {'models': {'OptionSpread': <class 'models.OptionSpread'>, 'User': <class 'models.User'>, 'User_Finvant': <class 'models.User_Finvant'>}}
tortoise - INFO - Tortoise-ORM generating schema
uvicorn.error - INFO - Application startup complete.
uvicorn.error - INFO - Uvicorn running on http://0.0.0.0:8000 (Press CTRL+C to quit)
root - INFO - 2023-03-20 09:35:15.838347 - Order placement successful for users: []
root - INFO - 2023-03-20 09:40:15.892748 - Order placement successful for users: []
root - INFO - 2023-03-20 09:50:15.963442 - Order placed for FINVANT_LIVE ALTAIR BANKNIFTY_SYNTHETIC_INTRADAY_SHORT BUY 1 2 0.5
root - INFO - 2023-03-20 09:50:16.069697 - Order placed for AIRAN ALTAIR_FUTURES BANKNIFTY OPEN SHORT -3 0.5 2
root - INFO - 2023-03-20 09:50:16.166227 - Order placed for BPWealth_AHO7706 ALTAIR_FUTURES BANKNIFTY OPEN SHORT -1 0.5 2
root - INFO - 2023-03-20 09:50:16.265570 - Order placement successful for users: [{'user_name': 'FINVANT_LIVE', 'strategy': 'ALTAIR', 'instrument_nomenclature': 'BANKNIFTY_SYNTHETIC_INTRADAY_SHORT', 'position': 'BUY', 'target': 0.5, 'stoploss': 2, 'quantity': 1}, {'user_name': 'AIRAN', 'strategy': 'ALTAIR_FUTURES', 'instrument_nomenclature': 'BANKNIFTY', 'position': 'OPEN SHORT', 'target': 2, 'stoploss': 0.5, 'quantity': 3}, {'user_name': 'BPWealth_AHO7706', 'strategy': 'ALTAIR_FUTURES', 'instrument_nomenclature': 'BANKNIFTY', 'position': 'OPEN SHORT', 'target': 2, 'stoploss': 0.5, 'quantity': 1}]
root - INFO - 2023-03-20 09:55:15.853605 - Order placement successful for users: []
uvicorn.error - INFO - Shutting down
uvicorn.error - INFO - Waiting for application shutdown.
tortoise - INFO - Tortoise-ORM shutdown
uvicorn.error - INFO - Application shutdown complete.
uvicorn.error - INFO - Finished server process [4977]
root - INFO - 2023-03-20 10:02:29.727341 - OMS Server turned on.
uvicorn.error - INFO - Started server process [19500]
uvicorn.error - INFO - Waiting for application startup.
tortoise - INFO - Tortoise-ORM started, {'default': <tortoise.backends.sqlite.client.SqliteClient object at 0x123e4d6a0>}, {'models': {'OptionSpread': <class 'models.OptionSpread'>, 'User': <class 'models.User'>, 'User_Finvant': <class 'models.User_Finvant'>}}
tortoise - INFO - Tortoise-ORM generating schema
uvicorn.error - INFO - Application startup complete.
uvicorn.error - INFO - Uvicorn running on http://0.0.0.0:8000 (Press CTRL+C to quit)
uvicorn.error - ERROR - Exception in ASGI application
Traceback (most recent call last):
  File "/opt/homebrew/lib/python3.9/site-packages/uvicorn/protocols/http/h11_impl.py", line 366, in run_asgi
    result = await app(self.scope, self.receive, self.send)
  File "/opt/homebrew/lib/python3.9/site-packages/uvicorn/middleware/proxy_headers.py", line 75, in __call__
    return await self.app(scope, receive, send)
  File "/opt/homebrew/lib/python3.9/site-packages/fastapi/applications.py", line 269, in __call__
    await super().__call__(scope, receive, send)
  File "/opt/homebrew/lib/python3.9/site-packages/starlette/applications.py", line 124, in __call__
    await self.middleware_stack(scope, receive, send)
  File "/opt/homebrew/lib/python3.9/site-packages/starlette/middleware/errors.py", line 184, in __call__
    raise exc
  File "/opt/homebrew/lib/python3.9/site-packages/starlette/middleware/errors.py", line 162, in __call__
    await self.app(scope, receive, _send)
  File "/opt/homebrew/lib/python3.9/site-packages/starlette/middleware/cors.py", line 84, in __call__
    await self.app(scope, receive, send)
  File "/opt/homebrew/lib/python3.9/site-packages/starlette/exceptions.py", line 93, in __call__
    raise exc
  File "/opt/homebrew/lib/python3.9/site-packages/starlette/exceptions.py", line 82, in __call__
    await self.app(scope, receive, sender)
  File "/opt/homebrew/lib/python3.9/site-packages/fastapi/middleware/asyncexitstack.py", line 21, in __call__
    raise e
  File "/opt/homebrew/lib/python3.9/site-packages/fastapi/middleware/asyncexitstack.py", line 18, in __call__
    await self.app(scope, receive, send)
  File "/opt/homebrew/lib/python3.9/site-packages/starlette/routing.py", line 670, in __call__
    await route.handle(scope, receive, send)
  File "/opt/homebrew/lib/python3.9/site-packages/starlette/routing.py", line 266, in handle
    await self.app(scope, receive, send)
  File "/opt/homebrew/lib/python3.9/site-packages/starlette/routing.py", line 65, in app
    response = await func(request)
  File "/opt/homebrew/lib/python3.9/site-packages/fastapi/routing.py", line 227, in app
    raw_response = await run_endpoint_function(
  File "/opt/homebrew/lib/python3.9/site-packages/fastapi/routing.py", line 160, in run_endpoint_function
    return await dependant.call(**values)
  File "/Users/aditya/Downloads/API 2/C/RUN/./main.py", line 959, in create_order
    user_details = await asyncio.create_task(getUserDetails(strategy, instrument_nomenclature, position)) # async allows to run multiple tasks at the same time
  File "/Users/aditya/Downloads/API 2/C/RUN/./main.py", line 645, in getUserDetails
    if user_data[user]['STRATEGY_DETAILS'][strategy][instrument][d] > 0:
KeyError: 'NIFTY_SYNTEHTIC_INTRADAY_SHORT'
uvicorn.error - ERROR - Exception in ASGI application
Traceback (most recent call last):
  File "/opt/homebrew/lib/python3.9/site-packages/uvicorn/protocols/http/h11_impl.py", line 366, in run_asgi
    result = await app(self.scope, self.receive, self.send)
  File "/opt/homebrew/lib/python3.9/site-packages/uvicorn/middleware/proxy_headers.py", line 75, in __call__
    return await self.app(scope, receive, send)
  File "/opt/homebrew/lib/python3.9/site-packages/fastapi/applications.py", line 269, in __call__
    await super().__call__(scope, receive, send)
  File "/opt/homebrew/lib/python3.9/site-packages/starlette/applications.py", line 124, in __call__
    await self.middleware_stack(scope, receive, send)
  File "/opt/homebrew/lib/python3.9/site-packages/starlette/middleware/errors.py", line 184, in __call__
    raise exc
  File "/opt/homebrew/lib/python3.9/site-packages/starlette/middleware/errors.py", line 162, in __call__
    await self.app(scope, receive, _send)
  File "/opt/homebrew/lib/python3.9/site-packages/starlette/middleware/cors.py", line 84, in __call__
    await self.app(scope, receive, send)
  File "/opt/homebrew/lib/python3.9/site-packages/starlette/exceptions.py", line 93, in __call__
    raise exc
  File "/opt/homebrew/lib/python3.9/site-packages/starlette/exceptions.py", line 82, in __call__
    await self.app(scope, receive, sender)
  File "/opt/homebrew/lib/python3.9/site-packages/fastapi/middleware/asyncexitstack.py", line 21, in __call__
    raise e
  File "/opt/homebrew/lib/python3.9/site-packages/fastapi/middleware/asyncexitstack.py", line 18, in __call__
    await self.app(scope, receive, send)
  File "/opt/homebrew/lib/python3.9/site-packages/starlette/routing.py", line 670, in __call__
    await route.handle(scope, receive, send)
  File "/opt/homebrew/lib/python3.9/site-packages/starlette/routing.py", line 266, in handle
    await self.app(scope, receive, send)
  File "/opt/homebrew/lib/python3.9/site-packages/starlette/routing.py", line 65, in app
    response = await func(request)
  File "/opt/homebrew/lib/python3.9/site-packages/fastapi/routing.py", line 227, in app
    raw_response = await run_endpoint_function(
  File "/opt/homebrew/lib/python3.9/site-packages/fastapi/routing.py", line 160, in run_endpoint_function
    return await dependant.call(**values)
  File "/Users/aditya/Downloads/API 2/C/RUN/./main.py", line 959, in create_order
    user_details = await asyncio.create_task(getUserDetails(strategy, instrument_nomenclature, position)) # async allows to run multiple tasks at the same time
  File "/Users/aditya/Downloads/API 2/C/RUN/./main.py", line 645, in getUserDetails
    if user_data[user]['STRATEGY_DETAILS'][strategy][instrument][d] > 0:
KeyError: 'NIFTY_SYNTEHTIC_INTRADAY_SHORT'
root - INFO - 2023-03-20 10:05:15.909296 - Order placed for FINVANT_LIVE QUASAR_5M BANKNIFTY_SYNTHETIC_INTRADAY_SHORT BUY 1 0 0.5
root - INFO - 2023-03-20 10:05:16.011618 - Order placed for FINVANT_LIVE QUASAR_5M NIFTY_SYNTHETIC_INTRADAY_SHORT BUY 2 0 0.5
root - INFO - 2023-03-20 10:05:16.128856 - Order placement successful for users: [{'user_name': 'FINVANT_LIVE', 'strategy': 'QUASAR_5M', 'instrument_nomenclature': 'BANKNIFTY_SYNTHETIC_INTRADAY_SHORT', 'position': 'BUY', 'target': 0.5, 'stoploss': 0, 'quantity': 1}, {'user_name': 'FINVANT_LIVE', 'strategy': 'QUASAR_5M', 'instrument_nomenclature': 'NIFTY_SYNTHETIC_INTRADAY_SHORT', 'position': 'BUY', 'target': 0.5, 'stoploss': 0, 'quantity': 2}]
root - INFO - 2023-03-20 10:10:15.930322 - Order placement successful for users: []
uvicorn.error - ERROR - Exception in ASGI application
Traceback (most recent call last):
  File "/opt/homebrew/lib/python3.9/site-packages/uvicorn/protocols/http/h11_impl.py", line 366, in run_asgi
    result = await app(self.scope, self.receive, self.send)
  File "/opt/homebrew/lib/python3.9/site-packages/uvicorn/middleware/proxy_headers.py", line 75, in __call__
    return await self.app(scope, receive, send)
  File "/opt/homebrew/lib/python3.9/site-packages/fastapi/applications.py", line 269, in __call__
    await super().__call__(scope, receive, send)
  File "/opt/homebrew/lib/python3.9/site-packages/starlette/applications.py", line 124, in __call__
    await self.middleware_stack(scope, receive, send)
  File "/opt/homebrew/lib/python3.9/site-packages/starlette/middleware/errors.py", line 184, in __call__
    raise exc
  File "/opt/homebrew/lib/python3.9/site-packages/starlette/middleware/errors.py", line 162, in __call__
    await self.app(scope, receive, _send)
  File "/opt/homebrew/lib/python3.9/site-packages/starlette/middleware/cors.py", line 84, in __call__
    await self.app(scope, receive, send)
  File "/opt/homebrew/lib/python3.9/site-packages/starlette/exceptions.py", line 93, in __call__
    raise exc
  File "/opt/homebrew/lib/python3.9/site-packages/starlette/exceptions.py", line 82, in __call__
    await self.app(scope, receive, sender)
  File "/opt/homebrew/lib/python3.9/site-packages/fastapi/middleware/asyncexitstack.py", line 21, in __call__
    raise e
  File "/opt/homebrew/lib/python3.9/site-packages/fastapi/middleware/asyncexitstack.py", line 18, in __call__
    await self.app(scope, receive, send)
  File "/opt/homebrew/lib/python3.9/site-packages/starlette/routing.py", line 670, in __call__
    await route.handle(scope, receive, send)
  File "/opt/homebrew/lib/python3.9/site-packages/starlette/routing.py", line 266, in handle
    await self.app(scope, receive, send)
  File "/opt/homebrew/lib/python3.9/site-packages/starlette/routing.py", line 65, in app
    response = await func(request)
  File "/opt/homebrew/lib/python3.9/site-packages/fastapi/routing.py", line 227, in app
    raw_response = await run_endpoint_function(
  File "/opt/homebrew/lib/python3.9/site-packages/fastapi/routing.py", line 160, in run_endpoint_function
    return await dependant.call(**values)
  File "/Users/aditya/Downloads/API 2/C/RUN/./main.py", line 1038, in create_order
    return user_result
UnboundLocalError: local variable 'user_result' referenced before assignment
root - INFO - 2023-03-20 10:10:17.184068 - Order placement successful for users: []
uvicorn.error - ERROR - Exception in ASGI application
Traceback (most recent call last):
  File "/opt/homebrew/lib/python3.9/site-packages/uvicorn/protocols/http/h11_impl.py", line 366, in run_asgi
    result = await app(self.scope, self.receive, self.send)
  File "/opt/homebrew/lib/python3.9/site-packages/uvicorn/middleware/proxy_headers.py", line 75, in __call__
    return await self.app(scope, receive, send)
  File "/opt/homebrew/lib/python3.9/site-packages/fastapi/applications.py", line 269, in __call__
    await super().__call__(scope, receive, send)
  File "/opt/homebrew/lib/python3.9/site-packages/starlette/applications.py", line 124, in __call__
    await self.middleware_stack(scope, receive, send)
  File "/opt/homebrew/lib/python3.9/site-packages/starlette/middleware/errors.py", line 184, in __call__
    raise exc
  File "/opt/homebrew/lib/python3.9/site-packages/starlette/middleware/errors.py", line 162, in __call__
    await self.app(scope, receive, _send)
  File "/opt/homebrew/lib/python3.9/site-packages/starlette/middleware/cors.py", line 84, in __call__
    await self.app(scope, receive, send)
  File "/opt/homebrew/lib/python3.9/site-packages/starlette/exceptions.py", line 93, in __call__
    raise exc
  File "/opt/homebrew/lib/python3.9/site-packages/starlette/exceptions.py", line 82, in __call__
    await self.app(scope, receive, sender)
  File "/opt/homebrew/lib/python3.9/site-packages/fastapi/middleware/asyncexitstack.py", line 21, in __call__
    raise e
  File "/opt/homebrew/lib/python3.9/site-packages/fastapi/middleware/asyncexitstack.py", line 18, in __call__
    await self.app(scope, receive, send)
  File "/opt/homebrew/lib/python3.9/site-packages/starlette/routing.py", line 670, in __call__
    await route.handle(scope, receive, send)
  File "/opt/homebrew/lib/python3.9/site-packages/starlette/routing.py", line 266, in handle
    await self.app(scope, receive, send)
  File "/opt/homebrew/lib/python3.9/site-packages/starlette/routing.py", line 65, in app
    response = await func(request)
  File "/opt/homebrew/lib/python3.9/site-packages/fastapi/routing.py", line 227, in app
    raw_response = await run_endpoint_function(
  File "/opt/homebrew/lib/python3.9/site-packages/fastapi/routing.py", line 160, in run_endpoint_function
    return await dependant.call(**values)
  File "/Users/aditya/Downloads/API 2/C/RUN/./main.py", line 1038, in create_order
    return user_result
UnboundLocalError: local variable 'user_result' referenced before assignment
root - INFO - 2023-03-20 10:15:15.884530 - Order placed for MASTER_TRUST OPHIUCUS NIFTY|L|0|CE|WEEK|0 OPEN SHORT -10 0 0
root - INFO - 2023-03-20 10:15:15.982765 - Order placed for ODIN OPHIUCUS NIFTY|L|0|CE|WEEK|0 OPEN SHORT -1 0 0
root - INFO - 2023-03-20 10:15:16.079754 - Order placed for FINVANT_LIVE OPHIUCUS NIFTY|L|0|CE|WEEK|0 OPEN SHORT -1 0 0
root - INFO - 2023-03-20 10:15:16.177239 - Order placed for BPWealth_AHD083 OPHIUCUS NIFTY|L|0|CE|WEEK|0 OPEN SHORT -1 0 0
root - INFO - 2023-03-20 10:15:16.275207 - Order placed for BPWealth_ACS1301 OPHIUCUS NIFTY|L|0|CE|WEEK|0 OPEN SHORT -1 0 0
root - INFO - 2023-03-20 10:15:16.382416 - Order placed for BPWealth_ACS1207 OPHIUCUS NIFTY|L|0|CE|WEEK|0 OPEN SHORT -1 0 0
root - INFO - 2023-03-20 10:15:16.479184 - Order placed for BPWealth_AC66 OPHIUCUS NIFTY|L|0|CE|WEEK|0 OPEN SHORT -1 0 0
root - INFO - 2023-03-20 10:15:16.576764 - Order placement successful for users: [{'user_name': 'MASTER_TRUST', 'strategy': 'OPHIUCUS', 'instrument_nomenclature': 'NIFTY|L|0|CE|WEEK|0', 'position': 'OPEN SHORT', 'target': 0, 'stoploss': 0, 'quantity': 10}, {'user_name': 'ODIN', 'strategy': 'OPHIUCUS', 'instrument_nomenclature': 'NIFTY|L|0|CE|WEEK|0', 'position': 'OPEN SHORT', 'target': 0, 'stoploss': 0, 'quantity': 1}, {'user_name': 'FINVANT_LIVE', 'strategy': 'OPHIUCUS', 'instrument_nomenclature': 'NIFTY|L|0|CE|WEEK|0', 'position': 'OPEN SHORT', 'target': 0, 'stoploss': 0, 'quantity': 1}, {'user_name': 'BPWealth_AHD083', 'strategy': 'OPHIUCUS', 'instrument_nomenclature': 'NIFTY|L|0|CE|WEEK|0', 'position': 'OPEN SHORT', 'target': 0, 'stoploss': 0, 'quantity': 1}, {'user_name': 'BPWealth_ACS1301', 'strategy': 'OPHIUCUS', 'instrument_nomenclature': 'NIFTY|L|0|CE|WEEK|0', 'position': 'OPEN SHORT', 'target': 0, 'stoploss': 0, 'quantity': 1}, {'user_name': 'BPWealth_ACS1207', 'strategy': 'OPHIUCUS', 'instrument_nomenclature': 'NIFTY|L|0|CE|WEEK|0', 'position': 'OPEN SHORT', 'target': 0, 'stoploss': 0, 'quantity': 1}, {'user_name': 'BPWealth_AC66', 'strategy': 'OPHIUCUS', 'instrument_nomenclature': 'NIFTY|L|0|CE|WEEK|0', 'position': 'OPEN SHORT', 'target': 0, 'stoploss': 0, 'quantity': 1}]
root - INFO - 2023-03-20 10:20:15.842200 - Order placement successful for users: []
root - INFO - 2023-03-20 10:25:15.856382 - Order placement successful for users: []
uvicorn.error - ERROR - Exception in ASGI application
Traceback (most recent call last):
  File "/opt/homebrew/lib/python3.9/site-packages/uvicorn/protocols/http/h11_impl.py", line 366, in run_asgi
    result = await app(self.scope, self.receive, self.send)
  File "/opt/homebrew/lib/python3.9/site-packages/uvicorn/middleware/proxy_headers.py", line 75, in __call__
    return await self.app(scope, receive, send)
  File "/opt/homebrew/lib/python3.9/site-packages/fastapi/applications.py", line 269, in __call__
    await super().__call__(scope, receive, send)
  File "/opt/homebrew/lib/python3.9/site-packages/starlette/applications.py", line 124, in __call__
    await self.middleware_stack(scope, receive, send)
  File "/opt/homebrew/lib/python3.9/site-packages/starlette/middleware/errors.py", line 184, in __call__
    raise exc
  File "/opt/homebrew/lib/python3.9/site-packages/starlette/middleware/errors.py", line 162, in __call__
    await self.app(scope, receive, _send)
  File "/opt/homebrew/lib/python3.9/site-packages/starlette/middleware/cors.py", line 84, in __call__
    await self.app(scope, receive, send)
  File "/opt/homebrew/lib/python3.9/site-packages/starlette/exceptions.py", line 93, in __call__
    raise exc
  File "/opt/homebrew/lib/python3.9/site-packages/starlette/exceptions.py", line 82, in __call__
    await self.app(scope, receive, sender)
  File "/opt/homebrew/lib/python3.9/site-packages/fastapi/middleware/asyncexitstack.py", line 21, in __call__
    raise e
  File "/opt/homebrew/lib/python3.9/site-packages/fastapi/middleware/asyncexitstack.py", line 18, in __call__
    await self.app(scope, receive, send)
  File "/opt/homebrew/lib/python3.9/site-packages/starlette/routing.py", line 670, in __call__
    await route.handle(scope, receive, send)
  File "/opt/homebrew/lib/python3.9/site-packages/starlette/routing.py", line 266, in handle
    await self.app(scope, receive, send)
  File "/opt/homebrew/lib/python3.9/site-packages/starlette/routing.py", line 65, in app
    response = await func(request)
  File "/opt/homebrew/lib/python3.9/site-packages/fastapi/routing.py", line 227, in app
    raw_response = await run_endpoint_function(
  File "/opt/homebrew/lib/python3.9/site-packages/fastapi/routing.py", line 160, in run_endpoint_function
    return await dependant.call(**values)
  File "/Users/aditya/Downloads/API 2/C/RUN/./main.py", line 1038, in create_order
    return user_result
UnboundLocalError: local variable 'user_result' referenced before assignment
root - INFO - 2023-03-20 10:25:17.118954 - Order placement successful for users: []
uvicorn.error - ERROR - Exception in ASGI application
Traceback (most recent call last):
  File "/opt/homebrew/lib/python3.9/site-packages/uvicorn/protocols/http/h11_impl.py", line 366, in run_asgi
    result = await app(self.scope, self.receive, self.send)
  File "/opt/homebrew/lib/python3.9/site-packages/uvicorn/middleware/proxy_headers.py", line 75, in __call__
    return await self.app(scope, receive, send)
  File "/opt/homebrew/lib/python3.9/site-packages/fastapi/applications.py", line 269, in __call__
    await super().__call__(scope, receive, send)
  File "/opt/homebrew/lib/python3.9/site-packages/starlette/applications.py", line 124, in __call__
    await self.middleware_stack(scope, receive, send)
  File "/opt/homebrew/lib/python3.9/site-packages/starlette/middleware/errors.py", line 184, in __call__
    raise exc
  File "/opt/homebrew/lib/python3.9/site-packages/starlette/middleware/errors.py", line 162, in __call__
    await self.app(scope, receive, _send)
  File "/opt/homebrew/lib/python3.9/site-packages/starlette/middleware/cors.py", line 84, in __call__
    await self.app(scope, receive, send)
  File "/opt/homebrew/lib/python3.9/site-packages/starlette/exceptions.py", line 93, in __call__
    raise exc
  File "/opt/homebrew/lib/python3.9/site-packages/starlette/exceptions.py", line 82, in __call__
    await self.app(scope, receive, sender)
  File "/opt/homebrew/lib/python3.9/site-packages/fastapi/middleware/asyncexitstack.py", line 21, in __call__
    raise e
  File "/opt/homebrew/lib/python3.9/site-packages/fastapi/middleware/asyncexitstack.py", line 18, in __call__
    await self.app(scope, receive, send)
  File "/opt/homebrew/lib/python3.9/site-packages/starlette/routing.py", line 670, in __call__
    await route.handle(scope, receive, send)
  File "/opt/homebrew/lib/python3.9/site-packages/starlette/routing.py", line 266, in handle
    await self.app(scope, receive, send)
  File "/opt/homebrew/lib/python3.9/site-packages/starlette/routing.py", line 65, in app
    response = await func(request)
  File "/opt/homebrew/lib/python3.9/site-packages/fastapi/routing.py", line 227, in app
    raw_response = await run_endpoint_function(
  File "/opt/homebrew/lib/python3.9/site-packages/fastapi/routing.py", line 160, in run_endpoint_function
    return await dependant.call(**values)
  File "/Users/aditya/Downloads/API 2/C/RUN/./main.py", line 1038, in create_order
    return user_result
UnboundLocalError: local variable 'user_result' referenced before assignment
root - INFO - 2023-03-20 10:30:16.884367 - Order placement successful for users: []
uvicorn.error - ERROR - Exception in ASGI application
Traceback (most recent call last):
  File "/opt/homebrew/lib/python3.9/site-packages/uvicorn/protocols/http/h11_impl.py", line 366, in run_asgi
    result = await app(self.scope, self.receive, self.send)
  File "/opt/homebrew/lib/python3.9/site-packages/uvicorn/middleware/proxy_headers.py", line 75, in __call__
    return await self.app(scope, receive, send)
  File "/opt/homebrew/lib/python3.9/site-packages/fastapi/applications.py", line 269, in __call__
    await super().__call__(scope, receive, send)
  File "/opt/homebrew/lib/python3.9/site-packages/starlette/applications.py", line 124, in __call__
    await self.middleware_stack(scope, receive, send)
  File "/opt/homebrew/lib/python3.9/site-packages/starlette/middleware/errors.py", line 184, in __call__
    raise exc
  File "/opt/homebrew/lib/python3.9/site-packages/starlette/middleware/errors.py", line 162, in __call__
    await self.app(scope, receive, _send)
  File "/opt/homebrew/lib/python3.9/site-packages/starlette/middleware/cors.py", line 84, in __call__
    await self.app(scope, receive, send)
  File "/opt/homebrew/lib/python3.9/site-packages/starlette/exceptions.py", line 93, in __call__
    raise exc
  File "/opt/homebrew/lib/python3.9/site-packages/starlette/exceptions.py", line 82, in __call__
    await self.app(scope, receive, sender)
  File "/opt/homebrew/lib/python3.9/site-packages/fastapi/middleware/asyncexitstack.py", line 21, in __call__
    raise e
  File "/opt/homebrew/lib/python3.9/site-packages/fastapi/middleware/asyncexitstack.py", line 18, in __call__
    await self.app(scope, receive, send)
  File "/opt/homebrew/lib/python3.9/site-packages/starlette/routing.py", line 670, in __call__
    await route.handle(scope, receive, send)
  File "/opt/homebrew/lib/python3.9/site-packages/starlette/routing.py", line 266, in handle
    await self.app(scope, receive, send)
  File "/opt/homebrew/lib/python3.9/site-packages/starlette/routing.py", line 65, in app
    response = await func(request)
  File "/opt/homebrew/lib/python3.9/site-packages/fastapi/routing.py", line 227, in app
    raw_response = await run_endpoint_function(
  File "/opt/homebrew/lib/python3.9/site-packages/fastapi/routing.py", line 160, in run_endpoint_function
    return await dependant.call(**values)
  File "/Users/aditya/Downloads/API 2/C/RUN/./main.py", line 1038, in create_order
    return user_result
UnboundLocalError: local variable 'user_result' referenced before assignment
root - INFO - 2023-03-20 10:30:18.170504 - Order placement successful for users: []
uvicorn.error - ERROR - Exception in ASGI application
Traceback (most recent call last):
  File "/opt/homebrew/lib/python3.9/site-packages/uvicorn/protocols/http/h11_impl.py", line 366, in run_asgi
    result = await app(self.scope, self.receive, self.send)
  File "/opt/homebrew/lib/python3.9/site-packages/uvicorn/middleware/proxy_headers.py", line 75, in __call__
    return await self.app(scope, receive, send)
  File "/opt/homebrew/lib/python3.9/site-packages/fastapi/applications.py", line 269, in __call__
    await super().__call__(scope, receive, send)
  File "/opt/homebrew/lib/python3.9/site-packages/starlette/applications.py", line 124, in __call__
    await self.middleware_stack(scope, receive, send)
  File "/opt/homebrew/lib/python3.9/site-packages/starlette/middleware/errors.py", line 184, in __call__
    raise exc
  File "/opt/homebrew/lib/python3.9/site-packages/starlette/middleware/errors.py", line 162, in __call__
    await self.app(scope, receive, _send)
  File "/opt/homebrew/lib/python3.9/site-packages/starlette/middleware/cors.py", line 84, in __call__
    await self.app(scope, receive, send)
  File "/opt/homebrew/lib/python3.9/site-packages/starlette/exceptions.py", line 93, in __call__
    raise exc
  File "/opt/homebrew/lib/python3.9/site-packages/starlette/exceptions.py", line 82, in __call__
    await self.app(scope, receive, sender)
  File "/opt/homebrew/lib/python3.9/site-packages/fastapi/middleware/asyncexitstack.py", line 21, in __call__
    raise e
  File "/opt/homebrew/lib/python3.9/site-packages/fastapi/middleware/asyncexitstack.py", line 18, in __call__
    await self.app(scope, receive, send)
  File "/opt/homebrew/lib/python3.9/site-packages/starlette/routing.py", line 670, in __call__
    await route.handle(scope, receive, send)
  File "/opt/homebrew/lib/python3.9/site-packages/starlette/routing.py", line 266, in handle
    await self.app(scope, receive, send)
  File "/opt/homebrew/lib/python3.9/site-packages/starlette/routing.py", line 65, in app
    response = await func(request)
  File "/opt/homebrew/lib/python3.9/site-packages/fastapi/routing.py", line 227, in app
    raw_response = await run_endpoint_function(
  File "/opt/homebrew/lib/python3.9/site-packages/fastapi/routing.py", line 160, in run_endpoint_function
    return await dependant.call(**values)
  File "/Users/aditya/Downloads/API 2/C/RUN/./main.py", line 1038, in create_order
    return user_result
UnboundLocalError: local variable 'user_result' referenced before assignment
root - INFO - 2023-03-20 10:35:15.885225 - Order placement successful for users: []
root - INFO - 2023-03-20 10:40:15.897497 - Order placement successful for users: []
root - INFO - 2023-03-20 10:45:15.856994 - Order placement successful for users: []
uvicorn.error - ERROR - Exception in ASGI application
Traceback (most recent call last):
  File "/opt/homebrew/lib/python3.9/site-packages/uvicorn/protocols/http/h11_impl.py", line 366, in run_asgi
    result = await app(self.scope, self.receive, self.send)
  File "/opt/homebrew/lib/python3.9/site-packages/uvicorn/middleware/proxy_headers.py", line 75, in __call__
    return await self.app(scope, receive, send)
  File "/opt/homebrew/lib/python3.9/site-packages/fastapi/applications.py", line 269, in __call__
    await super().__call__(scope, receive, send)
  File "/opt/homebrew/lib/python3.9/site-packages/starlette/applications.py", line 124, in __call__
    await self.middleware_stack(scope, receive, send)
  File "/opt/homebrew/lib/python3.9/site-packages/starlette/middleware/errors.py", line 184, in __call__
    raise exc
  File "/opt/homebrew/lib/python3.9/site-packages/starlette/middleware/errors.py", line 162, in __call__
    await self.app(scope, receive, _send)
  File "/opt/homebrew/lib/python3.9/site-packages/starlette/middleware/cors.py", line 84, in __call__
    await self.app(scope, receive, send)
  File "/opt/homebrew/lib/python3.9/site-packages/starlette/exceptions.py", line 93, in __call__
    raise exc
  File "/opt/homebrew/lib/python3.9/site-packages/starlette/exceptions.py", line 82, in __call__
    await self.app(scope, receive, sender)
  File "/opt/homebrew/lib/python3.9/site-packages/fastapi/middleware/asyncexitstack.py", line 21, in __call__
    raise e
  File "/opt/homebrew/lib/python3.9/site-packages/fastapi/middleware/asyncexitstack.py", line 18, in __call__
    await self.app(scope, receive, send)
  File "/opt/homebrew/lib/python3.9/site-packages/starlette/routing.py", line 670, in __call__
    await route.handle(scope, receive, send)
  File "/opt/homebrew/lib/python3.9/site-packages/starlette/routing.py", line 266, in handle
    await self.app(scope, receive, send)
  File "/opt/homebrew/lib/python3.9/site-packages/starlette/routing.py", line 65, in app
    response = await func(request)
  File "/opt/homebrew/lib/python3.9/site-packages/fastapi/routing.py", line 227, in app
    raw_response = await run_endpoint_function(
  File "/opt/homebrew/lib/python3.9/site-packages/fastapi/routing.py", line 160, in run_endpoint_function
    return await dependant.call(**values)
  File "/Users/aditya/Downloads/API 2/C/RUN/./main.py", line 1038, in create_order
    return user_result
UnboundLocalError: local variable 'user_result' referenced before assignment
root - INFO - 2023-03-20 10:45:17.200854 - Order placement successful for users: []
uvicorn.error - ERROR - Exception in ASGI application
Traceback (most recent call last):
  File "/opt/homebrew/lib/python3.9/site-packages/uvicorn/protocols/http/h11_impl.py", line 366, in run_asgi
    result = await app(self.scope, self.receive, self.send)
  File "/opt/homebrew/lib/python3.9/site-packages/uvicorn/middleware/proxy_headers.py", line 75, in __call__
    return await self.app(scope, receive, send)
  File "/opt/homebrew/lib/python3.9/site-packages/fastapi/applications.py", line 269, in __call__
    await super().__call__(scope, receive, send)
  File "/opt/homebrew/lib/python3.9/site-packages/starlette/applications.py", line 124, in __call__
    await self.middleware_stack(scope, receive, send)
  File "/opt/homebrew/lib/python3.9/site-packages/starlette/middleware/errors.py", line 184, in __call__
    raise exc
  File "/opt/homebrew/lib/python3.9/site-packages/starlette/middleware/errors.py", line 162, in __call__
    await self.app(scope, receive, _send)
  File "/opt/homebrew/lib/python3.9/site-packages/starlette/middleware/cors.py", line 84, in __call__
    await self.app(scope, receive, send)
  File "/opt/homebrew/lib/python3.9/site-packages/starlette/exceptions.py", line 93, in __call__
    raise exc
  File "/opt/homebrew/lib/python3.9/site-packages/starlette/exceptions.py", line 82, in __call__
    await self.app(scope, receive, sender)
  File "/opt/homebrew/lib/python3.9/site-packages/fastapi/middleware/asyncexitstack.py", line 21, in __call__
    raise e
  File "/opt/homebrew/lib/python3.9/site-packages/fastapi/middleware/asyncexitstack.py", line 18, in __call__
    await self.app(scope, receive, send)
  File "/opt/homebrew/lib/python3.9/site-packages/starlette/routing.py", line 670, in __call__
    await route.handle(scope, receive, send)
  File "/opt/homebrew/lib/python3.9/site-packages/starlette/routing.py", line 266, in handle
    await self.app(scope, receive, send)
  File "/opt/homebrew/lib/python3.9/site-packages/starlette/routing.py", line 65, in app
    response = await func(request)
  File "/opt/homebrew/lib/python3.9/site-packages/fastapi/routing.py", line 227, in app
    raw_response = await run_endpoint_function(
  File "/opt/homebrew/lib/python3.9/site-packages/fastapi/routing.py", line 160, in run_endpoint_function
    return await dependant.call(**values)
  File "/Users/aditya/Downloads/API 2/C/RUN/./main.py", line 1038, in create_order
    return user_result
UnboundLocalError: local variable 'user_result' referenced before assignment
root - INFO - 2023-03-20 10:50:15.906772 - Order placement successful for users: []
root - INFO - 2023-03-20 10:55:15.913750 - Order placement successful for users: []
root - INFO - 2023-03-20 11:00:15.870800 - Order placement successful for users: []
root - INFO - 2023-03-20 11:05:15.864285 - Order placement successful for users: []
root - INFO - 2023-03-20 11:10:15.827549 - Order placement successful for users: []
root - INFO - 2023-03-20 11:15:15.887155 - Order placement successful for users: []
root - INFO - 2023-03-20 11:30:15.877542 - Order placement successful for users: []
root - INFO - 2023-03-20 11:35:15.850387 - Order placement successful for users: []
uvicorn.error - ERROR - Exception in ASGI application
Traceback (most recent call last):
  File "/opt/homebrew/lib/python3.9/site-packages/uvicorn/protocols/http/h11_impl.py", line 366, in run_asgi
    result = await app(self.scope, self.receive, self.send)
  File "/opt/homebrew/lib/python3.9/site-packages/uvicorn/middleware/proxy_headers.py", line 75, in __call__
    return await self.app(scope, receive, send)
  File "/opt/homebrew/lib/python3.9/site-packages/fastapi/applications.py", line 269, in __call__
    await super().__call__(scope, receive, send)
  File "/opt/homebrew/lib/python3.9/site-packages/starlette/applications.py", line 124, in __call__
    await self.middleware_stack(scope, receive, send)
  File "/opt/homebrew/lib/python3.9/site-packages/starlette/middleware/errors.py", line 184, in __call__
    raise exc
  File "/opt/homebrew/lib/python3.9/site-packages/starlette/middleware/errors.py", line 162, in __call__
    await self.app(scope, receive, _send)
  File "/opt/homebrew/lib/python3.9/site-packages/starlette/middleware/cors.py", line 84, in __call__
    await self.app(scope, receive, send)
  File "/opt/homebrew/lib/python3.9/site-packages/starlette/exceptions.py", line 93, in __call__
    raise exc
  File "/opt/homebrew/lib/python3.9/site-packages/starlette/exceptions.py", line 82, in __call__
    await self.app(scope, receive, sender)
  File "/opt/homebrew/lib/python3.9/site-packages/fastapi/middleware/asyncexitstack.py", line 21, in __call__
    raise e
  File "/opt/homebrew/lib/python3.9/site-packages/fastapi/middleware/asyncexitstack.py", line 18, in __call__
    await self.app(scope, receive, send)
  File "/opt/homebrew/lib/python3.9/site-packages/starlette/routing.py", line 670, in __call__
    await route.handle(scope, receive, send)
  File "/opt/homebrew/lib/python3.9/site-packages/starlette/routing.py", line 266, in handle
    await self.app(scope, receive, send)
  File "/opt/homebrew/lib/python3.9/site-packages/starlette/routing.py", line 65, in app
    response = await func(request)
  File "/opt/homebrew/lib/python3.9/site-packages/fastapi/routing.py", line 227, in app
    raw_response = await run_endpoint_function(
  File "/opt/homebrew/lib/python3.9/site-packages/fastapi/routing.py", line 160, in run_endpoint_function
    return await dependant.call(**values)
  File "/Users/aditya/Downloads/API 2/C/RUN/./main.py", line 1038, in create_order
    return user_result
UnboundLocalError: local variable 'user_result' referenced before assignment
root - INFO - 2023-03-20 11:35:17.107269 - Order placement successful for users: []
uvicorn.error - ERROR - Exception in ASGI application
Traceback (most recent call last):
  File "/opt/homebrew/lib/python3.9/site-packages/uvicorn/protocols/http/h11_impl.py", line 366, in run_asgi
    result = await app(self.scope, self.receive, self.send)
  File "/opt/homebrew/lib/python3.9/site-packages/uvicorn/middleware/proxy_headers.py", line 75, in __call__
    return await self.app(scope, receive, send)
  File "/opt/homebrew/lib/python3.9/site-packages/fastapi/applications.py", line 269, in __call__
    await super().__call__(scope, receive, send)
  File "/opt/homebrew/lib/python3.9/site-packages/starlette/applications.py", line 124, in __call__
    await self.middleware_stack(scope, receive, send)
  File "/opt/homebrew/lib/python3.9/site-packages/starlette/middleware/errors.py", line 184, in __call__
    raise exc
  File "/opt/homebrew/lib/python3.9/site-packages/starlette/middleware/errors.py", line 162, in __call__
    await self.app(scope, receive, _send)
  File "/opt/homebrew/lib/python3.9/site-packages/starlette/middleware/cors.py", line 84, in __call__
    await self.app(scope, receive, send)
  File "/opt/homebrew/lib/python3.9/site-packages/starlette/exceptions.py", line 93, in __call__
    raise exc
  File "/opt/homebrew/lib/python3.9/site-packages/starlette/exceptions.py", line 82, in __call__
    await self.app(scope, receive, sender)
  File "/opt/homebrew/lib/python3.9/site-packages/fastapi/middleware/asyncexitstack.py", line 21, in __call__
    raise e
  File "/opt/homebrew/lib/python3.9/site-packages/fastapi/middleware/asyncexitstack.py", line 18, in __call__
    await self.app(scope, receive, send)
  File "/opt/homebrew/lib/python3.9/site-packages/starlette/routing.py", line 670, in __call__
    await route.handle(scope, receive, send)
  File "/opt/homebrew/lib/python3.9/site-packages/starlette/routing.py", line 266, in handle
    await self.app(scope, receive, send)
  File "/opt/homebrew/lib/python3.9/site-packages/starlette/routing.py", line 65, in app
    response = await func(request)
  File "/opt/homebrew/lib/python3.9/site-packages/fastapi/routing.py", line 227, in app
    raw_response = await run_endpoint_function(
  File "/opt/homebrew/lib/python3.9/site-packages/fastapi/routing.py", line 160, in run_endpoint_function
    return await dependant.call(**values)
  File "/Users/aditya/Downloads/API 2/C/RUN/./main.py", line 1038, in create_order
    return user_result
UnboundLocalError: local variable 'user_result' referenced before assignment
root - INFO - 2023-03-20 11:40:15.878726 - Order placement successful for users: []
uvicorn.error - ERROR - Exception in ASGI application
Traceback (most recent call last):
  File "/opt/homebrew/lib/python3.9/site-packages/uvicorn/protocols/http/h11_impl.py", line 366, in run_asgi
    result = await app(self.scope, self.receive, self.send)
  File "/opt/homebrew/lib/python3.9/site-packages/uvicorn/middleware/proxy_headers.py", line 75, in __call__
    return await self.app(scope, receive, send)
  File "/opt/homebrew/lib/python3.9/site-packages/fastapi/applications.py", line 269, in __call__
    await super().__call__(scope, receive, send)
  File "/opt/homebrew/lib/python3.9/site-packages/starlette/applications.py", line 124, in __call__
    await self.middleware_stack(scope, receive, send)
  File "/opt/homebrew/lib/python3.9/site-packages/starlette/middleware/errors.py", line 184, in __call__
    raise exc
  File "/opt/homebrew/lib/python3.9/site-packages/starlette/middleware/errors.py", line 162, in __call__
    await self.app(scope, receive, _send)
  File "/opt/homebrew/lib/python3.9/site-packages/starlette/middleware/cors.py", line 84, in __call__
    await self.app(scope, receive, send)
  File "/opt/homebrew/lib/python3.9/site-packages/starlette/exceptions.py", line 93, in __call__
    raise exc
  File "/opt/homebrew/lib/python3.9/site-packages/starlette/exceptions.py", line 82, in __call__
    await self.app(scope, receive, sender)
  File "/opt/homebrew/lib/python3.9/site-packages/fastapi/middleware/asyncexitstack.py", line 21, in __call__
    raise e
  File "/opt/homebrew/lib/python3.9/site-packages/fastapi/middleware/asyncexitstack.py", line 18, in __call__
    await self.app(scope, receive, send)
  File "/opt/homebrew/lib/python3.9/site-packages/starlette/routing.py", line 670, in __call__
    await route.handle(scope, receive, send)
  File "/opt/homebrew/lib/python3.9/site-packages/starlette/routing.py", line 266, in handle
    await self.app(scope, receive, send)
  File "/opt/homebrew/lib/python3.9/site-packages/starlette/routing.py", line 65, in app
    response = await func(request)
  File "/opt/homebrew/lib/python3.9/site-packages/fastapi/routing.py", line 227, in app
    raw_response = await run_endpoint_function(
  File "/opt/homebrew/lib/python3.9/site-packages/fastapi/routing.py", line 160, in run_endpoint_function
    return await dependant.call(**values)
  File "/Users/aditya/Downloads/API 2/C/RUN/./main.py", line 1038, in create_order
    return user_result
UnboundLocalError: local variable 'user_result' referenced before assignment
root - INFO - 2023-03-20 11:40:17.179323 - Order placement successful for users: []
uvicorn.error - ERROR - Exception in ASGI application
Traceback (most recent call last):
  File "/opt/homebrew/lib/python3.9/site-packages/uvicorn/protocols/http/h11_impl.py", line 366, in run_asgi
    result = await app(self.scope, self.receive, self.send)
  File "/opt/homebrew/lib/python3.9/site-packages/uvicorn/middleware/proxy_headers.py", line 75, in __call__
    return await self.app(scope, receive, send)
  File "/opt/homebrew/lib/python3.9/site-packages/fastapi/applications.py", line 269, in __call__
    await super().__call__(scope, receive, send)
  File "/opt/homebrew/lib/python3.9/site-packages/starlette/applications.py", line 124, in __call__
    await self.middleware_stack(scope, receive, send)
  File "/opt/homebrew/lib/python3.9/site-packages/starlette/middleware/errors.py", line 184, in __call__
    raise exc
  File "/opt/homebrew/lib/python3.9/site-packages/starlette/middleware/errors.py", line 162, in __call__
    await self.app(scope, receive, _send)
  File "/opt/homebrew/lib/python3.9/site-packages/starlette/middleware/cors.py", line 84, in __call__
    await self.app(scope, receive, send)
  File "/opt/homebrew/lib/python3.9/site-packages/starlette/exceptions.py", line 93, in __call__
    raise exc
  File "/opt/homebrew/lib/python3.9/site-packages/starlette/exceptions.py", line 82, in __call__
    await self.app(scope, receive, sender)
  File "/opt/homebrew/lib/python3.9/site-packages/fastapi/middleware/asyncexitstack.py", line 21, in __call__
    raise e
  File "/opt/homebrew/lib/python3.9/site-packages/fastapi/middleware/asyncexitstack.py", line 18, in __call__
    await self.app(scope, receive, send)
  File "/opt/homebrew/lib/python3.9/site-packages/starlette/routing.py", line 670, in __call__
    await route.handle(scope, receive, send)
  File "/opt/homebrew/lib/python3.9/site-packages/starlette/routing.py", line 266, in handle
    await self.app(scope, receive, send)
  File "/opt/homebrew/lib/python3.9/site-packages/starlette/routing.py", line 65, in app
    response = await func(request)
  File "/opt/homebrew/lib/python3.9/site-packages/fastapi/routing.py", line 227, in app
    raw_response = await run_endpoint_function(
  File "/opt/homebrew/lib/python3.9/site-packages/fastapi/routing.py", line 160, in run_endpoint_function
    return await dependant.call(**values)
  File "/Users/aditya/Downloads/API 2/C/RUN/./main.py", line 1038, in create_order
    return user_result
UnboundLocalError: local variable 'user_result' referenced before assignment
root - INFO - 2023-03-20 11:45:15.896500 - Order placement successful for users: []
root - INFO - 2023-03-20 11:50:15.846240 - Order placement successful for users: []
root - INFO - 2023-03-20 11:55:15.875906 - Order placement successful for users: []
root - INFO - 2023-03-20 12:00:15.862278 - Order placement successful for users: []
root - INFO - 2023-03-20 12:05:15.833016 - Order placement successful for users: []
uvicorn.error - ERROR - Exception in ASGI application
Traceback (most recent call last):
  File "/opt/homebrew/lib/python3.9/site-packages/uvicorn/protocols/http/h11_impl.py", line 366, in run_asgi
    result = await app(self.scope, self.receive, self.send)
  File "/opt/homebrew/lib/python3.9/site-packages/uvicorn/middleware/proxy_headers.py", line 75, in __call__
    return await self.app(scope, receive, send)
  File "/opt/homebrew/lib/python3.9/site-packages/fastapi/applications.py", line 269, in __call__
    await super().__call__(scope, receive, send)
  File "/opt/homebrew/lib/python3.9/site-packages/starlette/applications.py", line 124, in __call__
    await self.middleware_stack(scope, receive, send)
  File "/opt/homebrew/lib/python3.9/site-packages/starlette/middleware/errors.py", line 184, in __call__
    raise exc
  File "/opt/homebrew/lib/python3.9/site-packages/starlette/middleware/errors.py", line 162, in __call__
    await self.app(scope, receive, _send)
  File "/opt/homebrew/lib/python3.9/site-packages/starlette/middleware/cors.py", line 84, in __call__
    await self.app(scope, receive, send)
  File "/opt/homebrew/lib/python3.9/site-packages/starlette/exceptions.py", line 93, in __call__
    raise exc
  File "/opt/homebrew/lib/python3.9/site-packages/starlette/exceptions.py", line 82, in __call__
    await self.app(scope, receive, sender)
  File "/opt/homebrew/lib/python3.9/site-packages/fastapi/middleware/asyncexitstack.py", line 21, in __call__
    raise e
  File "/opt/homebrew/lib/python3.9/site-packages/fastapi/middleware/asyncexitstack.py", line 18, in __call__
    await self.app(scope, receive, send)
  File "/opt/homebrew/lib/python3.9/site-packages/starlette/routing.py", line 670, in __call__
    await route.handle(scope, receive, send)
  File "/opt/homebrew/lib/python3.9/site-packages/starlette/routing.py", line 266, in handle
    await self.app(scope, receive, send)
  File "/opt/homebrew/lib/python3.9/site-packages/starlette/routing.py", line 65, in app
    response = await func(request)
  File "/opt/homebrew/lib/python3.9/site-packages/fastapi/routing.py", line 227, in app
    raw_response = await run_endpoint_function(
  File "/opt/homebrew/lib/python3.9/site-packages/fastapi/routing.py", line 160, in run_endpoint_function
    return await dependant.call(**values)
  File "/Users/aditya/Downloads/API 2/C/RUN/./main.py", line 1038, in create_order
    return user_result
UnboundLocalError: local variable 'user_result' referenced before assignment
root - INFO - 2023-03-20 12:05:17.093502 - Order placement successful for users: []
uvicorn.error - ERROR - Exception in ASGI application
Traceback (most recent call last):
  File "/opt/homebrew/lib/python3.9/site-packages/uvicorn/protocols/http/h11_impl.py", line 366, in run_asgi
    result = await app(self.scope, self.receive, self.send)
  File "/opt/homebrew/lib/python3.9/site-packages/uvicorn/middleware/proxy_headers.py", line 75, in __call__
    return await self.app(scope, receive, send)
  File "/opt/homebrew/lib/python3.9/site-packages/fastapi/applications.py", line 269, in __call__
    await super().__call__(scope, receive, send)
  File "/opt/homebrew/lib/python3.9/site-packages/starlette/applications.py", line 124, in __call__
    await self.middleware_stack(scope, receive, send)
  File "/opt/homebrew/lib/python3.9/site-packages/starlette/middleware/errors.py", line 184, in __call__
    raise exc
  File "/opt/homebrew/lib/python3.9/site-packages/starlette/middleware/errors.py", line 162, in __call__
    await self.app(scope, receive, _send)
  File "/opt/homebrew/lib/python3.9/site-packages/starlette/middleware/cors.py", line 84, in __call__
    await self.app(scope, receive, send)
  File "/opt/homebrew/lib/python3.9/site-packages/starlette/exceptions.py", line 93, in __call__
    raise exc
  File "/opt/homebrew/lib/python3.9/site-packages/starlette/exceptions.py", line 82, in __call__
    await self.app(scope, receive, sender)
  File "/opt/homebrew/lib/python3.9/site-packages/fastapi/middleware/asyncexitstack.py", line 21, in __call__
    raise e
  File "/opt/homebrew/lib/python3.9/site-packages/fastapi/middleware/asyncexitstack.py", line 18, in __call__
    await self.app(scope, receive, send)
  File "/opt/homebrew/lib/python3.9/site-packages/starlette/routing.py", line 670, in __call__
    await route.handle(scope, receive, send)
  File "/opt/homebrew/lib/python3.9/site-packages/starlette/routing.py", line 266, in handle
    await self.app(scope, receive, send)
  File "/opt/homebrew/lib/python3.9/site-packages/starlette/routing.py", line 65, in app
    response = await func(request)
  File "/opt/homebrew/lib/python3.9/site-packages/fastapi/routing.py", line 227, in app
    raw_response = await run_endpoint_function(
  File "/opt/homebrew/lib/python3.9/site-packages/fastapi/routing.py", line 160, in run_endpoint_function
    return await dependant.call(**values)
  File "/Users/aditya/Downloads/API 2/C/RUN/./main.py", line 1038, in create_order
    return user_result
UnboundLocalError: local variable 'user_result' referenced before assignment
root - INFO - 2023-03-20 12:10:15.885893 - Order placement successful for users: []
uvicorn.error - ERROR - Exception in ASGI application
Traceback (most recent call last):
  File "/opt/homebrew/lib/python3.9/site-packages/uvicorn/protocols/http/h11_impl.py", line 366, in run_asgi
    result = await app(self.scope, self.receive, self.send)
  File "/opt/homebrew/lib/python3.9/site-packages/uvicorn/middleware/proxy_headers.py", line 75, in __call__
    return await self.app(scope, receive, send)
  File "/opt/homebrew/lib/python3.9/site-packages/fastapi/applications.py", line 269, in __call__
    await super().__call__(scope, receive, send)
  File "/opt/homebrew/lib/python3.9/site-packages/starlette/applications.py", line 124, in __call__
    await self.middleware_stack(scope, receive, send)
  File "/opt/homebrew/lib/python3.9/site-packages/starlette/middleware/errors.py", line 184, in __call__
    raise exc
  File "/opt/homebrew/lib/python3.9/site-packages/starlette/middleware/errors.py", line 162, in __call__
    await self.app(scope, receive, _send)
  File "/opt/homebrew/lib/python3.9/site-packages/starlette/middleware/cors.py", line 84, in __call__
    await self.app(scope, receive, send)
  File "/opt/homebrew/lib/python3.9/site-packages/starlette/exceptions.py", line 93, in __call__
    raise exc
  File "/opt/homebrew/lib/python3.9/site-packages/starlette/exceptions.py", line 82, in __call__
    await self.app(scope, receive, sender)
  File "/opt/homebrew/lib/python3.9/site-packages/fastapi/middleware/asyncexitstack.py", line 21, in __call__
    raise e
  File "/opt/homebrew/lib/python3.9/site-packages/fastapi/middleware/asyncexitstack.py", line 18, in __call__
    await self.app(scope, receive, send)
  File "/opt/homebrew/lib/python3.9/site-packages/starlette/routing.py", line 670, in __call__
    await route.handle(scope, receive, send)
  File "/opt/homebrew/lib/python3.9/site-packages/starlette/routing.py", line 266, in handle
    await self.app(scope, receive, send)
  File "/opt/homebrew/lib/python3.9/site-packages/starlette/routing.py", line 65, in app
    response = await func(request)
  File "/opt/homebrew/lib/python3.9/site-packages/fastapi/routing.py", line 227, in app
    raw_response = await run_endpoint_function(
  File "/opt/homebrew/lib/python3.9/site-packages/fastapi/routing.py", line 160, in run_endpoint_function
    return await dependant.call(**values)
  File "/Users/aditya/Downloads/API 2/C/RUN/./main.py", line 1038, in create_order
    return user_result
UnboundLocalError: local variable 'user_result' referenced before assignment
root - INFO - 2023-03-20 12:10:17.167852 - Order placement successful for users: []
uvicorn.error - ERROR - Exception in ASGI application
Traceback (most recent call last):
  File "/opt/homebrew/lib/python3.9/site-packages/uvicorn/protocols/http/h11_impl.py", line 366, in run_asgi
    result = await app(self.scope, self.receive, self.send)
  File "/opt/homebrew/lib/python3.9/site-packages/uvicorn/middleware/proxy_headers.py", line 75, in __call__
    return await self.app(scope, receive, send)
  File "/opt/homebrew/lib/python3.9/site-packages/fastapi/applications.py", line 269, in __call__
    await super().__call__(scope, receive, send)
  File "/opt/homebrew/lib/python3.9/site-packages/starlette/applications.py", line 124, in __call__
    await self.middleware_stack(scope, receive, send)
  File "/opt/homebrew/lib/python3.9/site-packages/starlette/middleware/errors.py", line 184, in __call__
    raise exc
  File "/opt/homebrew/lib/python3.9/site-packages/starlette/middleware/errors.py", line 162, in __call__
    await self.app(scope, receive, _send)
  File "/opt/homebrew/lib/python3.9/site-packages/starlette/middleware/cors.py", line 84, in __call__
    await self.app(scope, receive, send)
  File "/opt/homebrew/lib/python3.9/site-packages/starlette/exceptions.py", line 93, in __call__
    raise exc
  File "/opt/homebrew/lib/python3.9/site-packages/starlette/exceptions.py", line 82, in __call__
    await self.app(scope, receive, sender)
  File "/opt/homebrew/lib/python3.9/site-packages/fastapi/middleware/asyncexitstack.py", line 21, in __call__
    raise e
  File "/opt/homebrew/lib/python3.9/site-packages/fastapi/middleware/asyncexitstack.py", line 18, in __call__
    await self.app(scope, receive, send)
  File "/opt/homebrew/lib/python3.9/site-packages/starlette/routing.py", line 670, in __call__
    await route.handle(scope, receive, send)
  File "/opt/homebrew/lib/python3.9/site-packages/starlette/routing.py", line 266, in handle
    await self.app(scope, receive, send)
  File "/opt/homebrew/lib/python3.9/site-packages/starlette/routing.py", line 65, in app
    response = await func(request)
  File "/opt/homebrew/lib/python3.9/site-packages/fastapi/routing.py", line 227, in app
    raw_response = await run_endpoint_function(
  File "/opt/homebrew/lib/python3.9/site-packages/fastapi/routing.py", line 160, in run_endpoint_function
    return await dependant.call(**values)
  File "/Users/aditya/Downloads/API 2/C/RUN/./main.py", line 1038, in create_order
    return user_result
UnboundLocalError: local variable 'user_result' referenced before assignment
root - INFO - 2023-03-20 12:15:15.880463 - Order placement successful for users: []
uvicorn.error - ERROR - Exception in ASGI application
Traceback (most recent call last):
  File "/opt/homebrew/lib/python3.9/site-packages/uvicorn/protocols/http/h11_impl.py", line 366, in run_asgi
    result = await app(self.scope, self.receive, self.send)
  File "/opt/homebrew/lib/python3.9/site-packages/uvicorn/middleware/proxy_headers.py", line 75, in __call__
    return await self.app(scope, receive, send)
  File "/opt/homebrew/lib/python3.9/site-packages/fastapi/applications.py", line 269, in __call__
    await super().__call__(scope, receive, send)
  File "/opt/homebrew/lib/python3.9/site-packages/starlette/applications.py", line 124, in __call__
    await self.middleware_stack(scope, receive, send)
  File "/opt/homebrew/lib/python3.9/site-packages/starlette/middleware/errors.py", line 184, in __call__
    raise exc
  File "/opt/homebrew/lib/python3.9/site-packages/starlette/middleware/errors.py", line 162, in __call__
    await self.app(scope, receive, _send)
  File "/opt/homebrew/lib/python3.9/site-packages/starlette/middleware/cors.py", line 84, in __call__
    await self.app(scope, receive, send)
  File "/opt/homebrew/lib/python3.9/site-packages/starlette/exceptions.py", line 93, in __call__
    raise exc
  File "/opt/homebrew/lib/python3.9/site-packages/starlette/exceptions.py", line 82, in __call__
    await self.app(scope, receive, sender)
  File "/opt/homebrew/lib/python3.9/site-packages/fastapi/middleware/asyncexitstack.py", line 21, in __call__
    raise e
  File "/opt/homebrew/lib/python3.9/site-packages/fastapi/middleware/asyncexitstack.py", line 18, in __call__
    await self.app(scope, receive, send)
  File "/opt/homebrew/lib/python3.9/site-packages/starlette/routing.py", line 670, in __call__
    await route.handle(scope, receive, send)
  File "/opt/homebrew/lib/python3.9/site-packages/starlette/routing.py", line 266, in handle
    await self.app(scope, receive, send)
  File "/opt/homebrew/lib/python3.9/site-packages/starlette/routing.py", line 65, in app
    response = await func(request)
  File "/opt/homebrew/lib/python3.9/site-packages/fastapi/routing.py", line 227, in app
    raw_response = await run_endpoint_function(
  File "/opt/homebrew/lib/python3.9/site-packages/fastapi/routing.py", line 160, in run_endpoint_function
    return await dependant.call(**values)
  File "/Users/aditya/Downloads/API 2/C/RUN/./main.py", line 1038, in create_order
    return user_result
UnboundLocalError: local variable 'user_result' referenced before assignment
root - INFO - 2023-03-20 12:15:17.171522 - Order placement successful for users: []
uvicorn.error - ERROR - Exception in ASGI application
Traceback (most recent call last):
  File "/opt/homebrew/lib/python3.9/site-packages/uvicorn/protocols/http/h11_impl.py", line 366, in run_asgi
    result = await app(self.scope, self.receive, self.send)
  File "/opt/homebrew/lib/python3.9/site-packages/uvicorn/middleware/proxy_headers.py", line 75, in __call__
    return await self.app(scope, receive, send)
  File "/opt/homebrew/lib/python3.9/site-packages/fastapi/applications.py", line 269, in __call__
    await super().__call__(scope, receive, send)
  File "/opt/homebrew/lib/python3.9/site-packages/starlette/applications.py", line 124, in __call__
    await self.middleware_stack(scope, receive, send)
  File "/opt/homebrew/lib/python3.9/site-packages/starlette/middleware/errors.py", line 184, in __call__
    raise exc
  File "/opt/homebrew/lib/python3.9/site-packages/starlette/middleware/errors.py", line 162, in __call__
    await self.app(scope, receive, _send)
  File "/opt/homebrew/lib/python3.9/site-packages/starlette/middleware/cors.py", line 84, in __call__
    await self.app(scope, receive, send)
  File "/opt/homebrew/lib/python3.9/site-packages/starlette/exceptions.py", line 93, in __call__
    raise exc
  File "/opt/homebrew/lib/python3.9/site-packages/starlette/exceptions.py", line 82, in __call__
    await self.app(scope, receive, sender)
  File "/opt/homebrew/lib/python3.9/site-packages/fastapi/middleware/asyncexitstack.py", line 21, in __call__
    raise e
  File "/opt/homebrew/lib/python3.9/site-packages/fastapi/middleware/asyncexitstack.py", line 18, in __call__
    await self.app(scope, receive, send)
  File "/opt/homebrew/lib/python3.9/site-packages/starlette/routing.py", line 670, in __call__
    await route.handle(scope, receive, send)
  File "/opt/homebrew/lib/python3.9/site-packages/starlette/routing.py", line 266, in handle
    await self.app(scope, receive, send)
  File "/opt/homebrew/lib/python3.9/site-packages/starlette/routing.py", line 65, in app
    response = await func(request)
  File "/opt/homebrew/lib/python3.9/site-packages/fastapi/routing.py", line 227, in app
    raw_response = await run_endpoint_function(
  File "/opt/homebrew/lib/python3.9/site-packages/fastapi/routing.py", line 160, in run_endpoint_function
    return await dependant.call(**values)
  File "/Users/aditya/Downloads/API 2/C/RUN/./main.py", line 1038, in create_order
    return user_result
UnboundLocalError: local variable 'user_result' referenced before assignment
root - INFO - 2023-03-20 12:20:15.893491 - Order placement successful for users: []
uvicorn.error - ERROR - Exception in ASGI application
Traceback (most recent call last):
  File "/opt/homebrew/lib/python3.9/site-packages/uvicorn/protocols/http/h11_impl.py", line 366, in run_asgi
    result = await app(self.scope, self.receive, self.send)
  File "/opt/homebrew/lib/python3.9/site-packages/uvicorn/middleware/proxy_headers.py", line 75, in __call__
    return await self.app(scope, receive, send)
  File "/opt/homebrew/lib/python3.9/site-packages/fastapi/applications.py", line 269, in __call__
    await super().__call__(scope, receive, send)
  File "/opt/homebrew/lib/python3.9/site-packages/starlette/applications.py", line 124, in __call__
    await self.middleware_stack(scope, receive, send)
  File "/opt/homebrew/lib/python3.9/site-packages/starlette/middleware/errors.py", line 184, in __call__
    raise exc
  File "/opt/homebrew/lib/python3.9/site-packages/starlette/middleware/errors.py", line 162, in __call__
    await self.app(scope, receive, _send)
  File "/opt/homebrew/lib/python3.9/site-packages/starlette/middleware/cors.py", line 84, in __call__
    await self.app(scope, receive, send)
  File "/opt/homebrew/lib/python3.9/site-packages/starlette/exceptions.py", line 93, in __call__
    raise exc
  File "/opt/homebrew/lib/python3.9/site-packages/starlette/exceptions.py", line 82, in __call__
    await self.app(scope, receive, sender)
  File "/opt/homebrew/lib/python3.9/site-packages/fastapi/middleware/asyncexitstack.py", line 21, in __call__
    raise e
  File "/opt/homebrew/lib/python3.9/site-packages/fastapi/middleware/asyncexitstack.py", line 18, in __call__
    await self.app(scope, receive, send)
  File "/opt/homebrew/lib/python3.9/site-packages/starlette/routing.py", line 670, in __call__
    await route.handle(scope, receive, send)
  File "/opt/homebrew/lib/python3.9/site-packages/starlette/routing.py", line 266, in handle
    await self.app(scope, receive, send)
  File "/opt/homebrew/lib/python3.9/site-packages/starlette/routing.py", line 65, in app
    response = await func(request)
  File "/opt/homebrew/lib/python3.9/site-packages/fastapi/routing.py", line 227, in app
    raw_response = await run_endpoint_function(
  File "/opt/homebrew/lib/python3.9/site-packages/fastapi/routing.py", line 160, in run_endpoint_function
    return await dependant.call(**values)
  File "/Users/aditya/Downloads/API 2/C/RUN/./main.py", line 1038, in create_order
    return user_result
UnboundLocalError: local variable 'user_result' referenced before assignment
root - INFO - 2023-03-20 12:20:17.187444 - Order placement successful for users: []
uvicorn.error - ERROR - Exception in ASGI application
Traceback (most recent call last):
  File "/opt/homebrew/lib/python3.9/site-packages/uvicorn/protocols/http/h11_impl.py", line 366, in run_asgi
    result = await app(self.scope, self.receive, self.send)
  File "/opt/homebrew/lib/python3.9/site-packages/uvicorn/middleware/proxy_headers.py", line 75, in __call__
    return await self.app(scope, receive, send)
  File "/opt/homebrew/lib/python3.9/site-packages/fastapi/applications.py", line 269, in __call__
    await super().__call__(scope, receive, send)
  File "/opt/homebrew/lib/python3.9/site-packages/starlette/applications.py", line 124, in __call__
    await self.middleware_stack(scope, receive, send)
  File "/opt/homebrew/lib/python3.9/site-packages/starlette/middleware/errors.py", line 184, in __call__
    raise exc
  File "/opt/homebrew/lib/python3.9/site-packages/starlette/middleware/errors.py", line 162, in __call__
    await self.app(scope, receive, _send)
  File "/opt/homebrew/lib/python3.9/site-packages/starlette/middleware/cors.py", line 84, in __call__
    await self.app(scope, receive, send)
  File "/opt/homebrew/lib/python3.9/site-packages/starlette/exceptions.py", line 93, in __call__
    raise exc
  File "/opt/homebrew/lib/python3.9/site-packages/starlette/exceptions.py", line 82, in __call__
    await self.app(scope, receive, sender)
  File "/opt/homebrew/lib/python3.9/site-packages/fastapi/middleware/asyncexitstack.py", line 21, in __call__
    raise e
  File "/opt/homebrew/lib/python3.9/site-packages/fastapi/middleware/asyncexitstack.py", line 18, in __call__
    await self.app(scope, receive, send)
  File "/opt/homebrew/lib/python3.9/site-packages/starlette/routing.py", line 670, in __call__
    await route.handle(scope, receive, send)
  File "/opt/homebrew/lib/python3.9/site-packages/starlette/routing.py", line 266, in handle
    await self.app(scope, receive, send)
  File "/opt/homebrew/lib/python3.9/site-packages/starlette/routing.py", line 65, in app
    response = await func(request)
  File "/opt/homebrew/lib/python3.9/site-packages/fastapi/routing.py", line 227, in app
    raw_response = await run_endpoint_function(
  File "/opt/homebrew/lib/python3.9/site-packages/fastapi/routing.py", line 160, in run_endpoint_function
    return await dependant.call(**values)
  File "/Users/aditya/Downloads/API 2/C/RUN/./main.py", line 1038, in create_order
    return user_result
UnboundLocalError: local variable 'user_result' referenced before assignment
root - INFO - 2023-03-20 12:25:15.896763 - Order placement successful for users: []
uvicorn.error - ERROR - Exception in ASGI application
Traceback (most recent call last):
  File "/opt/homebrew/lib/python3.9/site-packages/uvicorn/protocols/http/h11_impl.py", line 366, in run_asgi
    result = await app(self.scope, self.receive, self.send)
  File "/opt/homebrew/lib/python3.9/site-packages/uvicorn/middleware/proxy_headers.py", line 75, in __call__
    return await self.app(scope, receive, send)
  File "/opt/homebrew/lib/python3.9/site-packages/fastapi/applications.py", line 269, in __call__
    await super().__call__(scope, receive, send)
  File "/opt/homebrew/lib/python3.9/site-packages/starlette/applications.py", line 124, in __call__
    await self.middleware_stack(scope, receive, send)
  File "/opt/homebrew/lib/python3.9/site-packages/starlette/middleware/errors.py", line 184, in __call__
    raise exc
  File "/opt/homebrew/lib/python3.9/site-packages/starlette/middleware/errors.py", line 162, in __call__
    await self.app(scope, receive, _send)
  File "/opt/homebrew/lib/python3.9/site-packages/starlette/middleware/cors.py", line 84, in __call__
    await self.app(scope, receive, send)
  File "/opt/homebrew/lib/python3.9/site-packages/starlette/exceptions.py", line 93, in __call__
    raise exc
  File "/opt/homebrew/lib/python3.9/site-packages/starlette/exceptions.py", line 82, in __call__
    await self.app(scope, receive, sender)
  File "/opt/homebrew/lib/python3.9/site-packages/fastapi/middleware/asyncexitstack.py", line 21, in __call__
    raise e
  File "/opt/homebrew/lib/python3.9/site-packages/fastapi/middleware/asyncexitstack.py", line 18, in __call__
    await self.app(scope, receive, send)
  File "/opt/homebrew/lib/python3.9/site-packages/starlette/routing.py", line 670, in __call__
    await route.handle(scope, receive, send)
  File "/opt/homebrew/lib/python3.9/site-packages/starlette/routing.py", line 266, in handle
    await self.app(scope, receive, send)
  File "/opt/homebrew/lib/python3.9/site-packages/starlette/routing.py", line 65, in app
    response = await func(request)
  File "/opt/homebrew/lib/python3.9/site-packages/fastapi/routing.py", line 227, in app
    raw_response = await run_endpoint_function(
  File "/opt/homebrew/lib/python3.9/site-packages/fastapi/routing.py", line 160, in run_endpoint_function
    return await dependant.call(**values)
  File "/Users/aditya/Downloads/API 2/C/RUN/./main.py", line 1038, in create_order
    return user_result
UnboundLocalError: local variable 'user_result' referenced before assignment
root - INFO - 2023-03-20 12:25:17.145381 - Order placement successful for users: []
uvicorn.error - ERROR - Exception in ASGI application
Traceback (most recent call last):
  File "/opt/homebrew/lib/python3.9/site-packages/uvicorn/protocols/http/h11_impl.py", line 366, in run_asgi
    result = await app(self.scope, self.receive, self.send)
  File "/opt/homebrew/lib/python3.9/site-packages/uvicorn/middleware/proxy_headers.py", line 75, in __call__
    return await self.app(scope, receive, send)
  File "/opt/homebrew/lib/python3.9/site-packages/fastapi/applications.py", line 269, in __call__
    await super().__call__(scope, receive, send)
  File "/opt/homebrew/lib/python3.9/site-packages/starlette/applications.py", line 124, in __call__
    await self.middleware_stack(scope, receive, send)
  File "/opt/homebrew/lib/python3.9/site-packages/starlette/middleware/errors.py", line 184, in __call__
    raise exc
  File "/opt/homebrew/lib/python3.9/site-packages/starlette/middleware/errors.py", line 162, in __call__
    await self.app(scope, receive, _send)
  File "/opt/homebrew/lib/python3.9/site-packages/starlette/middleware/cors.py", line 84, in __call__
    await self.app(scope, receive, send)
  File "/opt/homebrew/lib/python3.9/site-packages/starlette/exceptions.py", line 93, in __call__
    raise exc
  File "/opt/homebrew/lib/python3.9/site-packages/starlette/exceptions.py", line 82, in __call__
    await self.app(scope, receive, sender)
  File "/opt/homebrew/lib/python3.9/site-packages/fastapi/middleware/asyncexitstack.py", line 21, in __call__
    raise e
  File "/opt/homebrew/lib/python3.9/site-packages/fastapi/middleware/asyncexitstack.py", line 18, in __call__
    await self.app(scope, receive, send)
  File "/opt/homebrew/lib/python3.9/site-packages/starlette/routing.py", line 670, in __call__
    await route.handle(scope, receive, send)
  File "/opt/homebrew/lib/python3.9/site-packages/starlette/routing.py", line 266, in handle
    await self.app(scope, receive, send)
  File "/opt/homebrew/lib/python3.9/site-packages/starlette/routing.py", line 65, in app
    response = await func(request)
  File "/opt/homebrew/lib/python3.9/site-packages/fastapi/routing.py", line 227, in app
    raw_response = await run_endpoint_function(
  File "/opt/homebrew/lib/python3.9/site-packages/fastapi/routing.py", line 160, in run_endpoint_function
    return await dependant.call(**values)
  File "/Users/aditya/Downloads/API 2/C/RUN/./main.py", line 1038, in create_order
    return user_result
UnboundLocalError: local variable 'user_result' referenced before assignment
root - INFO - 2023-03-20 12:30:15.807460 - Order placement successful for users: []
uvicorn.error - ERROR - Exception in ASGI application
Traceback (most recent call last):
  File "/opt/homebrew/lib/python3.9/site-packages/uvicorn/protocols/http/h11_impl.py", line 366, in run_asgi
    result = await app(self.scope, self.receive, self.send)
  File "/opt/homebrew/lib/python3.9/site-packages/uvicorn/middleware/proxy_headers.py", line 75, in __call__
    return await self.app(scope, receive, send)
  File "/opt/homebrew/lib/python3.9/site-packages/fastapi/applications.py", line 269, in __call__
    await super().__call__(scope, receive, send)
  File "/opt/homebrew/lib/python3.9/site-packages/starlette/applications.py", line 124, in __call__
    await self.middleware_stack(scope, receive, send)
  File "/opt/homebrew/lib/python3.9/site-packages/starlette/middleware/errors.py", line 184, in __call__
    raise exc
  File "/opt/homebrew/lib/python3.9/site-packages/starlette/middleware/errors.py", line 162, in __call__
    await self.app(scope, receive, _send)
  File "/opt/homebrew/lib/python3.9/site-packages/starlette/middleware/cors.py", line 84, in __call__
    await self.app(scope, receive, send)
  File "/opt/homebrew/lib/python3.9/site-packages/starlette/exceptions.py", line 93, in __call__
    raise exc
  File "/opt/homebrew/lib/python3.9/site-packages/starlette/exceptions.py", line 82, in __call__
    await self.app(scope, receive, sender)
  File "/opt/homebrew/lib/python3.9/site-packages/fastapi/middleware/asyncexitstack.py", line 21, in __call__
    raise e
  File "/opt/homebrew/lib/python3.9/site-packages/fastapi/middleware/asyncexitstack.py", line 18, in __call__
    await self.app(scope, receive, send)
  File "/opt/homebrew/lib/python3.9/site-packages/starlette/routing.py", line 670, in __call__
    await route.handle(scope, receive, send)
  File "/opt/homebrew/lib/python3.9/site-packages/starlette/routing.py", line 266, in handle
    await self.app(scope, receive, send)
  File "/opt/homebrew/lib/python3.9/site-packages/starlette/routing.py", line 65, in app
    response = await func(request)
  File "/opt/homebrew/lib/python3.9/site-packages/fastapi/routing.py", line 227, in app
    raw_response = await run_endpoint_function(
  File "/opt/homebrew/lib/python3.9/site-packages/fastapi/routing.py", line 160, in run_endpoint_function
    return await dependant.call(**values)
  File "/Users/aditya/Downloads/API 2/C/RUN/./main.py", line 1038, in create_order
    return user_result
UnboundLocalError: local variable 'user_result' referenced before assignment
root - INFO - 2023-03-20 12:30:18.095403 - Order placement successful for users: []
uvicorn.error - ERROR - Exception in ASGI application
Traceback (most recent call last):
  File "/opt/homebrew/lib/python3.9/site-packages/uvicorn/protocols/http/h11_impl.py", line 366, in run_asgi
    result = await app(self.scope, self.receive, self.send)
  File "/opt/homebrew/lib/python3.9/site-packages/uvicorn/middleware/proxy_headers.py", line 75, in __call__
    return await self.app(scope, receive, send)
  File "/opt/homebrew/lib/python3.9/site-packages/fastapi/applications.py", line 269, in __call__
    await super().__call__(scope, receive, send)
  File "/opt/homebrew/lib/python3.9/site-packages/starlette/applications.py", line 124, in __call__
    await self.middleware_stack(scope, receive, send)
  File "/opt/homebrew/lib/python3.9/site-packages/starlette/middleware/errors.py", line 184, in __call__
    raise exc
  File "/opt/homebrew/lib/python3.9/site-packages/starlette/middleware/errors.py", line 162, in __call__
    await self.app(scope, receive, _send)
  File "/opt/homebrew/lib/python3.9/site-packages/starlette/middleware/cors.py", line 84, in __call__
    await self.app(scope, receive, send)
  File "/opt/homebrew/lib/python3.9/site-packages/starlette/exceptions.py", line 93, in __call__
    raise exc
  File "/opt/homebrew/lib/python3.9/site-packages/starlette/exceptions.py", line 82, in __call__
    await self.app(scope, receive, sender)
  File "/opt/homebrew/lib/python3.9/site-packages/fastapi/middleware/asyncexitstack.py", line 21, in __call__
    raise e
  File "/opt/homebrew/lib/python3.9/site-packages/fastapi/middleware/asyncexitstack.py", line 18, in __call__
    await self.app(scope, receive, send)
  File "/opt/homebrew/lib/python3.9/site-packages/starlette/routing.py", line 670, in __call__
    await route.handle(scope, receive, send)
  File "/opt/homebrew/lib/python3.9/site-packages/starlette/routing.py", line 266, in handle
    await self.app(scope, receive, send)
  File "/opt/homebrew/lib/python3.9/site-packages/starlette/routing.py", line 65, in app
    response = await func(request)
  File "/opt/homebrew/lib/python3.9/site-packages/fastapi/routing.py", line 227, in app
    raw_response = await run_endpoint_function(
  File "/opt/homebrew/lib/python3.9/site-packages/fastapi/routing.py", line 160, in run_endpoint_function
    return await dependant.call(**values)
  File "/Users/aditya/Downloads/API 2/C/RUN/./main.py", line 1038, in create_order
    return user_result
UnboundLocalError: local variable 'user_result' referenced before assignment
root - INFO - 2023-03-20 12:35:15.841090 - Order placement successful for users: []
uvicorn.error - ERROR - Exception in ASGI application
Traceback (most recent call last):
  File "/opt/homebrew/lib/python3.9/site-packages/uvicorn/protocols/http/h11_impl.py", line 366, in run_asgi
    result = await app(self.scope, self.receive, self.send)
  File "/opt/homebrew/lib/python3.9/site-packages/uvicorn/middleware/proxy_headers.py", line 75, in __call__
    return await self.app(scope, receive, send)
  File "/opt/homebrew/lib/python3.9/site-packages/fastapi/applications.py", line 269, in __call__
    await super().__call__(scope, receive, send)
  File "/opt/homebrew/lib/python3.9/site-packages/starlette/applications.py", line 124, in __call__
    await self.middleware_stack(scope, receive, send)
  File "/opt/homebrew/lib/python3.9/site-packages/starlette/middleware/errors.py", line 184, in __call__
    raise exc
  File "/opt/homebrew/lib/python3.9/site-packages/starlette/middleware/errors.py", line 162, in __call__
    await self.app(scope, receive, _send)
  File "/opt/homebrew/lib/python3.9/site-packages/starlette/middleware/cors.py", line 84, in __call__
    await self.app(scope, receive, send)
  File "/opt/homebrew/lib/python3.9/site-packages/starlette/exceptions.py", line 93, in __call__
    raise exc
  File "/opt/homebrew/lib/python3.9/site-packages/starlette/exceptions.py", line 82, in __call__
    await self.app(scope, receive, sender)
  File "/opt/homebrew/lib/python3.9/site-packages/fastapi/middleware/asyncexitstack.py", line 21, in __call__
    raise e
  File "/opt/homebrew/lib/python3.9/site-packages/fastapi/middleware/asyncexitstack.py", line 18, in __call__
    await self.app(scope, receive, send)
  File "/opt/homebrew/lib/python3.9/site-packages/starlette/routing.py", line 670, in __call__
    await route.handle(scope, receive, send)
  File "/opt/homebrew/lib/python3.9/site-packages/starlette/routing.py", line 266, in handle
    await self.app(scope, receive, send)
  File "/opt/homebrew/lib/python3.9/site-packages/starlette/routing.py", line 65, in app
    response = await func(request)
  File "/opt/homebrew/lib/python3.9/site-packages/fastapi/routing.py", line 227, in app
    raw_response = await run_endpoint_function(
  File "/opt/homebrew/lib/python3.9/site-packages/fastapi/routing.py", line 160, in run_endpoint_function
    return await dependant.call(**values)
  File "/Users/aditya/Downloads/API 2/C/RUN/./main.py", line 1038, in create_order
    return user_result
UnboundLocalError: local variable 'user_result' referenced before assignment
root - INFO - 2023-03-20 12:35:17.033594 - Order placement successful for users: []
uvicorn.error - ERROR - Exception in ASGI application
Traceback (most recent call last):
  File "/opt/homebrew/lib/python3.9/site-packages/uvicorn/protocols/http/h11_impl.py", line 366, in run_asgi
    result = await app(self.scope, self.receive, self.send)
  File "/opt/homebrew/lib/python3.9/site-packages/uvicorn/middleware/proxy_headers.py", line 75, in __call__
    return await self.app(scope, receive, send)
  File "/opt/homebrew/lib/python3.9/site-packages/fastapi/applications.py", line 269, in __call__
    await super().__call__(scope, receive, send)
  File "/opt/homebrew/lib/python3.9/site-packages/starlette/applications.py", line 124, in __call__
    await self.middleware_stack(scope, receive, send)
  File "/opt/homebrew/lib/python3.9/site-packages/starlette/middleware/errors.py", line 184, in __call__
    raise exc
  File "/opt/homebrew/lib/python3.9/site-packages/starlette/middleware/errors.py", line 162, in __call__
    await self.app(scope, receive, _send)
  File "/opt/homebrew/lib/python3.9/site-packages/starlette/middleware/cors.py", line 84, in __call__
    await self.app(scope, receive, send)
  File "/opt/homebrew/lib/python3.9/site-packages/starlette/exceptions.py", line 93, in __call__
    raise exc
  File "/opt/homebrew/lib/python3.9/site-packages/starlette/exceptions.py", line 82, in __call__
    await self.app(scope, receive, sender)
  File "/opt/homebrew/lib/python3.9/site-packages/fastapi/middleware/asyncexitstack.py", line 21, in __call__
    raise e
  File "/opt/homebrew/lib/python3.9/site-packages/fastapi/middleware/asyncexitstack.py", line 18, in __call__
    await self.app(scope, receive, send)
  File "/opt/homebrew/lib/python3.9/site-packages/starlette/routing.py", line 670, in __call__
    await route.handle(scope, receive, send)
  File "/opt/homebrew/lib/python3.9/site-packages/starlette/routing.py", line 266, in handle
    await self.app(scope, receive, send)
  File "/opt/homebrew/lib/python3.9/site-packages/starlette/routing.py", line 65, in app
    response = await func(request)
  File "/opt/homebrew/lib/python3.9/site-packages/fastapi/routing.py", line 227, in app
    raw_response = await run_endpoint_function(
  File "/opt/homebrew/lib/python3.9/site-packages/fastapi/routing.py", line 160, in run_endpoint_function
    return await dependant.call(**values)
  File "/Users/aditya/Downloads/API 2/C/RUN/./main.py", line 1038, in create_order
    return user_result
UnboundLocalError: local variable 'user_result' referenced before assignment
root - INFO - 2023-03-20 12:40:15.870523 - Order placement successful for users: []
uvicorn.error - ERROR - Exception in ASGI application
Traceback (most recent call last):
  File "/opt/homebrew/lib/python3.9/site-packages/uvicorn/protocols/http/h11_impl.py", line 366, in run_asgi
    result = await app(self.scope, self.receive, self.send)
  File "/opt/homebrew/lib/python3.9/site-packages/uvicorn/middleware/proxy_headers.py", line 75, in __call__
    return await self.app(scope, receive, send)
  File "/opt/homebrew/lib/python3.9/site-packages/fastapi/applications.py", line 269, in __call__
    await super().__call__(scope, receive, send)
  File "/opt/homebrew/lib/python3.9/site-packages/starlette/applications.py", line 124, in __call__
    await self.middleware_stack(scope, receive, send)
  File "/opt/homebrew/lib/python3.9/site-packages/starlette/middleware/errors.py", line 184, in __call__
    raise exc
  File "/opt/homebrew/lib/python3.9/site-packages/starlette/middleware/errors.py", line 162, in __call__
    await self.app(scope, receive, _send)
  File "/opt/homebrew/lib/python3.9/site-packages/starlette/middleware/cors.py", line 84, in __call__
    await self.app(scope, receive, send)
  File "/opt/homebrew/lib/python3.9/site-packages/starlette/exceptions.py", line 93, in __call__
    raise exc
  File "/opt/homebrew/lib/python3.9/site-packages/starlette/exceptions.py", line 82, in __call__
    await self.app(scope, receive, sender)
  File "/opt/homebrew/lib/python3.9/site-packages/fastapi/middleware/asyncexitstack.py", line 21, in __call__
    raise e
  File "/opt/homebrew/lib/python3.9/site-packages/fastapi/middleware/asyncexitstack.py", line 18, in __call__
    await self.app(scope, receive, send)
  File "/opt/homebrew/lib/python3.9/site-packages/starlette/routing.py", line 670, in __call__
    await route.handle(scope, receive, send)
  File "/opt/homebrew/lib/python3.9/site-packages/starlette/routing.py", line 266, in handle
    await self.app(scope, receive, send)
  File "/opt/homebrew/lib/python3.9/site-packages/starlette/routing.py", line 65, in app
    response = await func(request)
  File "/opt/homebrew/lib/python3.9/site-packages/fastapi/routing.py", line 227, in app
    raw_response = await run_endpoint_function(
  File "/opt/homebrew/lib/python3.9/site-packages/fastapi/routing.py", line 160, in run_endpoint_function
    return await dependant.call(**values)
  File "/Users/aditya/Downloads/API 2/C/RUN/./main.py", line 1038, in create_order
    return user_result
UnboundLocalError: local variable 'user_result' referenced before assignment
root - INFO - 2023-03-20 12:40:17.204353 - Order placement successful for users: []
uvicorn.error - ERROR - Exception in ASGI application
Traceback (most recent call last):
  File "/opt/homebrew/lib/python3.9/site-packages/uvicorn/protocols/http/h11_impl.py", line 366, in run_asgi
    result = await app(self.scope, self.receive, self.send)
  File "/opt/homebrew/lib/python3.9/site-packages/uvicorn/middleware/proxy_headers.py", line 75, in __call__
    return await self.app(scope, receive, send)
  File "/opt/homebrew/lib/python3.9/site-packages/fastapi/applications.py", line 269, in __call__
    await super().__call__(scope, receive, send)
  File "/opt/homebrew/lib/python3.9/site-packages/starlette/applications.py", line 124, in __call__
    await self.middleware_stack(scope, receive, send)
  File "/opt/homebrew/lib/python3.9/site-packages/starlette/middleware/errors.py", line 184, in __call__
    raise exc
  File "/opt/homebrew/lib/python3.9/site-packages/starlette/middleware/errors.py", line 162, in __call__
    await self.app(scope, receive, _send)
  File "/opt/homebrew/lib/python3.9/site-packages/starlette/middleware/cors.py", line 84, in __call__
    await self.app(scope, receive, send)
  File "/opt/homebrew/lib/python3.9/site-packages/starlette/exceptions.py", line 93, in __call__
    raise exc
  File "/opt/homebrew/lib/python3.9/site-packages/starlette/exceptions.py", line 82, in __call__
    await self.app(scope, receive, sender)
  File "/opt/homebrew/lib/python3.9/site-packages/fastapi/middleware/asyncexitstack.py", line 21, in __call__
    raise e
  File "/opt/homebrew/lib/python3.9/site-packages/fastapi/middleware/asyncexitstack.py", line 18, in __call__
    await self.app(scope, receive, send)
  File "/opt/homebrew/lib/python3.9/site-packages/starlette/routing.py", line 670, in __call__
    await route.handle(scope, receive, send)
  File "/opt/homebrew/lib/python3.9/site-packages/starlette/routing.py", line 266, in handle
    await self.app(scope, receive, send)
  File "/opt/homebrew/lib/python3.9/site-packages/starlette/routing.py", line 65, in app
    response = await func(request)
  File "/opt/homebrew/lib/python3.9/site-packages/fastapi/routing.py", line 227, in app
    raw_response = await run_endpoint_function(
  File "/opt/homebrew/lib/python3.9/site-packages/fastapi/routing.py", line 160, in run_endpoint_function
    return await dependant.call(**values)
  File "/Users/aditya/Downloads/API 2/C/RUN/./main.py", line 1038, in create_order
    return user_result
UnboundLocalError: local variable 'user_result' referenced before assignment
root - INFO - 2023-03-20 12:45:15.876925 - Order placement successful for users: []
root - INFO - 2023-03-20 12:50:15.944173 - Order placement successful for users: []
root - INFO - 2023-03-20 12:55:15.960342 - Order placement successful for users: []
uvicorn.error - ERROR - Exception in ASGI application
Traceback (most recent call last):
  File "/opt/homebrew/lib/python3.9/site-packages/uvicorn/protocols/http/h11_impl.py", line 366, in run_asgi
    result = await app(self.scope, self.receive, self.send)
  File "/opt/homebrew/lib/python3.9/site-packages/uvicorn/middleware/proxy_headers.py", line 75, in __call__
    return await self.app(scope, receive, send)
  File "/opt/homebrew/lib/python3.9/site-packages/fastapi/applications.py", line 269, in __call__
    await super().__call__(scope, receive, send)
  File "/opt/homebrew/lib/python3.9/site-packages/starlette/applications.py", line 124, in __call__
    await self.middleware_stack(scope, receive, send)
  File "/opt/homebrew/lib/python3.9/site-packages/starlette/middleware/errors.py", line 184, in __call__
    raise exc
  File "/opt/homebrew/lib/python3.9/site-packages/starlette/middleware/errors.py", line 162, in __call__
    await self.app(scope, receive, _send)
  File "/opt/homebrew/lib/python3.9/site-packages/starlette/middleware/cors.py", line 84, in __call__
    await self.app(scope, receive, send)
  File "/opt/homebrew/lib/python3.9/site-packages/starlette/exceptions.py", line 93, in __call__
    raise exc
  File "/opt/homebrew/lib/python3.9/site-packages/starlette/exceptions.py", line 82, in __call__
    await self.app(scope, receive, sender)
  File "/opt/homebrew/lib/python3.9/site-packages/fastapi/middleware/asyncexitstack.py", line 21, in __call__
    raise e
  File "/opt/homebrew/lib/python3.9/site-packages/fastapi/middleware/asyncexitstack.py", line 18, in __call__
    await self.app(scope, receive, send)
  File "/opt/homebrew/lib/python3.9/site-packages/starlette/routing.py", line 670, in __call__
    await route.handle(scope, receive, send)
  File "/opt/homebrew/lib/python3.9/site-packages/starlette/routing.py", line 266, in handle
    await self.app(scope, receive, send)
  File "/opt/homebrew/lib/python3.9/site-packages/starlette/routing.py", line 65, in app
    response = await func(request)
  File "/opt/homebrew/lib/python3.9/site-packages/fastapi/routing.py", line 227, in app
    raw_response = await run_endpoint_function(
  File "/opt/homebrew/lib/python3.9/site-packages/fastapi/routing.py", line 160, in run_endpoint_function
    return await dependant.call(**values)
  File "/Users/aditya/Downloads/API 2/C/RUN/./main.py", line 1038, in create_order
    return user_result
UnboundLocalError: local variable 'user_result' referenced before assignment
root - INFO - 2023-03-20 12:55:17.255605 - Order placement successful for users: []
uvicorn.error - ERROR - Exception in ASGI application
Traceback (most recent call last):
  File "/opt/homebrew/lib/python3.9/site-packages/uvicorn/protocols/http/h11_impl.py", line 366, in run_asgi
    result = await app(self.scope, self.receive, self.send)
  File "/opt/homebrew/lib/python3.9/site-packages/uvicorn/middleware/proxy_headers.py", line 75, in __call__
    return await self.app(scope, receive, send)
  File "/opt/homebrew/lib/python3.9/site-packages/fastapi/applications.py", line 269, in __call__
    await super().__call__(scope, receive, send)
  File "/opt/homebrew/lib/python3.9/site-packages/starlette/applications.py", line 124, in __call__
    await self.middleware_stack(scope, receive, send)
  File "/opt/homebrew/lib/python3.9/site-packages/starlette/middleware/errors.py", line 184, in __call__
    raise exc
  File "/opt/homebrew/lib/python3.9/site-packages/starlette/middleware/errors.py", line 162, in __call__
    await self.app(scope, receive, _send)
  File "/opt/homebrew/lib/python3.9/site-packages/starlette/middleware/cors.py", line 84, in __call__
    await self.app(scope, receive, send)
  File "/opt/homebrew/lib/python3.9/site-packages/starlette/exceptions.py", line 93, in __call__
    raise exc
  File "/opt/homebrew/lib/python3.9/site-packages/starlette/exceptions.py", line 82, in __call__
    await self.app(scope, receive, sender)
  File "/opt/homebrew/lib/python3.9/site-packages/fastapi/middleware/asyncexitstack.py", line 21, in __call__
    raise e
  File "/opt/homebrew/lib/python3.9/site-packages/fastapi/middleware/asyncexitstack.py", line 18, in __call__
    await self.app(scope, receive, send)
  File "/opt/homebrew/lib/python3.9/site-packages/starlette/routing.py", line 670, in __call__
    await route.handle(scope, receive, send)
  File "/opt/homebrew/lib/python3.9/site-packages/starlette/routing.py", line 266, in handle
    await self.app(scope, receive, send)
  File "/opt/homebrew/lib/python3.9/site-packages/starlette/routing.py", line 65, in app
    response = await func(request)
  File "/opt/homebrew/lib/python3.9/site-packages/fastapi/routing.py", line 227, in app
    raw_response = await run_endpoint_function(
  File "/opt/homebrew/lib/python3.9/site-packages/fastapi/routing.py", line 160, in run_endpoint_function
    return await dependant.call(**values)
  File "/Users/aditya/Downloads/API 2/C/RUN/./main.py", line 1038, in create_order
    return user_result
UnboundLocalError: local variable 'user_result' referenced before assignment
root - INFO - 2023-03-20 13:00:15.914257 - Order placement successful for users: []
uvicorn.error - ERROR - Exception in ASGI application
Traceback (most recent call last):
  File "/opt/homebrew/lib/python3.9/site-packages/uvicorn/protocols/http/h11_impl.py", line 366, in run_asgi
    result = await app(self.scope, self.receive, self.send)
  File "/opt/homebrew/lib/python3.9/site-packages/uvicorn/middleware/proxy_headers.py", line 75, in __call__
    return await self.app(scope, receive, send)
  File "/opt/homebrew/lib/python3.9/site-packages/fastapi/applications.py", line 269, in __call__
    await super().__call__(scope, receive, send)
  File "/opt/homebrew/lib/python3.9/site-packages/starlette/applications.py", line 124, in __call__
    await self.middleware_stack(scope, receive, send)
  File "/opt/homebrew/lib/python3.9/site-packages/starlette/middleware/errors.py", line 184, in __call__
    raise exc
  File "/opt/homebrew/lib/python3.9/site-packages/starlette/middleware/errors.py", line 162, in __call__
    await self.app(scope, receive, _send)
  File "/opt/homebrew/lib/python3.9/site-packages/starlette/middleware/cors.py", line 84, in __call__
    await self.app(scope, receive, send)
  File "/opt/homebrew/lib/python3.9/site-packages/starlette/exceptions.py", line 93, in __call__
    raise exc
  File "/opt/homebrew/lib/python3.9/site-packages/starlette/exceptions.py", line 82, in __call__
    await self.app(scope, receive, sender)
  File "/opt/homebrew/lib/python3.9/site-packages/fastapi/middleware/asyncexitstack.py", line 21, in __call__
    raise e
  File "/opt/homebrew/lib/python3.9/site-packages/fastapi/middleware/asyncexitstack.py", line 18, in __call__
    await self.app(scope, receive, send)
  File "/opt/homebrew/lib/python3.9/site-packages/starlette/routing.py", line 670, in __call__
    await route.handle(scope, receive, send)
  File "/opt/homebrew/lib/python3.9/site-packages/starlette/routing.py", line 266, in handle
    await self.app(scope, receive, send)
  File "/opt/homebrew/lib/python3.9/site-packages/starlette/routing.py", line 65, in app
    response = await func(request)
  File "/opt/homebrew/lib/python3.9/site-packages/fastapi/routing.py", line 227, in app
    raw_response = await run_endpoint_function(
  File "/opt/homebrew/lib/python3.9/site-packages/fastapi/routing.py", line 160, in run_endpoint_function
    return await dependant.call(**values)
  File "/Users/aditya/Downloads/API 2/C/RUN/./main.py", line 1038, in create_order
    return user_result
UnboundLocalError: local variable 'user_result' referenced before assignment
root - INFO - 2023-03-20 13:00:17.209302 - Order placement successful for users: []
uvicorn.error - ERROR - Exception in ASGI application
Traceback (most recent call last):
  File "/opt/homebrew/lib/python3.9/site-packages/uvicorn/protocols/http/h11_impl.py", line 366, in run_asgi
    result = await app(self.scope, self.receive, self.send)
  File "/opt/homebrew/lib/python3.9/site-packages/uvicorn/middleware/proxy_headers.py", line 75, in __call__
    return await self.app(scope, receive, send)
  File "/opt/homebrew/lib/python3.9/site-packages/fastapi/applications.py", line 269, in __call__
    await super().__call__(scope, receive, send)
  File "/opt/homebrew/lib/python3.9/site-packages/starlette/applications.py", line 124, in __call__
    await self.middleware_stack(scope, receive, send)
  File "/opt/homebrew/lib/python3.9/site-packages/starlette/middleware/errors.py", line 184, in __call__
    raise exc
  File "/opt/homebrew/lib/python3.9/site-packages/starlette/middleware/errors.py", line 162, in __call__
    await self.app(scope, receive, _send)
  File "/opt/homebrew/lib/python3.9/site-packages/starlette/middleware/cors.py", line 84, in __call__
    await self.app(scope, receive, send)
  File "/opt/homebrew/lib/python3.9/site-packages/starlette/exceptions.py", line 93, in __call__
    raise exc
  File "/opt/homebrew/lib/python3.9/site-packages/starlette/exceptions.py", line 82, in __call__
    await self.app(scope, receive, sender)
  File "/opt/homebrew/lib/python3.9/site-packages/fastapi/middleware/asyncexitstack.py", line 21, in __call__
    raise e
  File "/opt/homebrew/lib/python3.9/site-packages/fastapi/middleware/asyncexitstack.py", line 18, in __call__
    await self.app(scope, receive, send)
  File "/opt/homebrew/lib/python3.9/site-packages/starlette/routing.py", line 670, in __call__
    await route.handle(scope, receive, send)
  File "/opt/homebrew/lib/python3.9/site-packages/starlette/routing.py", line 266, in handle
    await self.app(scope, receive, send)
  File "/opt/homebrew/lib/python3.9/site-packages/starlette/routing.py", line 65, in app
    response = await func(request)
  File "/opt/homebrew/lib/python3.9/site-packages/fastapi/routing.py", line 227, in app
    raw_response = await run_endpoint_function(
  File "/opt/homebrew/lib/python3.9/site-packages/fastapi/routing.py", line 160, in run_endpoint_function
    return await dependant.call(**values)
  File "/Users/aditya/Downloads/API 2/C/RUN/./main.py", line 1038, in create_order
    return user_result
UnboundLocalError: local variable 'user_result' referenced before assignment
root - INFO - 2023-03-20 13:05:15.880839 - Order placement successful for users: []
uvicorn.error - ERROR - Exception in ASGI application
Traceback (most recent call last):
  File "/opt/homebrew/lib/python3.9/site-packages/uvicorn/protocols/http/h11_impl.py", line 366, in run_asgi
    result = await app(self.scope, self.receive, self.send)
  File "/opt/homebrew/lib/python3.9/site-packages/uvicorn/middleware/proxy_headers.py", line 75, in __call__
    return await self.app(scope, receive, send)
  File "/opt/homebrew/lib/python3.9/site-packages/fastapi/applications.py", line 269, in __call__
    await super().__call__(scope, receive, send)
  File "/opt/homebrew/lib/python3.9/site-packages/starlette/applications.py", line 124, in __call__
    await self.middleware_stack(scope, receive, send)
  File "/opt/homebrew/lib/python3.9/site-packages/starlette/middleware/errors.py", line 184, in __call__
    raise exc
  File "/opt/homebrew/lib/python3.9/site-packages/starlette/middleware/errors.py", line 162, in __call__
    await self.app(scope, receive, _send)
  File "/opt/homebrew/lib/python3.9/site-packages/starlette/middleware/cors.py", line 84, in __call__
    await self.app(scope, receive, send)
  File "/opt/homebrew/lib/python3.9/site-packages/starlette/exceptions.py", line 93, in __call__
    raise exc
  File "/opt/homebrew/lib/python3.9/site-packages/starlette/exceptions.py", line 82, in __call__
    await self.app(scope, receive, sender)
  File "/opt/homebrew/lib/python3.9/site-packages/fastapi/middleware/asyncexitstack.py", line 21, in __call__
    raise e
  File "/opt/homebrew/lib/python3.9/site-packages/fastapi/middleware/asyncexitstack.py", line 18, in __call__
    await self.app(scope, receive, send)
  File "/opt/homebrew/lib/python3.9/site-packages/starlette/routing.py", line 670, in __call__
    await route.handle(scope, receive, send)
  File "/opt/homebrew/lib/python3.9/site-packages/starlette/routing.py", line 266, in handle
    await self.app(scope, receive, send)
  File "/opt/homebrew/lib/python3.9/site-packages/starlette/routing.py", line 65, in app
    response = await func(request)
  File "/opt/homebrew/lib/python3.9/site-packages/fastapi/routing.py", line 227, in app
    raw_response = await run_endpoint_function(
  File "/opt/homebrew/lib/python3.9/site-packages/fastapi/routing.py", line 160, in run_endpoint_function
    return await dependant.call(**values)
  File "/Users/aditya/Downloads/API 2/C/RUN/./main.py", line 1038, in create_order
    return user_result
UnboundLocalError: local variable 'user_result' referenced before assignment
root - INFO - 2023-03-20 13:05:17.210706 - Order placement successful for users: []
uvicorn.error - ERROR - Exception in ASGI application
Traceback (most recent call last):
  File "/opt/homebrew/lib/python3.9/site-packages/uvicorn/protocols/http/h11_impl.py", line 366, in run_asgi
    result = await app(self.scope, self.receive, self.send)
  File "/opt/homebrew/lib/python3.9/site-packages/uvicorn/middleware/proxy_headers.py", line 75, in __call__
    return await self.app(scope, receive, send)
  File "/opt/homebrew/lib/python3.9/site-packages/fastapi/applications.py", line 269, in __call__
    await super().__call__(scope, receive, send)
  File "/opt/homebrew/lib/python3.9/site-packages/starlette/applications.py", line 124, in __call__
    await self.middleware_stack(scope, receive, send)
  File "/opt/homebrew/lib/python3.9/site-packages/starlette/middleware/errors.py", line 184, in __call__
    raise exc
  File "/opt/homebrew/lib/python3.9/site-packages/starlette/middleware/errors.py", line 162, in __call__
    await self.app(scope, receive, _send)
  File "/opt/homebrew/lib/python3.9/site-packages/starlette/middleware/cors.py", line 84, in __call__
    await self.app(scope, receive, send)
  File "/opt/homebrew/lib/python3.9/site-packages/starlette/exceptions.py", line 93, in __call__
    raise exc
  File "/opt/homebrew/lib/python3.9/site-packages/starlette/exceptions.py", line 82, in __call__
    await self.app(scope, receive, sender)
  File "/opt/homebrew/lib/python3.9/site-packages/fastapi/middleware/asyncexitstack.py", line 21, in __call__
    raise e
  File "/opt/homebrew/lib/python3.9/site-packages/fastapi/middleware/asyncexitstack.py", line 18, in __call__
    await self.app(scope, receive, send)
  File "/opt/homebrew/lib/python3.9/site-packages/starlette/routing.py", line 670, in __call__
    await route.handle(scope, receive, send)
  File "/opt/homebrew/lib/python3.9/site-packages/starlette/routing.py", line 266, in handle
    await self.app(scope, receive, send)
  File "/opt/homebrew/lib/python3.9/site-packages/starlette/routing.py", line 65, in app
    response = await func(request)
  File "/opt/homebrew/lib/python3.9/site-packages/fastapi/routing.py", line 227, in app
    raw_response = await run_endpoint_function(
  File "/opt/homebrew/lib/python3.9/site-packages/fastapi/routing.py", line 160, in run_endpoint_function
    return await dependant.call(**values)
  File "/Users/aditya/Downloads/API 2/C/RUN/./main.py", line 1038, in create_order
    return user_result
UnboundLocalError: local variable 'user_result' referenced before assignment
root - INFO - 2023-03-20 13:10:15.934942 - Order placement successful for users: []
root - INFO - 2023-03-20 13:15:15.941147 - Order placement successful for users: []
root - INFO - 2023-03-20 13:20:15.846610 - Order placement successful for users: []
uvicorn.error - ERROR - Exception in ASGI application
Traceback (most recent call last):
  File "/opt/homebrew/lib/python3.9/site-packages/uvicorn/protocols/http/h11_impl.py", line 366, in run_asgi
    result = await app(self.scope, self.receive, self.send)
  File "/opt/homebrew/lib/python3.9/site-packages/uvicorn/middleware/proxy_headers.py", line 75, in __call__
    return await self.app(scope, receive, send)
  File "/opt/homebrew/lib/python3.9/site-packages/fastapi/applications.py", line 269, in __call__
    await super().__call__(scope, receive, send)
  File "/opt/homebrew/lib/python3.9/site-packages/starlette/applications.py", line 124, in __call__
    await self.middleware_stack(scope, receive, send)
  File "/opt/homebrew/lib/python3.9/site-packages/starlette/middleware/errors.py", line 184, in __call__
    raise exc
  File "/opt/homebrew/lib/python3.9/site-packages/starlette/middleware/errors.py", line 162, in __call__
    await self.app(scope, receive, _send)
  File "/opt/homebrew/lib/python3.9/site-packages/starlette/middleware/cors.py", line 84, in __call__
    await self.app(scope, receive, send)
  File "/opt/homebrew/lib/python3.9/site-packages/starlette/exceptions.py", line 93, in __call__
    raise exc
  File "/opt/homebrew/lib/python3.9/site-packages/starlette/exceptions.py", line 82, in __call__
    await self.app(scope, receive, sender)
  File "/opt/homebrew/lib/python3.9/site-packages/fastapi/middleware/asyncexitstack.py", line 21, in __call__
    raise e
  File "/opt/homebrew/lib/python3.9/site-packages/fastapi/middleware/asyncexitstack.py", line 18, in __call__
    await self.app(scope, receive, send)
  File "/opt/homebrew/lib/python3.9/site-packages/starlette/routing.py", line 670, in __call__
    await route.handle(scope, receive, send)
  File "/opt/homebrew/lib/python3.9/site-packages/starlette/routing.py", line 266, in handle
    await self.app(scope, receive, send)
  File "/opt/homebrew/lib/python3.9/site-packages/starlette/routing.py", line 65, in app
    response = await func(request)
  File "/opt/homebrew/lib/python3.9/site-packages/fastapi/routing.py", line 227, in app
    raw_response = await run_endpoint_function(
  File "/opt/homebrew/lib/python3.9/site-packages/fastapi/routing.py", line 160, in run_endpoint_function
    return await dependant.call(**values)
  File "/Users/aditya/Downloads/API 2/C/RUN/./main.py", line 1038, in create_order
    return user_result
UnboundLocalError: local variable 'user_result' referenced before assignment
root - INFO - 2023-03-20 13:20:17.101280 - Order placement successful for users: []
uvicorn.error - ERROR - Exception in ASGI application
Traceback (most recent call last):
  File "/opt/homebrew/lib/python3.9/site-packages/uvicorn/protocols/http/h11_impl.py", line 366, in run_asgi
    result = await app(self.scope, self.receive, self.send)
  File "/opt/homebrew/lib/python3.9/site-packages/uvicorn/middleware/proxy_headers.py", line 75, in __call__
    return await self.app(scope, receive, send)
  File "/opt/homebrew/lib/python3.9/site-packages/fastapi/applications.py", line 269, in __call__
    await super().__call__(scope, receive, send)
  File "/opt/homebrew/lib/python3.9/site-packages/starlette/applications.py", line 124, in __call__
    await self.middleware_stack(scope, receive, send)
  File "/opt/homebrew/lib/python3.9/site-packages/starlette/middleware/errors.py", line 184, in __call__
    raise exc
  File "/opt/homebrew/lib/python3.9/site-packages/starlette/middleware/errors.py", line 162, in __call__
    await self.app(scope, receive, _send)
  File "/opt/homebrew/lib/python3.9/site-packages/starlette/middleware/cors.py", line 84, in __call__
    await self.app(scope, receive, send)
  File "/opt/homebrew/lib/python3.9/site-packages/starlette/exceptions.py", line 93, in __call__
    raise exc
  File "/opt/homebrew/lib/python3.9/site-packages/starlette/exceptions.py", line 82, in __call__
    await self.app(scope, receive, sender)
  File "/opt/homebrew/lib/python3.9/site-packages/fastapi/middleware/asyncexitstack.py", line 21, in __call__
    raise e
  File "/opt/homebrew/lib/python3.9/site-packages/fastapi/middleware/asyncexitstack.py", line 18, in __call__
    await self.app(scope, receive, send)
  File "/opt/homebrew/lib/python3.9/site-packages/starlette/routing.py", line 670, in __call__
    await route.handle(scope, receive, send)
  File "/opt/homebrew/lib/python3.9/site-packages/starlette/routing.py", line 266, in handle
    await self.app(scope, receive, send)
  File "/opt/homebrew/lib/python3.9/site-packages/starlette/routing.py", line 65, in app
    response = await func(request)
  File "/opt/homebrew/lib/python3.9/site-packages/fastapi/routing.py", line 227, in app
    raw_response = await run_endpoint_function(
  File "/opt/homebrew/lib/python3.9/site-packages/fastapi/routing.py", line 160, in run_endpoint_function
    return await dependant.call(**values)
  File "/Users/aditya/Downloads/API 2/C/RUN/./main.py", line 1038, in create_order
    return user_result
UnboundLocalError: local variable 'user_result' referenced before assignment
root - INFO - 2023-03-20 13:25:15.880056 - Order placement successful for users: []
root - INFO - 2023-03-20 13:30:15.914866 - Order placement successful for users: []
root - INFO - 2023-03-20 13:35:15.946480 - Order placement successful for users: []
root - INFO - 2023-03-20 13:40:15.892380 - Order placement successful for users: []
root - INFO - 2023-03-20 13:45:15.883955 - Order placement successful for users: []
uvicorn.error - ERROR - Exception in ASGI application
Traceback (most recent call last):
  File "/opt/homebrew/lib/python3.9/site-packages/uvicorn/protocols/http/h11_impl.py", line 366, in run_asgi
    result = await app(self.scope, self.receive, self.send)
  File "/opt/homebrew/lib/python3.9/site-packages/uvicorn/middleware/proxy_headers.py", line 75, in __call__
    return await self.app(scope, receive, send)
  File "/opt/homebrew/lib/python3.9/site-packages/fastapi/applications.py", line 269, in __call__
    await super().__call__(scope, receive, send)
  File "/opt/homebrew/lib/python3.9/site-packages/starlette/applications.py", line 124, in __call__
    await self.middleware_stack(scope, receive, send)
  File "/opt/homebrew/lib/python3.9/site-packages/starlette/middleware/errors.py", line 184, in __call__
    raise exc
  File "/opt/homebrew/lib/python3.9/site-packages/starlette/middleware/errors.py", line 162, in __call__
    await self.app(scope, receive, _send)
  File "/opt/homebrew/lib/python3.9/site-packages/starlette/middleware/cors.py", line 84, in __call__
    await self.app(scope, receive, send)
  File "/opt/homebrew/lib/python3.9/site-packages/starlette/exceptions.py", line 93, in __call__
    raise exc
  File "/opt/homebrew/lib/python3.9/site-packages/starlette/exceptions.py", line 82, in __call__
    await self.app(scope, receive, sender)
  File "/opt/homebrew/lib/python3.9/site-packages/fastapi/middleware/asyncexitstack.py", line 21, in __call__
    raise e
  File "/opt/homebrew/lib/python3.9/site-packages/fastapi/middleware/asyncexitstack.py", line 18, in __call__
    await self.app(scope, receive, send)
  File "/opt/homebrew/lib/python3.9/site-packages/starlette/routing.py", line 670, in __call__
    await route.handle(scope, receive, send)
  File "/opt/homebrew/lib/python3.9/site-packages/starlette/routing.py", line 266, in handle
    await self.app(scope, receive, send)
  File "/opt/homebrew/lib/python3.9/site-packages/starlette/routing.py", line 65, in app
    response = await func(request)
  File "/opt/homebrew/lib/python3.9/site-packages/fastapi/routing.py", line 227, in app
    raw_response = await run_endpoint_function(
  File "/opt/homebrew/lib/python3.9/site-packages/fastapi/routing.py", line 160, in run_endpoint_function
    return await dependant.call(**values)
  File "/Users/aditya/Downloads/API 2/C/RUN/./main.py", line 1038, in create_order
    return user_result
UnboundLocalError: local variable 'user_result' referenced before assignment
root - INFO - 2023-03-20 13:45:17.165720 - Order placement successful for users: []
uvicorn.error - ERROR - Exception in ASGI application
Traceback (most recent call last):
  File "/opt/homebrew/lib/python3.9/site-packages/uvicorn/protocols/http/h11_impl.py", line 366, in run_asgi
    result = await app(self.scope, self.receive, self.send)
  File "/opt/homebrew/lib/python3.9/site-packages/uvicorn/middleware/proxy_headers.py", line 75, in __call__
    return await self.app(scope, receive, send)
  File "/opt/homebrew/lib/python3.9/site-packages/fastapi/applications.py", line 269, in __call__
    await super().__call__(scope, receive, send)
  File "/opt/homebrew/lib/python3.9/site-packages/starlette/applications.py", line 124, in __call__
    await self.middleware_stack(scope, receive, send)
  File "/opt/homebrew/lib/python3.9/site-packages/starlette/middleware/errors.py", line 184, in __call__
    raise exc
  File "/opt/homebrew/lib/python3.9/site-packages/starlette/middleware/errors.py", line 162, in __call__
    await self.app(scope, receive, _send)
  File "/opt/homebrew/lib/python3.9/site-packages/starlette/middleware/cors.py", line 84, in __call__
    await self.app(scope, receive, send)
  File "/opt/homebrew/lib/python3.9/site-packages/starlette/exceptions.py", line 93, in __call__
    raise exc
  File "/opt/homebrew/lib/python3.9/site-packages/starlette/exceptions.py", line 82, in __call__
    await self.app(scope, receive, sender)
  File "/opt/homebrew/lib/python3.9/site-packages/fastapi/middleware/asyncexitstack.py", line 21, in __call__
    raise e
  File "/opt/homebrew/lib/python3.9/site-packages/fastapi/middleware/asyncexitstack.py", line 18, in __call__
    await self.app(scope, receive, send)
  File "/opt/homebrew/lib/python3.9/site-packages/starlette/routing.py", line 670, in __call__
    await route.handle(scope, receive, send)
  File "/opt/homebrew/lib/python3.9/site-packages/starlette/routing.py", line 266, in handle
    await self.app(scope, receive, send)
  File "/opt/homebrew/lib/python3.9/site-packages/starlette/routing.py", line 65, in app
    response = await func(request)
  File "/opt/homebrew/lib/python3.9/site-packages/fastapi/routing.py", line 227, in app
    raw_response = await run_endpoint_function(
  File "/opt/homebrew/lib/python3.9/site-packages/fastapi/routing.py", line 160, in run_endpoint_function
    return await dependant.call(**values)
  File "/Users/aditya/Downloads/API 2/C/RUN/./main.py", line 1038, in create_order
    return user_result
UnboundLocalError: local variable 'user_result' referenced before assignment
root - INFO - 2023-03-20 13:50:15.861637 - Order placement successful for users: []
uvicorn.error - ERROR - Exception in ASGI application
Traceback (most recent call last):
  File "/opt/homebrew/lib/python3.9/site-packages/uvicorn/protocols/http/h11_impl.py", line 366, in run_asgi
    result = await app(self.scope, self.receive, self.send)
  File "/opt/homebrew/lib/python3.9/site-packages/uvicorn/middleware/proxy_headers.py", line 75, in __call__
    return await self.app(scope, receive, send)
  File "/opt/homebrew/lib/python3.9/site-packages/fastapi/applications.py", line 269, in __call__
    await super().__call__(scope, receive, send)
  File "/opt/homebrew/lib/python3.9/site-packages/starlette/applications.py", line 124, in __call__
    await self.middleware_stack(scope, receive, send)
  File "/opt/homebrew/lib/python3.9/site-packages/starlette/middleware/errors.py", line 184, in __call__
    raise exc
  File "/opt/homebrew/lib/python3.9/site-packages/starlette/middleware/errors.py", line 162, in __call__
    await self.app(scope, receive, _send)
  File "/opt/homebrew/lib/python3.9/site-packages/starlette/middleware/cors.py", line 84, in __call__
    await self.app(scope, receive, send)
  File "/opt/homebrew/lib/python3.9/site-packages/starlette/exceptions.py", line 93, in __call__
    raise exc
  File "/opt/homebrew/lib/python3.9/site-packages/starlette/exceptions.py", line 82, in __call__
    await self.app(scope, receive, sender)
  File "/opt/homebrew/lib/python3.9/site-packages/fastapi/middleware/asyncexitstack.py", line 21, in __call__
    raise e
  File "/opt/homebrew/lib/python3.9/site-packages/fastapi/middleware/asyncexitstack.py", line 18, in __call__
    await self.app(scope, receive, send)
  File "/opt/homebrew/lib/python3.9/site-packages/starlette/routing.py", line 670, in __call__
    await route.handle(scope, receive, send)
  File "/opt/homebrew/lib/python3.9/site-packages/starlette/routing.py", line 266, in handle
    await self.app(scope, receive, send)
  File "/opt/homebrew/lib/python3.9/site-packages/starlette/routing.py", line 65, in app
    response = await func(request)
  File "/opt/homebrew/lib/python3.9/site-packages/fastapi/routing.py", line 227, in app
    raw_response = await run_endpoint_function(
  File "/opt/homebrew/lib/python3.9/site-packages/fastapi/routing.py", line 160, in run_endpoint_function
    return await dependant.call(**values)
  File "/Users/aditya/Downloads/API 2/C/RUN/./main.py", line 1038, in create_order
    return user_result
UnboundLocalError: local variable 'user_result' referenced before assignment
root - INFO - 2023-03-20 13:50:17.133334 - Order placement successful for users: []
uvicorn.error - ERROR - Exception in ASGI application
Traceback (most recent call last):
  File "/opt/homebrew/lib/python3.9/site-packages/uvicorn/protocols/http/h11_impl.py", line 366, in run_asgi
    result = await app(self.scope, self.receive, self.send)
  File "/opt/homebrew/lib/python3.9/site-packages/uvicorn/middleware/proxy_headers.py", line 75, in __call__
    return await self.app(scope, receive, send)
  File "/opt/homebrew/lib/python3.9/site-packages/fastapi/applications.py", line 269, in __call__
    await super().__call__(scope, receive, send)
  File "/opt/homebrew/lib/python3.9/site-packages/starlette/applications.py", line 124, in __call__
    await self.middleware_stack(scope, receive, send)
  File "/opt/homebrew/lib/python3.9/site-packages/starlette/middleware/errors.py", line 184, in __call__
    raise exc
  File "/opt/homebrew/lib/python3.9/site-packages/starlette/middleware/errors.py", line 162, in __call__
    await self.app(scope, receive, _send)
  File "/opt/homebrew/lib/python3.9/site-packages/starlette/middleware/cors.py", line 84, in __call__
    await self.app(scope, receive, send)
  File "/opt/homebrew/lib/python3.9/site-packages/starlette/exceptions.py", line 93, in __call__
    raise exc
  File "/opt/homebrew/lib/python3.9/site-packages/starlette/exceptions.py", line 82, in __call__
    await self.app(scope, receive, sender)
  File "/opt/homebrew/lib/python3.9/site-packages/fastapi/middleware/asyncexitstack.py", line 21, in __call__
    raise e
  File "/opt/homebrew/lib/python3.9/site-packages/fastapi/middleware/asyncexitstack.py", line 18, in __call__
    await self.app(scope, receive, send)
  File "/opt/homebrew/lib/python3.9/site-packages/starlette/routing.py", line 670, in __call__
    await route.handle(scope, receive, send)
  File "/opt/homebrew/lib/python3.9/site-packages/starlette/routing.py", line 266, in handle
    await self.app(scope, receive, send)
  File "/opt/homebrew/lib/python3.9/site-packages/starlette/routing.py", line 65, in app
    response = await func(request)
  File "/opt/homebrew/lib/python3.9/site-packages/fastapi/routing.py", line 227, in app
    raw_response = await run_endpoint_function(
  File "/opt/homebrew/lib/python3.9/site-packages/fastapi/routing.py", line 160, in run_endpoint_function
    return await dependant.call(**values)
  File "/Users/aditya/Downloads/API 2/C/RUN/./main.py", line 1038, in create_order
    return user_result
UnboundLocalError: local variable 'user_result' referenced before assignment
root - INFO - 2023-03-20 13:55:15.890860 - Order placement successful for users: []
uvicorn.error - ERROR - Exception in ASGI application
Traceback (most recent call last):
  File "/opt/homebrew/lib/python3.9/site-packages/uvicorn/protocols/http/h11_impl.py", line 366, in run_asgi
    result = await app(self.scope, self.receive, self.send)
  File "/opt/homebrew/lib/python3.9/site-packages/uvicorn/middleware/proxy_headers.py", line 75, in __call__
    return await self.app(scope, receive, send)
  File "/opt/homebrew/lib/python3.9/site-packages/fastapi/applications.py", line 269, in __call__
    await super().__call__(scope, receive, send)
  File "/opt/homebrew/lib/python3.9/site-packages/starlette/applications.py", line 124, in __call__
    await self.middleware_stack(scope, receive, send)
  File "/opt/homebrew/lib/python3.9/site-packages/starlette/middleware/errors.py", line 184, in __call__
    raise exc
  File "/opt/homebrew/lib/python3.9/site-packages/starlette/middleware/errors.py", line 162, in __call__
    await self.app(scope, receive, _send)
  File "/opt/homebrew/lib/python3.9/site-packages/starlette/middleware/cors.py", line 84, in __call__
    await self.app(scope, receive, send)
  File "/opt/homebrew/lib/python3.9/site-packages/starlette/exceptions.py", line 93, in __call__
    raise exc
  File "/opt/homebrew/lib/python3.9/site-packages/starlette/exceptions.py", line 82, in __call__
    await self.app(scope, receive, sender)
  File "/opt/homebrew/lib/python3.9/site-packages/fastapi/middleware/asyncexitstack.py", line 21, in __call__
    raise e
  File "/opt/homebrew/lib/python3.9/site-packages/fastapi/middleware/asyncexitstack.py", line 18, in __call__
    await self.app(scope, receive, send)
  File "/opt/homebrew/lib/python3.9/site-packages/starlette/routing.py", line 670, in __call__
    await route.handle(scope, receive, send)
  File "/opt/homebrew/lib/python3.9/site-packages/starlette/routing.py", line 266, in handle
    await self.app(scope, receive, send)
  File "/opt/homebrew/lib/python3.9/site-packages/starlette/routing.py", line 65, in app
    response = await func(request)
  File "/opt/homebrew/lib/python3.9/site-packages/fastapi/routing.py", line 227, in app
    raw_response = await run_endpoint_function(
  File "/opt/homebrew/lib/python3.9/site-packages/fastapi/routing.py", line 160, in run_endpoint_function
    return await dependant.call(**values)
  File "/Users/aditya/Downloads/API 2/C/RUN/./main.py", line 1038, in create_order
    return user_result
UnboundLocalError: local variable 'user_result' referenced before assignment
root - INFO - 2023-03-20 13:55:17.219092 - Order placement successful for users: []
uvicorn.error - ERROR - Exception in ASGI application
Traceback (most recent call last):
  File "/opt/homebrew/lib/python3.9/site-packages/uvicorn/protocols/http/h11_impl.py", line 366, in run_asgi
    result = await app(self.scope, self.receive, self.send)
  File "/opt/homebrew/lib/python3.9/site-packages/uvicorn/middleware/proxy_headers.py", line 75, in __call__
    return await self.app(scope, receive, send)
  File "/opt/homebrew/lib/python3.9/site-packages/fastapi/applications.py", line 269, in __call__
    await super().__call__(scope, receive, send)
  File "/opt/homebrew/lib/python3.9/site-packages/starlette/applications.py", line 124, in __call__
    await self.middleware_stack(scope, receive, send)
  File "/opt/homebrew/lib/python3.9/site-packages/starlette/middleware/errors.py", line 184, in __call__
    raise exc
  File "/opt/homebrew/lib/python3.9/site-packages/starlette/middleware/errors.py", line 162, in __call__
    await self.app(scope, receive, _send)
  File "/opt/homebrew/lib/python3.9/site-packages/starlette/middleware/cors.py", line 84, in __call__
    await self.app(scope, receive, send)
  File "/opt/homebrew/lib/python3.9/site-packages/starlette/exceptions.py", line 93, in __call__
    raise exc
  File "/opt/homebrew/lib/python3.9/site-packages/starlette/exceptions.py", line 82, in __call__
    await self.app(scope, receive, sender)
  File "/opt/homebrew/lib/python3.9/site-packages/fastapi/middleware/asyncexitstack.py", line 21, in __call__
    raise e
  File "/opt/homebrew/lib/python3.9/site-packages/fastapi/middleware/asyncexitstack.py", line 18, in __call__
    await self.app(scope, receive, send)
  File "/opt/homebrew/lib/python3.9/site-packages/starlette/routing.py", line 670, in __call__
    await route.handle(scope, receive, send)
  File "/opt/homebrew/lib/python3.9/site-packages/starlette/routing.py", line 266, in handle
    await self.app(scope, receive, send)
  File "/opt/homebrew/lib/python3.9/site-packages/starlette/routing.py", line 65, in app
    response = await func(request)
  File "/opt/homebrew/lib/python3.9/site-packages/fastapi/routing.py", line 227, in app
    raw_response = await run_endpoint_function(
  File "/opt/homebrew/lib/python3.9/site-packages/fastapi/routing.py", line 160, in run_endpoint_function
    return await dependant.call(**values)
  File "/Users/aditya/Downloads/API 2/C/RUN/./main.py", line 1038, in create_order
    return user_result
UnboundLocalError: local variable 'user_result' referenced before assignment
root - INFO - 2023-03-20 14:00:15.874028 - Order placement successful for users: []
root - INFO - 2023-03-20 14:05:15.956426 - Order placement successful for users: []
root - INFO - 2023-03-20 14:10:15.951225 - Order placement successful for users: []
root - INFO - 2023-03-20 14:15:15.915763 - Order placement successful for users: []
root - INFO - 2023-03-20 14:20:15.880510 - Order placement successful for users: []
root - INFO - 2023-03-20 14:25:15.935464 - Order placement successful for users: []
uvicorn.error - ERROR - Exception in ASGI application
Traceback (most recent call last):
  File "/opt/homebrew/lib/python3.9/site-packages/uvicorn/protocols/http/h11_impl.py", line 366, in run_asgi
    result = await app(self.scope, self.receive, self.send)
  File "/opt/homebrew/lib/python3.9/site-packages/uvicorn/middleware/proxy_headers.py", line 75, in __call__
    return await self.app(scope, receive, send)
  File "/opt/homebrew/lib/python3.9/site-packages/fastapi/applications.py", line 269, in __call__
    await super().__call__(scope, receive, send)
  File "/opt/homebrew/lib/python3.9/site-packages/starlette/applications.py", line 124, in __call__
    await self.middleware_stack(scope, receive, send)
  File "/opt/homebrew/lib/python3.9/site-packages/starlette/middleware/errors.py", line 184, in __call__
    raise exc
  File "/opt/homebrew/lib/python3.9/site-packages/starlette/middleware/errors.py", line 162, in __call__
    await self.app(scope, receive, _send)
  File "/opt/homebrew/lib/python3.9/site-packages/starlette/middleware/cors.py", line 84, in __call__
    await self.app(scope, receive, send)
  File "/opt/homebrew/lib/python3.9/site-packages/starlette/exceptions.py", line 93, in __call__
    raise exc
  File "/opt/homebrew/lib/python3.9/site-packages/starlette/exceptions.py", line 82, in __call__
    await self.app(scope, receive, sender)
  File "/opt/homebrew/lib/python3.9/site-packages/fastapi/middleware/asyncexitstack.py", line 21, in __call__
    raise e
  File "/opt/homebrew/lib/python3.9/site-packages/fastapi/middleware/asyncexitstack.py", line 18, in __call__
    await self.app(scope, receive, send)
  File "/opt/homebrew/lib/python3.9/site-packages/starlette/routing.py", line 670, in __call__
    await route.handle(scope, receive, send)
  File "/opt/homebrew/lib/python3.9/site-packages/starlette/routing.py", line 266, in handle
    await self.app(scope, receive, send)
  File "/opt/homebrew/lib/python3.9/site-packages/starlette/routing.py", line 65, in app
    response = await func(request)
  File "/opt/homebrew/lib/python3.9/site-packages/fastapi/routing.py", line 227, in app
    raw_response = await run_endpoint_function(
  File "/opt/homebrew/lib/python3.9/site-packages/fastapi/routing.py", line 160, in run_endpoint_function
    return await dependant.call(**values)
  File "/Users/aditya/Downloads/API 2/C/RUN/./main.py", line 1038, in create_order
    return user_result
UnboundLocalError: local variable 'user_result' referenced before assignment
root - INFO - 2023-03-20 14:25:17.168927 - Order placement successful for users: []
uvicorn.error - ERROR - Exception in ASGI application
Traceback (most recent call last):
  File "/opt/homebrew/lib/python3.9/site-packages/uvicorn/protocols/http/h11_impl.py", line 366, in run_asgi
    result = await app(self.scope, self.receive, self.send)
  File "/opt/homebrew/lib/python3.9/site-packages/uvicorn/middleware/proxy_headers.py", line 75, in __call__
    return await self.app(scope, receive, send)
  File "/opt/homebrew/lib/python3.9/site-packages/fastapi/applications.py", line 269, in __call__
    await super().__call__(scope, receive, send)
  File "/opt/homebrew/lib/python3.9/site-packages/starlette/applications.py", line 124, in __call__
    await self.middleware_stack(scope, receive, send)
  File "/opt/homebrew/lib/python3.9/site-packages/starlette/middleware/errors.py", line 184, in __call__
    raise exc
  File "/opt/homebrew/lib/python3.9/site-packages/starlette/middleware/errors.py", line 162, in __call__
    await self.app(scope, receive, _send)
  File "/opt/homebrew/lib/python3.9/site-packages/starlette/middleware/cors.py", line 84, in __call__
    await self.app(scope, receive, send)
  File "/opt/homebrew/lib/python3.9/site-packages/starlette/exceptions.py", line 93, in __call__
    raise exc
  File "/opt/homebrew/lib/python3.9/site-packages/starlette/exceptions.py", line 82, in __call__
    await self.app(scope, receive, sender)
  File "/opt/homebrew/lib/python3.9/site-packages/fastapi/middleware/asyncexitstack.py", line 21, in __call__
    raise e
  File "/opt/homebrew/lib/python3.9/site-packages/fastapi/middleware/asyncexitstack.py", line 18, in __call__
    await self.app(scope, receive, send)
  File "/opt/homebrew/lib/python3.9/site-packages/starlette/routing.py", line 670, in __call__
    await route.handle(scope, receive, send)
  File "/opt/homebrew/lib/python3.9/site-packages/starlette/routing.py", line 266, in handle
    await self.app(scope, receive, send)
  File "/opt/homebrew/lib/python3.9/site-packages/starlette/routing.py", line 65, in app
    response = await func(request)
  File "/opt/homebrew/lib/python3.9/site-packages/fastapi/routing.py", line 227, in app
    raw_response = await run_endpoint_function(
  File "/opt/homebrew/lib/python3.9/site-packages/fastapi/routing.py", line 160, in run_endpoint_function
    return await dependant.call(**values)
  File "/Users/aditya/Downloads/API 2/C/RUN/./main.py", line 1038, in create_order
    return user_result
UnboundLocalError: local variable 'user_result' referenced before assignment
root - INFO - 2023-03-20 14:30:15.981153 - Order placement successful for users: []
root - INFO - 2023-03-20 14:35:16.877891 - Order placement successful for users: []
root - INFO - 2023-03-20 14:40:15.858640 - Order placement successful for users: []
root - INFO - 2023-03-20 14:45:15.860716 - Order placement successful for users: []
root - INFO - 2023-03-20 14:50:15.896744 - Order placement successful for users: []
root - INFO - 2023-03-20 14:55:15.826791 - Order placement successful for users: []
root - INFO - 2023-03-20 15:00:15.885190 - Order placement successful for users: []
root - INFO - 2023-03-20 15:05:15.877555 - Order placement successful for users: []
root - INFO - 2023-03-20 15:10:15.981132 - Order placed for MASTER_TRUST OPHIUCUS NIFTY|L|0|CE|WEEK|0 CLOSE SHORT -10 0 0
root - INFO - 2023-03-20 15:10:16.084163 - Order placed for ODIN OPHIUCUS NIFTY|L|0|CE|WEEK|0 CLOSE SHORT -1 0 0
root - INFO - 2023-03-20 15:10:16.183270 - Order placed for FINVANT_LIVE OPHIUCUS NIFTY|L|0|CE|WEEK|0 CLOSE SHORT -1 0 0
root - INFO - 2023-03-20 15:10:16.294833 - Order placed for BPWealth_AHD083 OPHIUCUS NIFTY|L|0|CE|WEEK|0 CLOSE SHORT -1 0 0
root - INFO - 2023-03-20 15:10:16.392894 - Order placed for BPWealth_ACS1301 OPHIUCUS NIFTY|L|0|CE|WEEK|0 CLOSE SHORT -1 0 0
root - INFO - 2023-03-20 15:10:16.489360 - Order placed for BPWealth_ACS1207 OPHIUCUS NIFTY|L|0|CE|WEEK|0 CLOSE SHORT -1 0 0
root - INFO - 2023-03-20 15:10:16.587306 - Order placed for BPWealth_AC66 OPHIUCUS NIFTY|L|0|CE|WEEK|0 CLOSE SHORT -1 0 0
root - INFO - 2023-03-20 15:10:16.684952 - Order placement successful for users: [{'user_name': 'MASTER_TRUST', 'strategy': 'OPHIUCUS', 'instrument_nomenclature': 'NIFTY|L|0|CE|WEEK|0', 'position': 'CLOSE SHORT', 'target': 0, 'stoploss': 0}, {'user_name': 'ODIN', 'strategy': 'OPHIUCUS', 'instrument_nomenclature': 'NIFTY|L|0|CE|WEEK|0', 'position': 'CLOSE SHORT', 'target': 0, 'stoploss': 0}, {'user_name': 'FINVANT_LIVE', 'strategy': 'OPHIUCUS', 'instrument_nomenclature': 'NIFTY|L|0|CE|WEEK|0', 'position': 'CLOSE SHORT', 'target': 0, 'stoploss': 0}, {'user_name': 'BPWealth_AHD083', 'strategy': 'OPHIUCUS', 'instrument_nomenclature': 'NIFTY|L|0|CE|WEEK|0', 'position': 'CLOSE SHORT', 'target': 0, 'stoploss': 0}, {'user_name': 'BPWealth_ACS1301', 'strategy': 'OPHIUCUS', 'instrument_nomenclature': 'NIFTY|L|0|CE|WEEK|0', 'position': 'CLOSE SHORT', 'target': 0, 'stoploss': 0}, {'user_name': 'BPWealth_ACS1207', 'strategy': 'OPHIUCUS', 'instrument_nomenclature': 'NIFTY|L|0|CE|WEEK|0', 'position': 'CLOSE SHORT', 'target': 0, 'stoploss': 0}, {'user_name': 'BPWealth_AC66', 'strategy': 'OPHIUCUS', 'instrument_nomenclature': 'NIFTY|L|0|CE|WEEK|0', 'position': 'CLOSE SHORT', 'target': 0, 'stoploss': 0}]
root - INFO - 2023-03-20 15:20:15.822739 - Order placement successful for users: []
root - INFO - 2023-03-20 15:25:15.919178 - Order placed for FINVANT_LIVE ALTAIR BANKNIFTY_SYNTHETIC_INTRADAY_SHORT SELL 1 0 0
root - INFO - 2023-03-20 15:25:16.026364 - Order placed for AIRAN ALTAIR_FUTURES BANKNIFTY CLOSE SHORT -3 0 0
root - INFO - 2023-03-20 15:25:16.134855 - Order placed for BPWealth_AHO7706 ALTAIR_FUTURES BANKNIFTY CLOSE SHORT -1 0 0
root - INFO - 2023-03-20 15:25:16.245753 - Order placement successful for users: [{'user_name': 'FINVANT_LIVE', 'strategy': 'ALTAIR', 'instrument_nomenclature': 'BANKNIFTY_SYNTHETIC_INTRADAY_SHORT', 'position': 'SELL', 'target': 0, 'stoploss': 0}, {'user_name': 'AIRAN', 'strategy': 'ALTAIR_FUTURES', 'instrument_nomenclature': 'BANKNIFTY', 'position': 'CLOSE SHORT', 'target': 0, 'stoploss': 0}, {'user_name': 'BPWealth_AHO7706', 'strategy': 'ALTAIR_FUTURES', 'instrument_nomenclature': 'BANKNIFTY', 'position': 'CLOSE SHORT', 'target': 0, 'stoploss': 0}]
uvicorn.error - INFO - Shutting down
uvicorn.error - INFO - Waiting for application shutdown.
tortoise - INFO - Tortoise-ORM shutdown
uvicorn.error - INFO - Application shutdown complete.
uvicorn.error - INFO - Finished server process [19500]
