root - INFO - 2023-04-21 10:59:30.013879 - OMS Server turned on.
uvicorn.error - INFO - Started server process [18912]
uvicorn.error - INFO - Waiting for application startup.
tortoise - INFO - Tortoise-ORM started, {'default': <tortoise.backends.sqlite.client.SqliteClient object at 0x7f2328202f70>}, {'models': {'OptionSpread': <class 'models.OptionSpread'>, 'User': <class 'models.User'>, 'User_Finvant': <class 'models.User_Finvant'>}}
tortoise - INFO - Tortoise-ORM generating schema
uvicorn.error - INFO - Application startup complete.
uvicorn.error - INFO - Uvicorn running on http://0.0.0.0:9093 (Press CTRL+C to quit)
root - INFO - 2023-04-21 11:00:18.609325 - Order placement successful for users: []
root - INFO - 2023-04-21 11:05:18.456802 - Order placement successful for users: []
root - INFO - 2023-04-21 11:10:19.088941 - Order placement successful for users: []
root - INFO - 2023-04-21 11:20:18.114146 - Order placement successful for users: []
root - INFO - 2023-04-21 11:35:18.386269 - Order placement successful for users: []
root - INFO - 2023-04-21 11:45:22.038439 - Order placement successful for users: []
root - INFO - 2023-04-21 12:00:18.160486 - Order placement successful for users: []
root - INFO - 2023-04-21 12:20:18.062057 - Order placement successful for users: []
root - INFO - 2023-04-21 12:30:18.003681 - Order placement successful for users: []
root - INFO - 2023-04-21 12:45:19.205619 - Order placement successful for users: []
root - INFO - 2023-04-21 13:00:18.377022 - Order placement successful for users: []
root - INFO - 2023-04-21 13:15:18.363673 - Order placement successful for users: []
uvicorn.error - ERROR - Exception in ASGI application
Traceback (most recent call last):
  File "/home/ubuntu/.local/lib/python3.8/site-packages/uvicorn/protocols/http/h11_impl.py", line 373, in run_asgi
    result = await app(self.scope, self.receive, self.send)
  File "/home/ubuntu/.local/lib/python3.8/site-packages/uvicorn/middleware/proxy_headers.py", line 75, in __call__
    return await self.app(scope, receive, send)
  File "/home/ubuntu/.local/lib/python3.8/site-packages/fastapi/applications.py", line 208, in __call__
    await super().__call__(scope, receive, send)
  File "/home/ubuntu/.local/lib/python3.8/site-packages/starlette/applications.py", line 112, in __call__
    await self.middleware_stack(scope, receive, send)
  File "/home/ubuntu/.local/lib/python3.8/site-packages/starlette/middleware/errors.py", line 181, in __call__
    raise exc
  File "/home/ubuntu/.local/lib/python3.8/site-packages/starlette/middleware/errors.py", line 159, in __call__
    await self.app(scope, receive, _send)
  File "/home/ubuntu/.local/lib/python3.8/site-packages/starlette/middleware/cors.py", line 84, in __call__
    await self.app(scope, receive, send)
  File "/home/ubuntu/.local/lib/python3.8/site-packages/starlette/exceptions.py", line 82, in __call__
    raise exc
  File "/home/ubuntu/.local/lib/python3.8/site-packages/starlette/exceptions.py", line 71, in __call__
    await self.app(scope, receive, sender)
  File "/home/ubuntu/.local/lib/python3.8/site-packages/starlette/routing.py", line 656, in __call__
    await route.handle(scope, receive, send)
  File "/home/ubuntu/.local/lib/python3.8/site-packages/starlette/routing.py", line 259, in handle
    await self.app(scope, receive, send)
  File "/home/ubuntu/.local/lib/python3.8/site-packages/starlette/routing.py", line 61, in app
    response = await func(request)
  File "/home/ubuntu/.local/lib/python3.8/site-packages/fastapi/routing.py", line 226, in app
    raw_response = await run_endpoint_function(
  File "/home/ubuntu/.local/lib/python3.8/site-packages/fastapi/routing.py", line 159, in run_endpoint_function
    return await dependant.call(**values)
  File "/home/ubuntu/C/RUN/./main.py", line 1086, in create_order
    return user_result
UnboundLocalError: local variable 'user_result' referenced before assignment
root - INFO - 2023-04-21 13:15:23.114703 - Order placement successful for users: []
uvicorn.error - ERROR - Exception in ASGI application
Traceback (most recent call last):
  File "/home/ubuntu/.local/lib/python3.8/site-packages/uvicorn/protocols/http/h11_impl.py", line 373, in run_asgi
    result = await app(self.scope, self.receive, self.send)
  File "/home/ubuntu/.local/lib/python3.8/site-packages/uvicorn/middleware/proxy_headers.py", line 75, in __call__
    return await self.app(scope, receive, send)
  File "/home/ubuntu/.local/lib/python3.8/site-packages/fastapi/applications.py", line 208, in __call__
    await super().__call__(scope, receive, send)
  File "/home/ubuntu/.local/lib/python3.8/site-packages/starlette/applications.py", line 112, in __call__
    await self.middleware_stack(scope, receive, send)
  File "/home/ubuntu/.local/lib/python3.8/site-packages/starlette/middleware/errors.py", line 181, in __call__
    raise exc
  File "/home/ubuntu/.local/lib/python3.8/site-packages/starlette/middleware/errors.py", line 159, in __call__
    await self.app(scope, receive, _send)
  File "/home/ubuntu/.local/lib/python3.8/site-packages/starlette/middleware/cors.py", line 84, in __call__
    await self.app(scope, receive, send)
  File "/home/ubuntu/.local/lib/python3.8/site-packages/starlette/exceptions.py", line 82, in __call__
    raise exc
  File "/home/ubuntu/.local/lib/python3.8/site-packages/starlette/exceptions.py", line 71, in __call__
    await self.app(scope, receive, sender)
  File "/home/ubuntu/.local/lib/python3.8/site-packages/starlette/routing.py", line 656, in __call__
    await route.handle(scope, receive, send)
  File "/home/ubuntu/.local/lib/python3.8/site-packages/starlette/routing.py", line 259, in handle
    await self.app(scope, receive, send)
  File "/home/ubuntu/.local/lib/python3.8/site-packages/starlette/routing.py", line 61, in app
    response = await func(request)
  File "/home/ubuntu/.local/lib/python3.8/site-packages/fastapi/routing.py", line 226, in app
    raw_response = await run_endpoint_function(
  File "/home/ubuntu/.local/lib/python3.8/site-packages/fastapi/routing.py", line 159, in run_endpoint_function
    return await dependant.call(**values)
  File "/home/ubuntu/C/RUN/./main.py", line 1086, in create_order
    return user_result
UnboundLocalError: local variable 'user_result' referenced before assignment
root - INFO - 2023-04-21 13:20:18.492092 - Order placement successful for users: []
root - INFO - 2023-04-21 13:25:18.797530 - Order placement successful for users: []
root - INFO - 2023-04-21 13:30:19.107254 - Order placement successful for users: []
uvicorn.error - INFO - Shutting down
uvicorn.error - INFO - Waiting for application shutdown.
tortoise - INFO - Tortoise-ORM shutdown
tortoise - INFO - Tortoise-ORM shutdown
uvicorn.error - INFO - Application shutdown complete.
uvicorn.error - INFO - Finished server process [18912]
root - INFO - 2023-04-21 13:34:57.897771 - OMS Server turned on.
uvicorn.error - INFO - Started server process [21286]
uvicorn.error - INFO - Waiting for application startup.
tortoise - INFO - Tortoise-ORM started, {'default': <tortoise.backends.sqlite.client.SqliteClient object at 0x7f5f40c33f70>}, {'models': {'OptionSpread': <class 'models.OptionSpread'>, 'User': <class 'models.User'>, 'User_Finvant': <class 'models.User_Finvant'>}}
tortoise - INFO - Tortoise-ORM generating schema
uvicorn.error - INFO - Application startup complete.
uvicorn.error - INFO - Uvicorn running on http://0.0.0.0:9093 (Press CTRL+C to quit)
